Workbook
Name DiscountPct: DiscountPct!$B$29:$C$201
Name DiscountPct_1: DiscountPct!$B$206:$L$383
Name result: 'Total v2'!$B$1:$L$178
Name result: 'Total v3'!#REF!
Name result: 'Total v3 (2)'!#REF!
Name result: UPB!#REF!
Name result_1: 'Total v2'!$B$1:$L$178
Name result_1: 'Total v3'!#REF!
Name result_1: 'Total v3 (2)'!#REF!
Name result_1: 'Total v4'!$B$2:$L$178
Name result_2: 'Total v3'!$C$2:$O$179
Name result_2: 'Total v3 (2)'!$C$2:$O$179
Name result_3: 'Total v3'!$B$2:$L$179
Name result_3: 'Total v3 (2)'!$B$2:$M$179
Name resultSev_1: 'FC Severity'!$B$2:$L$179
Name resultSev_1: 'REO Severity'!$B$2:$L$177
Name resultSev_1: 'Total Severity'!$B$2:$L$179
Name temp: HPA!#REF!
Name temp: 'MI & nonMI'!$B$2:$F$182
Name temp: 'MI by LTV'!$A$1:$C$23
Name temp: 'REO-FC'!$N$2:$O$182
Name temp: UPB!$A$1:$C$181
Name temp_1: HPA!$A$1:$H$295
Name temp_1: 'MI by LTV'!$A$30:$C$45
Name temp_2: 'MI by LTV'!$N$30:$P$45
Name temp_2: 'REO-FC'!$U$2:$W$178
Name temp_3: 'MI by LTV'!$N$1:$P$23
Name temp_3: 'REO-FC'!$Q$2:$S$182
Name temp_4: 'MI by LTV'!$A$61:$C$83

Sheet DiscountPct
B1: ActualDiscountPct | C1: EstimDiscountPct
A2: 2000 | B2: 54.812222 | C2: 49.516693
A3: 2001 | B3: 48.35 | C3: 50.461736
A4: 2002 | B4: 50.973303 | C4: 49.722432
A5: 2003 | B5: 49.09195 | C5: 48.905621
A6: 2004 | B6: 48.450809 | C6: 49.305089
A7: 2005 | B7: 51.968391 | C7: 47.126141
A8: 2006 | B8: 51.773728 | C8: 46.662978
A9: 2007 | B9: 49.979083 | C9: 47.789304
A10: 2008 | B10: 49.665262 | C10: 51.587412
A11: 2009 | B11: 52.315884 | C11: 55.920927
A12: 2010 | B12: 52.822645 | C12: 55.660774
A13: 2011 | B13: 53.939908 | C13: 56.025464
... A16: 2014 | B16: 51.029181 | C16: 51.725002
B23: aggActualDiscountPct | C23: aggEstimDiscountPct
A24: 36617 | B24: 0 | C24: 47.79977 | AB24: aggActualDiscountPct | AC24: aggEstimDiscountPct | AF24: aggActualDiscountPct | AG24: aggEstimDiscountPct
A25: 36708 | B25: 32.38 | C25: 47.50331 | AA25: 36526 | AB25: 70.145 | AC25: 48.84349 | AE25: 36526 | AF25: 70.145 | AG25: 50.96046
A26: 36739 | B26: 69.04 | C26: 54.55322 | AA26: 36557 | AB26: 70.54 | AC26: 48.67422 | AE26: 36557 | AF26: 70.54 | AG26: 49.69116
A27: 36770 | B27: 51.36 | C27: 35.3317 | AA27: 36586 | AB27: 68.65 | AC27: 51.30261 | AE27: 36586 | AF27: 68.65 | AG27: 53.19627
A28: 36800 | B28: 77.9 | C28: 55.37734 | AA28: 36617 | AB28: 60.74368 | AC28: 51.96129 | AE28: 36617 | AF28: 60.74368 | AG28: 53.12217
A29: 36831 | B29: 49.84 | C29: 51.0143 | AA29: 36647 | AB29: 67.332 | AC29: 50.52687 | AE29: 36647 | AF29: 67.332 | AG29: 52.2107
A30: 36861 | B30: 83.53 | C30: 56.16892 | AA30: 36678 | AB30: 55.62833 | AC30: 47.97124 | AE30: 36678 | AF30: 55.62833 | AG30: 48.84454
A31: 36892 | B31: 65.045 | C31: 46.57433 | AA31: 36708 | AB31: 67.97684 | AC31: 52.71767 | AE31: 36708 | AF31: 67.97684 | AG31: 53.24407
A32: 36923 | B32: 43.24167 | C32: 55.51748 | AA32: 36739 | AB32: 54.49857 | AC32: 53.41312 | AE32: 36739 | AF32: 54.49857 | AG32: 54.05062
A33: 36951 | B33: 48.26 | C33: 50.76484 | AA33: 36770 | AB33: 56.59829 | AC33: 53.85646 | AE33: 36770 | AF33: 56.59829 | AG33: 54.08099
A34: 36982 | B34: 60.71 | C34: 46.87735 | AA34: 36800 | AB34: 52.73356 | AC34: 55.13465 | AE34: 36800 | AF34: 52.73356 | AG34: 55.42655
A35: 37012 | B35: 28.83667 | C35: 40.40541 | AA35: 36831 | AB35: 58.51923 | AC35: 53.52205 | AE35: 36831 | AF35: 58.51923 | AG35: 53.82192
A36: 37043 | B36: 68.434 | C36: 58.20074 | AA36: 36861 | AB36: 55.28043 | AC36: 51.52123 | AE36: 36861 | AF36: 55.28043 | AG36: 51.90715
... A195: 41883 | B195: 35.85296 | C195: 49.53352 | AA195: 41699 | AB195: 55.08208 | AC195: 51.09004 | AE195: 41699 | AF195: 55.08208 | AG195: 51.05814
AA196: 41730 | AB196: 54.50016 | AC196: 50.96236 | AE196: 41730 | AF196: 54.50016 | AG196: 50.99251
AA197: 41760 | AB197: 54.78196 | AC197: 51.64632 | AE197: 41760 | AF197: 54.78196 | AG197: 51.76538
AA198: 41791 | AB198: 51.8082 | AC198: 51.12732 | AE198: 41791 | AF198: 51.8082 | AG198: 51.36385
AA199: 41821 | AB199: 48.9036 | AC199: 51.03115 | AE199: 41821 | AF199: 48.9036 | AG199: 51.31376
AA200: 41852 | AB200: 50.3566 | AC200: 52.44168 | AE200: 41852 | AF200: 50.3566 | AG200: 53.21813
AA201: 41883 | AB201: 37.99976 | AC201: 50.80516 | AE201: 41883 | AF201: 37.99976 | AG201: 51.11397
B206: aggActuralBaseLoss | C206: aggEstimBassLoss | D206: aggActualExpenses | E206: aggEstimExpenses | F206: aggEstimInterest | G206: aggActualMIRecoveries | H206: aggEstimMIRecoveries | I206: aggActuralTotalLoss | J206: aggEstimTotalLoss | K206: aggActuralTotalSeverity | L206: aggEstimTotalSeverity
B207: 6708.2022 | C207: 0.19099306 | D207: 1232.7222 | E207: 0.02465956 | F207: 0.028735889 | G207: 9780.3157 | H207: 0.18258213 | I207: 0 | J207: 1829.7467 | K207: 0 | L207: 0.061806382
B208: 8969.9879 | C208: 0.284067 | D208: 2744.8299 | E208: 0.057787846 | F208: 0.045018574 | G208: 11854.395 | H208: 0.034155633 | I208: 4998.6314 | J208: 53286.264 | K208: 0.027590787 | L208: 0.35271778
B209: 5306.1588 | C209: 0.20587347 | D209: 2010.3248 | E209: 0.020190789 | F209: 0.04455445 | G209: 13175.769 | H209: 0.13329704 | I209: 333.78215 | J209: 15544.958 | K209: 0.003952464 | L209: 0.13732166
B210: 18269.307 | C210: 0.23610391 | D210: 3489.5026 | E210: 0.0327485 | F210: 0.046840533 | G210: 13772.278 | H210: 0.14078536 | I210: 14609.312 | J210: 29795.889 | K210: 0.068954344 | L210: 0.17490758
...

Sheet Base
W1: With HPI and DQTime | AB1: With zeroBalanceCode
B2: Actual | C2: Estimate | X2: aggActual | Y2: aggEstim | AC2: aggActual | AD2: aggEstim
A3: 36617 | B3: 44042.62 | C3: 20030.84 | W3: 36526 | X3: 4860.04 | Y3: 27028.31 | AB3: 36526 | AC3: 4860.04 | AD3: 24818.52
A4: 36708 | B4: 42000 | C4: 30789.85 | W4: 36557 | X4: 7089.07 | Y4: 40485.59 | AB4: 36557 | AC4: 7089.07 | AD4: 39366.44
A5: 36739 | B5: 30480.72 | C5: 53921.42 | W5: 36586 | X5: 15692.89 | Y5: 38519.59 | AB5: 36586 | AC5: 15692.89 | AD5: 35837.98
A6: 36770 | B6: 16826.43 | C6: 25958.05 | W6: 36617 | X6: 24984.78 | Y6: 43752.08 | AB6: 36617 | AC6: 24984.78 | AD6: 41513.9
A7: 36800 | B7: 13430.98 | C7: 53321.37 | W7: 36647 | X7: 13787.56 | Y7: 39105.22 | AB7: 36647 | AC7: 13787.56 | AD7: 36489.19
A8: 36831 | B8: 44400 | C8: 42979.17 | W8: 36678 | X8: 21517.9 | Y8: 35041.2 | AB8: 36678 | AC8: 21517.9 | AD8: 34068.66
A9: 36861 | B9: -10422.33 | C9: 40413.45 | W9: 36708 | X9: 16637.42 | Y9: 38750.39 | AB9: 36708 | AC9: 16637.42 | AD9: 38102.7
A10: 36892 | B10: 17597.5 | C10: 38190.2 | W10: 36739 | X10: 42666.88 | Y10: 38994.14 | AB10: 36739 | AC10: 42666.88 | AD10: 38281.66
A11: 36923 | B11: 82821.07 | C11: 49653.82 | W11: 36770 | X11: 36443.89 | Y11: 37851.25 | AB11: 36770 | AC11: 36443.89 | AD11: 37496.96
A12: 36951 | B12: 39601.83 | C12: 36377.54 | W12: 36800 | X12: 41965.21 | Y12: 40668.25 | AB12: 36800 | AC12: 41965.21 | AD12: 40011.8
A13: 36982 | B13: 18595.98 | C13: 35974.05 | W13: 36831 | X13: 33520.79 | Y13: 36893.2 | AB13: 36831 | AC13: 33520.79 | AD13: 36239.1
A14: 37012 | B14: 40268.57 | C14: 40024.22 | W14: 36861 | X14: 30332.13 | Y14: 34928.46 | AB14: 36861 | AC14: 30332.13 | AD14: 34454.7
... A174: 41883 | B174: 72994.03 | C174: 48349.01 | W174: 41730 | X174: 43483.02 | Y174: 49729.8 | AB174: 41730 | AC174: 43483.02 | AD174: 49607.72
W175: 41760 | X175: 44748.41 | Y175: 50236.41 | AB175: 41760 | AC175: 44748.41 | AD175: 49940.56
W176: 41791 | X176: 48579.99 | Y176: 49819.65 | AB176: 41791 | AC176: 48579.99 | AD176: 49277.17
W177: 41821 | X177: 53707.01 | Y177: 48118.38 | AB177: 41821 | AC177: 53707.01 | AD177: 47492.37
W178: 41852 | X178: 57973.8 | Y178: 52661.62 | AB178: 41852 | AC178: 57973.8 | AD178: 50697.34
W179: 41883 | X179: 76112.82 | Y179: 49065.47 | AB179: 41883 | AC179: 76112.82 | AD179: 48386.26

Sheet Expenses v3
B1: Total | S1: FC | X1: REO | AD1: Use State instead of Judicial
C2: aggActualExpenses | D2: New | E2: Old | F2: State | T2: aggActualExpenses | U2: New | V2: Old | Y2: aggActualExpenses | Z2: New | AA2: Old | AE2: aggActualExpenses | AF2: aggEstimExpenses
B3: 36434 | C3: 1385 | D3: 4591.093 | E3: 1882.874 | F3: 3849.284 | S3: 36434 | T3: 1385 | U3: 4591.093 | V3: 2179.415 | X3: 36557 | Y3: 5424 | Z3: 13329.86 | AA3: 13068.65 | AD3: 36434 | AE3: 1385 | AF3: 3849.284
B4: 36465 | C4: 2406 | D4: 3391.205 | E4: 738.8934 | F4: 2894.414 | S4: 36465 | T4: 2406 | U4: 3391.205 | V4: 492.0064 | X4: 36586 | Y4: 4349 | Z4: 9669.248 | AA4: 7619.622 | AD4: 36465 | AE4: 2406 | AF4: 2894.414
B5: 36495 | C5: 3163.75 | D5: 4468.612 | E5: 1801.07 | F5: 5920.565 | S5: 36495 | T5: 3163.75 | U5: 4468.612 | V5: 1388.604 | X5: 36617 | Y5: 5268.143 | Z5: 9027.725 | AA5: 7333.997 | AD5: 36495 | AE5: 3163.75 | AF5: 5920.565
B6: 36526 | C6: 1052 | D6: 3370.552 | E6: 745.5433 | F6: 4902.327 | S6: 36526 | T6: 1052 | U6: 3370.552 | V6: 801.5722 | X6: 36647 | Y6: 6074 | Z6: 7028.055 | AA6: 5147.148 | AD6: 36526 | AE6: 1052 | AF6: 4902.327
B7: 36557 | C7: 2202 | D7: 7391.18 | E7: 5328.131 | F7: 6382.491 | G7: expenses. ~ JudicialFlag. + timeDQ. + 2y Avg HPI + UPB | S7: 36557 | T7: 591 | U7: 4421.839 | V7: 1899.615 | X7: 36678 | Y7: 11563.78 | Z7: 9129.995 | AA7: 7745.724 | AD7: 36557 | AE7: 2202 | AF7: 6382.491
B8: 36586 | C8: 2126 | D8: 4420.108 | E8: 2064.273 | F8: 4386.048 | S8: 36586 | T8: 1808.429 | U8: 3670.231 | V8: 987.4444 | X8: 36708 | Y8: 6245.667 | Z8: 10938.11 | AA8: 9216.786 | AD8: 36586 | AE8: 2126 | AF8: 4386.048
B9: 36617 | C9: 3862.158 | D9: 6362.601 | E9: 4380.796 | F9: 5867.274 | S9: 36617 | T9: 3042 | U9: 4807.946 | V9: 2092.608 | X9: 36739 | Y9: 6184.45 | Z9: 11440.33 | AA9: 10084.08 | AD9: 36617 | AE9: 3862.158 | AF9: 5867.274
B10: 36647 | C10: 2559.7 | D10: 5150.324 | E10: 2952.702 | F10: 5621.804 | S10: 36647 | T10: 1681.125 | U10: 4680.891 | V10: 2018.488 | X10: 36770 | Y10: 6806.56 | Z10: 10424.44 | AA10: 8844.438 | AD10: 36647 | AE10: 2559.7 | AF10: 5621.804
B11: 36678 | C11: 6499.389 | D11: 6679.756 | E11: 4982.053 | F11: 5716.07 | S11: 36678 | T11: 1435 | U11: 4229.518 | V11: 1683.167 | X11: 36800 | Y11: 7814.1 | Z11: 12187.49 | AA11: 10525.95 | AD11: 36678 | AE11: 6499.389 | AF11: 5716.07
B12: 36708 | C12: 4198.895 | D12: 8229.74 | E12: 6742.645 | F12: 6710.715 | S12: 36708 | T12: 690.1429 | U12: 3586.822 | V12: 1042.222 | X12: 36831 | Y12: 7042.556 | Z12: 11472.42 | AA12: 9990.208 | AD12: 36708 | AE12: 4198.895 | AF12: 6710.715
B13: 36739 | C13: 4338.314 | D13: 8274.7 | E13: 6731.129 | F13: 7911.671 | S13: 36739 | T13: 1876.8 | U13: 4053.865 | V13: 1389.054 | X13: 36861 | Y13: 6915.484 | Z13: 11519.71 | AA13: 10437.57 | AD13: 36739 | AE13: 4338.314 | AF13: 7911.671
B14: 36770 | C14: 5293.514 | D14: 8485.466 | E14: 7164.229 | F14: 8209.065 | S14: 36770 | T14: 1510.9 | U14: 3638.023 | V14: 830.8601 | X14: 36892 | Y14: 6669.065 | Z14: 11314.02 | AA14: 10073.06 | AD14: 36770 | AE14: 5293.514 | AF14: 8209.065
B15: 36800 | C15: 5715.089 | D15: 9649.739 | E15: 8276.968 | F15: 8596.228 | S15: 36800 | T15: 1517.067 | U15: 4574.241 | V15: 1853.784 | X15: 36923 | Y15: 8177.489 | Z15: 12070.47 | AA15: 10652.57 | AD15: 36800 | AE15: 5715.089 | AF15: 8596.228
B16: 36831 | C16: 6352.077 | D16: 9441.115 | E16: 8139.729 | F16: 9035.938 | S16: 36831 | T16: 4798.5 | U16: 4870.685 | V16: 2193.209 | X16: 36951 | Y16: 6652.076 | Z16: 11330.02 | AA16: 9980.102 | AD16: 36831 | AE16: 6352.077 | AF16: 9035.938
B17: 36861 | C17: 5559.848 | D17: 9014.792 | E17: 7723.156 | F17: 8366.19 | S17: 36861 | T17: 2758.2 | U17: 3837.951 | V17: 1323.792 | X17: 36982 | Y17: 7272.924 | Z17: 11500.71 | AA17: 10084.59 | AD17: 36861 | AE17: 5559.848 | AF17: 8366.19
B18: 36892 | C18: 5547.172 | D18: 9686.357 | E18: 8580.607 | F18: 9274.893 | S18: 36892 | T18: 1246.583 | U18: 3446.973 | V18: 1054.469 | X18: 37012 | Y18: 7408.824 | Z18: 12006.26 | AA18: 10677.13 | AD18: 36892 | AE18: 5547.172 | AF18: 9274.893
B19: 36923 | C19: 6236.135 | D19: 9234.868 | E19: 7917.641 | F19: 8408.901 | S19: 36923 | T19: 2856.741 | U19: 4298.82 | V19: 1740.741 | X19: 37043 | Y19: 6832.583 | Z19: 11252.32 | AA19: 10032.6 | AD19: 36923 | AE19: 6236.135 | AF19: 8408.901
... B178: 41760 | C178: 25875.2 | D178: 21977.88 | E178: 22141.81 | F178: 22004.63 | S178: 41760 | T178: 11354.56 | U178: 10839.98 | V178: 11314.32 | X178: 41883 | Y178: 28065.9 | Z178: 28402.66 | AA178: 29174.44 | AD178: 41760 | AE178: 25875.2 | AF178: 22004.63
B179: 41791 | C179: 23799.69 | D179: 21510.74 | E179: 21718.3 | F179: 21534.75 | S179: 41791 | T179: 9582.141 | U179: 11085.74 | V179: 11618.78 | AD179: 41791 | AE179: 23799.69 | AF179: 21534.75
B180: 41821 | C180: 22809.42 | D180: 21690.16 | E180: 21938.42 | F180: 21607.8 | S180: 41821 | T180: 6693.002 | U180: 11468.32 | V180: 12078.98 | AD180: 41821 | AE180: 22809.42 | AF180: 21607.8
B181: 41852 | C181: 20747.82 | D181: 21335.08 | E181: 21649.1 | F181: 21371.84 | S181: 41852 | T181: 12469.31 | U181: 15427.94 | V181: 16070.08 | AD181: 41852 | AE181: 20747.82 | AF181: 21371.84
B182: 41883 | C182: 18554.98 | D182: 22372.5 | E182: 22687.92 | F182: 22302.35 | S182: 41883 | T182: 856.5183 | U182: 11151.22 | V182: 11817.09 | AD182: 41883 | AE182: 18554.98 | AF182: 22302.35

Sheet Expenses v2
B1: Total | S1: FC | X1: REO
C2: aggActualExpenses | D2: aggEstimExpenses | T2: aggActualExpenses | U2: aggEstimExpenses | Y2: aggActualExpenses | Z2: aggEstimExpenses
B3: 36434 | C3: 1385 | D3: 1882.874 | S3: 36434 | T3: 1385 | U3: 2179.415 | X3: 36557 | Y3: 5424 | Z3: 13068.65
B4: 36465 | C4: 2406 | D4: 738.8934 | S4: 36465 | T4: 2406 | U4: 492.0064 | X4: 36586 | Y4: 4349 | Z4: 7619.622
B5: 36495 | C5: 3163.75 | D5: 1801.07 | S5: 36495 | T5: 3163.75 | U5: 1388.604 | X5: 36617 | Y5: 5268.143 | Z5: 7333.997
B6: 36526 | C6: 1052 | D6: 745.5433 | S6: 36526 | T6: 1052 | U6: 801.5722 | X6: 36647 | Y6: 6074 | Z6: 5147.148
B7: 36557 | C7: 2202 | D7: 5328.131 | G7: expenses. ~ JudicialFlag. + timeDQ. + HPA. + currentValue. | S7: 36557 | T7: 591 | U7: 1899.615 | X7: 36678 | Y7: 11563.78 | Z7: 7745.724
B8: 36586 | C8: 2126 | D8: 2064.273 | S8: 36586 | T8: 1808.429 | U8: 987.4444 | X8: 36708 | Y8: 6245.667 | Z8: 9216.786
B9: 36617 | C9: 3862.158 | D9: 4380.796 | S9: 36617 | T9: 3042 | U9: 2092.608 | X9: 36739 | Y9: 6184.45 | Z9: 10084.08
B10: 36647 | C10: 2559.7 | D10: 2952.702 | S10: 36647 | T10: 1681.125 | U10: 2018.488 | X10: 36770 | Y10: 6806.56 | Z10: 8844.438
B11: 36678 | C11: 6499.389 | D11: 4982.053 | S11: 36678 | T11: 1435 | U11: 1683.167 | X11: 36800 | Y11: 7814.1 | Z11: 10525.95
B12: 36708 | C12: 4198.895 | D12: 6742.645 | S12: 36708 | T12: 690.1429 | U12: 1042.222 | X12: 36831 | Y12: 7042.556 | Z12: 9990.208
B13: 36739 | C13: 4338.314 | D13: 6731.129 | S13: 36739 | T13: 1876.8 | U13: 1389.054 | X13: 36861 | Y13: 6915.484 | Z13: 10437.57
B14: 36770 | C14: 5293.514 | D14: 7164.229 | S14: 36770 | T14: 1510.9 | U14: 830.8601 | X14: 36892 | Y14: 6669.065 | Z14: 10073.06
B15: 36800 | C15: 5715.089 | D15: 8276.968 | S15: 36800 | T15: 1517.067 | U15: 1853.784 | X15: 36923 | Y15: 8177.489 | Z15: 10652.57
B16: 36831 | C16: 6352.077 | D16: 8139.729 | S16: 36831 | T16: 4798.5 | U16: 2193.209 | X16: 36951 | Y16: 6652.076 | Z16: 9980.102
B17: 36861 | C17: 5559.848 | D17: 7723.156 | S17: 36861 | T17: 2758.2 | U17: 1323.792 | X17: 36982 | Y17: 7272.924 | Z17: 10084.59
B18: 36892 | C18: 5547.172 | D18: 8580.607 | S18: 36892 | T18: 1246.583 | U18: 1054.469 | X18: 37012 | Y18: 7408.824 | Z18: 10677.13
B19: 36923 | C19: 6236.135 | D19: 7917.641 | S19: 36923 | T19: 2856.741 | U19: 1740.741 | X19: 37043 | Y19: 6832.583 | Z19: 10032.6
... B178: 41760 | C178: 25875.2 | D178: 22141.81 | S178: 41760 | T178: 11354.56 | U178: 11314.32 | X178: 41883 | Y178: 28065.9 | Z178: 29174.44
B179: 41791 | C179: 23799.69 | D179: 21718.3 | S179: 41791 | T179: 9582.141 | U179: 11618.78
B180: 41821 | C180: 22809.42 | D180: 21938.42 | S180: 41821 | T180: 6693.002 | U180: 12078.98
B181: 41852 | C181: 20747.82 | D181: 21649.1 | S181: 41852 | T181: 12469.31 | U181: 16070.08
B182: 41883 | C182: 18554.98 | D182: 22687.92 | S182: 41883 | T182: 856.5183 | U182: 11817.09

Sheet Expenses v1
B1: Occup,loanpurpose,propertytype | S1: Occup,loanpurpose,propertytype, zeroBalanceCode | X1: simple without zeroBalanceCode
C2: aggActualExpenses | D2: aggEstimExpenses | T2: aggActualExpenses | U2: aggEstimExpenses | Y2: aggActualExpenses | Z2: aggEstimExpenses
B3: 36434 | C3: 1385 | D3: 4979.554 | S3: 36434 | T3: 1385 | U3: -645.564 | X3: 36434 | Y3: 1385 | Z3: 4970.767
B4: 36465 | C4: 2406 | D4: 3844.353 | S4: 36465 | T4: 2406 | U4: -2219.976 | X4: 36465 | Y4: 2406 | Z4: 3520.288
B5: 36495 | C5: 3163.75 | D5: 3712.237 | S5: 36495 | T5: 3163.75 | U5: -1316.501 | X5: 36495 | Y5: 3163.75 | Z5: 3619.116
B6: 36526 | C6: 1052 | D6: 2912.919 | S6: 36526 | T6: 1052 | U6: -3160.052 | X6: 36526 | Y6: 1052 | Z6: 2512.975
B7: 36557 | C7: 2202 | D7: 5333.942 | S7: 36557 | T7: 2202 | U7: 3089.047 | X7: 36557 | Y7: 2202 | Z7: 5679.442
B8: 36586 | C8: 2126 | D8: 4748.717 | S8: 36586 | T8: 2126 | U8: -509.1292 | X8: 36586 | Y8: 2126 | Z8: 4537.481
B9: 36617 | C9: 3862.158 | D9: 6188.439 | S9: 36617 | T9: 3862.158 | U9: 3447.014 | X9: 36617 | Y9: 3862.158 | Z9: 6041.903
B10: 36647 | C10: 2559.7 | D10: 5868.133 | S10: 36647 | T10: 2559.7 | U10: 1277.466 | X10: 36647 | Y10: 2559.7 | Z10: 5561.396
B11: 36678 | C11: 6499.389 | D11: 5651.823 | S11: 36678 | T11: 6499.389 | U11: 3935.378 | X11: 36678 | Y11: 6499.389 | Z11: 5621.234
B12: 36708 | C12: 4198.895 | D12: 6736.455 | S12: 36708 | T12: 4198.895 | U12: 6225.082 | X12: 36708 | Y12: 4198.895 | Z12: 6311.353
B13: 36739 | C13: 4338.314 | D13: 7054.969 | S13: 36739 | T13: 4338.314 | U13: 6124.389 | X13: 36739 | Y13: 4338.314 | Z13: 6495.376
B14: 36770 | C14: 5293.514 | D14: 6932.637 | S14: 36770 | T14: 5293.514 | U14: 7455.555 | X14: 36770 | Y14: 5293.514 | Z14: 6255.337
... B182: 41883 | C182: 18554.98 | D182: 24157.43 | S182: 41883 | T182: 18554.98 | U182: 22394.52 | X182: 41883 | Y182: 18554.98 | Z182: 24474.09

Sheet REO-FC
A1: Count | I1: TimeDQ
B2: FC | C2: REO | D2: Total | E2: FC% | F2: REO% | J2: FC | K2: REO | L2: Diff | N2: lossDate | O2: Total | Q2: lossDate | R2: FC | S2: TimeDQ | U2: lossDate | V2: REO | W2: TimeDQ
A3: 36434 | B3: =VLOOKUP(A3,Q:R,2,0) -> 2 | C3: =IF(ISNA(VLOOKUP(A3,U:V,2,0)),0,VLOOKUP(A3,U:V,2,0)) -> 0 | D3: =B3+C3 -> 2 | E3: =B3/D3 -> 1 | F3: =C3/D3 -> 0 | I3: 36434 | J3: =VLOOKUP(I3,Q:S,3,0) -> 6.5 | K3: =IF(ISNA(VLOOKUP(I3,U:W,3,0)),0,VLOOKUP(I3,U:W,3,0)) -> 0 | L3: =K3-J3 -> -6.5 | N3: 36434 | O3: 2 | Q3: 36434 | R3: 2 | S3: 6.5 | U3: 36557 | V3: 1 | W3: 9
A4: 36465 | B4: =VLOOKUP(A4,Q:R,2,0) -> 1 | C4: =IF(ISNA(VLOOKUP(A4,U:V,2,0)),0,VLOOKUP(A4,U:V,2,0)) -> 0 | D4: =B4+C4 -> 1 | E4: =B4/D4 -> 1 | F4: =C4/D4 -> 0 | I4: 36465 | J4: =VLOOKUP(I4,Q:S,3,0) -> 6 | K4: =IF(ISNA(VLOOKUP(I4,U:W,3,0)),0,VLOOKUP(I4,U:W,3,0)) -> 0 | L4: =K4-J4 -> -6 | N4: 36465 | O4: 1 | Q4: 36465 | R4: 1 | S4: 6 | U4: 36586 | V4: 1 | W4: 12
A5: 36495 | B5: =VLOOKUP(A5,Q:R,2,0) -> 4 | C5: =IF(ISNA(VLOOKUP(A5,U:V,2,0)),0,VLOOKUP(A5,U:V,2,0)) -> 0 | D5: =B5+C5 -> 4 | E5: =B5/D5 -> 1 | F5: =C5/D5 -> 0 | I5: 36495 | J5: =VLOOKUP(I5,Q:S,3,0) -> 5.25 | K5: =IF(ISNA(VLOOKUP(I5,U:W,3,0)),0,VLOOKUP(I5,U:W,3,0)) -> 0 | L5: =K5-J5 -> -5.25 | N5: 36495 | O5: 4 | Q5: 36495 | R5: 4 | S5: 5.25 | U5: 36617 | V5: 7 | W5: 11.57
A6: 36526 | B6: =VLOOKUP(A6,Q:R,2,0) -> 2 | C6: =IF(ISNA(VLOOKUP(A6,U:V,2,0)),0,VLOOKUP(A6,U:V,2,0)) -> 0 | D6: =B6+C6 -> 2 | E6: =B6/D6 -> 1 | F6: =C6/D6 -> 0 | I6: 36526 | J6: =VLOOKUP(I6,Q:S,3,0) -> 6 | K6: =IF(ISNA(VLOOKUP(I6,U:W,3,0)),0,VLOOKUP(I6,U:W,3,0)) -> 0 | L6: =K6-J6 -> -6 | N6: 36526 | O6: 2 | Q6: 36526 | R6: 2 | S6: 6 | U6: 36647 | V6: 2 | W6: 10.5
A7: 36557 | B7: =VLOOKUP(A7,Q:R,2,0) -> 3 | C7: =IF(ISNA(VLOOKUP(A7,U:V,2,0)),0,VLOOKUP(A7,U:V,2,0)) -> 1 | D7: =B7+C7 -> 4 | E7: =B7/D7 -> 0.75 | F7: =C7/D7 -> 0.25 | I7: 36557 | J7: =VLOOKUP(I7,Q:S,3,0) -> 7.5 | K7: =IF(ISNA(VLOOKUP(I7,U:W,3,0)),0,VLOOKUP(I7,U:W,3,0)) -> 9 | L7: =K7-J7 -> 1.5 | N7: 36557 | O7: 4 | Q7: 36557 | R7: 3 | S7: 7.5 | U7: 36678 | V7: 9 | W7: 10.89
A8: 36586 | B8: =VLOOKUP(A8,Q:R,2,0) -> 7 | C8: =IF(ISNA(VLOOKUP(A8,U:V,2,0)),0,VLOOKUP(A8,U:V,2,0)) -> 1 | D8: =B8+C8 -> 8 | E8: =B8/D8 -> 0.875 | F8: =C8/D8 -> 0.125 | I8: 36586 | J8: =VLOOKUP(I8,Q:S,3,0) -> 7.14 | K8: =IF(ISNA(VLOOKUP(I8,U:W,3,0)),0,VLOOKUP(I8,U:W,3,0)) -> 12 | L8: =K8-J8 -> 4.86 | N8: 36586 | O8: 8 | Q8: 36586 | R8: 7 | S8: 7.14 | U8: 36708 | V8: 12 | W8: 12.25
A9: 36617 | B9: =VLOOKUP(A9,Q:R,2,0) -> 12 | C9: =IF(ISNA(VLOOKUP(A9,U:V,2,0)),0,VLOOKUP(A9,U:V,2,0)) -> 7 | D9: =B9+C9 -> 19 | E9: =B9/D9 -> 0.63157895 | F9: =C9/D9 -> 0.36842105 | I9: 36617 | J9: =VLOOKUP(I9,Q:S,3,0) -> 7.42 | K9: =IF(ISNA(VLOOKUP(I9,U:W,3,0)),0,VLOOKUP(I9,U:W,3,0)) -> 11.57 | L9: =K9-J9 -> 4.15 | N9: 36617 | O9: 19 | Q9: 36617 | R9: 12 | S9: 7.42 | U9: 36739 | V9: 20 | W9: 12.15
A10: 36647 | B10: =VLOOKUP(A10,Q:R,2,0) -> 8 | C10: =IF(ISNA(VLOOKUP(A10,U:V,2,0)),0,VLOOKUP(A10,U:V,2,0)) -> 2 | D10: =B10+C10 -> 10 | E10: =B10/D10 -> 0.8 | F10: =C10/D10 -> 0.2 | I10: 36647 | J10: =VLOOKUP(I10,Q:S,3,0) -> 8.5 | K10: =IF(ISNA(VLOOKUP(I10,U:W,3,0)),0,VLOOKUP(I10,U:W,3,0)) -> 10.5 | L10: =K10-J10 -> 2 | N10: 36647 | O10: 10 | Q10: 36647 | R10: 8 | S10: 8.5 | U10: 36770 | V10: 25 | W10: 11.76
A11: 36678 | B11: =VLOOKUP(A11,Q:R,2,0) -> 9 | C11: =IF(ISNA(VLOOKUP(A11,U:V,2,0)),0,VLOOKUP(A11,U:V,2,0)) -> 9 | D11: =B11+C11 -> 18 | E11: =B11/D11 -> 0.5 | F11: =C11/D11 -> 0.5 | I11: 36678 | J11: =VLOOKUP(I11,Q:S,3,0) -> 8.44 | K11: =IF(ISNA(VLOOKUP(I11,U:W,3,0)),0,VLOOKUP(I11,U:W,3,0)) -> 10.89 | L11: =K11-J11 -> 2.45 | N11: 36678 | O11: 18 | Q11: 36678 | R11: 9 | S11: 8.44 | U11: 36800 | V11: 30 | W11: 12.43
A12: 36708 | B12: =VLOOKUP(A12,Q:R,2,0) -> 7 | C12: =IF(ISNA(VLOOKUP(A12,U:V,2,0)),0,VLOOKUP(A12,U:V,2,0)) -> 12 | D12: =B12+C12 -> 19 | E12: =B12/D12 -> 0.36842105 | F12: =C12/D12 -> 0.63157895 | I12: 36708 | J12: =VLOOKUP(I12,Q:S,3,0) -> 7.14 | K12: =IF(ISNA(VLOOKUP(I12,U:W,3,0)),0,VLOOKUP(I12,U:W,3,0)) -> 12.25 | L12: =K12-J12 -> 5.11 | N12: 36708 | O12: 19 | Q12: 36708 | R12: 7 | S12: 7.14 | U12: 36831 | V12: 36 | W12: 12.61
A13: 36739 | B13: =VLOOKUP(A13,Q:R,2,0) -> 16 | C13: =IF(ISNA(VLOOKUP(A13,U:V,2,0)),0,VLOOKUP(A13,U:V,2,0)) -> 20 | D13: =B13+C13 -> 36 | E13: =B13/D13 -> 0.44444444 | F13: =C13/D13 -> 0.55555556 | I13: 36739 | J13: =VLOOKUP(I13,Q:S,3,0) -> 7.33 | K13: =IF(ISNA(VLOOKUP(I13,U:W,3,0)),0,VLOOKUP(I13,U:W,3,0)) -> 12.15 | L13: =K13-J13 -> 4.82 | N13: 36739 | O13: 36 | Q13: 36739 | R13: 16 | S13: 7.33 | U13: 36861 | V13: 31 | W13: 12.9
A14: 36770 | B14: =VLOOKUP(A14,Q:R,2,0) -> 10 | C14: =IF(ISNA(VLOOKUP(A14,U:V,2,0)),0,VLOOKUP(A14,U:V,2,0)) -> 25 | D14: =B14+C14 -> 35 | E14: =B14/D14 -> 0.28571429 | F14: =C14/D14 -> 0.71428571 | I14: 36770 | J14: =VLOOKUP(I14,Q:S,3,0) -> 5.7 | K14: =IF(ISNA(VLOOKUP(I14,U:W,3,0)),0,VLOOKUP(I14,U:W,3,0)) -> 11.76 | L14: =K14-J14 -> 6.06 | N14: 36770 | O14: 35 | Q14: 36770 | R14: 10 | S14: 5.7 | U14: 36892 | V14: 47 | W14: 13
... A178: 41760 | B178: =VLOOKUP(A178,Q:R,2,0) -> 1399 | C178: =IF(ISNA(VLOOKUP(A178,U:V,2,0)),0,VLOOKUP(A178,U:V,2,0)) -> 3183 | D178: =B178+C178 -> 4582 | E178: =B178/D178 -> 0.30532519 | F178: =C178/D178 -> 0.69467481 | I178: 41760 | J178: =VLOOKUP(I178,Q:S,3,0) -> 25.34 | K178: =IF(ISNA(VLOOKUP(I178,U:W,3,0)),0,VLOOKUP(I178,U:W,3,0)) -> 33.01 | L178: =K178-J178 -> 7.67 | N178: 41760 | O178: 4582 | Q178: 41760 | R178: 1399 | S178: 25.34 | U178: 41883 | V178: 2434 | W178: 35.35
A179: 41791 | B179: =VLOOKUP(A179,Q:R,2,0) -> 1465 | C179: =IF(ISNA(VLOOKUP(A179,U:V,2,0)),0,VLOOKUP(A179,U:V,2,0)) -> 2832 | D179: =B179+C179 -> 4297 | E179: =B179/D179 -> 0.34093554 | F179: =C179/D179 -> 0.65906446 | I179: 41791 | J179: =VLOOKUP(I179,Q:S,3,0) -> 26.05 | K179: =IF(ISNA(VLOOKUP(I179,U:W,3,0)),0,VLOOKUP(I179,U:W,3,0)) -> 33.34 | L179: =K179-J179 -> 7.29 | N179: 41791 | O179: 4297 | Q179: 41791 | R179: 1465 | S179: 26.05
A180: 41821 | B180: =VLOOKUP(A180,Q:R,2,0) -> 1518 | C180: =IF(ISNA(VLOOKUP(A180,U:V,2,0)),0,VLOOKUP(A180,U:V,2,0)) -> 2811 | D180: =B180+C180 -> 4329 | E180: =B180/D180 -> 0.35065835 | F180: =C180/D180 -> 0.64934165 | I180: 41821 | J180: =VLOOKUP(I180,Q:S,3,0) -> 26.97 | K180: =IF(ISNA(VLOOKUP(I180,U:W,3,0)),0,VLOOKUP(I180,U:W,3,0)) -> 33.69 | L180: =K180-J180 -> 6.72 | N180: 41821 | O180: 4329 | Q180: 41821 | R180: 1518 | S180: 26.97
A181: 41852 | B181: =VLOOKUP(A181,Q:R,2,0) -> 2717 | C181: =IF(ISNA(VLOOKUP(A181,U:V,2,0)),0,VLOOKUP(A181,U:V,2,0)) -> 2641 | D181: =B181+C181 -> 5358 | E181: =B181/D181 -> 0.5070922 | F181: =C181/D181 -> 0.4929078 | I181: 41852 | J181: =VLOOKUP(I181,Q:S,3,0) -> 34.75 | K181: =IF(ISNA(VLOOKUP(I181,U:W,3,0)),0,VLOOKUP(I181,U:W,3,0)) -> 33.85 | L181: =K181-J181 -> -0.9 | N181: 41852 | O181: 5358 | Q181: 41852 | R181: 2717 | S181: 34.75
A182: 41883 | B182: =VLOOKUP(A182,Q:R,2,0) -> 1312 | C182: =IF(ISNA(VLOOKUP(A182,U:V,2,0)),0,VLOOKUP(A182,U:V,2,0)) -> 2434 | D182: =B182+C182 -> 3746 | E182: =B182/D182 -> 0.35024026 | F182: =C182/D182 -> 0.64975974 | I182: 41883 | J182: =VLOOKUP(I182,Q:S,3,0) -> 26.52 | K182: =IF(ISNA(VLOOKUP(I182,U:W,3,0)),0,VLOOKUP(I182,U:W,3,0)) -> 35.35 | L182: =K182-J182 -> 8.83 | N182: 41883 | O182: 3746 | Q182: 41883 | R182: 1312 | S182: 26.52

Sheet MI & nonMI
B2: lossDate | C2: cnt | D2: nonMIRecoveries | E2: MIRecoveries | F2: Actual Loss | G2: Ratio
B3: 36434 | C3: 2 | D3: 1401.5 | E3: 3062 | G3: =D3/E3 -> 0.45770738
B4: 36465 | C4: 1 | D4: 158 | E4: 8128 | G4: =D4/E4 -> 0.019438976
B5: 36495 | C5: 4 | D5: 752.5 | E5: 17603.5 | G5: =D5/E5 -> 0.042747181
B6: 36526 | C6: 2 | D6: 114.5 | E6: 8035 | F6: 0 | G6: =D6/E6 -> 0.014250156
B7: 36557 | C7: 4 | D7: 661.25 | E7: 7739 | F7: 3623.4 | G7: =D7/E7 -> 0.085443856
B8: 36586 | C8: 8 | D8: 10456.88 | E8: 12600 | F8: 53.38 | G8: =D8/E8 -> 0.82991111
B9: 36617 | C9: 19 | D9: 11190.47 | E9: 18266 | F9: 5903.51 | G9: =D9/E9 -> 0.61263933
B10: 36647 | C10: 10 | D10: 222 | E10: 19761.3 | F10: 1600.54 | G10: =D10/E10 -> 0.011234079
B11: 36678 | C11: 18 | D11: 11874.94 | E11: 18597.89 | F11: 2867.01 | G11: =D11/E11 -> 0.63851007
B12: 36708 | C12: 19 | D12: 2468.37 | E12: 22673.74 | F12: 2349.27 | G12: =D12/E12 -> 0.1088647
B13: 36739 | C13: 36 | D13: 35001.14 | E13: 15665.67 | F13: 2405.43 | G13: =D13/E13 -> 2.2342575
B14: 36770 | C14: 35 | D14: 19034.74 | E14: 27266.03 | F14: 2105.04 | G14: =D14/E14 -> 0.6981119
B15: 36800 | C15: 45 | D15: 29646.04 | E15: 24188.13 | F15: 2543.46 | G15: =D15/E15 -> 1.2256441
B16: 36831 | C16: 52 | D16: 19261.23 | E16: 24484.08 | F16: 3968.72 | G16: =D16/E16 -> 0.78668384
B17: 36861 | C17: 47 | D17: 21175.64 | E17: 15051.17 | F17: 6185.85 | G17: =D17/E17 -> 1.4069099
... B182: 41883 | C182: 3746 | D182: 2191.84 | E182: 6311.21 | F182: 111133.36 | G182: =D182/E182 -> 0.34729315

Sheet MI by LTV
A1: OLTV | B1: pctMtgIns | C1: ActualMIPct | N1: OLTV | O1: pctMtgIns | P1: ActualMIPct | AB1: OLTV | AC1: pctMtgIns | AD1: ActualMIPct | AF1: MI recoveries/UPB
A2: 81 | B2: 12.29 | C2: 4.45 | N2: 81 | O2: 12.51 | P2: 4.5 | AB2: 81 | AC2: 12.51 | AD2: 5.6
A3: 82 | B3: 12.39 | C3: 6.05 | N3: 82 | O3: 12.54 | P3: 6.15 | AB3: 82 | AC3: 12.54 | AD3: 7.54
A4: 83 | B4: 12.39 | C4: 6.86 | N4: 83 | O4: 12.44 | P4: 6.87 | AB4: 83 | AC4: 12.44 | AD4: 8.44
A5: 84 | B5: 12.46 | C5: 7.35 | N5: 84 | O5: 12.5 | P5: 7.5 | AB5: 84 | AC5: 12.5 | AD5: 9.25
A6: 85 | B6: 12.5 | C6: 8.19 | N6: 85 | O6: 12.51 | P6: 8.32 | AB6: 85 | AC6: 12.51 | AD6: 10.27
A7: 86 | B7: 24.04 | C7: 15.79 | N7: 86 | O7: 24.09 | P7: 16.07 | AB7: 86 | AC7: 24.09 | AD7: 19.94
A8: 87 | B8: 24.13 | C8: 16.01 | N8: 87 | O8: 24.13 | P8: 16.24 | AB8: 87 | AC8: 24.13 | AD8: 20.21
A9: 88 | B9: 24.2 | C9: 16.67 | N9: 88 | O9: 24.24 | P9: 16.9 | AB9: 88 | AC9: 24.24 | AD9: 20.89
A10: 89 | B10: 24.28 | C10: 17.14 | N10: 89 | O10: 24.32 | P10: 17.34 | AB10: 89 | AC10: 24.32 | AD10: 21.52
A11: 90 | B11: 24.41 | C11: 16.88 | N11: 90 | O11: 24.42 | P11: 17.14 | AB11: 90 | AC11: 24.42 | AD11: 21.28
A12: 91 | B12: 28.96 | C12: 20.42 | N12: 91 | O12: 29.12 | P12: 21.04 | AB12: 91 | AC12: 29.12 | AD12: 25.96
A13: 92 | B13: 28.86 | C13: 20.64 | N13: 92 | O13: 28.96 | P13: 21.09 | AB13: 92 | AC13: 28.96 | AD13: 26.03
... A23: 104 | B23: 35 | C23: 52.04 | N23: 104 | O23: 35 | P23: 52.04 | AB23: 104 | AC23: 35 | AD23: 68.08
A30: REOEndYear | B30: pctMtgIns | C30: ActualMIPct | O30: pctMtgIns | P30: ActualMIPct
A31: 2000 | B31: 24 | C31: 22.59 | N31: 2000 | O31: 25.92 | P31: 40.47
A32: 2001 | B32: 19.72 | C32: 16.75 | N32: 2001 | O32: 25.12 | P32: 31.16
A33: 2002 | B33: 19.11 | C33: 16.67 | N33: 2002 | O33: 25.12 | P33: 25.82
A34: 2003 | B34: 18.69 | C34: 14.39 | N34: 2003 | O34: 25.71 | P34: 21.34
A35: 2004 | B35: 18.66 | C35: 14.36 | N35: 2004 | O35: 25.7 | P35: 21.11
A36: 2005 | B36: 18.05 | C36: 11.93 | N36: 2005 | O36: 25.37 | P36: 18.68
A37: 2006 | B37: 16.62 | C37: 11.79 | N37: 2006 | O37: 25.17 | P37: 19.4
A38: 2007 | B38: 14.65 | C38: 10.66 | N38: 2007 | O38: 25.64 | P38: 20.42
A39: 2008 | B39: 12.46 | C39: 9.68 | N39: 2008 | O39: 26.09 | P39: 21.4
A40: 2009 | B40: 11.09 | C40: 7.4 | N40: 2009 | O40: 26.45 | P40: 17.83
A41: 2010 | B41: 10.03 | C41: 6.82 | N41: 2010 | O41: 26.2 | P41: 17.97
A42: 2011 | B42: 9.55 | C42: 6.69 | N42: 2011 | O42: 25.87 | P42: 18.2
... A45: 2014 | B45: 8.35 | C45: 5.15 | N45: 2014 | O45: 25.34 | P45: 15.57
B61: pctMtgIns | C61: ActualMI/Claim Amount | D61: ActualMI/UPB
A62: 81 | B62: 12.51 | C62: 4.5 | D62: 5.6
A63: 82 | B63: 12.54 | C63: 6.15 | D63: 7.54
A64: 83 | B64: 12.44 | C64: 6.87 | D64: 8.44
A65: 84 | B65: 12.5 | C65: 7.5 | D65: 9.25
A66: 85 | B66: 12.51 | C66: 8.32 | D66: 10.27
A67: 86 | B67: 24.09 | C67: 16.07 | D67: 19.94
A68: 87 | B68: 24.13 | C68: 16.24 | D68: 20.21
A69: 88 | B69: 24.24 | C69: 16.9 | D69: 20.89
A70: 89 | B70: 24.32 | C70: 17.34 | D70: 21.52
A71: 90 | B71: 24.42 | C71: 17.14 | D71: 21.28
A72: 91 | B72: 29.12 | C72: 21.04 | D72: 25.96
...

Sheet Servicer
A1: origServicer | B1: Severity | C1: TimeDQ | D1: cnt
A2: QUICKENLOANINC | B2: 19.36 | C2: 11.33 | D2: 6
A3: WASHINGTONMUTUALHOME | B3: 3.21 | C3: 12 | D3: 2
A4: FTMTGESERVICES,INC | B4: 6.45 | C4: 13.37 | D4: 254
A5: UNIONSAVINGSBANK | B5: 31.96 | C5: 13.4 | D5: 5
A6: CENDANTMTGECORPORATI | B6: 8.2 | C6: 13.48 | D6: 42
A7: PRINCIPALRESIDENTIAL | B7: 9.61 | C7: 13.63 | D7: 1419
A8: REGIONSBANKDBAREGION | B8: 23.97 | C8: 14.14 | D8: 43
A9: WELLSFARGOHOMEMORTGA | B9: 7.22 | C9: 14.17 | D9: 4431
A10: HOMESIDELENDING,INC | B10: 7.52 | C10: 14.18 | D10: 124
A11: BAMORTGAGE,LLC | B11: 9 | C11: 14.85 | D11: 201
A12: LAKEVIEWLOANSERVICIN | B12: 42.09 | C12: 15.01 | D12: 262
A13: PROVIDENTFUNDINGASSO | B13: 41.76 | C13: 15.04 | D13: 4114
... A46: NATIONSTARMTGELLC | B46: 54.63 | C46: 28.12 | D46: 7415

Sheet Total v1
B1: aggActuralBaseLoss | C1: aggEstimBassLoss | D1: aggActualExpenses | E1: aggEstimExpenses | F1: aggEstimInterest | G1: aggActualMIRecoveries | H1: aggEstimMIRecoveries | J1: aggActuralTotalLoss | K1: aggEstimTotalLoss | L1: Loss with NonMI | P1: aggActuralTotalSeverity | Q1: aggEstimTotalSeverity
A2: 36526 | B2: 6708.202 | C2: 20774.53 | D2: 1232.722 | E2: 2800.021 | F2: 1978.763 | G2: 9780.316 | H2: 17359.61 | I2: 36526 | J2: 0 | K2: 6626.404 | L2: =K2-VLOOKUP(I2,'MI & nonMI'!B:E,3,0) -> 6511.904 | O2: 36526 | P2: 0 | Q2: 0.09435984
A3: 36557 | B3: 8969.988 | C3: 41181.27 | D3: 2744.83 | E3: 8447.687 | F3: 6239.021 | G3: 11854.4 | H3: 2457.616 | I3: 36557 | J3: 4998.631 | K3: 47707.51 | L3: =K3-VLOOKUP(I3,'MI & nonMI'!B:E,3,0) -> 47046.26 | O3: 36557 | P3: 0.02948317 | Q3: 0.3260881
A4: 36586 | B4: 15881.03 | C4: 31819.17 | D4: 2269.82 | E4: 4779.726 | F4: 6444.495 | G4: 15302.97 | H4: 23053.17 | I4: 36586 | J4: -30.67917 | K4: 17480.31 | L4: =K4-VLOOKUP(I4,'MI & nonMI'!B:E,3,0) -> 7023.43 | O4: 36586 | P4: 0.0004709797 | Q4: 0.1753352
A5: 36617 | B5: 22419.09 | C5: 36526.18 | D5: 3886.187 | E5: 6276.043 | F5: 7397.871 | G5: 15379.61 | H5: 19042.62 | I5: 36617 | J5: 10459.44 | K5: 28767.62 | L5: =K5-VLOOKUP(I5,'MI & nonMI'!B:E,3,0) -> 17577.15 | O5: 36617 | P5: 0.045121 | Q5: 0.2161571
A6: 36647 | B6: 13292.85 | C6: 34592.63 | D6: 2344.642 | E6: 4856.641 | F6: 5723.476 | G6: 20386.21 | H6: 26590.04 | I6: 36647 | J6: 720.4012 | K6: 16070.71 | L6: =K6-VLOOKUP(I6,'MI & nonMI'!B:E,3,0) -> 15848.71 | O6: 36647 | P6: 0.01387627 | Q6: 0.1697531
A7: 36678 | B7: 21393.84 | C7: 36540.82 | D7: 7213.898 | E7: 7218.069 | F7: 6039.075 | G7: 19997.31 | H7: 18449.72 | I7: 36678 | J7: 1732.507 | K7: 31344.07 | L7: =K7-VLOOKUP(I7,'MI & nonMI'!B:E,3,0) -> 19469.13 | O7: 36678 | P7: 0.02966631 | Q7: 0.3063542
A8: 36708 | B8: 16778.07 | C8: 41134.09 | D8: 4691.98 | E8: 9000.816 | F8: 7503.704 | G8: 25157.12 | H8: 24768.16 | I8: 36708 | J8: 1839.4 | K8: 28561.61 | L8: =K8-VLOOKUP(I8,'MI & nonMI'!B:E,3,0) -> 26093.24 | O8: 36708 | P8: 0.02148766 | Q8: 0.2351386
A9: 36739 | B9: 54609.25 | C9: 41805.44 | D9: 4841.886 | E9: 8983.472 | F9: 8007.592 | G9: 17237.63 | H9: 30637.34 | I9: 36739 | J9: 2932.204 | K9: 24017.58 | L9: =K9-VLOOKUP(I9,'MI & nonMI'!B:E,3,0) -> -10983.56 | O9: 36739 | P9: 0.02018762 | Q9: 0.2034104
A10: 36770 | B10: 45625.43 | C10: 40045.4 | D10: 5297.55 | E10: 8919.124 | F10: 7567.798 | G10: 32437.81 | H10: 31605.56 | I10: 36770 | J10: 1115.638 | K10: 21305.2 | L10: =K10-VLOOKUP(I10,'MI & nonMI'!B:E,3,0) -> 2270.46 | O10: 36770 | P10: 0.01829494 | Q10: 0.1897252
A11: 36800 | B11: 43629.78 | C11: 42470.54 | D11: 6200.351 | E11: 10196.29 | F11: 10166.51 | G11: 27738.23 | H11: 39060.48 | I11: 36800 | J11: 2423.917 | K11: 19776.92 | L11: =K11-VLOOKUP(I11,'MI & nonMI'!B:E,3,0) -> -9869.12 | O11: 36800 | P11: 0.01892464 | Q11: 0.162968
A12: 36831 | B12: 42343.8 | C12: 38738.89 | D12: 6599.745 | E12: 9910.887 | F12: 9051.154 | G12: 33006.59 | H12: 31523.76 | I12: 36831 | J12: 3609.724 | K12: 22866.02 | L12: =K12-VLOOKUP(I12,'MI & nonMI'!B:E,3,0) -> 3604.79 | O12: 36831 | P12: 0.03217558 | Q12: 0.1937356
A13: 36861 | B13: 35630.35 | C13: 37335.76 | D13: 5779.823 | E13: 9828.161 | F13: 8674.147 | G13: 17108.03 | H13: 21354.88 | I13: 36861 | J13: 7223.608 | K13: 30434.85 | L13: =K13-VLOOKUP(I13,'MI & nonMI'!B:E,3,0) -> 9259.21 | O13: 36861 | P13: 0.05497331 | Q13: 0.2647751
... A178: 41883 | B178: 99806.55 | C178: 58240 | D178: 21049.85 | E178: 25525.65 | F178: 34448.14 | G178: 7599.122 | H178: 14853.21 | I178: 41883 | J178: 145046.2 | K178: 98884.78 | L178: =K178-VLOOKUP(I178,'MI & nonMI'!B:E,3,0) -> 96692.94 | O178: 41883 | P178: 0.733733 | Q178: 0.5344574

Sheet HPA
A1: RegionType | B1: Region | C1: Year | D1: Quarter | E1: asOf | F1: NSAIndex | G1: TwoYearAVG | H1: % changes | W1: asof | X1: avg(#HPA_MA.HPA_2YR) | Y1: % changes | Z1: avg(#HPA_MA.HPA_2YR) | AA1: % changes
A2: USA | B2: USA | C2: 1991 | D2: 1 | E2: 33239 | W2: 36526 | X2: 1.0934144 | Y2: =VLOOKUP(W2,E:H,4,0)+1 -> 1.4837986 | Z2: =-X2 -> -1.0934144 | AA2: =-Y2 -> -1.4837986
A3: USA | B3: USA | C3: 1991 | D3: 1 | E3: 33270 | W3: 36557 | X3: 1.0944393 | Y3: =VLOOKUP(W3,E:H,4,0)+1 -> 1.4901134 | Z3: =-X3 -> -1.0944393 | AA3: =-Y3 -> -1.4901134
A4: USA | B4: USA | C4: 1991 | D4: 1 | E4: 33298 | F4: 100 | G4: 100 | W4: 36586 | X4: 1.0954601 | Y4: =VLOOKUP(W4,E:H,4,0)+1 -> 1.496325 | Z4: =-X4 -> -1.0954601 | AA4: =-Y4 -> -1.496325
A5: USA | B5: USA | C5: 1991 | D5: 2 | E5: 33329 | F5: 100.17 | G5: 100.085 | H5: =(G5-G4)/G4*100 -> 0.085 | W5: 36617 | X5: 1.0982835 | Y5: =VLOOKUP(W5,E:H,4,0)+1 -> 1.5171804 | Z5: =-X5 -> -1.0982835 | AA5: =-Y5 -> -1.5171804
A6: USA | B6: USA | C6: 1991 | D6: 2 | E6: 33359 | F6: 100.34 | G6: 100.17 | H6: =(G6-G5)/G5*100 -> 0.084927811 | W6: 36647 | X6: 1.1010991 | Y6: =VLOOKUP(W6,E:H,4,0)+1 -> 1.5225219 | Z6: =-X6 -> -1.1010991 | AA6: =-Y6 -> -1.5225219
A7: USA | B7: USA | C7: 1991 | D7: 2 | E7: 33390 | F7: 100.51 | G7: 100.255 | H7: =(G7-G6)/G6*100 -> 0.084855745 | W7: 36678 | X7: 1.1039069 | Y7: =VLOOKUP(W7,E:H,4,0)+1 -> 1.5277667 | Z7: =-X7 -> -1.1039069 | AA7: =-Y7 -> -1.5277667
A8: USA | B8: USA | C8: 1991 | D8: 3 | E8: 33420 | F8: 100.60333 | G8: 100.32467 | H8: =(G8-G7)/G7*100 -> 0.069489469 | W8: 36708 | X8: 1.1053827 | Y8: =VLOOKUP(W8,E:H,4,0)+1 -> 1.5218486 | Z8: =-X8 -> -1.1053827 | AA8: =-Y8 -> -1.5218486
A9: USA | B9: USA | C9: 1991 | D9: 3 | E9: 33451 | F9: 100.69667 | G9: 100.38667 | H9: =(G9-G8)/G8*100 -> 0.061799358 | W9: 36739 | X9: 1.1068514 | Y9: =VLOOKUP(W9,E:H,4,0)+1 -> 1.5257045 | Z9: =-X9 -> -1.1068514 | AA9: =-Y9 -> -1.5257045
A10: USA | B10: USA | C10: 1991 | D10: 3 | E10: 33482 | F10: 100.79 | G10: 100.44429 | H10: =(G10-G9)/G9*100 -> 0.057397112 | W10: 36770 | X10: 1.1083129 | Y10: =VLOOKUP(W10,E:H,4,0)+1 -> 1.5294859 | Z10: =-X10 -> -1.1083129 | AA10: =-Y10 -> -1.5294859
A11: USA | B11: USA | C11: 1991 | D11: 4 | E11: 33512 | F11: 101.01333 | G11: 100.51542 | H11: =(G11-G10)/G10*100 -> 0.070816326 | W11: 36800 | X11: 1.1097112 | Y11: =VLOOKUP(W11,E:H,4,0)+1 -> 1.5246983 | Z11: =-X11 -> -1.1097112 | AA11: =-Y11 -> -1.5246983
A12: USA | B12: USA | C12: 1991 | D12: 4 | E12: 33543 | F12: 101.23667 | G12: 100.59556 | H12: =(G12-G11)/G11*100 -> 0.079727958 | W12: 36831 | X12: 1.1111025 | Y12: =VLOOKUP(W12,E:H,4,0)+1 -> 1.5252405 | Z12: =-X12 -> -1.1111025 | AA12: =-Y12 -> -1.5252405
A13: USA | B13: USA | C13: 1991 | D13: 4 | E13: 33573 | F13: 101.46 | G13: 100.682 | H13: =(G13-G12)/G12*100 -> 0.085932668 | W13: 36861 | X13: 1.1124868 | Y13: =VLOOKUP(W13,E:H,4,0)+1 -> 1.5257599 | Z13: =-X13 -> -1.1124868 | AA13: =-Y13 -> -1.5257599
A14: USA | B14: USA | C14: 1992 | D14: 1 | E14: 33604 | F14: 101.73 | G14: 100.77727 | H14: =(G14-G13)/G13*100 -> 0.094627369 | W14: 36892 | X14: 1.1175389 | Y14: =VLOOKUP(W14,E:H,4,0)+1 -> 1.5339307 | Z14: =-X14 -> -1.1175389 | AA14: =-Y14 -> -1.5339307
A15: USA | B15: USA | C15: 1992 | D15: 1 | E15: 33635 | F15: 102 | G15: 100.87917 | H15: =(G15-G14)/G14*100 -> 0.10110805 | W15: 36923 | X15: 1.1225612 | Y15: =VLOOKUP(W15,E:H,4,0)+1 -> 1.5379454 | Z15: =-X15 -> -1.1225612 | AA15: =-Y15 -> -1.5379454
A16: USA | B16: USA | C16: 1992 | D16: 1 | E16: 33664 | F16: 102.27 | G16: 100.98615 | H16: =(G16-G15)/G15*100 -> 0.10605478 | W16: 36951 | X16: 1.127554 | Y16: =VLOOKUP(W16,E:H,4,0)+1 -> 1.5418806 | Z16: =-X16 -> -1.127554 | AA16: =-Y16 -> -1.5418806
... A192: USA | B192: USA | C192: 2006 | D192: 4 | E192: 39022 | F192: 223.88 | G192: 213.612 | H192: =(G192-G191)/G191*100 -> 0.5463843 | W192: 42309 | X192: 1.0761138 | Y192: =VLOOKUP(W192,E:H,4,0)+1 -> #N/A | Z192: =-X192 -> -1.0761138 | AA192: =-Y192 -> #N/A
A193: USA | B193: USA | C193: 2006 | D193: 4 | E193: 39052 | F193: 223.56 | G193: 214.718 | H193: =(G193-G192)/G192*100 -> 0.51776117
A194: USA | B194: USA | C194: 2007 | D194: 1 | E194: 39083 | F194: 223.71333 | G194: 215.78813 | H194: =(G194-G193)/G193*100 -> 0.49839014
A195: USA | B195: USA | C195: 2007 | D195: 1 | E195: 39114 | F195: 223.86667 | G195: 216.8092 | H195: =(G195-G194)/G194*100 -> 0.47318017
A196: USA | B196: USA | C196: 2007 | D196: 1 | E196: 39142 | F196: 224.02 | G196: 217.7812 | H196: =(G196-G195)/G195*100 -> 0.44832046
A197: USA | B197: USA | C197: 2007 | D197: 2 | E197: 39173 | F197: 224.86667 | G197: 218.73187 | H197: =(G197-G196)/G196*100 -> 0.43652375
A198: USA | B198: USA | C198: 2007 | D198: 2 | E198: 39203 | F198: 225.71333 | G198: 219.61587 | H198: =(G198-G197)/G197*100 -> 0.40414779
A199: USA | B199: USA | C199: 2007 | D199: 2 | E199: 39234 | F199: 226.56 | G199: 220.4332 | H199: =(G199-G198)/G198*100 -> 0.37216497
A200: USA | B200: USA | C200: 2007 | D200: 3 | E200: 39264 | F200: 225.69667 | G200: 221.11547 | H200: =(G200-G199)/G199*100 -> 0.30951176
A201: USA | B201: USA | C201: 2007 | D201: 3 | E201: 39295 | F201: 224.83333 | G201: 221.68653 | H201: =(G201-G200)/G200*100 -> 0.25826627
A202: USA | B202: USA | C202: 2007 | D202: 3 | E202: 39326 | F202: 223.97 | G202: 222.1464 | H202: =(G202-G201)/G201*100 -> 0.20744005
A203: USA | B203: USA | C203: 2007 | D203: 4 | E203: 39356 | F203: 221.98 | G203: 222.45 | H203: =(G203-G202)/G202*100 -> 0.13666663
A204: USA | B204: USA | C204: 2007 | D204: 4 | E204: 39387 | F204: 219.99 | G204: 222.63867 | H204: =(G204-G203)/G203*100 -> 0.084813067
... A295: USA | B295: USA | C295: 2015 | D295: 2 | E295: 42156 | F295: 222.58 | G295: 209.6236 | H295: =(G295-G294)/G294*100 -> 0.4872315

Sheet Total v2
B1: aggActuralBaseLoss | C1: aggEstimBassLoss | D1: aggActualExpenses | E1: aggEstimExpenses | F1: aggEstimInterest | G1: aggActualMIRecoveries | H1: aggEstimMIRecoveries | I1: aggActuralTotalLoss | J1: aggEstimTotalLoss | K1: aggActuralTotalSeverity | L1: aggEstimTotalSeverity
A2: 36526 | B2: 6708.2022 | C2: 15070.072 | D2: 1232.7222 | E2: 101.88959 | F2: 1978.7634 | G2: 9780.3157 | H2: 17850.674 | I2: 0 | J2: 430.88404 | K2: 0 | L2: 0.012635548 | P2: using % chg HPA
A3: 36557 | B3: 8969.9879 | C3: 32476.307 | D3: 2744.8299 | E3: 7207.1367 | F3: 6239.0207 | G3: 11854.395 | H3: 2549.891 | I3: 4998.6314 | J3: 38910.266 | K3: 0.029483169 | L3: 0.28646864
A4: 36586 | B4: 15881.03 | C4: 20521.122 | D4: 2269.82 | E4: 2467.9378 | F4: 6444.4946 | G4: 15302.974 | H4: 23356.147 | I4: -30.679173 | J4: 5879.2897 | K4: 0.00047097972 | L4: 0.093288609
A5: 36617 | B5: 22419.092 | C5: 23449.38 | D5: 3886.187 | E5: 4389.9529 | F5: 7397.8712 | G5: 15379.613 | H5: 19311.387 | I5: 10459.44 | J5: 15422.051 | K5: 0.045120999 | L5: 0.14427952
A6: 36647 | B6: 13292.855 | C6: 22967.901 | D6: 2344.6416 | E6: 2638.4933 | F6: 5723.4758 | G6: 20386.209 | H6: 26942.576 | I6: 720.4012 | J6: 4093.4425 | K6: 0.013876271 | L6: 0.09201556
A7: 36678 | B7: 21393.844 | C7: 28591.581 | D7: 7213.8981 | E7: 6155.98 | F7: 6039.0749 | G7: 19997.311 | H7: 18640.507 | I7: 1732.507 | J7: 23204.047 | K7: 0.029666311 | L7: 0.22717056
A8: 36708 | B8: 16778.073 | C8: 33838.351 | D8: 4691.9799 | E8: 8457.5927 | F8: 7503.7037 | G8: 25157.12 | H8: 24826.003 | I8: 1839.3997 | J8: 21208.031 | K8: 0.021487661 | L8: 0.20607896
A9: 36739 | B9: 54609.248 | C9: 32636.213 | D9: 4841.8857 | E9: 8257.4221 | F9: 8007.5921 | G9: 17237.634 | H9: 30834.023 | I9: 2932.2044 | J9: 14651.667 | K9: 0.020187618 | L9: 0.16401488
A10: 36770 | B10: 45625.426 | C10: 31179.645 | D10: 5297.5501 | E10: 8414.099 | F10: 7567.7982 | G10: 32437.809 | H10: 31764.081 | I10: 1115.6384 | J10: 12280.912 | K10: 0.018294944 | L10: 0.15106185
A11: 36800 | B11: 43629.778 | C11: 31511.573 | D11: 6200.3509 | E11: 9611.9553 | F11: 10166.506 | G11: 27738.227 | H11: 39148.236 | I11: 2423.9174 | J11: 8730.1938 | K11: 0.018924636 | L11: 0.12116391
A12: 36831 | B12: 42343.8 | C12: 28738.02 | D12: 6599.7453 | E12: 9382.6397 | F12: 9051.1539 | G12: 33006.586 | H12: 31639.333 | I12: 3609.7238 | J12: 12749.586 | K12: 0.032175582 | L12: 0.14767003
A13: 36861 | B13: 35630.354 | C13: 28355.804 | D13: 5779.8229 | E13: 9397.9177 | F13: 8674.1469 | G13: 17108.032 | H13: 21436.714 | I13: 7223.6077 | J13: 21373.06 | K13: 0.054973311 | L13: 0.22604123
A14: 36892 | B14: 51624.091 | C14: 28289.853 | D14: 5936.2573 | E14: 10228.201 | F14: 8621.6516 | G14: 22398.65 | H14: 21404.074 | I14: 4191.7566 | J14: 21443.689 | K14: 0.037591073 | L14: 0.24442641
... A178: 41883 | B178: 99806.553 | C178: 50197.259 | D178: 21049.849 | E178: 26441.632 | F178: 34448.144 | G178: 7599.1224 | H178: 14780.829 | I178: 145046.23 | J178: 90914.423 | K178: 0.73373296 | L178: 0.52787162

Sheet UPB
A1: lossDate | B1: UPB | C1: cnt | D1: aggActuralTotalLoss | E1: aggEstimTotalLoss | F1: aggActuralTotalSeverity | G1: aggEstimTotalSeverity | H1: aggActuralTotalSeverityOld | I1: aggEstimTotalSeverityOld
A2: 36434 | B2: 124952.46 | C2: 2 | D2: 0 | E2: 430.88404 | F2: =D2/$B2 -> 0 | G2: =E2/$B2 -> 0.0034483838 | H2: 0 | I2: 0.017541124
A3: 36465 | B3: 138638.95 | C3: 1 | D3: 4998.6314 | E3: 38910.266 | F3: =D3/$B3 -> 0.036055029 | G3: =E3/$B3 -> 0.28065898 | H3: 0.029483169 | I3: 0.25757154
A4: 36495 | B4: 148678.87 | C4: 4 | D4: -30.679173 | E4: 5879.2897 | F4: =D4/$B4 -> -0.00020634521 | G4: =E4/$B4 -> 0.039543546 | H4: 0.00047097972 | I4: 0.093072327
A5: 36526 | B5: 77862.93 | C5: 2 | D5: 10459.44 | E5: 15422.051 | F5: =D5/$B5 -> 0.13433144 | G5: =E5/$B5 -> 0.19806667 | H5: 0.045120999 | I5: 0.13699093
A6: 36557 | B6: 115462.12 | C6: 4 | D6: 720.4012 | E6: 4093.4425 | F6: =D6/$B6 -> 0.0062392861 | G6: =E6/$B6 -> 0.035452688 | H6: 0.013876271 | I6: 0.086951418
A7: 36586 | B7: 113343.52 | C7: 8 | D7: 1732.507 | E7: 23204.047 | F7: =D7/$B7 -> 0.015285452 | G7: =E7/$B7 -> 0.20472319 | H7: 0.029666311 | I7: 0.23654157
A8: 36617 | B8: 130837.4 | C8: 19 | D8: 1839.3997 | E8: 21208.031 | F8: =D8/$B8 -> 0.014058669 | G8: =E8/$B8 -> 0.16209456 | H8: 0.021487661 | I8: 0.17537039
A9: 36647 | B9: 115343.67 | C9: 10 | D9: 2932.2044 | E9: 14651.667 | F9: =D9/$B9 -> 0.025421459 | G9: =E9/$B9 -> 0.12702619 | H9: 0.020187618 | I9: 0.13783417
A10: 36678 | B10: 96642.17 | C10: 18 | D10: 1115.6384 | E10: 12280.912 | F10: =D10/$B10 -> 0.011544013 | G10: =E10/$B10 -> 0.12707612 | H10: 0.018294944 | I10: 0.12684364
A11: 36708 | B11: 109331.46 | C11: 19 | D11: 2423.9174 | E11: 8730.1938 | F11: =D11/$B11 -> 0.022170356 | G11: =E11/$B11 -> 0.079850702 | H11: 0.018924636 | I11: 0.09569824
A12: 36739 | B12: 120420.59 | C12: 36 | D12: 3609.7238 | E12: 12749.586 | F12: =D12/$B12 -> 0.029975968 | G12: =E12/$B12 -> 0.10587547 | H12: 0.032175582 | I12: 0.12621048
A13: 36770 | B13: 115061.61 | C13: 35 | D13: 7223.6077 | E13: 21373.06 | F13: =D13/$B13 -> 0.062780346 | G13: =E13/$B13 -> 0.18575318 | H13: 0.054973311 | I13: 0.19960923
... A178: 41791 | B178: 150124.12 | C178: 4297 | D178: 145046.23 | E178: 90914.423 | F178: =D178/$B178 -> 0.96617537 | G178: =E178/$B178 -> 0.60559504 | H178: 0.73373296 | I178: 0.49675274
A179: 41821 | B179: 151203.68 | C179: 4329 | F179: =D179/$B179 -> 0 | G179: =E179/$B179 -> 0
A180: 41852 | B180: 169262.86 | C180: 5358 | F180: =D180/$B180 -> 0 | G180: =E180/$B180 -> 0
A181: 41883 | B181: 151443.43 | C181: 3746 | F181: =D181/$B181 -> 0 | G181: =E181/$B181 -> 0

Sheet TimeDQ
A1: asof | B1: avg TimeDQ | D1: asof | E1: avg(perf.beginBalance)
A2: 36434 | B2: 6.5 | D2: 36557 | E2: 169542.04
A3: 36465 | B3: 6 | D3: 36586 | E3: 100611.15
A4: 36495 | B4: 5.25 | D4: 36617 | E4: 89588.827
A5: 36526 | B5: 6 | D5: 36647 | E5: 72209.535
A6: 36557 | B6: 8 | D6: 36678 | E6: 97741.894
A7: 36586 | B7: 7.75 | D7: 36708 | E7: 115412.45
A8: 36617 | B8: 8.9473684 | D8: 36739 | E8: 123062.65
A9: 36647 | B9: 8.9 | D9: 36770 | E9: 107348.9
A10: 36678 | B10: 9.6666667 | D10: 36800 | E10: 125797.59
A11: 36708 | B11: 10.368421 | D11: 36831 | E11: 114529.19
A12: 36739 | B12: 10.085714 | D12: 36861 | E12: 112122.53
A13: 36770 | B13: 10.028571 | D13: 36892 | E13: 107871.93
... A180: 41852 | B180: 34.306988 | D180: 41852 | E180: 169262.86
A181: 41883 | B181: 32.26403

Sheet Total v3 (2)
B1: Bass Loss | D1: Expenses | F1: Accued Interest | G1: MI Recoveries | J1: Total Loss | L1: Severity
B2: Actural | C2: Estim | D2: Actural | E2: Estim | F2: Actural | G2: Actural | H2: Estim | I2: Diff | J2: Actural | K2: Estim | L2: Actural | M2: Estim | O2: Restructured R code
A3: 36526 | B3: 6708.2022 | C3: 15070.072 | D3: 1232.7222 | E3: 101.88959 | F3: 1978.7634 | G3: 9780.3157 | H3: 17850.674 | I3: =G3/H3 -> 0.54789616 | J3: 0 | K3: 430.88404 | L3: 0 | M3: 0.017541124
A4: 36557 | B4: 8969.9879 | C4: 32476.307 | D4: 2744.8299 | E4: 7207.1367 | F4: 6239.0207 | G4: 11854.395 | H4: 2549.891 | I4: 0.5 | J4: 4998.6314 | K4: 38910.266 | L4: 0.027590787 | M4: 0.25757154
A5: 36586 | B5: 15881.03 | C5: 20521.122 | D5: 2269.82 | E5: 2467.9378 | F5: 6444.4946 | G5: 15302.974 | H5: 23356.147 | I5: =G5/H5 -> 0.65520114 | J5: -30.679173 | K5: 5879.2897 | L5: 0.00018515957 | M5: 0.093072327
A6: 36617 | B6: 22419.092 | C6: 23449.38 | D6: 3886.187 | E6: 4389.9529 | F6: 7397.8712 | G6: 15379.613 | H6: 19311.387 | I6: =G6/H6 -> 0.79640126 | J6: 10459.44 | K6: 15422.051 | L6: 0.045850311 | M6: 0.13699093
A7: 36647 | B7: 13292.855 | C7: 22967.901 | D7: 2344.6416 | E7: 2638.4933 | F7: 5723.4758 | G7: 20386.209 | H7: 26942.576 | I7: =G7/H7 -> 0.75665405 | J7: 720.4012 | K7: 4093.4425 | L7: 0.013660463 | M7: 0.086951418
A8: 36678 | B8: 21393.844 | C8: 28591.581 | D8: 7213.8981 | E8: 6155.98 | F8: 6039.0749 | G8: 19997.311 | H8: 18640.507 | I8: =G8/H8 -> 1.0727879 | J8: 1732.507 | K8: 23204.047 | L8: 0.029612798 | M8: 0.23654157
A9: 36708 | B9: 16778.073 | C9: 33838.351 | D9: 4691.9799 | E9: 8457.5927 | F9: 7503.7037 | G9: 25157.12 | H9: 24826.003 | I9: =G9/H9 -> 1.0133375 | J9: 1839.3997 | K9: 21208.031 | L9: 0.022332071 | M9: 0.17537039
A10: 36739 | B10: 54609.248 | C10: 32636.213 | D10: 4841.8857 | E10: 8257.4221 | F10: 8007.5921 | G10: 17237.634 | H10: 30834.023 | I10: =G10/H10 -> 0.5590459 | J10: 2932.2044 | K10: 14651.667 | L10: 0.020768509 | M10: 0.13783417
A11: 36770 | B11: 45625.426 | C11: 31179.645 | D11: 5297.5501 | E11: 8414.099 | F11: 7567.7982 | G11: 32437.809 | H11: 31764.081 | I11: =G11/H11 -> 1.0212104 | J11: 1115.6384 | K11: 12280.912 | L11: 0.018674546 | M11: 0.12684364
A12: 36800 | B12: 43629.778 | C12: 31511.573 | D12: 6200.3509 | E12: 9611.9553 | F12: 10166.506 | G12: 27738.227 | H12: 39148.236 | I12: =G12/H12 -> 0.70854346 | J12: 2423.9174 | K12: 8730.1938 | L12: 0.019310052 | M12: 0.09569824
A13: 36831 | B13: 42343.8 | C13: 28738.02 | D13: 6599.7453 | E13: 9382.6397 | F13: 9051.1539 | G13: 33006.586 | H13: 31639.333 | I13: =G13/H13 -> 1.0432137 | J13: 3609.7238 | K13: 12749.586 | L13: 0.031829625 | M13: 0.12621048
A14: 36861 | B14: 35630.354 | C14: 28355.804 | D14: 5779.8229 | E14: 9397.9177 | F14: 8674.1469 | G14: 17108.032 | H14: 21436.714 | I14: =G14/H14 -> 0.79807157 | J14: 7223.6077 | K14: 21373.06 | L14: 0.054591475 | M14: 0.19960923
A15: 36892 | B15: 51624.091 | C15: 28289.853 | D15: 5936.2573 | E15: 10228.201 | F15: 8621.6516 | G15: 22398.65 | H15: 21404.074 | I15: =G15/H15 -> 1.0464667 | J15: 4191.7566 | K15: 21443.689 | L15: 0.037587597 | M15: 0.20749658
A16: 36923 | B16: 43327.616 | C16: 28239.968 | D16: 5875.6768 | E16: 9244.8786 | F16: 9551.5757 | G16: 20123.433 | H16: 27203.681 | I16: =G16/H16 -> 0.73973198 | J16: 3443.1941 | K16: 16463.539 | L16: 0.034494677 | M16: 0.16428124
... A179: 41883 | B179: 99806.553 | C179: 50197.259 | D179: 21049.849 | E179: 26441.632 | F179: 34448.144 | G179: 7599.1224 | H179: 14780.829 | I179: =G179/H179 -> 0.51412017 | J179: 145046.23 | K179: 90914.423 | L179: 0.73363894 | M179: 0.49675274

Sheet Total v3
B1: Bass Loss | D1: Expenses | F1: Accued Interest | G1: MI Recoveries | I1: Total Loss | K1: Severity
B2: Actural | C2: Estim | D2: Actural | E2: Estim | F2: Actural | G2: Actural | H2: Estim | I2: Actural | J2: Estim | K2: Actural | L2: Estim | O2: Restructured R code
A3: 36526 | B3: 6708.2022 | C3: 15070.072 | D3: 1232.7222 | E3: 101.88959 | F3: 1978.7634 | G3: 9780.3157 | H3: 17850.674 | I3: 0 | J3: -699.94854 | K3: 0 | L3: 0.012635548
A4: 36557 | B4: 8969.9879 | C4: 32476.307 | D4: 2744.8299 | E4: 7207.1367 | F4: 6239.0207 | G4: 11854.395 | H4: 2549.891 | I4: 4998.6314 | J4: 43372.573 | K4: 0.027590787 | L4: 0.28646864
A5: 36586 | B5: 15881.03 | C5: 20521.122 | D5: 2269.82 | E5: 2467.9378 | F5: 6444.4946 | G5: 15302.974 | H5: 23356.147 | I5: -30.679173 | J5: 6077.4074 | K5: 0.00018515957 | L5: 0.093288609
A6: 36617 | B6: 22419.092 | C6: 23449.38 | D6: 3886.187 | E6: 4389.9529 | F6: 7397.8712 | G6: 15379.613 | H6: 19311.387 | I6: 10459.44 | J6: 15925.817 | K6: 0.045850311 | L6: 0.14427952
A7: 36647 | B7: 13292.855 | C7: 22967.901 | D7: 2344.6416 | E7: 2638.4933 | F7: 5723.4758 | G7: 20386.209 | H7: 26942.576 | I7: 720.4012 | J7: 4387.2942 | K7: 0.013660463 | L7: 0.09201556
A8: 36678 | B8: 21393.844 | C8: 28591.581 | D8: 7213.8981 | E8: 6155.98 | F8: 6039.0749 | G8: 19997.311 | H8: 18640.507 | I8: 1732.507 | J8: 22146.129 | K8: 0.029612798 | L8: 0.22717056
A9: 36708 | B9: 16778.073 | C9: 33838.351 | D9: 4691.9799 | E9: 8457.5927 | F9: 7503.7037 | G9: 25157.12 | H9: 24826.003 | I9: 1839.3997 | J9: 24973.644 | K9: 0.022332071 | L9: 0.20607896
A10: 36739 | B10: 54609.248 | C10: 32636.213 | D10: 4841.8857 | E10: 8257.4221 | F10: 8007.5921 | G10: 17237.634 | H10: 30834.023 | I10: 2932.2044 | J10: 18067.204 | K10: 0.020768509 | L10: 0.16401488
A11: 36770 | B11: 45625.426 | C11: 31179.645 | D11: 5297.5501 | E11: 8414.099 | F11: 7567.7982 | G11: 32437.809 | H11: 31764.081 | I11: 1115.6384 | J11: 15397.461 | K11: 0.018674546 | L11: 0.15106185
A12: 36800 | B12: 43629.778 | C12: 31511.573 | D12: 6200.3509 | E12: 9611.9553 | F12: 10166.506 | G12: 27738.227 | H12: 39148.236 | I12: 2423.9174 | J12: 12141.798 | K12: 0.019310052 | L12: 0.12116391
A13: 36831 | B13: 42343.8 | C13: 28738.02 | D13: 6599.7453 | E13: 9382.6397 | F13: 9051.1539 | G13: 33006.586 | H13: 31639.333 | I13: 3609.7238 | J13: 15532.481 | K13: 0.031829625 | L13: 0.14767003
A14: 36861 | B14: 35630.354 | C14: 28355.804 | D14: 5779.8229 | E14: 9397.9177 | F14: 8674.1469 | G14: 17108.032 | H14: 21436.714 | I14: 7223.6077 | J14: 24991.155 | K14: 0.054591475 | L14: 0.22604123
... A179: 41883 | B179: 99806.553 | C179: 50197.259 | D179: 21049.849 | E179: 26441.632 | F179: 34448.144 | G179: 7599.1224 | H179: 14780.829 | I179: 145046.23 | J179: 96306.206 | K179: 0.73363894 | L179: 0.52787162

Sheet Total v4
B2: aggActuralBaseLoss | C2: aggEstimBassLoss | D2: aggActualExpenses | E2: aggEstimExpenses | F2: aggEstimInterest | G2: aggActualMIRecoveries | H2: aggEstimMIRecoveries | I2: aggActuralTotalLoss | J2: aggEstimTotalLoss | K2: aggActuralTotalSeverity | L2: aggEstimTotalSeverity | O2: Add filter on Severity (0,105)
A3: 36526 | B3: 21142.04 | C3: 57075.634 | D3: 5424 | E3: 14093.958 | F3: 8265.1745 | G3: 21762 | H3: 0 | I3: 10870.21 | J3: 79434.767 | K3: 0.06 | L3: 0.46852548
A4: 36557 | B4: 455.69 | C4: 21502.142 | D4: 581 | E4: 2390.0224 | F4: 2489.2403 | G4: 0 | H4: 0 | I4: 3377.93 | J4: 26381.405 | K4: 0.04 | L4: 0.33119298
A5: 36586 | B5: 41398.699 | C5: 30256.354 | D5: 5433.7928 | E5: 6106.5046 | F5: 7642.9749 | G5: 20482.231 | H5: 3987.7271 | I5: 32273.614 | J5: 40018.107 | K5: 0.15232793 | L5: 0.26320297
A6: 36617 | B6: 53281.972 | C6: 28886.632 | D6: 4751.5594 | E6: 5182.9873 | F6: 3395.3379 | G6: 57217.195 | H6: 14166.137 | I6: 4031.224 | J6: 23298.82 | K6: 0.076441586 | L6: 0.31937876
A7: 36647 | B7: 40328.788 | C7: 27830.22 | D7: 5093.1503 | E7: 5124.6605 | F7: 5753.6355 | G7: 40526.284 | H7: 17648.009 | I7: 10195.284 | J7: 21060.507 | K7: 0.10308962 | L7: 0.22376721
A8: 36678 | B8: 11981.059 | C8: 40700.606 | D8: 7708.1014 | E8: 12905.984 | F8: 9976.763 | G8: 17125.019 | H8: 15987.79 | I8: 12331.75 | J8: 47595.563 | K8: 0.12466559 | L8: 0.36883577
A9: 36708 | B9: 31352.977 | C9: 37183.29 | D9: 4147.7447 | E9: 6290.3871 | F9: 7278.4504 | G9: 18668.548 | H9: 25068.635 | I9: 23435.114 | J9: 25683.493 | K9: 0.16585412 | L9: 0.22760252
A10: 36739 | B10: 65025.086 | C10: 31601.564 | D10: 6231.696 | E10: 8862.5563 | F10: 7565.0714 | G10: 68176.582 | H10: 34789.469 | I10: 10262.994 | J10: 13239.723 | K10: 0.10527715 | L10: 0.16063757
A11: 36770 | B11: 43109.519 | C11: 39181.509 | D11: 7210.3503 | E11: 10885.981 | F11: 10092.615 | G11: 41763.021 | H11: 39432.715 | I11: 17801.508 | J11: 20727.39 | K11: 0.12698207 | L11: 0.20268567
A12: 36800 | B12: 37269.803 | C12: 37154.546 | D12: 6280.5592 | E12: 9115.0765 | F12: 8319.1324 | G12: 39473.142 | H12: 34167.3 | I12: 10846.534 | J12: 20421.455 | K12: 0.094942042 | L12: 0.19184357
A13: 36831 | B13: 29368.227 | C13: 37284.812 | D13: 6812.8443 | E13: 10579.179 | F13: 8798.9938 | G13: 18940.867 | H13: 16713.926 | I13: 24784.173 | J13: 39949.058 | K13: 0.18669596 | L13: 0.31301951
A14: 36861 | B14: 41523.389 | C14: 37702.37 | D14: 8295.2283 | E14: 10218.419 | F14: 8286.1985 | G14: 39384.527 | H14: 25735.027 | I14: 17864.79 | J14: 30471.96 | K14: 0.14493914 | L14: 0.27643733
... A178: 41852 | B178: 68524.849 | C178: 44713.196 | D178: 26848.966 | E178: 29741.477 | F178: 33432.099 | G178: 10409.717 | H178: 16669.872 | I178: 114911.79 | J178: 91216.9 | K178: 0.57147092 | L178: 0.48911184
A179: 41883

Sheet Total Severity
B1: Bass Loss | D1: Expenses | F1: Accued Interest | G1: MI Recoveries | I1: Total Loss | K1: Severity
B2: Actural | C2: Estim | D2: Actural | E2: Estim | F2: Actural | G2: Actural | H2: Estim | I2: Actural | J2: Estim | K2: Actural | L2: Estim
A3: 36526 | B3: 0.062417893 | C3: 0.19099306 | D3: 0.013510922 | E3: 0.02465956 | F3: 0.028735889 | G3: 9780.3157 | H3: 0.18258213 | I3: 0 | J3: 1829.7467 | K3: 0 | L3: 0.061806382
A4: 36557 | B4: 0.057682748 | C4: 0.284067 | D4: 0.017917359 | E4: 0.057787846 | F4: 0.045018574 | G4: 11854.395 | H4: 0.034155633 | I4: 4998.6314 | J4: 53286.264 | K4: 0.027590787 | L4: 0.35271778
A5: 36586 | B5: 0.030927682 | C5: 0.20587347 | D5: 0.015703286 | E5: 0.020190789 | F5: 0.04455445 | G5: 13175.769 | H5: 0.13329704 | I5: 333.78215 | J5: 15544.958 | K5: 0.003952464 | L5: 0.13732166
A6: 36617 | B6: 0.13435418 | C6: 0.23610391 | D6: 0.023280297 | E6: 0.0327485 | F6: 0.046840533 | G6: 13772.278 | H6: 0.14078536 | I6: 14609.312 | J6: 29795.889 | K6: 0.068954344 | L6: 0.17490758
A7: 36647 | B7: 0.11953457 | C7: 0.22354515 | D7: 0.022191942 | E7: 0.03332787 | F7: 0.045399839 | G7: 20386.209 | H7: 0.17130533 | I7: 720.4012 | J7: 12023.708 | K7: 0.013660463 | L7: 0.13096753
A8: 36678 | B8: 0.24723281 | C8: 0.23507284 | D8: 0.032166491 | E8: 0.049697339 | F8: 0.048774293 | G8: 28544.216 | H8: 0.18491763 | I8: 5351.858 | J8: 11011.296 | K8: 0.054115305 | L8: 0.14862685
A9: 36708 | B9: 0.057136269 | C9: 0.28220756 | D9: 0.03515325 | E9: 0.069092481 | F9: 0.057118658 | G9: 8634.7393 | H9: 0.17460472 | I9: 5182.499 | J9: 29519.079 | K9: 0.05291342 | L9: 0.23381399
A10: 36739 | B10: 0.084695162 | C10: 0.23969886 | D10: 0.027104098 | E10: 0.045154599 | F10: 0.04750883 | G10: 11340.708 | H10: 0.20231614 | I10: 10219.535 | J10: 11684.47 | K10: 0.072307082 | L10: 0.13004615
A11: 36770 | B11: 0.30039996 | C11: 0.25687565 | D11: 0.038839839 | E11: 0.058964636 | F11: 0.049453688 | G11: 45831.877 | H11: 0.25981937 | I11: 6686.9857 | J11: 8462.536 | K11: 0.068594656 | L11: 0.1054746
A12: 36800 | B12: 0.11526722 | C12: 0.25969231 | D12: 0.037644393 | E12: 0.054312613 | F12: 0.059400689 | G12: 24447.304 | H12: 0.20813011 | I12: 8298.8167 | J12: 21746.997 | K12: 0.05921849 | L12: 0.1652755
A13: 36831 | B13: 0.16426306 | C13: 0.26292747 | D13: 0.04840289 | E13: 0.061683161 | F13: 0.056271741 | G13: 29259.98 | H13: 0.20615971 | I13: 7805.986 | J13: 20465.984 | K13: 0.06826629 | L13: 0.17472266
A14: 36861 | B14: 0.14764193 | C14: 0.27184469 | D14: 0.04802276 | E14: 0.062796866 | F14: 0.057243316 | G14: 16978.982 | H14: 0.14848306 | I14: 15005.877 | J14: 32133.891 | K14: 0.11303732 | L14: 0.24340181
... A179: 41883 | B179: 0.32535735 | C179: 0.26262702 | D179: 0.14534267 | E179: 0.16989564 | F179: 0.15618061 | G179: 10088.785 | H179: 0.08311536 | I179: 111357.85 | J179: 99789.599 | K179: 0.55379385 | L179: 0.50558791

Sheet FC Severity
B1: Bass Loss | D1: Expenses | F1: Accued Interest | G1: MI Recoveries | I1: Total Loss | K1: Severity
B2: aggActuralBaseLoss | C2: aggEstimBassLoss | D2: aggActualExpenses | E2: aggEstimExpenses | F2: aggEstimInterest | G2: aggActualMIRecoveries | H2: aggEstimMIRecoveries | I2: aggActuralTotalLoss | J2: aggEstimTotalLoss | K2: aggActuralTotalSeverity | L2: aggEstimTotalSeverity
A3: 36526 | B3: 0.062417893 | C3: 0.19099306 | D3: 0.013510922 | E3: 0.02465956 | F3: 0.028735889 | G3: 9780.3157 | H3: 0.18258213 | I3: 0 | J3: 1829.7467 | K3: 0 | L3: 0.061806382
A4: 36557 | B4: 0.00062851904 | C4: 0.20338416 | D4: 0.0059352041 | E4: 0.028182112 | F4: 0.041841917 | G4: 3419.7997 | H4: 0.06323319 | I4: 0.0074391989 | J4: 23573.542 | K4: 0 | L4: 0.210175
A5: 36586 | B5: 0.030927682 | C5: 0.20587347 | D5: 0.015703286 | E5: 0.020190789 | F5: 0.04455445 | G5: 13175.769 | H5: 0.13329704 | I5: 333.78215 | J5: 15544.958 | K5: 0.003952464 | L5: 0.13732166 | O5: FC | AD5: REO
A6: 36617 | B6: 0.05436739 | C6: 0.21291887 | D6: 0.019977634 | E6: 0.019148308 | F6: 0.04457634 | G6: 5222.1804 | H6: 0.13893145 | I6: 16724.16 | J6: 27739.019 | K6: 0.0777456 | L6: 0.13771206
A7: 36647 | B7: 0.022652221 | C7: 0.20070284 | D7: 0.013328806 | E7: 0.021498558 | F7: 0.044340743 | G7: 11615.594 | H7: 0.16004192 | I7: 318.25196 | J7: 10311.6 | K7: 0.0048923126 | L7: 0.10650023
