Workbook
Name temp_1: Sheet1!$A$1:$C$384
Name temp_2: Sheet1!$U$1:$W$367
Name temp_3: Sheet1!#REF!

Sheet Sheet1
A1: poolIssueDate | B1: count() | C1: HARPStatus | J1: Sum of count() | K1: Column Labels | U1: poolIssueDate | V1: count() | W1: MHAStatus | AA1: Sum of count() | AB1: Column Labels | AI1: pmtdate | AJ1: count() | AK1: CombinedHARPStatus | AN1: Sum of count() | AO1: Column Labels | AW1: pmtdate | AX1: count() | AY1: CombinedHARPStatus | BB1: Sum of count() | BC1: Column Labels
A2: 38687 | B2: 19057 | C2: < 2009-06 | J2: Row Labels | K2: < 2009-06 | L2: HARP | M2: N/A | N2: NON-HARP | O2: Unknown | P2: (blank) | Q2: Grand Total | U2: 38687 | V2: 1771 | W2: MHA-ELIGIBLE | AA2: Row Labels | AB2: MHA-ELIGIBLE | AC2: NOMHA-PURCHASE | AD2: NOMHA-REFI | AE2: (blank) | AF2: Grand Total | AI2: 38353 | AJ2: 1751 | AK2: N/A | AN2: Row Labels | AO2: < 2009-06 | AP2: HARPed | AQ2: N/A | AR2: NON-HARPed | AS2: Grand Total | AW2: 38353 | AX2: 19296 | AY2: < 2009-06 | BB2: Row Labels | BC2: < 2009-06 | BD2: HARPed | BE2: N/A | BF2: NON-HARPed | BG2: (blank) | BH2: Grand Total
A3: 38687 | B3: 116679 | C3: N/A | J3: 38687 | K3: 19057 | M3: 116679 | Q3: 135736 | U3: 38687 | V3: 64164 | W3: NOMHA-REFI | AA3: 38687 | AB3: 1771 | AC3: 69801 | AD3: 64164 | AF3: 135736 | AI3: 38353 | AJ3: 226 | AK3: < 2009-06 | AN3: 38353 | AO3: 226 | AQ3: 1751 | AS3: 1977 | AW3: 38353 | AX3: 18274 | AY3: N/A | BB3: 38353 | BC3: 19296 | BE3: 18274 | BH3: 37570
A4: 38718 | B4: 15165 | C4: < 2009-06 | J4: 38718 | K4: 15165 | M4: 101038 | Q4: 116203 | U4: 38687 | V4: 69801 | W4: NOMHA-PURCHASE | AA4: 38718 | AB4: 1707 | AC4: 56048 | AD4: 58448 | AF4: 116203 | AI4: 38384 | AJ4: 237 | AK4: < 2009-06 | AN4: 38384 | AO4: 237 | AQ4: 1713 | AS4: 1950 | AW4: 38384 | AX4: 17818 | AY4: N/A | BB4: 38384 | BC4: 19367 | BE4: 17818 | BH4: 37185
A5: 38718 | B5: 101038 | C5: N/A | J5: 38749 | K5: 13726 | M5: 85924 | Q5: 99650 | U5: 38718 | V5: 58448 | W5: NOMHA-REFI | AA5: 38749 | AB5: 1596 | AC5: 48505 | AD5: 49549 | AF5: 99650 | AI5: 38384 | AJ5: 1713 | AK5: N/A | AN5: 38412 | AO5: 165 | AQ5: 1379 | AS5: 1544 | AW5: 38384 | AX5: 19367 | AY5: < 2009-06 | BB5: 38412 | BC5: 16217 | BE5: 14430 | BH5: 30647
A6: 38749 | B6: 13726 | C6: < 2009-06 | J6: 38777 | K6: 13317 | M6: 85045 | Q6: 98362 | U6: 38718 | V6: 56048 | W6: NOMHA-PURCHASE | AA6: 38777 | AB6: 1821 | AC6: 45628 | AD6: 50913 | AF6: 98362 | AI6: 38412 | AJ6: 1379 | AK6: N/A | AN6: 38443 | AO6: 248 | AQ6: 1406 | AS6: 1654 | AW6: 38412 | AX6: 16217 | AY6: < 2009-06 | BB6: 38443 | BC6: 18282 | BE6: 16447 | BH6: 34729
A7: 38749 | B7: 85924 | C7: N/A | J7: 38808 | K7: 13740 | M7: 91876 | Q7: 105616 | U7: 38718 | V7: 1707 | W7: MHA-ELIGIBLE | AA7: 38808 | AB7: 1451 | AC7: 50072 | AD7: 54093 | AF7: 105616 | AI7: 38412 | AJ7: 165 | AK7: < 2009-06 | AN7: 38473 | AO7: 357 | AQ7: 1954 | AS7: 2311 | AW7: 38412 | AX7: 14430 | AY7: N/A | BB7: 38473 | BC7: 22945 | BE7: 21208 | BH7: 44153
A8: 38777 | B8: 13317 | C8: < 2009-06 | J8: 38838 | K8: 11485 | M8: 83181 | Q8: 94666 | U8: 38749 | V8: 49549 | W8: NOMHA-REFI | AA8: 38838 | AB8: 1286 | AC8: 50281 | AD8: 43099 | AF8: 94666 | AI8: 38443 | AJ8: 248 | AK8: < 2009-06 | AN8: 38504 | AO8: 256 | AQ8: 2080 | AS8: 2336 | AW8: 38443 | AX8: 16447 | AY8: N/A | BB8: 38504 | BC8: 17249 | BE8: 20814 | BH8: 38063
A9: 38777 | B9: 85045 | C9: N/A | J9: 38869 | K9: 11763 | M9: 96000 | Q9: 107763 | U9: 38749 | V9: 48505 | W9: NOMHA-PURCHASE | AA9: 38869 | AB9: 1464 | AC9: 60815 | AD9: 45484 | AF9: 107763 | AI9: 38443 | AJ9: 1406 | AK9: N/A | AN9: 38534 | AO9: 314 | AQ9: 2676 | AS9: 2990 | AW9: 38443 | AX9: 18282 | AY9: < 2009-06 | BB9: 38534 | BC9: 20889 | BE9: 25422 | BH9: 46311
A10: 38808 | B10: 13740 | C10: < 2009-06 | J10: 38899 | K10: 10532 | M10: 94899 | Q10: 105431 | U10: 38749 | V10: 1596 | W10: MHA-ELIGIBLE | AA10: 38899 | AB10: 1287 | AC10: 62896 | AD10: 41248 | AF10: 105431 | AI10: 38473 | AJ10: 357 | AK10: < 2009-06 | AN10: 38565 | AO10: 372 | AQ10: 3211 | AS10: 3583 | AW10: 38473 | AX10: 22945 | AY10: < 2009-06 | BB10: 38565 | BC10: 27493 | BE10: 32384 | BH10: 59877
A11: 38808 | B11: 91876 | C11: N/A | J11: 38930 | K11: 11293 | M11: 106784 | Q11: 118077 | U11: 38777 | V11: 50913 | W11: NOMHA-REFI | AA11: 38930 | AB11: 1273 | AC11: 74272 | AD11: 42532 | AF11: 118077 | AI11: 38473 | AJ11: 1954 | AK11: N/A | AN11: 38596 | AO11: 617 | AQ11: 4048 | AS11: 4665 | AW11: 38473 | AX11: 21208 | AY11: N/A | BB11: 38596 | BC11: 31231 | BE11: 29845 | BH11: 61076
A12: 38838 | B12: 11485 | C12: < 2009-06 | J12: 38961 | K12: 11420 | M12: 107277 | Q12: 118697 | U12: 38777 | V12: 45628 | W12: NOMHA-PURCHASE | AA12: 38961 | AB12: 1279 | AC12: 74289 | AD12: 43129 | AF12: 118697 | AI12: 38504 | AJ12: 256 | AK12: < 2009-06 | AN12: 38626 | AO12: 996 | AQ12: 7481 | AS12: 8477 | AW12: 38504 | AX12: 20814 | AY12: N/A | BB12: 38626 | BC12: 30344 | BE12: 29919 | BH12: 60263
A13: 38838 | B13: 83181 | C13: N/A | J13: 38991 | K13: 11613 | M13: 92041 | Q13: 103654 | U13: 38777 | V13: 1821 | W13: MHA-ELIGIBLE | AA13: 38991 | AB13: 1152 | AC13: 59427 | AD13: 43075 | AF13: 103654 | AI13: 38504 | AJ13: 2080 | AK13: N/A | AN13: 38657 | AO13: 2199 | AQ13: 15991 | AS13: 18190 | AW13: 38504 | AX13: 17249 | AY13: < 2009-06 | BB13: 38657 | BC13: 27266 | BE13: 25968 | BH13: 53234
A14: 38869 | B14: 11763 | C14: < 2009-06 | J14: 39022 | K14: 13547 | M14: 83109 | Q14: 96656 | U14: 38808 | V14: 54093 | W14: NOMHA-REFI | AA14: 39022 | AB14: 1107 | AC14: 48845 | AD14: 46704 | AF14: 96656 | AI14: 38534 | AJ14: 314 | AK14: < 2009-06 | AN14: 38687 | AO14: 9660 | AQ14: 58394 | AS14: 68054 | AW14: 38534 | AX14: 25422 | AY14: N/A | BB14: 38687 | BC14: 26896 | BE14: 23032 | BH14: 49928
... A42: 39295 | B42: 17169 | C42: < 2009-06 | J42: 39873 | K42: 126468 | M42: 90938 | Q42: 217406 | U42: 39083 | V42: 52477 | W42: NOMHA-PURCHASE | AA42: 39873 | AB42: 2318 | AC42: 27687 | AD42: 187401 | AF42: 217406 | AI42: 38961 | AJ42: 101464 | AK42: N/A | AN42: 39539 | AO42: 60058 | AQ42: 99187 | AS42: 159245 | AW42: 38961 | AX42: 18244 | AY42: N/A | BB42: 39539 | BC42: 42764 | BE42: 22787 | BH42: 65551
A43: 39295 | B43: 117065 | C43: N/A | J43: 39904 | K43: 91317 | L43: 286 | M43: 70127 | N43: 4758 | Q43: 166488 | U43: 39083 | V43: 1046 | W43: MHA-ELIGIBLE | AA43: 39904 | AB43: 1785 | AC43: 24673 | AD43: 140030 | AF43: 166488 | AI43: 38961 | AJ43: 10662 | AK43: < 2009-06 | AN43: 39569 | AO43: 41596 | AQ43: 102401 | AS43: 143997 | AW43: 38961 | AX43: 12747 | AY43: < 2009-06 | BB43: 39569 | BC43: 31567 | BE43: 21383 | BH43: 52950
A44: 39326 | B44: 17527 | C44: < 2009-06 | J44: 39934 | K44: 25662 | L44: 5842 | M44: 67567 | N44: 51705 | Q44: 150776 | U44: 39114 | V44: 71070 | W44: NOMHA-REFI | AA44: 39934 | AB44: 2588 | AC44: 24641 | AD44: 123547 | AF44: 150776 | AI44: 38991 | AJ44: 102383 | AK44: N/A | AN44: 39600 | AO44: 38213 | AQ44: 98365 | AS44: 136578 | AW44: 38991 | AX44: 15647 | AY44: < 2009-06 | BB44: 39600 | BC44: 29505 | BE44: 22525 | BH44: 52030
A45: 39326 | B45: 136772 | C45: N/A | J45: 39965 | K45: 7053 | L45: 16517 | M45: 104095 | N45: 106391 | Q45: 234056 | U45: 39114 | V45: 56557 | W45: NOMHA-PURCHASE | AA45: 39965 | AB45: 9453 | AC45: 41335 | AD45: 183268 | AF45: 234056 | AI45: 38991 | AJ45: 11537 | AK45: < 2009-06 | AN45: 39630 | AO45: 23471 | AQ45: 81925 | AS45: 105396 | AW45: 38991 | AX45: 21523 | AY45: N/A | BB45: 39630 | BC45: 22067 | BE45: 23075 | BH45: 45142
A46: 39356 | B46: 17939 | C46: < 2009-06 | J46: 39995 | K46: 781 | L46: 22075 | M46: 71014 | N46: 60337 | Q46: 154207 | U46: 39114 | V46: 1203 | W46: MHA-ELIGIBLE | AA46: 39995 | AB46: 14498 | AC46: 32476 | AD46: 107233 | AF46: 154207 | AI46: 39022 | AJ46: 12948 | AK46: < 2009-06 | AN46: 39661 | AO46: 17448 | AQ46: 80739 | AS46: 98187 | AW46: 39022 | AX46: 20834 | AY46: N/A | BB46: 39661 | BC46: 15491 | BE46: 19612 | BH46: 35103
A47: 39356 | B47: 108346 | C47: N/A | J47: 40026 | K47: 173 | L47: 25210 | M47: 82357 | N47: 55906 | Q47: 163646 | U47: 39142 | V47: 67164 | W47: NOMHA-REFI | AA47: 40026 | AB47: 16086 | AC47: 42643 | AD47: 104917 | AF47: 163646 | AI47: 39022 | AJ47: 96093 | AK47: N/A | AN47: 39692 | AO47: 11582 | AQ47: 67217 | AS47: 78799 | AW47: 39022 | AX47: 16622 | AY47: < 2009-06 | BB47: 39692 | BC47: 10494 | BE47: 15980 | BH47: 26474
A48: 39387 | B48: 22061 | C48: < 2009-06 | J48: 40057 | K48: 258 | L48: 15667 | M48: 70570 | N48: 31910 | Q48: 118405 | U48: 39142 | V48: 60614 | W48: NOMHA-PURCHASE | AA48: 40057 | AB48: 8996 | AC48: 41473 | AD48: 67936 | AF48: 118405 | AI48: 39052 | AJ48: 107332 | AK48: N/A | AN48: 39722 | AO48: 7202 | AQ48: 45117 | AS48: 52319 | AW48: 39052 | AX48: 20654 | AY48: < 2009-06 | BB48: 39722 | BC48: 8915 | BE48: 14635 | BH48: 23550
A49: 39387 | B49: 118469 | C49: N/A | J49: 40087 | K49: 1059 | L49: 12098 | M49: 61209 | N49: 23119 | Q49: 97485 | U49: 39142 | V49: 1354 | W49: MHA-ELIGIBLE | AA49: 40087 | AB49: 6341 | AC49: 37039 | AD49: 54105 | AF49: 97485 | AI49: 39052 | AJ49: 17880 | AK49: < 2009-06 | AN49: 39753 | AO49: 10585 | AQ49: 50694 | AS49: 61279 | AW49: 39052 | AX49: 21144 | AY49: N/A | BB49: 39753 | BC49: 9826 | BE49: 14115 | BH49: 23941
A50: 39417 | B50: 23242 | C50: < 2009-06 | J50: 40118 | K50: 77 | L50: 16580 | M50: 54618 | N50: 22548 | Q50: 93823 | U50: 39173 | V50: 64185 | W50: NOMHA-REFI | AA50: 40118 | AB50: 8103 | AC50: 32297 | AD50: 53423 | AF50: 93823 | AI50: 39083 | AJ50: 17232 | AK50: < 2009-06 | AN50: 39783 | AO50: 15821 | AQ50: 52103 | AS50: 67924 | AW50: 39083 | AX50: 20779 | AY50: N/A | BB50: 39783 | BC50: 12743 | BE50: 15394 | BH50: 28137
A51: 39417 | B51: 108670 | C51: N/A | J51: 40148 | K51: 336 | L51: 25493 | M51: 70439 | N51: 30548 | Q51: 126816 | U51: 39173 | V51: 55862 | W51: NOMHA-PURCHASE | AA51: 40148 | AB51: 12795 | AC51: 42345 | AD51: 71676 | AF51: 126816 | AI51: 39083 | AJ51: 98456 | AK51: N/A | AN51: 39814 | AO51: 7542 | AQ51: 32448 | AS51: 39990 | AW51: 39083 | AX51: 19393 | AY51: < 2009-06 | BB51: 39814 | BC51: 9484 | BE51: 11771 | BH51: 21255
A52: 39448 | B52: 25971 | C52: < 2009-06 | J52: 40179 | K52: 360 | L52: 24649 | M52: 51271 | N52: 24350 | Q52: 100630 | U52: 39173 | V52: 1198 | W52: MHA-ELIGIBLE | AA52: 40179 | AB52: 12696 | AC52: 29955 | AD52: 57979 | AF52: 100630 | AI52: 39114 | AJ52: 21209 | AK52: < 2009-06 | AN52: 39845 | AO52: 32323 | AQ52: 52470 | AS52: 84793 | AW52: 39114 | AX52: 21525 | AY52: N/A | BB52: 39845 | BC52: 20177 | BE52: 15596 | BH52: 35773
A53: 39448 | B53: 90455 | C53: N/A | J53: 40210 | K53: 77 | L53: 26299 | M53: 51586 | N53: 28003 | Q53: 105965 | U53: 39203 | V53: 69464 | W53: NOMHA-REFI | AA53: 40210 | AB53: 13514 | AC53: 27636 | AD53: 64815 | AF53: 105965 | AI53: 39114 | AJ53: 99305 | AK53: N/A | AN53: 39873 | AO53: 81505 | AQ53: 58125 | AS53: 139630 | AW53: 39114 | AX53: 22776 | AY53: < 2009-06 | BB53: 39873 | BC53: 66165 | BE53: 17183 | BH53: 83348
A54: 39479 | B54: 41508 | C54: < 2009-06 | J54: 40238 | K54: 679 | L54: 21183 | M54: 56751 | N54: 25937 | Q54: 104550 | U54: 39203 | V54: 63827 | W54: NOMHA-PURCHASE | AA54: 40238 | AB54: 11773 | AC54: 30875 | AD54: 61902 | AF54: 104550 | AI54: 39142 | AJ54: 86895 | AK54: N/A | AN54: 39904 | AO54: 104826 | AQ54: 72314 | AS54: 177140 | AW54: 39142 | AX54: 22740 | AY54: < 2009-06 | BB54: 39904 | BC54: 81476 | BE54: 19205 | BH54: 100681
A55: 39479 | B55: 124215 | C55: N/A | J55: 40269 | K55: 113 | L55: 19513 | M55: 37231 | N55: 14416 | Q55: 71273 | U55: 39203 | V55: 1274 | W55: MHA-ELIGIBLE | AA55: 40269 | AB55: 10346 | AC55: 23058 | AD55: 37869 | AF55: 71273 | AI55: 39142 | AJ55: 20923 | AK55: < 2009-06 | AN55: 39934 | AO55: 108692 | AQ55: 87478 | AS55: 196170 | AW55: 39142 | AX55: 18020 | AY55: N/A | BB55: 39934 | BC55: 84588 | BE55: 22244 | BH55: 106832
A56: 39508 | B56: 49873 | C56: < 2009-06 | J56: 40299 | K56: 25 | L56: 17575 | M56: 46855 | N56: 15988 | Q56: 80443 | U56: 39234 | V56: 61490 | W56: NOMHA-REFI | AA56: 40299 | AB56: 9171 | AC56: 30710 | AD56: 40562 | AF56: 80443 | AI56: 39173 | AJ56: 18017 | AK56: < 2009-06 | AN56: 39965 | AP56: 10383 | AQ56: 80976 | AR56: 94312 | AS56: 185671 | AW56: 39173 | AX56: 20586 | AY56: < 2009-06 | BB56: 39965 | BD56: 22119 | BE56: 27796 | BF56: 81756 | BH56: 131671
A57: 39508 | B57: 88535 | C57: N/A | J57: 40330 | K57: 4 | L57: 19523 | M57: 55813 | N57: 14269 | Q57: 89609 | U57: 39234 | V57: 69687 | W57: NOMHA-PURCHASE | AA57: 40330 | AB57: 10433 | AC57: 38377 | AD57: 40799 | AF57: 89609 | AI57: 39173 | AJ57: 93294 | AK57: N/A | AN57: 39995 | AP57: 16311 | AQ57: 82570 | AR57: 90531 | AS57: 189412 | AW57: 39173 | AX57: 18869 | AY57: N/A | BB57: 39995 | BD57: 39349 | BE57: 35162 | BF57: 98694 | BH57: 173205
A58: 39539 | B58: 98952 | C58: N/A | J58: 40360 | K58: 1 | L58: 19158 | M58: 50706 | N58: 13900 | Q58: 83765 | U58: 39234 | V58: 1295 | W58: MHA-ELIGIBLE | AA58: 40360 | AB58: 9017 | AC58: 36953 | AD58: 37795 | AF58: 83765 | AI58: 39203 | AJ58: 118081 | AK58: N/A | AN58: 40026 | AP58: 25480 | AQ58: 89410 | AR58: 71783 | AS58: 186673 | AW58: 39203 | AX58: 25028 | AY58: < 2009-06 | BB58: 40026 | BD58: 41471 | BE58: 33907 | BF58: 79985 | BH58: 155363
A59: 39539 | B59: 44733 | C59: < 2009-06 | J59: 40391 | K59: 1120 | L59: 20121 | M59: 48810 | N59: 16488 | Q59: 86539 | U59: 39264 | V59: 53816 | W59: NOMHA-REFI | AA59: 40391 | AB59: 9218 | AC59: 32778 | AD59: 44543 | AF59: 86539 | AI59: 39203 | AJ59: 22875 | AK59: < 2009-06 | AN59: 40057 | AP59: 22620 | AQ59: 83867 | AR59: 45076 | AS59: 151563 | AW59: 39203 | AX59: 25321 | AY59: N/A | BB59: 40057 | BD59: 30038 | BE59: 25673 | BF59: 49944 | BH59: 105655
A60: 39569 | B60: 110414 | C60: N/A | J60: 40422 | K60: 326 | L60: 38354 | M60: 42017 | N60: 24337 | Q60: 105034 | U60: 39264 | V60: 63220 | W60: NOMHA-PURCHASE | AA60: 40422 | AB60: 16012 | AC60: 25077 | AD60: 63945 | AF60: 105034 | AI60: 39234 | AJ60: 122699 | AK60: N/A | AN60: 40087 | AP60: 16406 | AQ60: 62931 | AR60: 24616 | AS60: 103953 | AW60: 39234 | AX60: 26551 | AY60: < 2009-06 | BB60: 40087 | BD60: 21784 | BE60: 25546 | BF60: 32936 | BH60: 80266
A61: 39569 | B61: 41194 | C61: < 2009-06 | J61: 40452 | K61: 3 | L61: 36203 | M61: 39705 | N61: 29103 | Q61: 105014 | U61: 39264 | V61: 1176 | W61: MHA-ELIGIBLE | AA61: 40452 | AB61: 13956 | AC61: 21824 | AD61: 69234 | AF61: 105014 | AI61: 39234 | AJ61: 24801 | AK61: < 2009-06 | AN61: 40118 | AP61: 13051 | AQ61: 58846 | AR61: 20958 | AS61: 92855 | AW61: 39234 | AX61: 27815 | AY61: N/A | BB61: 40118 | BD61: 18281 | BE61: 24426 | BF61: 25969 | BH61: 68676
A62: 39600 | B62: 30865 | C62: < 2009-06 | J62: 40483 | K62: 24 | L62: 39308 | M62: 35585 | N62: 28907 | Q62: 103824 | U62: 39295 | V62: 55366 | W62: NOMHA-REFI | AA62: 40483 | AB62: 16014 | AC62: 19204 | AD62: 68606 | AF62: 103824 | AI62: 39264 | AJ62: 21810 | AK62: < 2009-06 | AN62: 40148 | AP62: 18179 | AQ62: 62802 | AR62: 26484 | AS62: 107465 | AW62: 39264 | AX62: 32290 | AY62: N/A | BB62: 40148 | BD62: 20048 | BE62: 26861 | BF62: 26137 | BH62: 73046
A63: 39600 | B63: 108177 | C63: N/A | J63: 40513 | K63: 3 | L63: 45723 | M63: 33399 | N63: 29330 | Q63: 108455 | U63: 39295 | V63: 77551 | W63: NOMHA-PURCHASE | AA63: 40513 | AB63: 17737 | AC63: 17561 | AD63: 73157 | AF63: 108455 | AI63: 39264 | AJ63: 125488 | AK63: N/A | AN63: 40179 | AP63: 23590 | AQ63: 60390 | AR63: 27562 | AS63: 111542 | AW63: 39264 | AX63: 26375 | AY63: < 2009-06 | BB63: 40179 | BD63: 22598 | BE63: 27023 | BF63: 27335 | BH63: 76956
A64: 39630 | B64: 62302 | C64: N/A | J64: 40544 | L64: 31180 | M64: 40868 | N64: 36053 | Q64: 108101 | U64: 39295 | V64: 1317 | W64: MHA-ELIGIBLE | AA64: 40544 | AB64: 14937 | AC64: 21831 | AD64: 71333 | AF64: 108101 | AI64: 39295 | AJ64: 118350 | AK64: N/A | AN64: 40210 | AP64: 26564 | AQ64: 54738 | AR64: 29806 | AS64: 111108 | AW64: 39295 | AX64: 21015 | AY64: < 2009-06 | BB64: 40210 | BD64: 26006 | BE64: 24131 | BF64: 31066 | BH64: 81203
A65: 39630 | B65: 15169 | C65: < 2009-06 | J65: 40575 | K65: 150 | L65: 36604 | M65: 38825 | N65: 24920 | Q65: 100499 | U65: 39326 | V65: 55888 | W65: NOMHA-REFI | AA65: 40575 | AB65: 17490 | AC65: 22007 | AD65: 61002 | AF65: 100499 | AI65: 39295 | AJ65: 17435 | AK65: < 2009-06 | AN65: 40238 | AP65: 24648 | AQ65: 43730 | AR65: 25134 | AS65: 93512 | AW65: 39295 | AX65: 29663 | AY65: N/A | BB65: 40238 | BD65: 24778 | BE65: 15542 | BF65: 24996 | BH65: 65316
A66: 39661 | B66: 68339 | C66: N/A | J66: 40603 | K66: 2646 | L66: 19980 | M66: 29596 | N66: 11405 | Q66: 63627 | U66: 39326 | V66: 97102 | W66: NOMHA-PURCHASE | AA66: 40603 | AB66: 10517 | AC66: 16260 | AD66: 36850 | AF66: 63627 | AI66: 39326 | AJ66: 113663 | AK66: N/A | AN66: 40269 | AP66: 17440 | AQ66: 42612 | AR66: 17800 | AS66: 77852 | AW66: 39326 | AX66: 24698 | AY66: N/A | BB66: 40269 | BD66: 19537 | BE66: 15025 | BF66: 16955 | BH66: 51517
A67: 39661 | B67: 12928 | C67: < 2009-06 | J67: 40634 | K67: 10 | L67: 18800 | M67: 24320 | N67: 9549 | Q67: 52679 | U67: 39326 | V67: 1309 | W67: MHA-ELIGIBLE | AA67: 40634 | AB67: 9118 | AC67: 15307 | AD67: 28254 | AF67: 52679 | AI67: 39326 | AJ67: 15467 | AK67: < 2009-06 | AN67: 40299 | AP67: 21045 | AQ67: 46375 | AR67: 16829 | AS67: 84249 | AW67: 39326 | AX67: 16987 | AY67: < 2009-06 | BB67: 40299 | BD67: 23581 | BE67: 24751 | BF67: 23261 | BH67: 71593
...

Sheet Sheet2
B1: N/A | C1: < 2009-06 | D1: NON-HARP | E1: HARP | F1: Unknown | X1: NOMHA-PURCHASE | Y1: NOMHA-REFI | Z1: MHA-ELIGIBLE | AE1: N/A | AF1: < 2009-06 | AG1: NON-HARPed | AH1: HARPed | AK1: FNMA | AM1: N/A | AN1: < 2009-06 | AO1: NON-HARPed | AP1: HARPed | AQ1: (blank)
A2: 38687 | B2: 116679 | C2: 19057 | W2: 38687 | X2: 69801 | Y2: 64164 | Z2: 1771 | AD2: 38353 | AE2: 1751 | AF2: 226 | AL2: 38353 | AM2: 18274 | AN2: 19296
A3: 38718 | B3: 101038 | C3: 15165 | W3: 38718 | X3: 56048 | Y3: 58448 | Z3: 1707 | AD3: 38384 | AE3: 1713 | AF3: 237 | AL3: 38384 | AM3: 17818 | AN3: 19367
A4: 38749 | B4: 85924 | C4: 13726 | W4: 38749 | X4: 48505 | Y4: 49549 | Z4: 1596 | AD4: 38412 | AE4: 1379 | AF4: 165 | AL4: 38412 | AM4: 14430 | AN4: 16217
A5: 38777 | B5: 85045 | C5: 13317 | W5: 38777 | X5: 45628 | Y5: 50913 | Z5: 1821 | AD5: 38443 | AE5: 1406 | AF5: 248 | AL5: 38443 | AM5: 16447 | AN5: 18282
A6: 38808 | B6: 91876 | C6: 13740 | W6: 38808 | X6: 50072 | Y6: 54093 | Z6: 1451 | AD6: 38473 | AE6: 1954 | AF6: 357 | AL6: 38473 | AM6: 21208 | AN6: 22945
A7: 38838 | B7: 83181 | C7: 11485 | W7: 38838 | X7: 50281 | Y7: 43099 | Z7: 1286 | AD7: 38504 | AE7: 2080 | AF7: 256 | AL7: 38504 | AM7: 20814 | AN7: 17249
A8: 38869 | B8: 96000 | C8: 11763 | W8: 38869 | X8: 60815 | Y8: 45484 | Z8: 1464 | AD8: 38534 | AE8: 2676 | AF8: 314 | AL8: 38534 | AM8: 25422 | AN8: 20889
A9: 38899 | B9: 94899 | C9: 10532 | W9: 38899 | X9: 62896 | Y9: 41248 | Z9: 1287 | AD9: 38565 | AE9: 3211 | AF9: 372 | AL9: 38565 | AM9: 32384 | AN9: 27493
A10: 38930 | B10: 106784 | C10: 11293 | W10: 38930 | X10: 74272 | Y10: 42532 | Z10: 1273 | AD10: 38596 | AE10: 4048 | AF10: 617 | AL10: 38596 | AM10: 29845 | AN10: 31231
A11: 38961 | B11: 107277 | C11: 11420 | W11: 38961 | X11: 74289 | Y11: 43129 | Z11: 1279 | AD11: 38626 | AE11: 7481 | AF11: 996 | AL11: 38626 | AM11: 29919 | AN11: 30344
A12: 38991 | B12: 92041 | C12: 11613 | W12: 38991 | X12: 59427 | Y12: 43075 | Z12: 1152 | AD12: 38657 | AE12: 15991 | AF12: 2199 | AL12: 38657 | AM12: 25968 | AN12: 27266
A13: 39022 | B13: 83109 | C13: 13547 | W13: 39022 | X13: 48845 | Y13: 46704 | Z13: 1107 | AD13: 38687 | AE13: 58394 | AF13: 9660 | AL13: 38687 | AM13: 23032 | AN13: 26896
... A41: 39873 | B41: 90938 | C41: 126468 | W41: 39873 | X41: 27687 | Y41: 187401 | Z41: 2318 | AD41: 39539 | AE41: 99187 | AF41: 60058 | AL41: 39539 | AM41: 22787 | AN41: 42764
A42: 39904 | B42: 70127 | C42: 91317 | D42: 4758 | E42: 286 | W42: 39904 | X42: 24673 | Y42: 140030 | Z42: 1785 | AD42: 39569 | AE42: 102401 | AF42: 41596 | AL42: 39569 | AM42: 21383 | AN42: 31567
A43: 39934 | B43: 67567 | C43: 25662 | D43: 51705 | E43: 5842 | W43: 39934 | X43: 24641 | Y43: 123547 | Z43: 2588 | AD43: 39600 | AE43: 98365 | AF43: 38213 | AL43: 39600 | AM43: 22525 | AN43: 29505
A44: 39965 | B44: 104095 | C44: 7053 | D44: 106391 | E44: 16517 | W44: 39965 | X44: 41335 | Y44: 183268 | Z44: 9453 | AD44: 39630 | AE44: 81925 | AF44: 23471 | AL44: 39630 | AM44: 23075 | AN44: 22067
A45: 39995 | B45: 71014 | C45: 781 | D45: 60337 | E45: 22075 | W45: 39995 | X45: 32476 | Y45: 107233 | Z45: 14498 | AD45: 39661 | AE45: 80739 | AF45: 17448 | AL45: 39661 | AM45: 19612 | AN45: 15491
A46: 40026 | B46: 82357 | C46: 173 | D46: 55906 | E46: 25210 | W46: 40026 | X46: 42643 | Y46: 104917 | Z46: 16086 | AD46: 39692 | AE46: 67217 | AF46: 11582 | AL46: 39692 | AM46: 15980 | AN46: 10494
A47: 40057 | B47: 70570 | C47: 258 | D47: 31910 | E47: 15667 | W47: 40057 | X47: 41473 | Y47: 67936 | Z47: 8996 | AD47: 39722 | AE47: 45117 | AF47: 7202 | AL47: 39722 | AM47: 14635 | AN47: 8915
A48: 40087 | B48: 61209 | C48: 1059 | D48: 23119 | E48: 12098 | W48: 40087 | X48: 37039 | Y48: 54105 | Z48: 6341 | AD48: 39753 | AE48: 50694 | AF48: 10585 | AL48: 39753 | AM48: 14115 | AN48: 9826
A49: 40118 | B49: 54618 | C49: 77 | D49: 22548 | E49: 16580 | W49: 40118 | X49: 32297 | Y49: 53423 | Z49: 8103 | AD49: 39783 | AE49: 52103 | AF49: 15821 | AL49: 39783 | AM49: 15394 | AN49: 12743
A50: 40148 | B50: 70439 | C50: 336 | D50: 30548 | E50: 25493 | W50: 40148 | X50: 42345 | Y50: 71676 | Z50: 12795 | AD50: 39814 | AE50: 32448 | AF50: 7542 | AL50: 39814 | AM50: 11771 | AN50: 9484
A51: 40179 | B51: 51271 | C51: 360 | D51: 24350 | E51: 24649 | W51: 40179 | X51: 29955 | Y51: 57979 | Z51: 12696 | AD51: 39845 | AE51: 52470 | AF51: 32323 | AL51: 39845 | AM51: 15596 | AN51: 20177
A52: 40210 | B52: 51586 | C52: 77 | D52: 28003 | E52: 26299 | W52: 40210 | X52: 27636 | Y52: 64815 | Z52: 13514 | AD52: 39873 | AE52: 58125 | AF52: 81505 | AL52: 39873 | AM52: 17183 | AN52: 66165
A53: 40238 | B53: 56751 | C53: 679 | D53: 25937 | E53: 21183 | W53: 40238 | X53: 30875 | Y53: 61902 | Z53: 11773 | AD53: 39904 | AE53: 72314 | AF53: 104826 | AL53: 39904 | AM53: 19205 | AN53: 81476
A54: 40269 | B54: 37231 | C54: 113 | D54: 14416 | E54: 19513 | W54: 40269 | X54: 23058 | Y54: 37869 | Z54: 10346 | AD54: 39934 | AE54: 87478 | AF54: 108692 | AL54: 39934 | AM54: 22244 | AN54: 84588
A55: 40299 | B55: 46855 | C55: 25 | D55: 15988 | E55: 17575 | W55: 40299 | X55: 30710 | Y55: 40562 | Z55: 9171 | AD55: 39965 | AE55: 80976 | AG55: 94312 | AH55: 10383 | AL55: 39965 | AM55: 27796 | AO55: 81756 | AP55: 22119
A56: 40330 | B56: 55813 | C56: 4 | D56: 14269 | E56: 19523 | W56: 40330 | X56: 38377 | Y56: 40799 | Z56: 10433 | AD56: 39995 | AE56: 82570 | AG56: 90531 | AH56: 16311 | AL56: 39995 | AM56: 35162 | AO56: 98694 | AP56: 39349
A57: 40360 | B57: 50706 | C57: 1 | D57: 13900 | E57: 19158 | W57: 40360 | X57: 36953 | Y57: 37795 | Z57: 9017 | AD57: 40026 | AE57: 89410 | AG57: 71783 | AH57: 25480 | AL57: 40026 | AM57: 33907 | AO57: 79985 | AP57: 41471
A58: 40391 | B58: 48810 | C58: 1120 | D58: 16488 | E58: 20121 | W58: 40391 | X58: 32778 | Y58: 44543 | Z58: 9218 | AD58: 40057 | AE58: 83867 | AG58: 45076 | AH58: 22620 | AL58: 40057 | AM58: 25673 | AO58: 49944 | AP58: 30038
A59: 40422 | B59: 42017 | C59: 326 | D59: 24337 | E59: 38354 | W59: 40422 | X59: 25077 | Y59: 63945 | Z59: 16012 | AD59: 40087 | AE59: 62931 | AG59: 24616 | AH59: 16406 | AL59: 40087 | AM59: 25546 | AO59: 32936 | AP59: 21784
A60: 40452 | B60: 39705 | C60: 3 | D60: 29103 | E60: 36203 | W60: 40452 | X60: 21824 | Y60: 69234 | Z60: 13956 | AD60: 40118 | AE60: 58846 | AG60: 20958 | AH60: 13051 | AL60: 40118 | AM60: 24426 | AO60: 25969 | AP60: 18281
A61: 40483 | B61: 35585 | C61: 24 | D61: 28907 | E61: 39308 | W61: 40483 | X61: 19204 | Y61: 68606 | Z61: 16014 | AD61: 40148 | AE61: 62802 | AG61: 26484 | AH61: 18179 | AL61: 40148 | AM61: 26861 | AO61: 26137 | AP61: 20048
A62: 40513 | B62: 33399 | C62: 3 | D62: 29330 | E62: 45723 | W62: 40513 | X62: 17561 | Y62: 73157 | Z62: 17737 | AD62: 40179 | AE62: 60390 | AG62: 27562 | AH62: 23590 | AL62: 40179 | AM62: 27023 | AO62: 27335 | AP62: 22598
A63: 40544 | B63: 40868 | D63: 36053 | E63: 31180 | W63: 40544 | X63: 21831 | Y63: 71333 | Z63: 14937 | AD63: 40210 | AE63: 54738 | AG63: 29806 | AH63: 26564 | AL63: 40210 | AM63: 24131 | AO63: 31066 | AP63: 26006
A64: 40575 | B64: 38825 | C64: 150 | D64: 24920 | E64: 36604 | W64: 40575 | X64: 22007 | Y64: 61002 | Z64: 17490 | AD64: 40238 | AE64: 43730 | AG64: 25134 | AH64: 24648 | AL64: 40238 | AM64: 15542 | AO64: 24996 | AP64: 24778
A65: 40603 | B65: 29596 | C65: 2646 | D65: 11405 | E65: 19980 | W65: 40603 | X65: 16260 | Y65: 36850 | Z65: 10517 | AD65: 40269 | AE65: 42612 | AG65: 17800 | AH65: 17440 | AL65: 40269 | AM65: 15025 | AO65: 16955 | AP65: 19537
A66: 40634 | B66: 24320 | C66: 10 | D66: 9549 | E66: 18800 | W66: 40634 | X66: 15307 | Y66: 28254 | Z66: 9118 | AD66: 40299 | AE66: 46375 | AG66: 16829 | AH66: 21045 | AL66: 40299 | AM66: 24751 | AO66: 23261 | AP66: 23581
A67: 40664 | B67: 26412 | D67: 7249 | E67: 12820 | W67: 40664 | X67: 18349 | Y67: 22304 | Z67: 5828 | AD67: 40330 | AE67: 49599 | AG67: 14699 | AH67: 19445 | AL67: 40330 | AM67: 26297 | AO67: 19774 | AP67: 21651
...

Sheet Sheet3
C2: =C3-C4 -> 1679.9 | D2: =C2/6 -> 279.98333 | E2: =D2/2 -> 139.99167 | I2: 300 | J2: =I2/8 -> 37.5
C3: 2243.8 | D3: =C3/6 -> 373.96667 | E3: =D3/2 -> 186.98333
C4: 563.9 | D4: =C4/6 -> 93.983333
D5: 225 | E5: =D5/2 -> 112.5
E6: =E3+E5 -> 299.48333
F10: 2.783 | G10: 2.783
F11: 93.6 | G11: =G12-G10 -> 1.037
F12: =F10+F11/100 -> 3.719 | G12: 3.82
A18: 2016-01-07 | B18: 2.9119507 | C18: 3.82 | D18: 1 | E18: 0.2 | F18: 1 | G18: 0.58239014 | H18: 0.2 | I18: 0 | J18: 0 | K18: 0.88815503
A19: 2016-01-08 | B19: 2.8854568 | C19: 3.82 | D19: 2 | E19: 0.2 | F19: 2 | G19: 1.1594815 | H19: 0.4 | I19: 0 | J19: 0 | K19: 0.88815503
A20: 2016-01-11 | B20: 2.8978342 | C20: 3.82 | D20: 5 | E20: 0.2 | F20: 3 | G20: 1.7390483 | H20: 0.6 | I20: 0 | J20: 0 | K20: 0.88815503
A21: 2016-01-12 | B21: 2.8424739 | C21: 3.82 | D21: 6 | E21: 0.2 | F21: 4 | G21: 2.3075431 | H21: 0.8 | I21: 2.8844289 | J21: 0.93557109 | K21: 0.93557109
B27: count() | C27: HARPStatus
B28: 1071585 | C28: < 2009-06 | D28: 1
B29: 1270049 | C29: HARP | D29: 1
B30: 7769037 | C30: N/A | D30: 1
B31: 1512868 | C31: NON-HARP | D31: 1
B32: 450103 | C32: Unknown
B34: count() | C34: MHAStatus
B35: 743314 | C35: MHA-ELIGIBLE
B36: 4968713 | C36: NOMHA-PURCHASE
B37: 6361615 | C37: NOMHA-REFI
B43: Old
B44: All | F44: 2015
B45: MHAStatus | C45: count(1) | F45: MHAStatus | G45: count(1)
B46: MHA-ELIGIBLE | C46: 1412406 | F46: MHA-ELIGIBLE | G46: 45056
B47: NOMHA-PURCHASE | C47: 5701166 | F47: NOMHA-PURCHASE | G47: 629706
B48: NOMHA-REFI-CO | C48: 4306137 | F48: NOMHA-REFI-CO | G48: 295887
B49: NOMHA-REFI-NCO | C49: 5961898 | F49: NOMHA-REFI | G49: 463837
C50: =SUM(C46:C49) -> 17381607 | G50: =SUM(G46:G49) -> 1434486
B52: MHAStatus | C52: count(1)
C53: 17381607
B56: MHAStatus | C56: count(1) | F56: MHAStatus | G56: count(1)
B57: MHA-ELIGIBLE | C57: 1448911 | F57: MHA-ELIGIBLE | G57: 45105
B58: NOMHA-PURCHASE | C58: 5701166 | F58: NOMHA-PURCHASE | G58: 629706
B59: NOMHA-REFI | C59: 10150562 | F59: NOMHA-REFI-NCO | G59: 759675
B60: MISC-VERIFY | C60: 80968 | F60: MISC-VERIFY | G60: 0
C61: =SUM(C57:C60) -> 17381607
B66: New
B67: HARPStatus | C67: count(1) | F67: HARPStatus | G67: count(1)
...

Sheet Sheet5
B1: N/A | C1: < 2009-06 | D1: NON-HARP | E1: HARP | F1: Unknown | G1: Total | J1: NOMHA-PURCHASE | K1: NOMHA-REFI | L1: MHA-ELIGIBLE | M1: Total | R1: New | S1: Old | T1: Ratio
A2: 38687 | B2: 116679 | C2: 19057 | G2: =SUM(B2:F2) -> 135736 | I2: 38687 | J2: 69801 | K2: 64164 | L2: 1771 | M2: =SUM(J2:L2) -> 135736 | Q2: 38687 | R2: =VLOOKUP(Q2,A:F,5,0) -> 0 | S2: =VLOOKUP(Q2,I:M,4,0) -> 1771
A3: 38718 | B3: 101038 | C3: 15165 | G3: =SUM(B3:F3) -> 116203 | I3: 38718 | J3: 56048 | K3: 58448 | L3: 1707 | M3: =SUM(J3:L3) -> 116203 | Q3: 38718 | R3: =VLOOKUP(Q3,A:F,5,0) -> 0 | S3: =VLOOKUP(Q3,I:M,4,0) -> 1707
A4: 38749 | B4: 85924 | C4: 13726 | G4: =SUM(B4:F4) -> 99650 | I4: 38749 | J4: 48505 | K4: 49549 | L4: 1596 | M4: =SUM(J4:L4) -> 99650 | Q4: 38749 | R4: =VLOOKUP(Q4,A:F,5,0) -> 0 | S4: =VLOOKUP(Q4,I:M,4,0) -> 1596
A5: 38777 | B5: 85045 | C5: 13317 | G5: =SUM(B5:F5) -> 98362 | I5: 38777 | J5: 45628 | K5: 50913 | L5: 1821 | M5: =SUM(J5:L5) -> 98362 | Q5: 38777 | R5: =VLOOKUP(Q5,A:F,5,0) -> 0 | S5: =VLOOKUP(Q5,I:M,4,0) -> 1821
A6: 38808 | B6: 91876 | C6: 13740 | G6: =SUM(B6:F6) -> 105616 | I6: 38808 | J6: 50072 | K6: 54093 | L6: 1451 | M6: =SUM(J6:L6) -> 105616 | Q6: 38808 | R6: =VLOOKUP(Q6,A:F,5,0) -> 0 | S6: =VLOOKUP(Q6,I:M,4,0) -> 1451
A7: 38838 | B7: 83181 | C7: 11485 | G7: =SUM(B7:F7) -> 94666 | I7: 38838 | J7: 50281 | K7: 43099 | L7: 1286 | M7: =SUM(J7:L7) -> 94666 | Q7: 38838 | R7: =VLOOKUP(Q7,A:F,5,0) -> 0 | S7: =VLOOKUP(Q7,I:M,4,0) -> 1286
A8: 38869 | B8: 96000 | C8: 11763 | G8: =SUM(B8:F8) -> 107763 | I8: 38869 | J8: 60815 | K8: 45484 | L8: 1464 | M8: =SUM(J8:L8) -> 107763 | Q8: 38869 | R8: =VLOOKUP(Q8,A:F,5,0) -> 0 | S8: =VLOOKUP(Q8,I:M,4,0) -> 1464
A9: 38899 | B9: 94899 | C9: 10532 | G9: =SUM(B9:F9) -> 105431 | I9: 38899 | J9: 62896 | K9: 41248 | L9: 1287 | M9: =SUM(J9:L9) -> 105431 | Q9: 38899 | R9: =VLOOKUP(Q9,A:F,5,0) -> 0 | S9: =VLOOKUP(Q9,I:M,4,0) -> 1287
A10: 38930 | B10: 106784 | C10: 11293 | G10: =SUM(B10:F10) -> 118077 | I10: 38930 | J10: 74272 | K10: 42532 | L10: 1273 | M10: =SUM(J10:L10) -> 118077 | Q10: 38930 | R10: =VLOOKUP(Q10,A:F,5,0) -> 0 | S10: =VLOOKUP(Q10,I:M,4,0) -> 1273
A11: 38961 | B11: 107277 | C11: 11420 | G11: =SUM(B11:F11) -> 118697 | I11: 38961 | J11: 74289 | K11: 43129 | L11: 1279 | M11: =SUM(J11:L11) -> 118697 | Q11: 38961 | R11: =VLOOKUP(Q11,A:F,5,0) -> 0 | S11: =VLOOKUP(Q11,I:M,4,0) -> 1279
A12: 38991 | B12: 92041 | C12: 11613 | G12: =SUM(B12:F12) -> 103654 | I12: 38991 | J12: 59427 | K12: 43075 | L12: 1152 | M12: =SUM(J12:L12) -> 103654 | Q12: 38991 | R12: =VLOOKUP(Q12,A:F,5,0) -> 0 | S12: =VLOOKUP(Q12,I:M,4,0) -> 1152
A13: 39022 | B13: 83109 | C13: 13547 | G13: =SUM(B13:F13) -> 96656 | I13: 39022 | J13: 48845 | K13: 46704 | L13: 1107 | M13: =SUM(J13:L13) -> 96656 | Q13: 39022 | R13: =VLOOKUP(Q13,A:F,5,0) -> 0 | S13: =VLOOKUP(Q13,I:M,4,0) -> 1107
... A41: 39873 | B41: 90938 | C41: 126468 | G41: =SUM(B41:F41) -> 217406 | I41: 39873 | J41: 27687 | K41: 187401 | L41: 2318 | M41: =SUM(J41:L41) -> 217406 | Q41: 39873 | R41: =VLOOKUP(Q41,A:F,5,0) -> 0 | S41: =VLOOKUP(Q41,I:M,4,0) -> 2318
A42: 39904 | B42: 70127 | C42: 91317 | D42: 4758 | E42: 286 | G42: =SUM(B42:F42) -> 166488 | I42: 39904 | J42: 24673 | K42: 140030 | L42: 1785 | M42: =SUM(J42:L42) -> 166488 | Q42: 39904 | R42: =VLOOKUP(Q42,A:F,5,0) -> 286 | S42: =VLOOKUP(Q42,I:M,4,0) -> 1785
A43: 39934 | B43: 67567 | C43: 25662 | D43: 51705 | E43: 5842 | G43: =SUM(B43:F43) -> 150776 | I43: 39934 | J43: 24641 | K43: 123547 | L43: 2588 | M43: =SUM(J43:L43) -> 150776 | Q43: 39934 | R43: =VLOOKUP(Q43,A:F,5,0) -> 5842 | S43: =VLOOKUP(Q43,I:M,4,0) -> 2588
A44: 39965 | B44: 104095 | C44: 7053 | D44: 106391 | E44: 16517 | G44: =SUM(B44:F44) -> 234056 | I44: 39965 | J44: 41335 | K44: 183268 | L44: 9453 | M44: =SUM(J44:L44) -> 234056 | Q44: 39965 | R44: =VLOOKUP(Q44,A:F,5,0) -> 16517 | S44: =VLOOKUP(Q44,I:M,4,0) -> 9453
A45: 39995 | B45: 71014 | C45: 781 | D45: 60337 | E45: 22075 | G45: =SUM(B45:F45) -> 154207 | I45: 39995 | J45: 32476 | K45: 107233 | L45: 14498 | M45: =SUM(J45:L45) -> 154207 | Q45: 39995 | R45: =VLOOKUP(Q45,A:F,5,0) -> 22075 | S45: =VLOOKUP(Q45,I:M,4,0) -> 14498 | T45: =R45/S45 -> 1.5226238
A46: 40026 | B46: 82357 | C46: 173 | D46: 55906 | E46: 25210 | G46: =SUM(B46:F46) -> 163646 | I46: 40026 | J46: 42643 | K46: 104917 | L46: 16086 | M46: =SUM(J46:L46) -> 163646 | Q46: 40026 | R46: =VLOOKUP(Q46,A:F,5,0) -> 25210 | S46: =VLOOKUP(Q46,I:M,4,0) -> 16086 | T46: =R46/S46 -> 1.5672013 | AC46: 2243 | AD46: =AC46/6 -> 373.83333
A47: 40057 | B47: 70570 | C47: 258 | D47: 31910 | E47: 15667 | G47: =SUM(B47:F47) -> 118405 | I47: 40057 | J47: 41473 | K47: 67936 | L47: 8996 | M47: =SUM(J47:L47) -> 118405 | Q47: 40057 | R47: =VLOOKUP(Q47,A:F,5,0) -> 15667 | S47: =VLOOKUP(Q47,I:M,4,0) -> 8996 | T47: =R47/S47 -> 1.7415518 | AC47: 564 | AD47: =AC47/6 -> 94
A48: 40087 | B48: 61209 | C48: 1059 | D48: 23119 | E48: 12098 | G48: =SUM(B48:F48) -> 97485 | I48: 40087 | J48: 37039 | K48: 54105 | L48: 6341 | M48: =SUM(J48:L48) -> 97485 | Q48: 40087 | R48: =VLOOKUP(Q48,A:F,5,0) -> 12098 | S48: =VLOOKUP(Q48,I:M,4,0) -> 6341 | T48: =R48/S48 -> 1.907901 | AC48: =AC46-AC47 -> 1679 | AD48: =AC48/6 -> 279.83333
A49: 40118 | B49: 54618 | C49: 77 | D49: 22548 | E49: 16580 | G49: =SUM(B49:F49) -> 93823 | I49: 40118 | J49: 32297 | K49: 53423 | L49: 8103 | M49: =SUM(J49:L49) -> 93823 | Q49: 40118 | R49: =VLOOKUP(Q49,A:F,5,0) -> 16580 | S49: =VLOOKUP(Q49,I:M,4,0) -> 8103 | T49: =R49/S49 -> 2.0461557
A50: 40148 | B50: 70439 | C50: 336 | D50: 30548 | E50: 25493 | G50: =SUM(B50:F50) -> 126816 | I50: 40148 | J50: 42345 | K50: 71676 | L50: 12795 | M50: =SUM(J50:L50) -> 126816 | Q50: 40148 | R50: =VLOOKUP(Q50,A:F,5,0) -> 25493 | S50: =VLOOKUP(Q50,I:M,4,0) -> 12795 | T50: =R50/S50 -> 1.9924189
A51: 40179 | B51: 51271 | C51: 360 | D51: 24350 | E51: 24649 | G51: =SUM(B51:F51) -> 100630 | I51: 40179 | J51: 29955 | K51: 57979 | L51: 12696 | M51: =SUM(J51:L51) -> 100630 | Q51: 40179 | R51: =VLOOKUP(Q51,A:F,5,0) -> 24649 | S51: =VLOOKUP(Q51,I:M,4,0) -> 12696 | T51: =R51/S51 -> 1.9414776
A52: 40210 | B52: 51586 | C52: 77 | D52: 28003 | E52: 26299 | G52: =SUM(B52:F52) -> 105965 | I52: 40210 | J52: 27636 | K52: 64815 | L52: 13514 | M52: =SUM(J52:L52) -> 105965 | Q52: 40210 | R52: =VLOOKUP(Q52,A:F,5,0) -> 26299 | S52: =VLOOKUP(Q52,I:M,4,0) -> 13514 | T52: =R52/S52 -> 1.9460559
A53: 40238 | B53: 56751 | C53: 679 | D53: 25937 | E53: 21183 | G53: =SUM(B53:F53) -> 104550 | I53: 40238 | J53: 30875 | K53: 61902 | L53: 11773 | M53: =SUM(J53:L53) -> 104550 | Q53: 40238 | R53: =VLOOKUP(Q53,A:F,5,0) -> 21183 | S53: =VLOOKUP(Q53,I:M,4,0) -> 11773 | T53: =R53/S53 -> 1.7992865
A54: 40269 | B54: 37231 | C54: 113 | D54: 14416 | E54: 19513 | G54: =SUM(B54:F54) -> 71273 | I54: 40269 | J54: 23058 | K54: 37869 | L54: 10346 | M54: =SUM(J54:L54) -> 71273 | Q54: 40269 | R54: =VLOOKUP(Q54,A:F,5,0) -> 19513 | S54: =VLOOKUP(Q54,I:M,4,0) -> 10346 | T54: =R54/S54 -> 1.8860429
A55: 40299 | B55: 46855 | C55: 25 | D55: 15988 | E55: 17575 | G55: =SUM(B55:F55) -> 80443 | I55: 40299 | J55: 30710 | K55: 40562 | L55: 9171 | M55: =SUM(J55:L55) -> 80443 | Q55: 40299 | R55: =VLOOKUP(Q55,A:F,5,0) -> 17575 | S55: =VLOOKUP(Q55,I:M,4,0) -> 9171 | T55: =R55/S55 -> 1.9163668
A56: 40330 | B56: 55813 | C56: 4 | D56: 14269 | E56: 19523 | G56: =SUM(B56:F56) -> 89609 | I56: 40330 | J56: 38377 | K56: 40799 | L56: 10433 | M56: =SUM(J56:L56) -> 89609 | Q56: 40330 | R56: =VLOOKUP(Q56,A:F,5,0) -> 19523 | S56: =VLOOKUP(Q56,I:M,4,0) -> 10433 | T56: =R56/S56 -> 1.8712738
A57: 40360 | B57: 50706 | C57: 1 | D57: 13900 | E57: 19158 | G57: =SUM(B57:F57) -> 83765 | I57: 40360 | J57: 36953 | K57: 37795 | L57: 9017 | M57: =SUM(J57:L57) -> 83765 | Q57: 40360 | R57: =VLOOKUP(Q57,A:F,5,0) -> 19158 | S57: =VLOOKUP(Q57,I:M,4,0) -> 9017 | T57: =R57/S57 -> 2.1246534
A58: 40391 | B58: 48810 | C58: 1120 | D58: 16488 | E58: 20121 | G58: =SUM(B58:F58) -> 86539 | I58: 40391 | J58: 32778 | K58: 44543 | L58: 9218 | M58: =SUM(J58:L58) -> 86539 | Q58: 40391 | R58: =VLOOKUP(Q58,A:F,5,0) -> 20121 | S58: =VLOOKUP(Q58,I:M,4,0) -> 9218 | T58: =R58/S58 -> 2.1827945
A59: 40422 | B59: 42017 | C59: 326 | D59: 24337 | E59: 38354 | G59: =SUM(B59:F59) -> 105034 | I59: 40422 | J59: 25077 | K59: 63945 | L59: 16012 | M59: =SUM(J59:L59) -> 105034 | Q59: 40422 | R59: =VLOOKUP(Q59,A:F,5,0) -> 38354 | S59: =VLOOKUP(Q59,I:M,4,0) -> 16012 | T59: =R59/S59 -> 2.3953285
A60: 40452 | B60: 39705 | C60: 3 | D60: 29103 | E60: 36203 | G60: =SUM(B60:F60) -> 105014 | I60: 40452 | J60: 21824 | K60: 69234 | L60: 13956 | M60: =SUM(J60:L60) -> 105014 | Q60: 40452 | R60: =VLOOKUP(Q60,A:F,5,0) -> 36203 | S60: =VLOOKUP(Q60,I:M,4,0) -> 13956 | T60: =R60/S60 -> 2.5940814
... A62: 40513 | B62: 33399 | C62: 3 | D62: 29330 | E62: 45723 | G62: =SUM(B62:F62) -> 108455 | I62: 40513 | J62: 17561 | K62: 73157 | L62: 17737 | M62: =SUM(J62:L62) -> 108455 | Q62: 40513 | R62: =VLOOKUP(Q62,A:F,5,0) -> 45723 | S62: =VLOOKUP(Q62,I:M,4,0) -> 17737 | T62: =R62/S62 -> 2.5778317
A63: 40544 | B63: 40868 | D63: 36053 | E63: 31180 | G63: =SUM(B63:F63) -> 108101 | I63: 40544 | J63: 21831 | K63: 71333 | L63: 14937 | M63: =SUM(J63:L63) -> 108101 | Q63: 40544 | R63: =VLOOKUP(Q63,A:F,5,0) -> 31180 | S63: =VLOOKUP(Q63,I:M,4,0) -> 14937 | T63: =R63/S63 -> 2.0874339
A64: 40575 | B64: 38825 | C64: 150 | D64: 24920 | E64: 36604 | G64: =SUM(B64:F64) -> 100499 | I64: 40575 | J64: 22007 | K64: 61002 | L64: 17490 | M64: =SUM(J64:L64) -> 100499 | Q64: 40575 | R64: =VLOOKUP(Q64,A:F,5,0) -> 36604 | S64: =VLOOKUP(Q64,I:M,4,0) -> 17490 | T64: =R64/S64 -> 2.0928531
A65: 40603 | B65: 29596 | C65: 2646 | D65: 11405 | E65: 19980 | G65: =SUM(B65:F65) -> 63627 | I65: 40603 | J65: 16260 | K65: 36850 | L65: 10517 | M65: =SUM(J65:L65) -> 63627 | Q65: 40603 | R65: =VLOOKUP(Q65,A:F,5,0) -> 19980 | S65: =VLOOKUP(Q65,I:M,4,0) -> 10517 | T65: =R65/S65 -> 1.8997813
A66: 40634 | B66: 24320 | C66: 10 | D66: 9549 | E66: 18800 | G66: =SUM(B66:F66) -> 52679 | I66: 40634 | J66: 15307 | K66: 28254 | L66: 9118 | M66: =SUM(J66:L66) -> 52679 | Q66: 40634 | R66: =VLOOKUP(Q66,A:F,5,0) -> 18800 | S66: =VLOOKUP(Q66,I:M,4,0) -> 9118 | T66: =R66/S66 -> 2.0618557
A67: 40664 | B67: 26412 | D67: 7249 | E67: 12820 | G67: =SUM(B67:F67) -> 46481 | I67: 40664 | J67: 18349 | K67: 22304 | L67: 5828 | M67: =SUM(J67:L67) -> 46481 | Q67: 40664 | R67: =VLOOKUP(Q67,A:F,5,0) -> 12820 | S67: =VLOOKUP(Q67,I:M,4,0) -> 5828 | T67: =R67/S67 -> 2.1997255
A68: 40695 | B68: 32058 | D68: 7079 | E68: 12588 | G68: =SUM(B68:F68) -> 51725 | I68: 40695 | J68: 23616 | K68: 22239 | L68: 5870 | M68: =SUM(J68:L68) -> 51725 | Q68: 40695 | R68: =VLOOKUP(Q68,A:F,5,0) -> 12588 | S68: =VLOOKUP(Q68,I:M,4,0) -> 5870 | T68: =R68/S68 -> 2.1444634
...

Sheet >80 LTV
A4: pmtdate | B4: count() | C4: HARPStatus | G4: pmtdate | H4: count() | I4: MHAStatus | M4: Sum of count() | N4: Column Labels | W4: Sum of count() | X4: Column Labels
A5: 38353 | B5: 865 | C5: N/A | G5: 38353 | H5: 826 | I5: NOMHA-PURCHASE | M5: Row Labels | N5: < 2009-06 | O5: HARP | P5: N/A | Q5: NON-HARP | R5: Unknown | S5: Grand Total | W5: Row Labels | X5: MHA-ELIGIBLE | Y5: NOMHA-PURCHASE | Z5: NOMHA-REFI | AA5: Grand Total | AF5: HARP-I | AG5: HARP-II | AH5: Ratio II/I | AI5: Total-I | AJ5: Total-II
A6: 38353 | B6: 23 | C6: < 2009-06 | G6: 38353 | H6: 44 | I6: MHA-ELIGIBLE | M6: 38353 | N6: 23 | P6: 865 | S6: 888 | W6: 38353 | X6: 44 | Y6: 826 | Z6: 18 | AA6: 888 | AE6: 39965 | AF6: =VLOOKUP(AE6,W:AB,2,0) -> 4272 | AG6: =VLOOKUP(AE6,M:S,3,0) -> 3673 | AH6: =AG6/AF6 -> 0.85978464 | AI6: =VLOOKUP(AE6,W:AB,5,0) -> 16449 | AJ6: =VLOOKUP(AE6,M:S,7,0) -> 16449
A7: 38384 | B7: 37 | C7: < 2009-06 | G7: 38353 | H7: 18 | I7: NOMHA-REFI | M7: 38384 | N7: 37 | P7: 843 | S7: 880 | W7: 38384 | X7: 49 | Y7: 813 | Z7: 18 | AA7: 880 | AE7: 39995 | AF7: =VLOOKUP(AE7,W:AB,2,0) -> 9557 | AG7: =VLOOKUP(AE7,M:S,3,0) -> 9247 | AH7: =AG7/AF7 -> 0.96756304 | AI7: =VLOOKUP(AE7,W:AB,5,0) -> 21488 | AJ7: =VLOOKUP(AE7,M:S,7,0) -> 21488
A8: 38384 | B8: 843 | C8: N/A | G8: 38384 | H8: 49 | I8: MHA-ELIGIBLE | M8: 38412 | N8: 24 | P8: 643 | S8: 667 | W8: 38412 | X8: 30 | Y8: 614 | Z8: 23 | AA8: 667 | AE8: 40026 | AF8: =VLOOKUP(AE8,W:AB,2,0) -> 15810 | AG8: =VLOOKUP(AE8,M:S,3,0) -> 15370 | AH8: =AG8/AF8 -> 0.97216951 | AI8: =VLOOKUP(AE8,W:AB,5,0) -> 28635 | AJ8: =VLOOKUP(AE8,M:S,7,0) -> 28635
A9: 38412 | B9: 643 | C9: N/A | G9: 38384 | H9: 813 | I9: NOMHA-PURCHASE | M9: 38443 | N9: 34 | P9: 600 | S9: 634 | W9: 38443 | X9: 35 | Y9: 571 | Z9: 28 | AA9: 634 | AE9: 40057 | AF9: =VLOOKUP(AE9,W:AB,2,0) -> 14494 | AG9: =VLOOKUP(AE9,M:S,3,0) -> 14029 | AH9: =AG9/AF9 -> 0.96791776 | AI9: =VLOOKUP(AE9,W:AB,5,0) -> 26615 | AJ9: =VLOOKUP(AE9,M:S,7,0) -> 26615
A10: 38412 | B10: 24 | C10: < 2009-06 | G10: 38384 | H10: 18 | I10: NOMHA-REFI | M10: 38473 | N10: 29 | P10: 713 | S10: 742 | W10: 38473 | X10: 28 | Y10: 695 | Z10: 19 | AA10: 742 | AE10: 40087 | AF10: =VLOOKUP(AE10,W:AB,2,0) -> 9396 | AG10: =VLOOKUP(AE10,M:S,3,0) -> 9135 | AH10: =AG10/AF10 -> 0.97222222 | AI10: =VLOOKUP(AE10,W:AB,5,0) -> 18752 | AJ10: =VLOOKUP(AE10,M:S,7,0) -> 18752
A11: 38443 | B11: 34 | C11: < 2009-06 | G11: 38412 | H11: 23 | I11: NOMHA-REFI | M11: 38504 | N11: 28 | P11: 794 | S11: 822 | W11: 38504 | X11: 16 | Y11: 767 | Z11: 39 | AA11: 822 | AE11: 40118 | AF11: =VLOOKUP(AE11,W:AB,2,0) -> 7014 | AG11: =VLOOKUP(AE11,M:S,3,0) -> 6784 | AH11: =AG11/AF11 -> 0.96720844 | AI11: =VLOOKUP(AE11,W:AB,5,0) -> 15438 | AJ11: =VLOOKUP(AE11,M:S,7,0) -> 15438
A12: 38443 | B12: 600 | C12: N/A | G12: 38412 | H12: 30 | I12: MHA-ELIGIBLE | M12: 38534 | N12: 59 | P12: 999 | S12: 1058 | W12: 38534 | X12: 39 | Y12: 949 | Z12: 70 | AA12: 1058 | AE12: 40148 | AF12: =VLOOKUP(AE12,W:AB,2,0) -> 9189 | AG12: =VLOOKUP(AE12,M:S,3,0) -> 8893 | AH12: =AG12/AF12 -> 0.96778757 | AI12: =VLOOKUP(AE12,W:AB,5,0) -> 18116 | AJ12: =VLOOKUP(AE12,M:S,7,0) -> 18116
A13: 38473 | B13: 713 | C13: N/A | G13: 38412 | H13: 614 | I13: NOMHA-PURCHASE | M13: 38565 | N13: 54 | P13: 1154 | S13: 1208 | W13: 38565 | X13: 57 | Y13: 1084 | Z13: 67 | AA13: 1208 | AE13: 40179 | AF13: =VLOOKUP(AE13,W:AB,2,0) -> 11722 | AG13: =VLOOKUP(AE13,M:S,3,0) -> 11371 | AH13: =AG13/AF13 -> 0.9700563 | AI13: =VLOOKUP(AE13,W:AB,5,0) -> 20516 | AJ13: =VLOOKUP(AE13,M:S,7,0) -> 20516
A14: 38473 | B14: 29 | C14: < 2009-06 | G14: 38443 | H14: 35 | I14: MHA-ELIGIBLE | M14: 38596 | N14: 96 | P14: 1240 | S14: 1336 | W14: 38596 | X14: 49 | Y14: 1170 | Z14: 117 | AA14: 1336 | AE14: 40210 | AF14: =VLOOKUP(AE14,W:AB,2,0) -> 13737 | AG14: =VLOOKUP(AE14,M:S,3,0) -> 13463 | AH14: =AG14/AF14 -> 0.98005387 | AI14: =VLOOKUP(AE14,W:AB,5,0) -> 20379 | AJ14: =VLOOKUP(AE14,M:S,7,0) -> 20379
A15: 38504 | B15: 28 | C15: < 2009-06 | G15: 38443 | H15: 571 | I15: NOMHA-PURCHASE | M15: 38626 | N15: 133 | P15: 1903 | S15: 2036 | W15: 38626 | X15: 112 | Y15: 1749 | Z15: 175 | AA15: 2036 | AE15: 40238 | AF15: =VLOOKUP(AE15,W:AB,2,0) -> 12676 | AG15: =VLOOKUP(AE15,M:S,3,0) -> 12639 | AH15: =AG15/AF15 -> 0.9970811 | AI15: =VLOOKUP(AE15,W:AB,5,0) -> 17708 | AJ15: =VLOOKUP(AE15,M:S,7,0) -> 17708
A16: 38504 | B16: 794 | C16: N/A | G16: 38443 | H16: 28 | I16: NOMHA-REFI | M16: 38657 | N16: 283 | P16: 3071 | S16: 3354 | W16: 38657 | X16: 243 | Y16: 2639 | Z16: 472 | AA16: 3354 | AE16: 40269 | AF16: =VLOOKUP(AE16,W:AB,2,0) -> 9563 | AG16: =VLOOKUP(AE16,M:S,3,0) -> 9607 | AH16: =AG16/AF16 -> 1.0046011 | AI16: =VLOOKUP(AE16,W:AB,5,0) -> 14556 | AJ16: =VLOOKUP(AE16,M:S,7,0) -> 14556
A17: 38534 | B17: 999 | C17: N/A | G17: 38473 | H17: 19 | I17: NOMHA-REFI | M17: 38687 | N17: 1405 | P17: 9731 | S17: 11136 | W17: 38687 | X17: 989 | Y17: 7648 | Z17: 2499 | AA17: 11136 | AE17: 40299 | AF17: =VLOOKUP(AE17,W:AB,2,0) -> 11244 | AG17: =VLOOKUP(AE17,M:S,3,0) -> 11233 | AH17: =AG17/AF17 -> 0.9990217 | AI17: =VLOOKUP(AE17,W:AB,5,0) -> 17676 | AJ17: =VLOOKUP(AE17,M:S,7,0) -> 17676
... A58: 39142 | B58: 16836 | C58: N/A | G58: 38869 | H58: 1389 | I58: MHA-ELIGIBLE | M58: 39934 | N58: 7801 | P58: 8110 | S58: 15911 | W58: 39934 | X58: 1844 | Y58: 7665 | Z58: 6402 | AA58: 15911 | AE58: 41548 | AF58: =VLOOKUP(AE58,W:AB,2,0) -> 8489 | AG58: =VLOOKUP(AE58,M:S,3,0) -> 8808 | AH58: =AG58/AF58 -> 1.037578 | AI58: =VLOOKUP(AE58,W:AB,5,0) -> 25586 | AJ58: =VLOOKUP(AE58,M:S,7,0) -> 25586
A59: 39173 | B59: 19589 | C59: N/A | G59: 38899 | H59: 3240 | I59: NOMHA-REFI | M59: 39965 | O59: 3673 | P59: 7390 | Q59: 5386 | S59: 16449 | W59: 39965 | X59: 4272 | Y59: 7108 | Z59: 5069 | AA59: 16449 | AE59: 41579 | AF59: =VLOOKUP(AE59,W:AB,2,0) -> 6264 | AG59: =VLOOKUP(AE59,M:S,3,0) -> 6521 | AH59: =AG59/AF59 -> 1.0410281 | AI59: =VLOOKUP(AE59,W:AB,5,0) -> 20817 | AJ59: =VLOOKUP(AE59,M:S,7,0) -> 20817
A60: 39173 | B60: 2844 | C60: < 2009-06 | G60: 38899 | H60: 15985 | I60: NOMHA-PURCHASE | M60: 39995 | O60: 9247 | P60: 7562 | Q60: 4679 | S60: 21488 | W60: 39995 | X60: 9557 | Y60: 7329 | Z60: 4602 | AA60: 21488 | AE60: 41609 | AF60: =VLOOKUP(AE60,W:AB,2,0) -> 5421 | AG60: =VLOOKUP(AE60,M:S,3,0) -> 5615 | AH60: =AG60/AF60 -> 1.0357868 | AI60: =VLOOKUP(AE60,W:AB,5,0) -> 20796 | AJ60: =VLOOKUP(AE60,M:S,7,0) -> 20796
A61: 39203 | B61: 27055 | C61: N/A | G61: 38899 | H61: 1405 | I61: MHA-ELIGIBLE | M61: 40026 | O61: 15370 | P61: 8903 | Q61: 4362 | S61: 28635 | W61: 40026 | X61: 15810 | Y61: 8765 | Z61: 4060 | AA61: 28635 | AE61: 41640 | AF61: =VLOOKUP(AE61,W:AB,2,0) -> 4753 | AG61: =VLOOKUP(AE61,M:S,3,0) -> 4989 | AH61: =AG61/AF61 -> 1.0496529 | AI61: =VLOOKUP(AE61,W:AB,5,0) -> 20698 | AJ61: =VLOOKUP(AE61,M:S,7,0) -> 20698
A62: 39203 | B62: 3865 | C62: < 2009-06 | G62: 38930 | H62: 3287 | I62: NOMHA-REFI | M62: 40057 | O62: 14029 | P62: 9675 | Q62: 2911 | S62: 26615 | W62: 40057 | X62: 14494 | Y62: 9547 | Z62: 2574 | AA62: 26615 | AE62: 41671 | AF62: =VLOOKUP(AE62,W:AB,2,0) -> 4811 | AG62: =VLOOKUP(AE62,M:S,3,0) -> 4958 | AH62: =AG62/AF62 -> 1.030555 | AI62: =VLOOKUP(AE62,W:AB,5,0) -> 21746 | AJ62: =VLOOKUP(AE62,M:S,7,0) -> 21746
A63: 39234 | B63: 4487 | C63: < 2009-06 | G63: 38930 | H63: 18666 | I63: NOMHA-PURCHASE | M63: 40087 | O63: 9135 | P63: 7833 | Q63: 1784 | S63: 18752 | W63: 40087 | X63: 9396 | Y63: 7753 | Z63: 1603 | AA63: 18752 | AE63: 41699 | AF63: =VLOOKUP(AE63,W:AB,2,0) -> 3966 | AG63: =VLOOKUP(AE63,M:S,3,0) -> 4086 | AH63: =AG63/AF63 -> 1.0302572 | AI63: =VLOOKUP(AE63,W:AB,5,0) -> 14988 | AJ63: =VLOOKUP(AE63,M:S,7,0) -> 14988
A64: 39234 | B64: 30328 | C64: N/A | G64: 38930 | H64: 1330 | I64: MHA-ELIGIBLE | M64: 40118 | O64: 6784 | P64: 7262 | Q64: 1392 | S64: 15438 | W64: 40118 | X64: 7014 | Y64: 7215 | Z64: 1209 | AA64: 15438 | AE64: 41730 | AF64: =VLOOKUP(AE64,W:AB,2,0) -> 3315 | AG64: =VLOOKUP(AE64,M:S,3,0) -> 0 | AH64: =AG64/AF64 -> 0 | AI64: =VLOOKUP(AE64,W:AB,5,0) -> 15796 | AJ64: =VLOOKUP(AE64,M:S,7,0) -> 15796
A65: 39264 | B65: 4388 | C65: < 2009-06 | G65: 38961 | H65: 2937 | I65: NOMHA-REFI | M65: 40148 | O65: 8893 | P65: 7497 | Q65: 1726 | S65: 18116 | W65: 40148 | X65: 9189 | Y65: 7453 | Z65: 1474 | AA65: 18116 | AE65: 41760 | AF65: =VLOOKUP(AE65,W:AB,2,0) -> 3393 | AG65: =VLOOKUP(AE65,M:S,3,0) -> 0 | AH65: =AG65/AF65 -> 0 | AI65: =VLOOKUP(AE65,W:AB,5,0) -> 20982 | AJ65: =VLOOKUP(AE65,M:S,7,0) -> 20982
A66: 39264 | B66: 35720 | C66: N/A | G66: 38961 | H66: 17479 | I66: NOMHA-PURCHASE | M66: 40179 | O66: 11371 | P66: 7168 | Q66: 1977 | S66: 20516 | W66: 40179 | X66: 11722 | Y66: 7105 | Z66: 1689 | AA66: 20516 | AE66: 41791 | AF66: =VLOOKUP(AE66,W:AB,2,0) -> 3249 | AG66: =VLOOKUP(AE66,M:S,3,0) -> 0 | AH66: =AG66/AF66 -> 0 | AI66: =VLOOKUP(AE66,W:AB,5,0) -> 22620 | AJ66: =VLOOKUP(AE66,M:S,7,0) -> 22620
A67: 39295 | B67: 37873 | C67: N/A | G67: 38961 | H67: 1215 | I67: MHA-ELIGIBLE | M67: 40210 | O67: 13463 | P67: 4904 | Q67: 2012 | S67: 20379 | W67: 40210 | X67: 13737 | Y67: 4854 | Z67: 1788 | AA67: 20379 | AE67: 41821 | AF67: =VLOOKUP(AE67,W:AB,2,0) -> 2784 | AG67: =VLOOKUP(AE67,M:S,3,0) -> 0 | AH67: =AG67/AF67 -> 0 | AI67: =VLOOKUP(AE67,W:AB,5,0) -> 24951 | AJ67: =VLOOKUP(AE67,M:S,7,0) -> 24951
A68: 39295 | B68: 3914 | C68: < 2009-06 | G68: 38991 | H68: 3389 | I68: NOMHA-REFI | M68: 40238 | O68: 12639 | P68: 3313 | Q68: 1756 | S68: 17708 | W68: 40238 | X68: 12676 | Y68: 3289 | Z68: 1743 | AA68: 17708 | AE68: 41852 | AF68: =VLOOKUP(AE68,W:AB,2,0) -> 2417 | AG68: =VLOOKUP(AE68,M:S,3,0) -> 0 | AH68: =AG68/AF68 -> 0 | AI68: =VLOOKUP(AE68,W:AB,5,0) -> 29558 | AJ68: =VLOOKUP(AE68,M:S,7,0) -> 29558
A69: 39326 | B69: 38162 | C69: N/A | G69: 38991 | H69: 17925 | I69: NOMHA-PURCHASE | M69: 40269 | O69: 9607 | P69: 3693 | Q69: 1256 | S69: 14556 | W69: 40269 | X69: 9563 | Y69: 3687 | Z69: 1306 | AA69: 14556 | AE69: 41883 | AF69: =VLOOKUP(AE69,W:AB,2,0) -> 2312 | AG69: =VLOOKUP(AE69,M:S,3,0) -> 0 | AH69: =AG69/AF69 -> 0 | AI69: =VLOOKUP(AE69,W:AB,5,0) -> 29191 | AJ69: =VLOOKUP(AE69,M:S,7,0) -> 29191
A70: 39326 | B70: 3751 | C70: < 2009-06 | G70: 38991 | H70: 1252 | I70: MHA-ELIGIBLE | M70: 40299 | O70: 11233 | P70: 5123 | Q70: 1320 | S70: 17676 | W70: 40299 | X70: 11244 | Y70: 5116 | Z70: 1316 | AA70: 17676 | AE70: 41913 | AF70: =VLOOKUP(AE70,W:AB,2,0) -> 2380 | AG70: =VLOOKUP(AE70,M:S,3,0) -> 0 | AH70: =AG70/AF70 -> 0 | AI70: =VLOOKUP(AE70,W:AB,5,0) -> 27720 | AJ70: =VLOOKUP(AE70,M:S,7,0) -> 27720
... A86: 39569 | B86: 7954 | C86: < 2009-06 | G86: 39173 | H86: 4921 | I86: NOMHA-REFI | M86: 40787 | O86: 6722 | P86: 7102 | Q86: 1234 | S86: 15058 | W86: 40787 | X86: 6608 | Y86: 7099 | Z86: 1351 | AA86: 15058 | AE86: 42401 | AF86: =VLOOKUP(AE86,W:AB,2,0) -> 780 | AG86: =VLOOKUP(AE86,M:S,3,0) -> 0 | AH86: =AG86/AF86 -> 0 | AI86: =VLOOKUP(AE86,W:AB,5,0) -> 13212 | AJ86: =VLOOKUP(AE86,M:S,7,0) -> 13212
A87: 39600 | B87: 6216 | C87: < 2009-06 | G87: 39173 | H87: 16457 | I87: NOMHA-PURCHASE | M87: 40817 | O87: 6917 | P87: 7201 | Q87: 1403 | S87: 15521 | W87: 40817 | X87: 6814 | Y87: 7200 | Z87: 1507 | AA87: 15521
A88: 39600 | B88: 22886 | C88: N/A | G88: 39173 | H88: 1055 | I88: MHA-ELIGIBLE | M88: 40848 | O88: 8052 | P88: 6033 | Q88: 2060 | S88: 16145 | W88: 40848 | X88: 7897 | Y88: 6027 | Z88: 2221 | AA88: 16145
A89: 39630 | B89: 19843 | C89: N/A | G89: 39203 | H89: 6718 | I89: NOMHA-REFI | M89: 40878 | O89: 9402 | P89: 4254 | Q89: 2144 | S89: 15800 | W89: 40878 | X89: 9245 | Y89: 4246 | Z89: 2309 | AA89: 15800
A90: 39630 | B90: 3812 | C90: < 2009-06 | G90: 39203 | H90: 22883 | I90: NOMHA-PURCHASE | M90: 40909 | O90: 9964 | P90: 4698 | Q90: 2387 | S90: 17049 | W90: 40909 | X90: 9831 | Y90: 4694 | Z90: 2524 | AA90: 17049
A91: 39661 | B91: 20321 | C91: N/A | G91: 39203 | H91: 1319 | I91: MHA-ELIGIBLE | M91: 40940 | O91: 9237 | P91: 5414 | Q91: 2593 | S91: 17244 | W91: 40940 | X91: 9082 | Y91: 5408 | Z91: 2754 | AA91: 17244
A92: 39661 | B92: 3008 | C92: < 2009-06 | G92: 39234 | H92: 7851 | I92: NOMHA-REFI | M92: 40969 | O92: 11247 | P92: 3241 | Q92: 2164 | S92: 16652 | W92: 40969 | X92: 11001 | Y92: 3234 | Z92: 2417 | AA92: 16652
A93: 39692 | B93: 15950 | C93: N/A | G93: 39234 | H93: 25651 | I93: NOMHA-PURCHASE | M93: 41000 | O93: 14409 | P93: 3375 | Q93: 2253 | S93: 20037 | W93: 41000 | X93: 14080 | Y93: 3368 | Z93: 2589 | AA93: 20037
A94: 39692 | B94: 1917 | C94: < 2009-06 | G94: 39234 | H94: 1313 | I94: MHA-ELIGIBLE | M94: 41030 | O94: 13389 | P94: 4588 | Q94: 2438 | S94: 20415 | W94: 41030 | X94: 13189 | Y94: 4588 | Z94: 2638 | AA94: 20415
A95: 39722 | B95: 1181 | C95: < 2009-06 | G95: 39264 | H95: 7479 | I95: NOMHA-REFI | M95: 41061 | O95: 12542 | P95: 7595 | Q95: 2289 | S95: 22426 | W95: 41061 | X95: 12382 | Y95: 7585 | Z95: 2459 | AA95: 22426
A96: 39722 | B96: 10778 | C96: N/A | G96: 39264 | H96: 31265 | I96: NOMHA-PURCHASE | M96: 41091 | O96: 13383 | P96: 9142 | Q96: 1944 | S96: 24469 | W96: 41091 | X96: 13178 | Y96: 9137 | Z96: 2154 | AA96: 24469
A97: 39753 | B97: 1415 | C97: < 2009-06 | G97: 39264 | H97: 1364 | I97: MHA-ELIGIBLE | M97: 41122 | O97: 13357 | P97: 10878 | Q97: 2105 | S97: 26340 | W97: 41122 | X97: 13092 | Y97: 10864 | Z97: 2384 | AA97: 26340
A98: 39753 | B98: 10864 | C98: N/A | G98: 39295 | H98: 6834 | I98: NOMHA-REFI | M98: 41153 | O98: 13492 | P98: 11393 | Q98: 3217 | S98: 28102 | W98: 41153 | X98: 13246 | Y98: 11375 | Z98: 3481 | AA98: 28102
...

Sheet <80 LTV
A4: pmtdate | B4: count() | C4: HARPStatus | F4: pmtdate | G4: count() | H4: MHAStatus | L4: Sum of count() | M4: Column Labels | V4: Sum of count() | W4: Column Labels | AG4: I-NOMHA-REFI
A5: 38353 | B5: 886 | C5: N/A | F5: 38353 | G5: 551 | H5: NOMHA-PURCHASE | L5: Row Labels | M5: < 2009-06 | N5: HARP | O5: N/A | P5: NON-HARP | Q5: Unknown | R5: Grand Total | V5: Row Labels | W5: NOMHA-PURCHASE | X5: NOMHA-REFI | Y5: Grand Total | AE5: HARP-II | AF5: Tot6al-II | AG5: Total Refi-II | AI5: Ratio HARP/Refi
A6: 38353 | B6: 203 | C6: < 2009-06 | F6: 38353 | G6: 538 | H6: NOMHA-REFI | L6: 38353 | M6: 203 | O6: 886 | R6: 1089 | V6: 38353 | W6: 551 | X6: 538 | Y6: 1089 | AD6: 39965 | AE6: =VLOOKUP(AD6,L:R,3,0) -> 6710 | AF6: =VLOOKUP(AD6,L:R,7,0) -> 169223 | AG6: =VLOOKUP(AD6,V:Z,3,0) -> 146791 | AH6: =AD6 -> 39965 | AI6: =AE6/AG6 -> 0.045711249
A7: 38384 | B7: 200 | C7: < 2009-06 | F7: 38384 | G7: 534 | H7: NOMHA-REFI | L7: 38384 | M7: 200 | O7: 870 | R7: 1070 | V7: 38384 | W7: 536 | X7: 534 | Y7: 1070 | AD7: 39995 | AE7: =VLOOKUP(AD7,L:R,3,0) -> 7064 | AF7: =VLOOKUP(AD7,L:R,7,0) -> 167924 | AG7: =VLOOKUP(AD7,V:Z,3,0) -> 142852 | AH7: =AD7 -> 39995 | AI7: =AE7/AG7 -> 0.04944978
A8: 38384 | B8: 870 | C8: N/A | F8: 38384 | G8: 536 | H8: NOMHA-PURCHASE | L8: 38412 | M8: 141 | O8: 736 | R8: 877 | V8: 38412 | W8: 443 | X8: 434 | Y8: 877 | AD8: 40026 | AE8: =VLOOKUP(AD8,L:R,3,0) -> 10110 | AF8: =VLOOKUP(AD8,L:R,7,0) -> 158038 | AG8: =VLOOKUP(AD8,V:Z,3,0) -> 124476 | AH8: =AD8 -> 40026 | AI8: =AE8/AG8 -> 0.081220476
A9: 38412 | B9: 736 | C9: N/A | F9: 38412 | G9: 443 | H9: NOMHA-PURCHASE | L9: 38443 | M9: 214 | O9: 807 | R9: 1021 | V9: 38443 | W9: 461 | X9: 560 | Y9: 1021 | AD9: 40057 | AE9: =VLOOKUP(AD9,L:R,3,0) -> 8591 | AF9: =VLOOKUP(AD9,L:R,7,0) -> 124948 | AG9: =VLOOKUP(AD9,V:Z,3,0) -> 87106 | AH9: =AD9 -> 40057 | AI9: =AE9/AG9 -> 0.09862696
A10: 38412 | B10: 141 | C10: < 2009-06 | F10: 38412 | G10: 434 | H10: NOMHA-REFI | L10: 38473 | M10: 328 | O10: 1241 | R10: 1569 | V10: 38473 | W10: 691 | X10: 878 | Y10: 1569 | AD10: 40087 | AE10: =VLOOKUP(AD10,L:R,3,0) -> 7271 | AF10: =VLOOKUP(AD10,L:R,7,0) -> 85201 | AG10: =VLOOKUP(AD10,V:Z,3,0) -> 54292 | AH10: =AD10 -> 40087 | AI10: =AE10/AG10 -> 0.13392397
A11: 38443 | B11: 214 | C11: < 2009-06 | F11: 38443 | G11: 560 | H11: NOMHA-REFI | L11: 38504 | M11: 228 | O11: 1286 | R11: 1514 | V11: 38504 | W11: 807 | X11: 707 | Y11: 1514 | AD11: 40118 | AE11: =VLOOKUP(AD11,L:R,3,0) -> 6267 | AF11: =VLOOKUP(AD11,L:R,7,0) -> 77417 | AG11: =VLOOKUP(AD11,V:Z,3,0) -> 48305 | AH11: =AD11 -> 40118 | AI11: =AE11/AG11 -> 0.12973812
A12: 38443 | B12: 807 | C12: N/A | F12: 38443 | G12: 461 | H12: NOMHA-PURCHASE | L12: 38534 | M12: 255 | O12: 1677 | R12: 1932 | V12: 38534 | W12: 1136 | X12: 796 | Y12: 1932 | AD12: 40148 | AE12: =VLOOKUP(AD12,L:R,3,0) -> 9286 | AF12: =VLOOKUP(AD12,L:R,7,0) -> 89349 | AG12: =VLOOKUP(AD12,V:Z,3,0) -> 58549 | AH12: =AD12 -> 40148 | AI12: =AE12/AG12 -> 0.1586022
A13: 38473 | B13: 328 | C13: < 2009-06 | F13: 38473 | G13: 691 | H13: NOMHA-PURCHASE | L13: 38565 | M13: 319 | O13: 2059 | R13: 2378 | V13: 38565 | W13: 1378 | X13: 1000 | Y13: 2378 | AD13: 40179 | AE13: =VLOOKUP(AD13,L:R,3,0) -> 12219 | AF13: =VLOOKUP(AD13,L:R,7,0) -> 91026 | AG13: =VLOOKUP(AD13,V:Z,3,0) -> 62306 | AH13: =AD13 -> 40179 | AI13: =AE13/AG13 -> 0.19611273
A14: 38473 | B14: 1241 | C14: N/A | F14: 38473 | G14: 878 | H14: NOMHA-REFI | L14: 38596 | M14: 522 | O14: 2809 | R14: 3331 | V14: 38596 | W14: 1664 | X14: 1667 | Y14: 3331 | AD14: 40210 | AE14: =VLOOKUP(AD14,L:R,3,0) -> 13101 | AF14: =VLOOKUP(AD14,L:R,7,0) -> 90729 | AG14: =VLOOKUP(AD14,V:Z,3,0) -> 65898 | AH14: =AD14 -> 40210 | AI14: =AE14/AG14 -> 0.19880725
A15: 38504 | B15: 1286 | C15: N/A | F15: 38504 | G15: 707 | H15: NOMHA-REFI | L15: 38626 | M15: 863 | O15: 5579 | R15: 6442 | V15: 38626 | W15: 3200 | X15: 3242 | Y15: 6442 | AD15: 40238 | AE15: =VLOOKUP(AD15,L:R,3,0) -> 12009 | AF15: =VLOOKUP(AD15,L:R,7,0) -> 75804 | AG15: =VLOOKUP(AD15,V:Z,3,0) -> 57402 | AH15: =AD15 -> 40238 | AI15: =AE15/AG15 -> 0.20920874
A16: 38504 | B16: 228 | C16: < 2009-06 | F16: 38504 | G16: 807 | H16: NOMHA-PURCHASE | L16: 38657 | M16: 1916 | O16: 12921 | R16: 14837 | V16: 38657 | W16: 6604 | X16: 8233 | Y16: 14837 | AD16: 40269 | AE16: =VLOOKUP(AD16,L:R,3,0) -> 7833 | AF16: =VLOOKUP(AD16,L:R,7,0) -> 63296 | AG16: =VLOOKUP(AD16,V:Z,3,0) -> 43064 | AH16: =AD16 -> 40269 | AI16: =AE16/AG16 -> 0.18189207
A17: 38534 | B17: 1677 | C17: N/A | F17: 38534 | G17: 796 | H17: NOMHA-REFI | L17: 38687 | M17: 8255 | O17: 48663 | R17: 56918 | V17: 38687 | W17: 23709 | X17: 33209 | Y17: 56918 | AD17: 40299 | AE17: =VLOOKUP(AD17,L:R,3,0) -> 9812 | AF17: =VLOOKUP(AD17,L:R,7,0) -> 66574 | AG17: =VLOOKUP(AD17,V:Z,3,0) -> 42670 | AH17: =AD17 -> 40299 | AI17: =AE17/AG17 -> 0.22995079
... A58: 39142 | B58: 17882 | C58: < 2009-06 | F58: 39142 | G58: 56801 | H58: NOMHA-REFI | L58: 39934 | M58: 100891 | O58: 79368 | R58: 180259 | V58: 39934 | W58: 23794 | X58: 156465 | Y58: 180259 | AD58: 41548 | AE58: =VLOOKUP(AD58,L:R,3,0) -> 7185 | AF58: =VLOOKUP(AD58,L:R,7,0) -> 51169 | AG58: =VLOOKUP(AD58,V:Z,3,0) -> 26886 | AH58: =AD58 -> 41548 | AI58: =AE58/AG58 -> 0.26723946
A59: 39173 | B59: 73705 | C59: N/A | F59: 39173 | G59: 36891 | H59: NOMHA-PURCHASE | L59: 39965 | N59: 6710 | O59: 73587 | P59: 88926 | R59: 169223 | V59: 39965 | W59: 22432 | X59: 146791 | Y59: 169223 | AD59: 41579 | AE59: =VLOOKUP(AD59,L:R,3,0) -> 5561 | AF59: =VLOOKUP(AD59,L:R,7,0) -> 40813 | AG59: =VLOOKUP(AD59,V:Z,3,0) -> 20443 | AH59: =AD59 -> 41579 | AI59: =AE59/AG59 -> 0.27202465
A60: 39173 | B60: 15173 | C60: < 2009-06 | F60: 39173 | G60: 51987 | H60: NOMHA-REFI | L60: 39995 | N60: 7064 | O60: 75008 | P60: 85852 | R60: 167924 | V60: 39995 | W60: 25072 | X60: 142852 | Y60: 167924 | AD60: 41609 | AE60: =VLOOKUP(AD60,L:R,3,0) -> 5307 | AF60: =VLOOKUP(AD60,L:R,7,0) -> 43828 | AG60: =VLOOKUP(AD60,V:Z,3,0) -> 20950 | AH60: =AD60 -> 41609 | AI60: =AE60/AG60 -> 0.25331742
A61: 39203 | B61: 19010 | C61: < 2009-06 | F61: 39203 | G61: 63370 | H61: NOMHA-REFI | L61: 40026 | N61: 10110 | O61: 80507 | P61: 67421 | R61: 158038 | V61: 40026 | W61: 33562 | X61: 124476 | Y61: 158038 | AD61: 41640 | AE61: =VLOOKUP(AD61,L:R,3,0) -> 4763 | AF61: =VLOOKUP(AD61,L:R,7,0) -> 44471 | AG61: =VLOOKUP(AD61,V:Z,3,0) -> 22294 | AH61: =AD61 -> 41640 | AI61: =AE61/AG61 -> 0.21364493
A62: 39203 | B62: 91026 | C62: N/A | F62: 39203 | G62: 46666 | H62: NOMHA-PURCHASE | L62: 40057 | N62: 8591 | O62: 74192 | P62: 42165 | R62: 124948 | V62: 40057 | W62: 37842 | X62: 87106 | Y62: 124948 | AD62: 41671 | AE62: =VLOOKUP(AD62,L:R,3,0) -> 4713 | AF62: =VLOOKUP(AD62,L:R,7,0) -> 45779 | AG62: =VLOOKUP(AD62,V:Z,3,0) -> 22659 | AH62: =AD62 -> 41671 | AI62: =AE62/AG62 -> 0.20799682
A63: 39234 | B63: 20314 | C63: < 2009-06 | F63: 39234 | G63: 47775 | H63: NOMHA-PURCHASE | L63: 40087 | N63: 7271 | O63: 55098 | P63: 22832 | R63: 85201 | V63: 40087 | W63: 30909 | X63: 54292 | Y63: 85201 | AD63: 41699 | AE63: =VLOOKUP(AD63,L:R,3,0) -> 4009 | AF63: =VLOOKUP(AD63,L:R,7,0) -> 31876 | AG63: =VLOOKUP(AD63,V:Z,3,0) -> 16538 | AH63: =AD63 -> 41699 | AI63: =AE63/AG63 -> 0.24241142
A64: 39234 | B64: 92371 | C64: N/A | F64: 39234 | G64: 64910 | H64: NOMHA-REFI | L64: 40118 | N64: 6267 | O64: 51584 | P64: 19566 | R64: 77417 | V64: 40118 | W64: 29112 | X64: 48305 | Y64: 77417 | AD64: 41730 | AE64: =VLOOKUP(AD64,L:R,3,0) -> 0 | AF64: =VLOOKUP(AD64,L:R,7,0) -> 31455 | AG64: =VLOOKUP(AD64,V:Z,3,0) -> 15114 | AH64: =AD64 -> 41730 | AI64: =AE64/AG64 -> 0
A65: 39264 | B65: 17422 | C65: < 2009-06 | F65: 39264 | G65: 48295 | H65: NOMHA-PURCHASE | L65: 40148 | N65: 9286 | O65: 55305 | P65: 24758 | R65: 89349 | V65: 40148 | W65: 30800 | X65: 58549 | Y65: 89349 | AD65: 41760 | AE65: =VLOOKUP(AD65,L:R,3,0) -> 0 | AF65: =VLOOKUP(AD65,L:R,7,0) -> 40342 | AG65: =VLOOKUP(AD65,V:Z,3,0) -> 18555 | AH65: =AD65 -> 41760 | AI65: =AE65/AG65 -> 0
A66: 39264 | B66: 89770 | C66: N/A | F66: 39264 | G66: 58897 | H66: NOMHA-REFI | L66: 40179 | N66: 12219 | O66: 53222 | P66: 25585 | R66: 91026 | V66: 40179 | W66: 28720 | X66: 62306 | Y66: 91026 | AD66: 41791 | AE66: =VLOOKUP(AD66,L:R,3,0) -> 0 | AF66: =VLOOKUP(AD66,L:R,7,0) -> 41368 | AG66: =VLOOKUP(AD66,V:Z,3,0) -> 18408 | AH66: =AD66 -> 41791 | AI66: =AE66/AG66 -> 0
A67: 39295 | B67: 13521 | C67: < 2009-06 | F67: 39295 | G67: 46378 | H67: NOMHA-PURCHASE | L67: 40210 | N67: 13101 | O67: 49834 | P67: 27794 | R67: 90729 | V67: 40210 | W67: 24831 | X67: 65898 | Y67: 90729 | AD67: 41821 | AE67: =VLOOKUP(AD67,L:R,3,0) -> 0 | AF67: =VLOOKUP(AD67,L:R,7,0) -> 43669 | AG67: =VLOOKUP(AD67,V:Z,3,0) -> 17628 | AH67: =AD67 -> 41821 | AI67: =AE67/AG67 -> 0
