Workbook
Name temp: refiuniverse!$A$1:$B$1273
Name temp_1: Sheet2!$A$8:$B$23

Sheet result refi&HARPeligible (2)
V1: actual | W1: predict | AB1: actual | AC1: predict | AF1: actual | AG1: predict
U2: 40603 | V2: 0.4772727 | W2: 0.4739275 | AA2: 40603 | AB2: 0.4836592 | AC2: 0.4231084 | AE2: 40603 | AF2: 0.4836592 | AG2: 0.3428127
C3: RMSE | U3: 40634 | V3: 0.5159862 | W3: 0.4897489 | AA3: 40634 | AB3: 0.5203754 | AC3: 0.450117 | AE3: 40634 | AF3: 0.5203754 | AG3: 0.3498156
B4: assign 0.35 to every loan | C4: 0.4737837 | U4: 40664 | V4: 0.4658106 | W4: 0.4908522 | AA4: 40664 | AB4: 0.4577533 | AC4: 0.4406855 | AE4: 40664 | AF4: 0.4577533 | AG4: 0.3488942
B5: randomly pcik 35% loans | C5: 0.6713326 | U5: 40695 | V5: 0.5236664 | W5: 0.486666 | AA5: 40695 | AB5: 0.5057121 | AC5: 0.4436939 | AE5: 40695 | AF5: 0.5057121 | AG5: 0.3512215
U6: 40725 | V6: 0.5046687 | W6: 0.4619681 | AA6: 40725 | AB6: 0.5069663 | AC6: 0.4196232 | AE6: 40725 | AF6: 0.5069663 | AG6: 0.3435553
U7: 40756 | V7: 0.4516696 | W7: 0.4182017 | AA7: 40756 | AB7: 0.4348306 | AC7: 0.3876331 | AE7: 40756 | AF7: 0.4348306 | AG7: 0.33798
B8: cs + SATO + originalLoanAmount | C8: 0.4068609 | U8: 40787 | V8: 0.4763223 | W8: 0.4565048 | AA8: 40787 | AB8: 0.4633385 | AC8: 0.4288078 | AE8: 40787 | AF8: 0.4633385 | AG8: 0.35622
B9: refiPct | C9: 0.4032042 | U9: 40817 | V9: 0.4008889 | W9: 0.4043257 | AA9: 40817 | AB9: 0.4200993 | AC9: 0.389292 | AE9: 40817 | AF9: 0.4200993 | AG9: 0.3524389
B10: refiPct + HARPpct | C10: 0.402476 | U10: 40848 | V10: 0.3245629 | W10: 0.3520719 | AA10: 40848 | AB10: 0.3147089 | AC10: 0.3271299 | AE10: 40848 | AF10: 0.3147089 | AG10: 0.3385441
U11: 40878 | V11: 0.3595055 | W11: 0.3308159 | AA11: 40878 | AB11: 0.3477556 | AC11: 0.3039926 | AE11: 40878 | AF11: 0.3477556 | AG11: 0.339101
U12: 40909 | V12: 0.3669897 | W12: 0.3303852 | AA12: 40909 | AB12: 0.365072 | AC12: 0.3118797 | AE12: 40909 | AF12: 0.365072 | AG12: 0.3425566
U13: 40940 | V13: 0.2951873 | W13: 0.3369645 | AA13: 40940 | AB13: 0.2934799 | AC13: 0.3223848 | AE13: 40940 | AF13: 0.2934799 | AG13: 0.3377061
U14: 40969 | V14: 0.3147251 | W14: 0.3154888 | AA14: 40969 | AB14: 0.3251256 | AC14: 0.3064456 | AE14: 40969 | AF14: 0.3251256 | AG14: 0.3389843
U15: 41000 | V15: 0.3199592 | W15: 0.320496 | AA15: 41000 | AB15: 0.3252394 | AC15: 0.3092675 | AE15: 41000 | AF15: 0.3252394 | AG15: 0.3354354
U16: 41030 | V16: 0.3161012 | W16: 0.3428521 | AA16: 41030 | AB16: 0.3072246 | AC16: 0.3295007 | AE16: 41030 | AF16: 0.3072246 | AG16: 0.3332027
U17: 41061 | V17: 0.3168793 | W17: 0.3241428 | AA17: 41061 | AB17: 0.3240582 | AC17: 0.3183786 | AE17: 41061 | AF17: 0.3240582 | AG17: 0.3373106
U18: 41091 | V18: 0.2856584 | W18: 0.3121096 | AA18: 41091 | AB18: 0.2876685 | AC18: 0.3079743 | AE18: 41091 | AF18: 0.2876685 | AG18: 0.3337594
U19: 41122 | V19: 0.2977605 | W19: 0.2927848 | AA19: 41122 | AB19: 0.2919557 | AC19: 0.2883763 | AE19: 41122 | AF19: 0.2919557 | AG19: 0.3401025
U20: 41153 | V20: 0.3138438 | W20: 0.2977758 | AA20: 41153 | AB20: 0.312422 | AC20: 0.294128 | AE20: 41153 | AF20: 0.312422 | AG20: 0.3406977
U21: 41183 | V21: 0.2636114 | W21: 0.290491 | AA21: 41183 | AB21: 0.2692837 | AC21: 0.2933604 | AE21: 41183 | AF21: 0.2692837 | AG21: 0.3395908
U22: 41214 | V22: 0.2730065 | W22: 0.2902347 | AA22: 41214 | AB22: 0.270557 | AC22: 0.2923207 | AE22: 41214 | AF22: 0.270557 | AG22: 0.3394151
... U38: 41699 | V38: 0.4319006 | W38: 0.4532145 | AA38: 41699 | AB38: 0.4063325 | AC38: 0.4861443 | AE38: 41699 | AF38: 0.4063325 | AG38: 0.343544

Sheet result refi&HARPeligible
V1: actual | W1: refiPct + HARPpct | X1: refiPct | Y1: cs + origNoteRate + originalLoanAmount | AB1: actual | AC1: predict | AF1: actual | AG1: predict
U2: 40603 | V2: 0.4836592 | W2: 0.4429318 | X2: =VLOOKUP(U2,AA:AC,3,0) -> 0.4231084 | Y2: =VLOOKUP(U2,AE:AG,3,0) -> 0.3428127 | AA2: 40603 | AB2: 0.4836592 | AC2: 0.4231084 | AE2: 40603 | AF2: 0.4836592 | AG2: 0.3428127
C3: RMSE | U3: 40634 | V3: 0.5203754 | W3: 0.4669131 | X3: =VLOOKUP(U3,AA:AC,3,0) -> 0.450117 | Y3: =VLOOKUP(U3,AE:AG,3,0) -> 0.3498156 | AA3: 40634 | AB3: 0.5203754 | AC3: 0.450117 | AE3: 40634 | AF3: 0.5203754 | AG3: 0.3498156
B4: assign 0.35 to every loan | C4: 0.4737837 | U4: 40664 | V4: 0.4577533 | W4: 0.4606391 | X4: =VLOOKUP(U4,AA:AC,3,0) -> 0.4406855 | Y4: =VLOOKUP(U4,AE:AG,3,0) -> 0.3488942 | AA4: 40664 | AB4: 0.4577533 | AC4: 0.4406855 | AE4: 40664 | AF4: 0.4577533 | AG4: 0.3488942
B5: randomly pcik 35% loans | C5: 0.6713326 | U5: 40695 | V5: 0.5057121 | W5: 0.4620257 | X5: =VLOOKUP(U5,AA:AC,3,0) -> 0.4436939 | Y5: =VLOOKUP(U5,AE:AG,3,0) -> 0.3512215 | AA5: 40695 | AB5: 0.5057121 | AC5: 0.4436939 | AE5: 40695 | AF5: 0.5057121 | AG5: 0.3512215
U6: 40725 | V6: 0.5069663 | W6: 0.4397201 | X6: =VLOOKUP(U6,AA:AC,3,0) -> 0.4196232 | Y6: =VLOOKUP(U6,AE:AG,3,0) -> 0.3435553 | AA6: 40725 | AB6: 0.5069663 | AC6: 0.4196232 | AE6: 40725 | AF6: 0.5069663 | AG6: 0.3435553
U7: 40756 | V7: 0.4348306 | W7: 0.4106047 | X7: =VLOOKUP(U7,AA:AC,3,0) -> 0.3876331 | Y7: =VLOOKUP(U7,AE:AG,3,0) -> 0.33798 | AA7: 40756 | AB7: 0.4348306 | AC7: 0.3876331 | AE7: 40756 | AF7: 0.4348306 | AG7: 0.33798
B8: cs + SATO + originalLoanAmount | C8: 0.4068609 | U8: 40787 | V8: 0.4633385 | W8: 0.4486258 | X8: =VLOOKUP(U8,AA:AC,3,0) -> 0.4288078 | Y8: =VLOOKUP(U8,AE:AG,3,0) -> 0.35622 | AA8: 40787 | AB8: 0.4633385 | AC8: 0.4288078 | AE8: 40787 | AF8: 0.4633385 | AG8: 0.35622
B9: refiPct | C9: 0.4032042 | U9: 40817 | V9: 0.4200993 | W9: 0.4129574 | X9: =VLOOKUP(U9,AA:AC,3,0) -> 0.389292 | Y9: =VLOOKUP(U9,AE:AG,3,0) -> 0.3524389 | AA9: 40817 | AB9: 0.4200993 | AC9: 0.389292 | AE9: 40817 | AF9: 0.4200993 | AG9: 0.3524389
B10: refiPct + HARPpct | C10: 0.4029186 | U10: 40848 | V10: 0.3147089 | W10: 0.3499748 | X10: =VLOOKUP(U10,AA:AC,3,0) -> 0.3271299 | Y10: =VLOOKUP(U10,AE:AG,3,0) -> 0.3385441 | AA10: 40848 | AB10: 0.3147089 | AC10: 0.3271299 | AE10: 40848 | AF10: 0.3147089 | AG10: 0.3385441
U11: 40878 | V11: 0.3477556 | W11: 0.3250066 | X11: =VLOOKUP(U11,AA:AC,3,0) -> 0.3039926 | Y11: =VLOOKUP(U11,AE:AG,3,0) -> 0.339101 | AA11: 40878 | AB11: 0.3477556 | AC11: 0.3039926 | AE11: 40878 | AF11: 0.3477556 | AG11: 0.339101
U12: 40909 | V12: 0.365072 | W12: 0.3319656 | X12: =VLOOKUP(U12,AA:AC,3,0) -> 0.3118797 | Y12: =VLOOKUP(U12,AE:AG,3,0) -> 0.3425566 | AA12: 40909 | AB12: 0.365072 | AC12: 0.3118797 | AE12: 40909 | AF12: 0.365072 | AG12: 0.3425566
U13: 40940 | V13: 0.2934799 | W13: 0.3425895 | X13: =VLOOKUP(U13,AA:AC,3,0) -> 0.3223848 | Y13: =VLOOKUP(U13,AE:AG,3,0) -> 0.3377061 | AA13: 40940 | AB13: 0.2934799 | AC13: 0.3223848 | AE13: 40940 | AF13: 0.2934799 | AG13: 0.3377061
U14: 40969 | V14: 0.3251256 | W14: 0.3237077 | X14: =VLOOKUP(U14,AA:AC,3,0) -> 0.3064456 | Y14: =VLOOKUP(U14,AE:AG,3,0) -> 0.3389843 | AA14: 40969 | AB14: 0.3251256 | AC14: 0.3064456 | AE14: 40969 | AF14: 0.3251256 | AG14: 0.3389843
U15: 41000 | V15: 0.3252394 | W15: 0.3250677 | X15: =VLOOKUP(U15,AA:AC,3,0) -> 0.3092675 | Y15: =VLOOKUP(U15,AE:AG,3,0) -> 0.3354354 | AA15: 41000 | AB15: 0.3252394 | AC15: 0.3092675 | AE15: 41000 | AF15: 0.3252394 | AG15: 0.3354354
U16: 41030 | V16: 0.3072246 | W16: 0.3467129 | X16: =VLOOKUP(U16,AA:AC,3,0) -> 0.3295007 | Y16: =VLOOKUP(U16,AE:AG,3,0) -> 0.3332027 | AA16: 41030 | AB16: 0.3072246 | AC16: 0.3295007 | AE16: 41030 | AF16: 0.3072246 | AG16: 0.3332027
U17: 41061 | V17: 0.3240582 | W17: 0.3324224 | X17: =VLOOKUP(U17,AA:AC,3,0) -> 0.3183786 | Y17: =VLOOKUP(U17,AE:AG,3,0) -> 0.3373106 | AA17: 41061 | AB17: 0.3240582 | AC17: 0.3183786 | AE17: 41061 | AF17: 0.3240582 | AG17: 0.3373106
U18: 41091 | V18: 0.2876685 | W18: 0.3212439 | X18: =VLOOKUP(U18,AA:AC,3,0) -> 0.3079743 | Y18: =VLOOKUP(U18,AE:AG,3,0) -> 0.3337594 | AA18: 41091 | AB18: 0.2876685 | AC18: 0.3079743 | AE18: 41091 | AF18: 0.2876685 | AG18: 0.3337594
U19: 41122 | V19: 0.2919557 | W19: 0.2959912 | X19: =VLOOKUP(U19,AA:AC,3,0) -> 0.2883763 | Y19: =VLOOKUP(U19,AE:AG,3,0) -> 0.3401025 | AA19: 41122 | AB19: 0.2919557 | AC19: 0.2883763 | AE19: 41122 | AF19: 0.2919557 | AG19: 0.3401025
U20: 41153 | V20: 0.312422 | W20: 0.3003808 | X20: =VLOOKUP(U20,AA:AC,3,0) -> 0.294128 | Y20: =VLOOKUP(U20,AE:AG,3,0) -> 0.3406977 | AA20: 41153 | AB20: 0.312422 | AC20: 0.294128 | AE20: 41153 | AF20: 0.312422 | AG20: 0.3406977
U21: 41183 | V21: 0.2692837 | W21: 0.3000548 | X21: =VLOOKUP(U21,AA:AC,3,0) -> 0.2933604 | Y21: =VLOOKUP(U21,AE:AG,3,0) -> 0.3395908 | AA21: 41183 | AB21: 0.2692837 | AC21: 0.2933604 | AE21: 41183 | AF21: 0.2692837 | AG21: 0.3395908
U22: 41214 | V22: 0.270557 | W22: 0.2884446 | X22: =VLOOKUP(U22,AA:AC,3,0) -> 0.2923207 | Y22: =VLOOKUP(U22,AE:AG,3,0) -> 0.3394151 | AA22: 41214 | AB22: 0.270557 | AC22: 0.2923207 | AE22: 41214 | AF22: 0.270557 | AG22: 0.3394151
... U38: 41699 | V38: 0.4063325 | W38: 0.4703882 | X38: =VLOOKUP(U38,AA:AC,3,0) -> 0.4861443 | Y38: =VLOOKUP(U38,AE:AG,3,0) -> 0.343544 | AA38: 41699 | AB38: 0.4063325 | AC38: 0.4861443 | AE38: 41699 | AF38: 0.4063325 | AG38: 0.343544

Sheet result refi&HARPeligible FNM
V1: actual | W1: predict | X1: refiPct | Y1: cs + origNoteRate + originalLoanAmount | AB1: actual | AC1: predict | AF1: actual | AG1: predict
U2: 40603 | V2: 0.3875373 | W2: 0.4544924 | X2: =VLOOKUP(U2,AA:AC,3,0) -> 0.4231084 | Y2: =VLOOKUP(U2,AE:AG,3,0) -> 0.3428127 | AA2: 40603 | AB2: 0.4836592 | AC2: 0.4231084 | AE2: 40603 | AF2: 0.4836592 | AG2: 0.3428127
C3: RMSE | U3: 40634 | V3: 0.4033833 | W3: 0.4735342 | X3: =VLOOKUP(U3,AA:AC,3,0) -> 0.450117 | Y3: =VLOOKUP(U3,AE:AG,3,0) -> 0.3498156 | AA3: 40634 | AB3: 0.5203754 | AC3: 0.450117 | AE3: 40634 | AF3: 0.5203754 | AG3: 0.3498156
B4: assign 0.35 to every loan | C4: 0.4853221 | U4: 40664 | V4: 0.4507297 | W4: 0.4688623 | X4: =VLOOKUP(U4,AA:AC,3,0) -> 0.4406855 | Y4: =VLOOKUP(U4,AE:AG,3,0) -> 0.3488942 | AA4: 40664 | AB4: 0.4577533 | AC4: 0.4406855 | AE4: 40664 | AF4: 0.4577533 | AG4: 0.3488942
B5: randomly pcik 35% loans | C5: 0.6810048 | U5: 40695 | V5: 0.4934734 | W5: 0.4700301 | X5: =VLOOKUP(U5,AA:AC,3,0) -> 0.4436939 | Y5: =VLOOKUP(U5,AE:AG,3,0) -> 0.3512215 | AA5: 40695 | AB5: 0.5057121 | AC5: 0.4436939 | AE5: 40695 | AF5: 0.5057121 | AG5: 0.3512215
U6: 40725 | V6: 0.5002662 | W6: 0.4547391 | X6: =VLOOKUP(U6,AA:AC,3,0) -> 0.4196232 | Y6: =VLOOKUP(U6,AE:AG,3,0) -> 0.3435553 | AA6: 40725 | AB6: 0.5069663 | AC6: 0.4196232 | AE6: 40725 | AF6: 0.5069663 | AG6: 0.3435553
U7: 40756 | V7: 0.5116544 | W7: 0.4268039 | X7: =VLOOKUP(U7,AA:AC,3,0) -> 0.3876331 | Y7: =VLOOKUP(U7,AE:AG,3,0) -> 0.33798 | AA7: 40756 | AB7: 0.4348306 | AC7: 0.3876331 | AE7: 40756 | AF7: 0.4348306 | AG7: 0.33798
U8: 40787 | V8: 0.4861067 | W8: 0.4462276 | X8: =VLOOKUP(U8,AA:AC,3,0) -> 0.4288078 | Y8: =VLOOKUP(U8,AE:AG,3,0) -> 0.35622 | AA8: 40787 | AB8: 0.4633385 | AC8: 0.4288078 | AE8: 40787 | AF8: 0.4633385 | AG8: 0.35622
B9: refiPct | C9: 0.4617159 | U9: 40817 | V9: 0.4079484 | W9: 0.4079123 | X9: =VLOOKUP(U9,AA:AC,3,0) -> 0.389292 | Y9: =VLOOKUP(U9,AE:AG,3,0) -> 0.3524389 | AA9: 40817 | AB9: 0.4200993 | AC9: 0.389292 | AE9: 40817 | AF9: 0.4200993 | AG9: 0.3524389
U10: 40848 | V10: 0.3217911 | W10: 0.3594228 | X10: =VLOOKUP(U10,AA:AC,3,0) -> 0.3271299 | Y10: =VLOOKUP(U10,AE:AG,3,0) -> 0.3385441 | AA10: 40848 | AB10: 0.3147089 | AC10: 0.3271299 | AE10: 40848 | AF10: 0.3147089 | AG10: 0.3385441
U11: 40878 | V11: 0.2772941 | W11: 0.3336602 | X11: =VLOOKUP(U11,AA:AC,3,0) -> 0.3039926 | Y11: =VLOOKUP(U11,AE:AG,3,0) -> 0.339101 | AA11: 40878 | AB11: 0.3477556 | AC11: 0.3039926 | AE11: 40878 | AF11: 0.3477556 | AG11: 0.339101
U12: 40909 | V12: 0.2532248 | W12: 0.3374493 | X12: =VLOOKUP(U12,AA:AC,3,0) -> 0.3118797 | Y12: =VLOOKUP(U12,AE:AG,3,0) -> 0.3425566 | AA12: 40909 | AB12: 0.365072 | AC12: 0.3118797 | AE12: 40909 | AF12: 0.365072 | AG12: 0.3425566
U13: 40940 | V13: 0.2639857 | W13: 0.3540076 | X13: =VLOOKUP(U13,AA:AC,3,0) -> 0.3223848 | Y13: =VLOOKUP(U13,AE:AG,3,0) -> 0.3377061 | AA13: 40940 | AB13: 0.2934799 | AC13: 0.3223848 | AE13: 40940 | AF13: 0.2934799 | AG13: 0.3377061
U14: 40969 | V14: 0.2616373 | W14: 0.3361301 | X14: =VLOOKUP(U14,AA:AC,3,0) -> 0.3064456 | Y14: =VLOOKUP(U14,AE:AG,3,0) -> 0.3389843 | AA14: 40969 | AB14: 0.3251256 | AC14: 0.3064456 | AE14: 40969 | AF14: 0.3251256 | AG14: 0.3389843
U15: 41000 | V15: 0.2398526 | W15: 0.3421164 | X15: =VLOOKUP(U15,AA:AC,3,0) -> 0.3092675 | Y15: =VLOOKUP(U15,AE:AG,3,0) -> 0.3354354 | AA15: 41000 | AB15: 0.3252394 | AC15: 0.3092675 | AE15: 41000 | AF15: 0.3252394 | AG15: 0.3354354
U16: 41030 | V16: 0.2334491 | W16: 0.3663856 | X16: =VLOOKUP(U16,AA:AC,3,0) -> 0.3295007 | Y16: =VLOOKUP(U16,AE:AG,3,0) -> 0.3332027 | AA16: 41030 | AB16: 0.3072246 | AC16: 0.3295007 | AE16: 41030 | AF16: 0.3072246 | AG16: 0.3332027
U17: 41061 | V17: 0.2550872 | W17: 0.351593 | X17: =VLOOKUP(U17,AA:AC,3,0) -> 0.3183786 | Y17: =VLOOKUP(U17,AE:AG,3,0) -> 0.3373106 | AA17: 41061 | AB17: 0.3240582 | AC17: 0.3183786 | AE17: 41061 | AF17: 0.3240582 | AG17: 0.3373106
U18: 41091 | V18: 0.2626412 | W18: 0.3437433 | X18: =VLOOKUP(U18,AA:AC,3,0) -> 0.3079743 | Y18: =VLOOKUP(U18,AE:AG,3,0) -> 0.3337594 | AA18: 41091 | AB18: 0.2876685 | AC18: 0.3079743 | AE18: 41091 | AF18: 0.2876685 | AG18: 0.3337594
U19: 41122 | V19: 0.2443873 | W19: 0.3159201 | X19: =VLOOKUP(U19,AA:AC,3,0) -> 0.2883763 | Y19: =VLOOKUP(U19,AE:AG,3,0) -> 0.3401025 | AA19: 41122 | AB19: 0.2919557 | AC19: 0.2883763 | AE19: 41122 | AF19: 0.2919557 | AG19: 0.3401025
U20: 41153 | V20: 0.3810015 | W20: 0.3220752 | X20: =VLOOKUP(U20,AA:AC,3,0) -> 0.294128 | Y20: =VLOOKUP(U20,AE:AG,3,0) -> 0.3406977 | AA20: 41153 | AB20: 0.312422 | AC20: 0.294128 | AE20: 41153 | AF20: 0.312422 | AG20: 0.3406977
U21: 41183 | V21: 0.3584632 | W21: 0.3206457 | X21: =VLOOKUP(U21,AA:AC,3,0) -> 0.2933604 | Y21: =VLOOKUP(U21,AE:AG,3,0) -> 0.3395908 | AA21: 41183 | AB21: 0.2692837 | AC21: 0.2933604 | AE21: 41183 | AF21: 0.2692837 | AG21: 0.3395908
... U38: 41699 | V38: 0.5491525 | W38: 0.5233798 | X38: =VLOOKUP(U38,AA:AC,3,0) -> 0.4861443 | Y38: =VLOOKUP(U38,AE:AG,3,0) -> 0.343544 | AA38: 41699 | AB38: 0.4063325 | AC38: 0.4861443 | AE38: 41699 | AF38: 0.4063325 | AG38: 0.343544
U39: 41730 | V39: 0.5412804 | W39: 0.4702986
U40: 41760 | V40: 0.5402924 | W40: 0.487701
U41: 41791 | V41: 0.5286463 | W41: 0.5032691
U42: 41821 | V42: 0.4971885 | W42: 0.4759633
U43: 41852 | V43: 0.4861549 | W43: 0.4651827
U44: 41883 | V44: 0.4872802 | W44: 0.453852
U45: 41913 | V45: 0.4836523 | W45: 0.4674633
U46: 41944 | V46: 0.4893377 | W46: 0.4595931
U47: 41974 | V47: 0.513555 | W47: 0.4607353

Sheet Sheet2
B3: RMSE
A4: assign 0.35 to every loan | B4: 0.4654944
A5: randomly pcik 35% loans | B5: 0.6668168
A7: Logistic Regression | B7: RMSE | C7: %lower than #1 | D7: %lower than #2
A8: cs | B8: 0.4557664 | C8: =ABS(B8-$B$4)/$B$4 -> 0.020898211 | D8: =ABS(B8-$B$5)/$B$5 -> 0.31650432
A9: origLTV | B9: 0.4623356 | C9: =ABS(B9-$B$4)/$B$4 -> 0.0067859033 | D9: =ABS(B9-$B$5)/$B$5 -> 0.30665274
A10: SATO | B10: 0.4605173 | C10: =ABS(B10-$B$4)/$B$4 -> 0.010692073 | D10: =ABS(B10-$B$5)/$B$5 -> 0.30937958
A11: originalLoanAmount | B11: 0.4480879 | C11: =ABS(B11-$B$4)/$B$4 -> 0.037393576 | D11: =ABS(B11-$B$5)/$B$5 -> 0.32801948
A12: occType | B12: 0.4634543 | C12: =ABS(B12-$B$4)/$B$4 -> 0.0043826521 | D12: =ABS(B12-$B$5)/$B$5 -> 0.30497507
A13: propertyType | B13: 0.4634044 | C13: =ABS(B13-$B$4)/$B$4 -> 0.0044898499 | D13: =ABS(B13-$B$5)/$B$5 -> 0.3050499
A15: occType + propertyType | B15: 0.4627858 | C15: =ABS(B15-$B$4)/$B$4 -> 0.0058187596 | D15: =ABS(B15-$B$5)/$B$5 -> 0.30597759
A16: origLTV + SATO | B16: 0.4585144 | C16: =ABS(B16-$B$4)/$B$4 -> 0.01499481 | D16: =ABS(B16-$B$5)/$B$5 -> 0.31238325
A18: cs + origLTV + SATO | B18: 0.4501444 | C18: =ABS(B18-$B$4)/$B$4 -> 0.032975692 | D18: =ABS(B18-$B$5)/$B$5 -> 0.32493542
A19: cs + origLTV | B19: 0.4531138 | C19: =ABS(B19-$B$4)/$B$4 -> 0.026596668 | D19: =ABS(B19-$B$5)/$B$5 -> 0.32048233
A20: cs + origLTV + SATO + originalLoanAmount + occType + propertyType | B20: 0.4352924 | C20: =ABS(B20-$B$4)/$B$4 -> 0.064881554 | D20: =ABS(B20-$B$5)/$B$5 -> 0.34720841
A21: cs + origLTV + SATO + originalLoanAmount + occType | B21: 0.4354107 | C21: =ABS(B21-$B$4)/$B$4 -> 0.064627415 | D21: =ABS(B21-$B$5)/$B$5 -> 0.347031
A22: cs + origLTV + SATO + originalLoanAmount | B22: 0.4354701 | C22: =ABS(B22-$B$4)/$B$4 -> 0.064499809 | D22: =ABS(B22-$B$5)/$B$5 -> 0.34694192 | I22: RMSE | Z22: RMSE
A23: cs + origLTV + SATO | B23: 0.4501444 | C23: =ABS(B23-$B$4)/$B$4 -> 0.032975692 | D23: =ABS(B23-$B$5)/$B$5 -> 0.32493542 | H23: assign 0.35 to every loan | I23: 0.4654944 | Y23: assign 0.35 to every loan | Z23: 0.4654944
H24: randomly pcik 35% loans | I24: 0.6668168 | Y24: randomly pcik 35% loans | Z24: 0.6668168
H27: cs + origLTV + SATO + originalLoanAmount + occType + propertyType | I27: 0.4352924 | Y27: cs + origLTV + SATO + originalLoanAmount | Z27: 0.4352924
H28: Using diff from monthly average | I28: 0.421 | Y28: Using diff from monthly average | Z28: 0.421
H29: Z-Score | I29: 0.4213991 | Y29: Z-Score | Z29: 0.4213991

Sheet Sheet3
B1: actual | C1: predict | G1: actual | H1: predict | I1: avg | L1: actual | M1: predict
A2: 39965 | B2: 0.07023884 | C2: 0.3001795 | F2: 40179 | G2: 0.3213912 | H2: 0.3374162 | I2: 0.3615071 | K2: 40179 | L2: 0.3280648 | M2: 0.3615071
A3: 39995 | B3: 0.07608288 | C3: 0.3025389 | F3: 40210 | G3: 0.3114496 | H3: 0.3272611 | I3: 0.3626786 | K3: 40210 | L3: 0.3270333 | M3: 0.3626786
A4: 40026 | B4: 0.12830577 | C4: 0.3079294 | F4: 40238 | G4: 0.3489828 | H4: 0.3324479 | I4: 0.3613687 | K4: 40238 | L4: 0.3382374 | M4: 0.3613687
A5: 40057 | B5: 0.16403318 | C5: 0.3171359 | F5: 40269 | G5: 0.3284717 | H5: 0.3410579 | I5: 0.3553853 | K5: 40269 | L5: 0.3128164 | M5: 0.3553853
A6: 40087 | B6: 0.23585684 | C6: 0.3266649 | F6: 40299 | G6: 0.3920546 | H6: 0.357614 | I6: 0.3581997 | K6: 40299 | L6: 0.3905242 | M6: 0.3581997
A7: 40118 | B7: 0.23949169 | C7: 0.3257731 | F7: 40330 | G7: 0.3824176 | H7: 0.3515098 | I7: 0.358505 | K7: 40330 | L7: 0.4123318 | M7: 0.358505
A8: 40148 | B8: 0.2742672 | C8: 0.3194692 | F8: 40360 | G8: 0.3988811 | H8: 0.3630283 | I8: 0.3659389 | K8: 40360 | L8: 0.4070772 | M8: 0.3659389
A9: 40179 | B9: 0.32891774 | C9: 0.3168475 | F9: 40391 | G9: 0.4134965 | H9: 0.3548097 | I9: 0.3622043 | K9: 40391 | L9: 0.4296636 | M9: 0.3622043
A10: 40210 | B10: 0.31371823 | C10: 0.3151981 | F10: 40422 | G10: 0.4331246 | H10: 0.348894 | I10: 0.3587015 | K10: 40422 | L10: 0.4376988 | M10: 0.3587015
A11: 40238 | B11: 0.34936709 | C11: 0.3211168 | F11: 40452 | G11: 0.4007306 | H11: 0.3521303 | I11: 0.3558059 | K11: 40452 | L11: 0.4006462 | M11: 0.3558059
A12: 40269 | B12: 0.32372641 | C12: 0.3264996 | F12: 40483 | G12: 0.4472342 | H12: 0.3529933 | I12: 0.3567713 | K12: 40483 | L12: 0.4450533 | M12: 0.3567713
A13: 40299 | B13: 0.38164055 | C13: 0.3257728 | F13: 40513 | G13: 0.4483482 | H13: 0.3377487 | I13: 0.3583197 | K13: 40513 | L13: 0.4523955 | M13: 0.3583197
... A52: 41487 | B52: 0.32457565 | C52: 0.3266534 | F52: 41699 | G52: 0.4195652 | H52: 0.4639518 | I52: 0.3667739 | K52: 41699 | L52: 0.4256575 | M52: 0.3667739
A53: 41518 | B53: 0.3807499 | C53: 0.3391359
A54: 41548 | B54: 0.43400713 | C54: 0.3513938
A55: 41579 | B55: 0.44777961 | C55: 0.3576192
A56: 41609 | B56: 0.43788692 | C56: 0.3587945
A57: 41640 | B57: 0.37098692 | C57: 0.3507997
A58: 41671 | B58: 0.35990529 | C58: 0.3544432
A59: 41699 | B59: 0.40829346 | C59: 0.3617164

Sheet Sheet3 (2)
B1: actual | C1: predict | G1: actual | H1: predict | I1: avg | J1: z-score | M1: actual | N1: predict | O1: -Refi Universe | R1: actual | S1: refi
A2: 39965 | B2: 0.07023884 | C2: 0.3001795 | F2: 40179 | G2: 0.3213912 | H2: 0.3374162 | I2: 0.3615071 | J2: 0.3567805 | L2: 40179 | M2: 0.3190879 | N2: 0.3567805 | O2: =-VLOOKUP(L2,refiuniverse!A:B,2,0) -> #N/A | Q2: 40179 | R2: 0.3213912 | S2: =-VLOOKUP(Q2,refiuniverse!D:F,3,0) -> #N/A
A3: 39995 | B3: 0.07608288 | C3: 0.3025389 | F3: 40210 | G3: 0.3114496 | H3: 0.3272611 | I3: 0.3626786 | J3: 0.360284 | L3: 40210 | M3: 0.3223716 | N3: 0.360284 | O3: =-VLOOKUP(L3,refiuniverse!A:B,2,0) -> #N/A | Q3: 40210 | R3: 0.3114496 | S3: =-VLOOKUP(Q3,refiuniverse!D:F,3,0) -> #N/A
A4: 40026 | B4: 0.12830577 | C4: 0.3079294 | F4: 40238 | G4: 0.3489828 | H4: 0.3324479 | I4: 0.3613687 | J4: 0.3630143 | L4: 40238 | M4: 0.3462028 | N4: 0.3630143 | O4: =-VLOOKUP(L4,refiuniverse!A:B,2,0) -> #N/A | Q4: 40238 | R4: 0.3489828 | S4: =-VLOOKUP(Q4,refiuniverse!D:F,3,0) -> #N/A
A5: 40057 | B5: 0.16403318 | C5: 0.3171359 | F5: 40269 | G5: 0.3284717 | H5: 0.3410579 | I5: 0.3553853 | J5: 0.3564305 | L5: 40269 | M5: 0.3150206 | N5: 0.3564305 | O5: =-VLOOKUP(L5,refiuniverse!A:B,2,0) -> #N/A | Q5: 40269 | R5: 0.3284717 | S5: =-VLOOKUP(Q5,refiuniverse!D:F,3,0) -> #N/A
A6: 40087 | B6: 0.23585684 | C6: 0.3266649 | F6: 40299 | G6: 0.3920546 | H6: 0.357614 | I6: 0.3581997 | J6: 0.3597287 | L6: 40299 | M6: 0.3878486 | N6: 0.3597287 | O6: =-VLOOKUP(L6,refiuniverse!A:B,2,0) -> #N/A | Q6: 40299 | R6: 0.3920546 | S6: =-VLOOKUP(Q6,refiuniverse!D:F,3,0) -> #N/A
A7: 40118 | B7: 0.23949169 | C7: 0.3257731 | F7: 40330 | G7: 0.3824176 | H7: 0.3515098 | I7: 0.358505 | J7: 0.3574694 | L7: 40330 | M7: 0.3933108 | N7: 0.3574694 | O7: =-VLOOKUP(L7,refiuniverse!A:B,2,0) -> #N/A | Q7: 40330 | R7: 0.3824176 | S7: =-VLOOKUP(Q7,refiuniverse!D:F,3,0) -> #N/A
A8: 40148 | B8: 0.2742672 | C8: 0.3194692 | F8: 40360 | G8: 0.3988811 | H8: 0.3630283 | I8: 0.3659389 | J8: 0.3650827 | L8: 40360 | M8: 0.3960044 | N8: 0.3650827 | O8: =-VLOOKUP(L8,refiuniverse!A:B,2,0) -> #N/A | Q8: 40360 | R8: 0.3988811 | S8: =-VLOOKUP(Q8,refiuniverse!D:F,3,0) -> #N/A
A9: 40179 | B9: 0.32891774 | C9: 0.3168475 | F9: 40391 | G9: 0.4134965 | H9: 0.3548097 | I9: 0.3622043 | J9: 0.364863 | L9: 40391 | M9: 0.4285987 | N9: 0.364863 | O9: =-VLOOKUP(L9,refiuniverse!A:B,2,0) -> #N/A | Q9: 40391 | R9: 0.4134965 | S9: =-VLOOKUP(Q9,refiuniverse!D:F,3,0) -> #N/A
A10: 40210 | B10: 0.31371823 | C10: 0.3151981 | F10: 40422 | G10: 0.4331246 | H10: 0.348894 | I10: 0.3587015 | J10: 0.3615126 | L10: 40422 | M10: 0.4289424 | N10: 0.3615126 | O10: =-VLOOKUP(L10,refiuniverse!A:B,2,0) -> #N/A | Q10: 40422 | R10: 0.4331246 | S10: =-VLOOKUP(Q10,refiuniverse!D:F,3,0) -> #N/A
A11: 40238 | B11: 0.34936709 | C11: 0.3211168 | F11: 40452 | G11: 0.4007306 | H11: 0.3521303 | I11: 0.3558059 | J11: 0.3595301 | L11: 40452 | M11: 0.40853 | N11: 0.3595301 | O11: =-VLOOKUP(L11,refiuniverse!A:B,2,0) -> #N/A | Q11: 40452 | R11: 0.4007306 | S11: =-VLOOKUP(Q11,refiuniverse!D:F,3,0) -> #N/A
A12: 40269 | B12: 0.32372641 | C12: 0.3264996 | F12: 40483 | G12: 0.4472342 | H12: 0.3529933 | I12: 0.3567713 | J12: 0.3628489 | L12: 40483 | M12: 0.4440469 | N12: 0.3628489 | O12: =-VLOOKUP(L12,refiuniverse!A:B,2,0) -> #N/A | Q12: 40483 | R12: 0.4472342 | S12: =-VLOOKUP(Q12,refiuniverse!D:F,3,0) -> #N/A
A13: 40299 | B13: 0.38164055 | C13: 0.3257728 | F13: 40513 | G13: 0.4483482 | H13: 0.3377487 | I13: 0.3583197 | J13: 0.3596647 | L13: 40513 | M13: 0.4545376 | N13: 0.3596647 | O13: =-VLOOKUP(L13,refiuniverse!A:B,2,0) -> #N/A | Q13: 40513 | R13: 0.4483482 | S13: =-VLOOKUP(Q13,refiuniverse!D:F,3,0) -> #N/A
... A15: 40360 | B15: 0.38568644 | C15: 0.3271157 | F15: 40575 | G15: 0.4244278 | H15: 0.3340892 | I15: 0.3632133 | J15: 0.3635254 | L15: 40575 | M15: 0.4222647 | N15: 0.3635254 | O15: =-VLOOKUP(L15,refiuniverse!A:B,2,0) -> -0.4063865 | Q15: 40575 | R15: 0.4244278 | S15: =-VLOOKUP(Q15,refiuniverse!D:F,3,0) -> -0.45873086
A16: 40391 | B16: 0.41777611 | C16: 0.316401 | F16: 40603 | G16: 0.4916515 | H16: 0.3578812 | I16: 0.369675 | J16: 0.3685353 | L16: 40603 | M16: 0.4876961 | N16: 0.3685353 | O16: -0.4063865 | Q16: 40603 | R16: 0.4916515 | S16: =-VLOOKUP(Q16,refiuniverse!D:F,3,0) -> -0.4063865
A17: 40422 | B17: 0.43757094 | C17: 0.3092787 | F17: 40634 | G17: 0.5089632 | H17: 0.3688754 | I17: 0.3586894 | J17: 0.3663634 | L17: 40634 | M17: 0.5124269 | N17: 0.3663634 | O17: -0.42811303 | Q17: 40634 | R17: 0.5089632 | S17: =-VLOOKUP(Q17,refiuniverse!D:F,3,0) -> -0.42811303
A18: 40452 | B18: 0.40491535 | C18: 0.3053363 | F18: 40664 | G18: 0.4682514 | H18: 0.3696262 | I18: 0.3695518 | J18: 0.3665499 | L18: 40664 | M18: 0.4458455 | N18: 0.3665499 | O18: -0.42393008 | Q18: 40664 | R18: 0.4682514 | S18: =-VLOOKUP(Q18,refiuniverse!D:F,3,0) -> -0.42393008
A19: 40483 | B19: 0.45091415 | C19: 0.3037789 | F19: 40695 | G19: 0.503476 | H19: 0.3846795 | I19: 0.3533504 | J19: 0.3678849 | L19: 40695 | M19: 0.5081542 | N19: 0.3678849 | O19: -0.46807222 | Q19: 40695 | R19: 0.503476 | S19: =-VLOOKUP(Q19,refiuniverse!D:F,3,0) -> -0.46807222
A20: 40513 | B20: 0.45162134 | C20: 0.306931 | F20: 40725 | G20: 0.4799097 | H20: 0.3752652 | I20: 0.3548019 | J20: 0.3630031 | L20: 40725 | M20: 0.505244 | N20: 0.3630031 | O20: -0.55179807 | Q20: 40725 | R20: 0.4799097 | S20: =-VLOOKUP(Q20,refiuniverse!D:F,3,0) -> -0.55179807
A21: 40544 | B21: 0.46572839 | C21: 0.3067354 | F21: 40756 | G21: 0.4396339 | H21: 0.3659419 | I21: 0.3636976 | J21: 0.3674499 | L21: 40756 | M21: 0.4407871 | N21: 0.3674499 | O21: -0.4825646 | Q21: 40756 | R21: 0.4396339 | S21: =-VLOOKUP(Q21,refiuniverse!D:F,3,0) -> -0.4825646
A22: 40575 | B22: 0.41524073 | C22: 0.3093742 | F22: 40787 | G22: 0.4705695 | H22: 0.3786024 | I22: 0.3541044 | J22: 0.3641317 | L22: 40787 | M22: 0.4576324 | N22: 0.3641317 | O22: -0.59268589 | Q22: 40787 | R22: 0.4705695 | S22: =-VLOOKUP(Q22,refiuniverse!D:F,3,0) -> -0.59268589
A23: 40603 | B23: 0.50021717 | C23: 0.3205679 | F23: 40817 | G23: 0.425 | H23: 0.3794833 | I23: 0.3739978 | J23: 0.3719699 | L23: 40819 | M23: 0.4098898 | N23: 0.3719699 | O23: -0.74727193 | Q23: 40817 | R23: 0.425 | S23: =-VLOOKUP(Q23,refiuniverse!D:F,3,0) -> -0.74727193
A24: 40634 | B24: 0.51820236 | C24: 0.33094 | F24: 40848 | G24: 0.3315453 | H24: 0.3319768 | I24: 0.3637666 | J24: 0.3630662 | L24: 40848 | M24: 0.3275717 | N24: 0.3630662 | O24: -0.82897178 | Q24: 40848 | R24: 0.3315453 | S24: =-VLOOKUP(Q24,refiuniverse!D:F,3,0) -> -0.82897178
A25: 40664 | B25: 0.46110057 | C25: 0.3338557 | F25: 40878 | G25: 0.3510291 | H25: 0.334967 | I25: 0.3663141 | J25: 0.3666475 | L25: 40878 | M25: 0.3598726 | N25: 0.3666475 | O25: -0.81332289 | Q25: 40878 | R25: 0.3510291 | S25: =-VLOOKUP(Q25,refiuniverse!D:F,3,0) -> -0.81332289
A26: 40695 | B26: 0.51568845 | C26: 0.3326232 | F26: 40909 | G26: 0.3714775 | H26: 0.3355774 | I26: 0.3591378 | J26: 0.3609085 | L26: 40911 | M26: 0.3713139 | N26: 0.3609085 | O26: -0.76053873 | Q26: 40909 | R26: 0.3714775 | S26: =-VLOOKUP(Q26,refiuniverse!D:F,3,0) -> -0.76053873
A27: 40725 | B27: 0.49586397 | C27: 0.3329651 | F27: 40940 | G27: 0.2901197 | H27: 0.3306146 | I27: 0.3577466 | J27: 0.3608444 | L27: 40940 | M27: 0.2915043 | N27: 0.3608444 | O27: -0.82143068 | Q27: 40940 | R27: 0.2901197 | S27: =-VLOOKUP(Q27,refiuniverse!D:F,3,0) -> -0.82143068
... A52: 41487 | B52: 0.32457565 | C52: 0.3266534 | F52: 41699 | G52: 0.4195652 | H52: 0.4639518 | I52: 0.3667739 | J52: 0.3705389 | L52: 41701 | M52: 0.4324324 | N52: 0.3705389 | O52: -0.41717069 | Q52: 41699 | R52: 0.4195652 | S52: =-VLOOKUP(Q52,refiuniverse!D:F,3,0) -> -0.41717069
A53: 41518 | B53: 0.3807499 | C53: 0.3391359 | O53: -0.36528365
A54: 41548 | B54: 0.43400713 | C54: 0.3513938 | O54: -0.36528365
A55: 41579 | B55: 0.44777961 | C55: 0.3576192
A56: 41609 | B56: 0.43788692 | C56: 0.3587945
A57: 41640 | B57: 0.37098692 | C57: 0.3507997
A58: 41671 | B58: 0.35990529 | C58: 0.3544432
A59: 41699 | B59: 0.40829346 | C59: 0.3617164

Sheet result-refi
B1: actual | C1: predict | F1: actual | G1: predict | Y1: actual | Z1: predict | AB1: asofdate | AC1: HARPpct | AF1: actual | AG1: predict | AJ1: actual | AK1: predict
A2: 40575 | B2: 0.4166934 | C2: 0.4072347 | E2: 40603 | F2: 0.4773383 | G2: 0.4314931 | X2: 26 | Y2: 0.4077977 | Z2: 0.4775687 | AB2: 40548 | AC2: 0.98703087 | AE2: 40603 | AF2: 0.492077 | AG2: 0.4440403 | AI2: 882 | AJ2: 0.3219271 | AK2: 0.2872587
A3: 40603 | B3: 0.4832909 | C3: 0.4276956 | E3: 40634 | F3: 0.5187045 | G3: 0.4475459 | P3: assign 0.35 | Q3: 0.4745234 | X3: 30 | Y3: 0.4398014 | Z3: 0.4773019 | AB3: 40575 | AC3: 0.98625506 | AE3: 40634 | AF3: 0.5231179 | AG3: 0.4639961 | AI3: 901 | AJ3: 0.2769198 | AK3: 0.2750663
A4: 40634 | B4: 0.5111057 | C4: 0.415572 | E4: 40664 | F4: 0.4368301 | G4: 0.4294567 | P4: randomly pick 35% loans | Q4: 0.672302 | X4: 32 | Y4: 0.3975762 | Z4: 0.4652146 | AB4: 40603 | AC4: 0.98919617 | AE4: 40664 | AF4: 0.4482978 | AG4: 0.4519832 | AI4: 902 | AJ4: 0.3700306 | AK4: 0.3118745
A5: 40664 | B5: 0.4471045 | C5: 0.4195145 | E5: 40695 | F5: 0.4936663 | G5: 0.4336748 | P5: refi 1m lag | Q5: 0.4029652 | R5: refiPct + cs + origNoteRate + originalLoanAmount | X5: 40 | Y5: 0.446249 | Z5: 0.4473393 | AB5: 40634 | AC5: 0.98747188 | AE5: 40695 | AF5: 0.4881603 | AG5: 0.4538685 | AI5: 908 | AJ5: 0.2699275 | AK5: 0.2921768
A6: 40695 | B6: 0.4994532 | C6: 0.4061403 | E6: 40725 | F6: 0.4981702 | G6: 0.42535 | P6: refi 2m lag | Q6: 0.3994912 | X6: 42 | Y6: 0.4637111 | Z6: 0.4307652 | AB6: 40665 | AC6: 0.98709404 | AE6: 40725 | AF6: 0.4937413 | AG6: 0.4454106 | AI6: 909 | AJ6: 0.3374031 | AK6: 0.3293285
A7: 40725 | B7: 0.4988463 | C7: 0.3898548 | E7: 40756 | F7: 0.4330909 | G7: 0.3928721 | X7: 43 | Y7: 0.4484749 | Z7: 0.444994 | AB7: 40695 | AC7: 0.98437075 | AE7: 40756 | AF7: 0.4335787 | AG7: 0.4122594 | AI7: 911 | AJ7: 0.2861635 | AK7: 0.2841209
A8: 40756 | B8: 0.428267 | C8: 0.3949019 | E8: 40787 | F8: 0.4590006 | G8: 0.4134619 | X8: 44 | Y8: 0.383758 | Z8: 0.4284393 | AB8: 40725 | AC8: 0.98523798 | AE8: 40787 | AF8: 0.4660314 | AG8: 0.431377 | AI8: 913 | AJ8: 0.2972746 | AK8: 0.3078762
A9: 40787 | B9: 0.4514233 | C9: 0.3693091 | E9: 40817 | F9: 0.413582 | G9: 0.384076 | X9: 45 | Y9: 0.4773383 | Z9: 0.4314847 | AB9: 40756 | AC9: 0.98250613 | AE9: 40817 | AF9: 0.4176847 | AG9: 0.4132188 | AI9: 919 | AJ9: 0.2663595 | AK9: 0.2856662
A10: 40817 | B10: 0.4293478 | C10: 0.3436645 | E10: 40848 | F10: 0.3229009 | G10: 0.3261051 | X10: 46 | Y10: 0.4981702 | Z10: 0.4249928 | AB10: 40787 | AC10: 0.97181601 | AE10: 40848 | AF10: 0.3316361 | AG10: 0.3520199 | AI10: 927 | AJ10: 0.4444444 | AK10: 0.4067468
A11: 40848 | B11: 0.3177101 | C11: 0.3053501 | E11: 40878 | F11: 0.3667603 | G11: 0.3081158 | X11: 48 | Y11: 0.4590006 | Z11: 0.4126452 | AB11: 40819 | AC11: 0.96344397 | AE11: 40878 | AF11: 0.3615422 | AG11: 0.3227473 | AI11: 936 | AJ11: 0.3172144 | AK11: 0.3033328
A12: 40878 | B12: 0.3490854 | C12: 0.3105074 | E12: 40909 | F12: 0.3701692 | G12: 0.3091872 | X12: 55 | Y12: 0.4330909 | Z12: 0.3914824 | AB12: 40848 | AC12: 0.96289666 | AE12: 40909 | AF12: 0.3649112 | AG12: 0.3260181 | AI12: 937 | AJ12: 0.2804503 | AK12: 0.2977998
A13: 40909 | B13: 0.3663093 | C13: 0.3242778 | E13: 40940 | F13: 0.3001529 | G13: 0.3200103 | X13: 57 | Y13: 0.3227028 | Z13: 0.3769146 | AB13: 40878 | AC13: 0.96683863 | AE13: 40940 | AF13: 0.3001862 | AG13: 0.3394588 | AI13: 942 | AJ13: 0.3773962 | AK13: 0.4516498
A14: 40940 | B14: 0.2926264 | C14: 0.3066745 | E14: 40969 | F14: 0.3167013 | G14: 0.3030508 | X14: 59 | Y14: 0.413582 | Z14: 0.3841708 | AB14: 40911 | AC14: 0.95835929 | AE14: 40969 | AF14: 0.3223223 | AG14: 0.3239161 | AI14: 945 | AJ14: 0.3855038 | AK14: 0.4276421
A15: 40969 | B15: 0.3150264 | C15: 0.3100255 | E15: 41000 | F15: 0.3224394 | G15: 0.3061163 | X15: 71 | Y15: 0.3745839 | Z15: 0.3419866 | AB15: 40940 | AC15: 0.95771186 | AE15: 41000 | AF15: 0.3080918 | AG15: 0.3199074 | AI15: 952 | AJ15: 0.4407682 | AK15: 0.4690796
A16: 41000 | B16: 0.3258081 | C16: 0.3347053 | E16: 41030 | F16: 0.3113442 | G16: 0.3337525 | X16: 72 | Y16: 0.3113442 | Z16: 0.3344309 | AB16: 40969 | AC16: 0.96529195 | AE16: 41030 | AF16: 0.3029133 | AG16: 0.3404345 | AI16: 953 | AJ16: 0.2890595 | AK16: 0.3182442
A17: 41030 | B17: 0.3097777 | C17: 0.3122893 | E17: 41061 | F17: 0.3216251 | G17: 0.3132471 | X17: 73 | Y17: 0.2961452 | Z17: 0.3262133 | AB17: 41001 | AC17: 0.95671296 | AE17: 41061 | AF17: 0.3183253 | AG17: 0.3284365 | AI17: 955 | AJ17: 0.4290822 | AK17: 0.4627974
A18: 41061 | B18: 0.3093194 | C18: 0.3118203 | E18: 41091 | F18: 0.2852401 | G18: 0.3034555 | X18: 74 | Y18: 0.3229009 | Z18: 0.3253873 | AB18: 41030 | AC18: 0.9538313 | AE18: 41091 | AF18: 0.2890595 | AG18: 0.3182442 | AI18: 956 | AJ18: 0.3183253 | AK18: 0.3284365
... A29: 41395 | B29: 0.3605183 | C29: 0.3400958 | E29: 41426 | F29: 0.3745839 | G29: 0.3423152 | X29: 91 | Y29: 0.2848831 | Z29: 0.2818098 | AB29: 41365 | AC29: 0.9090083 | AE29: 41426 | AF29: 0.3844732 | AG29: 0.3233321 | AI29: 986 | AJ29: 0.5231179 | AK29: 0.4639961
A30: 41426 | B30: 0.3770657 | C30: 0.3174338 | E30: 41456 | F30: 0.3274181 | G30: 0.316605 | AB30: 41395 | AC30: 0.8829888 | AE30: 41456 | AF30: 0.3219271 | AG30: 0.2872587 | AI30: 987 | AJ30: 0.4914787 | AK30: 0.4465411
A31: 41456 | B31: 0.3269892 | C31: 0.3710823 | E31: 41487 | F31: 0.3227028 | G31: 0.377165 | AB31: 41428 | AC31: 0.91317148 | AE31: 41487 | AF31: 0.3283862 | AG31: 0.3558123 | AI31: 989 | AJ31: 0.4482978 | AK31: 0.4519832
A32: 41487 | B32: 0.3390024 | C32: 0.4160121 | E32: 41518 | F32: 0.3893054 | G32: 0.4472888 | AB32: 41456 | AC32: 0.945686 | AE32: 41518 | AF32: 0.3855038 | AG32: 0.4276421
A33: 41518 | B33: 0.3816172 | C33: 0.4410953 | E33: 41548 | F33: 0.4259098 | G33: 0.4626911 | AB33: 41487 | AC33: 0.95538185 | AE33: 41548 | AF33: 0.4290822 | AG33: 0.4627974
A34: 41548 | B34: 0.4312782 | C34: 0.4513287 | E34: 41579 | F34: 0.4398014 | G34: 0.4768737 | AB34: 41520 | AC34: 0.95262566 | AE34: 41579 | AF34: 0.4639769 | AG34: 0.4733894
A35: 41579 | B35: 0.4546881 | C35: 0.4186511 | E35: 41609 | F35: 0.4484749 | G35: 0.4449421 | AB35: 41548 | AC35: 0.92754953 | AE35: 41609 | AF35: 0.4444444 | AG35: 0.4067468
A36: 41609 | B36: 0.4435685 | C36: 0.4121534 | E36: 41640 | F36: 0.383758 | G36: 0.4283463 | AB36: 41579 | AC36: 0.90965776 | AE36: 41640 | AF36: 0.3827515 | AG36: 0.3979253
A37: 41640 | B37: 0.3677269 | C37: 0.4485208 | E37: 41671 | F37: 0.358739 | G37: 0.467556 | AB37: 41610 | AC37: 0.94265532 | AE37: 41671 | AF37: 0.3773962 | AG37: 0.4516498
A38: 41671 | B38: 0.3689548 | C38: 0.4596438 | E38: 41699 | F38: 0.4077977 | G38: 0.4771037 | AB38: 41641 | AC38: 0.95267533 | AE38: 41699 | AF38: 0.4109878 | AG38: 0.4635494
A39: 41699 | B39: 0.415268 | C39: 0.4066924 | AB39: 41673 | AC39: 0.90637175
AB40: 41701 | AC40: 0.92482608
AB41: 41730 | AC41: 0.93612957
AB42: 41760 | AC42: 0.91068733
AB43: 41792 | AC43: 0.89558117
AB44: 41821 | AC44: 0.89002336
AB45: 41852 | AC45: 0.88950375
AB46: 41884 | AC46: 0.87801682
AB47: 41913 | AC47: 0.88052319
AB48: 41946 | AC48: 0.8443907
AB49: 41974 | AC49: 0.84391713
AB50: 42006 | AC50: 0.80400561
...

Sheet monthly diff
A1: cs | E1: origLTV | J1: actual | K1: predict | N1: actual | O1: predict | R1: actual | S1: predict
B2: actual | C2: predict | F2: actual | G2: predict | I2: -152 | J2: 1 | K2: 0.032446731 | M2: -152 | N2: 1 | O2: 0.032446731 | Q2: -24 | R2: 1 | S2: 0.91720113
A3: -334 | B3: 1 | C3: 0.91347004 | E3: -60 | F3: 0 | G3: 0.4995728 | I3: -148 | J3: 1 | K3: 0.005196975 | M3: -148 | N3: 1 | O3: 0.005196975 | Q3: -23 | R3: 0.375 | S3: 0.74434039
A4: -328 | B4: 1 | C4: 0.77616808 | E4: -59 | F4: 0.75 | G4: 0.7427421 | I4: -140 | J4: 0 | K4: 0.009952531 | M4: -140 | N4: 0 | O4: 0.009952531 | Q4: -22 | R4: 0.50617284 | S4: 0.75607373
A5: -327 | B5: 1 | C5: 0.94843036 | E5: -58 | F5: 0.6666667 | G5: 0.6639824 | I5: -136 | J5: 0 | K5: 0.012902509 | M5: -136 | N5: 0 | O5: 0.012902509 | Q5: -21 | R5: 0.53462604 | S5: 0.73036043
A6: -309 | B6: 1 | C6: 0.89686853 | E6: -57 | F6: 0.5217391 | G6: 0.6680351 | I6: -135 | J6: 0 | K6: 0.009010143 | M6: -135 | N6: 0 | O6: 0.009010143 | Q6: -20 | R6: 0.56582633 | S6: 0.67916173
A7: -305 | B7: 1 | C7: 0.89592847 | E7: -56 | F7: 0.5102041 | G7: 0.5887101 | I7: -127 | J7: 0.07692308 | K7: 0.019255178 | M7: -127 | N7: 0.07692308 | O7: 0.019255178 | Q7: -19 | R7: 0.54980843 | S7: 0.64752735
A8: -304 | B8: 1 | C8: 0.83782979 | E8: -55 | F8: 0.62 | G8: 0.601841 | I8: -126 | J8: 1 | K8: 0.023942672 | M8: -126 | N8: 1 | O8: 0.023942672 | Q8: -18 | R8: 0.56795042 | S8: 0.6154843
A9: -301 | B9: 1 | C9: 0.7165351 | E9: -54 | F9: 0.4343434 | G9: 0.5835808 | I9: -122 | J9: 0.2 | K9: 0.017065042 | M9: -122 | N9: 0.2 | O9: 0.017065042 | Q9: -17 | R9: 0.53019146 | S9: 0.56654007
A10: -298 | B10: 1 | C10: 0.89018556 | E10: -53 | F10: 0.4310345 | G10: 0.5644169 | I10: -121 | J10: 0 | K10: 0.047460925 | M10: -121 | N10: 0 | O10: 0.047460925 | Q10: -16 | R10: 0.50970301 | S10: 0.52768188
A11: -297 | B11: 1 | C11: 0.85628645 | E11: -52 | F11: 0.4375 | G11: 0.5705214 | I11: -118 | J11: 0.25 | K11: 0.021544438 | M11: -118 | N11: 0.25 | O11: 0.021544438 | Q11: -15 | R11: 0.48850085 | S11: 0.49306256
A12: -296 | B12: 1 | C12: 0.74052835 | E12: -51 | F12: 0.3791469 | G12: 0.5139179 | I12: -116 | J12: 0 | K12: 0.023776882 | M12: -116 | N12: 0 | O12: 0.023776882 | Q12: -14 | R12: 0.47102494 | S12: 0.4651576
A13: -295 | B13: 1 | C13: 0.9065456 | E13: -50 | F13: 0.3703704 | G13: 0.518275 | I13: -115 | J13: 0.2 | K13: 0.0284404 | M13: -115 | N13: 0.2 | O13: 0.0284404 | Q13: -13 | R13: 0.44496135 | S13: 0.44092666
A14: -294 | B14: 1 | C14: 0.79305192 | E14: -49 | F14: 0.3843648 | G14: 0.5148191 | I14: -114 | J14: 0 | K14: 0.033825151 | M14: -114 | N14: 0 | O14: 0.033825151 | Q14: -12 | R14: 0.43968116 | S14: 0.42591393
... A81: -223 | B81: 1 | C81: 0.75265542 | E81: 18 | F81: 0.2335958 | G81: 0.2748942 | I81: -44 | J81: 0.06838632 | K81: 0.11445928 | M81: -44 | N81: 0.06838632 | O81: 0.11445928 | Q81: 55 | R81: 0.11764706 | S81: 0.09657092
A82: -222 | B82: 1 | C82: 0.74710214 | I82: -43 | J82: 0.13705882 | K82: 0.12348252 | M82: -43 | N82: 0.13705882 | O82: 0.12348252 | Q82: 56 | R82: 0.08333333 | S82: 0.05785221
A83: -221 | B83: 1 | C83: 0.71318568 | I83: -42 | J83: 0.08653846 | K83: 0.11903949 | M83: -42 | N83: 0.08653846 | O83: 0.11903949 | Q83: 57 | R83: 0.14285714 | S83: 0.10625961
A84: -220 | B84: 1 | C84: 0.7232616 | I84: -41 | J84: 0.08458781 | K84: 0.12700639 | M84: -41 | N84: 0.08458781 | O84: 0.12700639 | Q84: 58 | R84: 0 | S84: 0.02633527
A85: -219 | B85: 1 | C85: 0.7782533 | I85: -40 | J85: 0.07695061 | K85: 0.13501139 | M85: -40 | N85: 0.07695061 | O85: 0.13501139 | Q85: 59 | R85: 0 | S85: 0.05081607
A86: -218 | B86: 1 | C86: 0.76148626 | I86: -39 | J86: 0.1316726 | K86: 0.12960621 | M86: -39 | N86: 0.1316726 | O86: 0.12960621 | Q86: 60 | R86: 0 | S86: 0.13420378
A87: -217 | B87: 1 | C87: 0.77882368 | I87: -38 | J87: 0.08062678 | K87: 0.1346233 | M87: -38 | N87: 0.08062678 | O87: 0.1346233 | Q87: 61 | R87: 0 | S87: 0.11765284
A88: -216 | B88: 1 | C88: 0.73930852 | I88: -37 | J88: 0.13517528 | K88: 0.13518282 | M88: -37 | N88: 0.13517528 | O88: 0.13518282 | Q88: 62 | R88: 0 | S88: 0.05955361
A89: -215 | B89: 1 | C89: 0.75820916 | I89: -36 | J89: 0.12808843 | K89: 0.13765235 | M89: -36 | N89: 0.12808843 | O89: 0.13765235 | Q89: 63 | R89: 0 | S89: 0.04651581
A90: -214 | B90: 1 | C90: 0.72592901 | I90: -35 | J90: 0.2412908 | K90: 0.14456557 | M90: -35 | N90: 0.2412908 | O90: 0.14456557 | Q90: 64 | R90: 0 | S90: 0.18342578
A91: -213 | B91: 1 | C91: 0.78013786 | I91: -34 | J91: 0.12043682 | K91: 0.14675948 | M91: -34 | N91: 0.12043682 | O91: 0.14675948 | Q91: 65 | R91: 0 | S91: 0.05039074
A92: -212 | B92: 1 | C92: 0.71035197 | I92: -33 | J92: 0.19069966 | K92: 0.14192013 | M92: -33 | N92: 0.19069966 | O92: 0.14192013 | Q92: 66 | R92: 0 | S92: 0.06336769
A93: -211 | B93: 1 | C93: 0.71004158 | I93: -32 | J93: 0.08559561 | K93: 0.14565912 | M93: -32 | N93: 0.08559561 | O93: 0.14565912 | Q93: 68 | R93: 0 | S93: 0.0356542
... A100: -204 | B100: 0.9583333 | C100: 0.651801 | I100: -25 | J100: 0.1511519 | K100: 0.1777418 | M100: -25 | N100: 0.1511519 | O100: 0.1777418 | Q100: 91 | R100: 0 | S100: 0.0412946
A101: -203 | B101: 1 | C101: 0.69840455 | I101: -24 | J101: 0.1551265 | K101: 0.18069753 | M101: -24 | N101: 0.1551265 | O101: 0.18069753
A102: -202 | B102: 1 | C102: 0.68397545 | I102: -23 | J102: 0.23476454 | K102: 0.18200126 | M102: -23 | N102: 0.23476454 | O102: 0.18200126
A103: -201 | B103: 1 | C103: 0.7344226 | I103: -22 | J103: 0.23956901 | K103: 0.18900063 | M103: -22 | N103: 0.23956901 | O103: 0.18900063
A104: -200 | B104: 1 | C104: 0.72415507 | I104: -21 | J104: 0.18868414 | K104: 0.19158786 | M104: -21 | N104: 0.18868414 | O104: 0.19158786
A105: -199 | B105: 1 | C105: 0.68839214 | I105: -20 | J105: 0.16151888 | K105: 0.19508794 | M105: -20 | N105: 0.16151888 | O105: 0.19508794
A106: -198 | B106: 1 | C106: 0.75556767 | I106: -19 | J106: 0.19249499 | K106: 0.19853988 | M106: -19 | N106: 0.19249499 | O106: 0.19853988
A107: -197 | B107: 1 | C107: 0.70807919 | I107: -18 | J107: 0.20349986 | K107: 0.20799386 | M107: -18 | N107: 0.20349986 | O107: 0.20799386
A108: -196 | B108: 0.9677419 | C108: 0.7163269 | I108: -17 | J108: 0.28380187 | K108: 0.20785031 | M108: -17 | N108: 0.28380187 | O108: 0.20785031
A109: -195 | B109: 0.9714286 | C109: 0.74594015 | I109: -16 | J109: 0.15448585 | K109: 0.21318583 | M109: -16 | N109: 0.15448585 | O109: 0.21318583
A110: -194 | B110: 1 | C110: 0.74327111 | I110: -15 | J110: 0.13633803 | K110: 0.22167232 | M110: -15 | N110: 0.13633803 | O110: 0.22167232
A111: -193 | B111: 1 | C111: 0.74196778 | I111: -14 | J111: 0.2538926 | K111: 0.21778395 | M111: -14 | N111: 0.2538926 | O111: 0.21778395
A112: -192 | B112: 1 | C112: 0.74337073 | I112: -13 | J112: 0.13315981 | K112: 0.23088135 | M112: -13 | N112: 0.13315981 | O112: 0.23088135
...

Sheet z-score
A1: cs | E1: origLTV | J1: actual | K1: predict | R1: actual | S1: predict
B2: actual | C2: predict | F2: actual | G2: predict | I2: -51 | J2: 0 | K2: 0.007734278 | Q2: -19 | R2: 1 | S2: 0.86310154
A3: -76 | B3: 1 | C3: 0.8097831 | E3: -43 | F3: 0.6666667 | G3: 0.8330468 | I3: -48 | J3: 0 | K3: 0.007418719 | Q3: -18 | R3: 0.83333333 | S3: 0.84992046
A4: -75 | B4: 1 | C4: 0.9509061 | E4: -42 | F4: 1 | G4: 0.9344043 | I4: -45 | J4: 0 | K4: 0.00655177 | Q4: -17 | R4: 0.77409639 | S4: 0.78657135
A5: -74 | B5: 1 | C5: 0.8121768 | E5: -41 | F5: 0.6666667 | G5: 0.8026029 | I5: -44 | J5: 0 | K5: 0.016299807 | Q5: -16 | R5: 0.72904624 | S5: 0.75357013
A6: -70 | B6: 1 | C6: 0.9172994 | E6: -40 | F6: 0.5714286 | G6: 0.6866327 | I6: -43 | J6: 0 | K6: 0.008353843 | Q6: -15 | R6: 0.68436658 | S6: 0.71599737
A7: -69 | B7: 1 | C7: 0.859653 | E7: -39 | F7: 0.6666667 | G7: 0.710132 | I7: -41 | J7: 0 | K7: 0.01355446 | Q7: -14 | R7: 0.62432859 | S7: 0.66295604
A8: -68 | B8: 1 | C8: 0.7949071 | E8: -38 | F8: 0.4333333 | G8: 0.6632149 | I8: -39 | J8: 0.66666667 | K8: 0.020120493 | Q8: -13 | R8: 0.58974359 | S8: 0.6046416
A9: -67 | B9: 1 | C9: 0.9821501 | E9: -37 | F9: 0.5466667 | G9: 0.6707642 | I9: -38 | J9: 0.27272727 | K9: 0.02605176 | Q9: -12 | R9: 0.5668607 | S9: 0.56063077
A10: -66 | B10: 1 | C10: 0.8714531 | E10: -36 | F10: 0.4245283 | G10: 0.6506463 | I10: -37 | J10: 0.25 | K10: 0.018358587 | Q10: -11 | R10: 0.5260944 | S10: 0.52287145
A11: -65 | B11: 1 | C11: 0.8047968 | E11: -35 | F11: 0.5290323 | G11: 0.6384003 | I11: -36 | J11: 0 | K11: 0.031413818 | Q11: -10 | R11: 0.49877301 | S11: 0.49883207
A12: -64 | B12: 1 | C12: 0.9070159 | E12: -34 | F12: 0.522449 | G12: 0.6422268 | I12: -35 | J12: 0.42857143 | K12: 0.030564737 | Q12: -9 | R12: 0.4671799 | S12: 0.4722221
A13: -63 | B13: 1 | C13: 0.8716824 | E13: -33 | F13: 0.4931973 | G13: 0.6198169 | I13: -34 | J13: 0.27777778 | K13: 0.029688538 | Q13: -8 | R13: 0.43876718 | S13: 0.45350067
A14: -62 | B14: 1 | C14: 0.8159426 | E14: -32 | F14: 0.4623894 | G14: 0.6199208 | I14: -33 | J14: 0 | K14: 0.030066951 | Q14: -7 | R14: 0.41806577 | S14: 0.43641521
... A57: -19 | B57: 0.5655668 | C57: 0.5640069 | E57: 11 | F57: 0.1745176 | G57: 0.2780178 | I57: 10 | J57: 0.60227828 | K57: 0.60077229 | Q57: 36 | R57: 0.06451613 | S57: 0.10318729
A58: -18 | B58: 0.5334324 | C58: 0.547423 | I58: 11 | J58: 0.63151303 | K58: 0.62695824 | Q58: 37 | R58: 0.01834862 | S58: 0.08866901
A59: -17 | B59: 0.5135516 | C59: 0.5258569 | I59: 12 | J59: 0.65304212 | K59: 0.64030285 | Q59: 38 | R59: 0.02453988 | S59: 0.09004385
A60: -16 | B60: 0.5007416 | C60: 0.5155405 | I60: 13 | J60: 0.64092664 | K60: 0.66370844 | Q60: 39 | R60: 0.02521008 | S60: 0.09384026
A61: -15 | B61: 0.4646675 | C61: 0.4878936 | I61: 14 | J61: 0.71762835 | K61: 0.69051888 | Q61: 40 | R61: 0.01459854 | S61: 0.09177153
A62: -14 | B62: 0.4480038 | C62: 0.4786151 | I62: 15 | J62: 0.68489583 | K62: 0.70447224 | Q62: 41 | R62: 0.02702703 | S62: 0.10644947
A63: -13 | B63: 0.4266849 | C63: 0.4602905 | I63: 16 | J63: 0.71551052 | K63: 0.72497369 | Q63: 42 | R63: 0.05479452 | S63: 0.08988957
A64: -12 | B64: 0.432735 | C64: 0.4505291 | I64: 17 | J64: 0.7470015 | K64: 0.7493146 | Q64: 43 | R64: 0.13043478 | S64: 0.09098443
A65: -11 | B65: 0.4233519 | C65: 0.439362 | I65: 18 | J65: 0.7734301 | K65: 0.76171681 | Q65: 44 | R65: 0.04347826 | S65: 0.07593255
A66: -10 | B66: 0.4015762 | C66: 0.4125423 | I66: 19 | J66: 0.76847892 | K66: 0.78849767 | Q66: 45 | R66: 0.2 | S66: 0.10565781
A67: -9 | B67: 0.3854466 | C67: 0.4078662 | I67: 20 | J67: 0.80420595 | K67: 0.79784038 | Q67: 46 | R67: 0.11111111 | S67: 0.1089741
A68: -8 | B68: 0.3866046 | C68: 0.3950276 | I68: 21 | J68: 0.82261209 | K68: 0.81898187 | Q68: 47 | R68: 0 | S68: 0.09346143
A69: -7 | B69: 0.3708251 | C69: 0.3772522 | I69: 22 | J69: 0.81506849 | K69: 0.83065357 | Q69: 48 | R69: 0 | S69: 0.09292984
... A79: 3 | B79: 0.2923209 | C79: 0.304815 | I79: 32 | J79: 0.8474026 | K79: 0.93035357 | Q79: 66 | R79: 0 | S79: 0.07948331
A80: 4 | B80: 0.2837297 | C80: 0.2995484 | I80: 33 | J80: 0.87755102 | K80: 0.93768072
A81: 5 | B81: 0.2942499 | C81: 0.3002835 | I81: 34 | J81: 0.92405063 | K81: 0.94499387
A82: 6 | B82: 0.2892072 | C82: 0.2989264 | I82: 35 | J82: 0.875 | K82: 0.94949732
A83: 7 | B83: 0.3019857 | C83: 0.3015964 | I83: 36 | J83: 0.88495575 | K83: 0.95529365
A84: 8 | B84: 0.3213926 | C84: 0.3109476 | I84: 37 | J84: 0.89361702 | K84: 0.95346729
A85: 9 | B85: 0.3468144 | C85: 0.3202905 | I85: 38 | J85: 0.80434783 | K85: 0.9550433
A86: 10 | B86: 0.3610719 | C86: 0.333211 | I86: 39 | J86: 0.93548387 | K86: 0.96912659
A87: 11 | B87: 0.3895214 | C87: 0.3403712 | I87: 40 | J87: 0.86486486 | K87: 0.97080628
A88: 12 | B88: 0.4002134 | C88: 0.3609127 | I88: 41 | J88: 0.91428571 | K88: 0.97171656
A89: 13 | B89: 0.4516686 | C89: 0.3774566 | I89: 42 | J89: 0.84482759 | K89: 0.97247781
A90: 14 | B90: 0.5643341 | C90: 0.3964889 | I90: 43 | J90: 1 | K90: 0.97772163
A91: 15 | B91: 0.7875 | C91: 0.4562725 | I91: 44 | J91: 0.87804878 | K91: 0.97483247
...

Sheet Sheet7
A1: pmtdate | B1: avg_cs | C1: avg_OLTV | D1: avg_origNoteRate | E1: avg_coupon | F1: avg_originalLoanAmount | G1: std_cs | H1: std_OLTV | I1: std_origNoteRate | J1: std_coupon | K1: std_originalLoanAmount
A2: 39965 | B2: 768.60824 | C2: 63.076427 | D2: 4.8907737 | E2: 4.4091327 | F2: 241949.49 | G2: 36.575491 | H2: 15.599471 | I2: 0.28237917 | J2: 0.31829699 | K2: 120744.41
A3: 39995 | B3: 767.84389 | C3: 62.767299 | D3: 4.8740204 | E3: 4.4573292 | F3: 236344.8 | G3: 38.553339 | H3: 15.684624 | I3: 0.27730078 | J3: 0.29458492 | K3: 121871.52
A4: 40026 | B4: 765.15961 | C4: 62.624303 | D4: 4.9068122 | E4: 4.5116035 | F4: 234067.5 | G4: 40.48061 | H4: 15.908993 | I4: 0.30060613 | J4: 0.30774965 | K4: 126161.79
A5: 40057 | B5: 761.00179 | C5: 62.613946 | D5: 5.05318 | E5: 4.6403689 | F5: 240877.48 | G5: 43.266023 | H5: 16.095509 | I5: 0.35959009 | J5: 0.34849121 | K5: 135230.24
A6: 40087 | B6: 755.89512 | C6: 62.851035 | D6: 5.2086603 | E6: 4.7699744 | F6: 227448.83 | G6: 46.519528 | H6: 16.108841 | I6: 0.39327481 | J6: 0.38696806 | K6: 128596.68
A7: 40118 | B7: 755.9293 | C7: 62.98006 | D7: 5.2359105 | E7: 4.7843813 | F7: 231115.35 | G7: 46.022629 | H7: 15.914442 | I7: 0.3711429 | J7: 0.38507604 | K7: 131487.87
A8: 40148 | B8: 759.74481 | C8: 63.155283 | D8: 5.1131488 | E8: 4.6688993 | F8: 237626.09 | G8: 44.788743 | H8: 15.546028 | I8: 0.31021818 | J8: 0.33200614 | K8: 131507.95
A9: 40179 | B9: 761.43317 | C9: 62.461905 | D9: 5.0828619 | E9: 4.6510714 | F9: 234922.13 | G9: 44.704186 | H9: 15.869008 | I9: 0.27355977 | J9: 0.294376 | K9: 131303.56
A10: 40210 | B10: 760.31596 | C10: 63.112633 | D10: 5.0317269 | E10: 4.625324 | F10: 237672.24 | G10: 45.20789 | H10: 15.474632 | I10: 0.26609122 | J10: 0.2767145 | K10: 131191.1
A11: 40238 | B11: 759.12451 | C11: 62.751455 | D11: 5.0617065 | E11: 4.6586221 | F11: 235541.99 | G11: 45.985121 | H11: 15.770035 | I11: 0.26345379 | J11: 0.2734368 | K11: 129589.91
A12: 40269 | B12: 756.1708 | C12: 63.018545 | D12: 5.140029 | E12: 4.715033 | F12: 234207.9 | G12: 47.169907 | H12: 15.751537 | I12: 0.26419037 | J12: 0.28104193 | K12: 131107.02
A13: 40299 | B13: 754.92729 | C13: 63.337796 | D13: 5.1684021 | E13: 4.7320893 | F13: 225229.86 | G13: 48.932009 | H13: 15.365404 | I13: 0.25661319 | J13: 0.29105695 | K13: 130361.02
... A83: 42430 | B83: 733.03267 | C83: 65.029038 | D83: 4.3333013 | E83: 3.6533575 | F83: 198745.89 | G83: 57.296064 | H83: 14.006981 | I83: 0.31423955 | J83: 0.36002851 | K83: 109537.77

Sheet refiuniverse
A1: asof | B1: Refiuniver | D1: Month | F1: Refiuniver | G1: -pctPreHARP | I1: Month | J1: asOfDate | K1: pctPreHARP | L1: HARP%Result
A2: 40548 | B2: 0.45873086 | D2: 40575 | E2: 40548 | F2: 0.45873086 | G2: =-VLOOKUP(E2,J:K,2,0) -> -0.93758543 | I2: 40603 | J2: 40548 | K2: 0.93758543 | L2: =VLOOKUP(I2,'result refi&HARPeligible'!U:V,2,0) -> 0.4836592
A3: 40549 | B3: 0.45929621 | D3: 40603 | E3: 40575 | F3: 0.4063865 | G3: =-VLOOKUP(E3,J:K,2,0) -> -0.93907892 | I3: 40634 | J3: 40575 | K3: 0.93907892 | L3: =VLOOKUP(I3,'result refi&HARPeligible'!U:V,2,0) -> 0.5203754
A4: 40550 | B4: 0.48970402 | D4: 40634 | E4: 40603 | F4: 0.42811303 | G4: =-VLOOKUP(E4,J:K,2,0) -> -0.94171582 | I4: 40664 | J4: 40603 | K4: 0.94171582 | L4: =VLOOKUP(I4,'result refi&HARPeligible'!U:V,2,0) -> 0.4577533
A5: 40553 | B5: 0.4903531 | D5: 40664 | E5: 40634 | F5: 0.42393008 | G5: =-VLOOKUP(E5,J:K,2,0) -> -0.9392777 | I5: 40695 | J5: 40634 | K5: 0.9392777 | L5: =VLOOKUP(I5,'result refi&HARPeligible'!U:V,2,0) -> 0.5057121
A6: 40554 | B6: 0.47527398 | D6: 40695 | E6: 40665 | F6: 0.46807222 | G6: =-VLOOKUP(E6,J:K,2,0) -> -0.8741709 | I6: 40725 | J6: 40665 | K6: 0.8741709 | L6: =VLOOKUP(I6,'result refi&HARPeligible'!U:V,2,0) -> 0.5069663
A7: 40555 | B7: 0.48977291 | D7: 40725 | E7: 40695 | F7: 0.55179807 | G7: =-VLOOKUP(E7,J:K,2,0) -> -0.73383216 | I7: 40756 | J7: 40695 | K7: 0.73383216 | L7: =VLOOKUP(I7,'result refi&HARPeligible'!U:V,2,0) -> 0.4348306
A8: 40556 | B8: 0.5063898 | D8: 40756 | E8: 40725 | F8: 0.4825646 | G8: =-VLOOKUP(E8,J:K,2,0) -> -0.82413465 | I8: 40787 | J8: 40725 | K8: 0.82413465 | L8: =VLOOKUP(I8,'result refi&HARPeligible'!U:V,2,0) -> 0.4633385
A9: 40557 | B9: 0.50629083 | D9: 40787 | E9: 40756 | F9: 0.59268589 | G9: =-VLOOKUP(E9,J:K,2,0) -> -0.66759397 | I9: 40817 | J9: 40756 | K9: 0.66759397 | L9: =VLOOKUP(I9,'result refi&HARPeligible'!U:V,2,0) -> 0.4200993
A10: 40561 | B10: 0.48949714 | D10: 40817 | E10: 40787 | F10: 0.74727193 | G10: =-VLOOKUP(E10,J:K,2,0) -> -0.53883928 | I10: 40848 | J10: 40787 | K10: 0.53883928 | L10: =VLOOKUP(I10,'result refi&HARPeligible'!U:V,2,0) -> 0.3147089
A11: 40562 | B11: 0.47508681 | D11: 40848 | E11: 40819 | F11: 0.82897178 | G11: =-VLOOKUP(E11,J:K,2,0) -> -0.47166286 | I11: 40878 | J11: 40819 | K11: 0.47166286 | L11: =VLOOKUP(I11,'result refi&HARPeligible'!U:V,2,0) -> 0.3477556
A12: 40563 | B12: 0.45875463 | D12: 40878 | E12: 40848 | F12: 0.81332289 | G12: =-VLOOKUP(E12,J:K,2,0) -> -0.4749166 | I12: 40909 | J12: 40848 | K12: 0.4749166 | L12: =VLOOKUP(I12,'result refi&HARPeligible'!U:V,2,0) -> 0.365072
A13: 40564 | B13: 0.45921127 | D13: 40909 | E13: 40878 | F13: 0.76053873 | G13: =-VLOOKUP(E13,J:K,2,0) -> -0.50668588 | I13: 40940 | J13: 40878 | K13: 0.50668588 | L13: =VLOOKUP(I13,'result refi&HARPeligible'!U:V,2,0) -> 0.2934799
... A63: 40637 | B63: 0.42393428 | D63: 42430 | E63: 42401 | F63: 0.54973638 | G63: =-VLOOKUP(E63,J:K,2,0) -> -0.16293996 | I63: 42461 | J63: 42401 | K63: 0.16293996 | L63: =VLOOKUP(I63,'result refi&HARPeligible'!U:V,2,0) -> #N/A
A64: 40638 | B64: 0.41160885
A65: 40639 | B65: 0.41152464
A66: 40640 | B66: 0.41153044
A67: 40641 | B67: 0.41149724
A68: 40644 | B68: 0.41152464
A69: 40645 | B69: 0.42377826
A70: 40646 | B70: 0.42427152
A71: 40647 | B71: 0.4241657
A72: 40648 | B72: 0.43912464
A73: 40651 | B73: 0.45308885
A74: 40652 | B74: 0.45337409
A75: 40653 | B75: 0.43867378
... A1273: 42404 | B1273: 0.58964809

Sheet Sheet8
B1: actual | C1: predict | F1: actual | G1: predict | J1: actual | K1: predict | N1: actual | O1: predict | R1: actual | S1: predict
A2: -78 | B2: 1 | C2: 0.9595525 | E2: -51 | F2: 0 | G2: 0.012617021 | I2: -19 | J2: 0.66666667 | K2: 0.87300306 | M2: 26 | N2: 0.4063325 | O2: 0.4703882 | Q2: 882 | R2: 0.3231868 | S2: 0.2876518
A3: -72 | B3: 1 | C3: 0.8538265 | E3: -47 | F3: 0 | G3: 0.00397775 | I3: -18 | J3: 0.86206897 | K3: 0.77639277 | M3: 30 | N3: 0.4592133 | O3: 0.4694501 | Q3: 901 | R3: 0.272679 | S3: 0.2739906
A4: -70 | B4: 1 | C4: 0.8285322 | E4: -43 | F4: 0 | G4: 0.016183314 | I4: -17 | J4: 0.7 | K4: 0.70734518 | M4: 32 | N4: 0.3998296 | O4: 0.4567522 | Q4: 902 | R4: 0.3548145 | S4: 0.3048905
A5: -66 | B5: 1 | C5: 0.9015354 | E5: -41 | F5: 0 | G5: 0.003915089 | I5: -16 | J5: 0.726647 | K5: 0.70967059 | M5: 40 | N5: 0.4468905 | O5: 0.4455031 | Q5: 908 | R5: 0.2667367 | S5: 0.289234
A6: -65 | B6: 1 | C6: 0.9765831 | E6: -38 | F6: 0.25 | G6: 0.037567101 | I6: -15 | J6: 0.71809872 | K6: 0.69370144 | M6: 42 | N6: 0.47979 | O6: 0.4612763 | Q6: 909 | R6: 0.3401272 | S6: 0.3259089
A7: -64 | B7: 1 | C7: 0.89337 | E7: -37 | F7: 0 | G7: 0.011214658 | I7: -14 | J7: 0.65465533 | K7: 0.64547674 | M7: 43 | N7: 0.4563977 | O7: 0.4133017 | Q7: 911 | R7: 0.2904264 | S7: 0.2859608
A8: -63 | B8: 1 | C8: 0.701022 | E8: -36 | F8: 0.5 | G8: 0.065640957 | I8: -13 | J8: 0.61210869 | K8: 0.59443842 | M8: 44 | N8: 0.3855799 | O8: 0.3892691 | Q8: 913 | R8: 0.3011954 | S8: 0.310541
A9: -62 | B9: 1 | C9: 0.9451958 | E9: -35 | F9: 0.5 | G9: 0.037257956 | I9: -12 | J9: 0.5809291 | K9: 0.55929967 | M9: 45 | N9: 0.4836592 | O9: 0.4429318 | Q9: 919 | R9: 0.270557 | S9: 0.2884446
A10: -61 | B10: 1 | C10: 0.8714475 | E10: -34 | F10: 0.375 | G10: 0.026485809 | I10: -11 | J10: 0.53100522 | K10: 0.52400062 | M10: 46 | N10: 0.5069663 | O10: 0.4397201 | Q10: 927 | R10: 0.4563977 | S10: 0.4133017
A11: -60 | B11: 1 | C11: 0.857473 | E11: -33 | F11: 0.2 | G11: 0.043794436 | I11: -10 | J11: 0.50729852 | K11: 0.50352421 | M11: 48 | N11: 0.4633385 | O11: 0.4486258 | Q11: 936 | R11: 0.312422 | S11: 0.3003808
A12: -59 | B12: 1 | C12: 0.8628866 | E12: -32 | F12: 0 | G12: 0.036172412 | I12: -9 | J12: 0.46207689 | K12: 0.47648836 | M12: 55 | N12: 0.4348306 | O12: 0.4106047 | Q12: 937 | R12: 0.2783528 | S12: 0.2984293
A13: -58 | B13: 1 | C13: 0.8295716 | E13: -31 | F13: 0.11111111 | G13: 0.037006168 | I13: -8 | J13: 0.44811612 | K13: 0.45436217 | M13: 57 | N13: 0.3249455 | O13: 0.354697 | Q13: 942 | R13: 0.3643287 | S13: 0.4556356
... A29: -42 | B29: 1 | C29: 0.8163633 | E29: -15 | F29: 0.1040033 | G29: 0.11075429 | I29: 8 | J29: 0.19529229 | K29: 0.17779458 | M29: 91 | N29: 0.2843431 | O29: 0.2792093 | Q29: 986 | R29: 0.5203754 | S29: 0.4669131
A30: -41 | B30: 0.9894737 | C30: 0.8025302 | E30: -14 | F30: 0.06770723 | G30: 0.086448418 | I30: 9 | J30: 0.17311494 | K30: 0.16334908 | Q30: 987 | R30: 0.4929162 | S30: 0.4465576
A31: -40 | B31: 0.9911504 | C31: 0.7780457 | E31: -13 | F31: 0.13764906 | G31: 0.12101557 | I31: 10 | J31: 0.16925208 | K31: 0.15386135 | Q31: 989 | R31: 0.4577533 | S31: 0.4606391
A32: -39 | B32: 0.9663866 | C32: 0.7704035 | E32: -12 | F32: 0.14031067 | G32: 0.13623381 | I32: 11 | J32: 0.14048213 | K32: 0.14122613
A33: -38 | B33: 0.9831933 | C33: 0.7829024 | E33: -11 | F33: 0.11634171 | G33: 0.12586371 | I33: 12 | J33: 0.16806723 | K33: 0.13064017
A34: -37 | B34: 0.9617834 | C34: 0.7618271 | E34: -10 | F34: 0.1071313 | G34: 0.12501343 | I34: 13 | J34: 0.17590028 | K34: 0.12091549
A35: -36 | B35: 1 | C35: 0.7907046 | E35: -9 | F35: 0.13630555 | G35: 0.14881009 | I35: 14 | J35: 0.10273747 | K35: 0.10873223
A36: -35 | B36: 0.9319372 | C36: 0.7637723 | E36: -8 | F36: 0.11899751 | G36: 0.15695866 | I36: 15 | J36: 0.09601113 | K36: 0.10624931
A37: -34 | B37: 0.9054054 | C37: 0.7534464 | E37: -7 | F37: 0.18419212 | G37: 0.19780822 | I37: 16 | J37: 0.15024496 | K37: 0.13184961
A38: -33 | B38: 0.9086957 | C38: 0.7309665 | E38: -6 | F38: 0.17584083 | G38: 0.18067491 | I38: 17 | J38: 0.0625471 | K38: 0.1254398
A39: -32 | B39: 0.8858268 | C39: 0.7355443 | E39: -5 | F39: 0.20761786 | G39: 0.22596365 | I39: 18 | J39: 0.06603774 | K39: 0.13311553
A40: -31 | B40: 0.8365019 | C40: 0.7136266 | E40: -4 | F40: 0.18962941 | G40: 0.24070929 | I40: 19 | J40: 0.05860806 | K40: 0.11613645
A41: -30 | B41: 0.7834758 | C41: 0.7138368 | E41: -3 | F41: 0.29004288 | G41: 0.26889019 | I41: 20 | J41: 0.08127208 | K41: 0.10276501
A42: -29 | B42: 0.8090186 | C42: 0.6930638 | E42: -2 | F42: 0.26832461 | G42: 0.25188081 | I42: 21 | J42: 0.06679389 | K42: 0.096412582
A43: -28 | B43: 0.7596741 | C43: 0.6921496 | E43: -1 | F43: 0.29354405 | G43: 0.28247112 | I43: 22 | J43: 0.06378987 | K43: 0.092383532
... A78: 7 | B78: 0.2679703 | C78: 0.2660558 | E78: 34 | F78: 0.94146341 | G78: 0.94965079 | I78: 62 | J78: 0 | K78: 0.05781309
A79: 8 | B79: 0.2836716 | C79: 0.2706492 | E79: 35 | F79: 0.91304348 | G79: 0.96057489
A80: 9 | B80: 0.3042254 | C80: 0.2769433 | E80: 36 | F80: 0.92763158 | G80: 0.96233673
A81: 10 | B81: 0.3298501 | C81: 0.2938968 | E81: 37 | F81: 0.89285714 | G81: 0.9545178
A82: 11 | B82: 0.3472112 | C82: 0.3047814 | E82: 38 | F82: 0.95714286 | G82: 0.95741628
A83: 12 | B83: 0.3807394 | C83: 0.3359476 | E83: 39 | F83: 0.84615385 | G83: 0.98046579
A84: 13 | B84: 0.4253545 | C84: 0.3585147 | E84: 40 | F84: 0.84210526 | G84: 0.97014613
A85: 14 | B85: 0.5247813 | C85: 0.425069 | E85: 41 | F85: 0.98 | G85: 0.96913422
A86: 15 | B86: 0.6938776 | C86: 0.4446971 | E86: 42 | F86: 0.85 | G86: 0.95948727
A87: 16 | B87: 1 | C87: 0.5271502 | E87: 43 | F87: 0.95 | G87: 0.98143446
A88: 17 | B88: 1 | C88: 0.5645899 | E88: 44 | F88: 0.84615385 | G88: 0.97459482
E89: 45 | F89: 0.9 | G89: 0.98154636
...

Sheet Sheet11
B1: actual | C1: predict | F1: actual | G1: predict | J1: actual | K1: predict | N1: actual | O1: predict
A2: -73 | B2: 1 | C2: 0.8140472 | E2: -49 | F2: 1 | G2: 0.13886646 | I2: -19 | J2: 1 | K2: 0.60397273 | M2: 26 | N2: 0.5491525 | O2: 0.5233798
A3: -71 | B3: 1 | C3: 0.757595 | E3: -48 | F3: 1 | G3: 0.07406551 | I3: -18 | J3: 0.54166667 | K3: 0.58467422 | M3: 30 | N3: 0.5229666 | O3: 0.5082496
A4: -70 | B4: 1 | C4: 0.7870852 | E4: -47 | F4: 0 | G4: 0.07071232 | I4: -17 | J4: 0.60238569 | K4: 0.57374391 | M4: 32 | N4: 0.4985127 | O4: 0.5011444
A5: -68 | B5: 1 | C5: 0.7616048 | E5: -46 | F5: 0.25 | G5: 0.08383448 | I5: -16 | J5: 0.60540403 | K5: 0.56462187 | M5: 36 | N5: 0.5402924 | O5: 0.487701
A6: -67 | B6: 1 | C6: 0.7417774 | E6: -45 | F6: 0.3333333 | G6: 0.13833734 | I6: -15 | J6: 0.58124687 | K6: 0.55074199 | M6: 39 | N6: 0.4971885 | O6: 0.4759633
A7: -66 | B7: 1 | C7: 0.6022017 | E7: -44 | F7: 0.5 | G7: 0.12301981 | I7: -14 | J7: 0.55439331 | K7: 0.53367443 | M7: 40 | N7: 0.4163421 | O7: 0.472382
A8: -65 | B8: 1 | C8: 0.7428138 | E8: -43 | F8: 0 | G8: 0.08297675 | I8: -13 | J8: 0.54201025 | K8: 0.52039796 | M8: 41 | N8: 0.5412804 | O8: 0.4702986
A9: -64 | B9: 1 | C9: 0.7366304 | E9: -42 | F9: 0.3333333 | G9: 0.21563146 | I9: -12 | J9: 0.51743332 | K9: 0.50591417 | M9: 42 | N9: 0.4743006 | O9: 0.468768
A10: -63 | B10: 1 | C10: 0.7182323 | E10: -41 | F10: 0.1111111 | G10: 0.17227506 | I10: -11 | J10: 0.5010004 | K10: 0.49413419 | M10: 43 | N10: 0.5261957 | O10: 0.4656309
A11: -62 | B11: 1 | C11: 0.7150825 | E11: -40 | F11: 0.6 | G11: 0.14522862 | I11: -10 | J11: 0.48975222 | K11: 0.48311545 | M11: 44 | N11: 0.5073851 | O11: 0.4598346
A12: -61 | B12: 1 | C12: 0.6766305 | E12: -39 | F12: 0.3333333 | G12: 0.14076471 | I12: -9 | J12: 0.47251514 | K12: 0.47167869 | M12: 45 | N12: 0.4226622 | O12: 0.4542668
