Workbook
Name temp: 'Input-equal'!$H$3:$I$102
Name temp: 'Input-lag'!$H$3:$I$102
Name temp_1: 'Pivot - lag'!#REF!
Name temp_1: 'Pivot-equal'!#REF!
Name temp_11: 'Input-equal'!$K$3:$L$102
Name temp_12: 'Input-equal'!$N$3:$O$101
Name temp_6: 'Input-lag'!$K$3:$L$102
Name temp_8: 'Input-lag'!$N$3:$O$102
Name temp_9: 'Input-equal'!$B$3:$E$1179
Name temp_9: 'Input-lag'!$B$3:$E$1403

Sheet Result-Combine
D3: Total | E3: Top 10 | F3: Top 5 | G3: Top 1 | H3: N/A | I3: Remaining | J3: Month Lag | M3: Top 10 | N3: Top 5 | O3: Top 1 | P3: N/A | Q3: Remaining
C4: ='Result-lag'!C4 -> 39083 | D4: =IF('Result-lag'!$O4<'Result -equal'!$O4,'Result-lag'!D4,'Result -equal'!D4) -> 4.8986974e+10 | E4: =IF('Result-lag'!$O4<'Result -equal'!$O4,'Result-lag'!E4,'Result -equal'!E4) -> 4.0280509e+10 | F4: =IF('Result-lag'!$O4<'Result -equal'!$O4,'Result-lag'!F4,'Result -equal'!F4) -> 3.2982462e+10 | G4: =IF('Result-lag'!$O4<'Result -equal'!$O4,'Result-lag'!G4,'Result -equal'!G4) -> 1.2068563e+10 | H4: =IF('Result-lag'!$O4<'Result -equal'!$O4,'Result-lag'!H4,'Result -equal'!H4) -> 1.8054911e+09 | I4: =IF('Result-lag'!$O4<'Result -equal'!$O4,'Result-lag'!I4,'Result -equal'!I4) -> 9.2902344e+08 | J4: =IF('Result-lag'!$O4<'Result -equal'!$O4,1,0) -> 1 | L4: =C4 -> 39083 | M4: =E4/$D4 -> 0.8222698 | N4: =F4/$D4 -> 0.67329045 | O4: =G4/$D4 -> 0.24636269 | P4: =H4/$D4 -> 0.036856555 | Q4: =I4/$D4 -> 0.018964704
C5: ='Result-lag'!C5 -> 39114 | D5: =IF('Result-lag'!$O5<'Result -equal'!$O5,'Result-lag'!D5,'Result -equal'!D5) -> 5.2453434e+10 | E5: =IF('Result-lag'!$O5<'Result -equal'!$O5,'Result-lag'!E5,'Result -equal'!E5) -> 4.4459011e+10 | F5: =IF('Result-lag'!$O5<'Result -equal'!$O5,'Result-lag'!F5,'Result -equal'!F5) -> 3.7335367e+10 | G5: =IF('Result-lag'!$O5<'Result -equal'!$O5,'Result-lag'!G5,'Result -equal'!G5) -> 1.4906337e+10 | H5: =IF('Result-lag'!$O5<'Result -equal'!$O5,'Result-lag'!H5,'Result -equal'!H5) -> 1.6799903e+09 | I5: =IF('Result-lag'!$O5<'Result -equal'!$O5,'Result-lag'!I5,'Result -equal'!I5) -> 668892203 | J5: =IF('Result-lag'!$O5<'Result -equal'!$O5,1,0) -> 1 | L5: =C5 -> 39114 | M5: =E5/$D5 -> 0.8475901 | N5: =F5/$D5 -> 0.71178118 | O5: =G5/$D5 -> 0.28418229 | P5: =H5/$D5 -> 0.032028224 | Q5: =I5/$D5 -> 0.012752115
C6: ='Result-lag'!C6 -> 39142 | D6: =IF('Result-lag'!$O6<'Result -equal'!$O6,'Result-lag'!D6,'Result -equal'!D6) -> 4.7757144e+10 | E6: =IF('Result-lag'!$O6<'Result -equal'!$O6,'Result-lag'!E6,'Result -equal'!E6) -> 3.9699963e+10 | F6: =IF('Result-lag'!$O6<'Result -equal'!$O6,'Result-lag'!F6,'Result -equal'!F6) -> 3.1729644e+10 | G6: =IF('Result-lag'!$O6<'Result -equal'!$O6,'Result-lag'!G6,'Result -equal'!G6) -> 1.1915399e+10 | H6: =IF('Result-lag'!$O6<'Result -equal'!$O6,'Result-lag'!H6,'Result -equal'!H6) -> 1.6727128e+09 | I6: =IF('Result-lag'!$O6<'Result -equal'!$O6,'Result-lag'!I6,'Result -equal'!I6) -> 7.5401117e+08 | J6: =IF('Result-lag'!$O6<'Result -equal'!$O6,1,0) -> 1 | L6: =C6 -> 39142 | M6: =E6/$D6 -> 0.83128848 | N6: =F6/$D6 -> 0.66439576 | O6: =G6/$D6 -> 0.24949983 | P6: =H6/$D6 -> 0.035025394 | Q6: =I6/$D6 -> 0.015788448
C7: ='Result-lag'!C7 -> 39173 | D7: =IF('Result-lag'!$O7<'Result -equal'!$O7,'Result-lag'!D7,'Result -equal'!D7) -> 5.2540646e+10 | E7: =IF('Result-lag'!$O7<'Result -equal'!$O7,'Result-lag'!E7,'Result -equal'!E7) -> 4.4612018e+10 | F7: =IF('Result-lag'!$O7<'Result -equal'!$O7,'Result-lag'!F7,'Result -equal'!F7) -> 3.6456609e+10 | G7: =IF('Result-lag'!$O7<'Result -equal'!$O7,'Result-lag'!G7,'Result -equal'!G7) -> 1.3440548e+10 | H7: =IF('Result-lag'!$O7<'Result -equal'!$O7,'Result-lag'!H7,'Result -equal'!H7) -> 1.5829348e+09 | I7: =IF('Result-lag'!$O7<'Result -equal'!$O7,'Result-lag'!I7,'Result -equal'!I7) -> 6.8427019e+08 | J7: =IF('Result-lag'!$O7<'Result -equal'!$O7,1,0) -> 1 | L7: =C7 -> 39173 | M7: =E7/$D7 -> 0.84909535 | N7: =F7/$D7 -> 0.69387438 | O7: =G7/$D7 -> 0.25581238 | P7: =H7/$D7 -> 0.030127813 | Q7: =I7/$D7 -> 0.013023635
C8: ='Result-lag'!C8 -> 39203 | D8: =IF('Result-lag'!$O8<'Result -equal'!$O8,'Result-lag'!D8,'Result -equal'!D8) -> 5.5030124e+10 | E8: =IF('Result-lag'!$O8<'Result -equal'!$O8,'Result-lag'!E8,'Result -equal'!E8) -> 4.5163386e+10 | F8: =IF('Result-lag'!$O8<'Result -equal'!$O8,'Result-lag'!F8,'Result -equal'!F8) -> 3.8184313e+10 | G8: =IF('Result-lag'!$O8<'Result -equal'!$O8,'Result-lag'!G8,'Result -equal'!G8) -> 1.458999e+10 | H8: =IF('Result-lag'!$O8<'Result -equal'!$O8,'Result-lag'!H8,'Result -equal'!H8) -> 2.7729062e+09 | I8: =IF('Result-lag'!$O8<'Result -equal'!$O8,'Result-lag'!I8,'Result -equal'!I8) -> 7.9461413e+08 | J8: =IF('Result-lag'!$O8<'Result -equal'!$O8,1,0) -> 1 | L8: =C8 -> 39203 | M8: =E8/$D8 -> 0.82070296 | N8: =F8/$D8 -> 0.69388019 | O8: =G8/$D8 -> 0.26512733 | P8: =H8/$D8 -> 0.050388877 | Q8: =I8/$D8 -> 0.014439621
C9: ='Result-lag'!C9 -> 39234 | D9: =IF('Result-lag'!$O9<'Result -equal'!$O9,'Result-lag'!D9,'Result -equal'!D9) -> 6.3791156e+10 | E9: =IF('Result-lag'!$O9<'Result -equal'!$O9,'Result-lag'!E9,'Result -equal'!E9) -> 5.1753074e+10 | F9: =IF('Result-lag'!$O9<'Result -equal'!$O9,'Result-lag'!F9,'Result -equal'!F9) -> 4.1821075e+10 | G9: =IF('Result-lag'!$O9<'Result -equal'!$O9,'Result-lag'!G9,'Result -equal'!G9) -> 1.5230409e+10 | H9: =IF('Result-lag'!$O9<'Result -equal'!$O9,'Result-lag'!H9,'Result -equal'!H9) -> 2.7963526e+09 | I9: =IF('Result-lag'!$O9<'Result -equal'!$O9,'Result-lag'!I9,'Result -equal'!I9) -> 7.1313849e+08 | J9: =IF('Result-lag'!$O9<'Result -equal'!$O9,1,0) -> 1 | L9: =C9 -> 39234 | M9: =E9/$D9 -> 0.81128917 | N9: =F9/$D9 -> 0.65559362 | O9: =G9/$D9 -> 0.23875425 | P9: =H9/$D9 -> 0.043836054 | Q9: =I9/$D9 -> 0.011179269
C10: ='Result-lag'!C10 -> 39264 | D10: =IF('Result-lag'!$O10<'Result -equal'!$O10,'Result-lag'!D10,'Result -equal'!D10) -> 6.6543384e+10 | E10: =IF('Result-lag'!$O10<'Result -equal'!$O10,'Result-lag'!E10,'Result -equal'!E10) -> 5.4801492e+10 | F10: =IF('Result-lag'!$O10<'Result -equal'!$O10,'Result-lag'!F10,'Result -equal'!F10) -> 4.5598191e+10 | G10: =IF('Result-lag'!$O10<'Result -equal'!$O10,'Result-lag'!G10,'Result -equal'!G10) -> 1.7586654e+10 | H10: =IF('Result-lag'!$O10<'Result -equal'!$O10,'Result-lag'!H10,'Result -equal'!H10) -> 2.979152e+09 | I10: =IF('Result-lag'!$O10<'Result -equal'!$O10,'Result-lag'!I10,'Result -equal'!I10) -> 9.7079402e+08 | J10: =IF('Result-lag'!$O10<'Result -equal'!$O10,1,0) -> 1 | L10: =C10 -> 39264 | M10: =E10/$D10 -> 0.82354532 | N10: =F10/$D10 -> 0.68524004 | O10: =G10/$D10 -> 0.26428854 | P10: =H10/$D10 -> 0.044770071 | Q10: =I10/$D10 -> 0.014588889
C11: ='Result-lag'!C11 -> 39295 | D11: =IF('Result-lag'!$O11<'Result -equal'!$O11,'Result-lag'!D11,'Result -equal'!D11) -> 6.6841769e+10 | E11: =IF('Result-lag'!$O11<'Result -equal'!$O11,'Result-lag'!E11,'Result -equal'!E11) -> 5.4076499e+10 | F11: =IF('Result-lag'!$O11<'Result -equal'!$O11,'Result-lag'!F11,'Result -equal'!F11) -> 4.3577028e+10 | G11: =IF('Result-lag'!$O11<'Result -equal'!$O11,'Result-lag'!G11,'Result -equal'!G11) -> 1.5188068e+10 | H11: =IF('Result-lag'!$O11<'Result -equal'!$O11,'Result-lag'!H11,'Result -equal'!H11) -> 3.267541e+09 | I11: =IF('Result-lag'!$O11<'Result -equal'!$O11,'Result-lag'!I11,'Result -equal'!I11) -> 7.1026208e+08 | J11: =IF('Result-lag'!$O11<'Result -equal'!$O11,1,0) -> 1 | L11: =C11 -> 39295 | M11: =E11/$D11 -> 0.80902256 | N11: =F11/$D11 -> 0.65194307 | O11: =G11/$D11 -> 0.22722421 | P11: =H11/$D11 -> 0.048884718 | Q11: =I11/$D11 -> 0.010626022
C12: ='Result-lag'!C12 -> 39326 | D12: =IF('Result-lag'!$O12<'Result -equal'!$O12,'Result-lag'!D12,'Result -equal'!D12) -> 5.8844727e+10 | E12: =IF('Result-lag'!$O12<'Result -equal'!$O12,'Result-lag'!E12,'Result -equal'!E12) -> 4.8436392e+10 | F12: =IF('Result-lag'!$O12<'Result -equal'!$O12,'Result-lag'!F12,'Result -equal'!F12) -> 3.8360575e+10 | G12: =IF('Result-lag'!$O12<'Result -equal'!$O12,'Result-lag'!G12,'Result -equal'!G12) -> 1.3829269e+10 | H12: =IF('Result-lag'!$O12<'Result -equal'!$O12,'Result-lag'!H12,'Result -equal'!H12) -> 2.5758234e+09 | I12: =IF('Result-lag'!$O12<'Result -equal'!$O12,'Result-lag'!I12,'Result -equal'!I12) -> 7.790342e+08 | J12: =IF('Result-lag'!$O12<'Result -equal'!$O12,1,0) -> 1 | L12: =C12 -> 39326 | M12: =E12/$D12 -> 0.82312205 | N12: =F12/$D12 -> 0.65189487 | O12: =G12/$D12 -> 0.23501288 | P12: =H12/$D12 -> 0.043773223 | Q12: =I12/$D12 -> 0.013238811
C13: ='Result-lag'!C13 -> 39356 | D13: =IF('Result-lag'!$O13<'Result -equal'!$O13,'Result-lag'!D13,'Result -equal'!D13) -> 6.1720789e+10 | E13: =IF('Result-lag'!$O13<'Result -equal'!$O13,'Result-lag'!E13,'Result -equal'!E13) -> 4.9150688e+10 | F13: =IF('Result-lag'!$O13<'Result -equal'!$O13,'Result-lag'!F13,'Result -equal'!F13) -> 4.018948e+10 | G13: =IF('Result-lag'!$O13<'Result -equal'!$O13,'Result-lag'!G13,'Result -equal'!G13) -> 1.6061361e+10 | H13: =IF('Result-lag'!$O13<'Result -equal'!$O13,'Result-lag'!H13,'Result -equal'!H13) -> 2.5699712e+09 | I13: =IF('Result-lag'!$O13<'Result -equal'!$O13,'Result-lag'!I13,'Result -equal'!I13) -> 7.0701634e+08 | J13: =IF('Result-lag'!$O13<'Result -equal'!$O13,1,0) -> 1 | L13: =C13 -> 39356 | M13: =E13/$D13 -> 0.79633927 | N13: =F13/$D13 -> 0.65114981 | O13: =G13/$D13 -> 0.26022611 | P13: =H13/$D13 -> 0.041638664 | Q13: =I13/$D13 -> 0.011455076
C14: ='Result-lag'!C14 -> 39387 | D14: =IF('Result-lag'!$O14<'Result -equal'!$O14,'Result-lag'!D14,'Result -equal'!D14) -> 5.7017095e+10 | E14: =IF('Result-lag'!$O14<'Result -equal'!$O14,'Result-lag'!E14,'Result -equal'!E14) -> 4.7384231e+10 | F14: =IF('Result-lag'!$O14<'Result -equal'!$O14,'Result-lag'!F14,'Result -equal'!F14) -> 3.7132353e+10 | G14: =IF('Result-lag'!$O14<'Result -equal'!$O14,'Result-lag'!G14,'Result -equal'!G14) -> 1.3009808e+10 | H14: =IF('Result-lag'!$O14<'Result -equal'!$O14,'Result-lag'!H14,'Result -equal'!H14) -> 2.0604413e+09 | I14: =IF('Result-lag'!$O14<'Result -equal'!$O14,'Result-lag'!I14,'Result -equal'!I14) -> 7.1463558e+08 | J14: =IF('Result-lag'!$O14<'Result -equal'!$O14,1,0) -> 1 | L14: =C14 -> 39387 | M14: =E14/$D14 -> 0.83105304 | N14: =F14/$D14 -> 0.65124947 | O14: =G14/$D14 -> 0.22817381 | P14: =H14/$D14 -> 0.036137255 | Q14: =I14/$D14 -> 0.012533707
C15: ='Result-lag'!C15 -> 39417 | D15: =IF('Result-lag'!$O15<'Result -equal'!$O15,'Result-lag'!D15,'Result -equal'!D15) -> 5.7339599e+10 | E15: =IF('Result-lag'!$O15<'Result -equal'!$O15,'Result-lag'!E15,'Result -equal'!E15) -> 4.6640588e+10 | F15: =IF('Result-lag'!$O15<'Result -equal'!$O15,'Result-lag'!F15,'Result -equal'!F15) -> 3.5423645e+10 | G15: =IF('Result-lag'!$O15<'Result -equal'!$O15,'Result-lag'!G15,'Result -equal'!G15) -> 1.2603634e+10 | H15: =IF('Result-lag'!$O15<'Result -equal'!$O15,'Result-lag'!H15,'Result -equal'!H15) -> 2.6422772e+09 | I15: =IF('Result-lag'!$O15<'Result -equal'!$O15,'Result-lag'!I15,'Result -equal'!I15) -> 6.3213746e+08 | J15: =IF('Result-lag'!$O15<'Result -equal'!$O15,1,0) -> 1 | L15: =C15 -> 39417 | M15: =E15/$D15 -> 0.81340974 | N15: =F15/$D15 -> 0.61778677 | O15: =G15/$D15 -> 0.2198068 | P15: =H15/$D15 -> 0.046081194 | Q15: =I15/$D15 -> 0.011024449
... C30: ='Result-lag'!C30 -> 39873 | D30: =IF('Result-lag'!$O30<'Result -equal'!$O30,'Result-lag'!D30,'Result -equal'!D30) -> 4.4753199e+10 | E30: =IF('Result-lag'!$O30<'Result -equal'!$O30,'Result-lag'!E30,'Result -equal'!E30) -> 3.2646008e+10 | F30: =IF('Result-lag'!$O30<'Result -equal'!$O30,'Result-lag'!F30,'Result -equal'!F30) -> 2.7275317e+10 | G30: =IF('Result-lag'!$O30<'Result -equal'!$O30,'Result-lag'!G30,'Result -equal'!G30) -> 9.9855092e+09 | H30: =IF('Result-lag'!$O30<'Result -equal'!$O30,'Result-lag'!H30,'Result -equal'!H30) -> 7.2828385e+09 | I30: =IF('Result-lag'!$O30<'Result -equal'!$O30,'Result-lag'!I30,'Result -equal'!I30) -> 7.0821182e+08 | J30: =IF('Result-lag'!$O30<'Result -equal'!$O30,1,0) -> 1 | L30: =C30 -> 39873 | M30: =E30/$D30 -> 0.72946759 | N30: =F30/$D30 -> 0.60946074 | O30: =G30/$D30 -> 0.22312392 | P30: =H30/$D30 -> 0.16273336 | Q30: =I30/$D30 -> 0.015824831
C31: ='Result-lag'!C31 -> 39904 | D31: =IF('Result-lag'!$O31>'Result -equal'!$O31,'Result-lag'!D31,'Result -equal'!D31) -> 8.9107407e+10 | E31: =IF('Result-lag'!$O31>'Result -equal'!$O31,'Result-lag'!E31,'Result -equal'!E31) -> 6.8408727e+10 | F31: =IF('Result-lag'!$O31>'Result -equal'!$O31,'Result-lag'!F31,'Result -equal'!F31) -> 5.9033004e+10 | G31: =IF('Result-lag'!$O31>'Result -equal'!$O31,'Result-lag'!G31,'Result -equal'!G31) -> 2.1059328e+10 | H31: =IF('Result-lag'!$O31>'Result -equal'!$O31,'Result-lag'!H31,'Result -equal'!H31) -> 1.3124114e+10 | I31: =IF('Result-lag'!$O31>'Result -equal'!$O31,'Result-lag'!I31,'Result -equal'!I31) -> 9.8034351e+08 | J31: =IF('Result-lag'!$O31<'Result -equal'!$O31,1,0) -> 0 | L31: =C31 -> 39904 | M31: =E31/$D31 -> 0.7677109 | N31: =F31/$D31 -> 0.66249267 | O31: =G31/$D31 -> 0.23633644 | P31: =H31/$D31 -> 0.14728421 | Q31: =I31/$D31 -> 0.011001818
C32: ='Result-lag'!C32 -> 39934 | D32: =IF('Result-lag'!$O32>'Result -equal'!$O32,'Result-lag'!D32,'Result -equal'!D32) -> 5.6341876e+10 | E32: =IF('Result-lag'!$O32>'Result -equal'!$O32,'Result-lag'!E32,'Result -equal'!E32) -> 3.6074918e+10 | F32: =IF('Result-lag'!$O32>'Result -equal'!$O32,'Result-lag'!F32,'Result -equal'!F32) -> 2.9187086e+10 | G32: =IF('Result-lag'!$O32>'Result -equal'!$O32,'Result-lag'!G32,'Result -equal'!G32) -> 1.1006091e+10 | H32: =IF('Result-lag'!$O32>'Result -equal'!$O32,'Result-lag'!H32,'Result -equal'!H32) -> 1.4916254e+10 | I32: =IF('Result-lag'!$O32>'Result -equal'!$O32,'Result-lag'!I32,'Result -equal'!I32) -> 5.1348512e+08 | J32: =IF('Result-lag'!$O32<'Result -equal'!$O32,1,0) -> 0 | L32: =C32 -> 39934 | M32: =E32/$D32 -> 0.64028607 | N32: =F32/$D32 -> 0.5180354 | O32: =G32/$D32 -> 0.19534477 | P32: =H32/$D32 -> 0.26474542 | Q32: =I32/$D32 -> 0.0091137384
C33: ='Result-lag'!C33 -> 39965 | D33: =IF('Result-lag'!$O33>'Result -equal'!$O33,'Result-lag'!D33,'Result -equal'!D33) -> 1.2605633e+11 | E33: =IF('Result-lag'!$O33>'Result -equal'!$O33,'Result-lag'!E33,'Result -equal'!E33) -> 4.7800828e+10 | F33: =IF('Result-lag'!$O33>'Result -equal'!$O33,'Result-lag'!F33,'Result -equal'!F33) -> 4.114211e+10 | G33: =IF('Result-lag'!$O33>'Result -equal'!$O33,'Result-lag'!G33,'Result -equal'!G33) -> 13967560067 | H33: =IF('Result-lag'!$O33>'Result -equal'!$O33,'Result-lag'!H33,'Result -equal'!H33) -> 7.1546121e+10 | I33: =IF('Result-lag'!$O33>'Result -equal'!$O33,'Result-lag'!I33,'Result -equal'!I33) -> 7.5091474e+08 | J33: =IF('Result-lag'!$O33<'Result -equal'!$O33,1,0) -> 0 | L33: =C33 -> 39965 | M33: =E33/$D33 -> 0.37920211 | N33: =F33/$D33 -> 0.32637876 | O33: =G33/$D33 -> 0.11080411 | P33: =H33/$D33 -> 0.5675726 | Q33: =I33/$D33 -> 0.0059569774
C34: ='Result-lag'!C34 -> 39995 | D34: =IF('Result-lag'!$O34>'Result -equal'!$O34,'Result-lag'!D34,'Result -equal'!D34) -> 1.2791682e+11 | E34: =IF('Result-lag'!$O34>'Result -equal'!$O34,'Result-lag'!E34,'Result -equal'!E34) -> 7.1000462e+10 | F34: =IF('Result-lag'!$O34>'Result -equal'!$O34,'Result-lag'!F34,'Result -equal'!F34) -> 6.2469997e+10 | G34: =IF('Result-lag'!$O34>'Result -equal'!$O34,'Result-lag'!G34,'Result -equal'!G34) -> 2.2149964e+10 | H34: =IF('Result-lag'!$O34>'Result -equal'!$O34,'Result-lag'!H34,'Result -equal'!H34) -> 4.8580167e+10 | I34: =IF('Result-lag'!$O34>'Result -equal'!$O34,'Result-lag'!I34,'Result -equal'!I34) -> 1.1450267e+09 | J34: =IF('Result-lag'!$O34<'Result -equal'!$O34,1,0) -> 0 | L34: =C34 -> 39995 | M34: =E34/$D34 -> 0.55505182 | N34: =F34/$D34 -> 0.48836423 | O34: =G34/$D34 -> 0.17315912 | P34: =H34/$D34 -> 0.37977936 | Q34: =I34/$D34 -> 0.0089513384
C35: ='Result-lag'!C35 -> 40026 | D35: =IF('Result-lag'!$O35>'Result -equal'!$O35,'Result-lag'!D35,'Result -equal'!D35) -> 7.8436522e+10 | E35: =IF('Result-lag'!$O35>'Result -equal'!$O35,'Result-lag'!E35,'Result -equal'!E35) -> 5.376059e+10 | F35: =IF('Result-lag'!$O35>'Result -equal'!$O35,'Result-lag'!F35,'Result -equal'!F35) -> 4.6530708e+10 | G35: =IF('Result-lag'!$O35>'Result -equal'!$O35,'Result-lag'!G35,'Result -equal'!G35) -> 1.7966598e+10 | H35: =IF('Result-lag'!$O35>'Result -equal'!$O35,'Result-lag'!H35,'Result -equal'!H35) -> 1.6641693e+10 | I35: =IF('Result-lag'!$O35>'Result -equal'!$O35,'Result-lag'!I35,'Result -equal'!I35) -> 1.0225149e+09 | J35: =IF('Result-lag'!$O35<'Result -equal'!$O35,1,0) -> 0 | L35: =C35 -> 40026 | M35: =E35/$D35 -> 0.68540252 | N35: =F35/$D35 -> 0.59322757 | O35: =G35/$D35 -> 0.22905909 | P35: =H35/$D35 -> 0.21216766 | Q35: =I35/$D35 -> 0.013036209
C36: ='Result-lag'!C36 -> 40057 | D36: =IF('Result-lag'!$O36<'Result -equal'!$O36,'Result-lag'!D36,'Result -equal'!D36) -> 5.9684456e+10 | E36: =IF('Result-lag'!$O36<'Result -equal'!$O36,'Result-lag'!E36,'Result -equal'!E36) -> 3.9894123e+10 | F36: =IF('Result-lag'!$O36<'Result -equal'!$O36,'Result-lag'!F36,'Result -equal'!F36) -> 3.4767573e+10 | G36: =IF('Result-lag'!$O36<'Result -equal'!$O36,'Result-lag'!G36,'Result -equal'!G36) -> 1.4871498e+10 | H36: =IF('Result-lag'!$O36<'Result -equal'!$O36,'Result-lag'!H36,'Result -equal'!H36) -> 1.3851899e+10 | I36: =IF('Result-lag'!$O36<'Result -equal'!$O36,'Result-lag'!I36,'Result -equal'!I36) -> 1.0994973e+09 | J36: =IF('Result-lag'!$O36<'Result -equal'!$O36,1,0) -> 1 | L36: =C36 -> 40057 | M36: =E36/$D36 -> 0.66841729 | N36: =F36/$D36 -> 0.58252307 | O36: =G36/$D36 -> 0.24916869 | P36: =H36/$D36 -> 0.23208554 | Q36: =I36/$D36 -> 0.018421837
C37: ='Result-lag'!C37 -> 40087 | D37: =IF('Result-lag'!$O37<'Result -equal'!$O37,'Result-lag'!D37,'Result -equal'!D37) -> 5.638603e+10 | E37: =IF('Result-lag'!$O37<'Result -equal'!$O37,'Result-lag'!E37,'Result -equal'!E37) -> 3.9812999e+10 | F37: =IF('Result-lag'!$O37<'Result -equal'!$O37,'Result-lag'!F37,'Result -equal'!F37) -> 3.6252926e+10 | G37: =IF('Result-lag'!$O37<'Result -equal'!$O37,'Result-lag'!G37,'Result -equal'!G37) -> 1.5019541e+10 | H37: =IF('Result-lag'!$O37<'Result -equal'!$O37,'Result-lag'!H37,'Result -equal'!H37) -> 1.2597169e+10 | I37: =IF('Result-lag'!$O37<'Result -equal'!$O37,'Result-lag'!I37,'Result -equal'!I37) -> 7.1926646e+08 | J37: =IF('Result-lag'!$O37<'Result -equal'!$O37,1,0) -> 1 | L37: =C37 -> 40087 | M37: =E37/$D37 -> 0.70607913 | N37: =F37/$D37 -> 0.64294162 | O37: =G37/$D37 -> 0.26636989 | P37: =H37/$D37 -> 0.22340939 | Q37: =I37/$D37 -> 0.012756111
C38: ='Result-lag'!C38 -> 40118 | D38: =IF('Result-lag'!$O38<'Result -equal'!$O38,'Result-lag'!D38,'Result -equal'!D38) -> 3.7508648e+10 | E38: =IF('Result-lag'!$O38<'Result -equal'!$O38,'Result-lag'!E38,'Result -equal'!E38) -> 2.7299804e+10 | F38: =IF('Result-lag'!$O38<'Result -equal'!$O38,'Result-lag'!F38,'Result -equal'!F38) -> 2.3964218e+10 | G38: =IF('Result-lag'!$O38<'Result -equal'!$O38,'Result-lag'!G38,'Result -equal'!G38) -> 9.8019521e+09 | H38: =IF('Result-lag'!$O38<'Result -equal'!$O38,'Result-lag'!H38,'Result -equal'!H38) -> 7.0659361e+09 | I38: =IF('Result-lag'!$O38<'Result -equal'!$O38,'Result-lag'!I38,'Result -equal'!I38) -> 7.5240953e+08 | J38: =IF('Result-lag'!$O38<'Result -equal'!$O38,1,0) -> 1 | L38: =C38 -> 40118 | M38: =E38/$D38 -> 0.72782692 | N38: =F38/$D38 -> 0.63889847 | O38: =G38/$D38 -> 0.26132512 | P38: =H38/$D38 -> 0.18838152 | Q38: =I38/$D38 -> 0.020059628
C39: ='Result-lag'!C39 -> 40148 | D39: =IF('Result-lag'!$O39<'Result -equal'!$O39,'Result-lag'!D39,'Result -equal'!D39) -> 3.650884e+10 | E39: =IF('Result-lag'!$O39<'Result -equal'!$O39,'Result-lag'!E39,'Result -equal'!E39) -> 2.6456406e+10 | F39: =IF('Result-lag'!$O39<'Result -equal'!$O39,'Result-lag'!F39,'Result -equal'!F39) -> 2.2409303e+10 | G39: =IF('Result-lag'!$O39<'Result -equal'!$O39,'Result-lag'!G39,'Result -equal'!G39) -> 7.9190408e+09 | H39: =IF('Result-lag'!$O39<'Result -equal'!$O39,'Result-lag'!H39,'Result -equal'!H39) -> 6.3677379e+09 | I39: =IF('Result-lag'!$O39<'Result -equal'!$O39,'Result-lag'!I39,'Result -equal'!I39) -> 5.9108656e+08 | J39: =IF('Result-lag'!$O39<'Result -equal'!$O39,1,0) -> 1 | L39: =C39 -> 40148 | M39: =E39/$D39 -> 0.72465753 | N39: =F39/$D39 -> 0.61380486 | O39: =G39/$D39 -> 0.21690749 | P39: =H39/$D39 -> 0.17441633 | Q39: =I39/$D39 -> 0.016190231
C40: ='Result-lag'!C40 -> 40179 | D40: =IF('Result-lag'!$O40<'Result -equal'!$O40,'Result-lag'!D40,'Result -equal'!D40) -> 4.7221078e+10 | E40: =IF('Result-lag'!$O40<'Result -equal'!$O40,'Result-lag'!E40,'Result -equal'!E40) -> 3.5319042e+10 | F40: =IF('Result-lag'!$O40<'Result -equal'!$O40,'Result-lag'!F40,'Result -equal'!F40) -> 3.0473733e+10 | G40: =IF('Result-lag'!$O40<'Result -equal'!$O40,'Result-lag'!G40,'Result -equal'!G40) -> 1.1776429e+10 | H40: =IF('Result-lag'!$O40<'Result -equal'!$O40,'Result-lag'!H40,'Result -equal'!H40) -> 7.787527e+09 | I40: =IF('Result-lag'!$O40<'Result -equal'!$O40,'Result-lag'!I40,'Result -equal'!I40) -> 7.2213822e+08 | J40: =IF('Result-lag'!$O40<'Result -equal'!$O40,1,0) -> 1 | L40: =C40 -> 40179 | M40: =E40/$D40 -> 0.74795077 | N40: =F40/$D40 -> 0.64534175 | O40: =G40/$D40 -> 0.24938925 | P40: =H40/$D40 -> 0.16491633 | Q40: =I40/$D40 -> 0.015292709
C41: ='Result-lag'!C41 -> 40210 | D41: =IF('Result-lag'!$O41<'Result -equal'!$O41,'Result-lag'!D41,'Result -equal'!D41) -> 3.9245939e+10 | E41: =IF('Result-lag'!$O41<'Result -equal'!$O41,'Result-lag'!E41,'Result -equal'!E41) -> 2.8320981e+10 | F41: =IF('Result-lag'!$O41<'Result -equal'!$O41,'Result-lag'!F41,'Result -equal'!F41) -> 2.5122317e+10 | G41: =IF('Result-lag'!$O41<'Result -equal'!$O41,'Result-lag'!G41,'Result -equal'!G41) -> 1.0182718e+10 | H41: =IF('Result-lag'!$O41<'Result -equal'!$O41,'Result-lag'!H41,'Result -equal'!H41) -> 7.3132766e+09 | I41: =IF('Result-lag'!$O41<'Result -equal'!$O41,'Result-lag'!I41,'Result -equal'!I41) -> 7.3011418e+08 | J41: =IF('Result-lag'!$O41<'Result -equal'!$O41,1,0) -> 1 | L41: =C41 -> 40210 | M41: =E41/$D41 -> 0.72162832 | N41: =F41/$D41 -> 0.64012526 | O41: =G41/$D41 -> 0.25945915 | P41: =H41/$D41 -> 0.1863448 | Q41: =I41/$D41 -> 0.01860356
C42: ='Result-lag'!C42 -> 40238 | D42: =IF('Result-lag'!$O42<'Result -equal'!$O42,'Result-lag'!D42,'Result -equal'!D42) -> 4.0750599e+10 | E42: =IF('Result-lag'!$O42<'Result -equal'!$O42,'Result-lag'!E42,'Result -equal'!E42) -> 3.145905e+10 | F42: =IF('Result-lag'!$O42<'Result -equal'!$O42,'Result-lag'!F42,'Result -equal'!F42) -> 2.8719429e+10 | G42: =IF('Result-lag'!$O42<'Result -equal'!$O42,'Result-lag'!G42,'Result -equal'!G42) -> 1.0733754e+10 | H42: =IF('Result-lag'!$O42<'Result -equal'!$O42,'Result-lag'!H42,'Result -equal'!H42) -> 5.5133079e+09 | I42: =IF('Result-lag'!$O42<'Result -equal'!$O42,'Result-lag'!I42,'Result -equal'!I42) -> 8.2270018e+08 | J42: =IF('Result-lag'!$O42<'Result -equal'!$O42,1,0) -> 1 | L42: =C42 -> 40238 | M42: =E42/$D42 -> 0.77198988 | N42: =F42/$D42 -> 0.70476092 | O42: =G42/$D42 -> 0.26340112 | P42: =H42/$D42 -> 0.13529391 | Q42: =I42/$D42 -> 0.020188665
C43: ='Result-lag'!C43 -> 40269 | D43: =IF('Result-lag'!$O43<'Result -equal'!$O43,'Result-lag'!D43,'Result -equal'!D43) -> 3.4495231e+10 | E43: =IF('Result-lag'!$O43<'Result -equal'!$O43,'Result-lag'!E43,'Result -equal'!E43) -> 2.7234086e+10 | F43: =IF('Result-lag'!$O43<'Result -equal'!$O43,'Result-lag'!F43,'Result -equal'!F43) -> 2.4936256e+10 | G43: =IF('Result-lag'!$O43<'Result -equal'!$O43,'Result-lag'!G43,'Result -equal'!G43) -> 8.0104325e+09 | H43: =IF('Result-lag'!$O43<'Result -equal'!$O43,'Result-lag'!H43,'Result -equal'!H43) -> 4.3841867e+09 | I43: =IF('Result-lag'!$O43<'Result -equal'!$O43,'Result-lag'!I43,'Result -equal'!I43) -> 6.3190681e+08 | J43: =IF('Result-lag'!$O43<'Result -equal'!$O43,1,0) -> 1 | L43: =C43 -> 40269 | M43: =E43/$D43 -> 0.78950296 | N43: =F43/$D43 -> 0.72288997 | O43: =G43/$D43 -> 0.23221855 | P43: =H43/$D43 -> 0.12709545 | Q43: =I43/$D43 -> 0.018318672
C44: ='Result-lag'!C44 -> 40299 | D44: =IF('Result-lag'!$O44<'Result -equal'!$O44,'Result-lag'!D44,'Result -equal'!D44) -> 3.4561762e+10 | E44: =IF('Result-lag'!$O44<'Result -equal'!$O44,'Result-lag'!E44,'Result -equal'!E44) -> 2.6609021e+10 | F44: =IF('Result-lag'!$O44<'Result -equal'!$O44,'Result-lag'!F44,'Result -equal'!F44) -> 2.3855723e+10 | G44: =IF('Result-lag'!$O44<'Result -equal'!$O44,'Result-lag'!G44,'Result -equal'!G44) -> 9.7934436e+09 | H44: =IF('Result-lag'!$O44<'Result -equal'!$O44,'Result-lag'!H44,'Result -equal'!H44) -> 4.8786661e+09 | I44: =IF('Result-lag'!$O44<'Result -equal'!$O44,'Result-lag'!I44,'Result -equal'!I44) -> 5.6034352e+08 | J44: =IF('Result-lag'!$O44<'Result -equal'!$O44,1,0) -> 1 | L44: =C44 -> 40299 | M44: =E44/$D44 -> 0.7698977 | N44: =F44/$D44 -> 0.69023459 | O44: =G44/$D44 -> 0.28336066 | P44: =H44/$D44 -> 0.14115791 | Q44: =I44/$D44 -> 0.016212817
C45: ='Result-lag'!C45 -> 40330 | D45: =IF('Result-lag'!$O45<'Result -equal'!$O45,'Result-lag'!D45,'Result -equal'!D45) -> 3.7643702e+10 | E45: =IF('Result-lag'!$O45<'Result -equal'!$O45,'Result-lag'!E45,'Result -equal'!E45) -> 2.6357644e+10 | F45: =IF('Result-lag'!$O45<'Result -equal'!$O45,'Result-lag'!F45,'Result -equal'!F45) -> 2.3095751e+10 | G45: =IF('Result-lag'!$O45<'Result -equal'!$O45,'Result-lag'!G45,'Result -equal'!G45) -> 8.1596999e+09 | H45: =IF('Result-lag'!$O45<'Result -equal'!$O45,'Result-lag'!H45,'Result -equal'!H45) -> 1496216485 | I45: =IF('Result-lag'!$O45<'Result -equal'!$O45,'Result-lag'!I45,'Result -equal'!I45) -> 5.3019842e+09 | J45: =IF('Result-lag'!$O45<'Result -equal'!$O45,1,0) -> 0 | L45: =C45 -> 40330 | M45: =E45/$D45 -> 0.70018733 | N45: =F45/$D45 -> 0.61353558 | O45: =G45/$D45 -> 0.21676135 | P45: =H45/$D45 -> 0.039746794 | Q45: =I45/$D45 -> 0.14084651
C46: ='Result-lag'!C46 -> 40360 | D46: =IF('Result-lag'!$O46<'Result -equal'!$O46,'Result-lag'!D46,'Result -equal'!D46) -> 4.0829244e+10 | E46: =IF('Result-lag'!$O46<'Result -equal'!$O46,'Result-lag'!E46,'Result -equal'!E46) -> 2.8451985e+10 | F46: =IF('Result-lag'!$O46<'Result -equal'!$O46,'Result-lag'!F46,'Result -equal'!F46) -> 2.5054192e+10 | G46: =IF('Result-lag'!$O46<'Result -equal'!$O46,'Result-lag'!G46,'Result -equal'!G46) -> 8.9555419e+09 | H46: =IF('Result-lag'!$O46<'Result -equal'!$O46,'Result-lag'!H46,'Result -equal'!H46) -> 1567537459 | I46: =IF('Result-lag'!$O46<'Result -equal'!$O46,'Result-lag'!I46,'Result -equal'!I46) -> 4.9510459e+09 | J46: =IF('Result-lag'!$O46<'Result -equal'!$O46,1,0) -> 0 | L46: =C46 -> 40360 | M46: =E46/$D46 -> 0.6968531 | N46: =F46/$D46 -> 0.6136335 | O46: =G46/$D46 -> 0.21934136 | P46: =H46/$D46 -> 0.038392517 | Q46: =I46/$D46 -> 0.12126225
C47: ='Result-lag'!C47 -> 40391 | D47: =IF('Result-lag'!$O47<'Result -equal'!$O47,'Result-lag'!D47,'Result -equal'!D47) -> 4.6909005e+10 | E47: =IF('Result-lag'!$O47<'Result -equal'!$O47,'Result-lag'!E47,'Result -equal'!E47) -> 3.0182508e+10 | F47: =IF('Result-lag'!$O47<'Result -equal'!$O47,'Result-lag'!F47,'Result -equal'!F47) -> 2.5021598e+10 | G47: =IF('Result-lag'!$O47<'Result -equal'!$O47,'Result-lag'!G47,'Result -equal'!G47) -> 1.0445667e+10 | H47: =IF('Result-lag'!$O47<'Result -equal'!$O47,'Result-lag'!H47,'Result -equal'!H47) -> 2325261137 | I47: =IF('Result-lag'!$O47<'Result -equal'!$O47,'Result-lag'!I47,'Result -equal'!I47) -> 7.5753204e+09 | J47: =IF('Result-lag'!$O47<'Result -equal'!$O47,1,0) -> 0 | L47: =C47 -> 40391 | M47: =E47/$D47 -> 0.64342674 | N47: =F47/$D47 -> 0.53340713 | O47: =G47/$D47 -> 0.22267935 | P47: =H47/$D47 -> 0.049569611 | Q47: =I47/$D47 -> 0.16148968
... C102: ='Result-lag'!C102 -> 42064 | D102: =IF('Result-lag'!$O102<'Result -equal'!$O102,'Result-lag'!D102,'Result -equal'!D102) -> 2.3910708e+10 | E102: =IF('Result-lag'!$O102<'Result -equal'!$O102,'Result-lag'!E102,'Result -equal'!E102) -> 1.1103072e+10 | F102: =IF('Result-lag'!$O102<'Result -equal'!$O102,'Result-lag'!F102,'Result -equal'!F102) -> 8.8444623e+09 | G102: =IF('Result-lag'!$O102<'Result -equal'!$O102,'Result-lag'!G102,'Result -equal'!G102) -> 4009024386 | H102: =IF('Result-lag'!$O102<'Result -equal'!$O102,'Result-lag'!H102,'Result -equal'!H102) -> 869290480 | I102: =IF('Result-lag'!$O102<'Result -equal'!$O102,'Result-lag'!I102,'Result -equal'!I102) -> 4.9833118e+09 | J102: =IF('Result-lag'!$O102<'Result -equal'!$O102,1,0) -> 0 | L102: =C102 -> 42064 | M102: =E102/$D102 -> 0.46435562 | N102: =F102/$D102 -> 0.36989546 | O102: =G102/$D102 -> 0.16766649 | P102: =H102/$D102 -> 0.036355698 | Q102: =I102/$D102 -> 0.20841339

Sheet Result-lag
D3: Total | E3: Top 10 | F3: Top 5 | G3: Top 1 | H3: N/A | I3: Remaining | L3: Top 10 | M3: Top 5 | N3: Top 1 | O3: N/A | P3: Remaining
C4: ='Input-lag'!H4 -> 39083 | D4: =VLOOKUP(C4,'Input-lag'!H$4:$I$102,2,0) -> 4.8986974e+10 | E4: =VLOOKUP(C4,'Pivot - lag'!$E$4:$F$144,2,0) -> 4.0280509e+10 | F4: =VLOOKUP(C4,'Pivot - lag'!$I$4:$J$144,2,0) -> 3.2982462e+10 | G4: =VLOOKUP(C4,'Pivot - lag'!$M$3:$N$144,2,0) -> 1.2068563e+10 | H4: =VLOOKUP(C4,'Input-lag'!$K$3:$L$102,2,0) -> 1.8054911e+09 | I4: =VLOOKUP(C4,'Input-lag'!temp_8,2,0) -> 9.2902344e+08 | K4: =C4 -> 39083 | L4: =E4/$D4 -> 0.8222698 | M4: =F4/$D4 -> 0.67329045 | N4: =G4/$D4 -> 0.24636269 | O4: =H4/$D4 -> 0.036856555 | P4: =I4/$D4 -> 0.018964704
C5: ='Input-lag'!H5 -> 39114 | D5: =VLOOKUP(C5,'Input-lag'!H$4:$I$102,2,0) -> 5.2453434e+10 | E5: =VLOOKUP(C5,'Pivot - lag'!$E$4:$F$144,2,0) -> 4.4459011e+10 | F5: =VLOOKUP(C5,'Pivot - lag'!$I$4:$J$144,2,0) -> 3.7335367e+10 | G5: =VLOOKUP(C5,'Pivot - lag'!$M$3:$N$144,2,0) -> 1.4906337e+10 | H5: =VLOOKUP(C5,'Input-lag'!$K$3:$L$102,2,0) -> 1.6799903e+09 | I5: =VLOOKUP(C5,'Input-lag'!temp_8,2,0) -> 668892203 | K5: =C5 -> 39114 | L5: =E5/$D5 -> 0.8475901 | M5: =F5/$D5 -> 0.71178118 | N5: =G5/$D5 -> 0.28418229 | O5: =H5/$D5 -> 0.032028224 | P5: =I5/$D5 -> 0.012752115
C6: ='Input-lag'!H6 -> 39142 | D6: =VLOOKUP(C6,'Input-lag'!H$4:$I$102,2,0) -> 4.7757144e+10 | E6: =VLOOKUP(C6,'Pivot - lag'!$E$4:$F$144,2,0) -> 3.9699963e+10 | F6: =VLOOKUP(C6,'Pivot - lag'!$I$4:$J$144,2,0) -> 3.1729644e+10 | G6: =VLOOKUP(C6,'Pivot - lag'!$M$3:$N$144,2,0) -> 1.1915399e+10 | H6: =VLOOKUP(C6,'Input-lag'!$K$3:$L$102,2,0) -> 1.6727128e+09 | I6: =VLOOKUP(C6,'Input-lag'!temp_8,2,0) -> 7.5401117e+08 | K6: =C6 -> 39142 | L6: =E6/$D6 -> 0.83128848 | M6: =F6/$D6 -> 0.66439576 | N6: =G6/$D6 -> 0.24949983 | O6: =H6/$D6 -> 0.035025394 | P6: =I6/$D6 -> 0.015788448
C7: ='Input-lag'!H7 -> 39173 | D7: =VLOOKUP(C7,'Input-lag'!H$4:$I$102,2,0) -> 5.2540646e+10 | E7: =VLOOKUP(C7,'Pivot - lag'!$E$4:$F$144,2,0) -> 4.4612018e+10 | F7: =VLOOKUP(C7,'Pivot - lag'!$I$4:$J$144,2,0) -> 3.6456609e+10 | G7: =VLOOKUP(C7,'Pivot - lag'!$M$3:$N$144,2,0) -> 1.3440548e+10 | H7: =VLOOKUP(C7,'Input-lag'!$K$3:$L$102,2,0) -> 1.5829348e+09 | I7: =VLOOKUP(C7,'Input-lag'!temp_8,2,0) -> 6.8427019e+08 | K7: =C7 -> 39173 | L7: =E7/$D7 -> 0.84909535 | M7: =F7/$D7 -> 0.69387438 | N7: =G7/$D7 -> 0.25581238 | O7: =H7/$D7 -> 0.030127813 | P7: =I7/$D7 -> 0.013023635
C8: ='Input-lag'!H8 -> 39203 | D8: =VLOOKUP(C8,'Input-lag'!H$4:$I$102,2,0) -> 5.5030124e+10 | E8: =VLOOKUP(C8,'Pivot - lag'!$E$4:$F$144,2,0) -> 4.5163386e+10 | F8: =VLOOKUP(C8,'Pivot - lag'!$I$4:$J$144,2,0) -> 3.8184313e+10 | G8: =VLOOKUP(C8,'Pivot - lag'!$M$3:$N$144,2,0) -> 1.458999e+10 | H8: =VLOOKUP(C8,'Input-lag'!$K$3:$L$102,2,0) -> 2.7729062e+09 | I8: =VLOOKUP(C8,'Input-lag'!temp_8,2,0) -> 7.9461413e+08 | K8: =C8 -> 39203 | L8: =E8/$D8 -> 0.82070296 | M8: =F8/$D8 -> 0.69388019 | N8: =G8/$D8 -> 0.26512733 | O8: =H8/$D8 -> 0.050388877 | P8: =I8/$D8 -> 0.014439621
C9: ='Input-lag'!H9 -> 39234 | D9: =VLOOKUP(C9,'Input-lag'!H$4:$I$102,2,0) -> 6.3791156e+10 | E9: =VLOOKUP(C9,'Pivot - lag'!$E$4:$F$144,2,0) -> 5.1753074e+10 | F9: =VLOOKUP(C9,'Pivot - lag'!$I$4:$J$144,2,0) -> 4.1821075e+10 | G9: =VLOOKUP(C9,'Pivot - lag'!$M$3:$N$144,2,0) -> 1.5230409e+10 | H9: =VLOOKUP(C9,'Input-lag'!$K$3:$L$102,2,0) -> 2.7963526e+09 | I9: =VLOOKUP(C9,'Input-lag'!temp_8,2,0) -> 7.1313849e+08 | K9: =C9 -> 39234 | L9: =E9/$D9 -> 0.81128917 | M9: =F9/$D9 -> 0.65559362 | N9: =G9/$D9 -> 0.23875425 | O9: =H9/$D9 -> 0.043836054 | P9: =I9/$D9 -> 0.011179269
C10: ='Input-lag'!H10 -> 39264 | D10: =VLOOKUP(C10,'Input-lag'!H$4:$I$102,2,0) -> 6.6543384e+10 | E10: =VLOOKUP(C10,'Pivot - lag'!$E$4:$F$144,2,0) -> 5.4801492e+10 | F10: =VLOOKUP(C10,'Pivot - lag'!$I$4:$J$144,2,0) -> 4.5598191e+10 | G10: =VLOOKUP(C10,'Pivot - lag'!$M$3:$N$144,2,0) -> 1.7586654e+10 | H10: =VLOOKUP(C10,'Input-lag'!$K$3:$L$102,2,0) -> 2.979152e+09 | I10: =VLOOKUP(C10,'Input-lag'!temp_8,2,0) -> 9.7079402e+08 | K10: =C10 -> 39264 | L10: =E10/$D10 -> 0.82354532 | M10: =F10/$D10 -> 0.68524004 | N10: =G10/$D10 -> 0.26428854 | O10: =H10/$D10 -> 0.044770071 | P10: =I10/$D10 -> 0.014588889
C11: ='Input-lag'!H11 -> 39295 | D11: =VLOOKUP(C11,'Input-lag'!H$4:$I$102,2,0) -> 6.6841769e+10 | E11: =VLOOKUP(C11,'Pivot - lag'!$E$4:$F$144,2,0) -> 5.4076499e+10 | F11: =VLOOKUP(C11,'Pivot - lag'!$I$4:$J$144,2,0) -> 4.3577028e+10 | G11: =VLOOKUP(C11,'Pivot - lag'!$M$3:$N$144,2,0) -> 1.5188068e+10 | H11: =VLOOKUP(C11,'Input-lag'!$K$3:$L$102,2,0) -> 3.267541e+09 | I11: =VLOOKUP(C11,'Input-lag'!temp_8,2,0) -> 7.1026208e+08 | K11: =C11 -> 39295 | L11: =E11/$D11 -> 0.80902256 | M11: =F11/$D11 -> 0.65194307 | N11: =G11/$D11 -> 0.22722421 | O11: =H11/$D11 -> 0.048884718 | P11: =I11/$D11 -> 0.010626022
C12: ='Input-lag'!H12 -> 39326 | D12: =VLOOKUP(C12,'Input-lag'!H$4:$I$102,2,0) -> 5.8844727e+10 | E12: =VLOOKUP(C12,'Pivot - lag'!$E$4:$F$144,2,0) -> 4.8436392e+10 | F12: =VLOOKUP(C12,'Pivot - lag'!$I$4:$J$144,2,0) -> 3.8360575e+10 | G12: =VLOOKUP(C12,'Pivot - lag'!$M$3:$N$144,2,0) -> 1.3829269e+10 | H12: =VLOOKUP(C12,'Input-lag'!$K$3:$L$102,2,0) -> 2.5758234e+09 | I12: =VLOOKUP(C12,'Input-lag'!temp_8,2,0) -> 7.790342e+08 | K12: =C12 -> 39326 | L12: =E12/$D12 -> 0.82312205 | M12: =F12/$D12 -> 0.65189487 | N12: =G12/$D12 -> 0.23501288 | O12: =H12/$D12 -> 0.043773223 | P12: =I12/$D12 -> 0.013238811
C13: ='Input-lag'!H13 -> 39356 | D13: =VLOOKUP(C13,'Input-lag'!H$4:$I$102,2,0) -> 6.1720789e+10 | E13: =VLOOKUP(C13,'Pivot - lag'!$E$4:$F$144,2,0) -> 4.9150688e+10 | F13: =VLOOKUP(C13,'Pivot - lag'!$I$4:$J$144,2,0) -> 4.018948e+10 | G13: =VLOOKUP(C13,'Pivot - lag'!$M$3:$N$144,2,0) -> 1.6061361e+10 | H13: =VLOOKUP(C13,'Input-lag'!$K$3:$L$102,2,0) -> 2.5699712e+09 | I13: =VLOOKUP(C13,'Input-lag'!temp_8,2,0) -> 7.0701634e+08 | K13: =C13 -> 39356 | L13: =E13/$D13 -> 0.79633927 | M13: =F13/$D13 -> 0.65114981 | N13: =G13/$D13 -> 0.26022611 | O13: =H13/$D13 -> 0.041638664 | P13: =I13/$D13 -> 0.011455076
C14: ='Input-lag'!H14 -> 39387 | D14: =VLOOKUP(C14,'Input-lag'!H$4:$I$102,2,0) -> 5.7017095e+10 | E14: =VLOOKUP(C14,'Pivot - lag'!$E$4:$F$144,2,0) -> 4.7384231e+10 | F14: =VLOOKUP(C14,'Pivot - lag'!$I$4:$J$144,2,0) -> 3.7132353e+10 | G14: =VLOOKUP(C14,'Pivot - lag'!$M$3:$N$144,2,0) -> 1.3009808e+10 | H14: =VLOOKUP(C14,'Input-lag'!$K$3:$L$102,2,0) -> 2.0604413e+09 | I14: =VLOOKUP(C14,'Input-lag'!temp_8,2,0) -> 7.1463558e+08 | K14: =C14 -> 39387 | L14: =E14/$D14 -> 0.83105304 | M14: =F14/$D14 -> 0.65124947 | N14: =G14/$D14 -> 0.22817381 | O14: =H14/$D14 -> 0.036137255 | P14: =I14/$D14 -> 0.012533707
C15: ='Input-lag'!H15 -> 39417 | D15: =VLOOKUP(C15,'Input-lag'!H$4:$I$102,2,0) -> 5.7339599e+10 | E15: =VLOOKUP(C15,'Pivot - lag'!$E$4:$F$144,2,0) -> 4.6640588e+10 | F15: =VLOOKUP(C15,'Pivot - lag'!$I$4:$J$144,2,0) -> 3.5423645e+10 | G15: =VLOOKUP(C15,'Pivot - lag'!$M$3:$N$144,2,0) -> 1.2603634e+10 | H15: =VLOOKUP(C15,'Input-lag'!$K$3:$L$102,2,0) -> 2.6422772e+09 | I15: =VLOOKUP(C15,'Input-lag'!temp_8,2,0) -> 6.3213746e+08 | K15: =C15 -> 39417 | L15: =E15/$D15 -> 0.81340974 | M15: =F15/$D15 -> 0.61778677 | N15: =G15/$D15 -> 0.2198068 | O15: =H15/$D15 -> 0.046081194 | P15: =I15/$D15 -> 0.011024449
... C32: ='Input-lag'!H32 -> 39934 | D32: =VLOOKUP(C32,'Input-lag'!H$4:$I$102,2,0) -> 5.6341876e+10 | E32: =VLOOKUP(C32,'Pivot - lag'!$E$4:$F$144,2,0) -> 3.6074918e+10 | F32: =VLOOKUP(C32,'Pivot - lag'!$I$4:$J$144,2,0) -> 2.9187086e+10 | G32: =VLOOKUP(C32,'Pivot - lag'!$M$3:$N$144,2,0) -> 1.1006091e+10 | H32: =VLOOKUP(C32,'Input-lag'!$K$3:$L$102,2,0) -> 1.4916254e+10 | I32: =VLOOKUP(C32,'Input-lag'!temp_8,2,0) -> 5.1348512e+08 | K32: =C32 -> 39934 | L32: =E32/$D32 -> 0.64028607 | M32: =F32/$D32 -> 0.5180354 | N32: =G32/$D32 -> 0.19534477 | O32: =H32/$D32 -> 0.26474542 | P32: =I32/$D32 -> 0.0091137384
B33: =D33+H33 -> 1.9760246e+11 | C33: ='Input-lag'!H33 -> 39965 | D33: =VLOOKUP(C33,'Input-lag'!H$4:$I$102,2,0) -> 1.2605633e+11 | E33: =VLOOKUP(C33,'Pivot - lag'!$E$4:$F$144,2,0) -> 4.7800828e+10 | F33: =VLOOKUP(C33,'Pivot - lag'!$I$4:$J$144,2,0) -> 4.114211e+10 | G33: =VLOOKUP(C33,'Pivot - lag'!$M$3:$N$144,2,0) -> 13967560067 | H33: =VLOOKUP(C33,'Input-lag'!$K$3:$L$102,2,0) -> 7.1546121e+10 | I33: =VLOOKUP(C33,'Input-lag'!temp_8,2,0) -> 7.5091474e+08 | K33: =C33 -> 39965 | L33: =E33/$D33 -> 0.37920211 | M33: =F33/$D33 -> 0.32637876 | N33: =G33/$D33 -> 0.11080411 | O33: =H33/$D33 -> 0.5675726 | P33: =I33/$D33 -> 0.0059569774
C34: ='Input-lag'!H34 -> 39995 | D34: =VLOOKUP(C34,'Input-lag'!H$4:$I$102,2,0) -> 1.2791682e+11 | E34: =VLOOKUP(C34,'Pivot - lag'!$E$4:$F$144,2,0) -> 7.1000462e+10 | F34: =VLOOKUP(C34,'Pivot - lag'!$I$4:$J$144,2,0) -> 6.2469997e+10 | G34: =VLOOKUP(C34,'Pivot - lag'!$M$3:$N$144,2,0) -> 2.2149964e+10 | H34: =VLOOKUP(C34,'Input-lag'!$K$3:$L$102,2,0) -> 4.8580167e+10 | I34: =VLOOKUP(C34,'Input-lag'!temp_8,2,0) -> 1.1450267e+09 | K34: =C34 -> 39995 | L34: =E34/$D34 -> 0.55505182 | M34: =F34/$D34 -> 0.48836423 | N34: =G34/$D34 -> 0.17315912 | O34: =H34/$D34 -> 0.37977936 | P34: =I34/$D34 -> 0.0089513384
C35: ='Input-lag'!H35 -> 40026 | D35: =VLOOKUP(C35,'Input-lag'!H$4:$I$102,2,0) -> 7.8436522e+10 | E35: =VLOOKUP(C35,'Pivot - lag'!$E$4:$F$144,2,0) -> 5.376059e+10 | F35: =VLOOKUP(C35,'Pivot - lag'!$I$4:$J$144,2,0) -> 4.6530708e+10 | G35: =VLOOKUP(C35,'Pivot - lag'!$M$3:$N$144,2,0) -> 1.7966598e+10 | H35: =VLOOKUP(C35,'Input-lag'!$K$3:$L$102,2,0) -> 1.6641693e+10 | I35: =VLOOKUP(C35,'Input-lag'!temp_8,2,0) -> 1.0225149e+09 | K35: =C35 -> 40026 | L35: =E35/$D35 -> 0.68540252 | M35: =F35/$D35 -> 0.59322757 | N35: =G35/$D35 -> 0.22905909 | O35: =H35/$D35 -> 0.21216766 | P35: =I35/$D35 -> 0.013036209
C36: ='Input-lag'!H36 -> 40057 | D36: =VLOOKUP(C36,'Input-lag'!H$4:$I$102,2,0) -> 5.9684456e+10 | E36: =VLOOKUP(C36,'Pivot - lag'!$E$4:$F$144,2,0) -> 3.9894123e+10 | F36: =VLOOKUP(C36,'Pivot - lag'!$I$4:$J$144,2,0) -> 3.4767573e+10 | G36: =VLOOKUP(C36,'Pivot - lag'!$M$3:$N$144,2,0) -> 1.4871498e+10 | H36: =VLOOKUP(C36,'Input-lag'!$K$3:$L$102,2,0) -> 1.3851899e+10 | I36: =VLOOKUP(C36,'Input-lag'!temp_8,2,0) -> 1.0994973e+09 | K36: =C36 -> 40057 | L36: =E36/$D36 -> 0.66841729 | M36: =F36/$D36 -> 0.58252307 | N36: =G36/$D36 -> 0.24916869 | O36: =H36/$D36 -> 0.23208554 | P36: =I36/$D36 -> 0.018421837
C37: ='Input-lag'!H37 -> 40087 | D37: =VLOOKUP(C37,'Input-lag'!H$4:$I$102,2,0) -> 5.638603e+10 | E37: =VLOOKUP(C37,'Pivot - lag'!$E$4:$F$144,2,0) -> 3.9812999e+10 | F37: =VLOOKUP(C37,'Pivot - lag'!$I$4:$J$144,2,0) -> 3.6252926e+10 | G37: =VLOOKUP(C37,'Pivot - lag'!$M$3:$N$144,2,0) -> 1.5019541e+10 | H37: =VLOOKUP(C37,'Input-lag'!$K$3:$L$102,2,0) -> 1.2597169e+10 | I37: =VLOOKUP(C37,'Input-lag'!temp_8,2,0) -> 7.1926646e+08 | K37: =C37 -> 40087 | L37: =E37/$D37 -> 0.70607913 | M37: =F37/$D37 -> 0.64294162 | N37: =G37/$D37 -> 0.26636989 | O37: =H37/$D37 -> 0.22340939 | P37: =I37/$D37 -> 0.012756111
C38: ='Input-lag'!H38 -> 40118 | D38: =VLOOKUP(C38,'Input-lag'!H$4:$I$102,2,0) -> 3.7508648e+10 | E38: =VLOOKUP(C38,'Pivot - lag'!$E$4:$F$144,2,0) -> 2.7299804e+10 | F38: =VLOOKUP(C38,'Pivot - lag'!$I$4:$J$144,2,0) -> 2.3964218e+10 | G38: =VLOOKUP(C38,'Pivot - lag'!$M$3:$N$144,2,0) -> 9.8019521e+09 | H38: =VLOOKUP(C38,'Input-lag'!$K$3:$L$102,2,0) -> 7.0659361e+09 | I38: =VLOOKUP(C38,'Input-lag'!temp_8,2,0) -> 7.5240953e+08 | K38: =C38 -> 40118 | L38: =E38/$D38 -> 0.72782692 | M38: =F38/$D38 -> 0.63889847 | N38: =G38/$D38 -> 0.26132512 | O38: =H38/$D38 -> 0.18838152 | P38: =I38/$D38 -> 0.020059628
C39: ='Input-lag'!H39 -> 40148 | D39: =VLOOKUP(C39,'Input-lag'!H$4:$I$102,2,0) -> 3.650884e+10 | E39: =VLOOKUP(C39,'Pivot - lag'!$E$4:$F$144,2,0) -> 2.6456406e+10 | F39: =VLOOKUP(C39,'Pivot - lag'!$I$4:$J$144,2,0) -> 2.2409303e+10 | G39: =VLOOKUP(C39,'Pivot - lag'!$M$3:$N$144,2,0) -> 7.9190408e+09 | H39: =VLOOKUP(C39,'Input-lag'!$K$3:$L$102,2,0) -> 6.3677379e+09 | I39: =VLOOKUP(C39,'Input-lag'!temp_8,2,0) -> 5.9108656e+08 | K39: =C39 -> 40148 | L39: =E39/$D39 -> 0.72465753 | M39: =F39/$D39 -> 0.61380486 | N39: =G39/$D39 -> 0.21690749 | O39: =H39/$D39 -> 0.17441633 | P39: =I39/$D39 -> 0.016190231
C40: ='Input-lag'!H40 -> 40179 | D40: =VLOOKUP(C40,'Input-lag'!H$4:$I$102,2,0) -> 4.7221078e+10 | E40: =VLOOKUP(C40,'Pivot - lag'!$E$4:$F$144,2,0) -> 3.5319042e+10 | F40: =VLOOKUP(C40,'Pivot - lag'!$I$4:$J$144,2,0) -> 3.0473733e+10 | G40: =VLOOKUP(C40,'Pivot - lag'!$M$3:$N$144,2,0) -> 1.1776429e+10 | H40: =VLOOKUP(C40,'Input-lag'!$K$3:$L$102,2,0) -> 7.787527e+09 | I40: =VLOOKUP(C40,'Input-lag'!temp_8,2,0) -> 7.2213822e+08 | K40: =C40 -> 40179 | L40: =E40/$D40 -> 0.74795077 | M40: =F40/$D40 -> 0.64534175 | N40: =G40/$D40 -> 0.24938925 | O40: =H40/$D40 -> 0.16491633 | P40: =I40/$D40 -> 0.015292709
C41: ='Input-lag'!H41 -> 40210 | D41: =VLOOKUP(C41,'Input-lag'!H$4:$I$102,2,0) -> 3.9245939e+10 | E41: =VLOOKUP(C41,'Pivot - lag'!$E$4:$F$144,2,0) -> 2.8320981e+10 | F41: =VLOOKUP(C41,'Pivot - lag'!$I$4:$J$144,2,0) -> 2.5122317e+10 | G41: =VLOOKUP(C41,'Pivot - lag'!$M$3:$N$144,2,0) -> 1.0182718e+10 | H41: =VLOOKUP(C41,'Input-lag'!$K$3:$L$102,2,0) -> 7.3132766e+09 | I41: =VLOOKUP(C41,'Input-lag'!temp_8,2,0) -> 7.3011418e+08 | K41: =C41 -> 40210 | L41: =E41/$D41 -> 0.72162832 | M41: =F41/$D41 -> 0.64012526 | N41: =G41/$D41 -> 0.25945915 | O41: =H41/$D41 -> 0.1863448 | P41: =I41/$D41 -> 0.01860356
C42: ='Input-lag'!H42 -> 40238 | D42: =VLOOKUP(C42,'Input-lag'!H$4:$I$102,2,0) -> 4.0750599e+10 | E42: =VLOOKUP(C42,'Pivot - lag'!$E$4:$F$144,2,0) -> 3.145905e+10 | F42: =VLOOKUP(C42,'Pivot - lag'!$I$4:$J$144,2,0) -> 2.8719429e+10 | G42: =VLOOKUP(C42,'Pivot - lag'!$M$3:$N$144,2,0) -> 1.0733754e+10 | H42: =VLOOKUP(C42,'Input-lag'!$K$3:$L$102,2,0) -> 5.5133079e+09 | I42: =VLOOKUP(C42,'Input-lag'!temp_8,2,0) -> 8.2270018e+08 | K42: =C42 -> 40238 | L42: =E42/$D42 -> 0.77198988 | M42: =F42/$D42 -> 0.70476092 | N42: =G42/$D42 -> 0.26340112 | O42: =H42/$D42 -> 0.13529391 | P42: =I42/$D42 -> 0.020188665
C43: ='Input-lag'!H43 -> 40269 | D43: =VLOOKUP(C43,'Input-lag'!H$4:$I$102,2,0) -> 3.4495231e+10 | E43: =VLOOKUP(C43,'Pivot - lag'!$E$4:$F$144,2,0) -> 2.7234086e+10 | F43: =VLOOKUP(C43,'Pivot - lag'!$I$4:$J$144,2,0) -> 2.4936256e+10 | G43: =VLOOKUP(C43,'Pivot - lag'!$M$3:$N$144,2,0) -> 8.0104325e+09 | H43: =VLOOKUP(C43,'Input-lag'!$K$3:$L$102,2,0) -> 4.3841867e+09 | I43: =VLOOKUP(C43,'Input-lag'!temp_8,2,0) -> 6.3190681e+08 | K43: =C43 -> 40269 | L43: =E43/$D43 -> 0.78950296 | M43: =F43/$D43 -> 0.72288997 | N43: =G43/$D43 -> 0.23221855 | O43: =H43/$D43 -> 0.12709545 | P43: =I43/$D43 -> 0.018318672
C44: ='Input-lag'!H44 -> 40299 | D44: =VLOOKUP(C44,'Input-lag'!H$4:$I$102,2,0) -> 3.4561762e+10 | E44: =VLOOKUP(C44,'Pivot - lag'!$E$4:$F$144,2,0) -> 2.6609021e+10 | F44: =VLOOKUP(C44,'Pivot - lag'!$I$4:$J$144,2,0) -> 2.3855723e+10 | G44: =VLOOKUP(C44,'Pivot - lag'!$M$3:$N$144,2,0) -> 9.7934436e+09 | H44: =VLOOKUP(C44,'Input-lag'!$K$3:$L$102,2,0) -> 4.8786661e+09 | I44: =VLOOKUP(C44,'Input-lag'!temp_8,2,0) -> 5.6034352e+08 | K44: =C44 -> 40299 | L44: =E44/$D44 -> 0.7698977 | M44: =F44/$D44 -> 0.69023459 | N44: =G44/$D44 -> 0.28336066 | O44: =H44/$D44 -> 0.14115791 | P44: =I44/$D44 -> 0.016212817
C45: ='Input-lag'!H45 -> 40330 | D45: =VLOOKUP(C45,'Input-lag'!H$4:$I$102,2,0) -> 3.3643649e+10 | E45: =VLOOKUP(C45,'Pivot - lag'!$E$4:$F$144,2,0) -> 2.6223578e+10 | F45: =VLOOKUP(C45,'Pivot - lag'!$I$4:$J$144,2,0) -> 2.3124403e+10 | G45: =VLOOKUP(C45,'Pivot - lag'!$M$3:$N$144,2,0) -> 8.7992948e+09 | H45: =VLOOKUP(C45,'Input-lag'!$K$3:$L$102,2,0) -> 4.255467e+09 | I45: =VLOOKUP(C45,'Input-lag'!temp_8,2,0) -> 7.0140741e+08 | K45: =C45 -> 40330 | L45: =E45/$D45 -> 0.77945107 | M45: =F45/$D45 -> 0.68733338 | N45: =G45/$D45 -> 0.26154401 | O45: =H45/$D45 -> 0.12648649 | P45: =I45/$D45 -> 0.020848137
... C102: ='Input-lag'!H102 -> 42064 | D102: =VLOOKUP(C102,'Input-lag'!H$4:$I$102,2,0) -> 3.5738947e+10 | E102: =VLOOKUP(C102,'Pivot - lag'!$E$4:$F$144,2,0) -> 1.4377805e+10 | F102: =VLOOKUP(C102,'Pivot - lag'!$I$4:$J$144,2,0) -> 1.0989454e+10 | G102: =VLOOKUP(C102,'Pivot - lag'!$M$3:$N$144,2,0) -> 4.7953702e+09 | H102: =VLOOKUP(C102,'Input-lag'!$K$3:$L$102,2,0) -> 1.471834e+10 | I102: =VLOOKUP(C102,'Input-lag'!temp_8,2,0) -> 9.8696934e+08 | K102: =C102 -> 42064 | L102: =E102/$D102 -> 0.40230076 | M102: =F102/$D102 -> 0.30749239 | N102: =G102/$D102 -> 0.13417771 | O102: =H102/$D102 -> 0.41182913 | P102: =I102/$D102 -> 0.027616072

Sheet Result -equal
D3: Total | E3: Top 10 | F3: Top 5 | G3: Top 1 | H3: N/A | I3: Remaining | L3: Top 10 | M3: Top 5 | N3: Top 1 | O3: N/A | P3: Remaining
C4: ='Input-equal'!H4 -> 39083 | D4: =VLOOKUP(C4,'Input-equal'!temp,2,0) -> 4.9068464e+10 | E4: =VLOOKUP(C4,'Pivot-equal'!$C$4:$D$122,2,0) -> 3.0025184e+10 | F4: =VLOOKUP(C4,'Pivot-equal'!$G$3:$H$121,2,0) -> 2.4746999e+10 | G4: =VLOOKUP(C4,'Pivot-equal'!$K$3:$L$122,2,0) -> 9008075393 | H4: =VLOOKUP(C4,'Input-equal'!temp_11,2,0) -> 1.27552e+10 | I4: =VLOOKUP(C4,'Input-equal'!$N$4:$O$101,2,0) -> 8.0499228e+08 | K4: =C4 -> 39083 | L4: =E4/$D4 -> 0.61190389 | M4: =F4/$D4 -> 0.50433611 | N4: =G4/$D4 -> 0.18358177 | O4: =H4/$D4 -> 0.25994699 | P4: =I4/$D4 -> 0.016405492
C5: ='Input-equal'!H5 -> 39114 | D5: =VLOOKUP(C5,'Input-equal'!temp,2,0) -> 4.6067241e+10 | E5: =VLOOKUP(C5,'Pivot-equal'!$C$4:$D$122,2,0) -> 3.0108179e+10 | F5: =VLOOKUP(C5,'Pivot-equal'!$G$3:$H$121,2,0) -> 2.3003135e+10 | G5: =VLOOKUP(C5,'Pivot-equal'!$K$3:$L$122,2,0) -> 8625817045 | H5: =VLOOKUP(C5,'Input-equal'!temp_11,2,0) -> 10090446420 | I5: =VLOOKUP(C5,'Input-equal'!$N$4:$O$101,2,0) -> 7.6726656e+08 | K5: =C5 -> 39114 | L5: =E5/$D5 -> 0.65357027 | M5: =F5/$D5 -> 0.49933824 | N5: =G5/$D5 -> 0.18724406 | O5: =H5/$D5 -> 0.21903735 | P5: =I5/$D5 -> 0.016655362
C6: ='Input-equal'!H6 -> 39142 | D6: =VLOOKUP(C6,'Input-equal'!temp,2,0) -> 4.7629783e+10 | E6: =VLOOKUP(C6,'Pivot-equal'!$C$4:$D$122,2,0) -> 2.8183297e+10 | F6: =VLOOKUP(C6,'Pivot-equal'!$G$3:$H$121,2,0) -> 2.1409134e+10 | G6: =VLOOKUP(C6,'Pivot-equal'!$K$3:$L$122,2,0) -> 7241357422 | H6: =VLOOKUP(C6,'Input-equal'!temp_11,2,0) -> 1.4264823e+10 | I6: =VLOOKUP(C6,'Input-equal'!$N$4:$O$101,2,0) -> 7.641544e+08 | K6: =C6 -> 39142 | L6: =E6/$D6 -> 0.59171584 | M6: =F6/$D6 -> 0.44949048 | N6: =G6/$D6 -> 0.15203423 | O6: =H6/$D6 -> 0.29949377 | P6: =I6/$D6 -> 0.016043625
C7: ='Input-equal'!H7 -> 39173 | D7: =VLOOKUP(C7,'Input-equal'!temp,2,0) -> 5.1130391e+10 | E7: =VLOOKUP(C7,'Pivot-equal'!$C$4:$D$122,2,0) -> 3.1533332e+10 | F7: =VLOOKUP(C7,'Pivot-equal'!$G$3:$H$121,2,0) -> 2.533764e+10 | G7: =VLOOKUP(C7,'Pivot-equal'!$K$3:$L$122,2,0) -> 8.4357953e+09 | H7: =VLOOKUP(C7,'Input-equal'!temp_11,2,0) -> 11172945973 | I7: =VLOOKUP(C7,'Input-equal'!$N$4:$O$101,2,0) -> 1.2973524e+09 | K7: =C7 -> 39173 | L7: =E7/$D7 -> 0.61672385 | M7: =F7/$D7 -> 0.49554951 | N7: =G7/$D7 -> 0.16498593 | O7: =H7/$D7 -> 0.21851869 | P7: =I7/$D7 -> 0.02537341
C8: ='Input-equal'!H8 -> 39203 | D8: =VLOOKUP(C8,'Input-equal'!temp,2,0) -> 5.824187e+10 | E8: =VLOOKUP(C8,'Pivot-equal'!$C$4:$D$122,2,0) -> 3.6317977e+10 | F8: =VLOOKUP(C8,'Pivot-equal'!$G$3:$H$121,2,0) -> 2.7080728e+10 | G8: =VLOOKUP(C8,'Pivot-equal'!$K$3:$L$122,2,0) -> 8.7570316e+09 | H8: =VLOOKUP(C8,'Input-equal'!temp_11,2,0) -> 13735083658 | I8: =VLOOKUP(C8,'Input-equal'!$N$4:$O$101,2,0) -> 1.1984126e+09 | K8: =C8 -> 39203 | L8: =E8/$D8 -> 0.62357161 | M8: =F8/$D8 -> 0.4649701 | N8: =G8/$D8 -> 0.15035629 | O8: =H8/$D8 -> 0.23582834 | P8: =I8/$D8 -> 0.020576478
C9: ='Input-equal'!H9 -> 39234 | D9: =VLOOKUP(C9,'Input-equal'!temp,2,0) -> 5.0433013e+10 | E9: =VLOOKUP(C9,'Pivot-equal'!$C$4:$D$122,2,0) -> 2.0208581e+09 | F9: =VLOOKUP(C9,'Pivot-equal'!$G$3:$H$121,2,0) -> 1640096016 | G9: =VLOOKUP(C9,'Pivot-equal'!$K$3:$L$122,2,0) -> 529500000 | H9: =VLOOKUP(C9,'Input-equal'!temp_11,2,0) -> 48262039856 | I9: =VLOOKUP(C9,'Input-equal'!$N$4:$O$101,2,0) -> #N/A | K9: =C9 -> 39234 | L9: =E9/$D9 -> 0.040070143 | M9: =F9/$D9 -> 0.032520286 | N9: =G9/$D9 -> 0.010499075 | O9: =H9/$D9 -> 0.95695332 | P9: =I9/$D9 -> #N/A
C10: ='Input-equal'!H10 -> 39264 | D10: =VLOOKUP(C10,'Input-equal'!temp,2,0) -> 5.3229368e+10 | E10: =VLOOKUP(C10,'Pivot-equal'!$C$4:$D$122,2,0) -> 1.9142144e+09 | F10: =VLOOKUP(C10,'Pivot-equal'!$G$3:$H$121,2,0) -> 1.3451641e+09 | G10: =VLOOKUP(C10,'Pivot-equal'!$K$3:$L$122,2,0) -> 5.874024e+08 | H10: =VLOOKUP(C10,'Input-equal'!temp_11,2,0) -> 49227506796 | I10: =VLOOKUP(C10,'Input-equal'!$N$4:$O$101,2,0) -> 1.3448531e+09 | K10: =C10 -> 39264 | L10: =E10/$D10 -> 0.035961622 | M10: =F10/$D10 -> 0.025271088 | N10: =G10/$D10 -> 0.011035307 | O10: =H10/$D10 -> 0.92481855 | P10: =I10/$D10 -> 0.025265246
C11: ='Input-equal'!H11 -> 39295 | D11: =VLOOKUP(C11,'Input-equal'!temp,2,0) -> 5.5852223e+10 | E11: =VLOOKUP(C11,'Pivot-equal'!$C$4:$D$122,2,0) -> 3.6163125e+10 | F11: =VLOOKUP(C11,'Pivot-equal'!$G$3:$H$121,2,0) -> 2.6896586e+10 | G11: =VLOOKUP(C11,'Pivot-equal'!$K$3:$L$122,2,0) -> 7.9703835e+09 | H11: =VLOOKUP(C11,'Input-equal'!temp_11,2,0) -> 10763644956 | I11: =VLOOKUP(C11,'Input-equal'!$N$4:$O$101,2,0) -> 1.0931784e+09 | K11: =C11 -> 39295 | L11: =E11/$D11 -> 0.6474787 | M11: =F11/$D11 -> 0.48156697 | N11: =G11/$D11 -> 0.14270486 | O11: =H11/$D11 -> 0.1927165 | P11: =I11/$D11 -> 0.019572692
C12: ='Input-equal'!H12 -> 39326 | D12: =VLOOKUP(C12,'Input-equal'!temp,2,0) -> 5.9519283e+10 | E12: =VLOOKUP(C12,'Pivot-equal'!$C$4:$D$122,2,0) -> 3.9727851e+10 | F12: =VLOOKUP(C12,'Pivot-equal'!$G$3:$H$121,2,0) -> 3.1387724e+10 | G12: =VLOOKUP(C12,'Pivot-equal'!$K$3:$L$122,2,0) -> 1.1906421e+10 | H12: =VLOOKUP(C12,'Input-equal'!temp_11,2,0) -> 9103829164 | I12: =VLOOKUP(C12,'Input-equal'!$N$4:$O$101,2,0) -> 1.3036333e+09 | K12: =C12 -> 39326 | L12: =E12/$D12 -> 0.66747865 | M12: =F12/$D12 -> 0.52735386 | N12: =G12/$D12 -> 0.20004309 | O12: =H12/$D12 -> 0.15295596 | P12: =I12/$D12 -> 0.021902705
C13: ='Input-equal'!H13 -> 39356 | D13: =VLOOKUP(C13,'Input-equal'!temp,2,0) -> 5.3589854e+10 | E13: =VLOOKUP(C13,'Pivot-equal'!$C$4:$D$122,2,0) -> 3.4611208e+10 | F13: =VLOOKUP(C13,'Pivot-equal'!$G$3:$H$121,2,0) -> 2.5266525e+10 | G13: =VLOOKUP(C13,'Pivot-equal'!$K$3:$L$122,2,0) -> 7.6112336e+09 | H13: =VLOOKUP(C13,'Input-equal'!temp_11,2,0) -> 11684087724 | I13: =VLOOKUP(C13,'Input-equal'!$N$4:$O$101,2,0) -> 8.4331109e+08 | K13: =C13 -> 39356 | L13: =E13/$D13 -> 0.64585374 | M13: =F13/$D13 -> 0.47147964 | N13: =G13/$D13 -> 0.14202751 | O13: =H13/$D13 -> 0.21802798 | P13: =I13/$D13 -> 0.015736395
C14: ='Input-equal'!H14 -> 39387 | D14: =VLOOKUP(C14,'Input-equal'!temp,2,0) -> 56318004683 | E14: =VLOOKUP(C14,'Pivot-equal'!$C$4:$D$122,2,0) -> 3.8426582e+10 | F14: =VLOOKUP(C14,'Pivot-equal'!$G$3:$H$121,2,0) -> 2.7917519e+10 | G14: =VLOOKUP(C14,'Pivot-equal'!$K$3:$L$122,2,0) -> 9251362639 | H14: =VLOOKUP(C14,'Input-equal'!temp_11,2,0) -> 1.0286728e+10 | I14: =VLOOKUP(C14,'Input-equal'!$N$4:$O$101,2,0) -> 1.2985406e+09 | K14: =C14 -> 39387 | L14: =E14/$D14 -> 0.68231433 | M14: =F14/$D14 -> 0.49571215 | N14: =G14/$D14 -> 0.16427007 | O14: =H14/$D14 -> 0.18265433 | P14: =I14/$D14 -> 0.02305729
C15: ='Input-equal'!H15 -> 39417 | D15: =VLOOKUP(C15,'Input-equal'!temp,2,0) -> 7.0720993e+10 | E15: =VLOOKUP(C15,'Pivot-equal'!$C$4:$D$122,2,0) -> 4.5838565e+10 | F15: =VLOOKUP(C15,'Pivot-equal'!$G$3:$H$121,2,0) -> 3.534814e+10 | G15: =VLOOKUP(C15,'Pivot-equal'!$K$3:$L$122,2,0) -> 1.2421827e+10 | H15: =VLOOKUP(C15,'Input-equal'!temp_11,2,0) -> 17719338930 | I15: =VLOOKUP(C15,'Input-equal'!$N$4:$O$101,2,0) -> 1.2944649e+09 | K15: =C15 -> 39417 | L15: =E15/$D15 -> 0.64816065 | M15: =F15/$D15 -> 0.49982528 | N15: =G15/$D15 -> 0.17564554 | O15: =H15/$D15 -> 0.25055274 | P15: =I15/$D15 -> 0.018303829
... C32: ='Input-equal'!H32 -> 39934 | D32: =VLOOKUP(C32,'Input-equal'!temp,2,0) -> 1.3384009e+11 | E32: =VLOOKUP(C32,'Pivot-equal'!$C$4:$D$122,2,0) -> 5.9246266e+10 | F32: =VLOOKUP(C32,'Pivot-equal'!$G$3:$H$121,2,0) -> 4.861435e+10 | G32: =VLOOKUP(C32,'Pivot-equal'!$K$3:$L$122,2,0) -> 1.6377154e+10 | H32: =VLOOKUP(C32,'Input-equal'!temp_11,2,0) -> 15344958750 | I32: =VLOOKUP(C32,'Input-equal'!$N$4:$O$101,2,0) -> 4.5560166e+10 | K32: =C32 -> 39934 | L32: =E32/$D32 -> 0.44266457 | M32: =F32/$D32 -> 0.36322712 | N32: =G32/$D32 -> 0.12236359 | O32: =H32/$D32 -> 0.11465144 | P32: =I32/$D32 -> 0.34040746
B33: =D33+H33 -> 1.5734892e+11 | C33: ='Input-equal'!H33 -> 39965 | D33: =VLOOKUP(C33,'Input-equal'!temp,2,0) -> 1.333969e+11 | E33: =VLOOKUP(C33,'Pivot-equal'!$C$4:$D$122,2,0) -> 6.254832e+10 | F33: =VLOOKUP(C33,'Pivot-equal'!$G$3:$H$121,2,0) -> 5.0633929e+10 | G33: =VLOOKUP(C33,'Pivot-equal'!$K$3:$L$122,2,0) -> 1.8556307e+10 | H33: =VLOOKUP(C33,'Input-equal'!temp_11,2,0) -> 23952022073 | I33: =VLOOKUP(C33,'Input-equal'!$N$4:$O$101,2,0) -> 3.3182797e+10 | K33: =C33 -> 39965 | L33: =E33/$D33 -> 0.46888886 | M33: =F33/$D33 -> 0.3795735 | N33: =G33/$D33 -> 0.13910598 | O33: =H33/$D33 -> 0.17955456 | P33: =I33/$D33 -> 0.24875238
C34: ='Input-equal'!H34 -> 39995 | D34: =VLOOKUP(C34,'Input-equal'!temp,2,0) -> 8.1085053e+10 | E34: =VLOOKUP(C34,'Pivot-equal'!$C$4:$D$122,2,0) -> 4.7492473e+10 | F34: =VLOOKUP(C34,'Pivot-equal'!$G$3:$H$121,2,0) -> 4.0903264e+10 | G34: =VLOOKUP(C34,'Pivot-equal'!$K$3:$L$122,2,0) -> 1.778028e+10 | H34: =VLOOKUP(C34,'Input-equal'!temp_11,2,0) -> 15630530955 | I34: =VLOOKUP(C34,'Input-equal'!$N$4:$O$101,2,0) -> 9.2791887e+09 | K34: =C34 -> 39995 | L34: =E34/$D34 -> 0.58571181 | M34: =F34/$D34 -> 0.50444888 | N34: =G34/$D34 -> 0.21927938 | O34: =H34/$D34 -> 0.19276711 | P34: =I34/$D34 -> 0.11443772
C35: ='Input-equal'!H35 -> 40026 | D35: =VLOOKUP(C35,'Input-equal'!temp,2,0) -> 6.2725888e+10 | E35: =VLOOKUP(C35,'Pivot-equal'!$C$4:$D$122,2,0) -> 3.5622456e+10 | F35: =VLOOKUP(C35,'Pivot-equal'!$G$3:$H$121,2,0) -> 3.0196349e+10 | G35: =VLOOKUP(C35,'Pivot-equal'!$K$3:$L$122,2,0) -> 1.3559469e+10 | H35: =VLOOKUP(C35,'Input-equal'!temp_11,2,0) -> 10784987411 | I35: =VLOOKUP(C35,'Input-equal'!$N$4:$O$101,2,0) -> 9.2330292e+09 | K35: =C35 -> 40026 | L35: =E35/$D35 -> 0.56790676 | M35: =F35/$D35 -> 0.4814017 | N35: =G35/$D35 -> 0.21617022 | O35: =H35/$D35 -> 0.17193838 | P35: =I35/$D35 -> 0.14719647
C36: ='Input-equal'!H36 -> 40057 | D36: =VLOOKUP(C36,'Input-equal'!temp,2,0) -> 5.8721967e+10 | E36: =VLOOKUP(C36,'Pivot-equal'!$C$4:$D$122,2,0) -> 2.9845785e+10 | F36: =VLOOKUP(C36,'Pivot-equal'!$G$3:$H$121,2,0) -> 2.5413967e+10 | G36: =VLOOKUP(C36,'Pivot-equal'!$K$3:$L$122,2,0) -> 9.7112614e+09 | H36: =VLOOKUP(C36,'Input-equal'!temp_11,2,0) -> 15838054203 | I36: =VLOOKUP(C36,'Input-equal'!$N$4:$O$101,2,0) -> 7.3381037e+09 | K36: =C36 -> 40057 | L36: =E36/$D36 -> 0.50825588 | M36: =F36/$D36 -> 0.43278467 | N36: =G36/$D36 -> 0.16537698 | O36: =H36/$D36 -> 0.2697126 | P36: =I36/$D36 -> 0.12496352
C37: ='Input-equal'!H37 -> 40087 | D37: =VLOOKUP(C37,'Input-equal'!temp,2,0) -> 4.0018067e+10 | E37: =VLOOKUP(C37,'Pivot-equal'!$C$4:$D$122,2,0) -> 1.8050213e+10 | F37: =VLOOKUP(C37,'Pivot-equal'!$G$3:$H$121,2,0) -> 1.5113924e+10 | G37: =VLOOKUP(C37,'Pivot-equal'!$K$3:$L$122,2,0) -> 7.2112824e+09 | H37: =VLOOKUP(C37,'Input-equal'!temp_11,2,0) -> 13765119592 | I37: =VLOOKUP(C37,'Input-equal'!$N$4:$O$101,2,0) -> 4.3781434e+09 | K37: =C37 -> 40087 | L37: =E37/$D37 -> 0.45105158 | M37: =F37/$D37 -> 0.37767751 | N37: =G37/$D37 -> 0.18020067 | O37: =H37/$D37 -> 0.34397262 | P37: =I37/$D37 -> 0.10940417
C38: ='Input-equal'!H38 -> 40118 | D38: =VLOOKUP(C38,'Input-equal'!temp,2,0) -> 3.9630339e+10 | E38: =VLOOKUP(C38,'Pivot-equal'!$C$4:$D$122,2,0) -> 2.1036922e+10 | F38: =VLOOKUP(C38,'Pivot-equal'!$G$3:$H$121,2,0) -> 1.7714705e+10 | G38: =VLOOKUP(C38,'Pivot-equal'!$K$3:$L$122,2,0) -> 7.75127e+09 | H38: =VLOOKUP(C38,'Input-equal'!temp_11,2,0) -> 10790428166 | I38: =VLOOKUP(C38,'Input-equal'!$N$4:$O$101,2,0) -> 4.2312966e+09 | K38: =C38 -> 40118 | L38: =E38/$D38 -> 0.53082871 | M38: =F38/$D38 -> 0.44699858 | N38: =G38/$D38 -> 0.19558929 | O38: =H38/$D38 -> 0.27227696 | P38: =I38/$D38 -> 0.10676913
C39: ='Input-equal'!H39 -> 40148 | D39: =VLOOKUP(C39,'Input-equal'!temp,2,0) -> 4.9380885e+10 | E39: =VLOOKUP(C39,'Pivot-equal'!$C$4:$D$122,2,0) -> 2.7010035e+10 | F39: =VLOOKUP(C39,'Pivot-equal'!$G$3:$H$121,2,0) -> 2.2935301e+10 | G39: =VLOOKUP(C39,'Pivot-equal'!$K$3:$L$122,2,0) -> 1.1583901e+10 | H39: =VLOOKUP(C39,'Input-equal'!temp_11,2,0) -> 12468205867 | I39: =VLOOKUP(C39,'Input-equal'!$N$4:$O$101,2,0) -> 4.6889929e+09 | K39: =C39 -> 40148 | L39: =E39/$D39 -> 0.54697348 | M39: =F39/$D39 -> 0.46445706 | N39: =G39/$D39 -> 0.23458269 | O39: =H39/$D39 -> 0.25249053 | P39: =I39/$D39 -> 0.094955626
C40: ='Input-equal'!H40 -> 40179 | D40: =VLOOKUP(C40,'Input-equal'!temp,2,0) -> 4.1171224e+10 | E40: =VLOOKUP(C40,'Pivot-equal'!$C$4:$D$122,2,0) -> 2.3918184e+10 | F40: =VLOOKUP(C40,'Pivot-equal'!$G$3:$H$121,2,0) -> 2.085892e+10 | G40: =VLOOKUP(C40,'Pivot-equal'!$K$3:$L$122,2,0) -> 9.9788493e+09 | H40: =VLOOKUP(C40,'Input-equal'!temp_11,2,0) -> 8643108800 | I40: =VLOOKUP(C40,'Input-equal'!$N$4:$O$101,2,0) -> 4.1257772e+09 | K40: =C40 -> 40179 | L40: =E40/$D40 -> 0.5809442 | M40: =F40/$D40 -> 0.50663831 | N40: =G40/$D40 -> 0.24237436 | O40: =H40/$D40 -> 0.20993082 | P40: =I40/$D40 -> 0.10021021
C41: ='Input-equal'!H41 -> 40210 | D41: =VLOOKUP(C41,'Input-equal'!temp,2,0) -> 4.3331381e+10 | E41: =VLOOKUP(C41,'Pivot-equal'!$C$4:$D$122,2,0) -> 2.521946e+10 | F41: =VLOOKUP(C41,'Pivot-equal'!$G$3:$H$121,2,0) -> 2.27325e+10 | G41: =VLOOKUP(C41,'Pivot-equal'!$K$3:$L$122,2,0) -> 9.807431e+09 | H41: =VLOOKUP(C41,'Input-equal'!temp_11,2,0) -> 10644755641 | I41: =VLOOKUP(C41,'Input-equal'!$N$4:$O$101,2,0) -> 3.1479302e+09 | K41: =C41 -> 40210 | L41: =E41/$D41 -> 0.58201376 | M41: =F41/$D41 -> 0.52461979 | N41: =G41/$D41 -> 0.22633553 | O41: =H41/$D41 -> 0.24565928 | P41: =I41/$D41 -> 0.072647816
C42: ='Input-equal'!H42 -> 40238 | D42: =VLOOKUP(C42,'Input-equal'!temp,2,0) -> 3.6714522e+10 | E42: =VLOOKUP(C42,'Pivot-equal'!$C$4:$D$122,2,0) -> 1.8730251e+10 | F42: =VLOOKUP(C42,'Pivot-equal'!$G$3:$H$121,2,0) -> 1.6626538e+10 | G42: =VLOOKUP(C42,'Pivot-equal'!$K$3:$L$122,2,0) -> 7.7521484e+09 | H42: =VLOOKUP(C42,'Input-equal'!temp_11,2,0) -> 12061455302 | I42: =VLOOKUP(C42,'Input-equal'!$N$4:$O$101,2,0) -> 3.1453618e+09 | K42: =C42 -> 40238 | L42: =E42/$D42 -> 0.51015919 | M42: =F42/$D42 -> 0.45286 | N42: =G42/$D42 -> 0.21114665 | O42: =H42/$D42 -> 0.32852002 | P42: =I42/$D42 -> 0.085670783
C43: ='Input-equal'!H43 -> 40269 | D43: =VLOOKUP(C43,'Input-equal'!temp,2,0) -> 3.6544416e+10 | E43: =VLOOKUP(C43,'Pivot-equal'!$C$4:$D$122,2,0) -> 2.1401297e+10 | F43: =VLOOKUP(C43,'Pivot-equal'!$G$3:$H$121,2,0) -> 1.8926472e+10 | G43: =VLOOKUP(C43,'Pivot-equal'!$K$3:$L$122,2,0) -> 8.7598562e+09 | H43: =VLOOKUP(C43,'Input-equal'!temp_11,2,0) -> 8738434979 | I43: =VLOOKUP(C43,'Input-equal'!$N$4:$O$101,2,0) -> 3.2078699e+09 | K43: =C43 -> 40269 | L43: =E43/$D43 -> 0.58562427 | M43: =F43/$D43 -> 0.51790325 | N43: =G43/$D43 -> 0.23970437 | O43: =H43/$D43 -> 0.2391182 | P43: =I43/$D43 -> 0.087780029
C44: ='Input-equal'!H44 -> 40299 | D44: =VLOOKUP(C44,'Input-equal'!temp,2,0) -> 3.6336611e+10 | E44: =VLOOKUP(C44,'Pivot-equal'!$C$4:$D$122,2,0) -> 2.2794601e+10 | F44: =VLOOKUP(C44,'Pivot-equal'!$G$3:$H$121,2,0) -> 1.9737345e+10 | G44: =VLOOKUP(C44,'Pivot-equal'!$K$3:$L$122,2,0) -> 7.9831172e+09 | H44: =VLOOKUP(C44,'Input-equal'!temp_11,2,0) -> 7568970433 | I44: =VLOOKUP(C44,'Input-equal'!$N$4:$O$101,2,0) -> 2.9185279e+09 | K44: =C44 -> 40299 | L44: =E44/$D44 -> 0.62731775 | M44: =F44/$D44 -> 0.54318068 | N44: =G44/$D44 -> 0.219699 | O44: =H44/$D44 -> 0.2083015 | P44: =I44/$D44 -> 0.080319211
