Workbook

Sheet 5 vs 11
B1: grp | C1: x | D1: actual.smm | E1: model.smm | F1: actual.cpr | G1: model.cpr | H1: ratio | I1: track.err | J1: curt.smm | K1: dflt.smm | L1: cout.smm | M1: turn.smm | N1: refi.smm | O1: pct_inv | P1: pct_2nd | Q1: pct_owner | R1: pct_purchase | S1: pct_REFI_NCO | T1: pct_REFI_CO | U1: pct_REFI_Other | V1: pct_REFI | W1: pct_dq | X1: incentive | Y1: burnout | Z1: refi_elig_pct | AA1: cltv | AB1: wacls | AC1: acls | AD1: wala | AE1: wam | AF1: wac | AG1: fico | AH1: pct_HARPed | AI1: pct_tpo | AJ1: cai | AK1: media_effect | AL1: sato | AM1: hpa_annual | AN1: hpa_cum | AO1: turn_cai_mult | AP1: turn_hpa_annual_mult | AQ1: turn_wala_mult | AR1: turn_incentive_mult | AS1: turn_cltv_mult | AT1: turn_acls_mult | AU1: turn_fico_mult | AV1: turn_tax_mult | AW1: turn_sato_mult | AX1: turn_pct_HARPed_mult | AY1: turn_HARP_eligible_mult | AZ1: turn_pct_purchase_mult | BA1: turn_pct_inv_mult | BB1: turn_pct_second_lien_mult | BC1: bal | BD1: std | BE1: n
A2: 1 | B2: 5 | C2: 0 | D2: 0.14631016 | E2: 0.049958196 | F2: 1.7416622 | G2: 0.59785384 | H2: 2.9286518 | I2: -0.096351965 | J2: 0.0016776749 | K2: 0.00022185858 | L2: 0 | M2: 0.048058662 | N2: 9.1706228e-11 | O2: 0 | P2: 9.4685993 | Q2: 90.531401 | R2: 76.425354 | S2: 15.754111 | T2: 7.8205353 | U2: 0 | V2: 23.574646 | W2: 0.0010182395 | X2: -37.310377 | Y2: 0 | Z2: 100 | AA2: 74.346911 | AB2: 310.35997 | AC2: 308.53904 | AD2: -0.013928194 | AE2: 359.36565 | AF2: 3.8063244 | AG2: 778.03438 | AH2: 1.0574863 | AI2: 45.011505 | AJ2: 176.58301 | AK2: 23.07572 | AL2: -60.120925 | AM2: -0.09873614 | AN2: -0.018232518 | AO2: 0.9 | AP2: 0.89337 | AQ2: 0.15921074 | AR2: 1.2845346 | AS2: 0.99076916 | AT2: 0.84600735 | AU2: 0.84330886 | AV2: 1 | AW2: 0.94188914 | AX2: 1 | AY2: 1 | AZ2: 0.96935296 | BA2: 1 | BB2: 0.97708382 | BC2: 7.9022591e+08 | BD2: 0.0015308369 | BE2: 718
A3: 2 | B3: 5 | C3: 6 | D3: 0.32502793 | E3: 0.15551926 | F3: 3.8313606 | G3: 1.8503507 | H3: 2.0899529 | I3: -0.16950867 | J3: 0.030002077 | K3: 0.0018827369 | L3: 0 | M3: 0.12217751 | N3: 0.0014569401 | O3: 0 | P3: 7.4453889 | Q3: 92.554611 | R3: 52.402511 | S3: 27.822904 | T3: 19.774586 | U3: 0 | V3: 47.597489 | W3: 0.20356299 | X3: -48.748626 | Y3: 6.9476931 | Z3: 100 | AA3: 71.266519 | AB3: 295.79211 | AC3: 293.64967 | AD3: 3.710124 | AE3: 354.18442 | AF3: 3.6272493 | AG3: 779.45157 | AH3: 5.1870431 | AI3: 46.593321 | AJ3: 172.2463 | AK3: 24.355655 | AL3: -28.455368 | AM3: 1.8289281 | AN3: 0.61731222 | AO3: 0.9 | AP3: 1.0207702 | AQ3: 0.35956436 | AR3: 1.27109 | AS3: 0.99226949 | AT3: 0.86183968 | AU3: 0.840905 | AV3: 1 | AW3: 0.99415805 | AX3: 1 | AY3: 1 | AZ3: 0.93812326 | BA3: 1 | BB3: 0.98745559 | BC3: 2.2663762e+10 | BD3: 0.035625648 | BE3: 7300
A4: 3 | B4: 5 | C4: 12 | D4: 0.33396962 | E4: 0.34608612 | F4: 3.9348352 | G4: 4.0748864 | H4: 0.96498991 | I4: 0.012116505 | J4: 0.035362423 | K4: 0.0028613862 | L4: 0 | M4: 0.30392552 | N4: 0.0039367951 | O4: 0 | P4: 5.5374128 | Q4: 94.462587 | R4: 60.607592 | S4: 25.129824 | T4: 14.262584 | U4: 0 | V4: 39.392408 | W4: 0.21004557 | X4: -45.754388 | Y4: 56.746925 | Z4: 100 | AA4: 70.710627 | AB4: 295.06802 | AC4: 292.82995 | AD4: 8.4193124 | AE4: 348.55756 | AF4: 3.6557577 | AG4: 780.10124 | AH4: 4.5062657 | AI4: 48.747643 | AJ4: 172.35743 | AK4: 23.410723 | AL4: -25.75689 | AM4: 2.9406769 | AN4: 2.1361365 | AO4: 0.9 | AP4: 1.1441075 | AQ4: 0.70910001 | AR4: 1.276543 | AS4: 0.99239789 | AT4: 0.86292542 | AU4: 0.83967607 | AV4: 1 | AW4: 0.99850432 | AX4: 1 | AY4: 1 | AZ4: 0.94878987 | BA4: 1 | BB4: 0.98572728 | BC4: 5.2606559e+10 | BD4: 0.052092701 | BE4: 10189
A5: 4 | B5: 5 | C5: 18 | D5: 0.34746613 | E5: 0.5076441 | F5: 4.0908257 | G5: 5.9244909 | H5: 0.68446798 | I5: 0.16017797 | J5: 0.035989504 | K5: 0.0087862284 | L5: 0 | M5: 0.45729472 | N5: 0.0055736453 | O5: 0 | P5: 5.2312579 | Q5: 94.768742 | R5: 51.960399 | S5: 31.779781 | T5: 16.25982 | U5: 0 | V5: 48.039601 | W5: 0.50593856 | X5: -47.291207 | Y5: 34.332723 | Z5: 100 | AA5: 67.150566 | AB5: 295.41921 | AC5: 293.18416 | AD5: 15.209418 | AE5: 340.62212 | AF5: 3.5097721 | AG5: 780.28438 | AH5: 5.4397517 | AI5: 47.280511 | AJ5: 176.95766 | AK5: 26.397506 | AL5: -26.589291 | AM5: 3.7381054 | AN5: 4.7732578 | AO5: 0.9 | AP5: 1.2250648 | AQ5: 1.1759225 | AR5: 1.2618114 | AS5: 0.99455842 | AT5: 0.86291689 | AU5: 0.83929623 | AV5: 1 | AW5: 0.99636208 | AX5: 1 | AY5: 1 | AZ5: 0.93754852 | BA5: 1 | BB5: 0.98671985 | BC5: 4.0074992e+10 | BD5: 0.052175348 | BE5: 6792
A6: 5 | B6: 5 | C6: 24 | D6: 0.50887619 | E6: 0.57600036 | F6: 5.9384701 | G6: 6.6971822 | H6: 0.88346505 | I6: 0.067124175 | J6: 0.037904579 | K6: 0.009584374 | L6: 3.4983497e-10 | M6: 0.52473201 | N6: 0.0037793997 | O6: 0 | P6: 5.1651503 | Q6: 94.83485 | R6: 51.23455 | S6: 31.283497 | T6: 17.481953 | U6: 0 | V6: 48.76545 | W6: 0.4459982 | X6: -51.159049 | Y6: 137.87563 | Z6: 100 | AA6: 64.397031 | AB6: 292.08593 | AC6: 289.90643 | AD6: 22.038392 | AE6: 332.5059 | AF6: 3.6361296 | AG6: 780.17404 | AH6: 3.86636 | AI6: 49.072564 | AJ6: 175.73712 | AK6: 20.261929 | AL6: -28.009511 | AM6: 3.6119465 | AN6: 6.7772773 | AO6: 0.9 | AP6: 1.2148145 | AQ6: 1.25 | AR6: 1.2583978 | AS6: 0.99639499 | AT6: 0.86668853 | AU6: 0.83947237 | AV6: 1 | AW6: 0.99300467 | AX6: 1 | AY6: 1 | AZ6: 0.93660492 | BA6: 1 | BB6: 0.99548427 | BC6: 2.5888123e+10 | BD6: 0.059717576 | BE6: 8207
A7: 6 | B7: 5 | C7: 30 | D7: 0.58670955 | E7: 0.65231404 | F7: 6.8177091 | G7: 7.5529473 | H7: 0.89942805 | I7: 0.065604492 | J7: 0.039266521 | K7: 0.0094229209 | L7: 4.0606219e-05 | M7: 0.59528723 | N7: 0.0082967543 | O7: 0 | P7: 5.570858 | Q7: 94.429142 | R7: 51.606751 | S7: 33.723154 | T7: 14.670095 | U7: 0 | V7: 48.393249 | W7: 0.39663717 | X7: -39.748478 | Y7: 229.60688 | Z7: 100 | AA7: 62.031029 | AB7: 292.67164 | AC7: 290.54577 | AD7: 25.673778 | AE7: 328.02571 | AF7: 3.684992 | AG7: 780.38955 | AH7: 2.470356 | AI7: 48.980398 | AJ7: 175.26321 | AK7: 22.518667 | AL7: -33.026224 | AM7: 3.9387651 | AN7: 8.6634773 | AO7: 0.9 | AP7: 1.2338712 | AQ7: 1.25 | AR7: 1.2829333 | AS7: 0.99806831 | AT7: 0.86615496 | AU7: 0.83903954 | AV7: 1 | AW7: 0.98364539 | AX7: 1 | AY7: 1 | AZ7: 0.93708878 | BA7: 1 | BB7: 0.99117862 | BC7: 8.7935926e+09 | BD7: 0.068873365 | BE7: 3991
A8: 7 | B8: 5 | C8: 36 | D8: 0.58657297 | E8: 0.60207517 | F8: 6.8161728 | G8: 6.9903927 | H8: 0.97425204 | I8: 0.015502207 | J8: 0.042792485 | K8: 0.014314723 | L8: 0.00042279389 | M8: 0.54030121 | N8: 0.0042439652 | O8: 0 | P8: 5.1798552 | Q8: 94.820145 | R8: 53.519484 | S8: 30.111867 | T8: 16.368648 | U8: 0 | V8: 46.480516 | W8: 0.51462799 | X8: -46.992146 | Y8: 292.95771 | Z8: 100 | AA8: 60.815186 | AB8: 283.94275 | AC8: 281.85228 | AD8: 34.079503 | AE8: 318.66902 | AF8: 3.7151886 | AG8: 780.05753 | AH8: 1.0475529 | AI8: 48.314946 | AJ8: 179.14606 | AK8: 18.453885 | AL8: -31.622497 | AM8: 3.7004675 | AN8: 10.939625 | AO8: 0.9 | AP8: 1.2157939 | AQ8: 1.25 | AR8: 1.2721341 | AS8: 0.99909724 | AT8: 0.87542239 | AU8: 0.83973187 | AV8: 1 | AW8: 0.98693541 | AX8: 1 | AY8: 1 | AZ8: 0.93957533 | BA8: 1 | BB8: 0.99597022 | BC8: 1.5856823e+10 | BD8: 0.05478465 | BE8: 5244
A9: 8 | B9: 5 | C9: 42 | D9: 0.48900706 | E9: 0.6310492 | F9: 5.7128048 | G9: 7.3152141 | H9: 0.77491114 | I9: 0.14204214 | J9: 0.045538975 | K9: 0.014317408 | L9: 0.0020006933 | M9: 0.56562552 | N9: 0.0035666084 | O9: 0 | P9: 6.1029444 | Q9: 93.897056 | R9: 31.282892 | S9: 50.442079 | T9: 18.275029 | U9: 0 | V9: 68.717108 | W9: 0.48857186 | X9: -54.810805 | Y9: 410.69046 | Z9: 100 | AA9: 56.477242 | AB9: 294.78286 | AC9: 293.02942 | AD9: 38.255528 | AE9: 312.94261 | AF9: 3.74537 | AG9: 780.35012 | AH9: 1.7869347 | AI9: 51.441879 | AJ9: 179.55461 | AK9: 14.340328 | AL9: -35.516339 | AM9: 3.9137028 | AN9: 13.039126 | AO9: 0.9 | AP9: 1.2311309 | AQ9: 1.25 | AR9: 1.246461 | AS9: 1.0018928 | AT9: 0.86443265 | AU9: 0.83906254 | AV9: 1 | AW9: 0.97971232 | AX9: 1 | AY9: 1 | AZ9: 0.91066776 | BA9: 1 | BB9: 1.0092875 | BC9: 2.9888402e+09 | BD9: 0.048214876 | BE9: 2300
A10: 9 | B10: 5 | C10: 48 | D10: 0.63294879 | E10: 0.61203863 | F10: 7.3364735 | G10: 7.1022084 | H10: 1.0341648 | I10: -0.020910152 | J10: 0.048762935 | K10: 0.0097278387 | L10: 0.0020728723 | M10: 0.54847579 | N10: 0.0029991987 | O10: 0 | P10: 5.5606109 | Q10: 94.439389 | R10: 38.069979 | S10: 43.563174 | T10: 18.366847 | U10: 0 | V10: 61.930021 | W10: 0.28388347 | X10: -49.242735 | Y10: 132.00147 | Z10: 100 | AA10: 56.093761 | AB10: 275.91347 | AC10: 273.94821 | AD10: 46.414836 | AE10: 305.08055 | AF10: 3.5113757 | AG10: 780.65744 | AH10: 2.9754841 | AI10: 50.417314 | AJ10: 169.64662 | AK10: 25.490076 | AL10: -29.635414 | AM10: 3.3228478 | AN10: 13.571415 | AO10: 0.9 | AP10: 1.1921863 | AQ10: 1.25 | AR10: 1.2724573 | AS10: 1.0021876 | AT10: 0.88490537 | AU10: 0.83859274 | AV10: 1 | AW10: 0.99044787 | AX10: 1 | AY10: 1 | AZ10: 0.91949097 | BA10: 1 | BB10: 1.0081647 | BC10: 3.036251e+10 | BD10: 0.057647682 | BE10: 6116
A11: 10 | B11: 5 | C11: 54 | D11: 0.66597249 | E11: 0.63889463 | F11: 7.7053489 | G11: 7.4029882 | H11: 1.0423824 | I11: -0.02707786 | J11: 0.051819584 | K11: 0.0082723213 | L11: 0.002967162 | M11: 0.5734478 | N11: 0.0023877639 | O11: 0 | P11: 5.3904311 | Q11: 94.609569 | R11: 28.18115 | S11: 50.935645 | T11: 20.883206 | U11: 0 | V11: 71.81885 | W11: 0.22150197 | X11: -50.827969 | Y11: 85.431185 | Z11: 100 | AA11: 53.465693 | AB11: 274.35975 | AC11: 272.41345 | AD11: 52.50894 | AE11: 298.27238 | AF11: 3.4171726 | AG11: 781.36605 | AH11: 2.3428315 | AI11: 58.50639 | AJ11: 170.47878 | AK11: 27.823198 | AL11: -26.390307 | AM11: 3.4588811 | AN11: 16.129157 | AO11: 0.9 | AP11: 1.2019834 | AQ11: 1.25 | AR11: 1.2669108 | AS11: 1.0035703 | AT11: 0.88671279 | AU11: 0.8372187 | AV11: 1 | AW11: 0.99696982 | AX11: 1 | AY11: 1 | AZ11: 0.90663549 | BA11: 1 | BB11: 1.0103472 | BC11: 4.4724842e+10 | BD11: 0.072465923 | BE11: 9052
A12: 11 | B12: 5 | C12: 60 | D12: 0.62588132 | E12: 0.60649674 | F12: 7.2573544 | G12: 7.0400293 | H12: 1.0319616 | I12: -0.019384586 | J12: 0.056333161 | K12: 0.012043577 | L12: 0.0069016168 | M12: 0.52771423 | N12: 0.0035041531 | O12: 0 | P12: 4.9400561 | Q12: 95.059944 | R12: 28.74507 | S12: 51.986782 | T12: 19.268149 | U12: 0 | V12: 71.25493 | W12: 0.31906745 | X12: -49.573103 | Y12: 241.35653 | Z12: 100 | AA12: 50.491295 | AB12: 266.73188 | AC12: 264.84705 | AD12: 60.812824 | AE12: 288.28956 | AF12: 3.5015947 | AG12: 781.83227 | AH12: 3.4057324 | AI12: 56.445058 | AJ12: 177.10291 | AK12: 24.446569 | AL12: -26.336318 | AM12: 3.5510288 | AN12: 19.460047 | AO12: 0.9 | AP12: 1.2083241 | AQ12: 1.25 | AR12: 1.2564903 | AS12: 1.005183 | AT12: 0.89583874 | AU12: 0.83627654 | AV12: 1 | AW12: 0.99673446 | AX12: 1 | AY12: 1 | AZ12: 0.90736859 | BA12: 1 | BB12: 1.0059478 | BC12: 1.3725586e+11 | BD12: 0.071744502 | BE12: 35146
A13: 12 | B13: 8 | C13: 6 | D13: 0.3721726 | E13: 0.19805504 | F13: 4.3757777 | G13: 2.3509416 | H13: 1.8791372 | I13: -0.17411756 | J13: 0.031238933 | K13: 0.001937151 | L13: 0 | M13: 0.16304351 | N13: 0.0018354436 | O13: 0 | P13: 6.3670636 | Q13: 93.632936 | R13: 45.806842 | S13: 30.836377 | T13: 23.356781 | U13: 0 | V13: 54.193158 | W13: 0.21584288 | X13: -47.189322 | Y13: 8.9541979 | Z13: 100 | AA13: 67.800836 | AB13: 302.91836 | AC13: 300.79921 | AD13: 3.9734126 | AE13: 354.04093 | AF13: 3.6384898 | AG13: 779.38165 | AH13: 5.6559206 | AI13: 47.217106 | AJ13: 172.33873 | AK13: 23.165461 | AL13: -25.683682 | AM13: 6.6289311 | AN13: 2.170562 | AO13: 0.9 | AP13: 1.290771 | AQ13: 0.37367596 | AR13: 1.2763047 | AS13: 0.99407654 | AT13: 0.85449125 | AU13: 0.84105105 | AV13: 1 | AW13: 0.99953289 | AX13: 1 | AY13: 1 | AZ13: 0.92954889 | BA13: 1 | BB13: 0.98800419 | BC13: 2.0696776e+10 | BD13: 0.050958854 | BE13: 6947
... A32: 31 | B32: 11 | C32: 60 | D32: 0.66436961 | E32: 0.62812469 | F32: 7.6874758 | G32: 7.2824753 | H32: 1.0577034 | I32: -0.036244917 | J32: 0.056039368 | K32: 0.011025731 | L32: 0.010150252 | M32: 0.54639567 | N32: 0.0045136726 | O32: 0 | P32: 4.714045 | Q32: 95.285955 | R32: 20.176637 | S32: 60.714009 | T32: 19.109354 | U32: 0 | V32: 79.823363 | W32: 0.31579218 | X32: -49.537354 | Y32: 260.95924 | Z32: 100 | AA32: 34.744158 | AB32: 284.18343 | AC32: 282.34785 | AD32: 60.88111 | AE32: 288.87618 | AF32: 3.5090458 | AG32: 784.33837 | AH32: 3.9138846 | AI32: 59.859471 | AJ32: 177.16525 | AK32: 24.138753 | AL32: -22.036875 | AM32: 9.5831937 | AN32: 59.488197 | AO32: 0.9 | AP32: 1.2902007 | AQ32: 1.25 | AR32: 1.2559156 | AS32: 1.0075915 | AT32: 0.87573184 | AU32: 0.8313026 | AV32: 1 | AW32: 1.0054733 | AX32: 1 | AY32: 1 | AZ32: 0.89622963 | BA32: 1 | BB32: 0.99694247 | BC32: 1.7011229e+11 | BD32: 0.073496056 | BE32: 28099
A39: Sum of actual.cpr | B39: Column Labels
A40: Row Labels | B40: 5 | C40: 8 | D40: 11
A41: 0 | B41: 1.7416622
A42: 6 | B42: 3.8313606 | C42: 4.3757777 | D42: 4.5191185
A43: 12 | B43: 3.9348352 | C43: 5.0766433 | D43: 5.811647
A44: 18 | B44: 4.0908257 | C44: 5.2572187 | D44: 6.4355926
A45: 24 | B45: 5.9384701 | C45: 6.9178852 | D45: 7.9602773
A46: 30 | B46: 6.8177091 | C46: 8.0799665 | D46: 9.3569981
A47: 36 | B47: 6.8161728 | C47: 8.307726 | D47: 9.7863694
A48: 42 | B48: 5.7128048 | C48: 9.2621573 | D48: 9.045593
A49: 48 | B49: 7.3364735 | C49: 8.9602259 | D49: 8.1900222
A50: 54 | B50: 7.7053489 | C50: 8.6643017 | D50: 7.7764876
A51: 60 | B51: 7.2573544 | C51: 8.1073922 | D51: 7.6874758
B56: 5 | C56: 8 | D56: 11
A57: 6 | B57: 3.8313606 | C57: 4.3757777 | D57: 4.5191185
A58: 12 | B58: 3.9348352 | C58: 5.0766433 | D58: 5.811647
A59: 18 | B59: 4.0908257 | C59: 5.2572187 | D59: 6.4355926
A60: 24 | B60: 5.9384701 | C60: 6.9178852 | D60: 7.9602773
A61: 30 | B61: 6.8177091 | C61: 8.0799665 | D61: 9.3569981
A62: 36 | B62: 6.8161728 | C62: 8.307726 | D62: 9.7863694
B65: 5 | C65: 8 | D65: 11
A66: =A57 -> 6 | B66: =(B57-MIN(B$57:B$61))/(MAX(B$57:B$61)-MIN(B$57:B$61)) -> 0 | C66: =(C57-MIN(C$57:C$61))/(MAX(C$57:C$61)-MIN(C$57:C$61)) -> 0 | D66: =(D57-MIN(D$57:D$61))/(MAX(D$57:D$61)-MIN(D$57:D$61)) -> 0
A67: =A58 -> 12 | B67: =(B58-MIN(B$57:B$61))/(MAX(B$57:B$61)-MIN(B$57:B$61)) -> 0.034649197 | C67: =(C58-MIN(C$57:C$61))/(MAX(C$57:C$61)-MIN(C$57:C$61)) -> 0.18920894 | D67: =(D58-MIN(D$57:D$61))/(MAX(D$57:D$61)-MIN(D$57:D$61)) -> 0.26716838
A68: =A59 -> 18 | B68: =(B59-MIN(B$57:B$61))/(MAX(B$57:B$61)-MIN(B$57:B$61)) -> 0.086883719 | C68: =(C59-MIN(C$57:C$61))/(MAX(C$57:C$61)-MIN(C$57:C$61)) -> 0.23795791 | D68: =(D59-MIN(D$57:D$61))/(MAX(D$57:D$61)-MIN(D$57:D$61)) -> 0.39613926
A69: =A60 -> 24 | B69: =(B60-MIN(B$57:B$61))/(MAX(B$57:B$61)-MIN(B$57:B$61)) -> 0.7055806 | C69: =(C60-MIN(C$57:C$61))/(MAX(C$57:C$61)-MIN(C$57:C$61)) -> 0.68627913 | D69: =(D60-MIN(D$57:D$61))/(MAX(D$57:D$61)-MIN(D$57:D$61)) -> 0.71129484
A70: =A61 -> 30 | B70: =(B61-MIN(B$57:B$61))/(MAX(B$57:B$61)-MIN(B$57:B$61)) -> 1 | C70: =(C61-MIN(C$57:C$61))/(MAX(C$57:C$61)-MIN(C$57:C$61)) -> 1 | D70: =(D61-MIN(D$57:D$61))/(MAX(D$57:D$61)-MIN(D$57:D$61)) -> 1
...

Sheet HPA 5 Fit
B1: grp | C1: x | D1: actual.smm | E1: model.smm | F1: actual.cpr | G1: model.cpr | H1: ratio | I1: track.err | J1: curt.smm | K1: dflt.smm | L1: cout.smm | M1: turn.smm | N1: refi.smm | O1: pct_inv | P1: pct_2nd | Q1: pct_owner | R1: pct_purchase | S1: pct_REFI_NCO | T1: pct_REFI_CO | U1: pct_REFI_Other | V1: pct_REFI | W1: pct_dq | X1: incentive | Y1: burnout | Z1: refi_elig_pct | AA1: cltv | AB1: wacls | AC1: acls | AD1: wala | AE1: wam | AF1: wac | AG1: fico | AH1: pct_HARPed | AI1: pct_tpo | AJ1: cai | AK1: media_effect | AL1: sato | AM1: hpa_annual | AN1: hpa_cum | AO1: turn_cai_mult | AP1: turn_hpa_annual_mult | AQ1: turn_wala_mult | AR1: turn_incentive_mult | AS1: turn_cltv_mult | AT1: turn_acls_mult | AU1: turn_fico_mult | AV1: turn_tax_mult | AW1: turn_sato_mult | AX1: turn_pct_HARPed_mult | AY1: turn_HARP_eligible_mult | AZ1: turn_pct_purchase_mult | BA1: turn_pct_inv_mult | BB1: turn_pct_second_lien_mult | BC1: bal | BD1: std | BE1: n
A2: 1 | B2: 5 | C2: 0 | D2: 0.14631016 | E2: 0.049958196 | F2: 1.7416622 | G2: 0.59785384 | H2: 2.9286518 | I2: -0.096351965 | J2: 0.0016776749 | K2: 0.00022185858 | L2: 0 | M2: 0.048058662 | N2: 9.1706228e-11 | O2: 0 | P2: 9.4685993 | Q2: 90.531401 | R2: 76.425354 | S2: 15.754111 | T2: 7.8205353 | U2: 0 | V2: 23.574646 | W2: 0.0010182395 | X2: -37.310377 | Y2: 0 | Z2: 100 | AA2: 74.346911 | AB2: 310.35997 | AC2: 308.53904 | AD2: -0.013928194 | AE2: 359.36565 | AF2: 3.8063244 | AG2: 778.03438 | AH2: 1.0574863 | AI2: 45.011505 | AJ2: 176.58301 | AK2: 23.07572 | AL2: -60.120925 | AM2: -0.09873614 | AN2: -0.018232518 | AO2: 0.9 | AP2: 0.89337 | AQ2: 0.15921074 | AR2: 1.2845346 | AS2: 0.99076916 | AT2: 0.84600735 | AU2: 0.84330886 | AV2: 1 | AW2: 0.94188914 | AX2: 1 | AY2: 1 | AZ2: 0.96935296 | BA2: 1 | BB2: 0.97708382 | BC2: 7.9022591e+08 | BD2: 0.0015308369 | BE2: 718
A3: 2 | B3: 5 | C3: 6 | D3: 0.32502793 | E3: 0.15551926 | F3: 3.8313606 | G3: 1.8503507 | H3: 2.0899529 | I3: -0.16950867 | J3: 0.030002077 | K3: 0.0018827369 | L3: 0 | M3: 0.12217751 | N3: 0.0014569401 | O3: 0 | P3: 7.4453889 | Q3: 92.554611 | R3: 52.402511 | S3: 27.822904 | T3: 19.774586 | U3: 0 | V3: 47.597489 | W3: 0.20356299 | X3: -48.748626 | Y3: 6.9476931 | Z3: 100 | AA3: 71.266519 | AB3: 295.79211 | AC3: 293.64967 | AD3: 3.710124 | AE3: 354.18442 | AF3: 3.6272493 | AG3: 779.45157 | AH3: 5.1870431 | AI3: 46.593321 | AJ3: 172.2463 | AK3: 24.355655 | AL3: -28.455368 | AM3: 1.8289281 | AN3: 0.61731222 | AO3: 0.9 | AP3: 1.0207702 | AQ3: 0.35956436 | AR3: 1.27109 | AS3: 0.99226949 | AT3: 0.86183968 | AU3: 0.840905 | AV3: 1 | AW3: 0.99415805 | AX3: 1 | AY3: 1 | AZ3: 0.93812326 | BA3: 1 | BB3: 0.98745559 | BC3: 2.2663762e+10 | BD3: 0.035625648 | BE3: 7300
A4: 3 | B4: 5 | C4: 12 | D4: 0.33396962 | E4: 0.34608612 | F4: 3.9348352 | G4: 4.0748864 | H4: 0.96498991 | I4: 0.012116505 | J4: 0.035362423 | K4: 0.0028613862 | L4: 0 | M4: 0.30392552 | N4: 0.0039367951 | O4: 0 | P4: 5.5374128 | Q4: 94.462587 | R4: 60.607592 | S4: 25.129824 | T4: 14.262584 | U4: 0 | V4: 39.392408 | W4: 0.21004557 | X4: -45.754388 | Y4: 56.746925 | Z4: 100 | AA4: 70.710627 | AB4: 295.06802 | AC4: 292.82995 | AD4: 8.4193124 | AE4: 348.55756 | AF4: 3.6557577 | AG4: 780.10124 | AH4: 4.5062657 | AI4: 48.747643 | AJ4: 172.35743 | AK4: 23.410723 | AL4: -25.75689 | AM4: 2.9406769 | AN4: 2.1361365 | AO4: 0.9 | AP4: 1.1441075 | AQ4: 0.70910001 | AR4: 1.276543 | AS4: 0.99239789 | AT4: 0.86292542 | AU4: 0.83967607 | AV4: 1 | AW4: 0.99850432 | AX4: 1 | AY4: 1 | AZ4: 0.94878987 | BA4: 1 | BB4: 0.98572728 | BC4: 5.2606559e+10 | BD4: 0.052092701 | BE4: 10189
A5: 4 | B5: 5 | C5: 18 | D5: 0.34746613 | E5: 0.5076441 | F5: 4.0908257 | G5: 5.9244909 | H5: 0.68446798 | I5: 0.16017797 | J5: 0.035989504 | K5: 0.0087862284 | L5: 0 | M5: 0.45729472 | N5: 0.0055736453 | O5: 0 | P5: 5.2312579 | Q5: 94.768742 | R5: 51.960399 | S5: 31.779781 | T5: 16.25982 | U5: 0 | V5: 48.039601 | W5: 0.50593856 | X5: -47.291207 | Y5: 34.332723 | Z5: 100 | AA5: 67.150566 | AB5: 295.41921 | AC5: 293.18416 | AD5: 15.209418 | AE5: 340.62212 | AF5: 3.5097721 | AG5: 780.28438 | AH5: 5.4397517 | AI5: 47.280511 | AJ5: 176.95766 | AK5: 26.397506 | AL5: -26.589291 | AM5: 3.7381054 | AN5: 4.7732578 | AO5: 0.9 | AP5: 1.2250648 | AQ5: 1.1759225 | AR5: 1.2618114 | AS5: 0.99455842 | AT5: 0.86291689 | AU5: 0.83929623 | AV5: 1 | AW5: 0.99636208 | AX5: 1 | AY5: 1 | AZ5: 0.93754852 | BA5: 1 | BB5: 0.98671985 | BC5: 4.0074992e+10 | BD5: 0.052175348 | BE5: 6792
A6: 5 | B6: 5 | C6: 24 | D6: 0.50887619 | E6: 0.57600036 | F6: 5.9384701 | G6: 6.6971822 | H6: 0.88346505 | I6: 0.067124175 | J6: 0.037904579 | K6: 0.009584374 | L6: 3.4983497e-10 | M6: 0.52473201 | N6: 0.0037793997 | O6: 0 | P6: 5.1651503 | Q6: 94.83485 | R6: 51.23455 | S6: 31.283497 | T6: 17.481953 | U6: 0 | V6: 48.76545 | W6: 0.4459982 | X6: -51.159049 | Y6: 137.87563 | Z6: 100 | AA6: 64.397031 | AB6: 292.08593 | AC6: 289.90643 | AD6: 22.038392 | AE6: 332.5059 | AF6: 3.6361296 | AG6: 780.17404 | AH6: 3.86636 | AI6: 49.072564 | AJ6: 175.73712 | AK6: 20.261929 | AL6: -28.009511 | AM6: 3.6119465 | AN6: 6.7772773 | AO6: 0.9 | AP6: 1.2148145 | AQ6: 1.25 | AR6: 1.2583978 | AS6: 0.99639499 | AT6: 0.86668853 | AU6: 0.83947237 | AV6: 1 | AW6: 0.99300467 | AX6: 1 | AY6: 1 | AZ6: 0.93660492 | BA6: 1 | BB6: 0.99548427 | BC6: 2.5888123e+10 | BD6: 0.059717576 | BE6: 8207
A7: 6 | B7: 5 | C7: 30 | D7: 0.58670955 | E7: 0.65231404 | F7: 6.8177091 | G7: 7.5529473 | H7: 0.89942805 | I7: 0.065604492 | J7: 0.039266521 | K7: 0.0094229209 | L7: 4.0606219e-05 | M7: 0.59528723 | N7: 0.0082967543 | O7: 0 | P7: 5.570858 | Q7: 94.429142 | R7: 51.606751 | S7: 33.723154 | T7: 14.670095 | U7: 0 | V7: 48.393249 | W7: 0.39663717 | X7: -39.748478 | Y7: 229.60688 | Z7: 100 | AA7: 62.031029 | AB7: 292.67164 | AC7: 290.54577 | AD7: 25.673778 | AE7: 328.02571 | AF7: 3.684992 | AG7: 780.38955 | AH7: 2.470356 | AI7: 48.980398 | AJ7: 175.26321 | AK7: 22.518667 | AL7: -33.026224 | AM7: 3.9387651 | AN7: 8.6634773 | AO7: 0.9 | AP7: 1.2338712 | AQ7: 1.25 | AR7: 1.2829333 | AS7: 0.99806831 | AT7: 0.86615496 | AU7: 0.83903954 | AV7: 1 | AW7: 0.98364539 | AX7: 1 | AY7: 1 | AZ7: 0.93708878 | BA7: 1 | BB7: 0.99117862 | BC7: 8.7935926e+09 | BD7: 0.068873365 | BE7: 3991
A8: 7 | B8: 5 | C8: 36 | D8: 0.58657297 | E8: 0.60207517 | F8: 6.8161728 | G8: 6.9903927 | H8: 0.97425204 | I8: 0.015502207 | J8: 0.042792485 | K8: 0.014314723 | L8: 0.00042279389 | M8: 0.54030121 | N8: 0.0042439652 | O8: 0 | P8: 5.1798552 | Q8: 94.820145 | R8: 53.519484 | S8: 30.111867 | T8: 16.368648 | U8: 0 | V8: 46.480516 | W8: 0.51462799 | X8: -46.992146 | Y8: 292.95771 | Z8: 100 | AA8: 60.815186 | AB8: 283.94275 | AC8: 281.85228 | AD8: 34.079503 | AE8: 318.66902 | AF8: 3.7151886 | AG8: 780.05753 | AH8: 1.0475529 | AI8: 48.314946 | AJ8: 179.14606 | AK8: 18.453885 | AL8: -31.622497 | AM8: 3.7004675 | AN8: 10.939625 | AO8: 0.9 | AP8: 1.2157939 | AQ8: 1.25 | AR8: 1.2721341 | AS8: 0.99909724 | AT8: 0.87542239 | AU8: 0.83973187 | AV8: 1 | AW8: 0.98693541 | AX8: 1 | AY8: 1 | AZ8: 0.93957533 | BA8: 1 | BB8: 0.99597022 | BC8: 1.5856823e+10 | BD8: 0.05478465 | BE8: 5244
A9: 8 | B9: 5 | C9: 42 | D9: 0.48900706 | E9: 0.6310492 | F9: 5.7128048 | G9: 7.3152141 | H9: 0.77491114 | I9: 0.14204214 | J9: 0.045538975 | K9: 0.014317408 | L9: 0.0020006933 | M9: 0.56562552 | N9: 0.0035666084 | O9: 0 | P9: 6.1029444 | Q9: 93.897056 | R9: 31.282892 | S9: 50.442079 | T9: 18.275029 | U9: 0 | V9: 68.717108 | W9: 0.48857186 | X9: -54.810805 | Y9: 410.69046 | Z9: 100 | AA9: 56.477242 | AB9: 294.78286 | AC9: 293.02942 | AD9: 38.255528 | AE9: 312.94261 | AF9: 3.74537 | AG9: 780.35012 | AH9: 1.7869347 | AI9: 51.441879 | AJ9: 179.55461 | AK9: 14.340328 | AL9: -35.516339 | AM9: 3.9137028 | AN9: 13.039126 | AO9: 0.9 | AP9: 1.2311309 | AQ9: 1.25 | AR9: 1.246461 | AS9: 1.0018928 | AT9: 0.86443265 | AU9: 0.83906254 | AV9: 1 | AW9: 0.97971232 | AX9: 1 | AY9: 1 | AZ9: 0.91066776 | BA9: 1 | BB9: 1.0092875 | BC9: 2.9888402e+09 | BD9: 0.048214876 | BE9: 2300
A10: 9 | B10: 5 | C10: 48 | D10: 0.63294879 | E10: 0.61203863 | F10: 7.3364735 | G10: 7.1022084 | H10: 1.0341648 | I10: -0.020910152 | J10: 0.048762935 | K10: 0.0097278387 | L10: 0.0020728723 | M10: 0.54847579 | N10: 0.0029991987 | O10: 0 | P10: 5.5606109 | Q10: 94.439389 | R10: 38.069979 | S10: 43.563174 | T10: 18.366847 | U10: 0 | V10: 61.930021 | W10: 0.28388347 | X10: -49.242735 | Y10: 132.00147 | Z10: 100 | AA10: 56.093761 | AB10: 275.91347 | AC10: 273.94821 | AD10: 46.414836 | AE10: 305.08055 | AF10: 3.5113757 | AG10: 780.65744 | AH10: 2.9754841 | AI10: 50.417314 | AJ10: 169.64662 | AK10: 25.490076 | AL10: -29.635414 | AM10: 3.3228478 | AN10: 13.571415 | AO10: 0.9 | AP10: 1.1921863 | AQ10: 1.25 | AR10: 1.2724573 | AS10: 1.0021876 | AT10: 0.88490537 | AU10: 0.83859274 | AV10: 1 | AW10: 0.99044787 | AX10: 1 | AY10: 1 | AZ10: 0.91949097 | BA10: 1 | BB10: 1.0081647 | BC10: 3.036251e+10 | BD10: 0.057647682 | BE10: 6116
A11: 10 | B11: 5 | C11: 54 | D11: 0.66597249 | E11: 0.63889463 | F11: 7.7053489 | G11: 7.4029882 | H11: 1.0423824 | I11: -0.02707786 | J11: 0.051819584 | K11: 0.0082723213 | L11: 0.002967162 | M11: 0.5734478 | N11: 0.0023877639 | O11: 0 | P11: 5.3904311 | Q11: 94.609569 | R11: 28.18115 | S11: 50.935645 | T11: 20.883206 | U11: 0 | V11: 71.81885 | W11: 0.22150197 | X11: -50.827969 | Y11: 85.431185 | Z11: 100 | AA11: 53.465693 | AB11: 274.35975 | AC11: 272.41345 | AD11: 52.50894 | AE11: 298.27238 | AF11: 3.4171726 | AG11: 781.36605 | AH11: 2.3428315 | AI11: 58.50639 | AJ11: 170.47878 | AK11: 27.823198 | AL11: -26.390307 | AM11: 3.4588811 | AN11: 16.129157 | AO11: 0.9 | AP11: 1.2019834 | AQ11: 1.25 | AR11: 1.2669108 | AS11: 1.0035703 | AT11: 0.88671279 | AU11: 0.8372187 | AV11: 1 | AW11: 0.99696982 | AX11: 1 | AY11: 1 | AZ11: 0.90663549 | BA11: 1 | BB11: 1.0103472 | BC11: 4.4724842e+10 | BD11: 0.072465923 | BE11: 9052
A12: 11 | B12: 5 | C12: 60 | D12: 0.62588132 | E12: 0.60649674 | F12: 7.2573544 | G12: 7.0400293 | H12: 1.0319616 | I12: -0.019384586 | J12: 0.056333161 | K12: 0.012043577 | L12: 0.0069016168 | M12: 0.52771423 | N12: 0.0035041531 | O12: 0 | P12: 4.9400561 | Q12: 95.059944 | R12: 28.74507 | S12: 51.986782 | T12: 19.268149 | U12: 0 | V12: 71.25493 | W12: 0.31906745 | X12: -49.573103 | Y12: 241.35653 | Z12: 100 | AA12: 50.491295 | AB12: 266.73188 | AC12: 264.84705 | AD12: 60.812824 | AE12: 288.28956 | AF12: 3.5015947 | AG12: 781.83227 | AH12: 3.4057324 | AI12: 56.445058 | AJ12: 177.10291 | AK12: 24.446569 | AL12: -26.336318 | AM12: 3.5510288 | AN12: 19.460047 | AO12: 0.9 | AP12: 1.2083241 | AQ12: 1.25 | AR12: 1.2564903 | AS12: 1.005183 | AT12: 0.89583874 | AU12: 0.83627654 | AV12: 1 | AW12: 0.99673446 | AX12: 1 | AY12: 1 | AZ12: 0.90736859 | BA12: 1 | BB12: 1.0059478 | BC12: 1.3725586e+11 | BD12: 0.071744502 | BE12: 35146
G16: 1
D17: wala | E17: bal | F17: =D1 -> actual.smm | G17: =E1 -> model.smm | H17: ratio | J17: Prod Knots | K17: Ratio | L17: Dev Knots | M17: =K1 -> dflt.smm | N17: Ratio
C18: =C2 -> 0 | D18: =AD2 -> -0.013928194 | E18: =BC2/1000000000 -> 0.79022591 | F18: =D2 -> 0.14631016 | G18: =J2+K2+L2+M2*$G$16+N2 -> 0.049958196 | H18: =F18/G18 -> 2.9286518 | J18: 0.16 | L18: =L19 -> 0.71
C19: =C3 -> 6 | D19: =AD3 -> 3.710124 | E19: =BC3/1000000000 -> 22.663762 | F19: =D3 -> 0.32502793 | G19: =J3+K3+L3+M3*$G$16+N3 -> 0.15551926 | H19: =F19/G19 -> 2.0899529 | J19: 0.5 | K19: 1.42 | L19: =J19*K19 -> 0.71 | M19: =J3+K3+L3+M3*$K19+N3 -> 0.20683382 | N19: =F19/M19 -> 1.5714448
C20: =C4 -> 12 | D20: =AD4 -> 8.4193124 | E20: =BC4/1000000000 -> 52.606559 | F20: =D4 -> 0.33396962 | G20: =J4+K4+L4+M4*$G$16+N4 -> 0.34608612 | H20: =F20/G20 -> 0.96498991 | J20: 1.02 | K20: 0.7 | L20: =J20*K20 -> 0.714 | M20: =J4+K4+L4+M4*$K20+N4 -> 0.25490847 | N20: =F20/M20 -> 1.3101551
C21: =C5 -> 18 | D21: =AD5 -> 15.209418 | E21: =BC5/1000000000 -> 40.074992 | F21: =D5 -> 0.34746613 | G21: =J5+K5+L5+M5*$G$16+N5 -> 0.5076441 | H21: =F21/G21 -> 0.68446798 | J21: 1.25 | K21: 0.68 | L21: =J21*K21 -> 0.85 | M21: =J5+K5+L5+M5*$K21+N5 -> 0.36130979 | N21: =F21/M21 -> 0.96168479
C22: =C6 -> 24 | D22: =AD6 -> 22.038392 | E22: =BC6/1000000000 -> 25.888123 | F22: =D6 -> 0.50887619 | G22: =J6+K6+L6+M6*$G$16+N6 -> 0.57600036 | H22: =F22/G22 -> 0.88346505 | J22: 1.25 | K22: 0.88 | L22: =J22*K22 -> 1.1 | M22: =J6+K6+L6+M6*$K22+N6 -> 0.51303252 | N22: =F22/M22 -> 0.9918985
C23: =C7 -> 30 | D23: =AD7 -> 25.673778 | E23: =BC7/1000000000 -> 8.7935926 | F23: =D7 -> 0.58670955 | G23: =J7+K7+L7+M7*$G$16+N7 -> 0.65231404 | H23: =F23/G23 -> 0.89942805 | J23: 1.25 | K23: 0.89 | L23: =J23*K23 -> 1.1125 | M23: =J7+K7+L7+M7*$K23+N7 -> 0.58683244 | N23: =F23/M23 -> 0.99979058
C24: =C8 -> 36 | D24: =AD8 -> 34.079503 | E24: =BC8/1000000000 -> 15.856823 | F24: =D8 -> 0.58657297 | G24: =J8+K8+L8+M8*$G$16+N8 -> 0.60207517 | H24: =F24/G24 -> 0.97425204 | J24: 1.25 | K24: 0.99 | L24: =J24*K24 -> 1.2375 | M24: =J8+K8+L8+M8*$K24+N8 -> 0.59667216 | N24: =F24/M24 -> 0.98307413
D30: HPA 11 | E30: HPA 5
C31: =C18 -> 0 | D31: ='HPA 11 Fit'!L17 -> 0.71 | E31: ='HPA 5 Fit'!L18 -> 0.71
C32: =C19 -> 6 | D32: ='HPA 11 Fit'!L18 -> 0.85 | E32: ='HPA 5 Fit'!L19 -> 0.71
C33: =C20 -> 12 | D33: ='HPA 11 Fit'!L19 -> 1.071 | E33: ='HPA 5 Fit'!L20 -> 0.714
C34: =C21 -> 18 | D34: ='HPA 11 Fit'!L20 -> 1.25 | E34: ='HPA 5 Fit'!L21 -> 0.85
C35: =C22 -> 24 | D35: ='HPA 11 Fit'!L21 -> 1.25 | E35: ='HPA 5 Fit'!L22 -> 1.1
C36: =C23 -> 30 | D36: ='HPA 11 Fit'!L22 -> 1.25 | E36: ='HPA 5 Fit'!L23 -> 1.1125
C37: =C24 -> 36 | D37: ='HPA 11 Fit'!L23 -> 1.25 | E37: ='HPA 5 Fit'!L24 -> 1.2375

Sheet HPA 11 Fit
B1: grp | C1: x | D1: actual.smm | E1: model.smm | F1: actual.cpr | G1: model.cpr | H1: ratio | I1: track.err | J1: curt.smm | K1: dflt.smm | L1: cout.smm | M1: turn.smm | N1: refi.smm | O1: pct_inv | P1: pct_2nd | Q1: pct_owner | R1: pct_purchase | S1: pct_REFI_NCO | T1: pct_REFI_CO | U1: pct_REFI_Other | V1: pct_REFI | W1: pct_dq | X1: incentive | Y1: burnout | Z1: refi_elig_pct | AA1: cltv | AB1: wacls | AC1: acls | AD1: wala | AE1: wam | AF1: wac | AG1: fico | AH1: pct_HARPed | AI1: pct_tpo | AJ1: cai | AK1: media_effect | AL1: sato | AM1: hpa_annual | AN1: hpa_cum | AO1: turn_cai_mult | AP1: turn_hpa_annual_mult | AQ1: turn_wala_mult | AR1: turn_incentive_mult | AS1: turn_cltv_mult | AT1: turn_acls_mult | AU1: turn_fico_mult | AV1: turn_tax_mult | AW1: turn_sato_mult | AX1: turn_pct_HARPed_mult | AY1: turn_HARP_eligible_mult | AZ1: turn_pct_purchase_mult | BA1: turn_pct_inv_mult | BB1: turn_pct_second_lien_mult | BC1: bal | BD1: std | BE1: n
A2: 22 | B2: 11 | C2: 6 | D2: 0.38462635 | E2: 0.20205797 | F2: 4.5191185 | G2: 2.3979302 | H2: 1.9035446 | I2: -0.18256838 | J2: 0.030426569 | K2: 0.0017528297 | L2: 0 | M2: 0.16801435 | N2: 0.0018642206 | O2: 0 | P2: 6.7659444 | Q2: 93.234056 | R2: 44.271888 | S2: 31.149503 | T2: 24.578609 | U2: 0 | V2: 55.728112 | W2: 0.20314617 | X2: -44.99102 | Y2: 5.8596704 | Z2: 100 | AA2: 65.660279 | AB2: 306.40362 | AC2: 304.19521 | AD2: 3.7304316 | AE2: 354.40578 | AF2: 3.6743912 | AG2: 779.38363 | AH2: 5.2995297 | AI2: 45.260266 | AJ2: 173.16898 | AK2: 21.725863 | AL2: -29.76267 | AM2: 11.631265 | AN2: 3.4721406 | AO2: 0.9 | AP2: 1.2902035 | AQ2: 0.36043888 | AR2: 1.2797851 | AS2: 0.99532631 | AT2: 0.85079115 | AU2: 0.84105338 | AV2: 1 | AW2: 0.99168691 | AX2: 1 | AY2: 1 | AZ2: 0.92755345 | BA2: 1 | BB2: 0.98612371 | BC2: 5.0589889e+10 | BD2: 0.036770709 | BE2: 11129
A3: 23 | B3: 11 | C3: 12 | D3: 0.49770443 | E3: 0.40808263 | F3: 5.811647 | G3: 4.7885622 | H3: 1.2196168 | I3: -0.089621808 | J3: 0.035216703 | K3: 0.0025008024 | L3: 5.6214664e-07 | M3: 0.36239142 | N3: 0.0079731433 | O3: 0 | P3: 6.4067775 | Q3: 93.593223 | R3: 43.198881 | S3: 35.007527 | T3: 21.793592 | U3: 0 | V3: 56.801119 | W3: 0.18957944 | X3: -39.193826 | Y3: 28.863649 | Z3: 100 | AA3: 63.757091 | AB3: 310.74497 | AC3: 308.54785 | AD3: 8.6302402 | AE3: 348.90178 | AF3: 3.5335568 | AG3: 780.02243 | AH3: 5.670902 | AI3: 49.786848 | AJ3: 172.66094 | AK3: 27.921916 | AL3: -25.678238 | AM3: 10.033796 | AN3: 7.0497363 | AO3: 0.9 | AP3: 1.2902013 | AQ3: 0.72722283 | AR3: 1.283389 | AS3: 0.99647034 | AT3: 0.8464468 | AU3: 0.83981093 | AV3: 1 | AW3: 0.99893144 | AX3: 1 | AY3: 1 | AZ3: 0.92615855 | BA3: 1 | BB3: 0.98512237 | BC3: 1.0289758e+11 | BD3: 0.052412013 | BE3: 12522
A4: 24 | B4: 11 | C4: 18 | D4: 0.55280088 | E4: 0.54727232 | F4: 6.4355926 | G4: 6.3731553 | H4: 1.010102 | I4: -0.0055285584 | J4: 0.035773436 | K4: 0.008407844 | L4: 0.00054715408 | M4: 0.49679533 | N4: 0.0057485606 | O4: 0 | P4: 5.2177755 | Q4: 94.782225 | R4: 34.652947 | S4: 39.632938 | T4: 25.714116 | U4: 0 | V4: 65.347053 | W4: 0.5215819 | X4: -50.182987 | Y4: 37.300445 | Z4: 100 | AA4: 57.187442 | AB4: 311.33377 | AC4: 309.11541 | AD4: 15.246028 | AE4: 341.2201 | AF4: 3.5440108 | AG4: 780.38598 | AH4: 6.6224067 | AI4: 46.977368 | AJ4: 177.60642 | AK4: 22.616104 | AL4: -24.063072 | AM4: 9.4337117 | AN4: 12.202568 | AO4: 0.9 | AP4: 1.2902005 | AQ4: 1.1747978 | AR4: 1.2556377 | AS4: 1.0008029 | AT4: 0.84614934 | AU4: 0.83908983 | AV4: 1 | AW4: 1.0016288 | AX4: 1 | AY4: 1 | AZ4: 0.91504883 | BA4: 1 | BB4: 0.98578828 | BC4: 9.4625076e+10 | BD4: 0.055320095 | BE4: 9753
A5: 25 | B5: 11 | C5: 24 | D5: 0.68886581 | E5: 0.62498096 | F5: 7.9602773 | G5: 7.2472706 | H5: 1.1022189 | I5: -0.063884849 | J5: 0.037568586 | K5: 0.010474769 | L5: 0.0054739655 | M5: 0.56857356 | N5: 0.0028900802 | O5: 0 | P5: 6.5512411 | Q5: 93.448759 | R5: 41.06929 | S5: 34.042847 | T5: 24.887863 | U5: 0 | V5: 58.93071 | W5: 0.52329866 | X5: -55.372566 | Y5: 158.63699 | Z5: 100 | AA5: 55.810958 | AB5: 302.89266 | AC5: 300.70345 | AD5: 22.082832 | AE5: 333.30429 | AF5: 3.6553758 | AG5: 780.29212 | AH5: 5.7124285 | AI5: 48.109234 | AJ5: 178.24794 | AK5: 16.919501 | AL5: -22.065397 | AM5: 9.2562277 | AN5: 17.772658 | AO5: 0.9 | AP5: 1.2902 | AQ5: 1.25 | AR5: 1.2496069 | AS5: 1.0021022 | AT5: 0.85513284 | AU5: 0.83930102 | AV5: 1 | AW5: 1.0055093 | AX5: 1 | AY5: 1 | AZ5: 0.92339008 | BA5: 1 | BB5: 0.98698777 | BC5: 3.877021e+10 | BD5: 0.065641592 | BE5: 8077
A6: 26 | B6: 11 | C6: 30 | D6: 0.8153367 | E6: 0.69492679 | F6: 9.3569981 | G6: 8.0276611 | H6: 1.1732699 | I6: -0.12040991 | J6: 0.038970036 | K6: 0.0099253264 | L6: 0.018150336 | M6: 0.61924971 | N6: 0.0086313868 | O6: 0 | P6: 6.25713 | Q6: 93.74287 | R6: 42.046487 | S6: 38.626331 | T6: 19.327182 | U6: 0 | V6: 57.953513 | W6: 0.45131636 | X6: -39.725459 | Y6: 296.81359 | Z6: 100 | AA6: 52.138341 | AB6: 301.62895 | AC6: 299.43852 | AD6: 25.757285 | AE6: 328.77533 | AF6: 3.7184679 | AG6: 781.37845 | AH6: 3.52425 | AI6: 48.122079 | AJ6: 175.99184 | AK6: 20.230748 | AL6: -29.163325 | AM6: 9.2770725 | AN6: 21.048291 | AO6: 0.9 | AP6: 1.2901998 | AQ6: 1.25 | AR6: 1.2844566 | AS6: 1.0040031 | AT6: 0.85653948 | AU6: 0.83717517 | AV6: 1 | AW6: 0.9916181 | AX6: 1 | AY6: 1 | AZ6: 0.92466043 | BA6: 1 | BB6: 0.98544878 | BC6: 2.0238524e+10 | BD6: 0.078835155 | BE6: 5251
A7: 27 | B7: 11 | C7: 36 | D7: 0.85457469 | E7: 0.6726589 | F7: 9.7863694 | G7: 7.7798723 | H7: 1.2704428 | I7: -0.18191579 | J7: 0.042805623 | K7: 0.014719723 | L7: 0.012521418 | M7: 0.59700659 | N7: 0.0056055522 | O7: 0 | P7: 8.573563 | Q7: 91.426437 | R7: 54.870061 | S7: 27.162079 | T7: 17.96786 | U7: 0 | V7: 45.129939 | W7: 0.56798289 | X7: -42.337233 | Y7: 400.77503 | Z7: 100 | AA7: 50.518163 | AB7: 287.21801 | AC7: 285.12268 | AD7: 34.377749 | AE7: 318.76185 | AF7: 3.7525904 | AG7: 781.37182 | AH7: 0.96524933 | AI7: 44.917228 | AJ7: 179.31279 | AK7: 17.140319 | AL7: -26.305737 | AM7: 9.4928293 | AN7: 29.781197 | AO7: 0.9 | AP7: 1.2902001 | AQ7: 1.25 | AR7: 1.2818083 | AS7: 1.0054861 | AT7: 0.87203941 | AU7: 0.83714977 | AV7: 1 | AW7: 0.99789758 | AX7: 1 | AY7: 1 | AZ7: 0.94133108 | BA7: 1 | BB7: 0.98845302 | BC7: 1.5442061e+10 | BD7: 0.079387319 | BE7: 4050
A8: 28 | B8: 11 | C8: 42 | D8: 0.78698549 | E8: 0.64317808 | F8: 9.045593 | G8: 7.4508791 | H8: 1.2235888 | I8: -0.1438074 | J8: 0.044186069 | K8: 0.012672234 | L8: 0.0058387582 | M8: 0.57795127 | N8: 0.0025297462 | O8: 0 | P8: 4.7682299 | Q8: 95.23177 | R8: 20.082999 | S8: 54.697141 | T8: 25.21986 | U8: 0 | V8: 79.917001 | W8: 0.46586252 | X8: -55.883518 | Y8: 383.53029 | Z8: 100 | AA8: 46.209104 | AB8: 302.06463 | AC8: 300.0016 | AD8: 37.483146 | AE8: 315.41373 | AF8: 3.7178088 | AG8: 781.33011 | AH8: 1.1240463 | AI8: 50.317078 | AJ8: 179.68306 | AK8: 13.832393 | AL8: -31.829491 | AM8: 9.1321118 | AN8: 31.495086 | AO8: 0.9 | AP8: 1.2901991 | AQ8: 1.25 | AR8: 1.2526838 | AS8: 1.0066516 | AT8: 0.8557761 | AU8: 0.83727825 | AV8: 1 | AW8: 0.98545869 | AX8: 1 | AY8: 1 | AZ8: 0.8961079 | BA8: 1 | BB8: 0.99028736 | BC8: 9.7206294e+09 | BD8: 0.074201435 | BE8: 2968
A9: 29 | B9: 11 | C9: 48 | D9: 0.70954744 | E9: 0.65469091 | F9: 8.1900222 | G9: 7.5794851 | H9: 1.08379 | I9: -0.054856523 | J9: 0.049006224 | K9: 0.0084765306 | L9: 0.0090604025 | M9: 0.58398353 | N9: 0.004164228 | O9: 0 | P9: 5.7141193 | Q9: 94.285881 | R9: 27.630916 | S9: 51.779275 | T9: 20.589809 | U9: 0 | V9: 72.369084 | W9: 0.2676895 | X9: -45.954728 | Y9: 136.40944 | Z9: 100 | AA9: 41.928021 | AB9: 290.70012 | AC9: 288.76735 | AD9: 47.218309 | AE9: 304.65229 | AF9: 3.5108018 | AG9: 782.73387 | AH9: 3.7593595 | AI9: 54.65036 | AJ9: 169.37986 | AK9: 25.8241 | AL9: -22.778884 | AM9: 9.0568521 | AN9: 40.783938 | AO9: 0.9 | AP9: 1.2901999 | AQ9: 1.25 | AR9: 1.2796505 | AS9: 1.0072585 | AT9: 0.868396 | AU9: 0.8344619 | AV9: 1 | AW9: 1.0047046 | AX9: 1 | AY9: 1 | AZ9: 0.90592019 | BA9: 1 | BB9: 0.99979854 | BC9: 2.4287688e+10 | BD9: 0.087300358 | BE9: 4331
A10: 30 | B10: 11 | C10: 54 | D10: 0.67235511 | E10: 0.67624709 | F10: 7.7764876 | G10: 7.8198416 | H10: 0.99424474 | I10: 0.003891977 | J10: 0.051724533 | K10: 0.0075517531 | L10: 0.0067401205 | M10: 0.607285 | N10: 0.002945681 | O10: 0 | P10: 5.2967855 | Q10: 94.703215 | R10: 20.310269 | S10: 58.510164 | T10: 21.179567 | U10: 0 | V10: 79.689731 | W10: 0.22501888 | X10: -48.570595 | Y10: 115.09047 | Z10: 100 | AA10: 38.352194 | AB10: 289.4268 | AC10: 287.55602 | AD10: 52.383397 | AE10: 298.51666 | AF10: 3.4339385 | AG10: 783.44654 | AH10: 2.8130345 | AI10: 61.852499 | AJ10: 170.35149 | AK10: 27.509017 | AL10: -22.744598 | AM10: 9.7287096 | AN10: 50.159685 | AO10: 0.9 | AP10: 1.2902008 | AQ10: 1.25 | AR10: 1.2725713 | AS10: 1.007465 | AT10: 0.8698994 | AU10: 0.83308615 | AV10: 1 | AW10: 1.0043012 | AX10: 1 | AY10: 1 | AZ10: 0.89640335 | BA10: 1 | BB10: 1.0028872 | BC10: 5.9253522e+10 | BD10: 0.07611461 | BE10: 9118
A11: 31 | B11: 11 | C11: 60 | D11: 0.66436961 | E11: 0.62812469 | F11: 7.6874758 | G11: 7.2824753 | H11: 1.0577034 | I11: -0.036244917 | J11: 0.056039368 | K11: 0.011025731 | L11: 0.010150252 | M11: 0.54639567 | N11: 0.0045136726 | O11: 0 | P11: 4.714045 | Q11: 95.285955 | R11: 20.176637 | S11: 60.714009 | T11: 19.109354 | U11: 0 | V11: 79.823363 | W11: 0.31579218 | X11: -49.537354 | Y11: 260.95924 | Z11: 100 | AA11: 34.744158 | AB11: 284.18343 | AC11: 282.34785 | AD11: 60.88111 | AE11: 288.87618 | AF11: 3.5090458 | AG11: 784.33837 | AH11: 3.9138846 | AI11: 59.859471 | AJ11: 177.16525 | AK11: 24.138753 | AL11: -22.036875 | AM11: 9.5831937 | AN11: 59.488197 | AO11: 0.9 | AP11: 1.2902007 | AQ11: 1.25 | AR11: 1.2559156 | AS11: 1.0075915 | AT11: 0.87573184 | AU11: 0.8313026 | AV11: 1 | AW11: 1.0054733 | AX11: 1 | AY11: 1 | AZ11: 0.89622963 | BA11: 1 | BB11: 0.99694247 | BC11: 1.7011229e+11 | BD11: 0.073496056 | BE11: 28099
G15: 1
D16: wala | E16: bal | F16: =D1 -> actual.smm | G16: =E1 -> model.smm | H16: ratio | J16: Prod Knots | K16: Ratio | L16: Dev Knots | M16: =K1 -> dflt.smm | N16: Ratio
C17: 0 | J17: 0.16 | L17: 0.71
C18: =C2 -> 6 | D18: =AD2 -> 3.7304316 | E18: =BC2/1000000000 -> 50.589889 | F18: =D2 -> 0.38462635 | G18: =J2+K2+L2+M2*$G$15+N2 -> 0.20205797 | H18: =F18/G18 -> 1.9035446 | J18: 0.5 | K18: 1.7 | L18: =J18*K18 -> 0.85 | M18: =J2+K2+L2+M2*$K18+N2 -> 0.31966801 | N18: =F18/M18 -> 1.2032056
C19: =C3 -> 12 | D19: =AD3 -> 8.6302402 | E19: =BC3/1000000000 -> 102.89758 | F19: =D3 -> 0.49770443 | G19: =J3+K3+L3+M3*$G$15+N3 -> 0.40808263 | H19: =F19/G19 -> 1.2196168 | J19: 1.02 | K19: 1.05 | L19: =J19*K19 -> 1.071 | M19: =J3+K3+L3+M3*$K19+N3 -> 0.4262022 | N19: =F19/M19 -> 1.167766
C20: =C4 -> 18 | D20: =AD4 -> 15.246028 | E20: =BC4/1000000000 -> 94.625076 | F20: =D4 -> 0.55280088 | G20: =J4+K4+L4+M4*$G$15+N4 -> 0.54727232 | H20: =F20/G20 -> 1.010102 | J20: 1.25 | K20: 1 | L20: =J20*K20 -> 1.25 | M20: =J4+K4+L4+M4*$K20+N4 -> 0.54727232 | N20: =F20/M20 -> 1.010102
C21: =C5 -> 24 | D21: =AD5 -> 22.082832 | E21: =BC5/1000000000 -> 38.77021 | F21: =D5 -> 0.68886581 | G21: =J5+K5+L5+M5*$G$15+N5 -> 0.62498096 | H21: =F21/G21 -> 1.1022189 | J21: 1.25 | K21: 1 | L21: =J21*K21 -> 1.25 | M21: =J5+K5+L5+M5*$K21+N5 -> 0.62498096 | N21: =F21/M21 -> 1.1022189
C22: =C6 -> 30 | D22: =AD6 -> 25.757285 | E22: =BC6/1000000000 -> 20.238524 | F22: =D6 -> 0.8153367 | G22: =J6+K6+L6+M6*$G$15+N6 -> 0.69492679 | H22: =F22/G22 -> 1.1732699 | J22: 1.25 | K22: 1 | L22: =J22*K22 -> 1.25 | M22: =J6+K6+L6+M6*$K22+N6 -> 0.69492679 | N22: =F22/M22 -> 1.1732699
C23: =C7 -> 36 | D23: =AD7 -> 34.377749 | E23: =BC7/1000000000 -> 15.442061 | F23: =D7 -> 0.85457469 | G23: =J7+K7+L7+M7*$G$15+N7 -> 0.6726589 | H23: =F23/G23 -> 1.2704428 | J23: 1.25 | K23: 1 | L23: =J23*K23 -> 1.25 | M23: =J7+K7+L7+M7*$K23+N7 -> 0.6726589 | N23: =F23/M23 -> 1.2704428
C24: =C8 -> 42 | D24: =AD8 -> 37.483146 | E24: =BC8/1000000000 -> 9.7206294 | F24: =D8 -> 0.78698549 | G24: =J8+K8+L8+M8*$G$15+N8 -> 0.64317808 | H24: =F24/G24 -> 1.2235888 | J24: 1.25 | K24: 1 | L24: =J24*K24 -> 1.25 | M24: =J8+K8+L8+M8*$K24+N8 -> 0.64317808 | N24: =F24/M24 -> 1.2235888
D30: HPA 11 | E30: HPA 5
C31: =C18 -> 6 | D31: ='HPA 11 Fit'!L17 -> 0.71 | E31: ='HPA 5 Fit'!L18 -> 0.71
C32: =C19 -> 12 | D32: ='HPA 11 Fit'!L18 -> 0.85 | E32: ='HPA 5 Fit'!L19 -> 0.71
C33: =C20 -> 18 | D33: ='HPA 11 Fit'!L19 -> 1.071 | E33: ='HPA 5 Fit'!L20 -> 0.714
C34: =C21 -> 24 | D34: ='HPA 11 Fit'!L20 -> 1.25 | E34: ='HPA 5 Fit'!L21 -> 0.85
C35: =C22 -> 30 | D35: ='HPA 11 Fit'!L21 -> 1.25 | E35: ='HPA 5 Fit'!L22 -> 1.1
C36: =C23 -> 36 | D36: ='HPA 11 Fit'!L22 -> 1.25 | E36: ='HPA 5 Fit'!L23 -> 1.1125
C37: =C24 -> 42 | D37: ='HPA 11 Fit'!L23 -> 1.25 | E37: ='HPA 5 Fit'!L24 -> 1.2375
