Workbook

Sheet Housing Stock
A1: Table with row headings in Column A and column headings are in rows 5, 26, 47, 68, 89, 110, and 131. Leading dots indicate sub-parts.
A2: Table 7. Estimates of the Total Housing Inventory for the United States: 1965 to Present
A3: (Numbers in thousands)
B5: 1965 | C5: 1966 | D5: 1967 | E5: 1968 | F5: 1969 | G5: 1970 | H5: 1971 | I5: 1972 | L5: 1999 | M5: 70097 | P5: 1999 | Q5: =VLOOKUP(P5,L:M,2,0) -> 70097 | R5: 1 | S5: =(R5-1)*(Q17-Q5)/12+Q5 -> 70097
L6: 2000 | M6: 71250 | P6: =IF(R6>1,P5,P5+2) -> 1999 | Q6: =VLOOKUP(P6,L:M,2,0) -> 70097 | R6: 2 | S6: =(R6-1)*(Q18-Q6)/12+Q6 -> 70193.083
A7: All housing units | B7: 64213 | C7: 65212 | D7: 66014 | E7: 67171 | F7: 68479 | G7: 69778 | H7: 71320 | I7: 73313 | L7: 2001 | M7: 72593 | P7: =IF(R7>1,P6,P6+2) -> 1999 | Q7: =VLOOKUP(P7,L:M,2,0) -> 70097 | R7: 3 | S7: =(R7-1)*(Q19-Q7)/12+Q7 -> 70289.167
L8: 2002 | M8: 73713 | P8: =IF(R8>1,P7,P7+2) -> 1999 | Q8: =VLOOKUP(P8,L:M,2,0) -> 70097 | R8: 4 | S8: =(R8-1)*(Q20-Q8)/12+Q8 -> 70385.25
A9: ..Vacant | B9: 6712 | C9: 6726 | D9: 6538 | E9: 6218 | F9: 6218 | G9: 6137 | H9: 6238 | I9: 6368 | L9: 2003 | M9: 71278 | P9: =IF(R9>1,P8,P8+2) -> 1999 | Q9: =VLOOKUP(P9,L:M,2,0) -> 70097 | R9: 5 | S9: =(R9-1)*(Q21-Q9)/12+Q9 -> 70481.333
A10: ….Year-round vacant | B10: 4853 | C10: 4909 | D10: 4762 | E10: 4446 | F10: 4437 | G10: 4391 | H10: 4559 | I10: 4665 | L10: 2004 | M10: 72054 | P10: =IF(R10>1,P9,P9+2) -> 1999 | Q10: =VLOOKUP(P10,L:M,2,0) -> 70097 | R10: 6 | S10: =(R10-1)*(Q22-Q10)/12+Q10 -> 70577.417
A11: …...For rent | B11: 1884 | C11: 1778 | D11: 1566 | E11: 1392 | F11: 1296 | G11: 1299 | H11: 1353 | I11: 1421 | L11: 2005 | M11: 73575 | P11: =IF(R11>1,P10,P10+2) -> 1999 | Q11: =VLOOKUP(P11,L:M,2,0) -> 70097 | R11: 7 | S11: =(R11-1)*(Q23-Q11)/12+Q11 -> 70673.5
A12: …...For sale only | B12: 548 | C12: 522 | D12: 499 | E12: 439 | F12: 408 | G12: 427 | H12: 422 | I12: 432 | L12: 2006 | M12: 74553 | P12: =IF(R12>1,P11,P11+2) -> 1999 | Q12: =VLOOKUP(P12,L:M,2,0) -> 70097 | R12: 8 | S12: =(R12-1)*(Q24-Q12)/12+Q12 -> 70769.583
A13: …...Rented or sold | B13: 330 | C13: 349 | D13: 348 | E13: 389 | F13: 402 | G13: 427 | H13: 478 | I13: 516 | L13: 2007 | M13: 75380 | P13: =IF(R13>1,P12,P12+2) -> 1999 | Q13: =VLOOKUP(P13,L:M,2,0) -> 70097 | R13: 9 | S13: =(R13-1)*(Q25-Q13)/12+Q13 -> 70865.667
A14: …...Held off market | B14: 2092 | C14: 2261 | D14: 2349 | E14: 2227 | F14: 2332 | G14: 2238 | H14: 2307 | I14: 2297 | L14: 2008 | M14: 75159 | P14: =IF(R14>1,P13,P13+2) -> 1999 | Q14: =VLOOKUP(P14,L:M,2,0) -> 70097 | R14: 10 | S14: =(R14-1)*(Q26-Q14)/12+Q14 -> 70961.75
A15: ……...Occasional use | B15: 504 | C15: 546 | D15: 571 | E15: 551 | F15: 619 | G15: 615 | H15: 652 | I15: 642 | L15: 2009 | M15: 75566 | P15: =IF(R15>1,P14,P14+2) -> 1999 | Q15: =VLOOKUP(P15,L:M,2,0) -> 70097 | R15: 11 | S15: =(R15-1)*(Q27-Q15)/12+Q15 -> 71057.833
A16: ……...URE | B16: 379 | C16: 434 | D16: 460 | E16: 438 | F16: 454 | G16: 429 | H16: 416 | I16: 419 | L16: 2010 | M16: 75014 | P16: =IF(R16>1,P15,P15+2) -> 1999 | Q16: =VLOOKUP(P16,L:M,2,0) -> 70097 | R16: 12 | S16: =(R16-1)*(Q28-Q16)/12+Q16 -> 71153.917
A17: ……...Other | B17: 1209 | C17: 1280 | D17: 1318 | E17: 1238 | F17: 1258 | G17: 1195 | H17: 1239 | I17: 1237 | L17: 2011 | M17: 74791 | P17: =IF(R17>1,P16,P16+1) -> 2000 | Q17: =VLOOKUP(P17,L:M,2,0) -> 71250 | R17: 1 | S17: =(R17-1)*(Q29-Q17)/12+Q17 -> 71250
L18: 2012 | M18: 75091 | P18: =IF(R18>1,P17,P17+1) -> 2000 | Q18: =VLOOKUP(P18,L:M,2,0) -> 71250 | R18: 2 | S18: =(R18-1)*(Q30-Q18)/12+Q18 -> 71361.917
A19: ….Seasonal | B19: 1860 | C19: 1817 | D19: 1776 | E19: 1772 | F19: 1782 | G19: 1746 | H19: 1680 | I19: 1703 | L19: 2013 | M19: 74668 | P19: =IF(R19>1,P18,P18+1) -> 2000 | Q19: =VLOOKUP(P19,L:M,2,0) -> 71250 | R19: 3 | S19: =(R19-1)*(Q31-Q19)/12+Q19 -> 71473.833
L20: 2014 | M20: 74427 | P20: =IF(R20>1,P19,P19+1) -> 2000 | Q20: =VLOOKUP(P20,L:M,2,0) -> 71250 | R20: 4 | S20: =(R20-1)*(Q32-Q20)/12+Q20 -> 71585.75
A21: ..Total occupied | B21: 57501 | C21: 58486 | D21: 59476 | E21: 60952 | F21: 62261 | G21: 63640 | H21: 65081 | I21: 66945 | L21: 2015 | M21: 74706 | P21: =IF(R21>1,P20,P20+1) -> 2000 | Q21: =VLOOKUP(P21,L:M,2,0) -> 71250 | R21: 5 | S21: =(R21-1)*(Q33-Q21)/12+Q21 -> 71697.667
A22: ….Owner | B22: 36230 | C22: 37109 | D22: 37842 | E22: 38918 | F22: 40049 | G22: 40834 | H22: 41816 | I22: 43096 | L22: 2016 | M22: =M21+400 -> 75106 | P22: =IF(R22>1,P21,P21+1) -> 2000 | Q22: =VLOOKUP(P22,L:M,2,0) -> 71250 | R22: 6 | S22: =(R22-1)*(Q34-Q22)/12+Q22 -> 71809.583
A23: ….Renter | B23: 21271 | C23: 21377 | D23: 21634 | E23: 22034 | F23: 22211 | G23: 22806 | H23: 23266 | I23: 23849 | L23: 2017 | M23: 75000 | P23: =IF(R23>1,P22,P22+1) -> 2000 | Q23: =VLOOKUP(P23,L:M,2,0) -> 71250 | R23: 7 | S23: =(R23-1)*(Q35-Q23)/12+Q23 -> 71921.5
L24: 2018 | M24: 75000 | P24: =IF(R24>1,P23,P23+1) -> 2000 | Q24: =VLOOKUP(P24,L:M,2,0) -> 71250 | R24: 8 | S24: =(R24-1)*(Q36-Q24)/12+Q24 -> 72033.417
P25: =IF(R25>1,P24,P24+1) -> 2000 | Q25: =VLOOKUP(P25,L:M,2,0) -> 71250 | R25: 9 | S25: =(R25-1)*(Q37-Q25)/12+Q25 -> 72145.333
B26: 1973 | C26: 1974 | D26: 1975 | E26: 1976 | F26: 1977 | G26: 1978 | H26: 1979 | I26: 1979\r1 | P26: =IF(R26>1,P25,P25+1) -> 2000 | Q26: =VLOOKUP(P26,L:M,2,0) -> 71250 | R26: 10 | S26: =(R26-1)*(Q38-Q26)/12+Q26 -> 72257.25
P27: =IF(R27>1,P26,P26+1) -> 2000 | Q27: =VLOOKUP(P27,L:M,2,0) -> 71250 | R27: 11 | S27: =(R27-1)*(Q39-Q27)/12+Q27 -> 72369.167
A28: All housing units | B28: 75407 | C28: 77462 | D28: 78821 | E28: 80189 | F28: 81645 | G28: 83496 | H28: 85061 | I28: 85735 | P28: =IF(R28>1,P27,P27+1) -> 2000 | Q28: =VLOOKUP(P28,L:M,2,0) -> 71250 | R28: 12 | S28: =(R28-1)*(Q40-Q28)/12+Q28 -> 72481.083
P29: =IF(R29>1,P28,P28+1) -> 2001 | Q29: =VLOOKUP(P29,L:M,2,0) -> 72593 | R29: 1 | S29: =(R29-1)*(Q41-Q29)/12+Q29 -> 72593
A30: ..Vacant | B30: 6558 | C30: 6904 | D30: 6896 | E30: 6774 | F30: 6861 | G30: 6948 | H30: 7129 | I30: 7589 | P30: =IF(R30>1,P29,P29+1) -> 2001 | Q30: =VLOOKUP(P30,L:M,2,0) -> 72593 | R30: 2 | S30: =(R30-1)*(Q42-Q30)/12+Q30 -> 72686.333
A31: ….Year-round vacant | B31: 4851 | C31: 5155 | D31: 5202 | E31: 5190 | F31: 5224 | G31: 5260 | H31: 5415 | I31: 5893 | P31: =IF(R31>1,P30,P30+1) -> 2001 | Q31: =VLOOKUP(P31,L:M,2,0) -> 72593 | R31: 3 | S31: =(R31-1)*(Q43-Q31)/12+Q31 -> 72779.667
A32: …...For rent | B32: 1521 | C32: 1661 | D32: 1647 | E32: 1546 | F32: 1472 | G32: 1433 | H32: 1431 | I32: 1579 | P32: =IF(R32>1,P31,P31+1) -> 2001 | Q32: =VLOOKUP(P32,L:M,2,0) -> 72593 | R32: 4 | S32: =(R32-1)*(Q44-Q32)/12+Q32 -> 72873
A33: …...For sale only | B33: 467 | C33: 557 | D33: 591 | E33: 598 | F33: 574 | G33: 524 | H33: 566 | I33: 607 | P33: =IF(R33>1,P32,P32+1) -> 2001 | Q33: =VLOOKUP(P33,L:M,2,0) -> 72593 | R33: 5 | S33: =(R33-1)*(Q45-Q33)/12+Q33 -> 72966.333
A34: …...Rented or sold | B34: 524 | C34: 543 | D34: 536 | E34: 564 | F34: 651 | G34: 650 | H34: 640 | I34: 705 | P34: =IF(R34>1,P33,P33+1) -> 2001 | Q34: =VLOOKUP(P34,L:M,2,0) -> 72593 | R34: 6 | S34: =(R34-1)*(Q46-Q34)/12+Q34 -> 73059.667
A35: …...Held off market | B35: 2340 | C35: 2393 | D35: 2429 | E35: 2482 | F35: 2528 | G35: 2653 | H35: 2778 | I35: 3003 | P35: =IF(R35>1,P34,P34+1) -> 2001 | Q35: =VLOOKUP(P35,L:M,2,0) -> 72593 | R35: 7 | S35: =(R35-1)*(Q47-Q35)/12+Q35 -> 73153
A36: ……...Occasional use | B36: 588 | C36: 617 | D36: 649 | E36: 705 | F36: 707 | G36: 689 | H36: 710 | I36: 794 | P36: =IF(R36>1,P35,P35+1) -> 2001 | Q36: =VLOOKUP(P36,L:M,2,0) -> 72593 | R36: 8 | S36: =(R36-1)*(Q48-Q36)/12+Q36 -> 73246.333
A37: ……...URE | B37: 433 | C37: 452 | D37: 470 | E37: 467 | F37: 438 | G37: 467 | H37: 541 | I37: 591 | P37: =IF(R37>1,P36,P36+1) -> 2001 | Q37: =VLOOKUP(P37,L:M,2,0) -> 72593 | R37: 9 | S37: =(R37-1)*(Q49-Q37)/12+Q37 -> 73339.667
A38: ……...Other | B38: 1320 | C38: 1325 | D38: 1309 | E38: 1310 | F38: 1383 | G38: 1498 | H38: 1528 | I38: 1618 | P38: =IF(R38>1,P37,P37+1) -> 2001 | Q38: =VLOOKUP(P38,L:M,2,0) -> 72593 | R38: 10 | S38: =(R38-1)*(Q50-Q38)/12+Q38 -> 73433
P39: =IF(R39>1,P38,P38+1) -> 2001 | Q39: =VLOOKUP(P39,L:M,2,0) -> 72593 | R39: 11 | S39: =(R39-1)*(Q51-Q39)/12+Q39 -> 73526.333
A40: ….Seasonal | B40: 1706 | C40: 1750 | D40: 1694 | E40: 1584 | F40: 1637 | G40: 1688 | H40: 1714 | I40: 1696 | P40: =IF(R40>1,P39,P39+1) -> 2001 | Q40: =VLOOKUP(P40,L:M,2,0) -> 72593 | R40: 12 | S40: =(R40-1)*(Q52-Q40)/12+Q40 -> 73619.667
P41: =IF(R41>1,P40,P40+1) -> 2002 | Q41: =VLOOKUP(P41,L:M,2,0) -> 73713 | R41: 1 | S41: =(R41-1)*(Q53-Q41)/12+Q41 -> 73713
...

Sheet EHS
A1: Security | B1: ETSLTOTL Index | D1: Seasonally adjusted annual rate
A2: Start Date | B2: 36191
A3: End Date | B3: 42429
A4: Period | B4: M
A6: Date | B6: PX_LAST | C6: FIRST_REVISION
A7: =_xll.BDH(B1,B6:C6,B2,B3,"Dir=V","Dts=S","Sort=D","Quote=C","QtTyp=P","Days=T",CONCATENATE("Per=c",B4),"DtFmt=D","UseDPDF=Y","cols=3;rows=206") -> #NAME? | B7: 5.08 | C7: #N/A N/A
A8: 42400 | B8: 5.47 | C8: #N/A N/A
A9: 42369 | B9: 5.45 | C9: 5.45
A10: 42338 | B10: 4.86 | C10: #N/A N/A
A11: 42308 | B11: 5.29 | C11: 5.32
A12: 42277 | B12: 5.44 | C12: #N/A N/A
A13: 42247 | B13: 5.29 | C13: 5.3
A14: 42216 | B14: 5.48 | C14: 5.58
A15: 42185 | B15: 5.41 | C15: 5.48
A16: 42155 | B16: 5.29 | C16: 5.32
A17: 42124 | B17: 5.14 | C17: 5.09
A18: 42094 | B18: 5.25 | C18: 5.21
A19: 42063 | B19: 4.97 | C19: 4.89
A20: 42035 | B20: 4.93 | C20: #N/A N/A
A21: 42004 | B21: 5.07 | C21: 5.07
A22: 41973 | B22: 5.04 | C22: 4.92
A23: 41943 | B23: 5.14 | C23: 5.25
A24: 41912 | B24: 5.03 | C24: 5.18
A25: 41882 | B25: 4.96 | C25: #N/A N/A
A26: 41851 | B26: 4.99 | C26: 5.14
A27: 41820 | B27: 4.97 | C27: 5.03
A28: 41790 | B28: 4.9 | C28: 4.91
A29: 41759 | B29: 4.78 | C29: 4.66
A30: 41729 | B30: 4.74 | C30: #N/A N/A
A31: 41698 | B31: 4.72 | C31: #N/A N/A
A32: 41670 | B32: 4.74 | C32: #N/A N/A
A33: 41639 | B33: 4.86 | C33: #N/A N/A
A34: 41608 | B34: 4.92 | C34: 4.82
A35: 41578 | B35: 5.04 | C35: #N/A N/A
A36: 41547 | B36: 5.14 | C36: #N/A N/A
A37: 41517 | B37: 5.26 | C37: 5.39
A38: 41486 | B38: 5.27 | C38: #N/A N/A
A39: 41455 | B39: 5.11 | C39: 5.06
A40: 41425 | B40: 5.14 | C40: 5.14
A41: 41394 | B41: 5.09 | C41: #N/A N/A
...

Sheet Turnover EHS
B1: Existing Home Sale(M) | C1: Housing Stock(K) | D1: Turnover EHS | E1: OTM Turnover MBS | F1: OTM Turnover MBS- 6m ma | G1: Diff | H1: OTM Refi * 3
A2: 36191 | B2: 5.23 | C2: ='Housing Stock'!S5 -> 70097 | D2: =B2/C2*1000 -> 0.074610896 | E2: ='OTM Turnover MBS'!C57/100 -> 0.024263375 | G2: =D2-E2 -> 0.050347521 | H2: ='OTM Refi'!B57/100*3 -> 0
A3: 36219 | B3: 5.1 | C3: ='Housing Stock'!S6 -> 70193.083 | D3: =B3/C3*1000 -> 0.072656731 | E3: ='OTM Turnover MBS'!C58/100 -> 0.025644127 | G3: =D3-E3 -> 0.047012604 | H3: ='OTM Refi'!B58/100*3 -> 0
A4: 36250 | B4: 5.15 | C4: ='Housing Stock'!S7 -> 70289.167 | D4: =B4/C4*1000 -> 0.073268759 | E4: ='OTM Turnover MBS'!C59/100 -> 0.0209915 | G4: =D4-E4 -> 0.052277259 | H4: ='OTM Refi'!B59/100*3 -> 0
A5: 36280 | B5: 5.08 | C5: ='Housing Stock'!S8 -> 70385.25 | D5: =B5/C5*1000 -> 0.072174213 | E5: ='OTM Turnover MBS'!C60/100 -> 0.029760818 | G5: =D5-E5 -> 0.042413395 | H5: ='OTM Refi'!B60/100*3 -> 0.00037754991
A6: 36311 | B6: 5.19 | C6: ='Housing Stock'!S9 -> 70481.333 | D6: =B6/C6*1000 -> 0.073636518 | E6: ='OTM Turnover MBS'!C61/100 -> 0.022461584 | G6: =D6-E6 -> 0.051174935 | H6: ='OTM Refi'!B61/100*3 -> 0.00091803033
A7: 36341 | B7: 5.43 | C7: ='Housing Stock'!S10 -> 70577.417 | D7: =B7/C7*1000 -> 0.076936792 | E7: ='OTM Turnover MBS'!C62/100 -> 0.032910223 | F7: =AVERAGE(E5:E7) -> 0.028377542 | G7: =D7-F7 -> 0.04855925 | H7: ='OTM Refi'!B62/100*3 -> 0.0014041312
A8: 36372 | B8: 5.25 | C8: ='Housing Stock'!S11 -> 70673.5 | D8: =B8/C8*1000 -> 0.07428527 | E8: ='OTM Turnover MBS'!C63/100 -> 0.056656474 | F8: =AVERAGE(E3:E8) -> 0.031404121 | G8: =D8-F8 -> 0.042881148 | H8: ='OTM Refi'!B63/100*3 -> 0.0012218846
A9: 36403 | B9: 5.23 | C9: ='Housing Stock'!S12 -> 70769.583 | D9: =B9/C9*1000 -> 0.073901806 | E9: ='OTM Turnover MBS'!C64/100 -> 0.052260865 | F9: =AVERAGE(E4:E9) -> 0.035840244 | G9: =D9-F9 -> 0.038061562 | H9: ='OTM Refi'!B64/100*3 -> 0.001205011
A10: 36433 | B10: 5.12 | C10: ='Housing Stock'!S13 -> 70865.667 | D10: =B10/C10*1000 -> 0.072249373 | E10: ='OTM Turnover MBS'!C65/100 -> 0.067444859 | F10: =AVERAGE(E5:E10) -> 0.043582471 | G10: =D10-F10 -> 0.028666903 | H10: ='OTM Refi'!B65/100*3 -> 0.00096084334
A11: 36464 | B11: 5.11 | C11: ='Housing Stock'!S14 -> 70961.75 | D11: =B11/C11*1000 -> 0.072010625 | E11: ='OTM Turnover MBS'!C66/100 -> 0.055302774 | F11: =AVERAGE(E6:E11) -> 0.047839463 | G11: =D11-F11 -> 0.024171162 | H11: ='OTM Refi'!B66/100*3 -> 0.0008792166
A12: 36494 | B12: 5.09 | C12: ='Housing Stock'!S15 -> 71057.833 | D12: =B12/C12*1000 -> 0.071631793 | E12: ='OTM Turnover MBS'!C67/100 -> 0.059474906 | F12: =AVERAGE(E7:E12) -> 0.05400835 | G12: =D12-F12 -> 0.017623443 | H12: ='OTM Refi'!B67/100*3 -> 0.00064960917
A13: 36525 | B13: 5.08 | C13: ='Housing Stock'!S16 -> 71153.917 | D13: =B13/C13*1000 -> 0.071394524 | E13: ='OTM Turnover MBS'!C68/100 -> 0.05817003 | F13: =AVERAGE(E8:E13) -> 0.058218318 | G13: =D13-F13 -> 0.013176206 | H13: ='OTM Refi'!B68/100*3 -> 0.00050638984
A14: 36556 | B14: 5.23 | C14: ='Housing Stock'!S17 -> 71250 | D14: =B14/C14*1000 -> 0.073403509 | E14: ='OTM Turnover MBS'!C69/100 -> 0.064966066 | F14: =AVERAGE(E9:E14) -> 0.05960325 | G14: =D14-F14 -> 0.013800259 | H14: ='OTM Refi'!B69/100*3 -> 0.00075124767
A15: 36585 | B15: 5.12 | C15: ='Housing Stock'!S18 -> 71361.917 | D15: =B15/C15*1000 -> 0.071746952 | E15: ='OTM Turnover MBS'!C70/100 -> 0.062111102 | F15: =AVERAGE(E10:E15) -> 0.061244956 | G15: =D15-F15 -> 0.010501996 | H15: ='OTM Refi'!B70/100*3 -> 0.0007538995
A16: 36616 | B16: 5.19 | C16: ='Housing Stock'!S19 -> 71473.833 | D16: =B16/C16*1000 -> 0.072613987 | E16: ='OTM Turnover MBS'!C71/100 -> 0.059012155 | F16: =AVERAGE(E11:E16) -> 0.059839506 | G16: =D16-F16 -> 0.012774481 | H16: ='OTM Refi'!B71/100*3 -> 0.00085630358
A17: 36646 | B17: 5.2 | C17: ='Housing Stock'!S20 -> 71585.75 | D17: =B17/C17*1000 -> 0.072640155 | E17: ='OTM Turnover MBS'!C72/100 -> 0.062799266 | F17: =AVERAGE(E12:E17) -> 0.061088921 | G17: =D17-F17 -> 0.011551234 | H17: ='OTM Refi'!B72/100*3 -> 0.0012932355
A18: 36677 | B18: 5.11 | C18: ='Housing Stock'!S21 -> 71697.667 | D18: =B18/C18*1000 -> 0.071271497 | E18: ='OTM Turnover MBS'!C73/100 -> 0.060251888 | F18: =AVERAGE(E13:E18) -> 0.061218418 | G18: =D18-F18 -> 0.010053078 | H18: ='OTM Refi'!B73/100*3 -> 0.0018200146
A19: 36707 | B19: 5.13 | C19: ='Housing Stock'!S22 -> 71809.583 | D19: =B19/C19*1000 -> 0.071438933 | E19: ='OTM Turnover MBS'!C74/100 -> 0.069298497 | F19: =AVERAGE(E14:E19) -> 0.063073162 | G19: =D19-F19 -> 0.0083657704 | H19: ='OTM Refi'!B74/100*3 -> 0.001424066
... A60: 37955 | B60: 6.23 | C60: ='Housing Stock'!S63 -> 71924.667 | D60: =B60/C60*1000 -> 0.086618406 | E60: ='OTM Turnover MBS'!C115/100 -> 0.028194274 | F60: =AVERAGE(E55:E60) -> 0.026730532 | G60: =D60-F60 -> 0.059887874 | H60: ='OTM Refi'!B115/100*3 -> 0.008919175
A61: 37986 | B61: 6.49 | C61: ='Housing Stock'!S64 -> 71989.333 | D61: =B61/C61*1000 -> 0.090152245 | E61: ='OTM Turnover MBS'!C116/100 -> 0.031053751 | F61: =AVERAGE(E56:E61) -> 0.031703638 | G61: =D61-F61 -> 0.058448607 | H61: ='OTM Refi'!B116/100*3 -> 0.01054325 | J61: 0.01
A62: 38017 | B62: 6.23 | C62: ='Housing Stock'!S65 -> 72054 | D62: =B62/C62*1000 -> 0.086462931 | E62: ='OTM Turnover MBS'!C117/100 -> 0.036707043 | F62: =AVERAGE(E57:E62) -> 0.037821478 | G62: =D62-F62 -> 0.048641452 | H62: ='OTM Refi'!B117/100*3 -> 0.01083052 | J62: =1-(1-J61)^(1/12) -> 0.00083717736
A63: 38046 | B63: 6.41 | C63: ='Housing Stock'!S66 -> 72180.75 | D63: =B63/C63*1000 -> 0.088804841 | E63: ='OTM Turnover MBS'!C118/100 -> 0.035604696 | F63: =AVERAGE(E58:E63) -> 0.041134434 | G63: =D63-F63 -> 0.047670407 | H63: ='OTM Refi'!B118/100*3 -> 0.011273158
A64: 38077 | B64: 6.66 | C64: ='Housing Stock'!S67 -> 72307.5 | D64: =B64/C64*1000 -> 0.092106628 | E64: ='OTM Turnover MBS'!C119/100 -> 0.044805894 | F64: =AVERAGE(E59:E64) -> 0.035050546 | G64: =D64-F64 -> 0.057056082 | H64: ='OTM Refi'!B119/100*3 -> 0.011646262
A65: 38107 | B65: 6.73 | C65: ='Housing Stock'!S68 -> 72434.25 | D65: =B65/C65*1000 -> 0.092911848 | E65: ='OTM Turnover MBS'!C120/100 -> 0.04676644 | F65: =AVERAGE(E60:E65) -> 0.037188683 | G65: =D65-F65 -> 0.055723165 | H65: ='OTM Refi'!B120/100*3 -> 0.013470849
A66: 38138 | B66: 6.85 | C66: ='Housing Stock'!S69 -> 72561 | D66: =B66/C66*1000 -> 0.09440333 | E66: ='OTM Turnover MBS'!C121/100 -> 0.067252951 | F66: =AVERAGE(E61:E66) -> 0.043698462 | G66: =D66-F66 -> 0.050704867 | H66: ='OTM Refi'!B121/100*3 -> 0.01273114
A67: 38168 | B67: 6.92 | C67: ='Housing Stock'!S70 -> 72687.75 | D67: =B67/C67*1000 -> 0.095201736 | E67: ='OTM Turnover MBS'!C122/100 -> 0.078936077 | F67: =AVERAGE(E62:E67) -> 0.05167885 | G67: =D67-F67 -> 0.043522886 | H67: ='OTM Refi'!B122/100*3 -> 0.011535985
A68: 38199 | B68: 6.84 | C68: ='Housing Stock'!S71 -> 72814.5 | D68: =B68/C68*1000 -> 0.093937334 | E68: ='OTM Turnover MBS'!C123/100 -> 0.071092295 | F68: =AVERAGE(E63:E68) -> 0.057409725 | G68: =D68-F68 -> 0.036527608 | H68: ='OTM Refi'!B123/100*3 -> 0.013235107
A69: 38230 | B69: 6.7 | C69: ='Housing Stock'!S72 -> 72941.25 | D69: =B69/C69*1000 -> 0.091854746 | E69: ='OTM Turnover MBS'!C124/100 -> 0.063286757 | F69: =AVERAGE(E64:E69) -> 0.062023402 | G69: =D69-F69 -> 0.029831344 | H69: ='OTM Refi'!B124/100*3 -> 0.016550796
A70: 38260 | B70: 6.68 | C70: ='Housing Stock'!S73 -> 73068 | D70: =B70/C70*1000 -> 0.091421689 | E70: ='OTM Turnover MBS'!C125/100 -> 0.071177051 | F70: =AVERAGE(E65:E70) -> 0.066418595 | G70: =D70-F70 -> 0.025003094 | H70: ='OTM Refi'!B125/100*3 -> 0.019465952
A71: 38291 | B71: 6.85 | C71: ='Housing Stock'!S74 -> 73194.75 | D71: =B71/C71*1000 -> 0.093585947 | E71: ='OTM Turnover MBS'!C126/100 -> 0.066572516 | F71: =AVERAGE(E66:E71) -> 0.069719608 | G71: =D71-F71 -> 0.023866339 | H71: ='OTM Refi'!B126/100*3 -> 0.020578175
A72: 38321 | B72: 6.96 | C72: ='Housing Stock'!S75 -> 73321.5 | D72: =B72/C72*1000 -> 0.094924408 | E72: ='OTM Turnover MBS'!C127/100 -> 0.078037302 | F72: =AVERAGE(E67:E72) -> 0.071517 | G72: =D72-F72 -> 0.023407408 | H72: ='OTM Refi'!B127/100*3 -> 0.021056302
A73: 38352 | B73: 6.89 | C73: ='Housing Stock'!S76 -> 73448.25 | D73: =B73/C73*1000 -> 0.093807545 | E73: ='OTM Turnover MBS'!C128/100 -> 0.084012087 | F73: =AVERAGE(E68:E73) -> 0.072363001 | G73: =D73-F73 -> 0.021444543 | H73: ='OTM Refi'!B128/100*3 -> 0.021816546
A74: 38383 | B74: 7.1 | C74: ='Housing Stock'!S77 -> 73575 | D74: =B74/C74*1000 -> 0.09650017 | E74: ='OTM Turnover MBS'!C129/100 -> 0.078062566 | F74: =AVERAGE(E69:E74) -> 0.073524713 | G74: =D74-F74 -> 0.022975457 | H74: ='OTM Refi'!B129/100*3 -> 0.022868134
... A205: 42369 | B205: 5.45 | C205: ='Housing Stock'!S208 -> 75072.667 | D205: =B205/C205*1000 -> 0.072596329 | E205: ='OTM Turnover MBS'!C260/100 -> 0.039071189 | F205: =AVERAGE(E200:E205) -> 0.03795772 | G205: =D205-F205 -> 0.034638609 | H205: ='OTM Refi'!B260/100*3 -> 0.0032527388
A206: 42400 | B206: 5.48 | C206: ='Housing Stock'!S209 -> 75106 | D206: =B206/C206*1000 -> 0.072963545
A207: 42429 | B207: 5.2 | C207: ='Housing Stock'!S210 -> 75097.167 | D207: =B207/C207*1000 -> 0.069243624
A208: 42460 | B208: 5.39 | C208: ='Housing Stock'!S211 -> 75088.333 | D208: =B208/C208*1000 -> 0.071782123
A209: 42490 | B209: 5.48 | C209: ='Housing Stock'!S212 -> 75079.5 | D209: =B209/C209*1000 -> 0.072989298
A210: 42521 | B210: 5.47 | C210: ='Housing Stock'!S213 -> 75070.667 | D210: =B210/C210*1000 -> 0.072864679
...

Sheet OTM Turnover MBS
C1: y_vals.act
A2: [1,] | B2: 34366 | C2: 0.73656777
A3: [2,] | B3: 34394 | C3: 0.88997227
A4: [3,] | B4: 34486 | C4: 0.77389678
A5: [4,] | B5: 34516 | C5: 3.3083775
A6: [5,] | B6: 34547 | C6: 3.1378462
A7: [6,] | B7: 34578 | C7: 3.8636187
A8: [7,] | B8: 34608 | C8: 3.362162
A9: [8,] | B9: 34639 | C9: 3.98567
A10: [9,] | B10: 34669 | C10: 3.9019009
A11: [10,] | B11: 34700 | C11: 4.2943868
A12: [11,] | B12: 34731 | C12: 3.5697073
A13: [12,] | B13: 34759 | C13: 2.9104906
... A263: [262,] | B263: 42430 | C263: 2.1667663

Sheet Mtg Rate
B1: rate | G1: hpa2yr | H1: Multiplier
A2: 36161 | B2: 6.76625 | F2: 34366 | G2: 105.02 | H2: =IF(G2<110,0,IF(G2<=125,(G2-110)/($K$2-$K$3),1)) -> 0 | J2: Upper | K2: 125
A3: 36192 | B3: 6.8075 | F3: 34394 | G3: 104.97 | H3: =IF(G3<110,0,IF(G3<=125,(G3-110)/($K$2-$K$3),1)) -> 0 | J3: Lower | K3: 110
A4: 36220 | B4: 7.015 | F4: 34486 | G4: 105.64 | H4: =IF(G4<110,0,IF(G4<=125,(G4-110)/($K$2-$K$3),1)) -> 0
A5: 36251 | B5: 6.911 | F5: 34516 | G5: 105.39 | H5: =IF(G5<110,0,IF(G5<=125,(G5-110)/($K$2-$K$3),1)) -> 0 | U5: (110%, 0) and (125%, 1).
A6: 36281 | B6: 7.145 | F6: 34547 | G6: 105.14 | H6: =IF(G6<110,0,IF(G6<=125,(G6-110)/($K$2-$K$3),1)) -> 0
A7: 36312 | B7: 7.55 | F7: 34578 | G7: 104.89 | H7: =IF(G7<110,0,IF(G7<=125,(G7-110)/($K$2-$K$3),1)) -> 0
A8: 36342 | B8: 7.632 | F8: 34608 | G8: 104.68 | H8: =IF(G8<110,0,IF(G8<=125,(G8-110)/($K$2-$K$3),1)) -> 0
A9: 36373 | B9: 7.9425 | F9: 34639 | G9: 104.47 | H9: =IF(G9<110,0,IF(G9<=125,(G9-110)/($K$2-$K$3),1)) -> 0
A10: 36404 | B10: 7.81625 | F10: 34669 | G10: 104.26 | H10: =IF(G10<110,0,IF(G10<=125,(G10-110)/($K$2-$K$3),1)) -> 0
A11: 36434 | B11: 7.852 | F11: 34700 | G11: 104.43 | H11: =IF(G11<110,0,IF(G11<=125,(G11-110)/($K$2-$K$3),1)) -> 0
A12: 36465 | B12: 7.7375 | F12: 34731 | G12: 104.61 | H12: =IF(G12<110,0,IF(G12<=125,(G12-110)/($K$2-$K$3),1)) -> 0
A13: 36495 | B13: 7.912 | F13: 34759 | G13: 104.78 | H13: =IF(G13<110,0,IF(G13<=125,(G13-110)/($K$2-$K$3),1)) -> 0
A14: 36526 | B14: 8.21 | F14: 34790 | G14: 105.02 | H14: =IF(G14<110,0,IF(G14<=125,(G14-110)/($K$2-$K$3),1)) -> 0
A15: 36557 | B15: 8.31875 | F15: 34820 | G15: 105.25 | H15: =IF(G15<110,0,IF(G15<=125,(G15-110)/($K$2-$K$3),1)) -> 0
A16: 36586 | B16: 8.235 | F16: 34851 | G16: 105.49 | H16: =IF(G16<110,0,IF(G16<=125,(G16-110)/($K$2-$K$3),1)) -> 0
A17: 36617 | B17: 8.14625 | F17: 34881 | G17: 105.74 | H17: =IF(G17<110,0,IF(G17<=125,(G17-110)/($K$2-$K$3),1)) -> 0
... A209: 42461 | B209: 3.465 | F209: 40787 | G209: 93.89 | H209: =IF(G209<110,0,IF(G209<=125,(G209-110)/($K$2-$K$3),1)) -> 0
F210: 40817 | G210: 94.26 | H210: =IF(G210<110,0,IF(G210<=125,(G210-110)/($K$2-$K$3),1)) -> 0
F211: 40848 | G211: 94.63 | H211: =IF(G211<110,0,IF(G211<=125,(G211-110)/($K$2-$K$3),1)) -> 0
F212: 40878 | G212: 95.01 | H212: =IF(G212<110,0,IF(G212<=125,(G212-110)/($K$2-$K$3),1)) -> 0
F213: 40909 | G213: 95.06 | H213: =IF(G213<110,0,IF(G213<=125,(G213-110)/($K$2-$K$3),1)) -> 0
F214: 40940 | G214: 95.12 | H214: =IF(G214<110,0,IF(G214<=125,(G214-110)/($K$2-$K$3),1)) -> 0
F215: 40969 | G215: 95.17 | H215: =IF(G215<110,0,IF(G215<=125,(G215-110)/($K$2-$K$3),1)) -> 0
F216: 41000 | G216: 95.34 | H216: =IF(G216<110,0,IF(G216<=125,(G216-110)/($K$2-$K$3),1)) -> 0
F217: 41030 | G217: 95.5 | H217: =IF(G217<110,0,IF(G217<=125,(G217-110)/($K$2-$K$3),1)) -> 0
F218: 41061 | G218: 95.67 | H218: =IF(G218<110,0,IF(G218<=125,(G218-110)/($K$2-$K$3),1)) -> 0
F219: 41091 | G219: 95.77 | H219: =IF(G219<110,0,IF(G219<=125,(G219-110)/($K$2-$K$3),1)) -> 0
F220: 41122 | G220: 95.88 | H220: =IF(G220<110,0,IF(G220<=125,(G220-110)/($K$2-$K$3),1)) -> 0
F221: 41153 | G221: 95.98 | H221: =IF(G221<110,0,IF(G221<=125,(G221-110)/($K$2-$K$3),1)) -> 0
... F263: 42430 | G263: 111.18 | H263: =IF(G263<110,0,IF(G263<=125,(G263-110)/($K$2-$K$3),1)) -> 0.078666667

Sheet OTM Refi
B1: smm.OTMrefi | C1: Rate | D1: hpa2yr | E1: cltv
A2: 34366 | B2: 0 | C2: 0.68463785 | D2: 0 | E2: 1
A3: 34394 | B3: 0 | C3: 0.68970429 | D3: 0 | E3: 1
A4: 34486 | B4: 0 | C4: 0.29594662 | D4: 0 | E4: 0.9993453
A5: 34516 | B5: 0 | C5: 0.30254042 | D5: 0 | E5: 0.99993915
A6: 34547 | B6: 0 | C6: 0.24002375 | D6: 0 | E6: 0.99991998
A7: 34578 | B7: 0 | C7: 0.28452538 | D7: 0 | E7: 0.999949
A8: 34608 | B8: 0 | C8: 0.24262641 | D8: 0 | E8: 0.99993615
A9: 34639 | B9: 0 | C9: 0.2084918 | D9: 0 | E9: 0.99990148
A10: 34669 | B10: 0 | C10: 0.15396001 | D10: 0 | E10: 0.99981207
A11: 34700 | B11: 0 | C11: 0.15212178 | D11: 0 | E11: 0.99981678
A12: 34731 | B12: 0 | C12: 0.15934843 | D12: 0 | E12: 0.99989065
A13: 34759 | B13: 0 | C13: 0.21101043 | D13: 0 | E13: 0.99996065
... A263: 42430 | B263: 0.017035644 | C263: 0.56672062 | D263: 0.078666667 | E263: 0.1485433

Sheet model vs actual
B1: actual | C1: model | D1: Diff | E1: actual-6m ma | F1: model-6m ma | G1: Diff-6m ma
A2: 34366 | B2: 0.52955312 | C2: 1.2219269 | D2: =C2-B2 -> 0.69237378
A3: 34394 | B3: 0.84380792 | C3: 1.945278 | D3: =C3-B3 -> 1.1014701
A4: 34486 | B4: 0.95963463 | C4: 1.1848702 | D4: =C4-B4 -> 0.22523558
A5: 34516 | B5: 3.8799472 | C5: 3.5802243 | D5: =C5-B5 -> -0.29972297
A6: 34547 | B6: 3.7538245 | C6: 3.6710838 | D6: =C6-B6 -> -0.082740743
A7: 34578 | B7: 3.8824669 | C7: 3.2984967 | D7: =C7-B7 -> -0.58397015 | E7: =AVERAGE(B2:B7) -> 2.3082057 | F7: =AVERAGE(C2:C7) -> 2.4836466 | G7: =F7-E7 -> 0.17544093
A8: 34608 | B8: 3.3455065 | C8: 3.2346733 | D8: =C8-B8 -> -0.11083317 | E8: =AVERAGE(B3:B8) -> 2.7775313 | F8: =AVERAGE(C3:C8) -> 2.8191044 | G8: =F8-E8 -> 0.041573104
A9: 34639 | B9: 3.5968463 | C9: 2.9043882 | D9: =C9-B9 -> -0.69245814 | E9: =AVERAGE(B4:B9) -> 3.236371 | F9: =AVERAGE(C4:C9) -> 2.9789561 | G9: =F9-E9 -> -0.25741493
A10: 34669 | B10: 3.6329631 | C10: 2.812532 | D10: =C10-B10 -> -0.82043106 | E10: =AVERAGE(B5:B10) -> 3.6819258 | F10: =AVERAGE(C5:C10) -> 3.250233 | G10: =F10-E10 -> -0.43169271
A11: 34700 | B11: 2.953825 | C11: 2.1187145 | D11: =C11-B11 -> -0.83511044 | E11: =AVERAGE(B6:B11) -> 3.527572 | F11: =AVERAGE(C6:C11) -> 3.0066481 | G11: =F11-E11 -> -0.52092395
A12: 34731 | B12: 2.5759916 | C12: 2.3256376 | D12: =C12-B12 -> -0.25035403 | E12: =AVERAGE(B7:B12) -> 3.3312666 | F12: =AVERAGE(C7:C12) -> 2.7824071 | G12: =F12-E12 -> -0.5488595
A13: 34759 | B13: 2.7608684 | C13: 3.4104257 | D13: =C13-B13 -> 0.64955732 | E13: =AVERAGE(B8:B13) -> 3.1443335 | F13: =AVERAGE(C8:C13) -> 2.8010619 | G13: =F13-E13 -> -0.34327159
A14: 34790 | B14: 3.3240019 | C14: 4.305967 | D14: =C14-B14 -> 0.98196501 | E14: =AVERAGE(B9:B14) -> 3.1407494 | F14: =AVERAGE(C9:C14) -> 2.9796108 | G14: =F14-E14 -> -0.16113856
A15: 34820 | B15: 3.4429434 | C15: 4.8025196 | D15: =C15-B15 -> 1.3595762 | E15: =AVERAGE(B10:B15) -> 3.1150989 | F15: =AVERAGE(C10:C15) -> 3.2959661 | G15: =F15-E15 -> 0.18086717
A16: 34851 | B16: 4.2943509 | C16: 5.7713103 | D16: =C16-B16 -> 1.4769594 | E16: =AVERAGE(B11:B16) -> 3.2253302 | F16: =AVERAGE(C11:C16) -> 3.7890958 | G16: =F16-E16 -> 0.56376558
A17: 34881 | B17: 4.5426026 | C17: 5.9571943 | D17: =C17-B17 -> 1.4145917 | E17: =AVERAGE(B12:B17) -> 3.4901265 | F17: =AVERAGE(C12:C17) -> 4.4288424 | G17: =F17-E17 -> 0.93871594
A18: 34912 | B18: 4.967469 | C18: 6.2090126 | D18: =C18-B18 -> 1.2415435 | E18: =AVERAGE(B13:B18) -> 3.888706 | F18: =AVERAGE(C13:C18) -> 5.0760716 | G18: =F18-E18 -> 1.1873655
... A263: 42430 | B263: 2.0550057 | C263: 2.3137704 | D263: =C263-B263 -> 0.25876473 | E263: =AVERAGE(B258:B263) -> 2.6757601 | F263: =AVERAGE(C258:C263) -> 4.2385629 | G263: =F263-E263 -> 1.5628028
