Workbook

Sheet WAC Differences
A1: Using pool level issue date | S1: Using loan level calcOrigMonth_LL
A2: FNCK | E2: FNCL | N2: CK-CL | S2: CK | W2: CL | AB2: CK-CL | AF2: CK-CL
A3: issueDate | B3: WAC | C3: issueAmount1 | E3: issueDate | F3: WAC | G3: issueAmount1 | K3: issueDate | L3: FNCK | M3: FNCL | N3: Diff | O3: Mkt Share | S3: calcOrigMonth_LL | T3: FNCKWAC | U3: FNCKAmount | W3: calcOrigMonth_LL | X3: FNCLWAC | Y3: FNCLAmount | AB3: calcOrigMonth_LL | AC3: FNCKWAC | AD3: FNCLWAC | AF3: Diff | AG3: Mkt Share
A4: 39569 | B4: 6.299317 | C4: 1161378160 | E4: 29891 | F4: 10.517914 | G4: 8.9799702e+10 | K4: 39569 | L4: 6.299317 | M4: =VLOOKUP(K4,E:G,2,0) -> 6.0140519 | N4: =(L4-M4)*100 -> 28.526507 | O4: =C4/VLOOKUP(K4,E:G,3,0) -> 0.00029165871 | S4: 199803 | T4: 7.375 | U4: 418500 | W4: 198302 | X4: 8.5 | Y4: 60000 | AB4: 199803 | AC4: =VLOOKUP(AB4,S:T,2,0) -> 7.375 | AD4: =VLOOKUP(AB4,W:X,2,0) -> 7.3383819 | AE4: =DATEVALUE(INT(AB4/100)&"/"&MOD(AB4,100)&"/1") -> 35855 | AF4: =(AC4-AD4)*100 -> 3.6618088 | AG4: =U4/VLOOKUP(AB4,W:Y,3,0) -> 0.017877821
A5: 39600 | B5: 6.144827 | C5: 35713732492 | E5: 29921 | F5: 12.625243 | G5: 1.3422202e+10 | K5: 39600 | L5: 6.144827 | M5: =VLOOKUP(K5,E:G,2,0) -> 5.9940115 | N5: =(L5-M5)*100 -> 15.081554 | O5: =C5/VLOOKUP(K5,E:G,3,0) -> 0.010583838 | S5: 200205 | T5: 7.75 | U5: 520000 | W5: 198307 | X5: 8.75 | Y5: 70600 | AB5: 200205 | AC5: =VLOOKUP(AB5,S:T,2,0) -> 7.75 | AD5: =VLOOKUP(AB5,W:X,2,0) -> 6.952079 | AE5: =DATEVALUE(INT(AB5/100)&"/"&MOD(AB5,100)&"/1") -> 37377 | AF5: =(AC5-AD5)*100 -> 79.792103 | AG5: =U5/VLOOKUP(AB5,W:Y,3,0) -> 0.003298931
A6: 39630 | B6: 6.0746575 | C6: 149039315115 | E6: 29952 | F6: 9.7391656 | G6: 6.0262819e+10 | K6: 39630 | L6: 6.0746575 | M6: =VLOOKUP(K6,E:G,2,0) -> 6.1169394 | N6: =(L6-M6)*100 -> -4.2281844 | O6: =C6/VLOOKUP(K6,E:G,3,0) -> 0.064944641 | S6: 200207 | T6: 7.125 | U6: 449509.3 | W6: 198312 | X6: 10.9 | Y6: 42700 | AB6: 200207 | AC6: =VLOOKUP(AB6,S:T,2,0) -> 7.125 | AD6: =VLOOKUP(AB6,W:X,2,0) -> 6.7840952 | AE6: =DATEVALUE(INT(AB6/100)&"/"&MOD(AB6,100)&"/1") -> 37438 | AF6: =(AC6-AD6)*100 -> 34.090477 | AG6: =U6/VLOOKUP(AB6,W:Y,3,0) -> 0.0023165201
A7: 39661 | B7: 6.2552582 | C7: 172002858607 | E7: 29983 | F7: 10.266598 | G7: 6.9871323e+10 | K7: 39661 | L7: 6.2552582 | M7: =VLOOKUP(K7,E:G,2,0) -> 6.3342757 | N7: =(L7-M7)*100 -> -7.9017461 | O7: =C7/VLOOKUP(K7,E:G,3,0) -> 0.092590993 | S7: 200208 | T7: 6.7207011 | U7: 2378500 | W7: 198401 | X7: 10.9 | Y7: 33250 | AB7: 200208 | AC7: =VLOOKUP(AB7,S:T,2,0) -> 6.7207011 | AD7: =VLOOKUP(AB7,W:X,2,0) -> 6.6540371 | AE7: =DATEVALUE(INT(AB7/100)&"/"&MOD(AB7,100)&"/1") -> 37469 | AF7: =(AC7-AD7)*100 -> 6.6664013 | AG7: =U7/VLOOKUP(AB7,W:Y,3,0) -> 0.0088320348
A8: 39692 | B8: 6.3763621 | C8: 198709500499 | E8: 30011 | F8: 9.6542115 | G8: 1.3937501e+11 | K8: 39692 | L8: 6.3763621 | M8: =VLOOKUP(K8,E:G,2,0) -> 6.4530924 | N8: =(L8-M8)*100 -> -7.6730342 | O8: =C8/VLOOKUP(K8,E:G,3,0) -> 0.083133751 | S8: 200209 | T8: 6.4549843 | U8: 3340500 | W8: 198405 | X8: 9.203158 | Y8: 166325.75 | AB8: 200209 | AC8: =VLOOKUP(AB8,S:T,2,0) -> 6.4549843 | AD8: =VLOOKUP(AB8,W:X,2,0) -> 6.4808207 | AE8: =DATEVALUE(INT(AB8/100)&"/"&MOD(AB8,100)&"/1") -> 37500 | AF8: =(AC8-AD8)*100 -> -2.5836431 | AG8: =U8/VLOOKUP(AB8,W:Y,3,0) -> 0.0086278321
A9: 39722 | B9: 6.3160939 | C9: 111855954373 | E9: 30042 | F9: 9.6723304 | G9: 1.0391281e+11 | K9: 39722 | L9: 6.3160939 | M9: =VLOOKUP(K9,E:G,2,0) -> 6.3436343 | N9: =(L9-M9)*100 -> -2.7540398 | O9: =C9/VLOOKUP(K9,E:G,3,0) -> 0.061816447 | S9: 200210 | T9: 6.4914358 | U9: 6598348.4 | W9: 198406 | X9: 9.5 | Y9: 55435 | AB9: 200210 | AC9: =VLOOKUP(AB9,S:T,2,0) -> 6.4914358 | AD9: =VLOOKUP(AB9,W:X,2,0) -> 6.2877589 | AE9: =DATEVALUE(INT(AB9/100)&"/"&MOD(AB9,100)&"/1") -> 37530 | AF9: =(AC9-AD9)*100 -> 20.367684 | AG9: =U9/VLOOKUP(AB9,W:Y,3,0) -> 0.011127151
A10: 39783 | B10: 6.615089 | C10: 965831396 | E10: 30072 | F10: 9.6530215 | G10: 1.0908755e+11 | K10: 39783 | L10: 6.615089 | M10: =VLOOKUP(K10,E:G,2,0) -> 5.9750408 | N10: =(L10-M10)*100 -> 64.004816 | O10: =C10/VLOOKUP(K10,E:G,3,0) -> 0.00035490679 | S10: 200211 | T10: 6.2133983 | U10: 8845052 | W10: 198407 | X10: 7.54 | Y10: 51118.62 | AB10: 200211 | AC10: =VLOOKUP(AB10,S:T,2,0) -> 6.2133983 | AD10: =VLOOKUP(AB10,W:X,2,0) -> 6.1342483 | AE10: =DATEVALUE(INT(AB10/100)&"/"&MOD(AB10,100)&"/1") -> 37561 | AF10: =(AC10-AD10)*100 -> 7.9149967 | AG10: =U10/VLOOKUP(AB10,W:Y,3,0) -> 0.0088522797
A11: 39845 | B11: 5.5408758 | C11: 44994601171 | E11: 30086 | F11: 8.83 | G11: 4.9661583e+08 | K11: 39845 | L11: 5.5408758 | M11: =VLOOKUP(K11,E:G,2,0) -> 5.0640383 | N11: =(L11-M11)*100 -> 47.68375 | O11: =C11/VLOOKUP(K11,E:G,3,0) -> 0.015250839 | S11: 200212 | T11: 6.1991777 | U11: 19037492 | W11: 198408 | X11: 9 | Y11: 45000 | AB11: 200212 | AC11: =VLOOKUP(AB11,S:T,2,0) -> 6.1991777 | AD11: =VLOOKUP(AB11,W:X,2,0) -> 6.1121504 | AE11: =DATEVALUE(INT(AB11/100)&"/"&MOD(AB11,100)&"/1") -> 37591 | AF11: =(AC11-AD11)*100 -> 8.7027314 | AG11: =U11/VLOOKUP(AB11,W:Y,3,0) -> 0.019225774
A12: 39873 | B12: 5.3354414 | C12: 47649314668 | E12: 30103 | F12: 9.6148224 | G12: 4.1110766e+10 | K12: 39873 | L12: 5.3354414 | M12: =VLOOKUP(K12,E:G,2,0) -> 4.9906923 | N12: =(L12-M12)*100 -> 34.474912 | O12: =C12/VLOOKUP(K12,E:G,3,0) -> 0.0081399541 | S12: 200301 | T12: 6.1294733 | U12: 18878311 | W12: 198410 | X12: 12.725054 | Y12: 162850 | AB12: 200301 | AC12: =VLOOKUP(AB12,S:T,2,0) -> 6.1294733 | AD12: =VLOOKUP(AB12,W:X,2,0) -> 6.0918997 | AE12: =DATEVALUE(INT(AB12/100)&"/"&MOD(AB12,100)&"/1") -> 37622 | AF12: =(AC12-AD12)*100 -> 3.7573605 | AG12: =U12/VLOOKUP(AB12,W:Y,3,0) -> 0.0167799
A13: 39904 | B13: 5.0985473 | C13: 36818027973 | E13: 30133 | F13: 10.904001 | G13: 7.6841925e+10 | K13: 39904 | L13: 5.0985473 | M13: =VLOOKUP(K13,E:G,2,0) -> 4.9396221 | N13: =(L13-M13)*100 -> 15.892521 | O13: =C13/VLOOKUP(K13,E:G,3,0) -> 0.01095784 | S13: 200302 | T13: 6.0640863 | U13: 23921055 | W13: 198411 | X13: 11.632258 | Y13: 114350 | AB13: 200302 | AC13: =VLOOKUP(AB13,S:T,2,0) -> 6.0640863 | AD13: =VLOOKUP(AB13,W:X,2,0) -> 6.0487147 | AE13: =DATEVALUE(INT(AB13/100)&"/"&MOD(AB13,100)&"/1") -> 37653 | AF13: =(AC13-AD13)*100 -> 1.5371669 | AG13: =U13/VLOOKUP(AB13,W:Y,3,0) -> 0.016212991
A14: 39934 | B14: 5.9487133 | C14: 524521902921 | E14: 30164 | F14: 10.3636 | G14: 1.0929102e+11 | K14: 39934 | L14: 5.9487133 | M14: =VLOOKUP(K14,E:G,2,0) -> 5.4298106 | N14: =(L14-M14)*100 -> 51.890264 | O14: =C14/VLOOKUP(K14,E:G,3,0) -> 0.065335356 | S14: 200303 | T14: 6.0056333 | U14: 31542616 | W14: 198412 | X14: 11.875 | Y14: 91150 | AB14: 200303 | AC14: =VLOOKUP(AB14,S:T,2,0) -> 6.0056333 | AD14: =VLOOKUP(AB14,W:X,2,0) -> 5.9727137 | AE14: =DATEVALUE(INT(AB14/100)&"/"&MOD(AB14,100)&"/1") -> 37681 | AF14: =(AC14-AD14)*100 -> 3.2919599 | AG14: =U14/VLOOKUP(AB14,W:Y,3,0) -> 0.008248494
A15: 39965 | B15: 6.0411523 | C15: 170048580527 | E15: 30195 | F15: 9.9629691 | G15: 1.4121992e+11 | K15: 39965 | L15: 6.0411523 | M15: =VLOOKUP(K15,E:G,2,0) -> 5.070909 | N15: =(L15-M15)*100 -> 97.024333 | O15: =C15/VLOOKUP(K15,E:G,3,0) -> 0.024668686 | S15: 200304 | T15: 5.845416 | U15: 41542098 | W15: 198504 | X15: 9.4323718 | Y15: 62400 | AB15: 200304 | AC15: =VLOOKUP(AB15,S:T,2,0) -> 5.845416 | AD15: =VLOOKUP(AB15,W:X,2,0) -> 5.8595959 | AE15: =DATEVALUE(INT(AB15/100)&"/"&MOD(AB15,100)&"/1") -> 37712 | AF15: =(AC15-AD15)*100 -> -1.4179862 | AG15: =U15/VLOOKUP(AB15,W:Y,3,0) -> 0.0042365768
... A93: 42339 | B93: 4.1293287 | C93: 51527836 | E93: 32509 | F93: 10.230599 | G93: 531738717456 | K93: 42339 | L93: 4.1293287 | M93: =VLOOKUP(K93,E:G,2,0) -> 4.1798345 | N93: =(L93-M93)*100 -> -5.0505814 | O93: =C93/VLOOKUP(K93,E:G,3,0) -> 0.00546092 | S93: 201005 | T93: 5.1754863 | U93: 523245005 | W93: 199204 | X93: 8.4008057 | Y93: 1122928.5 | AB93: 201005 | AC93: =VLOOKUP(AB93,S:T,2,0) -> 5.1754863 | AD93: =VLOOKUP(AB93,W:X,2,0) -> 5.173857 | AE93: =DATEVALUE(INT(AB93/100)&"/"&MOD(AB93,100)&"/1") -> 40299 | AF93: =(AC93-AD93)*100 -> 0.1629362 | AG93: =U93/VLOOKUP(AB93,W:Y,3,0) -> 0.038451944
E94: 32540 | F94: 10.371113 | G94: 457673159860 | S94: 201006 | T94: 5.1818456 | U94: 4.9050518e+08 | W94: 199205 | X94: 8.2257725 | Y94: 847852.73 | AB94: 201006 | AC94: =VLOOKUP(AB94,S:T,2,0) -> 5.1818456 | AD94: =VLOOKUP(AB94,W:X,2,0) -> 5.1954391 | AE94: =DATEVALUE(INT(AB94/100)&"/"&MOD(AB94,100)&"/1") -> 40330 | AF94: =(AC94-AD94)*100 -> -1.3593424 | AG94: =U94/VLOOKUP(AB94,W:Y,3,0) -> 0.040505649
E95: 32568 | F95: 10.543022 | G95: 391904063422 | S95: 201007 | T95: 5.0182634 | U95: 9.8251869e+08 | W95: 199206 | X95: 8.8042608 | Y95: 974623.62 | AB95: 201007 | AC95: =VLOOKUP(AB95,S:T,2,0) -> 5.0182634 | AD95: =VLOOKUP(AB95,W:X,2,0) -> 5.0508257 | AE95: =DATEVALUE(INT(AB95/100)&"/"&MOD(AB95,100)&"/1") -> 40360 | AF95: =(AC95-AD95)*100 -> -3.2562245 | AG95: =U95/VLOOKUP(AB95,W:Y,3,0) -> 0.063346913
E96: 32599 | F96: 10.477662 | G96: 336057672745 | S96: 201008 | T96: 4.890869 | U96: 1.2600621e+09 | W96: 199207 | X96: 8.6720294 | Y96: 1819353.4 | AB96: 201008 | AC96: =VLOOKUP(AB96,S:T,2,0) -> 4.890869 | AD96: =VLOOKUP(AB96,W:X,2,0) -> 4.857865 | AE96: =DATEVALUE(INT(AB96/100)&"/"&MOD(AB96,100)&"/1") -> 40391 | AF96: =(AC96-AD96)*100 -> 3.3004057 | AG96: =U96/VLOOKUP(AB96,W:Y,3,0) -> 0.067896197
E97: 32629 | F97: 10.656042 | G97: 362916754943 | S97: 201009 | T97: 4.7616593 | U97: 1.7263259e+09 | W97: 199208 | X97: 8.4708833 | Y97: 1827730.9 | AB97: 201009 | AC97: =VLOOKUP(AB97,S:T,2,0) -> 4.7616593 | AD97: =VLOOKUP(AB97,W:X,2,0) -> 4.6987703 | AE97: =DATEVALUE(INT(AB97/100)&"/"&MOD(AB97,100)&"/1") -> 40422 | AF97: =(AC97-AD97)*100 -> 6.2889014 | AG97: =U97/VLOOKUP(AB97,W:Y,3,0) -> 0.064998796
E98: 32660 | F98: 10.746475 | G98: 503529757559 | S98: 201010 | T98: 4.6342551 | U98: 2.1473031e+09 | W98: 199209 | X98: 8.1982097 | Y98: 3094974.7 | AB98: 201010 | AC98: =VLOOKUP(AB98,S:T,2,0) -> 4.6342551 | AD98: =VLOOKUP(AB98,W:X,2,0) -> 4.5814851 | AE98: =DATEVALUE(INT(AB98/100)&"/"&MOD(AB98,100)&"/1") -> 40452 | AF98: =(AC98-AD98)*100 -> 5.2770063 | AG98: =U98/VLOOKUP(AB98,W:Y,3,0) -> 0.072353968
E99: 32690 | F99: 10.608009 | G99: 559445046338 | S99: 201011 | T99: 4.5580911 | U99: 2.3588054e+09 | W99: 199210 | X99: 7.7882477 | Y99: 5163020.8 | AB99: 201011 | AC99: =VLOOKUP(AB99,S:T,2,0) -> 4.5580911 | AD99: =VLOOKUP(AB99,W:X,2,0) -> 4.515479 | AE99: =DATEVALUE(INT(AB99/100)&"/"&MOD(AB99,100)&"/1") -> 40483 | AF99: =(AC99-AD99)*100 -> 4.2612117 | AG99: =U99/VLOOKUP(AB99,W:Y,3,0) -> 0.077236716
E100: 32721 | F100: 10.242439 | G100: 653227969075 | S100: 201012 | T100: 4.4864947 | U100: 2.4416572e+09 | W100: 199211 | X100: 7.9227007 | Y100: 2900203.6 | AB100: 201012 | AC100: =VLOOKUP(AB100,S:T,2,0) -> 4.4864947 | AD100: =VLOOKUP(AB100,W:X,2,0) -> 4.4352051 | AE100: =DATEVALUE(INT(AB100/100)&"/"&MOD(AB100,100)&"/1") -> 40513 | AF100: =(AC100-AD100)*100 -> 5.1289591 | AG100: =U100/VLOOKUP(AB100,W:Y,3,0) -> 0.077046399
E101: 32752 | F101: 10.006825 | G101: 871811656909 | S101: 201101 | T101: 4.4756302 | U101: 2.3236757e+09 | W101: 199212 | X101: 8.0246924 | Y101: 3267756.1 | AB101: 201101 | AC101: =VLOOKUP(AB101,S:T,2,0) -> 4.4756302 | AD101: =VLOOKUP(AB101,W:X,2,0) -> 4.51361 | AE101: =DATEVALUE(INT(AB101/100)&"/"&MOD(AB101,100)&"/1") -> 40544 | AF101: =(AC101-AD101)*100 -> -3.7979726 | AG101: =U101/VLOOKUP(AB101,W:Y,3,0) -> 0.080612975
E102: 32782 | F102: 9.9354068 | G102: 862150992305 | S102: 201102 | T102: 4.5968152 | U102: 1.1814863e+09 | W102: 199301 | X102: 7.626203 | Y102: 2402185.7 | AB102: 201102 | AC102: =VLOOKUP(AB102,S:T,2,0) -> 4.5968152 | AD102: =VLOOKUP(AB102,W:X,2,0) -> 4.7298271 | AE102: =DATEVALUE(INT(AB102/100)&"/"&MOD(AB102,100)&"/1") -> 40575 | AF102: =(AC102-AD102)*100 -> -13.301197 | AG102: =U102/VLOOKUP(AB102,W:Y,3,0) -> 0.059643495
E103: 32813 | F103: 9.9648791 | G103: 1214779703446 | S103: 201103 | T103: 4.7415193 | U103: 7.0349436e+08 | W103: 199302 | X103: 7.6062296 | Y103: 925670.58 | AB103: 201103 | AC103: =VLOOKUP(AB103,S:T,2,0) -> 4.7415193 | AD103: =VLOOKUP(AB103,W:X,2,0) -> 4.9045841 | AE103: =DATEVALUE(INT(AB103/100)&"/"&MOD(AB103,100)&"/1") -> 40603 | AF103: =(AC103-AD103)*100 -> -16.306482 | AG103: =U103/VLOOKUP(AB103,W:Y,3,0) -> 0.044401945
E104: 32843 | F104: 9.9697027 | G104: 1270191337114 | S104: 201104 | T104: 4.894023 | U104: 6.4776865e+08 | W104: 199303 | X104: 8.1178802 | Y104: 2539576 | AB104: 201104 | AC104: =VLOOKUP(AB104,S:T,2,0) -> 4.894023 | AD104: =VLOOKUP(AB104,W:X,2,0) -> 5.0815136 | AE104: =DATEVALUE(INT(AB104/100)&"/"&MOD(AB104,100)&"/1") -> 40634 | AF104: =(AC104-AD104)*100 -> -18.749058 | AG104: =U104/VLOOKUP(AB104,W:Y,3,0) -> 0.04305102
E105: 32874 | F105: 9.8695634 | G105: 1201163707111 | S105: 201105 | T105: 4.9540184 | U105: 4.6624322e+08 | W105: 199304 | X105: 7.7459398 | Y105: 3542225.7 | AB105: 201105 | AC105: =VLOOKUP(AB105,S:T,2,0) -> 4.9540184 | AD105: =VLOOKUP(AB105,W:X,2,0) -> 5.1075137 | AE105: =DATEVALUE(INT(AB105/100)&"/"&MOD(AB105,100)&"/1") -> 40664 | AF105: =(AC105-AD105)*100 -> -15.349527 | AG105: =U105/VLOOKUP(AB105,W:Y,3,0) -> 0.036827663
... E159: 34516 | F159: 8.4775907 | G159: 986597311153 | S159: 201511 | T159: 4.0167302 | U159: 5.093829e+08 | W159: 199710 | X159: 7.8070873 | Y159: 16946125 | AB159: 201511 | AC159: =VLOOKUP(AB159,S:T,2,0) -> 4.0167302 | AD159: =VLOOKUP(AB159,W:X,2,0) -> 4.198904 | AE159: =DATEVALUE(INT(AB159/100)&"/"&MOD(AB159,100)&"/1") -> 42309 | AF159: =(AC159-AD159)*100 -> -18.217383 | AG159: =U159/VLOOKUP(AB159,W:Y,3,0) -> 0.020831562
E160: 34547 | F160: 8.5893804 | G160: 783069980814 | S160: 201512 | T160: 3.7609486 | U160: 143116878 | W160: 199711 | X160: 7.7094816 | Y160: 15690351
E161: 34578 | F161: 8.6653178 | G161: 814776376647 | W161: 199712 | X161: 7.6791941 | Y161: 17388390
E162: 34608 | F162: 8.7318931 | G162: 764579816780 | W162: 199801 | X162: 7.6700677 | Y162: 21218058
E163: 34639 | F163: 8.8767889 | G163: 881251050834 | W163: 199802 | X163: 7.3920611 | Y163: 17900750
E164: 34669 | F164: 8.9693276 | G164: 858967640923 | W164: 199803 | X164: 7.3383819 | Y164: 23408893
E165: 34700 | F165: 9.2680437 | G165: 532490402210 | W165: 199804 | X165: 7.2948537 | Y165: 29732055
E166: 34731 | F166: 9.2949159 | G166: 450680603345 | W166: 199805 | X166: 7.3530635 | Y166: 30487028
E167: 34759 | F167: 9.0094043 | G167: 396618038242 | W167: 199806 | X167: 7.2941348 | Y167: 27171899
E168: 34790 | F168: 9.0783827 | G168: 513492654076 | W168: 199807 | X168: 7.2642136 | Y168: 39041775
E169: 34820 | F169: 8.8181759 | G169: 717658553729 | W169: 199808 | X169: 7.281436 | Y169: 42709730
E170: 34851 | F170: 8.5354555 | G170: 1129307921633 | W170: 199809 | X170: 7.261018 | Y170: 43247375
...

Sheet Rate Differences - Credit
A1: FNM | B1: >417 | E1: FNM | F1: <= 417 | I1: FHL | J1: > 417 | M1: FHL | N1: <= 417 | S1: FNM | U1: FHL | X1: FNM | Z1: FHL | AO1: FNM | AP1: >417 | AS1: FNM | AT1: <= 417 | AW1: FHL | AX1: > 417 | BA1: FHL | BB1: <= 417 | BE1: FHL | BH1: FNM | BJ1: FHL | BM1: FNM | BO1: FHL
A2: issueDate | B2: WAC | C2: Amount | E2: issueDate | F2: WAC | G2: Amount | I2: issueDate | J2: WAC | K2: Amount | M2: issueDate | N2: WAC | O2: Amount | Q2: issueDate | R2: WAC | S2: Amount | T2: WAC | U2: Amount | V2: Large Loan Size | W2: WAC | X2: Amount | Y2: WAC | Z2: Amount | AA2: Small Loan Size | AB2: Diff | AO2: calcOrigMonth_LL | AP2: WAC | AQ2: Amount | AS2: calcOrigMonth_LL | AT2: WAC | AU2: Amount | AW2: calcOrigMonth_LL | AX2: WAC | AY2: Amount | BA2: calcOrigMonth_LL | BB2: WAC | BC2: Amount | BE2: calcOrigMonth_LL | BG2: WAC | BH2: Amount | BI2: WAC | BJ2: Amount | BK2: Large Loan Size | BL2: WAC | BM2: Amount | BN2: WAC | BO2: Amount | BP2: Small Loan Size | BQ2: Diff
A3: 37712 | B3: 5.6250488 | C3: 3202900 | E3: 37712 | F3: 5.7274296 | G3: 3259800 | I3: 38687 | J3: 5.7864762 | K3: 22815990 | M3: 38687 | N3: 5.7862689 | O3: 22159991 | Q3: 37712 | R3: =VLOOKUP($Q3,A:C,2,0) -> 5.6250488 | S3: =VLOOKUP($Q3,A:C,3,0) -> 3202900 | T3: 0 | U3: 0 | V3: =(R3*S3+T3*U3)/(S3+U3) -> 5.6250488 | W3: =VLOOKUP($Q3,E:G,2,0) -> 5.7274296 | X3: =VLOOKUP($Q3,E:G,3,0) -> 3259800 | Y3: 0 | Z3: 0 | AA3: =(W3*X3+Y3*Z3)/(X3+Z3) -> 5.7274296 | AB3: =(V3-AA3)*100 -> -10.238081 | AO3: 199311 | AP3: 7.125 | AQ3: 420000 | AS3: 198302 | AT3: 8.5 | AU3: 60000 | AW3: 200211 | AX3: 5.75 | AY3: 1266000 | BA3: 198111 | BB3: 7.5 | BC3: 16948 | BE3: 200211 | BF3: =DATEVALUE(INT(AW3/100)&"/"&MOD(AW3,100)&"/1") -> 37561 | BG3: =VLOOKUP($BE3,AO:AQ,2,0) -> 6.2173246 | BH3: =VLOOKUP($BE3,AO:AQ,3,0) -> 8468900 | BI3: =VLOOKUP($BE3,AW:AY,2,0) -> 5.75 | BJ3: =VLOOKUP($BE3,AW:AY,3,0) -> 1266000 | BK3: =(BG3*BH3+BI3*BJ3)/(BH3+BJ3) -> 6.1565501 | BL3: =VLOOKUP($BE3,AS:AU,2,0) -> 6.0958037 | BM3: =VLOOKUP($BE3,AS:AU,3,0) -> 7.3538878e+08 | BN3: =VLOOKUP($BE3,BA:BC,2,0) -> 6.0914446 | BO3: =VLOOKUP($BE3,BA:BC,3,0) -> 145929215 | BP3: =(BL3*BM3+BN3*BO3)/(BM3+BO3) -> 6.0950819 | BQ3: =(BK3-BP3)*100 -> 6.1468213
A4: 37742 | B4: 5.75 | C4: 460000 | E4: 37742 | F4: 5.3167406 | G4: 902000 | I4: 38718 | J4: 5.9437237 | K4: 35493184 | M4: 38718 | N4: 5.8846358 | O4: 40584083 | Q4: 37742 | R4: =VLOOKUP($Q4,A:C,2,0) -> 5.75 | S4: =VLOOKUP($Q4,A:C,3,0) -> 460000 | T4: 0 | U4: 0 | V4: =(R4*S4+T4*U4)/(S4+U4) -> 5.75 | W4: =VLOOKUP($Q4,E:G,2,0) -> 5.3167406 | X4: =VLOOKUP($Q4,E:G,3,0) -> 902000 | Y4: 0 | Z4: 0 | AA4: =(W4*X4+Y4*Z4)/(X4+Z4) -> 5.3167406 | AB4: =(V4-AA4)*100 -> 43.325942 | AO4: 199604 | AP4: 8.88 | AQ4: 470000 | AS4: 198307 | AT4: 8.75 | AU4: 70600 | AW4: 200212 | AX4: 5.9517987 | AY4: 974300 | BA4: 198405 | BB4: 8.9775673 | BC4: 46528 | BE4: 200212 | BF4: =DATEVALUE(INT(AW4/100)&"/"&MOD(AW4,100)&"/1") -> 37591 | BG4: =VLOOKUP($BE4,AO:AQ,2,0) -> 6.1909261 | BH4: =VLOOKUP($BE4,AO:AQ,3,0) -> 18983492 | BI4: =VLOOKUP($BE4,AW:AY,2,0) -> 5.9517987 | BJ4: =VLOOKUP($BE4,AW:AY,3,0) -> 974300 | BK4: =(BG4*BH4+BI4*BJ4)/(BH4+BJ4) -> 6.1792524 | BL4: =VLOOKUP($BE4,AS:AU,2,0) -> 6.0702153 | BM4: =VLOOKUP($BE4,AS:AU,3,0) -> 7.262851e+08 | BN4: =VLOOKUP($BE4,BA:BC,2,0) -> 6.031706 | BO4: =VLOOKUP($BE4,BA:BC,3,0) -> 165157956 | BP4: =(BL4*BM4+BN4*BO4)/(BM4+BO4) -> 6.0630807 | BQ4: =(BK4-BP4)*100 -> 11.617166
A5: 37773 | B5: 5.7137549 | C5: 1783000 | E5: 37773 | F5: 5.2973087 | G5: 2378000 | I5: 38749 | J5: 5.945174 | K5: 29389764 | M5: 38749 | N5: 6.0619456 | O5: 30099776 | Q5: 37773 | R5: =VLOOKUP($Q5,A:C,2,0) -> 5.7137549 | S5: =VLOOKUP($Q5,A:C,3,0) -> 1783000 | T5: 0 | U5: 0 | V5: =(R5*S5+T5*U5)/(S5+U5) -> 5.7137549 | W5: =VLOOKUP($Q5,E:G,2,0) -> 5.2973087 | X5: =VLOOKUP($Q5,E:G,3,0) -> 2378000 | Y5: 0 | Z5: 0 | AA5: =(W5*X5+Y5*Z5)/(X5+Z5) -> 5.2973087 | AB5: =(V5-AA5)*100 -> 41.644624 | AO5: 199803 | AP5: 7.375 | AQ5: 418500 | AS5: 198408 | AT5: 9 | AU5: 45000 | AW5: 200301 | AX5: 5.953272 | AY5: 938985 | BA5: 198409 | BB5: 8.375 | BC5: 40387 | BE5: 200301 | BF5: =DATEVALUE(INT(AW5/100)&"/"&MOD(AW5,100)&"/1") -> 37622 | BG5: =VLOOKUP($BE5,AO:AQ,2,0) -> 6.0869985 | BH5: =VLOOKUP($BE5,AO:AQ,3,0) -> 18129266 | BI5: =VLOOKUP($BE5,AW:AY,2,0) -> 5.953272 | BJ5: =VLOOKUP($BE5,AW:AY,3,0) -> 938985 | BK5: =(BG5*BH5+BI5*BJ5)/(BH5+BJ5) -> 6.0804134 | BL5: =VLOOKUP($BE5,AS:AU,2,0) -> 6.0533242 | BM5: =VLOOKUP($BE5,AS:AU,3,0) -> 8.1794963e+08 | BN5: =VLOOKUP($BE5,BA:BC,2,0) -> 6.0063645 | BO5: =VLOOKUP($BE5,BA:BC,3,0) -> 192765022 | BP5: =(BL5*BM5+BN5*BO5)/(BM5+BO5) -> 6.044368 | BQ5: =(BK5-BP5)*100 -> 3.6045427
A6: 37803 | B6: 5.1200481 | C6: 4197850 | E6: 37803 | F6: 5.3731102 | G6: 2788050 | I6: 38777 | J6: 5.9327354 | K6: 30459910 | M6: 38777 | N6: 6.0181337 | O6: 33370270 | Q6: 37803 | R6: =VLOOKUP($Q6,A:C,2,0) -> 5.1200481 | S6: =VLOOKUP($Q6,A:C,3,0) -> 4197850 | T6: 0 | U6: 0 | V6: =(R6*S6+T6*U6)/(S6+U6) -> 5.1200481 | W6: =VLOOKUP($Q6,E:G,2,0) -> 5.3731102 | X6: =VLOOKUP($Q6,E:G,3,0) -> 2788050 | Y6: 0 | Z6: 0 | AA6: =(W6*X6+Y6*Z6)/(X6+Z6) -> 5.3731102 | AB6: =(V6-AA6)*100 -> -25.306218 | AO6: 200110 | AP6: 7.4342316 | AQ6: 1171250 | AS6: 198603 | AT6: 9.375 | AU6: 60000 | AW6: 200302 | AX6: 5.875 | AY6: 465000 | BA6: 198410 | BB6: 8.375 | BC6: 48152 | BE6: 200305 | BF6: =DATEVALUE(INT(AW6/100)&"/"&MOD(AW6,100)&"/1") -> 37653 | BG6: =VLOOKUP($BE6,AO:AQ,2,0) -> 5.8231711 | BH6: =VLOOKUP($BE6,AO:AQ,3,0) -> 76266099 | BI6: =VLOOKUP($BE6,AW:AY,2,0) -> 5.875 | BJ6: =VLOOKUP($BE6,AW:AY,3,0) -> 542000 | BK6: =(BG6*BH6+BI6*BJ6)/(BH6+BJ6) -> 5.8235368 | BL6: =VLOOKUP($BE6,AS:AU,2,0) -> 5.8000917 | BM6: =VLOOKUP($BE6,AS:AU,3,0) -> 9.3845264e+09 | BN6: =VLOOKUP($BE6,BA:BC,2,0) -> 5.7654769 | BO6: =VLOOKUP($BE6,BA:BC,3,0) -> 203478902 | BP6: =(BL6*BM6+BN6*BO6)/(BM6+BO6) -> 5.7993571 | BQ6: =(BK6-BP6)*100 -> 2.4179741
A7: 37834 | B7: 5.145394 | C7: 6900300 | E7: 37834 | F7: 5.4899896 | G7: 5435600 | I7: 38808 | J7: 5.9637765 | K7: 23105765 | M7: 38808 | N7: 6.0313289 | O7: 24221125 | Q7: 37834 | R7: =VLOOKUP($Q7,A:C,2,0) -> 5.145394 | S7: =VLOOKUP($Q7,A:C,3,0) -> 6900300 | T7: 0 | U7: 0 | V7: =(R7*S7+T7*U7)/(S7+U7) -> 5.145394 | W7: =VLOOKUP($Q7,E:G,2,0) -> 5.4899896 | X7: =VLOOKUP($Q7,E:G,3,0) -> 5435600 | Y7: 0 | Z7: 0 | AA7: =(W7*X7+Y7*Z7)/(X7+Z7) -> 5.4899896 | AB7: =(V7-AA7)*100 -> -34.459556 | AO7: 200205 | AP7: 7.75 | AQ7: 520000 | AS7: 198604 | AT7: 9 | AU7: 26600 | AW7: 200303 | AX7: 5.875 | AY7: 432000 | BA7: 198507 | BB7: 8.375 | BC7: 83254 | BE7: 200308 | BF7: =DATEVALUE(INT(AW7/100)&"/"&MOD(AW7,100)&"/1") -> 37681 | BG7: =VLOOKUP($BE7,AO:AQ,2,0) -> 5.506515 | BH7: =VLOOKUP($BE7,AO:AQ,3,0) -> 1.95664e+08 | BI7: =VLOOKUP($BE7,AW:AY,2,0) -> 4.9166275 | BJ7: =VLOOKUP($BE7,AW:AY,3,0) -> 1597500 | BK7: =(BG7*BH7+BI7*BJ7)/(BH7+BJ7) -> 5.5017379 | BL7: =VLOOKUP($BE7,AS:AU,2,0) -> 5.3696281 | BM7: =VLOOKUP($BE7,AS:AU,3,0) -> 1.5363476e+10 | BN7: =VLOOKUP($BE7,BA:BC,2,0) -> 5.4783821 | BO7: =VLOOKUP($BE7,BA:BC,3,0) -> 367004141 | BP7: =(BL7*BM7+BN7*BO7)/(BM7+BO7) -> 5.3721654 | BQ7: =(BK7-BP7)*100 -> 12.957246
A8: 37865 | B8: 5.054441 | C8: 3265000 | E8: 37865 | F8: 5.0251603 | G8: 5473150 | I8: 38838 | J8: 6.0319394 | K8: 37337908 | M8: 38838 | N8: 6.1200181 | O8: 28001250 | Q8: 37865 | R8: =VLOOKUP($Q8,A:C,2,0) -> 5.054441 | S8: =VLOOKUP($Q8,A:C,3,0) -> 3265000 | T8: 0 | U8: 0 | V8: =(R8*S8+T8*U8)/(S8+U8) -> 5.054441 | W8: =VLOOKUP($Q8,E:G,2,0) -> 5.0251603 | X8: =VLOOKUP($Q8,E:G,3,0) -> 5473150 | Y8: 0 | Z8: 0 | AA8: =(W8*X8+Y8*Z8)/(X8+Z8) -> 5.0251603 | AB8: =(V8-AA8)*100 -> 2.9280713 | AO8: 200207 | AP8: 6.841629 | AQ8: 1037509.3 | AS8: 198605 | AT8: 10.022313 | AU8: 92100 | AW8: 200305 | AX8: 5.875 | AY8: 542000 | BA8: 198606 | BB8: 8.453854 | BC8: 301654 | BE8: 200404 | BF8: =DATEVALUE(INT(AW8/100)&"/"&MOD(AW8,100)&"/1") -> 37742 | BG8: =VLOOKUP($BE8,AO:AQ,2,0) -> 5.5240969 | BH8: =VLOOKUP($BE8,AO:AQ,3,0) -> 31436261 | BI8: =VLOOKUP($BE8,AW:AY,2,0) -> 6 | BJ8: =VLOOKUP($BE8,AW:AY,3,0) -> 548000 | BK8: =(BG8*BH8+BI8*BJ8)/(BH8+BJ8) -> 5.5322507 | BL8: =VLOOKUP($BE8,AS:AU,2,0) -> 5.626417 | BM8: =VLOOKUP($BE8,AS:AU,3,0) -> 6.1046403e+09 | BN8: =VLOOKUP($BE8,BA:BC,2,0) -> 5.595528 | BO8: =VLOOKUP($BE8,BA:BC,3,0) -> 290078493 | BP8: =(BL8*BM8+BN8*BO8)/(BM8+BO8) -> 5.6250158 | BQ8: =(BK8-BP8)*100 -> -9.2765067
A9: 37895 | B9: 5.4011454 | C9: 7241700 | E9: 37895 | F9: 5.6456239 | G9: 5610000 | I9: 38869 | J9: 6.2758067 | K9: 31251520 | M9: 38869 | N9: 6.3300807 | O9: 27142358 | Q9: 37895 | R9: =VLOOKUP($Q9,A:C,2,0) -> 5.4011454 | S9: =VLOOKUP($Q9,A:C,3,0) -> 7241700 | T9: 0 | U9: 0 | V9: =(R9*S9+T9*U9)/(S9+U9) -> 5.4011454 | W9: =VLOOKUP($Q9,E:G,2,0) -> 5.6456239 | X9: =VLOOKUP($Q9,E:G,3,0) -> 5610000 | Y9: 0 | Z9: 0 | AA9: =(W9*X9+Y9*Z9)/(X9+Z9) -> 5.6456239 | AB9: =(V9-AA9)*100 -> -24.447844 | AO9: 200208 | AP9: 6.7207011 | AQ9: 2378500 | AS9: 198606 | AT9: 10.291966 | AU9: 139250 | AW9: 200308 | AX9: 4.9166275 | AY9: 1597500 | BA9: 198608 | BB9: 7.25 | BC9: 47100 | BE9: 200405 | BF9: =DATEVALUE(INT(AW9/100)&"/"&MOD(AW9,100)&"/1") -> 37834 | BG9: =VLOOKUP($BE9,AO:AQ,2,0) -> 5.4590022 | BH9: =VLOOKUP($BE9,AO:AQ,3,0) -> 67857017 | BI9: =VLOOKUP($BE9,AW:AY,2,0) -> 5.625 | BJ9: =VLOOKUP($BE9,AW:AY,3,0) -> 600000 | BK9: =(BG9*BH9+BI9*BJ9)/(BH9+BJ9) -> 5.4604571 | BL9: =VLOOKUP($BE9,AS:AU,2,0) -> 5.5566838 | BM9: =VLOOKUP($BE9,AS:AU,3,0) -> 6.7653711e+09 | BN9: =VLOOKUP($BE9,BA:BC,2,0) -> 5.5521518 | BO9: =VLOOKUP($BE9,BA:BC,3,0) -> 458744668 | BP9: =(BL9*BM9+BN9*BO9)/(BM9+BO9) -> 5.556396 | BQ9: =(BK9-BP9)*100 -> -9.5938909
A10: 37926 | B10: 5.2483007 | C10: 1368200 | E10: 37926 | F10: 5.6267507 | G10: 1428000 | I10: 38899 | J10: 6.2844319 | K10: 24808750 | M10: 38899 | N10: 6.3767725 | O10: 27242700 | Q10: 37926 | R10: =VLOOKUP($Q10,A:C,2,0) -> 5.2483007 | S10: =VLOOKUP($Q10,A:C,3,0) -> 1368200 | T10: 0 | U10: 0 | V10: =(R10*S10+T10*U10)/(S10+U10) -> 5.2483007 | W10: =VLOOKUP($Q10,E:G,2,0) -> 5.6267507 | X10: =VLOOKUP($Q10,E:G,3,0) -> 1428000 | Y10: 0 | Z10: 0 | AA10: =(W10*X10+Y10*Z10)/(X10+Z10) -> 5.6267507 | AB10: =(V10-AA10)*100 -> -37.845001 | AO10: 200209 | AP10: 6.4549843 | AQ10: 3340500 | AS10: 198607 | AT10: 10.25 | AU10: 148100 | AW10: 200401 | AX10: 5.25 | AY10: 450450 | BA10: 198609 | BB10: 8.25 | BC10: 56400 | BE10: 200406 | BF10: =DATEVALUE(INT(AW10/100)&"/"&MOD(AW10,100)&"/1") -> 37987 | BG10: =VLOOKUP($BE10,AO:AQ,2,0) -> 5.6321563 | BH10: =VLOOKUP($BE10,AO:AQ,3,0) -> 40307922 | BI10: =VLOOKUP($BE10,AW:AY,2,0) -> 5.6234869 | BJ10: =VLOOKUP($BE10,AW:AY,3,0) -> 1024400 | BK10: =(BG10*BH10+BI10*BJ10)/(BH10+BJ10) -> 5.6319414 | BL10: =VLOOKUP($BE10,AS:AU,2,0) -> 5.841234 | BM10: =VLOOKUP($BE10,AS:AU,3,0) -> 4.0755488e+09 | BN10: =VLOOKUP($BE10,BA:BC,2,0) -> 5.6856944 | BO10: =VLOOKUP($BE10,BA:BC,3,0) -> 224947760 | BP10: =(BL10*BM10+BN10*BO10)/(BM10+BO10) -> 5.8330982 | BQ10: =(BK10-BP10)*100 -> -20.115673
A11: 37956 | B11: 5.5470499 | C11: 1380450 | E11: 37956 | F11: 5.8895825 | G11: 3750650 | I11: 38930 | J11: 6.4199066 | K11: 25865766 | M11: 38930 | N11: 6.4693391 | O11: 25911500 | Q11: 37956 | R11: =VLOOKUP($Q11,A:C,2,0) -> 5.5470499 | S11: =VLOOKUP($Q11,A:C,3,0) -> 1380450 | T11: 0 | U11: 0 | V11: =(R11*S11+T11*U11)/(S11+U11) -> 5.5470499 | W11: =VLOOKUP($Q11,E:G,2,0) -> 5.8895825 | X11: =VLOOKUP($Q11,E:G,3,0) -> 3750650 | Y11: 0 | Z11: 0 | AA11: =(W11*X11+Y11*Z11)/(X11+Z11) -> 5.8895825 | AB11: =(V11-AA11)*100 -> -34.25326 | AO11: 200210 | AP11: 6.4257553 | AQ11: 7664398.4 | AS11: 198609 | AT11: 10.572007 | AU11: 203800 | AW11: 200402 | AX11: 6.25 | AY11: 460000 | BA11: 198612 | BB11: 8.875 | BC11: 90100 | BE11: 200407 | BF11: =DATEVALUE(INT(AW11/100)&"/"&MOD(AW11,100)&"/1") -> 38018 | BG11: =VLOOKUP($BE11,AO:AQ,2,0) -> 5.936255 | BH11: =VLOOKUP($BE11,AO:AQ,3,0) -> 10902725 | BI11: =VLOOKUP($BE11,AW:AY,2,0) -> 5.875 | BJ11: =VLOOKUP($BE11,AW:AY,3,0) -> 624000 | BK11: =(BG11*BH11+BI11*BJ11)/(BH11+BJ11) -> 5.932939 | BL11: =VLOOKUP($BE11,AS:AU,2,0) -> 6.2082887 | BM11: =VLOOKUP($BE11,AS:AU,3,0) -> 2.6919759e+09 | BN11: =VLOOKUP($BE11,BA:BC,2,0) -> 5.9683358 | BO11: =VLOOKUP($BE11,BA:BC,3,0) -> 119655177 | BP11: =(BL11*BM11+BN11*BO11)/(BM11+BO11) -> 6.198077 | BQ11: =(BK11-BP11)*100 -> -26.513798
A12: 37987 | B12: 6.0246096 | C12: 4562760 | E12: 37987 | F12: 5.5960242 | G12: 4301000 | I12: 38961 | J12: 6.4051004 | K12: 27942450 | M12: 38961 | N12: 6.4840707 | O12: 22836117 | Q12: 37987 | R12: =VLOOKUP($Q12,A:C,2,0) -> 6.0246096 | S12: =VLOOKUP($Q12,A:C,3,0) -> 4562760 | T12: 0 | U12: 0 | V12: =(R12*S12+T12*U12)/(S12+U12) -> 6.0246096 | W12: =VLOOKUP($Q12,E:G,2,0) -> 5.5960242 | X12: =VLOOKUP($Q12,E:G,3,0) -> 4301000 | Y12: 0 | Z12: 0 | AA12: =(W12*X12+Y12*Z12)/(X12+Z12) -> 5.5960242 | AB12: =(V12-AA12)*100 -> 42.858538 | AO12: 200211 | AP12: 6.2173246 | AQ12: 8468900 | AS12: 198610 | AT12: 8.75 | AU12: 27900 | AW12: 200404 | AX12: 6 | AY12: 548000 | BA12: 198701 | BB12: 8.125 | BC12: 160000 | BE12: 200410 | BF12: =DATEVALUE(INT(AW12/100)&"/"&MOD(AW12,100)&"/1") -> 38078 | BG12: =VLOOKUP($BE12,AO:AQ,2,0) -> 5.8572353 | BH12: =VLOOKUP($BE12,AO:AQ,3,0) -> 24300722 | BI12: =VLOOKUP($BE12,AW:AY,2,0) -> 6.25 | BJ12: =VLOOKUP($BE12,AW:AY,3,0) -> 620000 | BK12: =(BG12*BH12+BI12*BJ12)/(BH12+BJ12) -> 5.8670068 | BL12: =VLOOKUP($BE12,AS:AU,2,0) -> 5.9311974 | BM12: =VLOOKUP($BE12,AS:AU,3,0) -> 3.5336296e+09 | BN12: =VLOOKUP($BE12,BA:BC,2,0) -> 5.8036994 | BO12: =VLOOKUP($BE12,BA:BC,3,0) -> 141634352 | BP12: =(BL12*BM12+BN12*BO12)/(BM12+BO12) -> 5.926284 | BQ12: =(BK12-BP12)*100 -> -5.9277137
A13: 38018 | B13: 5.5954868 | C13: 1384550 | E13: 38018 | F13: 5.5 | G13: 984050 | I13: 38991 | J13: 6.2922836 | K13: 26315228 | M13: 38991 | N13: 6.3558868 | O13: 21743150 | Q13: 38018 | R13: =VLOOKUP($Q13,A:C,2,0) -> 5.5954868 | S13: =VLOOKUP($Q13,A:C,3,0) -> 1384550 | T13: 0 | U13: 0 | V13: =(R13*S13+T13*U13)/(S13+U13) -> 5.5954868 | W13: =VLOOKUP($Q13,E:G,2,0) -> 5.5 | X13: =VLOOKUP($Q13,E:G,3,0) -> 984050 | Y13: 0 | Z13: 0 | AA13: =(W13*X13+Y13*Z13)/(X13+Z13) -> 5.5 | AB13: =(V13-AA13)*100 -> 9.5486801 | AO13: 200212 | AP13: 6.1909261 | AQ13: 18983492 | AS13: 198611 | AT13: 10.125 | AU13: 75550 | AW13: 200405 | AX13: 5.625 | AY13: 600000 | BA13: 198703 | BB13: 7.5 | BC13: 29524 | BE13: 200412 | BF13: =DATEVALUE(INT(AW13/100)&"/"&MOD(AW13,100)&"/1") -> 38108 | BG13: =VLOOKUP($BE13,AO:AQ,2,0) -> 5.7383682 | BH13: =VLOOKUP($BE13,AO:AQ,3,0) -> 29629350 | BI13: =VLOOKUP($BE13,AW:AY,2,0) -> 6.125 | BJ13: =VLOOKUP($BE13,AW:AY,3,0) -> 1100000 | BK13: =(BG13*BH13+BI13*BJ13)/(BH13+BJ13) -> 5.7522082 | BL13: =VLOOKUP($BE13,AS:AU,2,0) -> 5.8000772 | BM13: =VLOOKUP($BE13,AS:AU,3,0) -> 4.0512617e+09 | BN13: =VLOOKUP($BE13,BA:BC,2,0) -> 5.6765616 | BO13: =VLOOKUP($BE13,BA:BC,3,0) -> 166257983 | BP13: =(BL13*BM13+BN13*BO13)/(BM13+BO13) -> 5.7952081 | BQ13: =(BK13-BP13)*100 -> -4.2999959
A14: 38047 | B14: 5.415738 | C14: 1485100 | E14: 38047 | F14: 5.6898741 | G14: 4607000 | I14: 39022 | J14: 6.0857292 | K14: 21368896 | M14: 39022 | N14: 6.1714087 | O14: 29131494 | Q14: 38047 | R14: =VLOOKUP($Q14,A:C,2,0) -> 5.415738 | S14: =VLOOKUP($Q14,A:C,3,0) -> 1485100 | T14: 0 | U14: 0 | V14: =(R14*S14+T14*U14)/(S14+U14) -> 5.415738 | W14: =VLOOKUP($Q14,E:G,2,0) -> 5.6898741 | X14: =VLOOKUP($Q14,E:G,3,0) -> 4607000 | Y14: 0 | Z14: 0 | AA14: =(W14*X14+Y14*Z14)/(X14+Z14) -> 5.6898741 | AB14: =(V14-AA14)*100 -> -27.413611 | AO14: 200301 | AP14: 6.0869985 | AQ14: 18129266 | AS14: 198612 | AT14: 10.75 | AU14: 63900 | AW14: 200406 | AX14: 5.6234869 | AY14: 1024400 | BA14: 198704 | BB14: 8.75 | BC14: 63500 | BE14: 200502 | BF14: =DATEVALUE(INT(AW14/100)&"/"&MOD(AW14,100)&"/1") -> 38139 | BG14: =VLOOKUP($BE14,AO:AQ,2,0) -> 5.6240239 | BH14: =VLOOKUP($BE14,AO:AQ,3,0) -> 17374375 | BI14: =VLOOKUP($BE14,AW:AY,2,0) -> 5.75 | BJ14: =VLOOKUP($BE14,AW:AY,3,0) -> 535000 | BK14: =(BG14*BH14+BI14*BJ14)/(BH14+BJ14) -> 5.6277871 | BL14: =VLOOKUP($BE14,AS:AU,2,0) -> 5.7981358 | BM14: =VLOOKUP($BE14,AS:AU,3,0) -> 3.4135563e+09 | BN14: =VLOOKUP($BE14,BA:BC,2,0) -> 5.723748 | BO14: =VLOOKUP($BE14,BA:BC,3,0) -> 123404415 | BP14: =(BL14*BM14+BN14*BO14)/(BM14+BO14) -> 5.7955404 | BQ14: =(BK14-BP14)*100 -> -16.775329
... A34: 38657 | B34: 5.8168693 | C34: 5605900 | E34: 38657 | F34: 5.713226 | G34: 7051921 | I34: 39630 | J34: 6.0767739 | K34: 203470424 | M34: 39630 | N34: 6.1053923 | O34: 69068187 | Q34: 38657 | R34: =VLOOKUP($Q34,A:C,2,0) -> 5.8168693 | S34: =VLOOKUP($Q34,A:C,3,0) -> 5605900 | T34: 0 | U34: 0 | V34: =(R34*S34+T34*U34)/(S34+U34) -> 5.8168693 | W34: =VLOOKUP($Q34,E:G,2,0) -> 5.713226 | X34: =VLOOKUP($Q34,E:G,3,0) -> 7051921 | Y34: 0 | Z34: 0 | AA34: =(W34*X34+Y34*Z34)/(X34+Z34) -> 5.713226 | AB34: =(V34-AA34)*100 -> 10.364329 | AO34: 200409 | AP34: 6.0038005 | AQ34: 14829155 | AS34: 198812 | AT34: 8.6477273 | AU34: 220000 | AW34: 200605 | AX34: 6.1590872 | AY34: 61689758 | BA34: 198904 | BB34: 8.75 | BC34: 46315 | BE34: 200612 | BF34: =DATEVALUE(INT(AW34/100)&"/"&MOD(AW34,100)&"/1") -> 38838 | BG34: =VLOOKUP($BE34,AO:AQ,2,0) -> 6.0881997 | BH34: =VLOOKUP($BE34,AO:AQ,3,0) -> 14418894 | BI34: =VLOOKUP($BE34,AW:AY,2,0) -> 6.0276042 | BJ34: =VLOOKUP($BE34,AW:AY,3,0) -> 56830640 | BK34: =(BG34*BH34+BI34*BJ34)/(BH34+BJ34) -> 6.039867 | BL34: =VLOOKUP($BE34,AS:AU,2,0) -> 6.3971626 | BM34: =VLOOKUP($BE34,AS:AU,3,0) -> 4.4433006e+09 | BN34: =VLOOKUP($BE34,BA:BC,2,0) -> 6.3155299 | BO34: =VLOOKUP($BE34,BA:BC,3,0) -> 17996305801 | BP34: =(BL34*BM34+BN34*BO34)/(BM34+BO34) -> 6.3316941 | BQ34: =(BK34-BP34)*100 -> -29.182712
A35: 38687 | B35: 5.6912178 | C35: 6191959 | E35: 38687 | F35: 5.9230508 | G35: 7487070 | I35: 39661 | J35: 6.2766712 | K35: 133349260 | M35: 39661 | N35: 6.3469941 | O35: 63325914 | Q35: 38687 | R35: =VLOOKUP($Q35,A:C,2,0) -> 5.6912178 | S35: =VLOOKUP($Q35,A:C,3,0) -> 6191959 | T35: =VLOOKUP($Q35,I:K,2,0) -> 5.7864762 | U35: =VLOOKUP($Q35,I:K,3,0) -> 22815990 | V35: =(R35*S35+T35*U35)/(S35+U35) -> 5.7661426 | W35: =VLOOKUP($Q35,E:G,2,0) -> 5.9230508 | X35: =VLOOKUP($Q35,E:G,3,0) -> 7487070 | Y35: =VLOOKUP($Q35,M:O,2,0) -> 5.7862689 | Z35: =VLOOKUP($Q35,M:O,3,0) -> 22159991 | AA35: =(W35*X35+Y35*Z35)/(X35+Z35) -> 5.8208118 | AB35: =(V35-AA35)*100 -> -5.4669207 | AO35: 200410 | AP35: 5.8572353 | AQ35: 24300722 | AS35: 198901 | AT35: 7.875 | AU35: 43110 | AW35: 200606 | AX35: 6.2548785 | AY35: 46448420 | BA35: 198906 | BB35: 8.1929332 | BC35: 103289 | BE35: 200701 | BF35: =DATEVALUE(INT(AW35/100)&"/"&MOD(AW35,100)&"/1") -> 38869 | BG35: =VLOOKUP($BE35,AO:AQ,2,0) -> 5.8976215 | BH35: =VLOOKUP($BE35,AO:AQ,3,0) -> 20589241 | BI35: =VLOOKUP($BE35,AW:AY,2,0) -> 5.8824931 | BJ35: =VLOOKUP($BE35,AW:AY,3,0) -> 62964722 | BK35: =(BG35*BH35+BI35*BJ35)/(BH35+BJ35) -> 5.886221 | BL35: =VLOOKUP($BE35,AS:AU,2,0) -> 6.2256958 | BM35: =VLOOKUP($BE35,AS:AU,3,0) -> 5.310016e+09 | BN35: =VLOOKUP($BE35,BA:BC,2,0) -> 6.1444367 | BO35: =VLOOKUP($BE35,BA:BC,3,0) -> 19447655093 | BP35: =(BL35*BM35+BN35*BO35)/(BM35+BO35) -> 6.1618652 | BQ35: =(BK35-BP35)*100 -> -27.564416
A36: 38718 | B36: 5.8690842 | C36: 4373898 | E36: 38718 | F36: 6.1323165 | G36: 6536570 | I36: 39692 | J36: 6.282224 | K36: 77204423 | M36: 39692 | N36: 6.4133804 | O36: 31823920 | Q36: 38718 | R36: =VLOOKUP($Q36,A:C,2,0) -> 5.8690842 | S36: =VLOOKUP($Q36,A:C,3,0) -> 4373898 | T36: =VLOOKUP($Q36,I:K,2,0) -> 5.9437237 | U36: =VLOOKUP($Q36,I:K,3,0) -> 35493184 | V36: =(R36*S36+T36*U36)/(S36+U36) -> 5.9355348 | W36: =VLOOKUP($Q36,E:G,2,0) -> 6.1323165 | X36: =VLOOKUP($Q36,E:G,3,0) -> 6536570 | Y36: =VLOOKUP($Q36,M:O,2,0) -> 5.8846358 | Z36: =VLOOKUP($Q36,M:O,3,0) -> 40584083 | AA36: =(W36*X36+Y36*Z36)/(X36+Z36) -> 5.918994 | AB36: =(V36-AA36)*100 -> 1.6540832 | AO36: 200411 | AP36: 5.7779912 | AQ36: 24864150 | AS36: 198902 | AT36: 10 | AU36: 29600 | AW36: 200607 | AX36: 6.4030623 | AY36: 62014540 | BA36: 198907 | BB36: 7.5066515 | BC36: 119034 | BE36: 200702 | BF36: =DATEVALUE(INT(AW36/100)&"/"&MOD(AW36,100)&"/1") -> 38899 | BG36: =VLOOKUP($BE36,AO:AQ,2,0) -> 5.988772 | BH36: =VLOOKUP($BE36,AO:AQ,3,0) -> 13878800 | BI36: =VLOOKUP($BE36,AW:AY,2,0) -> 5.8892332 | BJ36: =VLOOKUP($BE36,AW:AY,3,0) -> 62711121 | BK36: =(BG36*BH36+BI36*BJ36)/(BH36+BJ36) -> 5.9072705 | BL36: =VLOOKUP($BE36,AS:AU,2,0) -> 6.231454 | BM36: =VLOOKUP($BE36,AS:AU,3,0) -> 4.8222434e+09 | BN36: =VLOOKUP($BE36,BA:BC,2,0) -> 6.1388584 | BO36: =VLOOKUP($BE36,BA:BC,3,0) -> 16559778229 | BP36: =(BL36*BM36+BN36*BO36)/(BM36+BO36) -> 6.1597413 | BQ36: =(BK36-BP36)*100 -> -25.24708
A37: 38749 | B37: 5.9717978 | C37: 3024475 | E37: 38749 | F37: 6.1167705 | G37: 4681537 | I37: 39722 | J37: 6.4479666 | K37: 128234681 | M37: 39722 | N37: 6.539903 | O37: 70770153 | Q37: 38749 | R37: =VLOOKUP($Q37,A:C,2,0) -> 5.9717978 | S37: =VLOOKUP($Q37,A:C,3,0) -> 3024475 | T37: =VLOOKUP($Q37,I:K,2,0) -> 5.945174 | U37: =VLOOKUP($Q37,I:K,3,0) -> 29389764 | V37: =(R37*S37+T37*U37)/(S37+U37) -> 5.9476582 | W37: =VLOOKUP($Q37,E:G,2,0) -> 6.1167705 | X37: =VLOOKUP($Q37,E:G,3,0) -> 4681537 | Y37: =VLOOKUP($Q37,M:O,2,0) -> 6.0619456 | Z37: =VLOOKUP($Q37,M:O,3,0) -> 30099776 | AA37: =(W37*X37+Y37*Z37)/(X37+Z37) -> 6.069325 | AB37: =(V37-AA37)*100 -> -12.166684 | AO37: 200412 | AP37: 5.7383682 | AQ37: 29629350 | AS37: 198903 | AT37: 9.8864763 | AU37: 95850 | AW37: 200608 | AX37: 6.5296005 | AY37: 62627291 | BA37: 198908 | BB37: 8.6220969 | BC37: 42196 | BE37: 200703 | BF37: =DATEVALUE(INT(AW37/100)&"/"&MOD(AW37,100)&"/1") -> 38930 | BG37: =VLOOKUP($BE37,AO:AQ,2,0) -> 5.9396814 | BH37: =VLOOKUP($BE37,AO:AQ,3,0) -> 8818800 | BI37: =VLOOKUP($BE37,AW:AY,2,0) -> 5.9841568 | BJ37: =VLOOKUP($BE37,AW:AY,3,0) -> 59707619 | BK37: =(BG37*BH37+BI37*BJ37)/(BH37+BJ37) -> 5.9784332 | BL37: =VLOOKUP($BE37,AS:AU,2,0) -> 6.3274898 | BM37: =VLOOKUP($BE37,AS:AU,3,0) -> 4.4743488e+09 | BN37: =VLOOKUP($BE37,BA:BC,2,0) -> 6.2348178 | BO37: =VLOOKUP($BE37,BA:BC,3,0) -> 16353600217 | BP37: =(BL37*BM37+BN37*BO37)/(BM37+BO37) -> 6.254726 | BQ37: =(BK37-BP37)*100 -> -27.629278
A38: 38777 | B38: 6.0169911 | C38: 4469625 | E38: 38777 | F38: 6.0562589 | G38: 10592375 | I38: 39753 | J38: 5.9975538 | K38: 75612505 | M38: 39753 | N38: 6.1779503 | O38: 42467260 | Q38: 38777 | R38: =VLOOKUP($Q38,A:C,2,0) -> 6.0169911 | S38: =VLOOKUP($Q38,A:C,3,0) -> 4469625 | T38: =VLOOKUP($Q38,I:K,2,0) -> 5.9327354 | U38: =VLOOKUP($Q38,I:K,3,0) -> 30459910 | V38: =(R38*S38+T38*U38)/(S38+U38) -> 5.9435169 | W38: =VLOOKUP($Q38,E:G,2,0) -> 6.0562589 | X38: =VLOOKUP($Q38,E:G,3,0) -> 10592375 | Y38: =VLOOKUP($Q38,M:O,2,0) -> 6.0181337 | Z38: =VLOOKUP($Q38,M:O,3,0) -> 33370270 | AA38: =(W38*X38+Y38*Z38)/(X38+Z38) -> 6.0273196 | AB38: =(V38-AA38)*100 -> -8.3802774 | AO38: 200501 | AP38: 5.6688293 | AQ38: 34147214 | AS38: 198904 | AT38: 9.875 | AU38: 34500 | AW38: 200609 | AX38: 6.3579778 | AY38: 50191495 | BA38: 198909 | BB38: 9.625 | BC38: 32800 | BE38: 200704 | BF38: =DATEVALUE(INT(AW38/100)&"/"&MOD(AW38,100)&"/1") -> 38961 | BG38: =VLOOKUP($BE38,AO:AQ,2,0) -> 6.0357502 | BH38: =VLOOKUP($BE38,AO:AQ,3,0) -> 22734042 | BI38: =VLOOKUP($BE38,AW:AY,2,0) -> 5.9464103 | BJ38: =VLOOKUP($BE38,AW:AY,3,0) -> 80179842 | BK38: =(BG38*BH38+BI38*BJ38)/(BH38+BJ38) -> 5.9661458 | BL38: =VLOOKUP($BE38,AS:AU,2,0) -> 6.264772 | BM38: =VLOOKUP($BE38,AS:AU,3,0) -> 5.5898112e+09 | BN38: =VLOOKUP($BE38,BA:BC,2,0) -> 6.1888058 | BO38: =VLOOKUP($BE38,BA:BC,3,0) -> 21110288744 | BP38: =(BL38*BM38+BN38*BO38)/(BM38+BO38) -> 6.2047098 | BQ38: =(BK38-BP38)*100 -> -23.8564
A39: 38808 | B39: 6.0473757 | C39: 6237900 | E39: 38808 | F39: 6.1659454 | G39: 9578675 | I39: 39783 | J39: 6.0180125 | K39: 101661190 | M39: 39783 | N39: 6.1147871 | O39: 58090120 | Q39: 38808 | R39: =VLOOKUP($Q39,A:C,2,0) -> 6.0473757 | S39: =VLOOKUP($Q39,A:C,3,0) -> 6237900 | T39: =VLOOKUP($Q39,I:K,2,0) -> 5.9637765 | U39: =VLOOKUP($Q39,I:K,3,0) -> 23105765 | V39: =(R39*S39+T39*U39)/(S39+U39) -> 5.9815481 | W39: =VLOOKUP($Q39,E:G,2,0) -> 6.1659454 | X39: =VLOOKUP($Q39,E:G,3,0) -> 9578675 | Y39: =VLOOKUP($Q39,M:O,2,0) -> 6.0313289 | Z39: =VLOOKUP($Q39,M:O,3,0) -> 24221125 | AA39: =(W39*X39+Y39*Z39)/(X39+Z39) -> 6.0694785 | AB39: =(V39-AA39)*100 -> -8.7930386 | AO39: 200502 | AP39: 5.6240239 | AQ39: 17374375 | AS39: 198905 | AT39: 11.5 | AU39: 39150 | AW39: 200610 | AX39: 6.1712891 | AY39: 53065417 | BA39: 198910 | BB39: 7.625 | BC39: 60437 | BE39: 200705 | BF39: =DATEVALUE(INT(AW39/100)&"/"&MOD(AW39,100)&"/1") -> 38991 | BG39: =VLOOKUP($BE39,AO:AQ,2,0) -> 5.9872911 | BH39: =VLOOKUP($BE39,AO:AQ,3,0) -> 26181475 | BI39: =VLOOKUP($BE39,AW:AY,2,0) -> 5.8912394 | BJ39: =VLOOKUP($BE39,AW:AY,3,0) -> 83554239 | BK39: =(BG39*BH39+BI39*BJ39)/(BH39+BJ39) -> 5.9141561 | BL39: =VLOOKUP($BE39,AS:AU,2,0) -> 6.2554837 | BM39: =VLOOKUP($BE39,AS:AU,3,0) -> 5.9262307e+09 | BN39: =VLOOKUP($BE39,BA:BC,2,0) -> 6.1664867 | BO39: =VLOOKUP($BE39,BA:BC,3,0) -> 20455591540 | BP39: =(BL39*BM39+BN39*BO39)/(BM39+BO39) -> 6.1864784 | BQ39: =(BK39-BP39)*100 -> -27.232231
A40: 38838 | B40: 6.2691606 | C40: 3425000 | E40: 38838 | F40: 6.1816776 | G40: 6505000 | I40: 39814 | J40: 5.5021271 | K40: 229832959 | M40: 39814 | N40: 5.7140389 | O40: 59033175 | Q40: 38838 | R40: =VLOOKUP($Q40,A:C,2,0) -> 6.2691606 | S40: =VLOOKUP($Q40,A:C,3,0) -> 3425000 | T40: =VLOOKUP($Q40,I:K,2,0) -> 6.0319394 | U40: =VLOOKUP($Q40,I:K,3,0) -> 37337908 | V40: =(R40*S40+T40*U40)/(S40+U40) -> 6.0518713 | W40: =VLOOKUP($Q40,E:G,2,0) -> 6.1816776 | X40: =VLOOKUP($Q40,E:G,3,0) -> 6505000 | Y40: =VLOOKUP($Q40,M:O,2,0) -> 6.1200181 | Z40: =VLOOKUP($Q40,M:O,3,0) -> 28001250 | AA40: =(W40*X40+Y40*Z40)/(X40+Z40) -> 6.1316419 | AB40: =(V40-AA40)*100 -> -7.977061 | AO40: 200503 | AP40: 5.6558361 | AQ40: 25542006 | AS40: 198907 | AT40: 9.875 | AU40: 43700 | AW40: 200611 | AX40: 6.0771989 | AY40: 76716916 | BA40: 198911 | BB40: 7.25 | BC40: 18981 | BE40: 200706 | BF40: =DATEVALUE(INT(AW40/100)&"/"&MOD(AW40,100)&"/1") -> 39022 | BG40: =VLOOKUP($BE40,AO:AQ,2,0) -> 6.0739246 | BH40: =VLOOKUP($BE40,AO:AQ,3,0) -> 31527834 | BI40: =VLOOKUP($BE40,AW:AY,2,0) -> 6.0183757 | BJ40: =VLOOKUP($BE40,AW:AY,3,0) -> 79049237 | BK40: =(BG40*BH40+BI40*BJ40)/(BH40+BJ40) -> 6.0342139 | BL40: =VLOOKUP($BE40,AS:AU,2,0) -> 6.2985263 | BM40: =VLOOKUP($BE40,AS:AU,3,0) -> 6.213146e+09 | BN40: =VLOOKUP($BE40,BA:BC,2,0) -> 6.24004 | BO40: =VLOOKUP($BE40,BA:BC,3,0) -> 19399905338 | BP40: =(BL40*BM40+BN40*BO40)/(BM40+BO40) -> 6.2542274 | BQ40: =(BK40-BP40)*100 -> -22.001356
A41: 38869 | B41: 6.2632386 | C41: 2477600 | E41: 38869 | F41: 6.4192662 | G41: 7523800 | I41: 39845 | J41: 5.2496838 | K41: 802621662 | M41: 39845 | N41: 5.3658936 | O41: 203142874 | Q41: 38869 | R41: =VLOOKUP($Q41,A:C,2,0) -> 6.2632386 | S41: =VLOOKUP($Q41,A:C,3,0) -> 2477600 | T41: =VLOOKUP($Q41,I:K,2,0) -> 6.2758067 | U41: =VLOOKUP($Q41,I:K,3,0) -> 31251520 | V41: =(R41*S41+T41*U41)/(S41+U41) -> 6.2748835 | W41: =VLOOKUP($Q41,E:G,2,0) -> 6.4192662 | X41: =VLOOKUP($Q41,E:G,3,0) -> 7523800 | Y41: =VLOOKUP($Q41,M:O,2,0) -> 6.3300807 | Z41: =VLOOKUP($Q41,M:O,3,0) -> 27142358 | AA41: =(W41*X41+Y41*Z41)/(X41+Z41) -> 6.3494372 | AB41: =(V41-AA41)*100 -> -7.4553637 | AO41: 200504 | AP41: 5.6706425 | AQ41: 48371643 | AS41: 198908 | AT41: 7.375 | AU41: 108100 | AW41: 200612 | AX41: 6.0276042 | AY41: 56830640 | BA41: 198912 | BB41: 9.875 | BC41: 66000 | BE41: 200707 | BF41: =DATEVALUE(INT(AW41/100)&"/"&MOD(AW41,100)&"/1") -> 39052 | BG41: =VLOOKUP($BE41,AO:AQ,2,0) -> 6.2206265 | BH41: =VLOOKUP($BE41,AO:AQ,3,0) -> 16753926 | BI41: =VLOOKUP($BE41,AW:AY,2,0) -> 6.2300617 | BJ41: =VLOOKUP($BE41,AW:AY,3,0) -> 57651605 | BK41: =(BG41*BH41+BI41*BJ41)/(BH41+BJ41) -> 6.2279371 | BL41: =VLOOKUP($BE41,AS:AU,2,0) -> 6.4565374 | BM41: =VLOOKUP($BE41,AS:AU,3,0) -> 5.1342036e+09 | BN41: =VLOOKUP($BE41,BA:BC,2,0) -> 6.4375155 | BO41: =VLOOKUP($BE41,BA:BC,3,0) -> 17364748539 | BP41: =(BL41*BM41+BN41*BO41)/(BM41+BO41) -> 6.4418562 | BQ41: =(BK41-BP41)*100 -> -21.391907
A42: 38899 | B42: 6.4022221 | C42: 3499000 | E42: 38899 | F42: 6.6109988 | G42: 3214000 | I42: 39873 | J42: 5.0043539 | K42: 1772490637 | M42: 39873 | N42: 5.045936 | O42: 399285730 | Q42: 38899 | R42: =VLOOKUP($Q42,A:C,2,0) -> 6.4022221 | S42: =VLOOKUP($Q42,A:C,3,0) -> 3499000 | T42: =VLOOKUP($Q42,I:K,2,0) -> 6.2844319 | U42: =VLOOKUP($Q42,I:K,3,0) -> 24808750 | V42: =(R42*S42+T42*U42)/(S42+U42) -> 6.2989914 | W42: =VLOOKUP($Q42,E:G,2,0) -> 6.6109988 | X42: =VLOOKUP($Q42,E:G,3,0) -> 3214000 | Y42: =VLOOKUP($Q42,M:O,2,0) -> 6.3767725 | Z42: =VLOOKUP($Q42,M:O,3,0) -> 27242700 | AA42: =(W42*X42+Y42*Z42)/(X42+Z42) -> 6.4014897 | AB42: =(V42-AA42)*100 -> -10.249821 | AO42: 200505 | AP42: 5.8192911 | AQ42: 39335463 | AS42: 198909 | AT42: 9.0690184 | AU42: 362150 | AW42: 200701 | AX42: 5.8824931 | AY42: 62964722 | BA42: 199003 | BB42: 8.25 | BC42: 47994 | BE42: 200708 | BF42: =DATEVALUE(INT(AW42/100)&"/"&MOD(AW42,100)&"/1") -> 39083 | BG42: =VLOOKUP($BE42,AO:AQ,2,0) -> 6.5375361 | BH42: =VLOOKUP($BE42,AO:AQ,3,0) -> 13383700 | BI42: =VLOOKUP($BE42,AW:AY,2,0) -> 6.3772621 | BJ42: =VLOOKUP($BE42,AW:AY,3,0) -> 48549800 | BK42: =(BG42*BH42+BI42*BJ42)/(BH42+BJ42) -> 6.411897 | BL42: =VLOOKUP($BE42,AS:AU,2,0) -> 6.7238616 | BM42: =VLOOKUP($BE42,AS:AU,3,0) -> 3.9252434e+09 | BN42: =VLOOKUP($BE42,BA:BC,2,0) -> 6.6811284 | BO42: =VLOOKUP($BE42,BA:BC,3,0) -> 15140103088 | BP42: =(BL42*BM42+BN42*BO42)/(BM42+BO42) -> 6.6899265 | BQ42: =(BK42-BP42)*100 -> -27.802951
A43: 38930 | B43: 6.4735523 | C43: 4287700 | E43: 38930 | F43: 6.6012416 | G43: 7663600 | I43: 39904 | J43: 4.9529414 | K43: 1822454826 | M43: 39904 | N43: 5.0255697 | O43: 413556978 | Q43: 38930 | R43: =VLOOKUP($Q43,A:C,2,0) -> 6.4735523 | S43: =VLOOKUP($Q43,A:C,3,0) -> 4287700 | T43: =VLOOKUP($Q43,I:K,2,0) -> 6.4199066 | U43: =VLOOKUP($Q43,I:K,3,0) -> 25865766 | V43: =(R43*S43+T43*U43)/(S43+U43) -> 6.4275348 | W43: =VLOOKUP($Q43,E:G,2,0) -> 6.6012416 | X43: =VLOOKUP($Q43,E:G,3,0) -> 7663600 | Y43: =VLOOKUP($Q43,M:O,2,0) -> 6.4693391 | Z43: =VLOOKUP($Q43,M:O,3,0) -> 25911500 | AA43: =(W43*X43+Y43*Z43)/(X43+Z43) -> 6.4994462 | AB43: =(V43-AA43)*100 -> -7.1911431 | AO43: 200506 | AP43: 5.7629275 | AQ43: 37985872 | AS43: 198910 | AT43: 9.5 | AU43: 47250 | AW43: 200702 | AX43: 5.8892332 | AY43: 62711121 | BA43: 199006 | BB43: 7.4567294 | BC43: 289651 | BE43: 200709 | BF43: =DATEVALUE(INT(AW43/100)&"/"&MOD(AW43,100)&"/1") -> 39114 | BG43: =VLOOKUP($BE43,AO:AQ,2,0) -> 6.5699224 | BH43: =VLOOKUP($BE43,AO:AQ,3,0) -> 15792151 | BI43: =VLOOKUP($BE43,AW:AY,2,0) -> 6.4813951 | BJ43: =VLOOKUP($BE43,AW:AY,3,0) -> 48010764 | BK43: =(BG43*BH43+BI43*BJ43)/(BH43+BJ43) -> 6.5033069 | BL43: =VLOOKUP($BE43,AS:AU,2,0) -> 6.7501479 | BM43: =VLOOKUP($BE43,AS:AU,3,0) -> 4.118855e+09 | BN43: =VLOOKUP($BE43,BA:BC,2,0) -> 6.684341 | BO43: =VLOOKUP($BE43,BA:BC,3,0) -> 14918196885 | BP43: =(BL43*BM43+BN43*BO43)/(BM43+BO43) -> 6.698579 | BQ43: =(BK43-BP43)*100 -> -19.527211
A44: 38961 | B44: 6.3834797 | C44: 4995446 | E44: 38961 | F44: 6.4662596 | G44: 3776061 | I44: 39934 | J44: 4.9302745 | K44: 1925414134 | M44: 39934 | N44: 4.9714065 | O44: 421224251 | Q44: 38961 | R44: =VLOOKUP($Q44,A:C,2,0) -> 6.3834797 | S44: =VLOOKUP($Q44,A:C,3,0) -> 4995446 | T44: =VLOOKUP($Q44,I:K,2,0) -> 6.4051004 | U44: =VLOOKUP($Q44,I:K,3,0) -> 27942450 | V44: =(R44*S44+T44*U44)/(S44+U44) -> 6.4018213 | W44: =VLOOKUP($Q44,E:G,2,0) -> 6.4662596 | X44: =VLOOKUP($Q44,E:G,3,0) -> 3776061 | Y44: =VLOOKUP($Q44,M:O,2,0) -> 6.4840707 | Z44: =VLOOKUP($Q44,M:O,3,0) -> 22836117 | AA44: =(W44*X44+Y44*Z44)/(X44+Z44) -> 6.4815434 | AB44: =(V44-AA44)*100 -> -7.9722082 | AO44: 200507 | AP44: 5.7181308 | AQ44: 50970440 | AS44: 198911 | AT44: 9.9019461 | AU44: 100200 | AW44: 200703 | AX44: 5.9841568 | AY44: 59707619 | BA44: 199007 | BB44: 8.375 | BC44: 70000 | BE44: 200710 | BF44: =DATEVALUE(INT(AW44/100)&"/"&MOD(AW44,100)&"/1") -> 39142 | BG44: =VLOOKUP($BE44,AO:AQ,2,0) -> 6.2683589 | BH44: =VLOOKUP($BE44,AO:AQ,3,0) -> 13407970 | BI44: =VLOOKUP($BE44,AW:AY,2,0) -> 6.2729881 | BJ44: =VLOOKUP($BE44,AW:AY,3,0) -> 59274402 | BK44: =(BG44*BH44+BI44*BJ44)/(BH44+BJ44) -> 6.2721341 | BL44: =VLOOKUP($BE44,AS:AU,2,0) -> 6.5961123 | BM44: =VLOOKUP($BE44,AS:AU,3,0) -> 4.0821233e+09 | BN44: =VLOOKUP($BE44,BA:BC,2,0) -> 6.5481771 | BO44: =VLOOKUP($BE44,BA:BC,3,0) -> 13501033240 | BP44: =(BL44*BM44+BN44*BO44)/(BM44+BO44) -> 6.5593058 | BQ44: =(BK44-BP44)*100 -> -28.717166
A45: 38991 | B45: 6.3847131 | C45: 5526790 | E45: 38991 | F45: 6.3134056 | G45: 5020750 | I45: 39965 | J45: 4.8882578 | K45: 2434241048 | M45: 39965 | N45: 4.9526677 | O45: 518161716 | Q45: 38991 | R45: =VLOOKUP($Q45,A:C,2,0) -> 6.3847131 | S45: =VLOOKUP($Q45,A:C,3,0) -> 5526790 | T45: =VLOOKUP($Q45,I:K,2,0) -> 6.2922836 | U45: =VLOOKUP($Q45,I:K,3,0) -> 26315228 | V45: =(R45*S45+T45*U45)/(S45+U45) -> 6.3083265 | W45: =VLOOKUP($Q45,E:G,2,0) -> 6.3134056 | X45: =VLOOKUP($Q45,E:G,3,0) -> 5020750 | Y45: =VLOOKUP($Q45,M:O,2,0) -> 6.3558868 | Z45: =VLOOKUP($Q45,M:O,3,0) -> 21743150 | AA45: =(W45*X45+Y45*Z45)/(X45+Z45) -> 6.3479176 | AB45: =(V45-AA45)*100 -> -3.9591084 | AO45: 200508 | AP45: 5.5959505 | AQ45: 56984892 | AS45: 198912 | AT45: 9.5 | AU45: 52350 | AW45: 200704 | AX45: 5.9464103 | AY45: 80179842 | BA45: 199008 | BB45: 7.625 | BC45: 103388 | BE45: 200711 | BF45: =DATEVALUE(INT(AW45/100)&"/"&MOD(AW45,100)&"/1") -> 39173 | BG45: =VLOOKUP($BE45,AO:AQ,2,0) -> 6.2182273 | BH45: =VLOOKUP($BE45,AO:AQ,3,0) -> 28515450 | BI45: =VLOOKUP($BE45,AW:AY,2,0) -> 6.1765181 | BJ45: =VLOOKUP($BE45,AW:AY,3,0) -> 55243320 | BK45: =(BG45*BH45+BI45*BJ45)/(BH45+BJ45) -> 6.1907179 | BL45: =VLOOKUP($BE45,AS:AU,2,0) -> 6.5049494 | BM45: =VLOOKUP($BE45,AS:AU,3,0) -> 4.9140296e+09 | BN45: =VLOOKUP($BE45,BA:BC,2,0) -> 6.4818337 | BO45: =VLOOKUP($BE45,BA:BC,3,0) -> 15334953232 | BP45: =(BL45*BM45+BN45*BO45)/(BM45+BO45) -> 6.4874434 | BQ45: =(BK45-BP45)*100 -> -29.672556
A46: 39022 | B46: 6.025314 | C46: 4967600 | E46: 39022 | F46: 6.1499587 | G46: 3749200 | I46: 39995 | J46: 4.9290046 | K46: 1909218702 | M46: 39995 | N46: 5.0074628 | O46: 424787797 | Q46: 39022 | R46: =VLOOKUP($Q46,A:C,2,0) -> 6.025314 | S46: =VLOOKUP($Q46,A:C,3,0) -> 4967600 | T46: =VLOOKUP($Q46,I:K,2,0) -> 6.0857292 | U46: =VLOOKUP($Q46,I:K,3,0) -> 21368896 | V46: =(R46*S46+T46*U46)/(S46+U46) -> 6.0743336 | W46: =VLOOKUP($Q46,E:G,2,0) -> 6.1499587 | X46: =VLOOKUP($Q46,E:G,3,0) -> 3749200 | Y46: =VLOOKUP($Q46,M:O,2,0) -> 6.1714087 | Z46: =VLOOKUP($Q46,M:O,3,0) -> 29131494 | AA46: =(W46*X46+Y46*Z46)/(X46+Z46) -> 6.1689628 | AB46: =(V46-AA46)*100 -> -9.4629202 | AO46: 200509 | AP46: 5.679906 | AQ46: 41468070 | AS46: 199001 | AT46: 9.1378386 | AU46: 117351 | AW46: 200705 | AX46: 5.8912394 | AY46: 83554239 | BA46: 199009 | BB46: 8.810688 | BC46: 284565 | BE46: 200712 | BF46: =DATEVALUE(INT(AW46/100)&"/"&MOD(AW46,100)&"/1") -> 39203 | BG46: =VLOOKUP($BE46,AO:AQ,2,0) -> 6.1684057 | BH46: =VLOOKUP($BE46,AO:AQ,3,0) -> 18670035 | BI46: =VLOOKUP($BE46,AW:AY,2,0) -> 6.1006424 | BJ46: =VLOOKUP($BE46,AW:AY,3,0) -> 62858740 | BK46: =(BG46*BH46+BI46*BJ46)/(BH46+BJ46) -> 6.1161601 | BL46: =VLOOKUP($BE46,AS:AU,2,0) -> 6.4136691 | BM46: =VLOOKUP($BE46,AS:AU,3,0) -> 4.8920491e+09 | BN46: =VLOOKUP($BE46,BA:BC,2,0) -> 6.3627999 | BO46: =VLOOKUP($BE46,BA:BC,3,0) -> 13888587684 | BP46: =(BL46*BM46+BN46*BO46)/(BM46+BO46) -> 6.3760505 | BQ46: =(BK46-BP46)*100 -> -25.989035
... A123: 41365 | B123: 3.7319712 | C123: 3.473621e+09 | E123: 41365 | F123: 3.8206332 | G123: 9.2380805e+08 | I123: 42339 | J123: 4.1351055 | K123: 359030819 | M123: 42339 | N123: 4.3712526 | O123: 265674913 | Q123: 41365 | R123: =VLOOKUP($Q123,A:C,2,0) -> 3.7319712 | S123: =VLOOKUP($Q123,A:C,3,0) -> 3.473621e+09 | T123: =VLOOKUP($Q123,I:K,2,0) -> 3.7335776 | U123: =VLOOKUP($Q123,I:K,3,0) -> 1406909862 | V123: =(R123*S123+T123*U123)/(S123+U123) -> 3.7324342 | W123: =VLOOKUP($Q123,E:G,2,0) -> 3.8206332 | X123: =VLOOKUP($Q123,E:G,3,0) -> 9.2380805e+08 | Y123: =VLOOKUP($Q123,M:O,2,0) -> 3.8492168 | Z123: =VLOOKUP($Q123,M:O,3,0) -> 435434397 | AA123: =(W123*X123+Y123*Z123)/(X123+Z123) -> 3.82979 | AB123: =(V123-AA123)*100 -> -9.7355741 | AO123: 201202 | AP123: 4.1761331 | AQ123: 3.1726755e+09 | AS123: 199606 | AT123: 7.9428142 | AU123: 2861438 | AW123: 201310 | AX123: 4.6972928 | AY123: 813187254 | BA123: 199702 | BB123: 7.8238247 | BC123: 3278330 | BE123: 201405 | BF123: =DATEVALUE(INT(AW123/100)&"/"&MOD(AW123,100)&"/1") -> 41548 | BG123: =VLOOKUP($BE123,AO:AQ,2,0) -> 4.5911349 | BH123: =VLOOKUP($BE123,AO:AQ,3,0) -> 1.2966068e+09 | BI123: =VLOOKUP($BE123,AW:AY,2,0) -> 4.601509 | BJ123: =VLOOKUP($BE123,AW:AY,3,0) -> 1069120555 | BK123: =(BG123*BH123+BI123*BJ123)/(BH123+BJ123) -> 4.5958231 | BL123: =VLOOKUP($BE123,AS:AU,2,0) -> 4.630367 | BM123: =VLOOKUP($BE123,AS:AU,3,0) -> 1.0615149e+10 | BN123: =VLOOKUP($BE123,BA:BC,2,0) -> 4.5799148 | BO123: =VLOOKUP($BE123,BA:BC,3,0) -> 7811056161 | BP123: =(BL123*BM123+BN123*BO123)/(BM123+BO123) -> 4.6089798 | BQ123: =(BK123-BP123)*100 -> -1.3156626
A124: 41395 | B124: 3.7642437 | C124: 3.4914329e+09 | E124: 41395 | F124: 3.8738365 | G124: 9.4379757e+08 | Q124: 41395 | R124: =VLOOKUP($Q124,A:C,2,0) -> 3.7642437 | S124: =VLOOKUP($Q124,A:C,3,0) -> 3.4914329e+09 | T124: =VLOOKUP($Q124,I:K,2,0) -> 3.761304 | U124: =VLOOKUP($Q124,I:K,3,0) -> 1398983889 | V124: =(R124*S124+T124*U124)/(S124+U124) -> 3.7634028 | W124: =VLOOKUP($Q124,E:G,2,0) -> 3.8738365 | X124: =VLOOKUP($Q124,E:G,3,0) -> 9.4379757e+08 | Y124: =VLOOKUP($Q124,M:O,2,0) -> 3.8755758 | Z124: =VLOOKUP($Q124,M:O,3,0) -> 467749117 | AA124: =(W124*X124+Y124*Z124)/(X124+Z124) -> 3.8744129 | AB124: =(V124-AA124)*100 -> -11.101012 | AO124: 201203 | AP124: 4.1128968 | AQ124: 3.8565397e+09 | AS124: 199607 | AT124: 8.2292798 | AU124: 2296485.8 | AW124: 201311 | AX124: 4.613467 | AY124: 1043332765 | BA124: 199703 | BB124: 7.8264595 | BC124: 2009645 | BE124: 201406 | BF124: =DATEVALUE(INT(AW124/100)&"/"&MOD(AW124,100)&"/1") -> 41579 | BG124: =VLOOKUP($BE124,AO:AQ,2,0) -> 4.516574 | BH124: =VLOOKUP($BE124,AO:AQ,3,0) -> 1.4786018e+09 | BI124: =VLOOKUP($BE124,AW:AY,2,0) -> 4.532351 | BJ124: =VLOOKUP($BE124,AW:AY,3,0) -> 1235754412 | BK124: =(BG124*BH124+BI124*BJ124)/(BH124+BJ124) -> 4.5237567 | BL124: =VLOOKUP($BE124,AS:AU,2,0) -> 4.573264 | BM124: =VLOOKUP($BE124,AS:AU,3,0) -> 1.2139069e+10 | BN124: =VLOOKUP($BE124,BA:BC,2,0) -> 4.5300965 | BO124: =VLOOKUP($BE124,BA:BC,3,0) -> 8459702562 | BP124: =(BL124*BM124+BN124*BO124)/(BM124+BO124) -> 4.5555356 | BQ124: =(BK124-BP124)*100 -> -3.1778868
A125: 41426 | B125: 3.7167 | C125: 3.574777e+09 | E125: 41426 | F125: 3.8266986 | G125: 9.2067881e+08 | Q125: 41426 | R125: =VLOOKUP($Q125,A:C,2,0) -> 3.7167 | S125: =VLOOKUP($Q125,A:C,3,0) -> 3.574777e+09 | T125: =VLOOKUP($Q125,I:K,2,0) -> 3.7173295 | U125: =VLOOKUP($Q125,I:K,3,0) -> 1626943702 | V125: =(R125*S125+T125*U125)/(S125+U125) -> 3.7168969 | W125: =VLOOKUP($Q125,E:G,2,0) -> 3.8266986 | X125: =VLOOKUP($Q125,E:G,3,0) -> 9.2067881e+08 | Y125: =VLOOKUP($Q125,M:O,2,0) -> 3.8567514 | Z125: =VLOOKUP($Q125,M:O,3,0) -> 505292286 | AA125: =(W125*X125+Y125*Z125)/(X125+Z125) -> 3.8373478 | AB125: =(V125-AA125)*100 -> -12.045093 | AO125: 201204 | AP125: 4.0928998 | AQ125: 3.7492728e+09 | AS125: 199608 | AT125: 8.2089603 | AU125: 2984417.6 | AW125: 201312 | AX125: 4.4777196 | AY125: 1218362562 | BA125: 199704 | BB125: 7.9097302 | BC125: 3374060 | BE125: 201407 | BF125: =DATEVALUE(INT(AW125/100)&"/"&MOD(AW125,100)&"/1") -> 41609 | BG125: =VLOOKUP($BE125,AO:AQ,2,0) -> 4.3994309 | BH125: =VLOOKUP($BE125,AO:AQ,3,0) -> 1.9944411e+09 | BI125: =VLOOKUP($BE125,AW:AY,2,0) -> 4.4192572 | BJ125: =VLOOKUP($BE125,AW:AY,3,0) -> 1653218353 | BK125: =(BG125*BH125+BI125*BJ125)/(BH125+BJ125) -> 4.4084167 | BL125: =VLOOKUP($BE125,AS:AU,2,0) -> 4.4559119 | BM125: =VLOOKUP($BE125,AS:AU,3,0) -> 1.3675313e+10 | BN125: =VLOOKUP($BE125,BA:BC,2,0) -> 4.4057272 | BO125: =VLOOKUP($BE125,BA:BC,3,0) -> 10042256705 | BP125: =(BL125*BM125+BN125*BO125)/(BM125+BO125) -> 4.4346632 | BQ125: =(BK125-BP125)*100 -> -2.6246523
A126: 41456 | B126: 3.7909483 | C126: 3.2709791e+09 | E126: 41456 | F126: 3.9033376 | G126: 1.0463391e+09 | Q126: 41456 | R126: =VLOOKUP($Q126,A:C,2,0) -> 3.7909483 | S126: =VLOOKUP($Q126,A:C,3,0) -> 3.2709791e+09 | T126: =VLOOKUP($Q126,I:K,2,0) -> 3.7501655 | U126: =VLOOKUP($Q126,I:K,3,0) -> 1504802517 | V126: =(R126*S126+T126*U126)/(S126+U126) -> 3.778098 | W126: =VLOOKUP($Q126,E:G,2,0) -> 3.9033376 | X126: =VLOOKUP($Q126,E:G,3,0) -> 1.0463391e+09 | Y126: =VLOOKUP($Q126,M:O,2,0) -> 3.9074155 | Z126: =VLOOKUP($Q126,M:O,3,0) -> 500173071 | AA126: =(W126*X126+Y126*Z126)/(X126+Z126) -> 3.9046564 | AB126: =(V126-AA126)*100 -> -12.655843 | AO126: 201205 | AP126: 4.1304714 | AQ126: 3.0994959e+09 | AS126: 199609 | AT126: 7.9810594 | AU126: 2350165.1 | AW126: 201401 | AX126: 4.5677657 | AY126: 1117025802 | BA126: 199705 | BB126: 7.8277393 | BC126: 3081547 | BE126: 201408 | BF126: =DATEVALUE(INT(AW126/100)&"/"&MOD(AW126,100)&"/1") -> 41640 | BG126: =VLOOKUP($BE126,AO:AQ,2,0) -> 4.3764155 | BH126: =VLOOKUP($BE126,AO:AQ,3,0) -> 1.8805004e+09 | BI126: =VLOOKUP($BE126,AW:AY,2,0) -> 4.3977899 | BJ126: =VLOOKUP($BE126,AW:AY,3,0) -> 1621150843 | BK126: =(BG126*BH126+BI126*BJ126)/(BH126+BJ126) -> 4.3863111 | BL126: =VLOOKUP($BE126,AS:AU,2,0) -> 4.4254967 | BM126: =VLOOKUP($BE126,AS:AU,3,0) -> 1.39276e+10 | BN126: =VLOOKUP($BE126,BA:BC,2,0) -> 4.3735477 | BO126: =VLOOKUP($BE126,BA:BC,3,0) -> 10647354204 | BP126: =(BL126*BM126+BN126*BO126)/(BM126+BO126) -> 4.4029893 | BQ126: =(BK126-BP126)*100 -> -1.6678106
A127: 41487 | B127: 4.0469353 | C127: 2.768166e+09 | E127: 41487 | F127: 4.2005282 | G127: 9.9900022e+08 | Q127: 41487 | R127: =VLOOKUP($Q127,A:C,2,0) -> 4.0469353 | S127: =VLOOKUP($Q127,A:C,3,0) -> 2.768166e+09 | T127: =VLOOKUP($Q127,I:K,2,0) -> 3.9373877 | U127: =VLOOKUP($Q127,I:K,3,0) -> 1276360626 | V127: =(R127*S127+T127*U127)/(S127+U127) -> 4.0123646 | W127: =VLOOKUP($Q127,E:G,2,0) -> 4.2005282 | X127: =VLOOKUP($Q127,E:G,3,0) -> 9.9900022e+08 | Y127: =VLOOKUP($Q127,M:O,2,0) -> 4.0877023 | Z127: =VLOOKUP($Q127,M:O,3,0) -> 499911736 | AA127: =(W127*X127+Y127*Z127)/(X127+Z127) -> 4.1628989 | AB127: =(V127-AA127)*100 -> -15.053429 | AO127: 201206 | AP127: 4.0922502 | AQ127: 3.549728e+09 | AS127: 199610 | AT127: 8.3278458 | AU127: 2185366 | AW127: 201402 | AX127: 4.6983754 | AY127: 745102196 | BA127: 199706 | BB127: 7.9572283 | BC127: 2637234 | BE127: 201409 | BF127: =DATEVALUE(INT(AW127/100)&"/"&MOD(AW127,100)&"/1") -> 41671 | BG127: =VLOOKUP($BE127,AO:AQ,2,0) -> 4.3742439 | BH127: =VLOOKUP($BE127,AO:AQ,3,0) -> 1.8238912e+09 | BI127: =VLOOKUP($BE127,AW:AY,2,0) -> 4.4076693 | BJ127: =VLOOKUP($BE127,AW:AY,3,0) -> 1497881481 | BK127: =(BG127*BH127+BI127*BJ127)/(BH127+BJ127) -> 4.3893163 | BL127: =VLOOKUP($BE127,AS:AU,2,0) -> 4.4279895 | BM127: =VLOOKUP($BE127,AS:AU,3,0) -> 1.3714956e+10 | BN127: =VLOOKUP($BE127,BA:BC,2,0) -> 4.3624891 | BO127: =VLOOKUP($BE127,BA:BC,3,0) -> 10440873099 | BP127: =(BL127*BM127+BN127*BO127)/(BM127+BO127) -> 4.3996782 | BQ127: =(BK127-BP127)*100 -> -1.0361904
A128: 41518 | B128: 4.3658062 | C128: 1.8360664e+09 | E128: 41518 | F128: 4.4771391 | G128: 7.388974e+08 | Q128: 41518 | R128: =VLOOKUP($Q128,A:C,2,0) -> 4.3658062 | S128: =VLOOKUP($Q128,A:C,3,0) -> 1.8360664e+09 | T128: =VLOOKUP($Q128,I:K,2,0) -> 4.3593781 | U128: =VLOOKUP($Q128,I:K,3,0) -> 808096685 | V128: =(R128*S128+T128*U128)/(S128+U128) -> 4.3638417 | W128: =VLOOKUP($Q128,E:G,2,0) -> 4.4771391 | X128: =VLOOKUP($Q128,E:G,3,0) -> 7.388974e+08 | Y128: =VLOOKUP($Q128,M:O,2,0) -> 4.4930913 | Z128: =VLOOKUP($Q128,M:O,3,0) -> 413868018 | AA128: =(W128*X128+Y128*Z128)/(X128+Z128) -> 4.4828663 | AB128: =(V128-AA128)*100 -> -11.90246 | AO128: 201207 | AP128: 3.994509 | AQ128: 4.7677691e+09 | AS128: 199611 | AT128: 8.2877523 | AU128: 2784384 | AW128: 201403 | AX128: 4.6159874 | AY128: 822591182 | BA128: 199707 | BB128: 7.9870407 | BC128: 3510813 | BE128: 201410 | BF128: =DATEVALUE(INT(AW128/100)&"/"&MOD(AW128,100)&"/1") -> 41699 | BG128: =VLOOKUP($BE128,AO:AQ,2,0) -> 4.3616386 | BH128: =VLOOKUP($BE128,AO:AQ,3,0) -> 1.7795949e+09 | BI128: =VLOOKUP($BE128,AW:AY,2,0) -> 4.3954875 | BJ128: =VLOOKUP($BE128,AW:AY,3,0) -> 1457242020 | BK128: =(BG128*BH128+BI128*BJ128)/(BH128+BJ128) -> 4.3768776 | BL128: =VLOOKUP($BE128,AS:AU,2,0) -> 4.4233495 | BM128: =VLOOKUP($BE128,AS:AU,3,0) -> 1.3426039e+10 | BN128: =VLOOKUP($BE128,BA:BC,2,0) -> 4.3619935 | BO128: =VLOOKUP($BE128,BA:BC,3,0) -> 9786755461 | BP128: =(BL128*BM128+BN128*BO128)/(BM128+BO128) -> 4.3974812 | BQ128: =(BK128-BP128)*100 -> -2.0603593
