Workbook

Sheet step1 Raw
B1: Adj. Purchase | C1: MBACAI
A2: 38139 | B2: 427.11408 | C2: 377
A3: 38169 | B3: 444.14165 | C3: 383.5
A4: 38200 | B4: 430.9873 | C4: 390
A5: 38231 | B5: 445.46918 | C5: 396.5
A6: 38261 | B6: 439.40181 | C6: 403
A7: 38292 | B7: 450.97969 | C7: 409.5
A8: 38322 | B8: 448.93689 | C8: 416
A9: 38353 | B9: 409.79235 | C9: 480.83333
A10: 38384 | B10: 410.5761 | C10: 545.66667
A11: 38412 | B11: 435.33756 | C11: 610.5
A12: 38443 | B12: 446.62214 | C12: 675.33333
A13: 38473 | B13: 460.15354 | C13: 740.16667
... A146: 42522 | B146: 225.0055 | C146: 119.8

Sheet step2 %Chg
B1: Purchase Chg | C1: MBACAI Chg
A2: 38139 | F2: Correlation | G2: =CORREL(B14:B146,C14:C146) -> 0.33448194
A3: 38169
A4: 38200
A5: 38231
A6: 38261
A7: 38292
A8: 38322
A9: 38353
A10: 38384
A11: 38412
A12: 38443
A13: 38473 | B13: =('step1 Raw'!B14-'step1 Raw'!B2)/'step1 Raw'!B2 -> 0.089977425 | C13: =('step1 Raw'!C14-'step1 Raw'!C2)/'step1 Raw'!C2 -> 1.1352785
A14: 38504 | B14: =('step1 Raw'!B15-'step1 Raw'!B3)/'step1 Raw'!B3 -> 0.056135384 | C14: =('step1 Raw'!C15-'step1 Raw'!C3)/'step1 Raw'!C3 -> 1.1177749
A15: 38534 | B15: =('step1 Raw'!B16-'step1 Raw'!B4)/'step1 Raw'!B4 -> 0.073255667 | C15: =('step1 Raw'!C16-'step1 Raw'!C4)/'step1 Raw'!C4 -> 1.1008547
A16: 38565 | B16: =('step1 Raw'!B17-'step1 Raw'!B5)/'step1 Raw'!B5 -> 0.047114225 | C16: =('step1 Raw'!C17-'step1 Raw'!C5)/'step1 Raw'!C5 -> 1.0844893
A17: 38596 | B17: =('step1 Raw'!B18-'step1 Raw'!B6)/'step1 Raw'!B6 -> 0.0076180038 | C17: =('step1 Raw'!C18-'step1 Raw'!C6)/'step1 Raw'!C6 -> 1.0686518
A18: 38626 | B18: =('step1 Raw'!B19-'step1 Raw'!B7)/'step1 Raw'!B7 -> -0.01164723 | C18: =('step1 Raw'!C19-'step1 Raw'!C7)/'step1 Raw'!C7 -> 1.0533171
A19: 38657 | B19: =('step1 Raw'!B20-'step1 Raw'!B8)/'step1 Raw'!B8 -> -0.04506397 | C19: =('step1 Raw'!C20-'step1 Raw'!C8)/'step1 Raw'!C8 -> 1.0384615
A20: 38687 | B20: =('step1 Raw'!B21-'step1 Raw'!B9)/'step1 Raw'!B9 -> 0.038620694 | C20: =('step1 Raw'!C21-'step1 Raw'!C9)/'step1 Raw'!C9 -> 0.77157712
A21: 38718 | B21: =('step1 Raw'!B22-'step1 Raw'!B10)/'step1 Raw'!B10 -> -0.069792062 | C21: =('step1 Raw'!C22-'step1 Raw'!C10)/'step1 Raw'!C10 -> 0.5681124
A22: 38749 | B22: =('step1 Raw'!B23-'step1 Raw'!B11)/'step1 Raw'!B11 -> -0.12134406 | C22: =('step1 Raw'!C23-'step1 Raw'!C11)/'step1 Raw'!C11 -> 0.40786241
A23: 38777 | B23: =('step1 Raw'!B24-'step1 Raw'!B12)/'step1 Raw'!B12 -> -0.13515983 | C23: =('step1 Raw'!C24-'step1 Raw'!C12)/'step1 Raw'!C12 -> 0.27838105
A24: 38808 | B24: =('step1 Raw'!B25-'step1 Raw'!B13)/'step1 Raw'!B13 -> -0.16782823 | C24: =('step1 Raw'!C25-'step1 Raw'!C13)/'step1 Raw'!C13 -> 0.17158298
... A146: 42522 | B146: =('step1 Raw'!B147-'step1 Raw'!B135)/'step1 Raw'!B135 -> -1 | C146: =('step1 Raw'!C147-'step1 Raw'!C135)/'step1 Raw'!C135 -> -1

Sheet step3 Regression
B1: Purchase Chg | C1: ='step2 %Chg'!C1 -> MBACAI Chg
A2: ='step2 %Chg'!A2 -> 38139 | B2: ='step2 %Chg'!B2 -> 0 | C2: ='step2 %Chg'!C2 -> 0
A3: ='step2 %Chg'!A3 -> 38169 | B3: ='step2 %Chg'!B3 -> 0 | C3: ='step2 %Chg'!C3 -> 0
A4: ='step2 %Chg'!A4 -> 38200 | B4: ='step2 %Chg'!B4 -> 0 | C4: ='step2 %Chg'!C4 -> 0
A5: ='step2 %Chg'!A5 -> 38231 | B5: ='step2 %Chg'!B5 -> 0 | C5: ='step2 %Chg'!C5 -> 0
A6: ='step2 %Chg'!A6 -> 38261 | B6: ='step2 %Chg'!B6 -> 0 | C6: ='step2 %Chg'!C6 -> 0
A7: ='step2 %Chg'!A7 -> 38292 | B7: ='step2 %Chg'!B7 -> 0 | C7: ='step2 %Chg'!C7 -> 0 | L7: Excel Version
A8: ='step2 %Chg'!A8 -> 38322 | B8: ='step2 %Chg'!B8 -> 0 | C8: ='step2 %Chg'!C8 -> 0
A9: ='step2 %Chg'!A9 -> 38353 | B9: ='step2 %Chg'!B9 -> 0 | C9: ='step2 %Chg'!C9 -> 0
A10: ='step2 %Chg'!A10 -> 38384 | B10: ='step2 %Chg'!B10 -> 0 | C10: ='step2 %Chg'!C10 -> 0
A11: ='step2 %Chg'!A11 -> 38412 | B11: ='step2 %Chg'!B11 -> 0 | C11: ='step2 %Chg'!C11 -> 0
A12: ='step2 %Chg'!A12 -> 38443 | B12: ='step2 %Chg'!B12 -> 0 | C12: ='step2 %Chg'!C12 -> 0
A13: ='step2 %Chg'!A13 -> 38473 | B13: ='step2 %Chg'!B13 -> 0.089977425 | C13: ='step2 %Chg'!C13 -> 1.1352785
A14: ='step2 %Chg'!A14 -> 38504 | B14: ='step2 %Chg'!B14 -> 0.056135384 | C14: ='step2 %Chg'!C14 -> 1.1177749
A15: ='step2 %Chg'!A15 -> 38534 | B15: ='step2 %Chg'!B15 -> 0.073255667 | C15: ='step2 %Chg'!C15 -> 1.1008547
A16: ='step2 %Chg'!A16 -> 38565 | B16: ='step2 %Chg'!B16 -> 0.047114225 | C16: ='step2 %Chg'!C16 -> 1.0844893
A17: ='step2 %Chg'!A17 -> 38596 | B17: ='step2 %Chg'!B17 -> 0.0076180038 | C17: ='step2 %Chg'!C17 -> 1.0686518
A18: ='step2 %Chg'!A18 -> 38626 | B18: ='step2 %Chg'!B18 -> -0.01164723 | C18: ='step2 %Chg'!C18 -> 1.0533171
A19: ='step2 %Chg'!A19 -> 38657 | B19: ='step2 %Chg'!B19 -> -0.04506397 | C19: ='step2 %Chg'!C19 -> 1.0384615
... A32: ='step2 %Chg'!A32 -> 39052 | B32: ='step2 %Chg'!B32 -> -0.058764768 | C32: ='step2 %Chg'!C32 -> -0.18254745
A33: ='step2 %Chg'!A33 -> 39083 | B33: ='step2 %Chg'!B33 -> -0.033073263 | C33: ='step2 %Chg'!C33 -> -0.22088041 | L33: R version
A34: ='step2 %Chg'!A34 -> 39114 | B34: ='step2 %Chg'!B34 -> -0.0055935102 | C34: ='step2 %Chg'!C34 -> -0.25887144
A35: ='step2 %Chg'!A35 -> 39142 | B35: ='step2 %Chg'!B35 -> -0.0070190005 | C35: ='step2 %Chg'!C35 -> -0.2965251
A36: ='step2 %Chg'!A36 -> 39173 | B36: ='step2 %Chg'!B36 -> 0.054792054 | C36: ='step2 %Chg'!C36 -> -0.33384586
A37: ='step2 %Chg'!A37 -> 39203 | B37: ='step2 %Chg'!B37 -> 0.086635522 | C37: ='step2 %Chg'!C37 -> -0.37083812
A38: ='step2 %Chg'!A38 -> 39234 | B38: ='step2 %Chg'!B38 -> 0.091578485 | C38: ='step2 %Chg'!C38 -> -0.39834678
A39: ='step2 %Chg'!A39 -> 39264 | B39: ='step2 %Chg'!B39 -> 0.14673342 | C39: ='step2 %Chg'!C39 -> -0.42747164
A40: ='step2 %Chg'!A40 -> 39295 | B40: ='step2 %Chg'!B40 -> 0.091371753 | C40: ='step2 %Chg'!C40 -> -0.45835942
A41: ='step2 %Chg'!A41 -> 39326 | B41: ='step2 %Chg'!B41 -> 0.099072904 | C41: ='step2 %Chg'!C41 -> -0.4911752
A42: ='step2 %Chg'!A42 -> 39356 | B42: ='step2 %Chg'!B42 -> 0.053827842 | C42: ='step2 %Chg'!C42 -> -0.52610531
A43: ='step2 %Chg'!A43 -> 39387 | B43: ='step2 %Chg'!B43 -> -0.027523047 | C43: ='step2 %Chg'!C43 -> -0.56336088
A44: ='step2 %Chg'!A44 -> 39417 | B44: ='step2 %Chg'!B44 -> -0.023890785 | C44: ='step2 %Chg'!C44 -> -0.5923887
A45: ='step2 %Chg'!A45 -> 39448 | B45: ='step2 %Chg'!B45 -> -0.046742531 | C45: ='step2 %Chg'!C45 -> -0.624
... A146: ='step2 %Chg'!A146 -> 42522 | B146: ='step2 %Chg'!B146 -> -1 | C146: ='step2 %Chg'!C146 -> -1

Sheet step4 Pred. Chg
B1: Adj. Purchase Chg | C1: Purchase Chg | D1: MBACAI Predict
A2: 32874 | B2: 92.4 | C2: =(B2-B14)/B2 -> 0.054383117 | D2: =0.01171672+0.68563835*C2 -> 0.049003871
A3: 32905 | B3: 100.175 | C3: =(B3-B15)/B3 -> 0.01372598 | D3: =0.01171672+0.68563835*C3 -> 0.021127778
A4: 32933 | B4: 92.28 | C4: =(B4-B16)/B4 -> -0.24187256 | D4: =0.01171672+0.68563835*C4 -> -0.15412038
A5: 32964 | B5: 91.25 | C5: =(B5-B17)/B5 -> -0.22739726 | D5: =0.01171672+0.68563835*C5 -> -0.14419556
A6: 32994 | B6: 85.5 | C6: =(B6-B18)/B6 -> -0.37216374 | D6: =0.01171672+0.68563835*C6 -> -0.24345301
A7: 33025 | B7: 92 | C7: =(B7-B19)/B7 -> -0.23777174 | D7: =0.01171672+0.68563835*C7 -> -0.1513087
A8: 33055 | B8: 88.65 | C8: =(B8-B20)/B8 -> -0.31838691 | D8: =0.01171672+0.68563835*C8 -> -0.20658156
A9: 33086 | B9: 89.18 | C9: =(B9-B21)/B9 -> -0.18030949 | D9: =0.01171672+0.68563835*C9 -> -0.11191038
A10: 33117 | B10: 80.45 | C10: =(B10-B22)/B10 -> -0.32877564 | D10: =0.01171672+0.68563835*C10 -> -0.21370447
A11: 33147 | B11: 74.95 | C11: =(B11-B23)/B11 -> -0.49733155 | D11: =0.01171672+0.68563835*C11 -> -0.32927287
A12: 33178 | B12: 81.84 | C12: =(B12-B24)/B12 -> -0.26466276 | D12: =0.01171672+0.68563835*C12 -> -0.16974622
A13: 33208 | B13: 78.9 | C13: =(B13-B25)/B13 -> -0.27059569 | D13: =0.01171672+0.68563835*C13 -> -0.17381406
... A307: 42156 | B307: 193.92415 | C307: =(B307-B319)/B307 -> -0.16029902 | D307: =0.01171672+0.68563835*C307 -> -0.098190435
A308: 42186 | B308: 189.50004
A309: 42217 | B309: 187.26218
A310: 42248 | B310: 191.78951
A311: 42278 | B311: 188.71187
A312: 42309 | B312: 197.67737
A313: 42339 | B313: 211.47045
A314: 42370 | B314: 208.96048
A315: 42401 | B315: 203.96401
A316: 42430 | B316: 212.19764
A317: 42461 | B317: 220.59546
A318: 42491 | B318: 215.43479
A319: 42522 | B319: 225.01

Sheet step5 Pred. Level
B1: MCAI Raw | C1: Predicted Chgs | D1: Predicted Level
A2: 32874 | C2: =VLOOKUP(A2,'step4 Pred. Chg'!A:D,4,0) -> 0.049003871 | D2: =D14/(1+C2) -> 1639.969
A3: 32905 | C3: =VLOOKUP(A3,'step4 Pred. Chg'!A:D,4,0) -> 0.021127778 | D3: =D15/(1+C3) -> 1463.8347
A4: 32933 | C4: =VLOOKUP(A4,'step4 Pred. Chg'!A:D,4,0) -> -0.15412038 | D4: =D16/(1+C4) -> 1801.3866
A5: 32964 | C5: =VLOOKUP(A5,'step4 Pred. Chg'!A:D,4,0) -> -0.14419556 | D5: =D17/(1+C5) -> 2211.7569
A6: 32994 | C6: =VLOOKUP(A6,'step4 Pred. Chg'!A:D,4,0) -> -0.24345301 | D6: =D18/(1+C6) -> 2541.5441
A7: 33025 | C7: =VLOOKUP(A7,'step4 Pred. Chg'!A:D,4,0) -> -0.1513087 | D7: =D19/(1+C7) -> 1122.4786
A8: 33055 | C8: =VLOOKUP(A8,'step4 Pred. Chg'!A:D,4,0) -> -0.20658156 | D8: =D20/(1+C8) -> 1209.6423
A9: 33086 | C9: =VLOOKUP(A9,'step4 Pred. Chg'!A:D,4,0) -> -0.11191038 | D9: =D21/(1+C9) -> 1172.5063
A10: 33117 | C10: =VLOOKUP(A10,'step4 Pred. Chg'!A:D,4,0) -> -0.21370447 | D10: =D22/(1+C10) -> 1640.3946
A11: 33147 | C11: =VLOOKUP(A11,'step4 Pred. Chg'!A:D,4,0) -> -0.32927287 | D11: =D23/(1+C11) -> 1820.6378
A12: 33178 | C12: =VLOOKUP(A12,'step4 Pred. Chg'!A:D,4,0) -> -0.16974622 | D12: =D24/(1+C12) -> 1502.1895
A13: 33208 | C13: =VLOOKUP(A13,'step4 Pred. Chg'!A:D,4,0) -> -0.17381406 | D13: =D25/(1+C13) -> 1830.9186
... A162: 37742 | C162: =VLOOKUP(A162,'step4 Pred. Chg'!A:D,4,0) -> -0.056293138 | D162: =D174/(1+C162) -> 788.81885
A163: 37773 | C163: =VLOOKUP(A163,'step4 Pred. Chg'!A:D,4,0) -> -0.011652937 | D163: =B175/(1+C163) -> 381.44495
A164: 37803 | C164: =VLOOKUP(A164,'step4 Pred. Chg'!A:D,4,0) -> -0.022249023 | D164: =B176/(1+C164) -> 392.22666
A165: 37834 | C165: =VLOOKUP(A165,'step4 Pred. Chg'!A:D,4,0) -> -0.048509256 | D165: =B177/(1+C165) -> 409.88313
A166: 37865 | C166: =VLOOKUP(A166,'step4 Pred. Chg'!A:D,4,0) -> -0.065135528 | D166: =B178/(1+C166) -> 424.12565
A167: 37895 | C167: =VLOOKUP(A167,'step4 Pred. Chg'!A:D,4,0) -> -0.092779881 | D167: =B179/(1+C167) -> 444.21413
A168: 37926 | C168: =VLOOKUP(A168,'step4 Pred. Chg'!A:D,4,0) -> -0.047850092 | D168: =B180/(1+C168) -> 430.07934
A169: 37956 | C169: =VLOOKUP(A169,'step4 Pred. Chg'!A:D,4,0) -> -0.074275902 | D169: =B181/(1+C169) -> 449.37795
A170: 37987 | C170: =VLOOKUP(A170,'step4 Pred. Chg'!A:D,4,0) -> 0.053945738 | D170: =B182/(1+C170) -> 456.2221
A171: 38018 | C171: =VLOOKUP(A171,'step4 Pred. Chg'!A:D,4,0) -> -0.00021435084 | D171: =B183/(1+C171) -> 545.78366
A172: 38047 | C172: =VLOOKUP(A172,'step4 Pred. Chg'!A:D,4,0) -> 0.0029946103 | D172: =B184/(1+C172) -> 608.67725
A173: 38078 | C173: =VLOOKUP(A173,'step4 Pred. Chg'!A:D,4,0) -> 0.0063959752 | D173: =B185/(1+C173) -> 671.04137
A174: 38108 | C174: =VLOOKUP(A174,'step4 Pred. Chg'!A:D,4,0) -> -0.0057052849 | D174: =B186/(1+C174) -> 744.41376
A175: 38139 | B175: =VLOOKUP(A175,'step1 Raw'!A:C,3,0) -> 377 | C175: =VLOOKUP(A175,'step4 Pred. Chg'!A:D,4,0) -> -0.049975253
A176: 38169 | B176: =VLOOKUP(A176,'step1 Raw'!A:C,3,0) -> 383.5 | C176: =VLOOKUP(A176,'step4 Pred. Chg'!A:D,4,0) -> -0.026771852
A177: 38200 | B177: =VLOOKUP(A177,'step1 Raw'!A:C,3,0) -> 390 | C177: =VLOOKUP(A177,'step4 Pred. Chg'!A:D,4,0) -> -0.038510175
A178: 38231 | B178: =VLOOKUP(A178,'step1 Raw'!A:C,3,0) -> 396.5 | C178: =VLOOKUP(A178,'step4 Pred. Chg'!A:D,4,0) -> -0.020586599
A179: 38261 | B179: =VLOOKUP(A179,'step1 Raw'!A:C,3,0) -> 403 | C179: =VLOOKUP(A179,'step4 Pred. Chg'!A:D,4,0) -> 0.0064935245
A180: 38292 | B180: =VLOOKUP(A180,'step1 Raw'!A:C,3,0) -> 409.5 | C180: =VLOOKUP(A180,'step4 Pred. Chg'!A:D,4,0) -> 0.019702508
A181: 38322 | B181: =VLOOKUP(A181,'step1 Raw'!A:C,3,0) -> 416 | C181: =VLOOKUP(A181,'step4 Pred. Chg'!A:D,4,0) -> 0.042614306
A182: 38353 | B182: =VLOOKUP(A182,'step1 Raw'!A:C,3,0) -> 480.83333 | C182: =VLOOKUP(A182,'step4 Pred. Chg'!A:D,4,0) -> -0.014763109
A183: 38384 | B183: =VLOOKUP(A183,'step1 Raw'!A:C,3,0) -> 545.66667 | C183: =VLOOKUP(A183,'step4 Pred. Chg'!A:D,4,0) -> 0.059568834
A184: 38412 | B184: =VLOOKUP(A184,'step1 Raw'!A:C,3,0) -> 610.5 | C184: =VLOOKUP(A184,'step4 Pred. Chg'!A:D,4,0) -> 0.094914859
A185: 38443 | B185: =VLOOKUP(A185,'step1 Raw'!A:C,3,0) -> 675.33333 | C185: =VLOOKUP(A185,'step4 Pred. Chg'!A:D,4,0) -> 0.10438749
A186: 38473 | B186: =VLOOKUP(A186,'step1 Raw'!A:C,3,0) -> 740.16667 | C186: =VLOOKUP(A186,'step4 Pred. Chg'!A:D,4,0) -> 0.12678619
... A319: 42522 | B319: =VLOOKUP(A319,'step1 Raw'!A:C,3,0) -> 119.8 | C319: =VLOOKUP(A319,'step4 Pred. Chg'!A:D,4,0) -> 0

Sheet Appendix-Adj Purch
B1: PRCH | C1: Inventory | D1: Adj. | H1: MBAVPRCH | I1: Inventory | J1: Inventory Adj
A2: 38139 | B2: 442.9 | C2: 1.0369595 | D2: 427.11408 | G2: 32874 | H2: 92.4 | I2: #N/A | J2: =H2/1 -> 92.4
A3: 38169 | B3: 461.36 | C3: 1.0387677 | D3: 444.14165 | G3: 32905 | H3: 100.175 | I3: #N/A | J3: =H3/1 -> 100.175
A4: 38200 | B4: 448.475 | C4: 1.0405759 | D4: 430.9873 | G4: 32933 | H4: 92.28 | I4: #N/A | J4: =H4/1 -> 92.28
A5: 38231 | B5: 464.35 | C5: 1.0423841 | D5: 445.46918 | G5: 32964 | H5: 91.25 | I5: #N/A | J5: =H5/1 -> 91.25
A6: 38261 | B6: 458.82 | C6: 1.0441923 | D6: 439.40181 | G6: 32994 | H6: 85.5 | I6: #N/A | J6: =H6/1 -> 85.5
A7: 38292 | B7: 471.725 | C7: 1.0460005 | D7: 450.97969 | G7: 33025 | H7: 92 | I7: #N/A | J7: =H7/1 -> 92
A8: 38322 | B8: 470.4 | C8: 1.0478088 | D8: 448.93689 | G8: 33055 | H8: 88.65 | I8: #N/A | J8: =H8/1 -> 88.65
A9: 38353 | B9: 430.125 | C9: 1.049617 | D9: 409.79235 | G9: 33086 | H9: 89.18 | I9: #N/A | J9: =H9/1 -> 89.18
A10: 38384 | B10: 431.425 | C10: 1.0507796 | D10: 410.5761 | G10: 33117 | H10: 80.45 | I10: #N/A | J10: =H10/1 -> 80.45
A11: 38412 | B11: 457.95 | C11: 1.0519423 | D11: 435.33756 | G11: 33147 | H11: 74.95 | I11: #N/A | J11: =H11/1 -> 74.95
A12: 38443 | B12: 470.34 | C12: 1.053105 | D12: 446.62214 | G12: 33178 | H12: 81.84 | I12: #N/A | J12: =H12/1 -> 81.84
A13: 38473 | B13: 485.125 | C13: 1.0542677 | D13: 460.15354 | G13: 33208 | H13: 78.9 | I13: #N/A | J13: =H13/1 -> 78.9
... A109: 41395 | B109: 211.08 | C109: 1.0640636 | D109: 198.3716 | G109: 36130 | H109: 281.275 | I109: #N/A | J109: =H109/1 -> 281.275
A110: 41426 | B110: 212.6 | C110: 1.0637771 | D110: 199.8539 | G110: 36161 | H110: 266.28 | I110: 1 | J110: 266.28
A111: 41456 | B111: 198.65 | C111: 1.0634906 | D111: 186.79056 | G111: 36192 | H111: 246.975 | I111: 1.0013707 | J111: 246.63693
A112: 41487 | B112: 187.74 | C112: 1.0632041 | D112: 176.57946 | G112: 36220 | H112: 257.2 | I112: 1.0027414 | J112: 256.49683
A113: 41518 | B113: 190.425 | C113: 1.0629176 | D113: 179.15312 | G113: 36251 | H113: 277.2 | I113: 1.0041122 | J113: 276.06478
A114: 41548 | B114: 182.975 | C114: 1.0626311 | D114: 172.19052 | G114: 36281 | H114: 288.275 | I114: 1.0054829 | J114: 286.70304
A115: 41579 | B115: 187.02 | C115: 1.0623446 | D115: 176.04458 | G115: 36312 | H115: 309.6 | I115: 1.0068536 | J115: 307.49257
A116: 41609 | B116: 175.525 | C116: 1.0620581 | D116: 165.26874 | G116: 36342 | H116: 285.86 | I116: 1.0082243 | J116: 283.52817
A117: 41640 | B117: 183.3 | C117: 1.0617715 | D117: 172.63601 | G117: 36373 | H117: 277.45 | I117: 1.009595 | J117: 274.81316
A118: 41671 | B118: 164.2 | C118: 1.0621032 | D118: 154.59891 | G118: 36404 | H118: 264.85 | I118: 1.0109658 | J118: 261.97722
A119: 41699 | B119: 171.9 | C119: 1.0624349 | D119: 161.79815 | G119: 36434 | H119: 272.38 | I119: 1.0123365 | J119: 269.06074
A120: 41730 | B120: 177.775 | C120: 1.0627666 | D120: 167.27568 | G120: 36465 | H120: 295.475 | I120: 1.0137072 | J120: 291.47963
A121: 41760 | B121: 180 | C121: 1.0630983 | D121: 169.31643 | G121: 36495 | H121: 269.86 | I121: 1.0150779 | J121: 265.85151
... A145: 42491 | B145: 229.6 | C145: 1.0657517 | D145: 215.43479 | G145: 37226 | H145: 315 | I145: 1.0502542 | J145: 299.9274
A146: 42522 | B146: 239.8 | C146: 1.0657517 | D146: =B146/C146 -> 225.0055 | G146: 37257 | H146: 356.2 | I146: 1.0515857 | J146: 338.72657
G147: 37288 | H147: 315.325 | I147: 1.0486909 | J147: 300.68442
G148: 37316 | H148: 328.24 | I148: 1.0457961 | J148: 313.86617
G149: 37347 | H149: 347.525 | I149: 1.0429013 | J149: 333.22905
G150: 37377 | H150: 369.16 | I150: 1.0400065 | J150: 354.95933
G151: 37408 | H151: 373.175 | I151: 1.0371117 | J151: 359.82143
G152: 37438 | H152: 374.25 | I152: 1.0342169 | J152: 361.86801
G153: 37469 | H153: 360.6 | I153: 1.0313221 | J153: 349.64829
G154: 37500 | H154: 369.525 | I154: 1.0284273 | J154: 359.31077
G155: 37530 | H155: 348.625 | I155: 1.0255325 | J155: 339.94535
G156: 37561 | H156: 356.92 | I156: 1.0226377 | J156: 349.01902
G157: 37591 | H157: 357.625 | I157: 1.0197429 | J157: 350.70115
G158: 37622 | H158: 365.22 | I158: 1.0168481 | J158: 359.1687
...
