Workbook

Sheet Result
B1: Input | N1: Normalized
B2: HPA2Yr | C2: MBA CAI | D2: Purchase | E2: Cello | N2: HPA2Yr | O2: MBA CAI | P2: Purchase | Q2: Cello CAI | R2: Tracking Diff
A3: 34335 | B3: =VLOOKUP(A3,HPA2Yr!A:F,6,0)*100 -> 105.07688 | C3: =VLOOKUP(A3,'MBA CA Index'!A:F,3,0) -> #N/A | D3: =VLOOKUP(A3,'Purchase Index'!M:T,5,0) -> #N/A | E3: =VLOOKUP(A3,Cello!A:F,3,0)*100 -> #N/A | M3: 34335 | N3: =(B3-H$6)/(H$7-H$6)*100 -> 48.786493 | O3: =(C3-I$6)/(I$7-I$6)*100 -> #N/A | P3: =(D3-J$6)/(J$7-J$6)*100 -> #N/A | Q3: =(E3-K$6)/(K$7-K$6)*100 -> #N/A | R3: =VLOOKUP(M3,'Tracking Diff'!A:D,4,0) -> 1.4751267
A4: 34366 | B4: =VLOOKUP(A4,HPA2Yr!A:F,6,0)*100 -> 105.03075 | C4: =VLOOKUP(A4,'MBA CA Index'!A:F,3,0) -> #N/A | D4: =VLOOKUP(A4,'Purchase Index'!M:T,5,0) -> #N/A | E4: =VLOOKUP(A4,Cello!A:F,3,0)*100 -> #N/A | M4: 34366 | N4: =(B4-H$6)/(H$7-H$6)*100 -> 48.657148 | O4: =(C4-I$6)/(I$7-I$6)*100 -> #N/A | P4: =(D4-J$6)/(J$7-J$6)*100 -> #N/A | Q4: =(E4-K$6)/(K$7-K$6)*100 -> #N/A | R4: =VLOOKUP(M4,'Tracking Diff'!A:D,4,0) -> #N/A
A5: 34394 | B5: =VLOOKUP(A5,HPA2Yr!A:F,6,0)*100 -> 104.98486 | C5: =VLOOKUP(A5,'MBA CA Index'!A:F,3,0) -> #N/A | D5: =VLOOKUP(A5,'Purchase Index'!M:T,5,0) -> #N/A | E5: =VLOOKUP(A5,Cello!A:F,3,0)*100 -> #N/A | H5: HPA2Yr | I5: MBA CAI | J5: Purchase | K5: Cello | M5: 34394 | N5: =(B5-H$6)/(H$7-H$6)*100 -> 48.528466 | O5: =(C5-I$6)/(I$7-I$6)*100 -> #N/A | P5: =(D5-J$6)/(J$7-J$6)*100 -> #N/A | Q5: =(E5-K$6)/(K$7-K$6)*100 -> #N/A | R5: =VLOOKUP(M5,'Tracking Diff'!A:D,4,0) -> 2.555785
A6: 34425 | B6: =VLOOKUP(A6,HPA2Yr!A:F,6,0)*100 -> 105.20451 | C6: =VLOOKUP(A6,'MBA CA Index'!A:F,3,0) -> #N/A | D6: =VLOOKUP(A6,'Purchase Index'!M:T,5,0) -> #N/A | E6: =VLOOKUP(A6,Cello!A:F,3,0)*100 -> #N/A | G6: Min | H6: =MIN(B3:B272) -> 87.678928 | I6: =MIN(C128:C270) -> 102.27083 | J6: =MIN(D86:D271) -> 169.5007 | K6: =MIN(E138:E267) -> 1.8177369 | M6: 34425 | N6: =(B6-H$6)/(H$7-H$6)*100 -> 49.144405 | O6: =(C6-I$6)/(I$7-I$6)*100 -> #N/A | P6: =(D6-J$6)/(J$7-J$6)*100 -> #N/A | Q6: =(E6-K$6)/(K$7-K$6)*100 -> #N/A | R6: =VLOOKUP(M6,'Tracking Diff'!A:D,4,0) -> #N/A
A7: 34455 | B7: =VLOOKUP(A7,HPA2Yr!A:F,6,0)*100 -> 105.42419 | C7: =VLOOKUP(A7,'MBA CA Index'!A:F,3,0) -> #N/A | D7: =VLOOKUP(A7,'Purchase Index'!M:T,5,0) -> #N/A | E7: =VLOOKUP(A7,Cello!A:F,3,0)*100 -> #N/A | G7: Max | H7: =MAX(B3:B272) -> 123.34033 | I7: =MAX(C128:C270) -> 795.33333 | J7: =MAX(D86:D271) -> 441.34894 | K7: =MAX(E138:E267) -> 5.9497534 | M7: 34455 | N7: =(B7-H$6)/(H$7-H$6)*100 -> 49.760416 | O7: =(C7-I$6)/(I$7-I$6)*100 -> #N/A | P7: =(D7-J$6)/(J$7-J$6)*100 -> #N/A | Q7: =(E7-K$6)/(K$7-K$6)*100 -> #N/A | R7: =VLOOKUP(M7,'Tracking Diff'!A:D,4,0) -> #N/A
A8: 34486 | B8: =VLOOKUP(A8,HPA2Yr!A:F,6,0)*100 -> 105.64389 | C8: =VLOOKUP(A8,'MBA CA Index'!A:F,3,0) -> #N/A | D8: =VLOOKUP(A8,'Purchase Index'!M:T,5,0) -> #N/A | E8: =VLOOKUP(A8,Cello!A:F,3,0)*100 -> #N/A | M8: 34486 | N8: =(B8-H$6)/(H$7-H$6)*100 -> 50.376498 | O8: =(C8-I$6)/(I$7-I$6)*100 -> #N/A | P8: =(D8-J$6)/(J$7-J$6)*100 -> #N/A | Q8: =(E8-K$6)/(K$7-K$6)*100 -> #N/A | R8: =VLOOKUP(M8,'Tracking Diff'!A:D,4,0) -> 2.1325189
A9: 34516 | B9: =VLOOKUP(A9,HPA2Yr!A:F,6,0)*100 -> 105.39051 | C9: =VLOOKUP(A9,'MBA CA Index'!A:F,3,0) -> #N/A | D9: =VLOOKUP(A9,'Purchase Index'!M:T,5,0) -> #N/A | E9: =VLOOKUP(A9,Cello!A:F,3,0)*100 -> #N/A | M9: 34516 | N9: =(B9-H$6)/(H$7-H$6)*100 -> 49.665965 | O9: =(C9-I$6)/(I$7-I$6)*100 -> #N/A | P9: =(D9-J$6)/(J$7-J$6)*100 -> #N/A | Q9: =(E9-K$6)/(K$7-K$6)*100 -> #N/A | R9: =VLOOKUP(M9,'Tracking Diff'!A:D,4,0) -> 0.11230065
A10: 34547 | B10: =VLOOKUP(A10,HPA2Yr!A:F,6,0)*100 -> 105.13903 | C10: =VLOOKUP(A10,'MBA CA Index'!A:F,3,0) -> #N/A | D10: =VLOOKUP(A10,'Purchase Index'!M:T,5,0) -> #N/A | E10: =VLOOKUP(A10,Cello!A:F,3,0)*100 -> #N/A | M10: 34547 | N10: =(B10-H$6)/(H$7-H$6)*100 -> 48.960772 | O10: =(C10-I$6)/(I$7-I$6)*100 -> #N/A | P10: =(D10-J$6)/(J$7-J$6)*100 -> #N/A | Q10: =(E10-K$6)/(K$7-K$6)*100 -> #N/A | R10: =VLOOKUP(M10,'Tracking Diff'!A:D,4,0) -> 0.93702258
A11: 34578 | B11: =VLOOKUP(A11,HPA2Yr!A:F,6,0)*100 -> 104.88943 | C11: =VLOOKUP(A11,'MBA CA Index'!A:F,3,0) -> #N/A | D11: =VLOOKUP(A11,'Purchase Index'!M:T,5,0) -> #N/A | E11: =VLOOKUP(A11,Cello!A:F,3,0)*100 -> #N/A | M11: 34578 | N11: =(B11-H$6)/(H$7-H$6)*100 -> 48.260859 | O11: =(C11-I$6)/(I$7-I$6)*100 -> #N/A | P11: =(D11-J$6)/(J$7-J$6)*100 -> #N/A | Q11: =(E11-K$6)/(K$7-K$6)*100 -> #N/A | R11: =VLOOKUP(M11,'Tracking Diff'!A:D,4,0) -> 0.51841072
A12: 34608 | B12: =VLOOKUP(A12,HPA2Yr!A:F,6,0)*100 -> 104.67795 | C12: =VLOOKUP(A12,'MBA CA Index'!A:F,3,0) -> #N/A | D12: =VLOOKUP(A12,'Purchase Index'!M:T,5,0) -> #N/A | E12: =VLOOKUP(A12,Cello!A:F,3,0)*100 -> #N/A | M12: 34608 | N12: =(B12-H$6)/(H$7-H$6)*100 -> 47.667841 | O12: =(C12-I$6)/(I$7-I$6)*100 -> #N/A | P12: =(D12-J$6)/(J$7-J$6)*100 -> #N/A | Q12: =(E12-K$6)/(K$7-K$6)*100 -> #N/A | R12: =VLOOKUP(M12,'Tracking Diff'!A:D,4,0) -> 0.84196986
A13: 34639 | B13: =VLOOKUP(A13,HPA2Yr!A:F,6,0)*100 -> 104.46719 | C13: =VLOOKUP(A13,'MBA CA Index'!A:F,3,0) -> #N/A | D13: =VLOOKUP(A13,'Purchase Index'!M:T,5,0) -> #N/A | E13: =VLOOKUP(A13,Cello!A:F,3,0)*100 -> #N/A | M13: 34639 | N13: =(B13-H$6)/(H$7-H$6)*100 -> 47.076842 | O13: =(C13-I$6)/(I$7-I$6)*100 -> #N/A | P13: =(D13-J$6)/(J$7-J$6)*100 -> #N/A | Q13: =(E13-K$6)/(K$7-K$6)*100 -> #N/A | R13: =VLOOKUP(M13,'Tracking Diff'!A:D,4,0) -> 0.25037565
A14: 34669 | B14: =VLOOKUP(A14,HPA2Yr!A:F,6,0)*100 -> 104.25715 | C14: =VLOOKUP(A14,'MBA CA Index'!A:F,3,0) -> #N/A | D14: =VLOOKUP(A14,'Purchase Index'!M:T,5,0) -> #N/A | E14: =VLOOKUP(A14,Cello!A:F,3,0)*100 -> #N/A | M14: 34669 | N14: =(B14-H$6)/(H$7-H$6)*100 -> 46.487853 | O14: =(C14-I$6)/(I$7-I$6)*100 -> #N/A | P14: =(D14-J$6)/(J$7-J$6)*100 -> #N/A | Q14: =(E14-K$6)/(K$7-K$6)*100 -> #N/A | R14: =VLOOKUP(M14,'Tracking Diff'!A:D,4,0) -> 0.15709683
A15: 34700 | B15: =VLOOKUP(A15,HPA2Yr!A:F,6,0)*100 -> 104.43235 | C15: =VLOOKUP(A15,'MBA CA Index'!A:F,3,0) -> #N/A | D15: =VLOOKUP(A15,'Purchase Index'!M:T,5,0) -> #N/A | E15: =VLOOKUP(A15,Cello!A:F,3,0)*100 -> #N/A | M15: 34700 | N15: =(B15-H$6)/(H$7-H$6)*100 -> 46.979146 | O15: =(C15-I$6)/(I$7-I$6)*100 -> #N/A | P15: =(D15-J$6)/(J$7-J$6)*100 -> #N/A | Q15: =(E15-K$6)/(K$7-K$6)*100 -> #N/A | R15: =VLOOKUP(M15,'Tracking Diff'!A:D,4,0) -> 0.29732508
A16: 34731 | B16: =VLOOKUP(A16,HPA2Yr!A:F,6,0)*100 -> 104.60751 | C16: =VLOOKUP(A16,'MBA CA Index'!A:F,3,0) -> #N/A | D16: =VLOOKUP(A16,'Purchase Index'!M:T,5,0) -> #N/A | E16: =VLOOKUP(A16,Cello!A:F,3,0)*100 -> #N/A | M16: 34731 | N16: =(B16-H$6)/(H$7-H$6)*100 -> 47.470327 | O16: =(C16-I$6)/(I$7-I$6)*100 -> #N/A | P16: =(D16-J$6)/(J$7-J$6)*100 -> #N/A | Q16: =(E16-K$6)/(K$7-K$6)*100 -> #N/A | R16: =VLOOKUP(M16,'Tracking Diff'!A:D,4,0) -> 0.2588371
A17: 34759 | B17: =VLOOKUP(A17,HPA2Yr!A:F,6,0)*100 -> 104.78263 | C17: =VLOOKUP(A17,'MBA CA Index'!A:F,3,0) -> #N/A | D17: =VLOOKUP(A17,'Purchase Index'!M:T,5,0) -> #N/A | E17: =VLOOKUP(A17,Cello!A:F,3,0)*100 -> #N/A | M17: 34759 | N17: =(B17-H$6)/(H$7-H$6)*100 -> 47.961395 | O17: =(C17-I$6)/(I$7-I$6)*100 -> #N/A | P17: =(D17-J$6)/(J$7-J$6)*100 -> #N/A | Q17: =(E17-K$6)/(K$7-K$6)*100 -> #N/A | R17: =VLOOKUP(M17,'Tracking Diff'!A:D,4,0) -> 2.1575242
A18: 34790 | B18: =VLOOKUP(A18,HPA2Yr!A:F,6,0)*100 -> 105.01875 | C18: =VLOOKUP(A18,'MBA CA Index'!A:F,3,0) -> #N/A | D18: =VLOOKUP(A18,'Purchase Index'!M:T,5,0) -> #N/A | E18: =VLOOKUP(A18,Cello!A:F,3,0)*100 -> #N/A | M18: 34790 | N18: =(B18-H$6)/(H$7-H$6)*100 -> 48.623492 | O18: =(C18-I$6)/(I$7-I$6)*100 -> #N/A | P18: =(D18-J$6)/(J$7-J$6)*100 -> #N/A | Q18: =(E18-K$6)/(K$7-K$6)*100 -> #N/A | R18: =VLOOKUP(M18,'Tracking Diff'!A:D,4,0) -> 2.8663997
A19: 34820 | B19: =VLOOKUP(A19,HPA2Yr!A:F,6,0)*100 -> 105.25337 | C19: =VLOOKUP(A19,'MBA CA Index'!A:F,3,0) -> #N/A | D19: =VLOOKUP(A19,'Purchase Index'!M:T,5,0) -> #N/A | E19: =VLOOKUP(A19,Cello!A:F,3,0)*100 -> #N/A | M19: 34820 | N19: =(B19-H$6)/(H$7-H$6)*100 -> 49.281418 | O19: =(C19-I$6)/(I$7-I$6)*100 -> #N/A | P19: =(D19-J$6)/(J$7-J$6)*100 -> #N/A | Q19: =(E19-K$6)/(K$7-K$6)*100 -> #N/A | R19: =VLOOKUP(M19,'Tracking Diff'!A:D,4,0) -> 3.2180772
... A272: 42522 | B272: =VLOOKUP(A272,HPA2Yr!A:F,6,0)*100 -> 109.80418 | C272: =VLOOKUP(A272,'MBA CA Index'!A:F,3,0) -> #N/A | D272: =VLOOKUP(A272,'Purchase Index'!M:T,5,0) -> #N/A | E272: =VLOOKUP(A272,Cello!A:F,3,0)*100 -> #N/A | M272: 42522 | N272: =(B272-H$6)/(H$7-H$6)*100 -> 62.042586 | O272: =(C272-I$6)/(I$7-I$6)*100 -> #N/A | P272: =(D272-J$6)/(J$7-J$6)*100 -> #N/A | Q272: =(E272-K$6)/(K$7-K$6)*100 -> #N/A | R272: =VLOOKUP(M272,'Tracking Diff'!A:D,4,0) -> #N/A

Sheet HPA2Yr
B1: HPIndex | C1: HPIndex_1YR | D1: HPIndex_2YR | E1: HPA_1YR | F1: HPA_2YR
A2: 28185 | B2: 69.35 | C2: 62.82 | D2: 59.7 | E2: 1.1039478 | F2: 1.1616415
A3: 28216 | B3: 70.463333 | C3: 63.716667 | D3: 60.176667 | E3: 1.1058854 | F3: 1.1709411
A4: 28246 | B4: 71.576667 | C4: 64.613333 | D4: 60.653333 | E4: 1.1077693 | F4: 1.1800945
A5: 28277 | B5: 72.69 | C5: 65.51 | D5: 61.13 | E5: 1.1096016 | F5: 1.1891052
A6: 28307 | B6: 73.25 | C6: 65.87 | D6: 61.176667 | E6: 1.1120389 | F6: 1.1973519
A7: 28338 | B7: 73.81 | C7: 66.23 | D7: 61.223333 | E7: 1.1144496 | F7: 1.2055861
A8: 28369 | B8: 74.37 | C8: 66.59 | D8: 61.27 | E8: 1.1168344 | F8: 1.2138077
A9: 28399 | B9: 75.306667 | C9: 66.866667 | D9: 61.62 | E9: 1.1262213 | F9: 1.222114
A10: 28430 | B10: 76.243333 | C10: 67.143333 | D10: 61.97 | E10: 1.135531 | F10: 1.2303265
A11: 28460 | B11: 77.18 | C11: 67.42 | D11: 62.32 | E11: 1.1447642 | F11: 1.2384467
A12: 28491 | B12: 77.966667 | C12: 68.063333 | D12: 62.486667 | E12: 1.1455017 | F12: 1.2477328
A13: 28522 | B13: 78.753333 | C13: 68.706667 | D13: 62.653333 | E13: 1.1462255 | F13: 1.2569696
... A476: 42614 | B476: 375.17407 | C476: 363.88 | D476: 344.38 | E476: 1.0310379 | F476: 1.0894189

Sheet MBA CA Index
A1: Date | B1: MCAI | C1: 24Mo MA | D1: 18Mo MA | E1: 12Mo MA | F1: 6Mo MA
A2: 38139 | B2: 377 | C2: =AVERAGE($B$2:B2) -> 377 | D2: =AVERAGE($B$2:B2) -> 377 | E2: =AVERAGE($B$2:B2) -> 377 | F2: =AVERAGE($B$2:B2) -> 377
A3: 38169 | B3: 383.5 | C3: =AVERAGE($B$2:B3) -> 380.25 | D3: =AVERAGE($B$2:B3) -> 380.25 | E3: =AVERAGE($B$2:B3) -> 380.25 | F3: =AVERAGE($B$2:B3) -> 380.25
A4: 38200 | B4: 390 | C4: =AVERAGE($B$2:B4) -> 383.5 | D4: =AVERAGE($B$2:B4) -> 383.5 | E4: =AVERAGE($B$2:B4) -> 383.5 | F4: =AVERAGE($B$2:B4) -> 383.5
A5: 38231 | B5: 396.5 | C5: =AVERAGE($B$2:B5) -> 386.75 | D5: =AVERAGE($B$2:B5) -> 386.75 | E5: =AVERAGE($B$2:B5) -> 386.75 | F5: =AVERAGE($B$2:B5) -> 386.75
A6: 38261 | B6: 403 | C6: =AVERAGE($B$2:B6) -> 390 | D6: =AVERAGE($B$2:B6) -> 390 | E6: =AVERAGE($B$2:B6) -> 390 | F6: =AVERAGE($B$2:B6) -> 390
A7: 38292 | B7: 409.5 | C7: =AVERAGE($B$2:B7) -> 393.25 | D7: =AVERAGE($B$2:B7) -> 393.25 | E7: =AVERAGE($B$2:B7) -> 393.25 | F7: =AVERAGE($B$2:B7) -> 393.25
A8: 38322 | B8: 416 | C8: =AVERAGE($B$2:B8) -> 396.5 | D8: =AVERAGE($B$2:B8) -> 396.5 | E8: =AVERAGE($B$2:B8) -> 396.5 | F8: =AVERAGE(B3:B8) -> 399.75
A9: 38353 | B9: 480.83333 | C9: =AVERAGE($B$2:B9) -> 407.04167 | D9: =AVERAGE($B$2:B9) -> 407.04167 | E9: =AVERAGE($B$2:B9) -> 407.04167 | F9: =AVERAGE(B4:B9) -> 415.97222
A10: 38384 | B10: 545.66667 | C10: =AVERAGE($B$2:B10) -> 422.44444 | D10: =AVERAGE($B$2:B10) -> 422.44444 | E10: =AVERAGE($B$2:B10) -> 422.44444 | F10: =AVERAGE(B5:B10) -> 441.91667
A11: 38412 | B11: 610.5 | C11: =AVERAGE($B$2:B11) -> 441.25 | D11: =AVERAGE($B$2:B11) -> 441.25 | E11: =AVERAGE($B$2:B11) -> 441.25 | F11: =AVERAGE(B6:B11) -> 477.58333
A12: 38443 | B12: 675.33333 | C12: =AVERAGE($B$2:B12) -> 462.5303 | D12: =AVERAGE($B$2:B12) -> 462.5303 | E12: =AVERAGE($B$2:B12) -> 462.5303 | F12: =AVERAGE(B7:B12) -> 522.97222
A13: 38473 | B13: 740.16667 | C13: =AVERAGE($B$2:B13) -> 485.66667 | D13: =AVERAGE($B$2:B13) -> 485.66667 | E13: =AVERAGE(B2:B13) -> 485.66667 | F13: =AVERAGE(B8:B13) -> 578.08333
A14: 38504 | B14: 805 | C14: =AVERAGE($B$2:B14) -> 510.23077 | D14: =AVERAGE($B$1:B14) -> 510.23077 | E14: =AVERAGE(B3:B14) -> 521.33333 | F14: =AVERAGE(B9:B14) -> 642.91667
A15: 38534 | B15: 812.16667 | C15: =AVERAGE($B$2:B15) -> 531.79762 | D15: =AVERAGE($B$1:B15) -> 531.79762 | E15: =AVERAGE(B4:B15) -> 557.05556 | F15: =AVERAGE(B10:B15) -> 698.13889
A16: 38565 | B16: 819.33333 | C16: =AVERAGE($B$2:B16) -> 550.96667 | D16: =AVERAGE($B$1:B16) -> 550.96667 | E16: =AVERAGE(B5:B16) -> 592.83333 | F16: =AVERAGE(B11:B16) -> 743.75
A17: 38596 | B17: 826.5 | C17: =AVERAGE($B$2:B17) -> 568.1875 | D17: =AVERAGE($B$1:B17) -> 568.1875 | E17: =AVERAGE(B6:B17) -> 628.66667 | F17: =AVERAGE(B12:B17) -> 779.75
A18: 38626 | B18: 833.66667 | C18: =AVERAGE($B$2:B18) -> 583.80392 | D18: =AVERAGE($B$1:B18) -> 583.80392 | E18: =AVERAGE(B7:B18) -> 664.55556 | F18: =AVERAGE(B13:B18) -> 806.13889
A19: 38657 | B19: 840.83333 | C19: =AVERAGE($B$2:B19) -> 598.08333 | D19: =AVERAGE(B2:B19) -> 598.08333 | E19: =AVERAGE(B8:B19) -> 700.5 | F19: =AVERAGE(B14:B19) -> 822.91667
A20: 38687 | B20: 848 | C20: =AVERAGE($B$2:B20) -> 611.23684 | D20: =AVERAGE(B3:B20) -> 624.25 | E20: =AVERAGE(B9:B20) -> 736.5 | F20: =AVERAGE(B15:B20) -> 830.08333
A21: 38718 | B21: 851.83333 | C21: =AVERAGE($B$2:B21) -> 623.26667 | D21: =AVERAGE(B4:B21) -> 650.26852 | E21: =AVERAGE(B10:B21) -> 767.41667 | F21: =AVERAGE(B16:B21) -> 836.69444
A22: 38749 | B22: 855.66667 | C22: =AVERAGE($B$2:B22) -> 634.33333 | D22: =AVERAGE(B5:B22) -> 676.13889 | E22: =AVERAGE(B11:B22) -> 793.25 | F22: =AVERAGE(B17:B22) -> 842.75
A23: 38777 | B23: 859.5 | C23: =AVERAGE($B$2:B23) -> 644.56818 | D23: =AVERAGE(B6:B23) -> 701.86111 | E23: =AVERAGE(B12:B23) -> 814 | F23: =AVERAGE(B18:B23) -> 848.25
A24: 38808 | B24: 863.33333 | C24: =AVERAGE($B$2:B24) -> 654.07971 | D24: =AVERAGE(B7:B24) -> 727.43519 | E24: =AVERAGE(B13:B24) -> 829.66667 | F24: =AVERAGE(B19:B24) -> 853.19444
A25: 38838 | B25: 867.16667 | C25: =AVERAGE($B$2:B25) -> 662.95833 | D25: =AVERAGE(B8:B25) -> 752.86111 | E25: =AVERAGE(B14:B25) -> 840.25 | F25: =AVERAGE(B20:B25) -> 857.58333
A26: 38869 | B26: 871 | C26: =AVERAGE(B3:B26) -> 683.54167 | D26: =AVERAGE(B9:B26) -> 778.13889 | E26: =AVERAGE(B15:B26) -> 845.75 | F26: =AVERAGE(B21:B26) -> 861.41667
A27: 38899 | B27: 846.83333 | C27: =AVERAGE(B4:B27) -> 702.84722 | D27: =AVERAGE(B10:B27) -> 798.47222 | E27: =AVERAGE(B16:B27) -> 848.63889 | F27: =AVERAGE(B22:B27) -> 860.58333
A28: 38930 | B28: 822.66667 | C28: =AVERAGE(B5:B28) -> 720.875 | D28: =AVERAGE(B11:B28) -> 813.86111 | E28: =AVERAGE(B17:B28) -> 848.91667 | F28: =AVERAGE(B23:B28) -> 855.08333
A29: 38961 | B29: 798.5 | C29: =AVERAGE(B6:B29) -> 737.625 | D29: =AVERAGE(B12:B29) -> 824.30556 | E29: =AVERAGE(B18:B29) -> 846.58333 | F29: =AVERAGE(B24:B29) -> 844.91667
A30: 38991 | B30: 774.33333 | C30: =AVERAGE(B7:B30) -> 753.09722 | D30: =AVERAGE(B13:B30) -> 829.80556 | E30: =AVERAGE(B19:B30) -> 841.63889 | F30: =AVERAGE(B25:B30) -> 830.08333
A31: 39022 | B31: 750.16667 | C31: =AVERAGE(B8:B31) -> 767.29167 | D31: =AVERAGE(B14:B31) -> 830.36111 | E31: =AVERAGE(B20:B31) -> 834.08333 | F31: =AVERAGE(B26:B31) -> 810.58333
A32: 39052 | B32: 726 | C32: =AVERAGE(B9:B32) -> 780.20833 | D32: =AVERAGE(B15:B32) -> 825.97222 | E32: =AVERAGE(B21:B32) -> 823.91667 | F32: =AVERAGE(B27:B32) -> 786.41667
A33: 39083 | B33: 696.33333 | C33: =AVERAGE(B10:B33) -> 789.1875 | D33: =AVERAGE(B16:B33) -> 819.53704 | E33: =AVERAGE(B22:B33) -> 810.95833 | F33: =AVERAGE(B28:B33) -> 761.33333
A34: 39114 | B34: 666.66667 | C34: =AVERAGE(B11:B34) -> 794.22917 | D34: =AVERAGE(B17:B34) -> 811.05556 | E34: =AVERAGE(B23:B34) -> 795.20833 | F34: =AVERAGE(B29:B34) -> 735.33333
A35: 39142 | B35: 637 | C35: =AVERAGE(B12:B35) -> 795.33333 | D35: =AVERAGE(B18:B35) -> 800.52778 | E35: =AVERAGE(B24:B35) -> 776.66667 | F35: =AVERAGE(B30:B35) -> 708.41667
A36: 39173 | B36: 607.33333 | C36: =AVERAGE(B13:B36) -> 792.5 | D36: =AVERAGE(B19:B36) -> 787.9537 | E36: =AVERAGE(B25:B36) -> 755.33333 | F36: =AVERAGE(B31:B36) -> 680.58333
A37: 39203 | B37: 577.66667 | C37: =AVERAGE(B14:B37) -> 785.72917 | D37: =AVERAGE(B20:B37) -> 773.33333 | E37: =AVERAGE(B26:B37) -> 731.20833 | F37: =AVERAGE(B32:B37) -> 651.83333
... A144: 42461 | B144: 122.4 | C144: =AVERAGE(B121:B144) -> 120.79604 | D144: =AVERAGE(B127:B144) -> 122.57806 | E144: =AVERAGE(B133:B144) -> 124.6955 | F144: =AVERAGE(B139:B144) -> 124.20767

Sheet Purchase Index
B1: Month | C1: MBAVPRCH | I1: Row Labels | J1: Average of MBAVPRCH | N1: MBAVPRCH | O1: Inventory | P1: Inventory Adj | Q1: 24Mo MA | R1: 18Mo MA | S1: 12Mo MA | T1: 6Mo MA
A2: 32878 | B2: =A2-DAY(A2)+1 -> 32874 | C2: 80.2 | I2: 32874 | J2: 92.4 | M2: 32874 | N2: 92.4 | O2: =VLOOKUP(M2,'Hosing Inventory'!B:D,3,0) -> #N/A | P2: =N2/VLOOKUP(M2,'Hosing Inventory'!B:D,3,0) -> #N/A | Q2: #N/A | R2: #N/A | S2: #N/A | T2: #N/A
A3: 32885 | B3: =A3-DAY(A3)+1 -> 32874 | C3: 83.3 | I3: 32905 | J3: 100.175 | M3: 32905 | N3: 100.175 | O3: =VLOOKUP(M3,'Hosing Inventory'!B:D,3,0) -> #N/A | P3: =N3/VLOOKUP(M3,'Hosing Inventory'!B:D,3,0) -> #N/A | Q3: #N/A | R3: #N/A | S3: #N/A | T3: #N/A
A4: 32892 | B4: =A4-DAY(A4)+1 -> 32874 | C4: 101.2 | I4: 32933 | J4: 92.28 | M4: 32933 | N4: 92.28 | O4: =VLOOKUP(M4,'Hosing Inventory'!B:D,3,0) -> #N/A | P4: =N4/VLOOKUP(M4,'Hosing Inventory'!B:D,3,0) -> #N/A | Q4: #N/A | R4: #N/A | S4: #N/A | T4: #N/A
A5: 32899 | B5: =A5-DAY(A5)+1 -> 32874 | C5: 104.9 | I5: 32964 | J5: 91.25 | M5: 32964 | N5: 91.25 | O5: =VLOOKUP(M5,'Hosing Inventory'!B:D,3,0) -> #N/A | P5: =N5/VLOOKUP(M5,'Hosing Inventory'!B:D,3,0) -> #N/A | Q5: #N/A | R5: #N/A | S5: #N/A | T5: #N/A
A6: 32906 | B6: =A6-DAY(A6)+1 -> 32905 | C6: 95.3 | I6: 32994 | J6: 85.5 | M6: 32994 | N6: 85.5 | O6: =VLOOKUP(M6,'Hosing Inventory'!B:D,3,0) -> #N/A | P6: =N6/VLOOKUP(M6,'Hosing Inventory'!B:D,3,0) -> #N/A | Q6: #N/A | R6: #N/A | S6: #N/A | T6: #N/A
A7: 32913 | B7: =A7-DAY(A7)+1 -> 32905 | C7: 93.2 | I7: 33025 | J7: 92 | M7: 33025 | N7: 92 | O7: =VLOOKUP(M7,'Hosing Inventory'!B:D,3,0) -> #N/A | P7: =N7/VLOOKUP(M7,'Hosing Inventory'!B:D,3,0) -> #N/A | Q7: #N/A | R7: #N/A | S7: #N/A | T7: #N/A
A8: 32920 | B8: =A8-DAY(A8)+1 -> 32905 | C8: 93.4 | I8: 33055 | J8: 88.65 | M8: 33055 | N8: 88.65 | O8: =VLOOKUP(M8,'Hosing Inventory'!B:D,3,0) -> #N/A | P8: =N8/VLOOKUP(M8,'Hosing Inventory'!B:D,3,0) -> #N/A | Q8: #N/A | R8: #N/A | S8: #N/A | T8: #N/A
A9: 32927 | B9: =A9-DAY(A9)+1 -> 32905 | C9: 118.8 | I9: 33086 | J9: 89.18 | M9: 33086 | N9: 89.18 | O9: =VLOOKUP(M9,'Hosing Inventory'!B:D,3,0) -> #N/A | P9: =N9/VLOOKUP(M9,'Hosing Inventory'!B:D,3,0) -> #N/A | Q9: #N/A | R9: #N/A | S9: #N/A | T9: #N/A
A10: 32934 | B10: =A10-DAY(A10)+1 -> 32933 | C10: 95.5 | I10: 33117 | J10: 80.45 | M10: 33117 | N10: 80.45 | O10: =VLOOKUP(M10,'Hosing Inventory'!B:D,3,0) -> #N/A | P10: =N10/VLOOKUP(M10,'Hosing Inventory'!B:D,3,0) -> #N/A | Q10: #N/A | R10: #N/A | S10: #N/A | T10: #N/A
A11: 32941 | B11: =A11-DAY(A11)+1 -> 32933 | C11: 88.7 | I11: 33147 | J11: 74.95 | M11: 33147 | N11: 74.95 | O11: =VLOOKUP(M11,'Hosing Inventory'!B:D,3,0) -> #N/A | P11: =N11/VLOOKUP(M11,'Hosing Inventory'!B:D,3,0) -> #N/A | Q11: #N/A | R11: #N/A | S11: #N/A | T11: #N/A
A12: 32948 | B12: =A12-DAY(A12)+1 -> 32933 | C12: 86.7 | I12: 33178 | J12: 81.84 | M12: 33178 | N12: 81.84 | O12: =VLOOKUP(M12,'Hosing Inventory'!B:D,3,0) -> #N/A | P12: =N12/VLOOKUP(M12,'Hosing Inventory'!B:D,3,0) -> #N/A | Q12: #N/A | R12: #N/A | S12: #N/A | T12: #N/A
A13: 32955 | B13: =A13-DAY(A13)+1 -> 32933 | C13: 94.3 | I13: 33208 | J13: 78.9 | M13: 33208 | N13: 78.9 | O13: =VLOOKUP(M13,'Hosing Inventory'!B:D,3,0) -> #N/A | P13: =N13/VLOOKUP(M13,'Hosing Inventory'!B:D,3,0) -> #N/A | Q13: #N/A | R13: #N/A | S13: #N/A | T13: #N/A
... A114: 33662 | B114: =A114-DAY(A114)+1 -> 33635 | C114: 102.9 | I114: 36281 | J114: 288.275 | M114: 36281 | N114: 288.275 | O114: =VLOOKUP(M114,'Hosing Inventory'!B:D,3,0) -> 1.0054829 | P114: =N114/VLOOKUP(M114,'Hosing Inventory'!B:D,3,0) -> 286.70304 | Q114: #N/A | R114: #N/A | S114: #N/A | T114: #N/A
A115: 33669 | B115: =A115-DAY(A115)+1 -> 33664 | C115: 115.2 | I115: 36312 | J115: 309.6 | M115: 36312 | N115: 309.6 | O115: =VLOOKUP(M115,'Hosing Inventory'!B:D,3,0) -> 1.0068536 | P115: =N115/VLOOKUP(M115,'Hosing Inventory'!B:D,3,0) -> 307.49257 | Q115: =AVERAGE(P92:P115) -> #N/A | R115: =AVERAGE(P98:P115) -> #N/A | S115: =AVERAGE(P104:P115) -> #N/A | T115: =AVERAGE(P110:P115) -> 273.27902
A116: 33676 | B116: =A116-DAY(A116)+1 -> 33664 | C116: 118.8 | I116: 36342 | J116: 285.86 | M116: 36342 | N116: 285.86 | O116: =VLOOKUP(M116,'Hosing Inventory'!B:D,3,0) -> 1.0082243 | P116: =N116/VLOOKUP(M116,'Hosing Inventory'!B:D,3,0) -> 283.52817 | Q116: =AVERAGE(P93:P116) -> #N/A | R116: =AVERAGE(P99:P116) -> #N/A | S116: =AVERAGE(P105:P116) -> #N/A | T116: =AVERAGE(P111:P116) -> 276.15372
A117: 33683 | B117: =A117-DAY(A117)+1 -> 33664 | C117: 111.8 | I117: 36373 | J117: 277.45 | M117: 36373 | N117: 277.45 | O117: =VLOOKUP(M117,'Hosing Inventory'!B:D,3,0) -> 1.009595 | P117: =N117/VLOOKUP(M117,'Hosing Inventory'!B:D,3,0) -> 274.81316 | Q117: =AVERAGE(P94:P117) -> #N/A | R117: =AVERAGE(P100:P117) -> #N/A | S117: =AVERAGE(P106:P117) -> #N/A | T117: =AVERAGE(P112:P117) -> 280.84976
A118: 33690 | B118: =A118-DAY(A118)+1 -> 33664 | C118: 117.9 | I118: 36404 | J118: 264.85 | M118: 36404 | N118: 264.85 | O118: =VLOOKUP(M118,'Hosing Inventory'!B:D,3,0) -> 1.0109658 | P118: =N118/VLOOKUP(M118,'Hosing Inventory'!B:D,3,0) -> 261.97722 | Q118: =AVERAGE(P95:P118) -> #N/A | R118: =AVERAGE(P101:P118) -> #N/A | S118: =AVERAGE(P107:P118) -> #N/A | T118: =AVERAGE(P113:P118) -> 281.76316
A119: 33697 | B119: =A119-DAY(A119)+1 -> 33695 | C119: 104.1 | I119: 36434 | J119: 272.38 | M119: 36434 | N119: 272.38 | O119: =VLOOKUP(M119,'Hosing Inventory'!B:D,3,0) -> 1.0123365 | P119: =N119/VLOOKUP(M119,'Hosing Inventory'!B:D,3,0) -> 269.06074 | Q119: =AVERAGE(P96:P119) -> #N/A | R119: =AVERAGE(P102:P119) -> #N/A | S119: =AVERAGE(P108:P119) -> #N/A | T119: =AVERAGE(P114:P119) -> 280.59582
A120: 33704 | B120: =A120-DAY(A120)+1 -> 33695 | C120: 109.6 | I120: 36465 | J120: 295.475 | M120: 36465 | N120: 295.475 | O120: =VLOOKUP(M120,'Hosing Inventory'!B:D,3,0) -> 1.0137072 | P120: =N120/VLOOKUP(M120,'Hosing Inventory'!B:D,3,0) -> 291.47963 | Q120: =AVERAGE(P97:P120) -> #N/A | R120: =AVERAGE(P103:P120) -> #N/A | S120: =AVERAGE(P109:P120) -> #N/A | T120: =AVERAGE(P115:P120) -> 281.39192
A121: 33711 | B121: =A121-DAY(A121)+1 -> 33695 | C121: 146.6 | I121: 36495 | J121: 269.86 | M121: 36495 | N121: 269.86 | O121: =VLOOKUP(M121,'Hosing Inventory'!B:D,3,0) -> 1.0150779 | P121: =N121/VLOOKUP(M121,'Hosing Inventory'!B:D,3,0) -> 265.85151 | Q121: =AVERAGE(P98:P121) -> #N/A | R121: =AVERAGE(P104:P121) -> #N/A | S121: =AVERAGE(P110:P121) -> 273.86538 | T121: =AVERAGE(P116:P121) -> 274.45174
A122: 33718 | B122: =A122-DAY(A122)+1 -> 33695 | C122: 111.5 | I122: 36526 | J122: 281.325 | M122: 36526 | N122: 281.325 | O122: =VLOOKUP(M122,'Hosing Inventory'!B:D,3,0) -> 1.0164486 | P122: =N122/VLOOKUP(M122,'Hosing Inventory'!B:D,3,0) -> 276.77247 | Q122: =AVERAGE(P99:P122) -> #N/A | R122: =AVERAGE(P105:P122) -> #N/A | S122: =AVERAGE(P111:P122) -> 274.73975 | T122: =AVERAGE(P117:P122) -> 273.32579
A123: 33725 | B123: =A123-DAY(A123)+1 -> 33725 | C123: 110.9 | I123: 36557 | J123: 279.675 | M123: 36557 | N123: 279.675 | O123: =VLOOKUP(M123,'Hosing Inventory'!B:D,3,0) -> 1.0180452 | P123: =N123/VLOOKUP(M123,'Hosing Inventory'!B:D,3,0) -> 274.71766 | Q123: =AVERAGE(P100:P123) -> #N/A | R123: =AVERAGE(P106:P123) -> #N/A | S123: =AVERAGE(P112:P123) -> 277.07982 | T123: =AVERAGE(P118:P123) -> 273.30987
A124: 33732 | B124: =A124-DAY(A124)+1 -> 33725 | C124: 112.2 | I124: 36586 | J124: 296.18 | M124: 36586 | N124: 296.18 | O124: =VLOOKUP(M124,'Hosing Inventory'!B:D,3,0) -> 1.0196418 | P124: =N124/VLOOKUP(M124,'Hosing Inventory'!B:D,3,0) -> 290.47455 | Q124: =AVERAGE(P101:P124) -> #N/A | R124: =AVERAGE(P107:P124) -> #N/A | S124: =AVERAGE(P113:P124) -> 279.91129 | T124: =AVERAGE(P119:P124) -> 278.05943
A125: 33739 | B125: =A125-DAY(A125)+1 -> 33725 | C125: 112 | I125: 36617 | J125: 304.9 | M125: 36617 | N125: 304.9 | O125: =VLOOKUP(M125,'Hosing Inventory'!B:D,3,0) -> 1.0212384 | P125: =N125/VLOOKUP(M125,'Hosing Inventory'!B:D,3,0) -> 298.55907 | Q125: =AVERAGE(P102:P125) -> #N/A | R125: =AVERAGE(P108:P125) -> #N/A | S125: =AVERAGE(P114:P125) -> 281.78582 | T125: =AVERAGE(P120:P125) -> 282.97582
A126: 33746 | B126: =A126-DAY(A126)+1 -> 33725 | C126: 116.3 | I126: 36647 | J126: 303.775 | M126: 36647 | N126: 303.775 | O126: =VLOOKUP(M126,'Hosing Inventory'!B:D,3,0) -> 1.022835 | P126: =N126/VLOOKUP(M126,'Hosing Inventory'!B:D,3,0) -> 296.99315 | Q126: =AVERAGE(P103:P126) -> #N/A | R126: =AVERAGE(P109:P126) -> #N/A | S126: =AVERAGE(P115:P126) -> 282.64333 | T126: =AVERAGE(P121:P126) -> 283.89474
... A319: 35097 | B319: =A319-DAY(A319)+1 -> 35096 | C319: 163.3 | I319: 42522 | J319: 239.8 | M319: 42522 | N319: 239.8 | O319: =VLOOKUP(M319,'Hosing Inventory'!B:D,3,0) -> #N/A | P319: =N319/VLOOKUP(M319,'Hosing Inventory'!B:D,3,0) -> #N/A | Q319: =AVERAGE(P296:P319) -> #N/A | R319: =AVERAGE(P302:P319) -> #N/A | S319: =AVERAGE(P308:P319) -> #N/A | T319: =AVERAGE(P314:P319) -> #N/A
A320: 35104 | B320: =A320-DAY(A320)+1 -> 35096 | C320: 157.4 | I320: (blank)
A321: 35111 | B321: =A321-DAY(A321)+1 -> 35096 | C321: 173 | I321: Grand Total | J321: 252.85062
A322: 35118 | B322: =A322-DAY(A322)+1 -> 35096 | C322: 199.9
A323: 35125 | B323: =A323-DAY(A323)+1 -> 35125 | C323: 181.3
A324: 35132 | B324: =A324-DAY(A324)+1 -> 35125 | C324: 173.4
A325: 35139 | B325: =A325-DAY(A325)+1 -> 35125 | C325: 176.4
A326: 35146 | B326: =A326-DAY(A326)+1 -> 35125 | C326: 164.9
A327: 35153 | B327: =A327-DAY(A327)+1 -> 35125 | C327: 200.5
A328: 35160 | B328: =A328-DAY(A328)+1 -> 35156 | C328: 195.1
A329: 35167 | B329: =A329-DAY(A329)+1 -> 35156 | C329: 166.7
A330: 35174 | B330: =A330-DAY(A330)+1 -> 35156 | C330: 172.4
A331: 35181 | B331: =A331-DAY(A331)+1 -> 35156 | C331: 175.2
A332: 35188 | B332: =A332-DAY(A332)+1 -> 35186 | C332: 209.6
...

Sheet Hosing Inventory
C1: Total Housing Inventory (K) | D1: Normalized
A2: 36191 | B2: =A2-DAY(A2)+1 -> 36161 | C2: ='[1]Housing Stock'!S5 -> 70097 | D2: =C2/$C$2 -> 1
A3: 36219 | B3: =A3-DAY(A3)+1 -> 36192 | C3: ='[1]Housing Stock'!S6 -> 70193.083 | D3: =C3/$C$2 -> 1.0013707
A4: 36250 | B4: =A4-DAY(A4)+1 -> 36220 | C4: ='[1]Housing Stock'!S7 -> 70289.167 | D4: =C4/$C$2 -> 1.0027414
A5: 36280 | B5: =A5-DAY(A5)+1 -> 36251 | C5: ='[1]Housing Stock'!S8 -> 70385.25 | D5: =C5/$C$2 -> 1.0041122
A6: 36311 | B6: =A6-DAY(A6)+1 -> 36281 | C6: ='[1]Housing Stock'!S9 -> 70481.333 | D6: =C6/$C$2 -> 1.0054829
A7: 36341 | B7: =A7-DAY(A7)+1 -> 36312 | C7: ='[1]Housing Stock'!S10 -> 70577.417 | D7: =C7/$C$2 -> 1.0068536
A8: 36372 | B8: =A8-DAY(A8)+1 -> 36342 | C8: ='[1]Housing Stock'!S11 -> 70673.5 | D8: =C8/$C$2 -> 1.0082243
A9: 36403 | B9: =A9-DAY(A9)+1 -> 36373 | C9: ='[1]Housing Stock'!S12 -> 70769.583 | D9: =C9/$C$2 -> 1.009595
A10: 36433 | B10: =A10-DAY(A10)+1 -> 36404 | C10: ='[1]Housing Stock'!S13 -> 70865.667 | D10: =C10/$C$2 -> 1.0109658
A11: 36464 | B11: =A11-DAY(A11)+1 -> 36434 | C11: ='[1]Housing Stock'!S14 -> 70961.75 | D11: =C11/$C$2 -> 1.0123365
A12: 36494 | B12: =A12-DAY(A12)+1 -> 36465 | C12: ='[1]Housing Stock'!S15 -> 71057.833 | D12: =C12/$C$2 -> 1.0137072
A13: 36525 | B13: =A13-DAY(A13)+1 -> 36495 | C13: ='[1]Housing Stock'!S16 -> 71153.917 | D13: =C13/$C$2 -> 1.0150779
... A205: 42369 | B205: =A205-DAY(A205)+1 -> 42339 | C205: ='[1]Housing Stock'!S208 -> 74706 | D205: =C205/$C$2 -> 1.0657517
A206: 42400 | B206: =A206-DAY(A206)+1 -> 42370 | C206: 74706 | D206: =C206/$C$2 -> 1.0657517
A207: 42429 | B207: =A207-DAY(A207)+1 -> 42401 | C207: 74706 | D207: =C207/$C$2 -> 1.0657517
A208: 42460 | B208: =A208-DAY(A208)+1 -> 42430 | C208: 74706 | D208: =C208/$C$2 -> 1.0657517
A209: 42490 | B209: =A209-DAY(A209)+1 -> 42461 | C209: 74706 | D209: =C209/$C$2 -> 1.0657517
A210: 42521 | B210: =A210-DAY(A210)+1 -> 42491 | C210: 74706 | D210: =C210/$C$2 -> 1.0657517

Sheet Cello
B1: MCAI-Universe | C1: 24Mo MA | D1: 18Mo MA | E1: 12Mo MA | F1: 6Mo MA
A2: 37742 | B2: 0.031505553 | C2: =AVERAGE($B$2:B2) -> 0.031505553 | D2: =AVERAGE($B$2:B2) -> 0.031505553 | E2: =AVERAGE($B$2:B2) -> 0.031505553 | F2: =AVERAGE($B$2:B2) -> 0.031505553
A3: 37773 | B3: 0.029411136 | C3: =AVERAGE($B$2:B3) -> 0.030458345 | D3: =AVERAGE($B$2:B3) -> 0.030458345 | E3: =AVERAGE($B$2:B3) -> 0.030458345 | F3: =AVERAGE($B$2:B3) -> 0.030458345
A4: 37803 | B4: 0.031692185 | C4: =AVERAGE($B$2:B4) -> 0.030869625 | D4: =AVERAGE($B$2:B4) -> 0.030869625 | E4: =AVERAGE($B$2:B4) -> 0.030869625 | F4: =AVERAGE($B$2:B4) -> 0.030869625
A5: 37834 | B5: 0.031405848 | C5: =AVERAGE($B$2:B5) -> 0.031003681 | D5: =AVERAGE($B$2:B5) -> 0.031003681 | E5: =AVERAGE($B$2:B5) -> 0.031003681 | F5: =AVERAGE($B$2:B5) -> 0.031003681
A6: 37865 | B6: 0.024846743 | C6: =AVERAGE($B$2:B6) -> 0.029772293 | D6: =AVERAGE($B$2:B6) -> 0.029772293 | E6: =AVERAGE($B$2:B6) -> 0.029772293 | F6: =AVERAGE($B$2:B6) -> 0.029772293
A7: 37895 | B7: 0.022551663 | C7: =AVERAGE($B$2:B7) -> 0.028568855 | D7: =AVERAGE($B$2:B7) -> 0.028568855 | E7: =AVERAGE($B$2:B7) -> 0.028568855 | F7: =AVERAGE($B$2:B7) -> 0.028568855
A8: 37926 | B8: 0.030090776 | C8: =AVERAGE($B$2:B8) -> 0.028786272 | D8: =AVERAGE($B$2:B8) -> 0.028786272 | E8: =AVERAGE($B$2:B8) -> 0.028786272 | F8: =AVERAGE(B3:B8) -> 0.028333059
A9: 37956 | B9: 0.031031237 | C9: =AVERAGE($B$2:B9) -> 0.029066893 | D9: =AVERAGE($B$2:B9) -> 0.029066893 | E9: =AVERAGE($B$2:B9) -> 0.029066893 | F9: =AVERAGE(B4:B9) -> 0.028603075
A10: 37987 | B10: 0.051273919 | C10: =AVERAGE($B$2:B10) -> 0.03153434 | D10: =AVERAGE($B$2:B10) -> 0.03153434 | E10: =AVERAGE($B$2:B10) -> 0.03153434 | F10: =AVERAGE(B5:B10) -> 0.031866698
A11: 38018 | B11: 0.050524335 | C11: =AVERAGE($B$2:B11) -> 0.03343334 | D11: =AVERAGE($B$2:B11) -> 0.03343334 | E11: =AVERAGE($B$2:B11) -> 0.03343334 | F11: =AVERAGE(B6:B11) -> 0.035053112
A12: 38047 | B12: 0.051459235 | C12: =AVERAGE($B$2:B12) -> 0.035072057 | D12: =AVERAGE($B$2:B12) -> 0.035072057 | E12: =AVERAGE($B$2:B12) -> 0.035072057 | F12: =AVERAGE(B7:B12) -> 0.039488528
A13: 38078 | B13: 0.053398071 | C13: =AVERAGE($B$2:B13) -> 0.036599225 | D13: =AVERAGE($B$2:B13) -> 0.036599225 | E13: =AVERAGE($B$2:B13) -> 0.036599225 | F13: =AVERAGE(B8:B13) -> 0.044629596
A14: 38108 | B14: 0.055833945 | C14: =AVERAGE($B$2:B14) -> 0.038078819 | D14: =AVERAGE($B$2:B14) -> 0.038078819 | E14: =AVERAGE(B3:B14) -> 0.038626591 | F14: =AVERAGE(B9:B14) -> 0.048920124
A15: 38139 | B15: 0.046486909 | C15: =AVERAGE($B$2:B15) -> 0.038679397 | D15: =AVERAGE($B$2:B15) -> 0.038679397 | E15: =AVERAGE(B4:B15) -> 0.040049572 | F15: =AVERAGE(B10:B15) -> 0.051496069
A16: 38169 | B16: 0.043236855 | C16: =AVERAGE($B$2:B16) -> 0.038983227 | D16: =AVERAGE($B$2:B16) -> 0.038983227 | E16: =AVERAGE(B5:B16) -> 0.041011628 | F16: =AVERAGE(B11:B16) -> 0.050156558
A17: 38200 | B17: 0.050649945 | C17: =AVERAGE($B$2:B17) -> 0.039712397 | D17: =AVERAGE($B$2:B17) -> 0.039712397 | E17: =AVERAGE(B6:B17) -> 0.042615303 | F17: =AVERAGE(B12:B17) -> 0.050177493
A18: 38231 | B18: 0.05526795 | C18: =AVERAGE($B$2:B18) -> 0.04062743 | D18: =AVERAGE($B$2:B18) -> 0.04062743 | E18: =AVERAGE(B7:B18) -> 0.045150403 | F18: =AVERAGE(B13:B18) -> 0.050812279
A19: 38261 | B19: 0.053382001 | C19: =AVERAGE($B$2:B19) -> 0.041336017 | D19: =AVERAGE($B$2:B19) -> 0.041336017 | E19: =AVERAGE(B8:B19) -> 0.047719598 | F19: =AVERAGE(B14:B19) -> 0.050809601
A20: 38292 | B20: 0.054919325 | C20: =AVERAGE($B$2:B20) -> 0.042050928 | D20: =AVERAGE(B3:B20) -> 0.042636782 | E20: =AVERAGE(B9:B20) -> 0.049788644 | F20: =AVERAGE(B15:B20) -> 0.050657164
A21: 38322 | B21: 0.052246834 | C21: =AVERAGE($B$2:B21) -> 0.042560723 | D21: =AVERAGE(B4:B21) -> 0.043905432 | E21: =AVERAGE(B10:B21) -> 0.05155661 | F21: =AVERAGE(B16:B21) -> 0.051617152
A22: 38353 | B22: 0.058879966 | C22: =AVERAGE($B$2:B22) -> 0.04333783 | D22: =AVERAGE(B5:B22) -> 0.045415864 | E22: =AVERAGE(B11:B22) -> 0.052190448 | F22: =AVERAGE(B17:B22) -> 0.054224337
A23: 38384 | B23: 0.057210385 | C23: =AVERAGE($B$2:B23) -> 0.043968401 | D23: =AVERAGE(B6:B23) -> 0.04684945 | E23: =AVERAGE(B12:B23) -> 0.052747619 | F23: =AVERAGE(B18:B23) -> 0.055317744
A24: 38412 | B24: 0.057237224 | C24: =AVERAGE($B$2:B24) -> 0.044545306 | D24: =AVERAGE(B7:B24) -> 0.048648921 | E24: =AVERAGE(B13:B24) -> 0.053229118 | F24: =AVERAGE(B19:B24) -> 0.055645956
A25: 38443 | B25: 0.057535858 | C25: =AVERAGE(B2:B25) -> 0.045086579 | D25: =AVERAGE(B8:B25) -> 0.050592487 | E25: =AVERAGE(B14:B25) -> 0.053573933 | F25: =AVERAGE(B20:B25) -> 0.056338265
A26: 38473 | B26: 0.05077385 | C26: =AVERAGE(B3:B26) -> 0.045889425 | D26: =AVERAGE(B9:B26) -> 0.051741547 | E26: =AVERAGE(B15:B26) -> 0.053152259 | F26: =AVERAGE(B21:B26) -> 0.055647353
A27: 38504 | B27: 0.056714358 | C27: =AVERAGE(B4:B27) -> 0.047027059 | D27: =AVERAGE(B10:B27) -> 0.053168387 | E27: =AVERAGE(B16:B27) -> 0.054004546 | F27: =AVERAGE(B22:B27) -> 0.05639194
A28: 38534 | B28: 0.057919481 | C28: =AVERAGE(B5:B28) -> 0.048119863 | D28: =AVERAGE(B11:B28) -> 0.053537585 | E28: =AVERAGE(B17:B28) -> 0.055228098 | F28: =AVERAGE(B23:B28) -> 0.056231859
A29: 38565 | B29: 0.05959428 | C29: =AVERAGE(B6:B29) -> 0.049294381 | D29: =AVERAGE(B12:B29) -> 0.054041471 | E29: =AVERAGE(B18:B29) -> 0.055973459 | F29: =AVERAGE(B24:B29) -> 0.056629175
A30: 38596 | B30: 0.053047415 | C30: =AVERAGE(B7:B30) -> 0.050469409 | D30: =AVERAGE(B13:B30) -> 0.054129703 | E30: =AVERAGE(B19:B30) -> 0.055788415 | F30: =AVERAGE(B25:B30) -> 0.055930874
A31: 38626 | B31: 0.056080162 | C31: =AVERAGE(B8:B31) -> 0.05186643 | D31: =AVERAGE(B14:B31) -> 0.054278708 | E31: =AVERAGE(B20:B31) -> 0.056013261 | F31: =AVERAGE(B26:B31) -> 0.055688258
A32: 38657 | B32: 0.057139927 | C32: =AVERAGE(B9:B32) -> 0.052993478 | D32: =AVERAGE(B15:B32) -> 0.054351262 | E32: =AVERAGE(B21:B32) -> 0.056198312 | F32: =AVERAGE(B27:B32) -> 0.05674927
A33: 38687 | B33: 0.05150863 | C33: =AVERAGE(B10:B33) -> 0.053846702 | D33: =AVERAGE(B16:B33) -> 0.054630247 | E33: =AVERAGE(B22:B33) -> 0.056136795 | F33: =AVERAGE(B28:B33) -> 0.055881649
A34: 38718 | B34: 0.055999784 | C34: =AVERAGE(B11:B34) -> 0.054043614 | D34: =AVERAGE(B17:B34) -> 0.055339299 | E34: =AVERAGE(B23:B34) -> 0.055896779 | F34: =AVERAGE(B29:B34) -> 0.0555617
A35: 38749 | B35: 0.058120425 | C35: =AVERAGE(B12:B35) -> 0.054360117 | D35: =AVERAGE(B18:B35) -> 0.055754325 | E35: =AVERAGE(B24:B35) -> 0.055972616 | F35: =AVERAGE(B30:B35) -> 0.055316057
A36: 38777 | B36: 0.060419452 | C36: =AVERAGE(B13:B36) -> 0.05473346 | D36: =AVERAGE(B19:B36) -> 0.05604052 | E36: =AVERAGE(B25:B36) -> 0.056237802 | F36: =AVERAGE(B31:B36) -> 0.05654473
... A154: 42370 | B154: 0.024942796 | C154: =AVERAGE(B131:B154) -> 0.026198903 | D154: =AVERAGE(B137:B154) -> 0.026648616 | E154: =AVERAGE(B143:B154) -> 0.026616439 | F154: =AVERAGE(B149:B154) -> 0.026022331

Sheet Tracking Diff
B1: act | C1: mdl | D1: Diff
A2: 34335 | B2: 1.1110551 | C2: 2.5861818 | D2: =ABS(C2-B2) -> 1.4751267
A3: 34394 | B3: 20.570074 | C3: 23.125859 | D3: =ABS(C3-B3) -> 2.555785
A4: 34486 | B4: 0.15474712 | C4: 2.2872661 | D4: =ABS(C4-B4) -> 2.1325189
A5: 34516 | B5: 7.5959542 | C5: 7.4836535 | D5: =ABS(C5-B5) -> 0.11230065
A6: 34547 | B6: 6.03597 | C6: 6.9729926 | D6: =ABS(C6-B6) -> 0.93702258
A7: 34578 | B7: 6.0766494 | C7: 6.5950601 | D7: =ABS(C7-B7) -> 0.51841072
A8: 34608 | B8: 5.4078252 | C8: 6.2497951 | D8: =ABS(C8-B8) -> 0.84196986
A9: 34639 | B9: 4.9789946 | C9: 5.2293702 | D9: =ABS(C9-B9) -> 0.25037565
A10: 34669 | B10: 5.0048594 | C10: 4.8477625 | D10: =ABS(C10-B10) -> 0.15709683
A11: 34700 | B11: 4.3062125 | C11: 4.0088874 | D11: =ABS(C11-B11) -> 0.29732508
A12: 34731 | B12: 4.0326649 | C12: 4.2915021 | D12: =ABS(C12-B12) -> 0.2588371
A13: 34759 | B13: 3.8047722 | C13: 5.9622964 | D13: =ABS(C13-B13) -> 2.1575242
... A265: 42491 | B265: 14.382712 | C265: 29.344364 | D265: =ABS(C265-B265) -> 14.961652

Sheet Regression
B1: Purchase | C1: MBACAI | D1: Regression | E1: Combine | F1: 18M MA | J1: Intercept | K1: Purchase | AC1: Purchase 18M | AD1: MBA CAI | AE1: Regression
A2: 32874 | B2: 92.4 | C2: =VLOOKUP(A2,'MBA CA Index'!A:B,2,0) -> #N/A | D2: =$J$2+$K$2*B2 -> -86.63304 | E2: =IF(ISNA(C2),D2,C2) -> -86.63304 | F2: =AVERAGE($E$2:E2) -> -86.63304 | J2: -277.7532 | K2: 2.0684 | AB2: 32874 | AC2: =AVERAGE($B$2:B2) -> 92.4 | AD2: =AVERAGE($C$2:C2) -> #N/A | AE2: =F2 -> -86.63304
A3: 32905 | B3: 100.175 | C3: =VLOOKUP(A3,'MBA CA Index'!A:B,2,0) -> #N/A | D3: =$J$2+$K$2*B3 -> -70.55123 | E3: =IF(ISNA(C3),D3,C3) -> -70.55123 | F3: =AVERAGE($E$2:E3) -> -78.592135 | AB3: 32905 | AC3: =AVERAGE($B$2:B3) -> 96.2875 | AD3: =AVERAGE($B$2:C3) -> #N/A | AE3: =F3 -> -78.592135
A4: 32933 | B4: 92.28 | C4: =VLOOKUP(A4,'MBA CA Index'!A:B,2,0) -> #N/A | D4: =$J$2+$K$2*B4 -> -86.881248 | E4: =IF(ISNA(C4),D4,C4) -> -86.881248 | F4: =AVERAGE($E$2:E4) -> -81.355173 | AB4: 32933 | AC4: =AVERAGE($B$2:B4) -> 94.951667 | AD4: =AVERAGE($B$2:C4) -> #N/A | AE4: =F4 -> -81.355173
A5: 32964 | B5: 91.25 | C5: =VLOOKUP(A5,'MBA CA Index'!A:B,2,0) -> #N/A | D5: =$J$2+$K$2*B5 -> -89.0117 | E5: =IF(ISNA(C5),D5,C5) -> -89.0117 | F5: =AVERAGE($E$2:E5) -> -83.269304 | AB5: 32964 | AC5: =AVERAGE($B$2:B5) -> 94.02625 | AD5: =AVERAGE($B$2:C5) -> #N/A | AE5: =F5 -> -83.269304
A6: 32994 | B6: 85.5 | C6: =VLOOKUP(A6,'MBA CA Index'!A:B,2,0) -> #N/A | D6: =$J$2+$K$2*B6 -> -100.905 | E6: =IF(ISNA(C6),D6,C6) -> -100.905 | F6: =AVERAGE($E$2:E6) -> -86.796444 | AB6: 32994 | AC6: =AVERAGE($B$2:B6) -> 92.321 | AD6: =AVERAGE($B$2:C6) -> #N/A | AE6: =F6 -> -86.796444
A7: 33025 | B7: 92 | C7: =VLOOKUP(A7,'MBA CA Index'!A:B,2,0) -> #N/A | D7: =$J$2+$K$2*B7 -> -87.4604 | E7: =IF(ISNA(C7),D7,C7) -> -87.4604 | F7: =AVERAGE($E$2:E7) -> -86.907103 | AB7: 33025 | AC7: =AVERAGE($B$2:B7) -> 92.2675 | AD7: =AVERAGE($B$2:C7) -> #N/A | AE7: =F7 -> -86.907103
A8: 33055 | B8: 88.65 | C8: =VLOOKUP(A8,'MBA CA Index'!A:B,2,0) -> #N/A | D8: =$J$2+$K$2*B8 -> -94.38954 | E8: =IF(ISNA(C8),D8,C8) -> -94.38954 | F8: =AVERAGE($E$2:E8) -> -87.976023 | AB8: 33055 | AC8: =AVERAGE($B$2:B8) -> 91.750714 | AD8: =AVERAGE($B$2:C8) -> #N/A | AE8: =F8 -> -87.976023
A9: 33086 | B9: 89.18 | C9: =VLOOKUP(A9,'MBA CA Index'!A:B,2,0) -> #N/A | D9: =$J$2+$K$2*B9 -> -93.293288 | E9: =IF(ISNA(C9),D9,C9) -> -93.293288 | F9: =AVERAGE($E$2:E9) -> -88.640681 | AB9: 33086 | AC9: =AVERAGE($B$2:B9) -> 91.429375 | AD9: =AVERAGE($B$2:C9) -> #N/A | AE9: =F9 -> -88.640681
A10: 33117 | B10: 80.45 | C10: =VLOOKUP(A10,'MBA CA Index'!A:B,2,0) -> #N/A | D10: =$J$2+$K$2*B10 -> -111.35042 | E10: =IF(ISNA(C10),D10,C10) -> -111.35042 | F10: =AVERAGE($E$2:E10) -> -91.163985 | AB10: 33117 | AC10: =AVERAGE($B$2:B10) -> 90.209444 | AD10: =AVERAGE($B$2:C10) -> #N/A | AE10: =F10 -> -91.163985
A11: 33147 | B11: 74.95 | C11: =VLOOKUP(A11,'MBA CA Index'!A:B,2,0) -> #N/A | D11: =$J$2+$K$2*B11 -> -122.72662 | E11: =IF(ISNA(C11),D11,C11) -> -122.72662 | F11: =AVERAGE($E$2:E11) -> -94.320249 | AB11: 33147 | AC11: =AVERAGE($B$2:B11) -> 88.6835 | AD11: =AVERAGE($B$2:C11) -> #N/A | AE11: =F11 -> -94.320249
A12: 33178 | B12: 81.84 | C12: =VLOOKUP(A12,'MBA CA Index'!A:B,2,0) -> #N/A | D12: =$J$2+$K$2*B12 -> -108.47534 | E12: =IF(ISNA(C12),D12,C12) -> -108.47534 | F12: =AVERAGE($E$2:E12) -> -95.607075 | AB12: 33178 | AC12: =AVERAGE($B$2:B12) -> 88.061364 | AD12: =AVERAGE($B$2:C12) -> #N/A | AE12: =F12 -> -95.607075
A13: 33208 | B13: 78.9 | C13: =VLOOKUP(A13,'MBA CA Index'!A:B,2,0) -> #N/A | D13: =$J$2+$K$2*B13 -> -114.55644 | E13: =IF(ISNA(C13),D13,C13) -> -114.55644 | F13: =AVERAGE($E$2:E13) -> -97.186189 | AB13: 33208 | AC13: =AVERAGE($B$2:B13) -> 87.297917 | AD13: =AVERAGE($B$2:C13) -> #N/A | AE13: =F13 -> -97.186189
A14: 33239 | B14: 87.375 | C14: =VLOOKUP(A14,'MBA CA Index'!A:B,2,0) -> #N/A | D14: =$J$2+$K$2*B14 -> -97.02675 | E14: =IF(ISNA(C14),D14,C14) -> -97.02675 | F14: =AVERAGE($E$2:E14) -> -97.173925 | AB14: 33239 | AC14: =AVERAGE($B$2:B14) -> 87.303846 | AD14: =AVERAGE($B$2:C14) -> #N/A | AE14: =F14 -> -97.173925
... A18: 33359 | B18: 117.32 | C18: =VLOOKUP(A18,'MBA CA Index'!A:B,2,0) -> #N/A | D18: =$J$2+$K$2*B18 -> -35.088512 | E18: =IF(ISNA(C18),D18,C18) -> -35.088512 | F18: =AVERAGE($E$2:E18) -> -85.797163 | AB18: 33359 | AC18: =AVERAGE($B$2:B18) -> 92.804118 | AD18: =AVERAGE($B$2:C18) -> #N/A | AE18: =F18 -> -85.797163
A19: 33390 | B19: 113.875 | C19: =VLOOKUP(A19,'MBA CA Index'!A:B,2,0) -> #N/A | D19: =$J$2+$K$2*B19 -> -42.21415 | E19: =IF(ISNA(C19),D19,C19) -> -42.21415 | F19: =AVERAGE($E$2:E19) -> -83.375885 | AB19: 33390 | AC19: =AVERAGE($B$2:B19) -> 93.974722 | AD19: =AVERAGE($C$2:C19) -> #N/A | AE19: =F19 -> -83.375885
A20: 33420 | B20: 116.875 | C20: =VLOOKUP(A20,'MBA CA Index'!A:B,2,0) -> #N/A | D20: =$J$2+$K$2*B20 -> -36.00895 | E20: =IF(ISNA(C20),D20,C20) -> -36.00895 | F20: =AVERAGE(E3:E20) -> -80.563435 | AB20: 33420 | AC20: =AVERAGE(B3:B20) -> 95.334444 | AD20: =AVERAGE(C3:C20) -> #N/A | AE20: =F20 -> -80.563435
A21: 33451 | B21: 105.26 | C21: =VLOOKUP(A21,'MBA CA Index'!A:B,2,0) -> #N/A | D21: =$J$2+$K$2*B21 -> -60.033416 | E21: =IF(ISNA(C21),D21,C21) -> -60.033416 | F21: =AVERAGE(E4:E21) -> -79.979112 | AB21: 33451 | AC21: =AVERAGE(B4:B21) -> 95.616944 | AD21: =AVERAGE(C4:C21) -> #N/A | AE21: =F21 -> -79.979112
A22: 33482 | B22: 106.9 | C22: =VLOOKUP(A22,'MBA CA Index'!A:B,2,0) -> #N/A | D22: =$J$2+$K$2*B22 -> -56.64124 | E22: =IF(ISNA(C22),D22,C22) -> -56.64124 | F22: =AVERAGE(E5:E22) -> -78.299112 | AB22: 33482 | AC22: =AVERAGE(B5:B22) -> 96.429167 | AD22: =AVERAGE(C5:C22) -> #N/A | AE22: =F22 -> -78.299112
A23: 33512 | B23: 112.225 | C23: =VLOOKUP(A23,'MBA CA Index'!A:B,2,0) -> #N/A | D23: =$J$2+$K$2*B23 -> -45.62701 | E23: =IF(ISNA(C23),D23,C23) -> -45.62701 | F23: =AVERAGE(E6:E23) -> -75.888851 | AB23: 33512 | AC23: =AVERAGE(B6:B23) -> 97.594444 | AD23: =AVERAGE(C6:C23) -> #N/A | AE23: =F23 -> -75.888851
A24: 33543 | B24: 103.5 | C24: =VLOOKUP(A24,'MBA CA Index'!A:B,2,0) -> #N/A | D24: =$J$2+$K$2*B24 -> -63.6738 | E24: =IF(ISNA(C24),D24,C24) -> -63.6738 | F24: =AVERAGE(E7:E24) -> -73.820451 | AB24: 33543 | AC24: =AVERAGE(B7:B24) -> 98.594444 | AD24: =AVERAGE(C7:C24) -> #N/A | AE24: =F24 -> -73.820451
A25: 33573 | B25: 100.25 | C25: =VLOOKUP(A25,'MBA CA Index'!A:B,2,0) -> #N/A | D25: =$J$2+$K$2*B25 -> -70.3961 | E25: =IF(ISNA(C25),D25,C25) -> -70.3961 | F25: =AVERAGE(E8:E25) -> -72.872434 | AB25: 33573 | AC25: =AVERAGE(B8:B25) -> 99.052778 | AD25: =AVERAGE(C8:C25) -> #N/A | AE25: =F25 -> -72.872434
A26: 33604 | B26: 132.84 | C26: =VLOOKUP(A26,'MBA CA Index'!A:B,2,0) -> #N/A | D26: =$J$2+$K$2*B26 -> -2.986944 | E26: =IF(ISNA(C26),D26,C26) -> -2.986944 | F26: =AVERAGE(E9:E26) -> -67.794512 | AB26: 33604 | AC26: =AVERAGE(B9:B26) -> 101.50778 | AD26: =AVERAGE(C9:C26) -> #N/A | AE26: =F26 -> -67.794512
A27: 33635 | B27: 129.375 | C27: =VLOOKUP(A27,'MBA CA Index'!A:B,2,0) -> #N/A | D27: =$J$2+$K$2*B27 -> -10.15395 | E27: =IF(ISNA(C27),D27,C27) -> -10.15395 | F27: =AVERAGE(E10:E27) -> -63.17566 | AB27: 33635 | AC27: =AVERAGE(B10:B27) -> 103.74083 | AD27: =AVERAGE(C10:C27) -> #N/A | AE27: =F27 -> -63.17566
A28: 33664 | B28: 115.925 | C28: =VLOOKUP(A28,'MBA CA Index'!A:B,2,0) -> #N/A | D28: =$J$2+$K$2*B28 -> -37.97393 | E28: =IF(ISNA(C28),D28,C28) -> -37.97393 | F28: =AVERAGE(E11:E28) -> -59.099189 | AB28: 33664 | AC28: =AVERAGE(B11:B28) -> 105.71167 | AD28: =AVERAGE(C11:C28) -> #N/A | AE28: =F28 -> -59.099189
A29: 33695 | B29: 117.95 | C29: =VLOOKUP(A29,'MBA CA Index'!A:B,2,0) -> #N/A | D29: =$J$2+$K$2*B29 -> -33.78542 | E29: =IF(ISNA(C29),D29,C29) -> -33.78542 | F29: =AVERAGE(E12:E29) -> -54.158011 | AB29: 33695 | AC29: =AVERAGE(B12:B29) -> 108.10056 | AD29: =AVERAGE(C12:C29) -> #N/A | AE29: =F29 -> -54.158011
A30: 33725 | B30: 117.66 | C30: =VLOOKUP(A30,'MBA CA Index'!A:B,2,0) -> #N/A | D30: =$J$2+$K$2*B30 -> -34.385256 | E30: =IF(ISNA(C30),D30,C30) -> -34.385256 | F30: =AVERAGE(E13:E30) -> -50.041895 | AB30: 33725 | AC30: =AVERAGE(B13:B30) -> 110.09056 | AD30: =AVERAGE(C13:C30) -> #N/A | AE30: =F30 -> -50.041895
A31: 33756 | B31: 117.05 | C31: =VLOOKUP(A31,'MBA CA Index'!A:B,2,0) -> #N/A | D31: =$J$2+$K$2*B31 -> -35.64698 | E31: =IF(ISNA(C31),D31,C31) -> -35.64698 | F31: =AVERAGE(E14:E31) -> -45.658036 | AB31: 33756 | AC31: =AVERAGE(B14:B31) -> 112.21 | AD31: =AVERAGE(C14:C31) -> #N/A | AE31: =F31 -> -45.658036
... A191: 38626 | B191: 469.35 | C191: =VLOOKUP(A191,'MBA CA Index'!A:B,2,0) -> 833.66667 | D191: =$J$2+$K$2*B191 -> 693.05034 | E191: =IF(ISNA(C191),D191,C191) -> 833.66667 | F191: =AVERAGE(E174:E191) -> 589.31872 | AB191: 38626 | AC191: =AVERAGE(B174:B191) -> 466.50306 | AD191: =AVERAGE(C174:C191) -> #N/A | AE191: =F191 -> 589.31872
A192: 38657 | B192: 473.025 | C192: =VLOOKUP(A192,'MBA CA Index'!A:B,2,0) -> 840.83333 | D192: =$J$2+$K$2*B192 -> 700.65171 | E192: =IF(ISNA(C192),D192,C192) -> 840.83333 | F192: =AVERAGE(E175:E192) -> 598.08333 | AB192: 38657 | AC192: =AVERAGE(B175:B192) -> 466.97528 | AD192: =AVERAGE($C$175:C192) -> 598.08333 | AF192: 598.08333
A193: 38687 | B193: 455.46 | C193: =VLOOKUP(A193,'MBA CA Index'!A:B,2,0) -> 848 | D193: =$J$2+$K$2*B193 -> 664.32026 | E193: =IF(ISNA(C193),D193,C193) -> 848 | F193: =AVERAGE(E176:E193) -> 624.25 | AB193: 38687 | AC193: =AVERAGE(B176:B193) -> 467.67306 | AD193: =AVERAGE(C176:C193) -> 624.25 | AF193: 624.25
A194: 38718 | B194: 452.675 | C194: =VLOOKUP(A194,'MBA CA Index'!A:B,2,0) -> 851.83333 | D194: =$J$2+$K$2*B194 -> 658.55977 | E194: =IF(ISNA(C194),D194,C194) -> 851.83333 | F194: =AVERAGE(E177:E194) -> 650.26852 | AB194: 38718 | AC194: =AVERAGE(B177:B194) -> 467.19056 | AD194: =AVERAGE(C177:C194) -> 650.26852 | AF194: 650.26852
A195: 38749 | B195: 406.575 | C195: =VLOOKUP(A195,'MBA CA Index'!A:B,2,0) -> 855.66667 | D195: =$J$2+$K$2*B195 -> 563.20653 | E195: =IF(ISNA(C195),D195,C195) -> 855.66667 | F195: =AVERAGE(E178:E195) -> 676.13889 | AB195: 38749 | AC195: =AVERAGE(B178:B195) -> 464.86278 | AD195: =AVERAGE(C178:C195) -> 676.13889 | AF195: 676.13889
A196: 38777 | B196: 407.58 | C196: =VLOOKUP(A196,'MBA CA Index'!A:B,2,0) -> 859.5 | D196: =$J$2+$K$2*B196 -> 565.28527 | E196: =IF(ISNA(C196),D196,C196) -> 859.5 | F196: =AVERAGE(E179:E196) -> 701.86111 | AB196: 38777 | AC196: =AVERAGE(B179:B196) -> 461.70889 | AD196: =AVERAGE(C179:C196) -> 701.86111 | AF196: 701.86111
A197: 38808 | B197: 411.95 | C197: =VLOOKUP(A197,'MBA CA Index'!A:B,2,0) -> 863.33333 | D197: =$J$2+$K$2*B197 -> 574.32418 | E197: =IF(ISNA(C197),D197,C197) -> 863.33333 | F197: =AVERAGE(E180:E197) -> 727.43519 | AB197: 38808 | AC197: =AVERAGE(B180:B197) -> 459.105 | AD197: =AVERAGE(C180:C197) -> 727.43519 | AF197: 727.43519
A198: 38838 | B198: 408.775 | C198: =VLOOKUP(A198,'MBA CA Index'!A:B,2,0) -> 867.16667 | D198: =$J$2+$K$2*B198 -> 567.75701 | E198: =IF(ISNA(C198),D198,C198) -> 867.16667 | F198: =AVERAGE(E181:E198) -> 752.86111 | AB198: 38838 | AC198: =AVERAGE(B181:B198) -> 455.60778 | AD198: =AVERAGE(C181:C198) -> 752.86111 | AF198: 752.86111
A199: 38869 | B199: 405.64 | C199: =VLOOKUP(A199,'MBA CA Index'!A:B,2,0) -> 871 | D199: =$J$2+$K$2*B199 -> 561.27258 | E199: =IF(ISNA(C199),D199,C199) -> 871 | F199: =AVERAGE(E182:E199) -> 778.13889 | AB199: 38869 | AC199: =AVERAGE(B182:B199) -> 452.01 | AD199: =AVERAGE(C182:C199) -> 778.13889 | AF199: 778.13889
A200: 38899 | B200: 397.175 | C200: =VLOOKUP(A200,'MBA CA Index'!A:B,2,0) -> 846.83333 | D200: =$J$2+$K$2*B200 -> 543.76357 | E200: =IF(ISNA(C200),D200,C200) -> 846.83333 | F200: =AVERAGE(E183:E200) -> 798.47222 | AB200: 38899 | AC200: =AVERAGE(B183:B200) -> 450.17944 | AD200: =AVERAGE(C183:C200) -> 798.47222 | AF200: 798.47222
A201: 38930 | B201: 383.225 | C201: =VLOOKUP(A201,'MBA CA Index'!A:B,2,0) -> 822.66667 | D201: =$J$2+$K$2*B201 -> 514.90939 | E201: =IF(ISNA(C201),D201,C201) -> 822.66667 | F201: =AVERAGE(E184:E201) -> 813.86111 | AB201: 38930 | AC201: =AVERAGE(B184:B201) -> 447.50167 | AD201: =AVERAGE(C184:C201) -> 813.86111 | AF201: 813.86111
A202: 38961 | B202: 395.66 | C202: =VLOOKUP(A202,'MBA CA Index'!A:B,2,0) -> 798.5 | D202: =$J$2+$K$2*B202 -> 540.62994 | E202: =IF(ISNA(C202),D202,C202) -> 798.5 | F202: =AVERAGE(E185:E202) -> 824.30556 | AB202: 38961 | AC202: =AVERAGE(B185:B202) -> 444.04111 | AD202: =AVERAGE(C185:C202) -> 824.30556 | AF202: 824.30556
...
