Workbook
Name temp: 'Refi Universe'!$E$1:$F$1262

Sheet OAS and Media Effect
A1: Date | B1: 4.5 2010 | C1: MTG[IOS IFN 34010 IO]::OAS | D1: 3.50 2012 | E1: 3 2012 | F1: Conventional 30y Primary Mort Rate - Production | G1: 30 Year Refinanceable Universe (rhs) | J1: Daily Refi Universe
A2: 40576 | B2: 314 | C2: 314 | F2: 4.982905 | G2: =VLOOKUP(A2,'[1]all FNCL'!A$2:B$993,2) -> 0.61149873 | H2: 4/2/2012 | I2: 0.86085196 | J2: =VLOOKUP(A2,'Refi Universe'!E:F,2,0) -> 0.58304512
A3: 40577 | B3: 311 | C3: 311 | F3: 5.013449 | G3: =VLOOKUP(A3,'[1]all FNCL'!A$2:B$993,2) -> 0.61074045 | H3: 4/3/2012 | I3: 0.86085196 | J3: =VLOOKUP(A3,'Refi Universe'!E:F,2,0) -> 0.55486214
A4: 40578 | B4: 283 | C4: 283 | F4: 5.059674 | G4: =VLOOKUP(A4,'[1]all FNCL'!A$2:B$993,2) -> 0.61074045 | H4: 4/4/2012 | I4: 0.86085196 | J4: =VLOOKUP(A4,'Refi Universe'!E:F,2,0) -> 0.51847262
A5: 40581 | B5: 282 | C5: 282 | F5: 5.072852 | G5: =VLOOKUP(A5,'[1]all FNCL'!A$2:B$993,2) -> 0.61074045 | H5: 4/5/2012 | I5: 0.86928745 | J5: =VLOOKUP(A5,'Refi Universe'!E:F,2,0) -> 0.51165345
A6: 40582 | B6: 267 | C6: 267 | F6: 5.132882 | G6: =VLOOKUP(A6,'[1]all FNCL'!A$2:B$993,2) -> 0.61074045 | H6: 4/6/2012 | I6: 0.86928745 | J6: =VLOOKUP(A6,'Refi Universe'!E:F,2,0) -> 0.47964871
A7: 40583 | B7: 286 | C7: 286 | F7: 5.1065 | G7: =VLOOKUP(A7,'[1]all FNCL'!A$2:B$993,2) -> 0.61074045 | H7: 4/9/2012 | I7: 0.86928745 | J7: =VLOOKUP(A7,'Refi Universe'!E:F,2,0) -> 0.49256091 | O7: LIBOR OAS
A8: 40584 | B8: 285 | C8: 285 | F8: 5.14615 | G8: =VLOOKUP(A8,'[1]all FNCL'!A$2:B$993,2) -> 0.5083654 | H8: 4/10/2012 | I8: 0.86928745 | J8: =VLOOKUP(A8,'Refi Universe'!E:F,2,0) -> 0.47335129
A9: 40585 | B9: 374 | C9: 374 | F9: 5.089252 | G9: =VLOOKUP(A9,'[1]all FNCL'!A$2:B$993,2) -> 0.5083654 | H9: 4/11/2012 | I9: 0.86928745 | J9: =VLOOKUP(A9,'Refi Universe'!E:F,2,0) -> 0.5014984
A10: 40588 | B10: 302 | C10: 302 | F10: 5.05812 | G10: =VLOOKUP(A10,'[1]all FNCL'!A$2:B$993,2) -> 0.5083654 | H10: 4/12/2012 | I10: 0.90843431 | J10: =VLOOKUP(A10,'Refi Universe'!E:F,2,0) -> 0.51758932
A11: 40589 | B11: 286 | C11: 286 | F11: 5.054787 | G11: =VLOOKUP(A11,'[1]all FNCL'!A$2:B$993,2) -> 0.5083654 | H11: 4/13/2012 | I11: 0.90843431 | J11: =VLOOKUP(A11,'Refi Universe'!E:F,2,0) -> 0.52073838
A12: 40590 | B12: 279 | C12: 279 | F12: 5.062899 | G12: =VLOOKUP(A12,'[1]all FNCL'!A$2:B$993,2) -> 0.5083654 | H12: 4/16/2012 | I12: 0.90843431 | J12: =VLOOKUP(A12,'Refi Universe'!E:F,2,0) -> 0.54280907
A13: 40591 | B13: 288 | C13: 288 | F13: 5.028637 | G13: =VLOOKUP(A13,'[1]all FNCL'!A$2:B$993,2) -> 0.52920494 | H13: 4/17/2012 | I13: 0.90843431 | J13: =VLOOKUP(A13,'Refi Universe'!E:F,2,0) -> 0.5752636
A14: 40592 | B14: 289 | C14: 289 | F14: 5.041465 | G14: =VLOOKUP(A14,'[1]all FNCL'!A$2:B$993,2) -> 0.52920494 | H14: 4/18/2012 | I14: 0.90843431 | J14: =VLOOKUP(A14,'Refi Universe'!E:F,2,0) -> 0.56400059
A15: 40596 | B15: 308 | C15: 308 | F15: 5.002443 | G15: =VLOOKUP(A15,'[1]all FNCL'!A$2:B$993,2) -> 0.52920494 | H15: 4/19/2012 | I15: 0.90710064 | J15: =VLOOKUP(A15,'Refi Universe'!E:F,2,0) -> 0.60264124
A16: 40597 | B16: 306 | C16: 306 | F16: 5.003258 | G16: =VLOOKUP(A16,'[1]all FNCL'!A$2:B$993,2) -> 0.52920494 | H16: 4/20/2012 | I16: 0.90710064 | J16: =VLOOKUP(A16,'Refi Universe'!E:F,2,0) -> 0.59292309
A17: 40598 | B17: 308 | C17: 308 | F17: 4.974755 | G17: =VLOOKUP(A17,'[1]all FNCL'!A$2:B$993,2) -> 0.55803025 | H17: 4/23/2012 | I17: 0.90710064 | J17: =VLOOKUP(A17,'Refi Universe'!E:F,2,0) -> 0.60476842
A18: 40599 | B18: 315 | C18: 315 | F18: 4.96538 | G18: =VLOOKUP(A18,'[1]all FNCL'!A$2:B$993,2) -> 0.55803025 | H18: 4/24/2012 | I18: 0.90710064 | J18: =VLOOKUP(A18,'Refi Universe'!E:F,2,0) -> 0.60606985
A19: 40602 | B19: 319 | C19: 319 | F19: 4.957307 | G19: =VLOOKUP(A19,'[1]all FNCL'!A$2:B$993,2) -> 0.55803025 | H19: 4/25/2012 | I19: 0.90710064 | J19: =VLOOKUP(A19,'Refi Universe'!E:F,2,0) -> 0.61003046
... A507: 41313 | B507: 546 | C507: 546 | F507: 3.721522 | G507: =VLOOKUP(A507,'[1]all FNCL'!A$2:B$993,2) -> 0.82271172 | H507: 5/13/2014 | I507: 0.40121754 | J507: =VLOOKUP(A507,'Refi Universe'!E:F,2,0) -> 0.79899058
A508: 41316 | B508: 607 | C508: 607 | D508: 307 | E508: 235 | F508: 3.711424 | G508: =VLOOKUP(A508,'[1]all FNCL'!A$2:B$993,2) -> 0.82271172 | H508: 5/14/2014 | I508: 0.40121754 | J508: =VLOOKUP(A508,'Refi Universe'!E:F,2,0) -> 0.80855877
A509: 41317 | B509: 562 | C509: 562 | D509: 302 | E509: 171 | F509: 3.737002 | G509: =VLOOKUP(A509,'[1]all FNCL'!A$2:B$993,2) -> 0.82271172 | H509: 5/15/2014 | I509: 0.40418716 | J509: =VLOOKUP(A509,'Refi Universe'!E:F,2,0) -> 0.75767121
A510: 41318 | B510: 569 | C510: 569 | D510: 296 | E510: 175 | F510: 3.765228 | G510: =VLOOKUP(A510,'[1]all FNCL'!A$2:B$993,2) -> 0.82271172 | H510: 5/16/2014 | I510: 0.40418716 | J510: =VLOOKUP(A510,'Refi Universe'!E:F,2,0) -> 0.73648318
A511: 41319 | B511: 567 | C511: 567 | D511: 302 | E511: 176 | F511: 3.738366 | G511: =VLOOKUP(A511,'[1]all FNCL'!A$2:B$993,2) -> 0.82271172 | H511: 5/19/2014 | I511: 0.40418716 | J511: =VLOOKUP(A511,'Refi Universe'!E:F,2,0) -> 0.7754737
A512: 41320 | B512: 582 | C512: 582 | D512: 319 | E512: 177 | F512: 3.744896 | G512: =VLOOKUP(A512,'[1]all FNCL'!A$2:B$993,2) -> 0.82271172 | H512: 5/20/2014 | I512: 0.40418716 | J512: =VLOOKUP(A512,'Refi Universe'!E:F,2,0) -> 0.75767121
A513: 41324 | B513: 623 | C513: 623 | D513: 313 | E513: 187 | F513: 3.757999 | G513: =VLOOKUP(A513,'[1]all FNCL'!A$2:B$993,2) -> 0.82271172 | H513: 5/21/2014 | I513: 0.40418716 | J513: =VLOOKUP(A513,'Refi Universe'!E:F,2,0) -> 0.74506516
A514: 41325 | B514: 620 | C514: 620 | D514: 315 | E514: 192 | F514: 3.760095 | G514: =VLOOKUP(A514,'[1]all FNCL'!A$2:B$993,2) -> 0.82271172 | H514: 5/22/2014 | I514: 0.43156044 | J514: =VLOOKUP(A514,'Refi Universe'!E:F,2,0) -> 0.74910363
A515: 41326 | B515: 622 | C515: 622 | D515: 317 | E515: 190 | F515: 3.74624 | G515: =VLOOKUP(A515,'[1]all FNCL'!A$2:B$993,2) -> 0.79171462 | H515: 5/23/2014 | I515: 0.43156044 | J515: =VLOOKUP(A515,'Refi Universe'!E:F,2,0) -> 0.75956073
A516: 41327 | B516: 624 | C516: 624 | D516: 321 | E516: 169 | F516: 3.749736 | G516: =VLOOKUP(A516,'[1]all FNCL'!A$2:B$993,2) -> 0.79171462 | H516: 5/27/2014 | I516: 0.43156044 | J516: =VLOOKUP(A516,'Refi Universe'!E:F,2,0) -> 0.76181047
A517: 41330 | B517: 636 | C517: 636 | D517: 321 | E517: 151 | F517: 3.713573 | G517: =VLOOKUP(A517,'[1]all FNCL'!A$2:B$993,2) -> 0.79171462 | H517: 5/28/2014 | I517: 0.43156044 | J517: =VLOOKUP(A517,'Refi Universe'!E:F,2,0) -> 0.83204617
A518: 41331 | B518: 649 | C518: 649 | D518: 324 | E518: 159 | F518: 3.701635 | G518: =VLOOKUP(A518,'[1]all FNCL'!A$2:B$993,2) -> 0.79171462 | H518: 5/29/2014 | I518: 0.44289145 | J518: =VLOOKUP(A518,'Refi Universe'!E:F,2,0) -> 0.8421502
A519: 41332 | B519: 642 | C519: 642 | D519: 320 | E519: 164 | F519: 3.717285 | G519: =VLOOKUP(A519,'[1]all FNCL'!A$2:B$993,2) -> 0.79171462 | H519: 5/30/2014 | I519: 0.44289145 | J519: =VLOOKUP(A519,'Refi Universe'!E:F,2,0) -> 0.82756768
... A676: 41557 | B676: 336 | C676: 336 | D676: 109 | E676: 66 | F676: 4.2557 | G676: =VLOOKUP(A676,'[1]all FNCL'!A$2:B$993,2) -> 0.41233772 | H676: 1/15/2015 | I676: 0.65257309 | J676: =VLOOKUP(A676,'Refi Universe'!E:F,2,0) -> 0.40641393
A677: 41558 | B677: 342 | C677: 342 | D677: 118 | E677: 69 | F677: 4.261774 | G677: =VLOOKUP(A677,'[1]all FNCL'!A$2:B$993,2) -> 0.41233772 | H677: 42020 | I677: 0.65257309 | J677: =VLOOKUP(A677,'Refi Universe'!E:F,2,0) -> 0.40564359
A678: 41562 | B678: 353 | C678: 353 | D678: 124 | E678: 76 | F678: 4.293714 | G678: =VLOOKUP(A678,'[1]all FNCL'!A$2:B$993,2) -> 0.41233772 | J678: =VLOOKUP(A678,'Refi Universe'!E:F,2,0) -> 0.39927588
A679: 41563 | B679: 358 | C679: 358 | D679: 127 | E679: 76 | F679: 4.257464 | G679: =VLOOKUP(A679,'[1]all FNCL'!A$2:B$993,2) -> 0.41233772 | J679: =VLOOKUP(A679,'Refi Universe'!E:F,2,0) -> 0.40419689
A680: 41564 | B680: 381 | C680: 381 | D680: 133 | E680: 77 | F680: 4.183002 | G680: =VLOOKUP(A680,'[1]all FNCL'!A$2:B$993,2) -> 0.40226084 | J680: =VLOOKUP(A680,'Refi Universe'!E:F,2,0) -> 0.42440229
A681: 41565 | B681: 391 | C681: 391 | D681: 115 | E681: 62 | F681: 4.183854 | G681: =VLOOKUP(A681,'[1]all FNCL'!A$2:B$993,2) -> 0.40226084 | J681: =VLOOKUP(A681,'Refi Universe'!E:F,2,0) -> 0.42308899
A682: 41568 | B682: 383 | C682: 383 | D682: 120 | E682: 62 | F682: 4.202485 | G682: =VLOOKUP(A682,'[1]all FNCL'!A$2:B$993,2) -> 0.40226084 | J682: =VLOOKUP(A682,'Refi Universe'!E:F,2,0) -> 0.41834655
A683: 41569 | B683: 414 | C683: 414 | D683: 133 | E683: 69 | F683: 4.121184 | G683: =VLOOKUP(A683,'[1]all FNCL'!A$2:B$993,2) -> 0.40226084 | J683: =VLOOKUP(A683,'Refi Universe'!E:F,2,0) -> 0.45559037
...

Sheet Disclaimer
A1: This information has been prepared by the Corporate & Investment Banking Division of Barclays and is issued by Barclays Bank PLC and/or one or more of its affiliates (collectively and each individually, "Barclays"). All information is provided "as is" and Barclays makes no express or implied warranties, and expressly disclaims all warranties of merchantability or fitness for a particular purpose or use with respect to any data included herein. Barclays makes no representations that the information contained herein or any of the analytic tools or reports referenced herein are accurate, reliable, complete, or appropriate for use by all investors in all locations. Because of the possibility of human and mechanical errors as well as other factors, Barclays is not responsible for any errors or omissions in the information contained herein or any of the analytic tools or reports referenced herein. Barclays will not treat unauthorized recipients of this information herein as its clients.
A3: Without limiting any of the foregoing and to the extent permitted by law, in no event shall Barclays nor any of their respective officers, directors, partners, or employees have any liability for (a) any special, punitive, indirect, or consequential damages; or (b) any lost profits, lost revenue, loss of anticipated savings or loss of opportunity or other financial loss, even if notified of the possibility of such damages, arising from any use of, or reliance on, this information, analytic tools or reports referenced herein.
A5: Barclays is not utilizing this document to provide investment advice to you or any other party. The information, analytic tools or reports referenced herein and any results derived from their use provided herein are intended for informational purposes only and should not be regarded as an offer to sell or a solicitation of an offer to buy the products or securities to which it applies. No representation is made that any returns will be achieved through their use. Any data on past performance, modelling or back-testing contained herein is not necessarily indicative of future results. All levels, prices and spreads are historical and do not represent current market levels, prices or spreads, some or all of which may have changed. Any price provided herein is non-binding and is subject to change and may differ from a live bid, offer or price subsequently quoted by Barclays. The receipt by you of such price shall not constitute a binding transaction at such price. The information referenced herein or any of the results derived from any analytic tools or reports referenced herein are not intended to predict actual results and no assurances are given with respect thereto. Barclays does not guarantee the accuracy or completeness of information which is stated to have been obtained from, or is based upon, trade and statistical services or other third party sources. You should consult with your own accounting, legal or other advisors as to the adequacy of this information for your purposes.
A7: Barclays may (in various capacities) have inventory positions or deal in transactions or securities (or related derivatives) identical or similar to those described herein.
A9: Not all products or services mentioned are available in all jurisdictions. No offers, sales, resales, or delivery of any products or services described herein or any offering materials relating to any such products or services may be made in or from any jurisdiction except in circumstances which will result with compliance with any applicable laws and regulations and which will not impose any obligations on Barclays.
A11: This communication is being made available in the UK and Europe primarily to persons who are investment professionals as that term is defined in Article 19 of the Financial Services and Markets Act 2000 (Financial Promotion Order) 2005. It is directed at, and therefore should only be relied upon by, persons who have professional experience in matters relating to investments. The investments to which it relates are available only to such persons and will be entered into only with such persons. Barclays Bank PLC is authorised by the Prudential Regulation Authority and regulated by the Financial Conduct Authority and the Prudential Regulation Authority and is a member of the London Stock Exchange.
A13: Barclays Capital Inc., U.S. registered broker/dealer and member of FINRA (www.finra.org), is distributing this material in the United States and, in connection therewith accepts responsibility for its contents. Any U.S. person wishing to effect a transaction in any security discussed herein should do so only by contacting a representative of Barclays Capital Inc. in the U.S. at 745 Seventh Avenue, New York, New York 10019. Non-US persons should contact and execute transactions through a Barclays Bank PLC branch or affiliate in their home jurisdiction unless local regulations permit otherwise.
A15: IRS Circular 230 Prepared Materials Disclaimer: Barclays does not provide tax advice and nothing contained herein should be construed to be tax advice. Please be advised that any discussion of U.S. tax matters contained herein (including any attachments) (i) is not intended or written to be used, and cannot be used, by you for the purpose of avoiding U.S. tax-related penalties; and (ii) was written to support the promotion or marketing of the transactions or other matters addressed herein. Accordingly, you should seek advice based on your particular circumstances from an independent tax advisor.
A17: Barclays is not responsible for, and makes no warranties whatsoever as to, the content of any third-party web site accessed via a hyperlink contained herein and such information is not incorporated by reference.
A19: © Copyright Barclays Bank PLC (2015). All rights reserved. No part of this information may be reproduced in any manner without the prior written permission of Barclays or any of its affiliates. Barclays Bank PLC is registered in England No. 1026167. Registered office 1 Churchill Place, London, E14 5HP. Additional information will be furnished upon request.

Sheet Refi Universe
A1: 42390 | B1: 0.53686727 | E1: asof | F1: 0
A2: 42383 | B2: 0.48424776 | E2: 40548 | F2: 0.61432784
A3: 42376 | B3: 0.46862902 | E3: 40549 | F3: 0.61885565
A4: 42369 | B4: 0.44657508 | E4: 40550 | F4: 0.62793782
A5: 42362 | B5: 0.47802441 | E5: 40553 | F5: 0.6299181
A6: 42355 | B6: 0.47424192 | E6: 40554 | F6: 0.62592525
A7: 42348 | B7: 0.48108279 | E7: 40555 | F7: 0.6281149
A8: 42341 | B8: 0.48721505 | E8: 40556 | F8: 0.63372354
A9: 42333 | B9: 0.47590353 | E9: 40557 | F9: 0.63236365
A10: 42327 | B10: 0.47861527 | E10: 40561 | F10: 0.6272984
A11: 42320 | B11: 0.47253062 | E11: 40562 | F11: 0.62516854
A12: 42313 | B12: 0.5151151 | E12: 40563 | F12: 0.61496306
A13: 42306 | B13: 0.57894029 | E13: 40564 | F13: 0.61842282
... A56: 42004 | B56: 0.59452653 | E56: 40626 | F56: 0.59047443
E57: 40627 | F57: 0.5722928
E58: 40630 | F58: 0.57025108
E59: 40631 | F59: 0.54296453
E60: 40632 | F60: 0.59292116
E61: 40633 | F61: 0.59330693
E62: 40634 | F62: 0.58564294
E63: 40637 | F63: 0.58600547
E64: 40638 | F64: 0.56064664
E65: 40639 | F65: 0.55462959
E66: 40640 | F66: 0.5571321
E67: 40641 | F67: 0.5507678
E68: 40644 | F68: 0.55462959
... E1262: 42389 | F1262: 0.51737109

Sheet Daily Refi
V1: SeriesNumValue | W1: AsOfDate
B2: AsOfDate | C2: SeriesNumValue | D2: Rate | E2: Weekday | F2: Weight | G2: Counter | H2: Accumulated Weighted CC | I2: AccumulatedWeight | J2: WA CC | K2: Servicing Spread | L2: Servicing Spread Non-Zero | M2: Daily Mortgage Rate | V2: 3.71 | W2: 42390
B3: 2010-12-01 | C3: 3.9343682 | D3: 4.41 | E3: =WEEKDAY(B3,14) -> 7 | F3: =VLOOKUP(E3,Q$5:R$11,2,FALSE) -> 0.2 | G3: =IF(AND(E3>E2,G2<6),G2+1,1) -> 1 | H3: =IF(G3>G2,H2+C3*F3,C3*F3) -> 0.78687365 | I3: =IF(AND(G3<6,G3>G2),F3+I2,F3) -> 0.2 | J3: =IF(G3>G4,H3/I3,0) -> 0 | K3: =IF(CurrentMtgRatesDataTable811[[#This Row],[WA CC]]<>0,D2-CurrentMtgRatesDataTable811[[#This Row],[WA CC]],0) -> 0 | L3: =IF(CurrentMtgRatesDataTable811[[#This Row],[Servicing Spread]]<=0,L2,CurrentMtgRatesDataTable811[[#This Row],[Servicing Spread]]) -> Servicing Spread Non-Zero | M3: =CurrentMtgRatesDataTable811[[#This Row],[SeriesNumValue]]+CurrentMtgRatesDataTable811[[#This Row],[Servicing Spread Non-Zero]] -> #VALUE! | V3: 3.82 | W3: 42383
B4: 2010-12-02 | C4: 3.9593987 | D4: 4.535 | E4: =WEEKDAY(B4,14) -> 1 | F4: =VLOOKUP(E4,Q$5:R$11,2,FALSE) -> 0.2 | G4: =IF(AND(E4>E3,G3<6),G3+1,1) -> 1 | H4: =IF(G4>G3,H3+C4*F4,C4*F4) -> 0.79187974 | I4: =IF(AND(G4<6,G4>G3),F4+I3,F4) -> 0.2 | J4: =IF(G4>G5,H4/I4,0) -> 0 | K4: =IF(CurrentMtgRatesDataTable811[[#This Row],[WA CC]]<>0,D3-CurrentMtgRatesDataTable811[[#This Row],[WA CC]],0) -> 0 | L4: =IF(CurrentMtgRatesDataTable811[[#This Row],[Servicing Spread]]<=0,L3,CurrentMtgRatesDataTable811[[#This Row],[Servicing Spread]]) -> Servicing Spread Non-Zero | M4: =CurrentMtgRatesDataTable811[[#This Row],[SeriesNumValue]]+CurrentMtgRatesDataTable811[[#This Row],[Servicing Spread Non-Zero]] -> #VALUE! | V4: 3.87 | W4: 42376
B5: 2010-12-03 | C5: 3.944568 | D5: 4.535 | E5: =WEEKDAY(B5,14) -> 2 | F5: =VLOOKUP(E5,Q$5:R$11,2,FALSE) -> 0.2 | G5: =IF(AND(E5>E4,G4<6),G4+1,1) -> 2 | H5: =IF(G5>G4,H4+C5*F5,C5*F5) -> 1.5807933 | I5: =IF(AND(G5<6,G5>G4),F5+I4,F5) -> 0.4 | J5: =IF(G5>G6,H5/I5,0) -> 0 | K5: =IF(CurrentMtgRatesDataTable811[[#This Row],[WA CC]]<>0,D4-CurrentMtgRatesDataTable811[[#This Row],[WA CC]],0) -> 0 | L5: =IF(CurrentMtgRatesDataTable811[[#This Row],[Servicing Spread]]<=0,L4,CurrentMtgRatesDataTable811[[#This Row],[Servicing Spread]]) -> Servicing Spread Non-Zero | M5: =CurrentMtgRatesDataTable811[[#This Row],[SeriesNumValue]]+CurrentMtgRatesDataTable811[[#This Row],[Servicing Spread Non-Zero]] -> #VALUE! | P5: MONDAY | Q5: 5 | R5: 0.2 | V5: 3.91 | W5: 42369
B6: 2010-12-06 | C6: 3.8510282 | D6: 4.535 | E6: =WEEKDAY(B6,14) -> 5 | F6: =VLOOKUP(E6,Q$5:R$11,2,FALSE) -> 0.2 | G6: =IF(AND(E6>E5,G5<6),G5+1,1) -> 3 | H6: =IF(G6>G5,H5+C6*F6,C6*F6) -> 2.350999 | I6: =IF(AND(G6<6,G6>G5),F6+I5,F6) -> 0.6 | J6: =IF(G6>G7,H6/I6,0) -> 0 | K6: =IF(CurrentMtgRatesDataTable811[[#This Row],[WA CC]]<>0,D5-CurrentMtgRatesDataTable811[[#This Row],[WA CC]],0) -> 0 | L6: =IF(CurrentMtgRatesDataTable811[[#This Row],[Servicing Spread]]<=0,L5,CurrentMtgRatesDataTable811[[#This Row],[Servicing Spread]]) -> Servicing Spread Non-Zero | M6: =CurrentMtgRatesDataTable811[[#This Row],[SeriesNumValue]]+CurrentMtgRatesDataTable811[[#This Row],[Servicing Spread Non-Zero]] -> #VALUE! | P6: TUESDAY | Q6: 6 | R6: 0.2 | V6: 3.86 | W6: 42362
B7: 2010-12-07 | C7: 4.0550664 | D7: 4.535 | E7: =WEEKDAY(B7,14) -> 6 | F7: =VLOOKUP(E7,Q$5:R$11,2,FALSE) -> 0.2 | G7: =IF(AND(E7>E6,G6<6),G6+1,1) -> 4 | H7: =IF(G7>G6,H6+C7*F7,C7*F7) -> 3.1620123 | I7: =IF(AND(G7<6,G7>G6),F7+I6,F7) -> 0.8 | J7: =IF(G7>G8,H7/I7,0) -> 0 | K7: =IF(CurrentMtgRatesDataTable811[[#This Row],[WA CC]]<>0,D6-CurrentMtgRatesDataTable811[[#This Row],[WA CC]],0) -> 0 | L7: =IF(CurrentMtgRatesDataTable811[[#This Row],[Servicing Spread]]<=0,L6,CurrentMtgRatesDataTable811[[#This Row],[Servicing Spread]]) -> Servicing Spread Non-Zero | M7: =CurrentMtgRatesDataTable811[[#This Row],[SeriesNumValue]]+CurrentMtgRatesDataTable811[[#This Row],[Servicing Spread Non-Zero]] -> #VALUE! | P7: WEDNESDAY | Q7: 7 | R7: 0.2 | V7: 3.87 | W7: 42355
B8: 2010-12-08 | C8: 4.1053912 | D8: 4.535 | E8: =WEEKDAY(B8,14) -> 7 | F8: =VLOOKUP(E8,Q$5:R$11,2,FALSE) -> 0.2 | G8: =IF(AND(E8>E7,G7<6),G7+1,1) -> 5 | H8: =IF(G8>G7,H7+C8*F8,C8*F8) -> 3.9830905 | I8: =IF(AND(G8<6,G8>G7),F8+I7,F8) -> 1 | J8: =IF(G8>G9,H8/I8,0) -> 3.9830905 | K8: =IF(CurrentMtgRatesDataTable811[[#This Row],[WA CC]]<>0,D7-CurrentMtgRatesDataTable811[[#This Row],[WA CC]],0) -> 0.5519095 | L8: =IF(CurrentMtgRatesDataTable811[[#This Row],[Servicing Spread]]<=0,L7,CurrentMtgRatesDataTable811[[#This Row],[Servicing Spread]]) -> 0.5519095 | M8: =CurrentMtgRatesDataTable811[[#This Row],[SeriesNumValue]]+CurrentMtgRatesDataTable811[[#This Row],[Servicing Spread Non-Zero]] -> 4.6573007 | P8: THURSDAY | Q8: 1 | R8: 0.2 | V8: 3.85 | W8: 42348
B9: 2010-12-09 | C9: 4.0560726 | D9: 4.755 | E9: =WEEKDAY(B9,14) -> 1 | F9: =VLOOKUP(E9,Q$5:R$11,2,FALSE) -> 0.2 | G9: =IF(AND(E9>E8,G8<6),G8+1,1) -> 1 | H9: =IF(G9>G8,H8+C9*F9,C9*F9) -> 0.81121451 | I9: =IF(AND(G9<6,G9>G8),F9+I8,F9) -> 0.2 | J9: =IF(G9>G10,H9/I9,0) -> 0 | K9: =IF(CurrentMtgRatesDataTable811[[#This Row],[WA CC]]<>0,D8-CurrentMtgRatesDataTable811[[#This Row],[WA CC]],0) -> 0 | L9: =IF(CurrentMtgRatesDataTable811[[#This Row],[Servicing Spread]]<=0,L8,CurrentMtgRatesDataTable811[[#This Row],[Servicing Spread]]) -> 0.5519095 | M9: =CurrentMtgRatesDataTable811[[#This Row],[SeriesNumValue]]+CurrentMtgRatesDataTable811[[#This Row],[Servicing Spread Non-Zero]] -> 4.6079821 | P9: FRIDAY | Q9: 2 | R9: 0.2 | V9: 3.83 | W9: 42341
B10: 2010-12-10 | C10: 4.1283648 | D10: 4.755 | E10: =WEEKDAY(B10,14) -> 2 | F10: =VLOOKUP(E10,Q$5:R$11,2,FALSE) -> 0.2 | G10: =IF(AND(E10>E9,G9<6),G9+1,1) -> 2 | H10: =IF(G10>G9,H9+C10*F10,C10*F10) -> 1.6368875 | I10: =IF(AND(G10<6,G10>G9),F10+I9,F10) -> 0.4 | J10: =IF(G10>G11,H10/I10,0) -> 0 | K10: =IF(CurrentMtgRatesDataTable811[[#This Row],[WA CC]]<>0,D9-CurrentMtgRatesDataTable811[[#This Row],[WA CC]],0) -> 0 | L10: =IF(CurrentMtgRatesDataTable811[[#This Row],[Servicing Spread]]<=0,L9,CurrentMtgRatesDataTable811[[#This Row],[Servicing Spread]]) -> 0.5519095 | M10: =CurrentMtgRatesDataTable811[[#This Row],[SeriesNumValue]]+CurrentMtgRatesDataTable811[[#This Row],[Servicing Spread Non-Zero]] -> 4.6802743 | P10: SATURDAY | Q10: 3 | R10: 0 | V10: 3.875 | W10: 42333
B11: 2010-12-13 | C11: 4.1089743 | D11: 4.755 | E11: =WEEKDAY(B11,14) -> 5 | F11: =VLOOKUP(E11,Q$5:R$11,2,FALSE) -> 0.2 | G11: =IF(AND(E11>E10,G10<6),G10+1,1) -> 3 | H11: =IF(G11>G10,H10+C11*F11,C11*F11) -> 2.4586823 | I11: =IF(AND(G11<6,G11>G10),F11+I10,F11) -> 0.6 | J11: =IF(G11>G12,H11/I11,0) -> 0 | K11: =IF(CurrentMtgRatesDataTable811[[#This Row],[WA CC]]<>0,D10-CurrentMtgRatesDataTable811[[#This Row],[WA CC]],0) -> 0 | L11: =IF(CurrentMtgRatesDataTable811[[#This Row],[Servicing Spread]]<=0,L10,CurrentMtgRatesDataTable811[[#This Row],[Servicing Spread]]) -> 0.5519095 | M11: =CurrentMtgRatesDataTable811[[#This Row],[SeriesNumValue]]+CurrentMtgRatesDataTable811[[#This Row],[Servicing Spread Non-Zero]] -> 4.6608838 | P11: SUNDAY | Q11: 4 | R11: 0 | V11: 3.87 | W11: 42327
B12: 2010-12-14 | C12: 4.2874792 | D12: 4.755 | E12: =WEEKDAY(B12,14) -> 6 | F12: =VLOOKUP(E12,Q$5:R$11,2,FALSE) -> 0.2 | G12: =IF(AND(E12>E11,G11<6),G11+1,1) -> 4 | H12: =IF(G12>G11,H11+C12*F12,C12*F12) -> 3.3161782 | I12: =IF(AND(G12<6,G12>G11),F12+I11,F12) -> 0.8 | J12: =IF(G12>G13,H12/I12,0) -> 0 | K12: =IF(CurrentMtgRatesDataTable811[[#This Row],[WA CC]]<>0,D11-CurrentMtgRatesDataTable811[[#This Row],[WA CC]],0) -> 0 | L12: =IF(CurrentMtgRatesDataTable811[[#This Row],[Servicing Spread]]<=0,L11,CurrentMtgRatesDataTable811[[#This Row],[Servicing Spread]]) -> 0.5519095 | M12: =CurrentMtgRatesDataTable811[[#This Row],[SeriesNumValue]]+CurrentMtgRatesDataTable811[[#This Row],[Servicing Spread Non-Zero]] -> 4.8393887 | V12: 3.88 | W12: 42320
B13: 2010-12-15 | C13: 4.3841235 | D13: 4.755 | E13: =WEEKDAY(B13,14) -> 7 | F13: =VLOOKUP(E13,Q$5:R$11,2,FALSE) -> 0.2 | G13: =IF(AND(E13>E12,G12<6),G12+1,1) -> 5 | H13: =IF(G13>G12,H12+C13*F13,C13*F13) -> 4.1930029 | I13: =IF(AND(G13<6,G13>G12),F13+I12,F13) -> 1 | J13: =IF(G13>G14,H13/I13,0) -> 4.1930029 | K13: =IF(CurrentMtgRatesDataTable811[[#This Row],[WA CC]]<>0,D12-CurrentMtgRatesDataTable811[[#This Row],[WA CC]],0) -> 0.56199713 | L13: =IF(CurrentMtgRatesDataTable811[[#This Row],[Servicing Spread]]<=0,L12,CurrentMtgRatesDataTable811[[#This Row],[Servicing Spread]]) -> 0.56199713 | M13: =CurrentMtgRatesDataTable811[[#This Row],[SeriesNumValue]]+CurrentMtgRatesDataTable811[[#This Row],[Servicing Spread Non-Zero]] -> 4.9461206 | V13: 3.77 | W13: 42313
B14: 2010-12-16 | C14: 4.3563887 | D14: 4.735 | E14: =WEEKDAY(B14,14) -> 1 | F14: =VLOOKUP(E14,Q$5:R$11,2,FALSE) -> 0.2 | G14: =IF(AND(E14>E13,G13<6),G13+1,1) -> 1 | H14: =IF(G14>G13,H13+C14*F14,C14*F14) -> 0.87127775 | I14: =IF(AND(G14<6,G14>G13),F14+I13,F14) -> 0.2 | J14: =IF(G14>G15,H14/I14,0) -> 0 | K14: =IF(CurrentMtgRatesDataTable811[[#This Row],[WA CC]]<>0,D13-CurrentMtgRatesDataTable811[[#This Row],[WA CC]],0) -> 0 | L14: =IF(CurrentMtgRatesDataTable811[[#This Row],[Servicing Spread]]<=0,L13,CurrentMtgRatesDataTable811[[#This Row],[Servicing Spread]]) -> 0.56199713 | M14: =CurrentMtgRatesDataTable811[[#This Row],[SeriesNumValue]]+CurrentMtgRatesDataTable811[[#This Row],[Servicing Spread Non-Zero]] -> 4.9183859 | V14: 3.66 | W14: 42306
B15: 2010-12-17 | C15: 4.1670202 | D15: 4.735 | E15: =WEEKDAY(B15,14) -> 2 | F15: =VLOOKUP(E15,Q$5:R$11,2,FALSE) -> 0.2 | G15: =IF(AND(E15>E14,G14<6),G14+1,1) -> 2 | H15: =IF(G15>G14,H14+C15*F15,C15*F15) -> 1.7046818 | I15: =IF(AND(G15<6,G15>G14),F15+I14,F15) -> 0.4 | J15: =IF(G15>G16,H15/I15,0) -> 0 | K15: =IF(CurrentMtgRatesDataTable811[[#This Row],[WA CC]]<>0,D14-CurrentMtgRatesDataTable811[[#This Row],[WA CC]],0) -> 0 | L15: =IF(CurrentMtgRatesDataTable811[[#This Row],[Servicing Spread]]<=0,L14,CurrentMtgRatesDataTable811[[#This Row],[Servicing Spread]]) -> 0.56199713 | M15: =CurrentMtgRatesDataTable811[[#This Row],[SeriesNumValue]]+CurrentMtgRatesDataTable811[[#This Row],[Servicing Spread Non-Zero]] -> 4.7290173 | V15: 3.69 | W15: 42299
B16: 2010-12-20 | C16: 4.210619 | D16: 4.735 | E16: =WEEKDAY(B16,14) -> 5 | F16: =VLOOKUP(E16,Q$5:R$11,2,FALSE) -> 0.2 | G16: =IF(AND(E16>E15,G15<6),G15+1,1) -> 3 | H16: =IF(G16>G15,H15+C16*F16,C16*F16) -> 2.5468056 | I16: =IF(AND(G16<6,G16>G15),F16+I15,F16) -> 0.6 | J16: =IF(G16>G17,H16/I16,0) -> 0 | K16: =IF(CurrentMtgRatesDataTable811[[#This Row],[WA CC]]<>0,D15-CurrentMtgRatesDataTable811[[#This Row],[WA CC]],0) -> 0 | L16: =IF(CurrentMtgRatesDataTable811[[#This Row],[Servicing Spread]]<=0,L15,CurrentMtgRatesDataTable811[[#This Row],[Servicing Spread]]) -> 0.56199713 | M16: =CurrentMtgRatesDataTable811[[#This Row],[SeriesNumValue]]+CurrentMtgRatesDataTable811[[#This Row],[Servicing Spread Non-Zero]] -> 4.7726162 | V16: 3.72 | W16: 42292
B17: 2010-12-21 | C17: 4.174777 | D17: 4.735 | E17: =WEEKDAY(B17,14) -> 6 | F17: =VLOOKUP(E17,Q$5:R$11,2,FALSE) -> 0.2 | G17: =IF(AND(E17>E16,G16<6),G16+1,1) -> 4 | H17: =IF(G17>G16,H16+C17*F17,C17*F17) -> 3.381761 | I17: =IF(AND(G17<6,G17>G16),F17+I16,F17) -> 0.8 | J17: =IF(G17>G18,H17/I17,0) -> 0 | K17: =IF(CurrentMtgRatesDataTable811[[#This Row],[WA CC]]<>0,D16-CurrentMtgRatesDataTable811[[#This Row],[WA CC]],0) -> 0 | L17: =IF(CurrentMtgRatesDataTable811[[#This Row],[Servicing Spread]]<=0,L16,CurrentMtgRatesDataTable811[[#This Row],[Servicing Spread]]) -> 0.56199713 | M17: =CurrentMtgRatesDataTable811[[#This Row],[SeriesNumValue]]+CurrentMtgRatesDataTable811[[#This Row],[Servicing Spread Non-Zero]] -> 4.7367741 | V17: 3.66 | W17: 42285
B18: 2010-12-22 | C18: 4.1785024 | D18: 4.735 | E18: =WEEKDAY(B18,14) -> 7 | F18: =VLOOKUP(E18,Q$5:R$11,2,FALSE) -> 0.2 | G18: =IF(AND(E18>E17,G17<6),G17+1,1) -> 5 | H18: =IF(G18>G17,H17+C18*F18,C18*F18) -> 4.2174615 | I18: =IF(AND(G18<6,G18>G17),F18+I17,F18) -> 1 | J18: =IF(G18>G19,H18/I18,0) -> 4.2174615 | K18: =IF(CurrentMtgRatesDataTable811[[#This Row],[WA CC]]<>0,D17-CurrentMtgRatesDataTable811[[#This Row],[WA CC]],0) -> 0.51753854 | L18: =IF(CurrentMtgRatesDataTable811[[#This Row],[Servicing Spread]]<=0,L17,CurrentMtgRatesDataTable811[[#This Row],[Servicing Spread]]) -> 0.51753854 | M18: =CurrentMtgRatesDataTable811[[#This Row],[SeriesNumValue]]+CurrentMtgRatesDataTable811[[#This Row],[Servicing Spread Non-Zero]] -> 4.6960409 | V18: 3.75 | W18: 42278
B19: 2010-12-23 | C19: 4.2265071 | D19: 4.81 | E19: =WEEKDAY(B19,14) -> 1 | F19: =VLOOKUP(E19,Q$5:R$11,2,FALSE) -> 0.2 | G19: =IF(AND(E19>E18,G18<6),G18+1,1) -> 1 | H19: =IF(G19>G18,H18+C19*F19,C19*F19) -> 0.84530142 | I19: =IF(AND(G19<6,G19>G18),F19+I18,F19) -> 0.2 | J19: =IF(G19>G20,H19/I19,0) -> 0 | K19: =IF(CurrentMtgRatesDataTable811[[#This Row],[WA CC]]<>0,D18-CurrentMtgRatesDataTable811[[#This Row],[WA CC]],0) -> 0 | L19: =IF(CurrentMtgRatesDataTable811[[#This Row],[Servicing Spread]]<=0,L18,CurrentMtgRatesDataTable811[[#This Row],[Servicing Spread]]) -> 0.51753854 | M19: =CurrentMtgRatesDataTable811[[#This Row],[SeriesNumValue]]+CurrentMtgRatesDataTable811[[#This Row],[Servicing Spread Non-Zero]] -> 4.7440456 | V19: 3.785 | W19: 42271
B20: 2010-12-27 | C20: 4.2128405 | D20: 4.81 | E20: =WEEKDAY(B20,14) -> 5 | F20: =VLOOKUP(E20,Q$5:R$11,2,FALSE) -> 0.2 | G20: =IF(AND(E20>E19,G19<6),G19+1,1) -> 2 | H20: =IF(G20>G19,H19+C20*F20,C20*F20) -> 1.6878695 | I20: =IF(AND(G20<6,G20>G19),F20+I19,F20) -> 0.4 | J20: =IF(G20>G21,H20/I20,0) -> 0 | K20: =IF(CurrentMtgRatesDataTable811[[#This Row],[WA CC]]<>0,D19-CurrentMtgRatesDataTable811[[#This Row],[WA CC]],0) -> 0 | L20: =IF(CurrentMtgRatesDataTable811[[#This Row],[Servicing Spread]]<=0,L19,CurrentMtgRatesDataTable811[[#This Row],[Servicing Spread]]) -> 0.51753854 | M20: =CurrentMtgRatesDataTable811[[#This Row],[SeriesNumValue]]+CurrentMtgRatesDataTable811[[#This Row],[Servicing Spread Non-Zero]] -> 4.730379 | V20: 3.81 | W20: 42264
B21: 2010-12-28 | C21: 4.3267789 | D21: 4.81 | E21: =WEEKDAY(B21,14) -> 6 | F21: =VLOOKUP(E21,Q$5:R$11,2,FALSE) -> 0.2 | G21: =IF(AND(E21>E20,G20<6),G20+1,1) -> 3 | H21: =IF(G21>G20,H20+C21*F21,C21*F21) -> 2.5532253 | I21: =IF(AND(G21<6,G21>G20),F21+I20,F21) -> 0.6 | J21: =IF(G21>G22,H21/I21,0) -> 0 | K21: =IF(CurrentMtgRatesDataTable811[[#This Row],[WA CC]]<>0,D20-CurrentMtgRatesDataTable811[[#This Row],[WA CC]],0) -> 0 | L21: =IF(CurrentMtgRatesDataTable811[[#This Row],[Servicing Spread]]<=0,L20,CurrentMtgRatesDataTable811[[#This Row],[Servicing Spread]]) -> 0.51753854 | M21: =CurrentMtgRatesDataTable811[[#This Row],[SeriesNumValue]]+CurrentMtgRatesDataTable811[[#This Row],[Servicing Spread Non-Zero]] -> 4.8443175 | V21: 3.8 | W21: 42257
B22: 2010-12-29 | C22: 4.1712027 | D22: 4.81 | E22: =WEEKDAY(B22,14) -> 7 | F22: =VLOOKUP(E22,Q$5:R$11,2,FALSE) -> 0.2 | G22: =IF(AND(E22>E21,G21<6),G21+1,1) -> 4 | H22: =IF(G22>G21,H21+C22*F22,C22*F22) -> 3.3874658 | I22: =IF(AND(G22<6,G22>G21),F22+I21,F22) -> 0.8 | J22: =IF(G22>G23,H22/I22,0) -> 4.2343323 | K22: =IF(CurrentMtgRatesDataTable811[[#This Row],[WA CC]]<>0,D21-CurrentMtgRatesDataTable811[[#This Row],[WA CC]],0) -> 0.57566771 | L22: =IF(CurrentMtgRatesDataTable811[[#This Row],[Servicing Spread]]<=0,L21,CurrentMtgRatesDataTable811[[#This Row],[Servicing Spread]]) -> 0.57566771 | M22: =CurrentMtgRatesDataTable811[[#This Row],[SeriesNumValue]]+CurrentMtgRatesDataTable811[[#This Row],[Servicing Spread Non-Zero]] -> 4.7468704 | V22: 3.79 | W22: 42250
B23: 2010-12-30 | C23: 4.1887844 | D23: 4.72 | E23: =WEEKDAY(B23,14) -> 1 | F23: =VLOOKUP(E23,Q$5:R$11,2,FALSE) -> 0.2 | G23: =IF(AND(E23>E22,G22<6),G22+1,1) -> 1 | H23: =IF(G23>G22,H22+C23*F23,C23*F23) -> 0.83775689 | I23: =IF(AND(G23<6,G23>G22),F23+I22,F23) -> 0.2 | J23: =IF(G23>G24,H23/I23,0) -> 0 | K23: =IF(CurrentMtgRatesDataTable811[[#This Row],[WA CC]]<>0,D22-CurrentMtgRatesDataTable811[[#This Row],[WA CC]],0) -> 0 | L23: =IF(CurrentMtgRatesDataTable811[[#This Row],[Servicing Spread]]<=0,L22,CurrentMtgRatesDataTable811[[#This Row],[Servicing Spread]]) -> 0.57566771 | M23: =CurrentMtgRatesDataTable811[[#This Row],[SeriesNumValue]]+CurrentMtgRatesDataTable811[[#This Row],[Servicing Spread Non-Zero]] -> 4.7644521 | V23: 3.74 | W23: 42243
... B270: 2011-12-23 | C270: 3.1705041 | D270: 3.875 | E270: =WEEKDAY(B270,14) -> 2 | F270: =VLOOKUP(E270,Q$5:R$11,2,FALSE) -> 0.2 | G270: =IF(AND(E270>E269,G269<6),G269+1,1) -> 2 | H270: =IF(G270>G269,H269+C270*F270,C270*F270) -> 1.2532463 | I270: =IF(AND(G270<6,G270>G269),F270+I269,F270) -> 0.4 | J270: =IF(G270>G271,H270/I270,0) -> 0 | K270: =IF(CurrentMtgRatesDataTable811[[#This Row],[WA CC]]<>0,D269-CurrentMtgRatesDataTable811[[#This Row],[WA CC]],0) -> 0 | L270: =IF(CurrentMtgRatesDataTable811[[#This Row],[Servicing Spread]]<=0,L269,CurrentMtgRatesDataTable811[[#This Row],[Servicing Spread]]) -> 0.79175927 | M270: =CurrentMtgRatesDataTable811[[#This Row],[SeriesNumValue]]+CurrentMtgRatesDataTable811[[#This Row],[Servicing Spread Non-Zero]] -> 3.9622634 | V270: 4.41 | W270: 40514
B271: 2011-12-27 | C271: 3.1525411 | D271: 3.875 | E271: =WEEKDAY(B271,14) -> 6 | F271: =VLOOKUP(E271,Q$5:R$11,2,FALSE) -> 0.2 | G271: =IF(AND(E271>E270,G270<6),G270+1,1) -> 3 | H271: =IF(G271>G270,H270+C271*F271,C271*F271) -> 1.8837546 | I271: =IF(AND(G271<6,G271>G270),F271+I270,F271) -> 0.6 | J271: =IF(G271>G272,H271/I271,0) -> 0 | K271: =IF(CurrentMtgRatesDataTable811[[#This Row],[WA CC]]<>0,D270-CurrentMtgRatesDataTable811[[#This Row],[WA CC]],0) -> 0 | L271: =IF(CurrentMtgRatesDataTable811[[#This Row],[Servicing Spread]]<=0,L270,CurrentMtgRatesDataTable811[[#This Row],[Servicing Spread]]) -> 0.79175927 | M271: =CurrentMtgRatesDataTable811[[#This Row],[SeriesNumValue]]+CurrentMtgRatesDataTable811[[#This Row],[Servicing Spread Non-Zero]] -> 3.9443004
B272: 2011-12-28 | C272: 3.0482411 | D272: 3.875 | E272: =WEEKDAY(B272,14) -> 7 | F272: =VLOOKUP(E272,Q$5:R$11,2,FALSE) -> 0.2 | G272: =IF(AND(E272>E271,G271<6),G271+1,1) -> 4 | H272: =IF(G272>G271,H271+C272*F272,C272*F272) -> 2.4934028 | I272: =IF(AND(G272<6,G272>G271),F272+I271,F272) -> 0.8 | J272: =IF(G272>G273,H272/I272,0) -> 3.1167535 | K272: =IF(CurrentMtgRatesDataTable811[[#This Row],[WA CC]]<>0,D271-CurrentMtgRatesDataTable811[[#This Row],[WA CC]],0) -> 0.75824651 | L272: =IF(CurrentMtgRatesDataTable811[[#This Row],[Servicing Spread]]<=0,L271,CurrentMtgRatesDataTable811[[#This Row],[Servicing Spread]]) -> 0.75824651 | M272: =CurrentMtgRatesDataTable811[[#This Row],[SeriesNumValue]]+CurrentMtgRatesDataTable811[[#This Row],[Servicing Spread Non-Zero]] -> 3.8064876
B273: 2011-12-29 | C273: 3.0288836 | D273: 3.86 | E273: =WEEKDAY(B273,14) -> 1 | F273: =VLOOKUP(E273,Q$5:R$11,2,FALSE) -> 0.2 | G273: =IF(AND(E273>E272,G272<6),G272+1,1) -> 1 | H273: =IF(G273>G272,H272+C273*F273,C273*F273) -> 0.60577671 | I273: =IF(AND(G273<6,G273>G272),F273+I272,F273) -> 0.2 | J273: =IF(G273>G274,H273/I273,0) -> 0 | K273: =IF(CurrentMtgRatesDataTable811[[#This Row],[WA CC]]<>0,D272-CurrentMtgRatesDataTable811[[#This Row],[WA CC]],0) -> 0 | L273: =IF(CurrentMtgRatesDataTable811[[#This Row],[Servicing Spread]]<=0,L272,CurrentMtgRatesDataTable811[[#This Row],[Servicing Spread]]) -> 0.75824651 | M273: =CurrentMtgRatesDataTable811[[#This Row],[SeriesNumValue]]+CurrentMtgRatesDataTable811[[#This Row],[Servicing Spread Non-Zero]] -> 3.7871301
B274: 2011-12-30 | C274: 3.0169009 | D274: 3.86 | E274: =WEEKDAY(B274,14) -> 2 | F274: =VLOOKUP(E274,Q$5:R$11,2,FALSE) -> 0.2 | G274: =IF(AND(E274>E273,G273<6),G273+1,1) -> 2 | H274: =IF(G274>G273,H273+C274*F274,C274*F274) -> 1.2091569 | I274: =IF(AND(G274<6,G274>G273),F274+I273,F274) -> 0.4 | J274: =IF(G274>G275,H274/I274,0) -> 0 | K274: =IF(CurrentMtgRatesDataTable811[[#This Row],[WA CC]]<>0,D273-CurrentMtgRatesDataTable811[[#This Row],[WA CC]],0) -> 0 | L274: =IF(CurrentMtgRatesDataTable811[[#This Row],[Servicing Spread]]<=0,L273,CurrentMtgRatesDataTable811[[#This Row],[Servicing Spread]]) -> 0.75824651 | M274: =CurrentMtgRatesDataTable811[[#This Row],[SeriesNumValue]]+CurrentMtgRatesDataTable811[[#This Row],[Servicing Spread Non-Zero]] -> 3.7751474
B275: 2012-01-03 | C275: 2.9922052 | D275: 3.86 | E275: =WEEKDAY(B275,14) -> 6 | F275: =VLOOKUP(E275,Q$5:R$11,2,FALSE) -> 0.2 | G275: =IF(AND(E275>E274,G274<6),G274+1,1) -> 3 | H275: =IF(G275>G274,H274+C275*F275,C275*F275) -> 1.8075979 | I275: =IF(AND(G275<6,G275>G274),F275+I274,F275) -> 0.6 | J275: =IF(G275>G276,H275/I275,0) -> 0 | K275: =IF(CurrentMtgRatesDataTable811[[#This Row],[WA CC]]<>0,D274-CurrentMtgRatesDataTable811[[#This Row],[WA CC]],0) -> 0 | L275: =IF(CurrentMtgRatesDataTable811[[#This Row],[Servicing Spread]]<=0,L274,CurrentMtgRatesDataTable811[[#This Row],[Servicing Spread]]) -> 0.75824651 | M275: =CurrentMtgRatesDataTable811[[#This Row],[SeriesNumValue]]+CurrentMtgRatesDataTable811[[#This Row],[Servicing Spread Non-Zero]] -> 3.7504517
B276: 2012-01-04 | C276: 2.9957031 | D276: 3.86 | E276: =WEEKDAY(B276,14) -> 7 | F276: =VLOOKUP(E276,Q$5:R$11,2,FALSE) -> 0.2 | G276: =IF(AND(E276>E275,G275<6),G275+1,1) -> 4 | H276: =IF(G276>G275,H275+C276*F276,C276*F276) -> 2.4067385 | I276: =IF(AND(G276<6,G276>G275),F276+I275,F276) -> 0.8 | J276: =IF(G276>G277,H276/I276,0) -> 3.0084232 | K276: =IF(CurrentMtgRatesDataTable811[[#This Row],[WA CC]]<>0,D275-CurrentMtgRatesDataTable811[[#This Row],[WA CC]],0) -> 0.85157682 | L276: =IF(CurrentMtgRatesDataTable811[[#This Row],[Servicing Spread]]<=0,L275,CurrentMtgRatesDataTable811[[#This Row],[Servicing Spread]]) -> 0.85157682 | M276: =CurrentMtgRatesDataTable811[[#This Row],[SeriesNumValue]]+CurrentMtgRatesDataTable811[[#This Row],[Servicing Spread Non-Zero]] -> 3.8472799
B277: 2012-01-05 | C277: 2.9101104 | D277: 3.815 | E277: =WEEKDAY(B277,14) -> 1 | F277: =VLOOKUP(E277,Q$5:R$11,2,FALSE) -> 0.2 | G277: =IF(AND(E277>E276,G276<6),G276+1,1) -> 1 | H277: =IF(G277>G276,H276+C277*F277,C277*F277) -> 0.58202208 | I277: =IF(AND(G277<6,G277>G276),F277+I276,F277) -> 0.2 | J277: =IF(G277>G278,H277/I277,0) -> 0 | K277: =IF(CurrentMtgRatesDataTable811[[#This Row],[WA CC]]<>0,D276-CurrentMtgRatesDataTable811[[#This Row],[WA CC]],0) -> 0 | L277: =IF(CurrentMtgRatesDataTable811[[#This Row],[Servicing Spread]]<=0,L276,CurrentMtgRatesDataTable811[[#This Row],[Servicing Spread]]) -> 0.85157682 | M277: =CurrentMtgRatesDataTable811[[#This Row],[SeriesNumValue]]+CurrentMtgRatesDataTable811[[#This Row],[Servicing Spread Non-Zero]] -> 3.7616872
B278: 2012-01-06 | C278: 2.8573773 | D278: 3.815 | E278: =WEEKDAY(B278,14) -> 2 | F278: =VLOOKUP(E278,Q$5:R$11,2,FALSE) -> 0.2 | G278: =IF(AND(E278>E277,G277<6),G277+1,1) -> 2 | H278: =IF(G278>G277,H277+C278*F278,C278*F278) -> 1.1534975 | I278: =IF(AND(G278<6,G278>G277),F278+I277,F278) -> 0.4 | J278: =IF(G278>G279,H278/I278,0) -> 0 | K278: =IF(CurrentMtgRatesDataTable811[[#This Row],[WA CC]]<>0,D277-CurrentMtgRatesDataTable811[[#This Row],[WA CC]],0) -> 0 | L278: =IF(CurrentMtgRatesDataTable811[[#This Row],[Servicing Spread]]<=0,L277,CurrentMtgRatesDataTable811[[#This Row],[Servicing Spread]]) -> 0.85157682 | M278: =CurrentMtgRatesDataTable811[[#This Row],[SeriesNumValue]]+CurrentMtgRatesDataTable811[[#This Row],[Servicing Spread Non-Zero]] -> 3.7089541
B279: 2012-01-09 | C279: 2.8757178 | D279: 3.815 | E279: =WEEKDAY(B279,14) -> 5 | F279: =VLOOKUP(E279,Q$5:R$11,2,FALSE) -> 0.2 | G279: =IF(AND(E279>E278,G278<6),G278+1,1) -> 3 | H279: =IF(G279>G278,H278+C279*F279,C279*F279) -> 1.7286411 | I279: =IF(AND(G279<6,G279>G278),F279+I278,F279) -> 0.6 | J279: =IF(G279>G280,H279/I279,0) -> 0 | K279: =IF(CurrentMtgRatesDataTable811[[#This Row],[WA CC]]<>0,D278-CurrentMtgRatesDataTable811[[#This Row],[WA CC]],0) -> 0 | L279: =IF(CurrentMtgRatesDataTable811[[#This Row],[Servicing Spread]]<=0,L278,CurrentMtgRatesDataTable811[[#This Row],[Servicing Spread]]) -> 0.85157682 | M279: =CurrentMtgRatesDataTable811[[#This Row],[SeriesNumValue]]+CurrentMtgRatesDataTable811[[#This Row],[Servicing Spread Non-Zero]] -> 3.7272946
B280: 2012-01-10 | C280: 2.9177878 | D280: 3.815 | E280: =WEEKDAY(B280,14) -> 6 | F280: =VLOOKUP(E280,Q$5:R$11,2,FALSE) -> 0.2 | G280: =IF(AND(E280>E279,G279<6),G279+1,1) -> 4 | H280: =IF(G280>G279,H279+C280*F280,C280*F280) -> 2.3121987 | I280: =IF(AND(G280<6,G280>G279),F280+I279,F280) -> 0.8 | J280: =IF(G280>G281,H280/I280,0) -> 0 | K280: =IF(CurrentMtgRatesDataTable811[[#This Row],[WA CC]]<>0,D279-CurrentMtgRatesDataTable811[[#This Row],[WA CC]],0) -> 0 | L280: =IF(CurrentMtgRatesDataTable811[[#This Row],[Servicing Spread]]<=0,L279,CurrentMtgRatesDataTable811[[#This Row],[Servicing Spread]]) -> 0.85157682 | M280: =CurrentMtgRatesDataTable811[[#This Row],[SeriesNumValue]]+CurrentMtgRatesDataTable811[[#This Row],[Servicing Spread Non-Zero]] -> 3.7693646
B281: 2012-01-11 | C281: 2.883772 | D281: 3.815 | E281: =WEEKDAY(B281,14) -> 7 | F281: =VLOOKUP(E281,Q$5:R$11,2,FALSE) -> 0.2 | G281: =IF(AND(E281>E280,G280<6),G280+1,1) -> 5 | H281: =IF(G281>G280,H280+C281*F281,C281*F281) -> 2.8889531 | I281: =IF(AND(G281<6,G281>G280),F281+I280,F281) -> 1 | J281: =IF(G281>G282,H281/I281,0) -> 2.8889531 | K281: =IF(CurrentMtgRatesDataTable811[[#This Row],[WA CC]]<>0,D280-CurrentMtgRatesDataTable811[[#This Row],[WA CC]],0) -> 0.92604694 | L281: =IF(CurrentMtgRatesDataTable811[[#This Row],[Servicing Spread]]<=0,L280,CurrentMtgRatesDataTable811[[#This Row],[Servicing Spread]]) -> 0.92604694 | M281: =CurrentMtgRatesDataTable811[[#This Row],[SeriesNumValue]]+CurrentMtgRatesDataTable811[[#This Row],[Servicing Spread Non-Zero]] -> 3.809819
B282: 2012-01-12 | C282: 2.8523399 | D282: 3.83 | E282: =WEEKDAY(B282,14) -> 1 | F282: =VLOOKUP(E282,Q$5:R$11,2,FALSE) -> 0.2 | G282: =IF(AND(E282>E281,G281<6),G281+1,1) -> 1 | H282: =IF(G282>G281,H281+C282*F282,C282*F282) -> 0.57046798 | I282: =IF(AND(G282<6,G282>G281),F282+I281,F282) -> 0.2 | J282: =IF(G282>G283,H282/I282,0) -> 0 | K282: =IF(CurrentMtgRatesDataTable811[[#This Row],[WA CC]]<>0,D281-CurrentMtgRatesDataTable811[[#This Row],[WA CC]],0) -> 0 | L282: =IF(CurrentMtgRatesDataTable811[[#This Row],[Servicing Spread]]<=0,L281,CurrentMtgRatesDataTable811[[#This Row],[Servicing Spread]]) -> 0.92604694 | M282: =CurrentMtgRatesDataTable811[[#This Row],[SeriesNumValue]]+CurrentMtgRatesDataTable811[[#This Row],[Servicing Spread Non-Zero]] -> 3.7783869
... B1287: 2016-01-20 | C1287: 2.7399956 | D1287: 3.71 | E1287: =WEEKDAY(B1287,14) -> 7 | F1287: =VLOOKUP(E1287,Q$5:R$11,2,FALSE) -> 0.2 | G1287: =IF(AND(E1287>E1286,G1286<6),G1286+1,1) -> 4 | H1287: =IF(G1287>G1286,H1286+C1287*F1287,C1287*F1287) -> 2.2273222 | I1287: =IF(AND(G1287<6,G1287>G1286),F1287+I1286,F1287) -> 0.8 | J1287: =IF(G1287>G1288,H1287/I1287,0) -> 2.7841527 | K1287: =IF(CurrentMtgRatesDataTable811[[#This Row],[WA CC]]<>0,D1286-CurrentMtgRatesDataTable811[[#This Row],[WA CC]],0) -> 0.92584729 | L1287: =IF(CurrentMtgRatesDataTable811[[#This Row],[Servicing Spread]]<=0,L1286,CurrentMtgRatesDataTable811[[#This Row],[Servicing Spread]]) -> 0.92584729 | M1287: =CurrentMtgRatesDataTable811[[#This Row],[SeriesNumValue]]+CurrentMtgRatesDataTable811[[#This Row],[Servicing Spread Non-Zero]] -> 3.6658429
B1288: 2016-01-21
B1289: 2016-01-22
B1290: 2016-01-23
...
