Workbook
Name temp: 'Refi Universe'!$G$1:$H$1262

Sheet OAS and Media Effect
A1: Date | B1: 4.5 2010 | C1: MTG[IOS IFN 34010 IO]::OAS | D1: 3.50 2012 | E1: 3 2012 | F1: Conventional 30y Primary Mort Rate - Production | G1: 30 Year Refinanceable Universe (rhs) | J1: YB OAS | K1: Daily Refi Universe
A2: 40576 | B2: 314 | C2: 314 | F2: 4.982905 | G2: =VLOOKUP(A2,'[1]all FNCL'!A$2:B$993,2) -> 0.61149873 | H2: 4/2/2012 | I2: 0.86085196 | J2: =VLOOKUP(A2,'YB OAS'!B:E,4,0) -> E | K2: =VLOOKUP(A2,'Refi Universe'!E:F,2,0) -> 0.58304512
A3: 40577 | B3: 311 | C3: 311 | F3: 5.013449 | G3: =VLOOKUP(A3,'[1]all FNCL'!A$2:B$993,2) -> 0.61074045 | H3: 4/3/2012 | I3: 0.86085196 | J3: =VLOOKUP(A3,'YB OAS'!B:E,4,0) -> E | K3: =VLOOKUP(A3,'Refi Universe'!E:F,2,0) -> 0.55486214
A4: 40578 | B4: 283 | C4: 283 | F4: 5.059674 | G4: =VLOOKUP(A4,'[1]all FNCL'!A$2:B$993,2) -> 0.61074045 | H4: 4/4/2012 | I4: 0.86085196 | J4: =VLOOKUP(A4,'YB OAS'!B:E,4,0) -> E | K4: =VLOOKUP(A4,'Refi Universe'!E:F,2,0) -> 0.51847262
A5: 40581 | B5: 282 | C5: 282 | F5: 5.072852 | G5: =VLOOKUP(A5,'[1]all FNCL'!A$2:B$993,2) -> 0.61074045 | H5: 4/5/2012 | I5: 0.86928745 | J5: =VLOOKUP(A5,'YB OAS'!B:E,4,0) -> E | K5: =VLOOKUP(A5,'Refi Universe'!E:F,2,0) -> 0.51165345
A6: 40582 | B6: 267 | C6: 267 | F6: 5.132882 | G6: =VLOOKUP(A6,'[1]all FNCL'!A$2:B$993,2) -> 0.61074045 | H6: 4/6/2012 | I6: 0.86928745 | J6: =VLOOKUP(A6,'YB OAS'!B:E,4,0) -> E | K6: =VLOOKUP(A6,'Refi Universe'!E:F,2,0) -> 0.47964871
A7: 40583 | B7: 286 | C7: 286 | F7: 5.1065 | G7: =VLOOKUP(A7,'[1]all FNCL'!A$2:B$993,2) -> 0.61074045 | H7: 4/9/2012 | I7: 0.86928745 | J7: =VLOOKUP(A7,'YB OAS'!B:E,4,0) -> E | K7: =VLOOKUP(A7,'Refi Universe'!E:F,2,0) -> 0.49256091
A8: 40584 | B8: 285 | C8: 285 | F8: 5.14615 | G8: =VLOOKUP(A8,'[1]all FNCL'!A$2:B$993,2) -> 0.5083654 | H8: 4/10/2012 | I8: 0.86928745 | J8: =VLOOKUP(A8,'YB OAS'!B:E,4,0) -> E | K8: =VLOOKUP(A8,'Refi Universe'!E:F,2,0) -> 0.47335129
A9: 40585 | B9: 374 | C9: 374 | F9: 5.089252 | G9: =VLOOKUP(A9,'[1]all FNCL'!A$2:B$993,2) -> 0.5083654 | H9: 4/11/2012 | I9: 0.86928745 | J9: =VLOOKUP(A9,'YB OAS'!B:E,4,0) -> E | K9: =VLOOKUP(A9,'Refi Universe'!E:F,2,0) -> 0.5014984
A10: 40588 | B10: 302 | C10: 302 | F10: 5.05812 | G10: =VLOOKUP(A10,'[1]all FNCL'!A$2:B$993,2) -> 0.5083654 | H10: 4/12/2012 | I10: 0.90843431 | J10: =VLOOKUP(A10,'YB OAS'!B:F,5,0) -> -46.355499 | K10: =VLOOKUP(A10,'Refi Universe'!E:F,2,0) -> 0.51758932
A11: 40589 | B11: 286 | C11: 286 | F11: 5.054787 | G11: =VLOOKUP(A11,'[1]all FNCL'!A$2:B$993,2) -> 0.5083654 | H11: 4/13/2012 | I11: 0.90843431 | J11: =VLOOKUP(A11,'YB OAS'!B:F,5,0) -> -59.443802 | K11: =VLOOKUP(A11,'Refi Universe'!E:F,2,0) -> 0.52073838
A12: 40590 | B12: 279 | C12: 279 | F12: 5.062899 | G12: =VLOOKUP(A12,'[1]all FNCL'!A$2:B$993,2) -> 0.5083654 | H12: 4/16/2012 | I12: 0.90843431 | J12: =VLOOKUP(A12,'YB OAS'!B:F,5,0) -> -65.651901 | K12: =VLOOKUP(A12,'Refi Universe'!E:F,2,0) -> 0.54280907
A13: 40591 | B13: 288 | C13: 288 | F13: 5.028637 | G13: =VLOOKUP(A13,'[1]all FNCL'!A$2:B$993,2) -> 0.52920494 | H13: 4/17/2012 | I13: 0.90843431 | J13: =VLOOKUP(A13,'YB OAS'!B:F,5,0) -> -47.389 | K13: =VLOOKUP(A13,'Refi Universe'!E:F,2,0) -> 0.5752636
A14: 40592 | B14: 289 | C14: 289 | F14: 5.041465 | G14: =VLOOKUP(A14,'[1]all FNCL'!A$2:B$993,2) -> 0.52920494 | H14: 4/18/2012 | I14: 0.90843431 | J14: =VLOOKUP(A14,'YB OAS'!B:F,5,0) -> -51.927299 | K14: =VLOOKUP(A14,'Refi Universe'!E:F,2,0) -> 0.56400059
A15: 40596 | B15: 308 | C15: 308 | F15: 5.002443 | G15: =VLOOKUP(A15,'[1]all FNCL'!A$2:B$993,2) -> 0.52920494 | H15: 4/19/2012 | I15: 0.90710064 | J15: =VLOOKUP(A15,'YB OAS'!B:F,5,0) -> -36.043598 | K15: =VLOOKUP(A15,'Refi Universe'!E:F,2,0) -> 0.60264124
A16: 40597 | B16: 306 | C16: 306 | F16: 5.003258 | G16: =VLOOKUP(A16,'[1]all FNCL'!A$2:B$993,2) -> 0.52920494 | H16: 4/20/2012 | I16: 0.90710064 | J16: =VLOOKUP(A16,'YB OAS'!B:F,5,0) -> -40.838699 | K16: =VLOOKUP(A16,'Refi Universe'!E:F,2,0) -> 0.59292309
A17: 40598 | B17: 308 | C17: 308 | F17: 4.974755 | G17: =VLOOKUP(A17,'[1]all FNCL'!A$2:B$993,2) -> 0.55803025 | H17: 4/23/2012 | I17: 0.90710064 | J17: =VLOOKUP(A17,'YB OAS'!B:F,5,0) -> -36.337601 | K17: =VLOOKUP(A17,'Refi Universe'!E:F,2,0) -> 0.60476842
A18: 40599 | B18: 315 | C18: 315 | F18: 4.96538 | G18: =VLOOKUP(A18,'[1]all FNCL'!A$2:B$993,2) -> 0.55803025 | H18: 4/24/2012 | I18: 0.90710064 | J18: =VLOOKUP(A18,'YB OAS'!B:F,5,0) -> -30.010599 | K18: =VLOOKUP(A18,'Refi Universe'!E:F,2,0) -> 0.60606985
A19: 40602 | B19: 319 | C19: 319 | F19: 4.957307 | G19: =VLOOKUP(A19,'[1]all FNCL'!A$2:B$993,2) -> 0.55803025 | H19: 4/25/2012 | I19: 0.90710064 | J19: =VLOOKUP(A19,'YB OAS'!B:F,5,0) -> -27.406799 | K19: =VLOOKUP(A19,'Refi Universe'!E:F,2,0) -> 0.61003046
A20: 40603 | B20: 322 | C20: 322 | F20: 4.957528 | G20: =VLOOKUP(A20,'[1]all FNCL'!A$2:B$993,2) -> 0.54582432 | H20: 4/26/2012 | I20: 0.90843431 | J20: =VLOOKUP(A20,'YB OAS'!B:F,5,0) -> -22.981199 | K20: =VLOOKUP(A20,'Refi Universe'!E:F,2,0) -> 0.59558513
A21: 40604 | B21: 320 | C21: 320 | F21: 4.981656 | G21: =VLOOKUP(A21,'[1]all FNCL'!A$2:B$993,2) -> 0.54582432 | H21: 4/27/2012 | I21: 0.90843431 | J21: =VLOOKUP(A21,'YB OAS'!B:F,5,0) -> -28.4123 | K21: =VLOOKUP(A21,'Refi Universe'!E:F,2,0) -> 0.58351578
... A507: 41313 | B507: 546 | C507: 546 | F507: 3.721522 | G507: =VLOOKUP(A507,'[1]all FNCL'!A$2:B$993,2) -> 0.82271172 | H507: 5/13/2014 | I507: 0.40121754 | J507: =VLOOKUP(A507,'YB OAS'!B:F,5,0) -> 451.4668 | K507: =VLOOKUP(A507,'Refi Universe'!E:F,2,0) -> 0.79899058
A508: 41316 | B508: 607 | C508: 607 | D508: 307 | E508: 235 | F508: 3.711424 | G508: =VLOOKUP(A508,'[1]all FNCL'!A$2:B$993,2) -> 0.82271172 | H508: 5/14/2014 | I508: 0.40121754 | J508: =VLOOKUP(A508,'YB OAS'!B:F,5,0) -> 478.33621 | K508: =VLOOKUP(A508,'Refi Universe'!E:F,2,0) -> 0.80855877
A509: 41317 | B509: 562 | C509: 562 | D509: 302 | E509: 171 | F509: 3.737002 | G509: =VLOOKUP(A509,'[1]all FNCL'!A$2:B$993,2) -> 0.82271172 | H509: 5/15/2014 | I509: 0.40418716 | J509: =VLOOKUP(A509,'YB OAS'!B:F,5,0) -> 477.54089 | K509: =VLOOKUP(A509,'Refi Universe'!E:F,2,0) -> 0.75767121
A510: 41318 | B510: 569 | C510: 569 | D510: 296 | E510: 175 | F510: 3.765228 | G510: =VLOOKUP(A510,'[1]all FNCL'!A$2:B$993,2) -> 0.82271172 | H510: 5/16/2014 | I510: 0.40418716 | J510: =VLOOKUP(A510,'YB OAS'!B:F,5,0) -> 476.40799 | K510: =VLOOKUP(A510,'Refi Universe'!E:F,2,0) -> 0.73648318
A511: 41319 | B511: 567 | C511: 567 | D511: 302 | E511: 176 | F511: 3.738366 | G511: =VLOOKUP(A511,'[1]all FNCL'!A$2:B$993,2) -> 0.82271172 | H511: 5/19/2014 | I511: 0.40418716 | J511: =VLOOKUP(A511,'YB OAS'!B:F,5,0) -> 479.40008 | K511: =VLOOKUP(A511,'Refi Universe'!E:F,2,0) -> 0.7754737
A512: 41320 | B512: 582 | C512: 582 | D512: 319 | E512: 177 | F512: 3.744896 | G512: =VLOOKUP(A512,'[1]all FNCL'!A$2:B$993,2) -> 0.82271172 | H512: 5/20/2014 | I512: 0.40418716 | J512: =VLOOKUP(A512,'YB OAS'!B:F,5,0) -> 490.98279 | K512: =VLOOKUP(A512,'Refi Universe'!E:F,2,0) -> 0.75767121
A513: 41324 | B513: 623 | C513: 623 | D513: 313 | E513: 187 | F513: 3.757999 | G513: =VLOOKUP(A513,'[1]all FNCL'!A$2:B$993,2) -> 0.82271172 | H513: 5/21/2014 | I513: 0.40418716 | J513: =VLOOKUP(A513,'YB OAS'!B:F,5,0) -> 523.18982 | K513: =VLOOKUP(A513,'Refi Universe'!E:F,2,0) -> 0.74506516
A514: 41325 | B514: 620 | C514: 620 | D514: 315 | E514: 192 | F514: 3.760095 | G514: =VLOOKUP(A514,'[1]all FNCL'!A$2:B$993,2) -> 0.82271172 | H514: 5/22/2014 | I514: 0.43156044 | J514: =VLOOKUP(A514,'YB OAS'!B:F,5,0) -> 523.54883 | K514: =VLOOKUP(A514,'Refi Universe'!E:F,2,0) -> 0.74910363
A515: 41326 | B515: 622 | C515: 622 | D515: 317 | E515: 190 | F515: 3.74624 | G515: =VLOOKUP(A515,'[1]all FNCL'!A$2:B$993,2) -> 0.79171462 | H515: 5/23/2014 | I515: 0.43156044 | J515: =VLOOKUP(A515,'YB OAS'!B:F,5,0) -> 540.1828 | K515: =VLOOKUP(A515,'Refi Universe'!E:F,2,0) -> 0.75956073
A516: 41327 | B516: 624 | C516: 624 | D516: 321 | E516: 169 | F516: 3.749736 | G516: =VLOOKUP(A516,'[1]all FNCL'!A$2:B$993,2) -> 0.79171462 | H516: 5/27/2014 | I516: 0.43156044 | J516: =VLOOKUP(A516,'YB OAS'!B:F,5,0) -> 530.26148 | K516: =VLOOKUP(A516,'Refi Universe'!E:F,2,0) -> 0.76181047
A517: 41330 | B517: 636 | C517: 636 | D517: 321 | E517: 151 | F517: 3.713573 | G517: =VLOOKUP(A517,'[1]all FNCL'!A$2:B$993,2) -> 0.79171462 | H517: 5/28/2014 | I517: 0.43156044 | J517: =VLOOKUP(A517,'YB OAS'!B:F,5,0) -> 544.89648 | K517: =VLOOKUP(A517,'Refi Universe'!E:F,2,0) -> 0.83204617
A518: 41331 | B518: 649 | C518: 649 | D518: 324 | E518: 159 | F518: 3.701635 | G518: =VLOOKUP(A518,'[1]all FNCL'!A$2:B$993,2) -> 0.79171462 | H518: 5/29/2014 | I518: 0.44289145 | J518: =VLOOKUP(A518,'YB OAS'!B:F,5,0) -> 548.72937 | K518: =VLOOKUP(A518,'Refi Universe'!E:F,2,0) -> 0.8421502
A519: 41332 | B519: 642 | C519: 642 | D519: 320 | E519: 164 | F519: 3.717285 | G519: =VLOOKUP(A519,'[1]all FNCL'!A$2:B$993,2) -> 0.79171462 | H519: 5/30/2014 | I519: 0.44289145 | J519: =VLOOKUP(A519,'YB OAS'!B:F,5,0) -> 548.00592 | K519: =VLOOKUP(A519,'Refi Universe'!E:F,2,0) -> 0.82756768
... A676: 41557 | B676: 336 | C676: 336 | D676: 109 | E676: 66 | F676: 4.2557 | G676: =VLOOKUP(A676,'[1]all FNCL'!A$2:B$993,2) -> 0.41233772 | H676: 1/15/2015 | I676: 0.65257309 | J676: =VLOOKUP(A676,'YB OAS'!B:F,5,0) -> 164.8412 | K676: =VLOOKUP(A676,'Refi Universe'!E:F,2,0) -> 0.40641393
A677: 41558 | B677: 342 | C677: 342 | D677: 118 | E677: 69 | F677: 4.261774 | G677: =VLOOKUP(A677,'[1]all FNCL'!A$2:B$993,2) -> 0.41233772 | H677: 42020 | I677: 0.65257309 | J677: =VLOOKUP(A677,'YB OAS'!B:F,5,0) -> 169.5805 | K677: =VLOOKUP(A677,'Refi Universe'!E:F,2,0) -> 0.40564359
A678: 41562 | B678: 353 | C678: 353 | D678: 124 | E678: 76 | F678: 4.293714 | G678: =VLOOKUP(A678,'[1]all FNCL'!A$2:B$993,2) -> 0.41233772 | J678: =VLOOKUP(A678,'YB OAS'!B:F,5,0) -> 181.22479 | K678: =VLOOKUP(A678,'Refi Universe'!E:F,2,0) -> 0.39927588
A679: 41563 | B679: 358 | C679: 358 | D679: 127 | E679: 76 | F679: 4.257464 | G679: =VLOOKUP(A679,'[1]all FNCL'!A$2:B$993,2) -> 0.41233772 | J679: =VLOOKUP(A679,'YB OAS'!B:F,5,0) -> 184.85381 | K679: =VLOOKUP(A679,'Refi Universe'!E:F,2,0) -> 0.40419689
A680: 41564 | B680: 381 | C680: 381 | D680: 133 | E680: 77 | F680: 4.183002 | G680: =VLOOKUP(A680,'[1]all FNCL'!A$2:B$993,2) -> 0.40226084 | J680: =VLOOKUP(A680,'YB OAS'!B:F,5,0) -> 192.0623 | K680: =VLOOKUP(A680,'Refi Universe'!E:F,2,0) -> 0.42440229
A681: 41565 | B681: 391 | C681: 391 | D681: 115 | E681: 62 | F681: 4.183854 | G681: =VLOOKUP(A681,'[1]all FNCL'!A$2:B$993,2) -> 0.40226084 | J681: =VLOOKUP(A681,'YB OAS'!B:F,5,0) -> 203.09 | K681: =VLOOKUP(A681,'Refi Universe'!E:F,2,0) -> 0.42308899
...

Sheet Disclaimer
A1: This information has been prepared by the Corporate & Investment Banking Division of Barclays and is issued by Barclays Bank PLC and/or one or more of its affiliates (collectively and each individually, "Barclays"). All information is provided "as is" and Barclays makes no express or implied warranties, and expressly disclaims all warranties of merchantability or fitness for a particular purpose or use with respect to any data included herein. Barclays makes no representations that the information contained herein or any of the analytic tools or reports referenced herein are accurate, reliable, complete, or appropriate for use by all investors in all locations. Because of the possibility of human and mechanical errors as well as other factors, Barclays is not responsible for any errors or omissions in the information contained herein or any of the analytic tools or reports referenced herein. Barclays will not treat unauthorized recipients of this information herein as its clients.
A3: Without limiting any of the foregoing and to the extent permitted by law, in no event shall Barclays nor any of their respective officers, directors, partners, or employees have any liability for (a) any special, punitive, indirect, or consequential damages; or (b) any lost profits, lost revenue, loss of anticipated savings or loss of opportunity or other financial loss, even if notified of the possibility of such damages, arising from any use of, or reliance on, this information, analytic tools or reports referenced herein.
A5: Barclays is not utilizing this document to provide investment advice to you or any other party. The information, analytic tools or reports referenced herein and any results derived from their use provided herein are intended for informational purposes only and should not be regarded as an offer to sell or a solicitation of an offer to buy the products or securities to which it applies. No representation is made that any returns will be achieved through their use. Any data on past performance, modelling or back-testing contained herein is not necessarily indicative of future results. All levels, prices and spreads are historical and do not represent current market levels, prices or spreads, some or all of which may have changed. Any price provided herein is non-binding and is subject to change and may differ from a live bid, offer or price subsequently quoted by Barclays. The receipt by you of such price shall not constitute a binding transaction at such price. The information referenced herein or any of the results derived from any analytic tools or reports referenced herein are not intended to predict actual results and no assurances are given with respect thereto. Barclays does not guarantee the accuracy or completeness of information which is stated to have been obtained from, or is based upon, trade and statistical services or other third party sources. You should consult with your own accounting, legal or other advisors as to the adequacy of this information for your purposes.
A7: Barclays may (in various capacities) have inventory positions or deal in transactions or securities (or related derivatives) identical or similar to those described herein.
A9: Not all products or services mentioned are available in all jurisdictions. No offers, sales, resales, or delivery of any products or services described herein or any offering materials relating to any such products or services may be made in or from any jurisdiction except in circumstances which will result with compliance with any applicable laws and regulations and which will not impose any obligations on Barclays.
A11: This communication is being made available in the UK and Europe primarily to persons who are investment professionals as that term is defined in Article 19 of the Financial Services and Markets Act 2000 (Financial Promotion Order) 2005. It is directed at, and therefore should only be relied upon by, persons who have professional experience in matters relating to investments. The investments to which it relates are available only to such persons and will be entered into only with such persons. Barclays Bank PLC is authorised by the Prudential Regulation Authority and regulated by the Financial Conduct Authority and the Prudential Regulation Authority and is a member of the London Stock Exchange.
A13: Barclays Capital Inc., U.S. registered broker/dealer and member of FINRA (www.finra.org), is distributing this material in the United States and, in connection therewith accepts responsibility for its contents. Any U.S. person wishing to effect a transaction in any security discussed herein should do so only by contacting a representative of Barclays Capital Inc. in the U.S. at 745 Seventh Avenue, New York, New York 10019. Non-US persons should contact and execute transactions through a Barclays Bank PLC branch or affiliate in their home jurisdiction unless local regulations permit otherwise.
A15: IRS Circular 230 Prepared Materials Disclaimer: Barclays does not provide tax advice and nothing contained herein should be construed to be tax advice. Please be advised that any discussion of U.S. tax matters contained herein (including any attachments) (i) is not intended or written to be used, and cannot be used, by you for the purpose of avoiding U.S. tax-related penalties; and (ii) was written to support the promotion or marketing of the transactions or other matters addressed herein. Accordingly, you should seek advice based on your particular circumstances from an independent tax advisor.
A17: Barclays is not responsible for, and makes no warranties whatsoever as to, the content of any third-party web site accessed via a hyperlink contained herein and such information is not incorporated by reference.
A19: © Copyright Barclays Bank PLC (2015). All rights reserved. No part of this information may be reproduced in any manner without the prior written permission of Barclays or any of its affiliates. Barclays Bank PLC is registered in England No. 1026167. Registered office 1 Churchill Place, London, E14 5HP. Additional information will be furnished upon request.

Sheet Refi Universe
A1: 42390 | B1: 0.53686727 | E1: asof | F1: 0
A2: 42383 | B2: 0.48424776 | E2: 42445 | F2: 0.60607815
A3: 42376 | B3: 0.46862902 | E3: 42444 | F3: 0.56824863
A4: 42369 | B4: 0.44657508 | E4: 42443 | F4: 0.57831771
A5: 42362 | B5: 0.47802441 | E5: 42440 | F5: 0.57144903
A6: 42355 | B6: 0.47424192 | E6: 42439 | F6: 0.59432431
A7: 42348 | B7: 0.48108279 | E7: 42438 | F7: 0.56910388
A8: 42341 | B8: 0.48721505 | E8: 42437 | F8: 0.62096764
A9: 42333 | B9: 0.47590353 | E9: 42436 | F9: 0.58315185
A10: 42327 | B10: 0.47861527 | E10: 42433 | F10: 0.61029121
A11: 42320 | B11: 0.47253062 | E11: 42432 | F11: 0.63703244
A12: 42313 | B12: 0.5151151 | E12: 42431 | F12: 0.58954858
A13: 42306 | B13: 0.57894029 | E13: 42430 | F13: 0.60868165
... A56: 42004 | B56: 0.59452653 | E56: 42366 | F56: 0.47089364
E57: 42362 | F57: 0.45615068
E58: 42361 | F58: 0.44537185
E59: 42360 | F59: 0.45523454
E60: 42359 | F60: 0.47717956
E61: 42356 | F61: 0.47921917
E62: 42355 | F62: 0.4698406
E63: 42354 | F63: 0.44349123
E64: 42353 | F64: 0.45523454
E65: 42352 | F65: 0.47264946
E66: 42349 | F66: 0.49263546
E67: 42348 | F67: 0.47195742
E68: 42347 | F68: 0.48373664
... E1302: 40207 | F1302: 0.70311759

Sheet YB OAS
B1: Date | C1: Price | D1: oas (slow) | E1: OAS YB hist | F1: Numbers
A2: fn30.400.10(iox) | B2: 40576 | C2: =[2]!YBHIST($A$2,$B2,"Price","sec","") -> E | D2: =[2]!YBPRICE($A$2,C2&"d",$B3,"OAS","Swap",B2,"LMMSkew","","Model",100,"OAS") -> E | E2: =[2]!YBHIST($A$2,B2,"LMMOAS","sec","") -> E | F2: NA
B3: 40577 | C3: =[2]!YBHIST($A$2,$B3,"Price","sec","") -> E | D3: =[2]!YBPRICE($A$2,C3&"d",$B4,"OAS","Swap",B3,"LMMSkew","","Model",100,"OAS") -> E | E3: =[2]!YBHIST($A$2,B3,"LMMOAS","sec","") -> E | F3: NA
B4: 40578 | C4: =[2]!YBHIST($A$2,$B4,"Price","sec","") -> E | D4: =[2]!YBPRICE($A$2,C4&"d",$B5,"OAS","Swap",B4,"LMMSkew","","Model",100,"OAS") -> E | E4: =[2]!YBHIST($A$2,B4,"LMMOAS","sec","") -> E | F4: NA
B5: 40581 | C5: =[2]!YBHIST($A$2,$B5,"Price","sec","") -> E | D5: =[2]!YBPRICE($A$2,C5&"d",$B6,"OAS","Swap",B5,"LMMSkew","","Model",100,"OAS") -> E | E5: =[2]!YBHIST($A$2,B5,"LMMOAS","sec","") -> E | F5: NA
B6: 40582 | C6: =[2]!YBHIST($A$2,$B6,"Price","sec","") -> E | D6: =[2]!YBPRICE($A$2,C6&"d",$B7,"OAS","Swap",B6,"LMMSkew","","Model",100,"OAS") -> E | E6: =[2]!YBHIST($A$2,B6,"LMMOAS","sec","") -> E | F6: NA
B7: 40583 | C7: =[2]!YBHIST($A$2,$B7,"Price","sec","") -> E | D7: =[2]!YBPRICE($A$2,C7&"d",$B8,"OAS","Swap",B7,"LMMSkew","","Model",100,"OAS") -> E | E7: =[2]!YBHIST($A$2,B7,"LMMOAS","sec","") -> E | F7: NA
B8: 40584 | C8: =[2]!YBHIST($A$2,$B8,"Price","sec","") -> E | D8: =[2]!YBPRICE($A$2,C8&"d",$B9,"OAS","Swap",B8,"LMMSkew","","Model",100,"OAS") -> E | E8: =[2]!YBHIST($A$2,B8,"LMMOAS","sec","") -> E | F8: NA
B9: 40585 | C9: =[2]!YBHIST($A$2,$B9,"Price","sec","") -> E | D9: =[2]!YBPRICE($A$2,C9&"d",$B10,"OAS","Swap",B9,"LMMSkew","","Model",100,"OAS") -> E | E9: =[2]!YBHIST($A$2,B9,"LMMOAS","sec","") -> E | F9: NA
B10: 40588 | C10: =[2]!YBHIST($A$2,$B10,"Price","sec","") -> E | D10: =[2]!YBPRICE($A$2,C10&"d",$B11,"OAS","Swap",B10,"LMMSkew","","Model",100,"OAS") -> E | E10: =[2]!YBHIST($A$2,B10,"LMMOAS","sec","") -> E | F10: -46.355499
B11: 40589 | C11: =[2]!YBHIST($A$2,$B11,"Price","sec","") -> E | D11: =[2]!YBPRICE($A$2,C11&"d",$B12,"OAS","Swap",B11,"LMMSkew","","Model",100,"OAS") -> E | E11: =[2]!YBHIST($A$2,B11,"LMMOAS","sec","") -> E | F11: -59.443802
B12: 40590 | C12: =[2]!YBHIST($A$2,$B12,"Price","sec","") -> E | D12: =[2]!YBPRICE($A$2,C12&"d",$B13,"OAS","Swap",B12,"LMMSkew","","Model",100,"OAS") -> E | E12: =[2]!YBHIST($A$2,B12,"LMMOAS","sec","") -> E | F12: -65.651901
B13: 40591 | C13: =[2]!YBHIST($A$2,$B13,"Price","sec","") -> E | D13: =[2]!YBPRICE($A$2,C13&"d",$B14,"OAS","Swap",B13,"LMMSkew","","Model",100,"OAS") -> E | E13: =[2]!YBHIST($A$2,B13,"LMMOAS","sec","") -> E | F13: -47.389
B14: 40592 | C14: =[2]!YBHIST($A$2,$B14,"Price","sec","") -> E | D14: =[2]!YBPRICE($A$2,C14&"d",$B15,"OAS","Swap",B14,"LMMSkew","","Model",100,"OAS") -> E | E14: =[2]!YBHIST($A$2,B14,"LMMOAS","sec","") -> E | F14: -51.927299
B15: 40596 | C15: =[2]!YBHIST($A$2,$B15,"Price","sec","") -> E | D15: =[2]!YBPRICE($A$2,C15&"d",$B16,"OAS","Swap",B15,"LMMSkew","","Model",100,"OAS") -> E | E15: =[2]!YBHIST($A$2,B15,"LMMOAS","sec","") -> E | F15: -36.043598
B16: 40597 | C16: =[2]!YBHIST($A$2,$B16,"Price","sec","") -> E | D16: =[2]!YBPRICE($A$2,C16&"d",$B17,"OAS","Swap",B16,"LMMSkew","","Model",100,"OAS") -> E | E16: =[2]!YBHIST($A$2,B16,"LMMOAS","sec","") -> E | F16: -40.838699
B17: 40598 | C17: =[2]!YBHIST($A$2,$B17,"Price","sec","") -> E | D17: =[2]!YBPRICE($A$2,C17&"d",$B18,"OAS","Swap",B17,"LMMSkew","","Model",100,"OAS") -> E | E17: =[2]!YBHIST($A$2,B17,"LMMOAS","sec","") -> E | F17: -36.337601
B18: 40599 | C18: =[2]!YBHIST($A$2,$B18,"Price","sec","") -> E | D18: =[2]!YBPRICE($A$2,C18&"d",$B19,"OAS","Swap",B18,"LMMSkew","","Model",100,"OAS") -> E | E18: =[2]!YBHIST($A$2,B18,"LMMOAS","sec","") -> E | F18: -30.010599
B19: 40602 | C19: =[2]!YBHIST($A$2,$B19,"Price","sec","") -> E | D19: =[2]!YBPRICE($A$2,C19&"d",$B20,"OAS","Swap",B19,"LMMSkew","","Model",100,"OAS") -> E | E19: =[2]!YBHIST($A$2,B19,"LMMOAS","sec","") -> E | F19: -27.406799
B20: 40603 | C20: =[2]!YBHIST($A$2,$B20,"Price","sec","") -> E | D20: =[2]!YBPRICE($A$2,C20&"d",$B21,"OAS","Swap",B20,"LMMSkew","","Model",100,"OAS") -> E | E20: =[2]!YBHIST($A$2,B20,"LMMOAS","sec","") -> E | F20: -22.981199
B21: 40604 | C21: =[2]!YBHIST($A$2,$B21,"Price","sec","") -> E | D21: =[2]!YBPRICE($A$2,C21&"d",$B22,"OAS","Swap",B21,"LMMSkew","","Model",100,"OAS") -> E | E21: =[2]!YBHIST($A$2,B21,"LMMOAS","sec","") -> E | F21: -28.4123
... B1258: 42411 | C1258: =[2]!YBHIST($A$2,$B1258,"Price","sec","") -> E | D1258: =[2]!YBPRICE($A$2,C1258&"d",$B1259,"OAS","Swap",B1258,"LMMSkew","","Model",100,"OAS") -> E | E1258: =[2]!YBHIST($A$2,B1258,"LMMOAS","sec","") -> E | F1258: 76.545998
B1259: 42412 | C1259: =[2]!YBHIST($A$2,$B1259,"Price","sec","") -> E | D1259: =[2]!YBPRICE($A$2,C1259&"d",$A1259,"OAS","Swap",B1259,"LMMSkew","","Model",100,"OAS") -> E | E1259: =[2]!YBHIST($A$2,B1259,"LMMOAS","sec","") -> E | F1259: 85.475899
B1260: 42416 | E1260: =[2]!YBHIST($A$2,B1260,"LMMOAS","sec","") -> E | F1260: 92.657997
B1261: 42417 | E1261: =[2]!YBHIST($A$2,B1261,"LMMOAS","sec","") -> E | F1261: 105.8745
B1262: 42418 | E1262: =[2]!YBHIST($A$2,B1262,"LMMOAS","sec","") -> E | F1262: 103.4613
B1263: 42419 | E1263: =[2]!YBHIST($A$2,B1263,"LMMOAS","sec","") -> 96.458702 | F1263: 96.458702
B1264: 42422 | E1264: =[2]!YBHIST($A$2,B1264,"LMMOAS","sec","") -> 89.089897 | F1264: 89.089897
B1265: 42423 | E1265: =[2]!YBHIST($A$2,B1265,"LMMOAS","sec","") -> 79.5261 | F1265: 79.5261
B1266: 42424 | E1266: =[2]!YBHIST($A$2,B1266,"LMMOAS","sec","") -> 72.053497 | F1266: 72.053497
B1267: 42425 | E1267: =[2]!YBHIST($A$2,B1267,"LMMOAS","sec","") -> 70.974098 | F1267: 70.974098
B1268: 42426 | E1268: =[2]!YBHIST($A$2,B1268,"LMMOAS","sec","") -> 76.661301 | F1268: 76.661301
B1269: 42429 | E1269: =[2]!YBHIST($A$2,B1269,"LMMOAS","sec","") -> 70.162903 | F1269: 70.162903
B1270: 42430 | E1270: =[2]!YBHIST($A$2,B1270,"LMMOAS","sec","") -> 82.245399 | F1270: 82.245399
B1271: 42431 | E1271: =[2]!YBHIST($A$2,B1271,"LMMOAS","sec","") -> 74.9207 | F1271: 74.9207
... B1280: 42444 | E1280: =[2]!YBHIST($A$2,B1280,"LMMOAS","sec","") -> 51.940498 | F1280: 51.940498
B1281: 42445 | E1281: =[2]!YBHIST($A$2,B1281,"LMMOAS","sec","") -> Error
