Workbook

Sheet Price D Coupon
F6: IOS + TBA + Curve Monthly Return (%) | AA6: Weight
F7: Date | G7: FN30. 300. 13 | H7: FN30. 300. 12 | I7: FN30. 350. 14 | J7: FN30. 350. 13 | K7: FN30. 350. 12 | L7: FN30. 350. 10 | M7: FN30. 400. 14 | N7: FN30. 400. 13 | O7: FN30. 400. 11 | P7: FN30. 400. 10 | Q7: FN30. 400. 09 | R7: FN30. 450. 11 | S7: FN30. 450. 10 | T7: FN30. 450. 09 | U7: FN30. 500. 10 | V7: FN30. 500. 09 | W7: FN30. 550. 08 | X7: FN30. 600. 08 | Y7: FN30. 650. 67 | AA7: Date | AB7: FN30. 300. 13 | AC7: FN30. 300. 12 | AD7: FN30. 350. 14 | AE7: FN30. 350. 13 | AF7: FN30. 350. 12 | AG7: FN30. 350. 10 | AH7: FN30. 400. 14 | AI7: FN30. 400. 13 | AJ7: FN30. 400. 11 | AK7: FN30. 400. 10 | AL7: FN30. 400. 09 | AM7: FN30. 450. 11 | AN7: FN30. 450. 10 | AO7: FN30. 450. 09 | AP7: FN30. 500. 10 | AQ7: FN30. 500. 09 | AR7: FN30. 550. 08 | AS7: FN30. 600. 08 | AT7: FN30. 650. 67 | AU7: Total
F8: 42034 | G8: =Return!G8 -> -0.096840414 | H8: =Return!H8 -> -0.090093257 | I8: =Return!I8 -> 0 | J8: =Return!J8 -> -0.13830215 | K8: =Return!K8 -> -0.107463 | L8: =Return!L8 -> -0.092784203 | M8: =Return!M8 -> 0 | N8: =Return!N8 -> -0.14559069 | ... Y8: =Return!Y8 -> 0.073502496 | AA8: =F8 -> 42034 | AB8: 0.1467089 | AC8: 0.1338754 | AD8: 0 | AE8: 0.10176797 | AF8: 0.1633136 | AG8: 0.011157228 | AH8: 0 | AI8: 0.092870263 | AJ8: 0.043174954 | AK8: 0.049576038 | AL8: 0.034657797 | AM8: 0.045038886 | AN8: 0.042605814 | AO8: 0.069138471 | AP8: 0.022670742 | AQ8: 0.019042072 | AR8: 0.0097161724 | AS8: 0.0055692771 | AT8: 0.0091164247 | AU8: =SUM(AB8:AT8) -> 1 | AW8: 42004 | AX8: -0.026017102
F9: 42062 | G9: =Return!G9 -> 0.039282818 | H9: =Return!H9 -> 0.031242122 | I9: =Return!I9 -> 0 | J9: =Return!J9 -> 0.085544343 | K9: =Return!K9 -> 0.050998415 | L9: =Return!L9 -> 0.055046249 | M9: =Return!M9 -> 0 | N9: =Return!N9 -> 0.11504397 | ... Y9: =Return!Y9 -> 0.027065614 | AA9: =F9 -> 42062 | AB9: 0.147653 | AC9: 0.13465479 | AD9: 0 | AE9: 0.10210331 | AF9: 0.16389333 | AG9: 0.011178399 | AH9: 0 | AI9: 0.092170981 | AJ9: 0.043127725 | AK9: 0.049492497 | AL9: 0.034505449 | AM9: 0.044865757 | AN9: 0.042362049 | AO9: 0.068507645 | AP9: 0.022522098 | AQ9: 0.018883043 | AR9: 0.0095794762 | AS9: 0.0054880754 | AT9: 0.0090123686 | AU9: =SUM(AB9:AT9) -> 1 | AW9: 42034 | AX9: -0.18730149
F10: 42094 | G10: =Return!G10 -> 0.0059426185 | H10: =Return!H10 -> 0.0077451797 | I10: =Return!I10 -> 0 | J10: =Return!J10 -> -0.0033134844 | K10: =Return!K10 -> 0.009420289 | L10: =Return!L10 -> 0.017238691 | M10: =Return!M10 -> 0 | N10: =Return!N10 -> -0.012040329 | ... Y10: =Return!Y10 -> 0.095701018 | AA10: =F10 -> 42094 | AB10: 0.14849148 | AC10: 0.1353443 | AD10: 0 | AE10: 0.10231681 | AF10: 0.16435025 | AG10: 0.011190124 | AH10: 0 | AI10: 0.091594999 | AJ10: 0.043110237 | AK10: 0.049415117 | AL10: 0.034341268 | AM10: 0.044714081 | AN10: 0.042190048 | AO10: 0.067955841 | AP10: 0.022388694 | AQ10: 0.018764085 | AR10: 0.0094829009 | AS10: 0.0054262526 | AT10: 0.0089235168 | AU10: =SUM(AB10:AT10) -> 1 | AW10: 42062 | AX10: 0.16728926
F11: 42124 | G11: =Return!G11 -> -0.007540183 | H11: =Return!H11 -> -0.011105228 | I11: =Return!I11 -> 0.041294602 | J11: =Return!J11 -> 0.012523492 | K11: =Return!K11 -> 0.0086805399 | L11: =Return!L11 -> 0.0077663309 | M11: =Return!M11 -> 0.03192673 | N11: =Return!N11 -> 0.028181834 | ... Y11: =Return!Y11 -> 0.01491138 | AA11: =F11 -> 42124 | AB11: 0.12423967 | AC11: 0.11316002 | AD11: 0.065143517 | AE11: 0.084910023 | AF11: 0.13692327 | AG11: 0.0092723001 | AH11: 0.10517165 | AI11: 0.074925706 | AJ11: 0.035687714 | AK11: 0.040903895 | AL11: 0.028249893 | AM11: 0.037025462 | AN11: 0.034861126 | AO11: 0.055879071 | AP11: 0.018510317 | AQ11: 0.015493011 | AR11: 0.0078094838 | AS11: 0.0044720981 | AT11: 0.0073617784 | AU11: =SUM(AB11:AT11) -> 1
F12: 42153 | G12: =Return!G12 -> -0.029440725 | H12: =Return!H12 -> -0.038613282 | I12: =Return!I12 -> -0.0016235535 | J12: =Return!J12 -> -0.0084007075 | K12: =Return!K12 -> -0.026115436 | L12: =Return!L12 -> -0.029535214 | M12: =Return!M12 -> 0.018283823 | N12: =Return!N12 -> 0.0051072162 | ... Y12: =Return!Y12 -> -0.030653927 | AA12: =F12 -> 42153 | AB12: 0.12572491 | AC12: 0.11440387 | AD12: 0.064891298 | AE12: 0.085184799 | AF12: 0.13772832 | AG12: 0.0092726415 | AH12: 0.10452851 | AI12: 0.073838407 | AJ12: 0.035574654 | AK12: 0.040704536 | AL12: 0.02797973 | AM12: 0.036917105 | AN12: 0.034665704 | AO12: 0.055241854 | AP12: 0.018443405 | AQ12: 0.015403647 | AR12: 0.0077284877 | AS12: 0.0044400971 | AT12: 0.0073280297 | AU12: =SUM(AB12:AT12) -> 1
F13: 42185 | G13: =Return!G13 -> -0.032015573 | H13: =Return!H13 -> -0.035059548 | I13: =Return!I13 -> -0.01343621 | J13: =Return!J13 -> -0.001673941 | K13: =Return!K13 -> -0.0081638584 | L13: =Return!L13 -> -0.01339384 | M13: =Return!M13 -> 0.02382159 | N13: =Return!N13 -> 0.037628722 | ... Y13: =Return!Y13 -> -0.010738156 | AA13: =F13 -> 42185 | AB13: 0.12678695 | AC13: 0.11532294 | AD13: 0.064927038 | AE13: 0.085499811 | AF13: 0.13825039 | AG13: 0.0092660239 | AH13: 0.10430482 | AI13: 0.073277879 | AJ13: 0.035456813 | AK13: 0.040529201 | AL13: 0.027703885 | AM13: 0.036717726 | AN13: 0.034408628 | AO13: 0.054618212 | AP13: 0.01832071 | AQ13: 0.015284585 | AR13: 0.0076473588 | AS13: 0.0043982432 | AT13: 0.007278789 | AU13: =SUM(AB13:AT13) -> 1
F14: 42216 | G14: =Return!G14 -> 0.01495254 | H14: =Return!H14 -> 0.0099166099 | I14: =Return!I14 -> 0.01812804 | J14: =Return!J14 -> 0.012310288 | K14: =Return!K14 -> 0.0052953237 | L14: =Return!L14 -> 0.0072184912 | M14: =Return!M14 -> 0.013688786 | N14: =Return!N14 -> 0.010820286 | ... Y14: =Return!Y14 -> 0.029785562 | AA14: =F14 -> 42216 | AB14: 0.12772296 | AC14: 0.11613134 | AD14: 0.064959658 | AE14: 0.085765656 | AF14: 0.13866824 | AG14: 0.0092606069 | AH14: 0.10418188 | AI14: 0.072856605 | AJ14: 0.035344316 | AK14: 0.040369113 | AL14: 0.027459824 | AM14: 0.036558359 | AN14: 0.034177569 | AO14: 0.054036209 | AP14: 0.018193765 | AQ14: 0.015148787 | AR14: 0.0075678071 | AS14: 0.0043576778 | AT14: 0.007239622 | AU14: =SUM(AB14:AT14) -> 1
F15: 42247 | G15: =Return!G15 -> -0.010256916 | H15: =Return!H15 -> -0.012140416 | I15: =Return!I15 -> -0.012437654 | J15: =Return!J15 -> -0.020659258 | K15: =Return!K15 -> -0.018220354 | L15: =Return!L15 -> -0.023115254 | M15: =Return!M15 -> -0.012588742 | N15: =Return!N15 -> -0.023010128 | ... Y15: =Return!Y15 -> -0.0091859996 | AA15: =F15 -> 42247 | AB15: 0.12772296 | AC15: 0.11613134 | AD15: 0.064959658 | AE15: 0.085765656 | AF15: 0.13866824 | AG15: 0.0092606069 | AH15: 0.10418188 | AI15: 0.072856605 | AJ15: 0.035344316 | AK15: 0.040369113 | AL15: 0.027459824 | AM15: 0.036558359 | AN15: 0.034177569 | AO15: 0.054036209 | AP15: 0.018193765 | AQ15: 0.015148787 | AR15: 0.0075678071 | AS15: 0.0043576778 | AT15: 0.007239622 | AU15: =SUM(AB15:AT15) -> 1
F16: 42277 | G16: =Return!G16 -> -0.0060420065 | H16: =Return!H16 -> -0.0056996905 | I16: =Return!I16 -> -0.0048283168 | J16: =Return!J16 -> -0.012285527 | K16: =Return!K16 -> -0.015047358 | L16: =Return!L16 -> -0.016947909 | M16: =Return!M16 -> -0.013963202 | N16: =Return!N16 -> -0.017782366 | ... Y16: =Return!Y16 -> -0.019853723 | AA16: =F16 -> 42277 | AB16: 0.12919628 | AC16: 0.11738741 | AD16: 0.065560709 | AE16: 0.086272954 | AF16: 0.139202 | AG16: 0.009255837 | AH16: 0.10431996 | AI16: 0.072339114 | AJ16: 0.035101492 | AK16: 0.040034355 | AL16: 0.027077082 | AM16: 0.036168606 | AN16: 0.03364021 | AO16: 0.052933918 | AP16: 0.01787747 | AQ16: 0.014877037 | AR16: 0.007358487 | AS16: 0.004263108 | AT16: 0.007133965 | AU16: =SUM(AB16:AT16) -> 1
F17: 42307 | G17: =Return!G17 -> -0.00076464741 | H17: =Return!H17 -> 0.0022550209 | I17: =Return!I17 -> -0.0087207325 | J17: =Return!J17 -> -0.010009567 | K17: =Return!K17 -> -0.0039820857 | L17: =Return!L17 -> -0.0012184644 | M17: =Return!M17 -> -0.0028413888 | N17: =Return!N17 -> -0.00056588623 | ... Y17: =Return!Y17 -> 0.013228227 | AA17: =F17 -> 42307 | AB17: 0.12976281 | AC17: 0.117865 | AD17: 0.065868953 | AE17: 0.086467604 | AF17: 0.13940283 | AG17: 0.0092574447 | AH17: 0.10436448 | AI17: 0.07216283 | AJ17: 0.035025929 | AK17: 0.039928897 | AL17: 0.026964805 | AM17: 0.03600221 | AN17: 0.033433781 | AO17: 0.052489573 | AP17: 0.017738765 | AQ17: 0.014729515 | AR17: 0.007262384 | AS17: 0.0042107499 | AT17: 0.0070614359 | AU17: =SUM(AB17:AT17) -> 1
F18: 42338 | G18: =Return!G18 -> 0.0053789495 | H18: =Return!H18 -> 0.010614526 | I18: =Return!I18 -> 0.025290237 | J18: =Return!J18 -> 0.013249373 | K18: =Return!K18 -> 0.017775697 | L18: =Return!L18 -> 0.015357564 | M18: =Return!M18 -> 0.02234622 | N18: =Return!N18 -> 0.023629695 | ... Y18: =Return!Y18 -> 0.0038403766 | AA18: =F18 -> 42338 | AB18: 0.13 | AC18: 0.12 | AD18: 0.07 | AE18: 0.09 | AF18: 0.14 | AG18: 0.01 | AH18: 0.1 | AI18: 0.07 | AJ18: 0.03 | AK18: 0.04 | AL18: 0.03 | AM18: 0.04 | AN18: 0.03 | AO18: 0.05 | AP18: 0.02 | AQ18: 0.01 | AR18: 0.01 | AS18: 0 | AT18: 0.01 | AU18: =SUM(AB18:AT18) -> 1
F19: 42369 | G19: =Return!G19 -> 0.0057506797 | H19: =Return!H19 -> 0.0062944841 | I19: =Return!I19 -> 0.0152466 | J19: =Return!J19 -> 0.012637304 | K19: =Return!K19 -> 0.013582202 | L19: =Return!L19 -> 0.020454416 | M19: =Return!M19 -> 0.016882201 | N19: =Return!N19 -> 0.016800967 | ... Y19: =Return!Y19 -> 0.016692534 | AA19: =F19 -> 42369 | AB19: 0.13 | AC19: 0.12 | AD19: 0.07 | AE19: 0.09 | AF19: 0.14 | AG19: 0.01 | AH19: 0.1 | AI19: 0.07 | AJ19: 0.03 | AK19: 0.04 | AL19: 0.03 | AM19: 0.04 | AN19: 0.03 | AO19: 0.05 | AP19: 0.02 | AQ19: 0.01 | AR19: 0.01 | AS19: 0 | AT19: 0.01 | AU19: =SUM(AB19:AT19) -> 1
F20: 42370 | G20: =Return!G20 -> -0.0011946167 | H20: =Return!H20 -> -0.00085414796 | I20: =Return!I20 -> -0.0066994681 | J20: =Return!J20 -> -0.017646732 | K20: =Return!K20 -> -0.022522298 | L20: =Return!L20 -> -0.016556483 | M20: =Return!M20 -> -0.043270868 | N20: =Return!N20 -> -0.04493881 | ... Y20: =Return!Y20 -> 0.0046090348 | AA20: =F20 -> 42370 | AB20: 0.13 | AC20: 0.12 | AD20: 0.07 | AE20: 0.09 | AF20: 0.14 | AG20: 0.01 | AH20: 0.1 | AI20: 0.07 | AJ20: 0.03 | AK20: 0.04 | AL20: 0.03 | AM20: 0.04 | AN20: 0.03 | AO20: 0.05 | AP20: 0.02 | AQ20: 0.01 | AR20: 0.01 | AS20: 0 | AT20: 0.01 | AU20: =SUM(AB20:AT20) -> 1
F21: 42429 | G21: =Return!G21 -> -0.0045170555 | H21: =Return!H21 -> 0.013262517 | I21: =Return!I21 -> 0.013383293 | J21: =Return!J21 -> 0.0054511858 | K21: =Return!K21 -> 0.0019780851 | L21: =Return!L21 -> 0.012403357 | M21: =Return!M21 -> -0.001444898 | N21: =Return!N21 -> -0.0047375767 | ... Y21: =Return!Y21 -> 0.032359413 | AA21: =F21 -> 42429 | AB21: 0.13 | AC21: 0.12 | AD21: 0.07 | AE21: 0.09 | AF21: 0.14 | AG21: 0.01 | AH21: 0.1 | AI21: 0.07 | AJ21: 0.03 | AK21: 0.04 | AL21: 0.03 | AM21: 0.04 | AN21: 0.03 | AO21: 0.05 | AP21: 0.02 | AQ21: 0.01 | AR21: 0.01 | AS21: 0 | AT21: 0.01 | AU21: =SUM(AB21:AT21) -> 1
F22: =Return!F22 -> 42460 | G22: =Return!G22 -> 0.0095596882 | H22: =Return!H22 -> 0.0066155518 | I22: =Return!I22 -> 0.010498592 | J22: =Return!J22 -> 0.012796543 | K22: =Return!K22 -> 0.0096846254 | L22: =Return!L22 -> 0.0141548 | M22: =Return!M22 -> 0.018324595 | ... Y22: =Return!Y22 -> 0.019157687 | AA22: =F22 -> 42460 | AB22: 0.13 | AC22: 0.12 | AD22: 0.07 | AE22: 0.09 | AF22: 0.14 | AG22: 0.01 | AH22: 0.1 | AI22: 0.07 | AJ22: 0.03 | AK22: 0.04 | AL22: 0.03 | AM22: 0.04 | AN22: 0.03 | AO22: 0.05 | AP22: 0.02 | AQ22: 0.01 | AR22: 0.01 | AS22: 0 | AT22: 0.01 | AU22: =SUM(AB22:AT22) -> 1
F23: =Return!F23 -> 42489 | G23: =Return!G23 -> 0.012924263 | H23: =Return!H23 -> 0.010213686 | I23: =Return!I23 -> 0.0051691191 | J23: =Return!J23 -> 0.012471291 | K23: =Return!K23 -> 0.0094981501 | L23: =Return!L23 -> 0.0081365643 | M23: =Return!M23 -> 0.012874107 | ... Y23: =Return!Y23 -> 0.018659863 | AA23: =F23 -> 42489 | AB23: 0.13 | AC23: 0.12 | AD23: 0.07 | AE23: 0.09 | AF23: 0.14 | AG23: 0.01 | AH23: 0.1 | AI23: 0.07 | AJ23: 0.03 | AK23: 0.04 | AL23: 0.03 | AM23: 0.04 | AN23: 0.03 | AO23: 0.05 | AP23: 0.02 | AQ23: 0.01 | AR23: 0.01 | AS23: 0 | AT23: 0.01 | AU23: =SUM(AB23:AT23) -> 1
F24: =Return!F24 -> 42521 | G24: =Return!G24 -> 0.037738095 | H24: =Return!H24 -> 0.038464176 | I24: =Return!I24 -> 0.04558378 | J24: =Return!J24 -> 0.03534232 | K24: =Return!K24 -> 0.030728284 | L24: =Return!L24 -> 0.034270764 | M24: =Return!M24 -> 0.037572338 | ... Y24: =Return!Y24 -> 0.028964066 | AA24: =F24 -> 42521 | AB24: 0.13 | AC24: 0.12 | AD24: 0.07 | AE24: 0.09 | AF24: 0.14 | AG24: 0.01 | AH24: 0.1 | AI24: 0.07 | AJ24: 0.03 | AK24: 0.04 | AL24: 0.03 | AM24: 0.04 | AN24: 0.03 | AO24: 0.05 | AP24: 0.02 | AQ24: 0.01 | AR24: 0.01 | AS24: 0 | AT24: 0.01 | AU24: =SUM(AB24:AT24) -> 1
F25: =Return!F25 -> 42551 | G25: =Return!G25 -> 0.034365654 | H25: =Return!H25 -> 0.037535544 | I25: =Return!I25 -> 0.039350154 | J25: =Return!J25 -> 0.019004338 | K25: =Return!K25 -> 0.011849015 | L25: =Return!L25 -> 0.030868702 | M25: =Return!M25 -> -0.0032835625 | ... Y25: =Return!Y25 -> 0.026140036 | AA25: =F25 -> 42551 | AB25: 0.13 | AC25: 0.12 | AD25: 0.07 | AE25: 0.09 | AF25: 0.14 | AG25: 0.01 | AH25: 0.1 | AI25: 0.07 | AJ25: 0.03 | AK25: 0.04 | AL25: 0.03 | AM25: 0.04 | AN25: 0.03 | AO25: 0.05 | AP25: 0.02 | AQ25: 0.01 | AR25: 0.01 | AS25: 0 | AT25: 0.01 | AU25: =SUM(AB25:AT25) -> 1
F26: =Return!F26 -> 42580 | G26: =Return!G26 -> 0.044669921 | H26: =Return!H26 -> 0.037337236 | I26: =Return!I26 -> 0.058379191 | J26: =Return!J26 -> 0.03942891 | K26: =Return!K26 -> 0.0375271 | L26: =Return!L26 -> 0.049246496 | M26: =Return!M26 -> 0.034961887 | ... Y26: =Return!Y26 -> 0.023975781 | AA26: =F26 -> 42580 | AB26: 0.13 | AC26: 0.12 | AD26: 0.07 | AE26: 0.09 | AF26: 0.14 | AG26: 0.01 | AH26: 0.1 | AI26: 0.07 | AJ26: 0.03 | AK26: 0.04 | AL26: 0.03 | AM26: 0.04 | AN26: 0.03 | AO26: 0.05 | AP26: 0.02 | AQ26: 0.01 | AR26: 0.01 | AS26: 0 | AT26: 0.01 | AU26: =SUM(AB26:AT26) -> 1
F27: =Return!F27 -> 42613 | G27: =Return!G27 -> 0.0086811732 | H27: =Return!H27 -> 0.0067193883 | I27: =Return!I27 -> 0.016216027 | J27: =Return!J27 -> 0.018001132 | K27: =Return!K27 -> 0.018195151 | L27: =Return!L27 -> 0.0096595651 | M27: =Return!M27 -> 0.027795084 | ... Y27: =Return!Y27 -> 0.022974496 | AA27: =F27 -> 42613 | AB27: 0.13 | AC27: 0.12 | AD27: 0.07 | AE27: 0.09 | AF27: 0.14 | AG27: 0.01 | AH27: 0.1 | AI27: 0.07 | AJ27: 0.03 | AK27: 0.04 | AL27: 0.03 | AM27: 0.04 | AN27: 0.03 | AO27: 0.05 | AP27: 0.02 | AQ27: 0.01 | AR27: 0.01 | AS27: 0 | AT27: 0.01 | AU27: =SUM(AB27:AT27) -> 1
F28: =Return!F28 -> 42643 | G28: =Return!G28 -> 0.010648351 | H28: =Return!H28 -> 0.010233387 | I28: =Return!I28 -> 0.011416132 | J28: =Return!J28 -> 0.002438662 | K28: =Return!K28 -> 0.005672116 | L28: =Return!L28 -> 0.010253358 | M28: =Return!M28 -> 0.0086619187 | ... Y28: =Return!Y28 -> 0.0077493236 | AA28: =F28 -> 42643 | AB28: 0.13 | AC28: 0.12 | AD28: 0.07 | AE28: 0.09 | AF28: 0.14 | AG28: 0.01 | AH28: 0.1 | AI28: 0.07 | AJ28: 0.03 | AK28: 0.04 | AL28: 0.03 | AM28: 0.04 | AN28: 0.03 | AO28: 0.05 | AP28: 0.02 | AQ28: 0.01 | AR28: 0.01 | AS28: 0 | AT28: 0.01 | AU28: =SUM(AB28:AT28) -> 1
F29: =Return!F29 -> 42674 | G29: =Return!G29 -> -0.0085206244 | H29: =Return!H29 -> -0.010130904 | I29: =Return!I29 -> 0.0093609261 | J29: =Return!J29 -> 0.0038605938 | K29: =Return!K29 -> 0.0068003446 | L29: =Return!L29 -> 0.0030933635 | M29: =Return!M29 -> 0.016515952 | ... Y29: =Return!Y29 -> -0.064025785 | AA29: =F29 -> 42674 | AB29: 0.13 | AC29: 0.12 | AD29: 0.07 | AE29: 0.09 | AF29: 0.14 | AG29: 0.01 | AH29: 0.1 | AI29: 0.07 | AJ29: 0.03 | AK29: 0.04 | AL29: 0.03 | AM29: 0.04 | AN29: 0.03 | AO29: 0.05 | AP29: 0.02 | AQ29: 0.01 | AR29: 0.01 | AS29: 0 | AT29: 0.01 | AU29: =SUM(AB29:AT29) -> 1
F30: =Return!F30 -> 42704 | G30: =Return!G30 -> -0.025132447 | H30: =Return!H30 -> -0.027904402 | I30: =Return!I30 -> 0.043038023 | J30: =Return!J30 -> 0.015726023 | K30: =Return!K30 -> 0.021912078 | L30: =Return!L30 -> 0.025500078 | M30: =Return!M30 -> 0.052475289 | ... Y30: =Return!Y30 -> -0.036909349 | AA30: =F30 -> 42704 | AB30: 0.13 | AC30: 0.12 | AD30: 0.07 | AE30: 0.09 | AF30: 0.14 | AG30: 0.01 | AH30: 0.1 | AI30: 0.07 | AJ30: 0.03 | AK30: 0.04 | AL30: 0.03 | AM30: 0.04 | AN30: 0.03 | AO30: 0.05 | AP30: 0.02 | AQ30: 0.01 | AR30: 0.01 | AS30: 0 | AT30: 0.01 | AU30: =SUM(AB30:AT30) -> 1
F31: =Return!F31 -> 42734 | G31: =Return!G31 -> 0.0062287484 | H31: =Return!H31 -> 0.0029586435 | I31: =Return!I31 -> 0.023131986 | J31: =Return!J31 -> 0.020663068 | K31: =Return!K31 -> 0.020687169 | L31: =Return!L31 -> -0.014367983 | M31: =Return!M31 -> 0.021182097 | ... Y31: =Return!Y31 -> -0.011454137 | AA31: 42734 | AB31: 0.14120858 | AC31: 0.1274691 | AD31: 0.06339404 | AE31: 0.089178699 | AF31: 0.14391704 | AG31: 0.0092403116 | AH31: 0.097811526 | AI31: 0.067805805 | AJ31: 0.034166999 | AK31: 0.038732876 | AL31: 0.025262992 | AM31: 0.034826419 | AN31: 0.031589233 | AO31: 0.048143137 | AP31: 0.016579316 | AQ31: 0.013711856 | AR31: 0.0065545179 | AS31: 0.0038291248 | AT31: 0.0065784239 | AU31: =SUM(AB31:AT31) -> 1
AA33: Weighted Average
AA34: Date | AB34: FN30. 300. 13 | AC34: FN30. 300. 12 | AD34: FN30. 350. 14 | AE34: FN30. 350. 13 | AF34: FN30. 350. 12 | AG34: FN30. 350. 10 | AH34: FN30. 400. 14 | AI34: FN30. 400. 13 | AJ34: FN30. 400. 11 | AK34: FN30. 400. 10 | AL34: FN30. 400. 09 | AM34: FN30. 450. 11 | AN34: FN30. 450. 10 | AO34: FN30. 450. 09 | AP34: FN30. 500. 10 | AQ34: FN30. 500. 09 | AR34: FN30. 550. 08 | AS34: FN30. 600. 08 | AT34: FN30. 650. 67 | AU34: Total
AA35: =F8 -> 42034 | AB35: =G8*AB8 -> -0.014207351 | AC35: =H8*AC8 -> -0.012061271 | AD35: =I8*AD8 -> 0 | AE35: =J8*AE8 -> -0.014074729 | AF35: =K8*AF8 -> -0.017550169 | AG35: =L8*AG8 -> -0.0010352145 | AH35: =M8*AH8 -> 0 | AI35: =N8*AI8 -> -0.013521046 | ... AT35: =Y8*AT8 -> 0.00067007997 | AU35: =SUM(AB35:AT35) -> -0.089367824
AA36: =F9 -> 42062 | AB36: =G9*AB9 -> 0.005800226 | AC36: =H9*AC9 -> 0.0042069015 | AD36: =I9*AD9 -> 0 | AE36: =J9*AE9 -> 0.0087343608 | AF36: =K9*AF9 -> 0.0083583002 | AG36: =L9*AG9 -> 0.00061532892 | AH36: =M9*AH9 -> 0 | AI36: =N9*AI9 -> 0.010603715 | ... AT36: =Y9*AT9 -> 0.00024392529 | AU36: =SUM(AB36:AT36) -> 0.055289116
AA37: =F10 -> 42094 | AB37: =G10*AB10 -> 0.0008824282 | AC37: =H10*AC10 -> 0.0010482659 | AD37: =I10*AD10 -> 0 | AE37: =J10*AE10 -> -0.00033902515 | AF37: =K10*AF10 -> 0.0015482269 | AG37: =L10*AG10 -> 0.00019290309 | AH37: =M10*AH10 -> 0 | AI37: =N10*AI10 -> -0.0011028339 | ... AT37: =Y10*AT10 -> 0.00085398964 | AU37: =SUM(AB37:AT37) -> 0.011795069
AA38: =F11 -> 42124 | AB38: =G11*AB11 -> -0.00093678985 | AC38: =H11*AC11 -> -0.0012566678 | AD38: =I11*AD11 -> 0.0026900756 | AE38: =J11*AE11 -> 0.00106337 | AF38: =K11*AF11 -> 0.0011885679 | AG38: =L11*AG11 -> 7.2011751e-05 | AH38: =M11*AH11 -> 0.0033577868 | AI38: =N11*AI11 -> 0.0021115438 | ... AT38: =Y11*AT11 -> 0.00010977428 | AU38: =SUM(AB38:AT38) -> 0.011911914
AA39: =F12 -> 42153 | AB39: =G12*AB12 -> -0.0037014325 | AC39: =H12*AC12 -> -0.0044175088 | AD39: =I12*AD12 -> -0.0001053545 | AE39: =J12*AE12 -> -0.00071561258 | AF39: =K12*AF12 -> -0.0035968351 | AG39: =L12*AG12 -> -0.00027386945 | AH39: =M12*AH12 -> 0.0019111808 | AI39: =N12*AI12 -> 0.00037710871 | ... AT39: =Y12*AT12 -> -0.00022463289 | AU39: =SUM(AB39:AT39) -> -0.016640711
AA40: =F13 -> 42185 | AB40: =G13*AB13 -> -0.0040591568 | AC40: =H13*AC13 -> -0.0040431701 | AD40: =I13*AD13 -> -0.0008723733 | AE40: =J13*AE13 -> -0.00014312164 | AF40: =K13*AF13 -> -0.0011286566 | AG40: =L13*AG13 -> -0.00012410764 | AH40: =M13*AH13 -> 0.0024847067 | AI40: =N13*AI13 -> 0.0027573529 | ... AT40: =Y13*AT13 -> -7.8160772e-05 | AU40: =SUM(AB40:AT40) -> -0.0065968608
AA41: =F14 -> 42216 | AB41: =G14*AB14 -> 0.0019097827 | AC41: =H14*AC14 -> 0.0011516292 | AD41: =I14*AD14 -> 0.0011775913 | AE41: =J14*AE14 -> 0.0010558 | AF41: =K14*AF14 -> 0.00073429325 | AG41: =L14*AG14 -> 6.684761e-05 | AH41: =M14*AH14 -> 0.0014261234 | AI41: =N14*AI14 -> 0.00078832927 | ... AT41: =Y14*AT14 -> 0.00021563621 | AU41: =SUM(AB41:AT41) -> 0.011808852
AA42: =F15 -> 42247 | AB42: =G15*AB15 -> -0.0013100437 | AC42: =H15*AC15 -> -0.0014098828 | AD42: =I15*AD15 -> -0.00080794573 | AE42: =J15*AE15 -> -0.0017718548 | AF42: =K15*AF15 -> -0.0025265845 | AG42: =L15*AG15 -> -0.00021406128 | AH42: =M15*AH15 -> -0.0013115188 | AI42: =N15*AI15 -> -0.0016764398 | ... AT42: =Y15*AT15 -> -6.6503165e-05 | AU42: =SUM(AB42:AT42) -> -0.015282507
AA43: =F16 -> 42277 | AB43: =G16*AB16 -> -0.00078060478 | AC43: =H16*AC16 -> -0.00066907193 | AD43: =I16*AD16 -> -0.00031654788 | AE43: =J16*AE16 -> -0.0010599087 | AF43: =K16*AF16 -> -0.0020946223 | AG43: =L16*AG16 -> -0.00015686709 | AH43: =M16*AH16 -> -0.0014566407 | AI43: =N16*AI16 -> -0.0012863606 | ... AT43: =Y16*AT16 -> -0.00014163577 | AU43: =SUM(AB43:AT43) -> -0.015878158
AA44: =F17 -> 42307 | AB44: =G17*AB17 -> -9.9222793e-05 | AC44: =H17*AC17 -> 0.00026578804 | AD44: =I17*AD17 -> -0.00057442553 | AE44: =J17*AE17 -> -0.00086550327 | AF44: =K17*AF17 -> -0.00055511404 | AG44: =L17*AG17 -> -1.1279867e-05 | AH44: =M17*AH17 -> -0.00029654006 | AI44: =N17*AI17 -> -4.0835952e-05 | ... AT44: =Y17*AT17 -> 9.3410278e-05 | AU44: =SUM(AB44:AT44) -> -0.0013092872
AA45: =F18 -> 42338 | AB45: =G18*AB18 -> 0.00069926344 | AC45: =H18*AC18 -> 0.0012737432 | AD45: =I18*AD18 -> 0.0017703166 | AE45: =J18*AE18 -> 0.0011924435 | AF45: =K18*AF18 -> 0.0024885976 | AG45: =L18*AG18 -> 0.00015357564 | AH45: =M18*AH18 -> 0.002234622 | AI45: =N18*AI18 -> 0.0016540786 | ... AT45: =Y18*AT18 -> 3.8403766e-05 | AU45: =SUM(AB45:AT45) -> 0.017776153
AA46: =F19 -> 42369 | AB46: =G19*AB19 -> 0.00074758835 | AC46: =H19*AC19 -> 0.0007553381 | AD46: =I19*AD19 -> 0.001067262 | AE46: =J19*AE19 -> 0.0011373574 | AF46: =K19*AF19 -> 0.0019015082 | AG46: =L19*AG19 -> 0.00020454416 | AH46: =M19*AH19 -> 0.0016882201 | AI46: =N19*AI19 -> 0.0011760677 | ... AT46: =Y19*AT19 -> 0.00016692534 | AU46: =SUM(AB46:AT46) -> 0.013600137
...

Sheet Return
F6: IOS Price (%)
F7: Date | G7: FN30. 300. 13 | H7: FN30. 300. 12 | I7: FN30. 350. 14 | J7: FN30. 350. 13 | K7: FN30. 350. 12 | L7: FN30. 350. 10 | M7: FN30. 400. 14 | N7: FN30. 400. 13 | O7: FN30. 400. 11 | P7: FN30. 400. 10 | Q7: FN30. 400. 09 | R7: FN30. 450. 11 | S7: FN30. 450. 10 | T7: FN30. 450. 09 | U7: FN30. 500. 10 | V7: FN30. 500. 09 | W7: FN30. 550. 08 | X7: FN30. 600. 08 | Y7: FN30. 650. 67 | Z7: GII30. 400. 10 | AA7: GII30. 450. 10 | AB7: GII30. 500. 10
F8: 42034 | G8: -0.096840414 | H8: -0.090093257 | J8: -0.13830215 | K8: -0.107463 | L8: -0.092784203 | N8: -0.14559069 | O8: -0.090559159 | P8: -0.078866816 | Q8: -0.060057989 | R8: -0.060349139 | S8: -0.061990926 | T8: -0.032292506 | U8: -0.050390065 | V8: -0.035474138 | W8: 0.12225784 | X8: 0.096068946 | Y8: 0.073502496 | Z8: -0.19618113 | AA8: -0.20865457 | AB8: -0.18610276
F9: 42062 | G9: 0.039282818 | H9: 0.031242122 | J9: 0.085544343 | K9: 0.050998415 | L9: 0.055046249 | N9: 0.11504397 | O9: 0.065138078 | P9: 0.054289247 | Q9: 0.058145201 | R9: 0.043256608 | S9: 0.054231315 | T9: 0.039976273 | U9: 0.052415127 | V9: 0.053363488 | W9: -0.0036105647 | X9: 0.017040138 | Y9: 0.027065614 | Z9: 0.12353284 | AA9: 0.12218105 | AB9: 0.1092174
F10: 42094 | G10: 0.0059426185 | H10: 0.0077451797 | J10: -0.0033134844 | K10: 0.009420289 | L10: 0.017238691 | N10: -0.012040329 | O10: 0.012096852 | P10: 0.013941854 | Q10: 0.016145595 | R10: 0.02830709 | S10: 0.020898957 | T10: 0.027526683 | U10: 0.025796198 | V10: 0.033411903 | W10: 0.11230271 | X10: 0.12139542 | Y10: 0.095701018 | Z10: -0.025536453 | AA10: -0.020860813 | AB10: 0.014848578
F11: 42124 | G11: -0.007540183 | H11: -0.011105228 | I11: 0.041294602 | J11: 0.012523492 | K11: 0.0086805399 | L11: 0.0077663309 | M11: 0.03192673 | N11: 0.028181834 | O11: 0.017261255 | P11: 0.012170888 | Q11: 0.012327425 | R11: 0.011220103 | S11: 0.010255826 | T11: 0.010101986 | U11: 0.016297583 | V11: 0.015490903 | W11: 0.013747274 | X11: 0.014234764 | Y11: 0.01491138 | Z11: 0.047398731 | AA11: 0.050260551 | AB11: 0.049688152
F12: 42153 | G12: -0.029440725 | H12: -0.038613282 | I12: -0.0016235535 | J12: -0.0084007075 | K12: -0.026115436 | L12: -0.029535214 | M12: 0.018283823 | N12: 0.0051072162 | O12: -0.0087522121 | P12: -0.013149058 | Q12: -0.01887545 | R12: -0.020973955 | S12: -0.025298899 | T12: -0.02869572 | U12: -0.014154089 | V12: -0.016937137 | W12: -0.070632449 | X12: -0.048356946 | Y12: -0.030653927 | Z12: 0.0093949435 | AA12: -0.00036562658 | AB12: 0.015940141
F13: 42185 | G13: -0.032015573 | H13: -0.035059548 | I13: -0.01343621 | J13: -0.001673941 | K13: -0.0081638584 | L13: -0.01339384 | M13: 0.02382159 | N13: 0.037628722 | O13: 0.007154936 | P13: -0.0024404508 | Q13: -0.0092152822 | R13: 0.0015525963 | S13: -0.0020594563 | T13: -0.012569122 | U13: -0.0033993866 | V13: -0.0077263548 | W13: -0.038639459 | X13: -0.025790919 | Y13: -0.010738156 | Z13: 0.093911761 | AA13: 0.085991928 | AB13: 0.076286059
F14: 42216 | G14: 0.01495254 | H14: 0.0099166099 | I14: 0.01812804 | J14: 0.012310288 | K14: 0.0052953237 | L14: 0.0072184912 | M14: 0.013688786 | N14: 0.010820286 | O14: 0.00098767849 | P14: 0.0080059531 | Q14: 0.013525007 | R14: 0.011102179 | S14: 0.013118825 | T14: 0.016284034 | U14: 0.013538548 | V14: 0.01637852 | W14: 0.021331063 | X14: 0.037471143 | Y14: 0.029785562 | Z14: -0.03133709 | AA14: -0.031283357 | AB14: -0.029292941
F15: 42247 | G15: -0.010256916 | H15: -0.012140416 | I15: -0.012437654 | J15: -0.020659258 | K15: -0.018220354 | L15: -0.023115254 | M15: -0.012588742 | N15: -0.023010128 | O15: -0.018062248 | P15: -0.018275592 | Q15: -0.01912293 | R15: -0.011065574 | S15: -0.010371734 | T15: -0.015609681 | U15: -0.010279806 | V15: -0.008855062 | W15: -0.027510534 | X15: -0.035459049 | Y15: -0.0091859996 | Z15: -0.015699467 | AA15: -0.020573699 | AB15: -0.006866385
F16: 42277 | G16: -0.0060420065 | H16: -0.0056996905 | I16: -0.0048283168 | J16: -0.012285527 | K16: -0.015047358 | L16: -0.016947909 | M16: -0.013963202 | N16: -0.017782366 | O16: -0.02269881 | P16: -0.021623673 | Q16: -0.023565554 | R16: -0.031546882 | S16: -0.033688149 | T16: -0.034196956 | U16: -0.039706862 | V16: -0.041666015 | W16: -0.0049474001 | X16: -0.038649649 | Y16: -0.019853723 | Z16: -0.042152036 | AA16: -0.047330199 | AB16: -0.043474669
F17: 42307 | G17: -0.00076464741 | H17: 0.0022550209 | I17: -0.0087207325 | J17: -0.010009567 | K17: -0.0039820857 | L17: -0.0012184644 | M17: -0.0028413888 | N17: -0.00056588623 | O17: 0.0014980854 | P17: 0.0021584683 | Q17: 0.0041463372 | R17: -0.0001480036 | S17: 0.0024206916 | T17: 0.0040523221 | U17: 0.00066577433 | V17: 0.00019362961 | W17: 0.022042626 | X17: 0.014467861 | Y17: 0.013228227 | Z17: 0.0077588206 | AA17: 0.0085450486 | AB17: 0.010151867
F18: 42338 | G18: 0.0053789495 | H18: 0.010614526 | I18: 0.025290237 | J18: 0.013249373 | K18: 0.017775697 | L18: 0.015357564 | M18: 0.02234622 | N18: 0.023629695 | O18: 0.020188402 | P18: 0.019774756 | Q18: 0.045771764 | R18: 0.018593115 | S18: 0.017943739 | T18: 0.031008313 | U18: 0.018385126 | V18: 0.017723391 | W18: 0.012392457 | X18: -0.0050151529 | Y18: 0.0038403766 | Z18: 0.037925195 | AA18: 0.033434043 | AB18: 0.032161978
F19: 42369 | G19: 0.0057506797 | H19: 0.0062944841 | I19: 0.0152466 | J19: 0.012637304 | K19: 0.013582202 | L19: 0.020454416 | M19: 0.016882201 | N19: 0.016800967 | O19: 0.011831685 | P19: 0.012443024 | Q19: 0.022389573 | R19: 0.015649684 | S19: 0.01601723 | T19: 0.025127181 | U19: 0.020254649 | V19: 0.023102236 | W19: 0.023198839 | X19: 0.013034082 | Y19: 0.016692534 | Z19: 0.012310276 | AA19: 0.025511528 | AB19: 0.018765553
F20: 42398 | G20: -0.0011946167 | H20: -0.00085414796 | I20: -0.0066994681 | J20: -0.017646732 | K20: -0.022522298 | L20: -0.016556483 | M20: -0.043270868 | N20: -0.04493881 | O20: -0.041565632 | P20: -0.032314865 | Q20: -0.023985347 | R20: -0.035758059 | S20: -0.030587827 | T20: -0.024843338 | U20: -0.028133851 | V20: -0.0235766 | W20: 0.015452482 | X20: 0.0056826979 | Y20: 0.0046090348 | Z20: -0.10749776 | AA20: -0.091054788 | AB20: -0.090510363
F21: 42429 | G21: -0.0045170555 | H21: 0.013262517 | I21: 0.013383293 | J21: 0.0054511858 | K21: 0.0019780851 | L21: 0.012403357 | M21: -0.001444898 | N21: -0.0047375767 | O21: -0.0027841267 | P21: 0.0045129684 | Q21: 0.012382789 | R21: 0.0068223203 | S21: 0.0078271603 | T21: 0.014900981 | U21: 0.013888565 | V21: 0.01121063 | W21: 0.036565246 | X21: 0.037922263 | Y21: 0.032359413 | Z21: -0.046397999 | AA21: -0.04311388 | AB21: -0.032969521
F22: 42460 | G22: 0.0095596882 | H22: 0.0066155518 | I22: 0.010498592 | J22: 0.012796543 | K22: 0.0096846254 | L22: 0.0141548 | M22: 0.018324595 | N22: 0.023444907 | O22: 0.025849646 | P22: 0.025888002 | Q22: 0.020624321 | R22: 0.013199056 | S22: 0.013153251 | T22: 0.013180275 | U22: 0.001804553 | V22: 0.0026630722 | W22: 0.017485969 | X22: 0.019579624 | Y22: 0.019157687 | Z22: 0.0093331157 | AA22: 0.010114274 | AB22: 0.0060930175
... F30: 42704 | G30: -0.025132447 | H30: -0.027904402 | I30: 0.043038023 | J30: 0.015726023 | K30: 0.021912078 | L30: 0.025500078 | M30: 0.052475289 | N30: 0.042372353 | O30: 0.032112763 | P30: 0.023170747 | Q30: 0.039031883 | R30: 0.011293277 | S30: 0.0064931459 | T30: 0.020715922 | U30: 0.0070988187 | V30: 0.020310748 | W30: -0.027529839 | X30: -0.015691571 | Y30: -0.036909349 | Z30: 0.14864993 | AA30: 0.12938759 | AB30: 0.11294798
F31: 42734 | G31: 0.0062287484 | H31: 0.0029586435 | I31: 0.023131986 | J31: 0.020663068 | K31: 0.020687169 | L31: -0.014367983 | M31: 0.021182097 | N31: 0.019448783 | O31: 0.022751933 | P31: 0.021239197 | Q31: -0.01365434 | R31: 0.018284544 | S31: 0.019445037 | T31: 0.020867687 | U31: 0.013884648 | V31: 0.015016773 | W31: -0.028362344 | X31: -0.028869332 | Y31: -0.011454137 | Z31: 0.016929013 | AA31: 0.017712492 | AB31: 0.01675483 | AC31: 0.0092499887
