Workbook
Name temp: 'ppm risk premium'!$C$3:$D$259

Sheet Data Set
B3: IOS Index
B4: Date | C4: Monthly Hedge Return (%) | D4: OAS | E4: IOS + TBA Carry (%) | F4: Realized Vol | G4: Yield Curve 10-2 | H4: Prepayment Risk Premium | I4: Px/Coupon
B5: 40633 | C5: 0.032147753 | D5: 12.454245 | E5: 0.010991114 | F5: =VLOOKUP(B5,'Realized Vol'!$A$2:$D$1466,4,0) -> 0.0496 | G5: =VLOOKUP(B5,'Yield Curve'!B5:G52,5,0) -> 4.507 | H5: =VLOOKUP(B5,'ppm risk premium'!$O$3:$R$51,4,0)*100 -> 76.888122 | I5: 5.4040031
B6: 40662 | C6: 0.039945301 | D6: -13.523942 | E6: 0.010984369 | F6: =VLOOKUP(B6,'Realized Vol'!$A$2:$D$1466,4,0) -> 0.0401 | G6: =VLOOKUP(B6,'Yield Curve'!B6:G53,5,0) -> 4.404 | H6: =VLOOKUP(B6,'ppm risk premium'!$O$3:$R$51,4,0)*100 -> 76.964596 | I6: 5.4712823
B7: 40694 | C7: 0.036836949 | D7: -39.195911 | E7: 0.012359979 | F7: =VLOOKUP(B7,'Realized Vol'!$A$2:$D$1466,4,0) -> 0.0325 | G7: =VLOOKUP(B7,'Yield Curve'!B7:G54,5,0) -> 4.215 | H7: =VLOOKUP(B7,'ppm risk premium'!$O$3:$R$51,4,0)*100 -> 96.692871 | I7: 5.4954374
B8: 40724 | C8: -0.0089725231 | D8: -71.812763 | E8: 0.011611305 | F8: =VLOOKUP(B8,'Realized Vol'!$A$2:$D$1466,4,0) -> 0.0344 | G8: =VLOOKUP(B8,'Yield Curve'!B8:G55,5,0) -> 4.382 | H8: =VLOOKUP(B8,'ppm risk premium'!$O$3:$R$51,4,0)*100 -> 106.0241 | I8: 6.7509728
B9: 40753 | C9: -0.0070542452 | D9: 14.555567 | E9: 0.0094859999 | F9: =VLOOKUP(B9,'Realized Vol'!$A$2:$D$1466,4,0) -> 0.04 | G9: =VLOOKUP(B9,'Yield Curve'!B9:G56,5,0) -> 4.133 | H9: =VLOOKUP(B9,'ppm risk premium'!$O$3:$R$51,4,0)*100 -> 102.75983 | I9: 6.371475
B10: 40786 | C10: -0.12940149 | D10: 413.13076 | E10: 0.0098897456 | F10: =VLOOKUP(B10,'Realized Vol'!$A$2:$D$1466,4,0) -> 0.0661 | G10: =VLOOKUP(B10,'Yield Curve'!B10:G57,5,0) -> 3.595 | H10: =VLOOKUP(B10,'ppm risk premium'!$O$3:$R$51,4,0)*100 -> 129.36128 | I10: 5.1216829
B11: 40816 | C11: -0.10646399 | D11: 707.36595 | E11: 0.014023414 | F11: =VLOOKUP(B11,'Realized Vol'!$A$2:$D$1466,4,0) -> 0.0808 | G11: =VLOOKUP(B11,'Yield Curve'!B11:G58,5,0) -> 2.92 | H11: =VLOOKUP(B11,'ppm risk premium'!$O$3:$R$51,4,0)*100 -> 146.66635 | I11: 4.1836002
B12: 40847 | C12: 0.023593585 | D12: 688.11427 | E12: 0.012905992 | F12: =VLOOKUP(B12,'Realized Vol'!$A$2:$D$1466,4,0) -> 0.0843 | G12: =VLOOKUP(B12,'Yield Curve'!B12:G59,5,0) -> 3.199 | H12: =VLOOKUP(B12,'ppm risk premium'!$O$3:$R$51,4,0)*100 -> 142.27169 | I12: 4.3757311
B13: 40877 | C13: 0.014407939 | D13: 623.10169 | E13: 0.0070135917 | F13: =VLOOKUP(B13,'Realized Vol'!$A$2:$D$1466,4,0) -> 0.0719 | G13: =VLOOKUP(B13,'Yield Curve'!B13:G60,5,0) -> 3.061 | H13: =VLOOKUP(B13,'ppm risk premium'!$O$3:$R$51,4,0)*100 -> 148.95811 | I13: 4.3526923
B14: 40907 | C14: 0.005832688 | D14: 610.59818 | E14: 0.0039545841 | F14: =VLOOKUP(B14,'Realized Vol'!$A$2:$D$1466,4,0) -> 0.0561 | G14: =VLOOKUP(B14,'Yield Curve'!B14:G61,5,0) -> 2.89 | H14: =VLOOKUP(B14,'ppm risk premium'!$O$3:$R$51,4,0)*100 -> 150.69836 | I14: 4.2681974
B15: 40939 | C15: -0.030247515 | D15: 465.33199 | E15: 0.0093155585 | F15: =VLOOKUP(B15,'Realized Vol'!$A$2:$D$1466,4,0) -> 0.0448 | G15: =VLOOKUP(B15,'Yield Curve'!B15:G62,5,0) -> 2.934 | H15: =VLOOKUP(B15,'ppm risk premium'!$O$3:$R$51,4,0)*100 -> 151.34349 | I15: 3.9101659
B16: 40968 | C16: 0.11557044 | D16: 220.00245 | E16: 0.017106233 | F16: =VLOOKUP(B16,'Realized Vol'!$A$2:$D$1466,4,0) -> 0.047 | G16: =VLOOKUP(B16,'Yield Curve'!B16:G63,5,0) -> 3.086 | H16: =VLOOKUP(B16,'ppm risk premium'!$O$3:$R$51,4,0)*100 -> 147.44672 | I16: 4.3387776
... B52: 42062 | C52: 0.11157649 | D52: -86.739531 | E52: 0.016224449 | F52: =VLOOKUP(B52,'Realized Vol'!$A$2:$D$1466,4,0) -> 0.0488 | G52: =VLOOKUP(B52,'Yield Curve'!B52:G99,5,0) -> 2.597 | H52: =VLOOKUP(B52,'ppm risk premium'!$O$3:$R$51,4,0)*100 -> 89.590633 | I52: 5.770476

Sheet Realized Vol
A1: Asof | B1: Coupon | C1: dy | D1: vol1
A2: 42074 | B2: 2.8278353 | C2: -0.0185 | D2: 0.0507
A3: 42073 | B3: 2.8463503 | C3: -0.0559 | D3: 0.0507
A4: 42072 | B4: 2.9022275 | C4: -0.0281 | D4: 0.0504
A5: 42069 | B5: 2.930317 | C5: 0.1148 | D5: 0.0503
A6: 42068 | B6: 2.8155616 | C6: -0.0086 | D6: 0.0484
A7: 42067 | B7: 2.8241837 | C7: -0.01 | D7: 0.0489
A8: 42066 | B8: 2.8341999 | C8: 0.0426 | D8: 0.049
A9: 42065 | B9: 2.791635 | C9: 0.055 | D9: 0.0487
A10: 42062 | B10: 2.7365986 | C10: -0.0276 | D10: 0.0488
A11: 42061 | B11: 2.764194 | C11: 0.038 | D11: 0.0488
A12: 42060 | B12: 2.7262373 | C12: -0.0194 | D12: 0.0487
A13: 42059 | B13: 2.7456842 | C13: -0.0595 | D13: 0.0487
... A1465: 39937 | B1465: 4.0382752 | C1465: -0.0476 | D1465: -0.011721065
A1466: 39934 | B1466: 4.0858866 | C1466: 4.0859 | D1466: #DIV/0!

Sheet Yield Curve
C3: Treasury Yields
B4: Date | C4: 2 | D4: 5 | E4: 10 | F4: 30 | G4: 10-2
B5: 40633 | C5: 0.786 | D5: 2.223 | E5: 3.45 | F5: 4.507 | G5: =E5-C5 -> 2.664
B6: 40662 | C6: 0.605 | D6: 1.97 | E6: 3.292 | F6: 4.404 | G6: =E6-C6 -> 2.687
B7: 40694 | C7: 0.465 | D7: 1.686 | E7: 3.05 | F7: 4.215 | G7: =E7-C7 -> 2.585
B8: 40724 | C8: 0.458 | D8: 1.754 | E8: 3.158 | F8: 4.382 | G8: =E8-C8 -> 2.7
B9: 40753 | C9: 0.363 | D9: 1.369 | E9: 2.802 | F9: 4.133 | G9: =E9-C9 -> 2.439
B10: 40786 | C10: 0.2 | D10: 0.95 | E10: 2.222 | F10: 3.595 | G10: =E10-C10 -> 2.022
B11: 40816 | C11: 0.251 | D11: 0.963 | E11: 1.924 | F11: 2.92 | G11: =E11-C11 -> 1.673
B12: 40847 | C12: 0.258 | D12: 1.006 | E12: 2.166 | F12: 3.199 | G12: =E12-C12 -> 1.908
B13: 40877 | C13: 0.254 | D13: 0.949 | E13: 2.063 | F13: 3.061 | G13: =E13-C13 -> 1.809
B14: 40907 | C14: 0.247 | D14: 0.837 | E14: 1.876 | F14: 2.89 | G14: =E14-C14 -> 1.629
B15: 40939 | C15: 0.215 | D15: 0.709 | E15: 1.799 | F15: 2.934 | G15: =E15-C15 -> 1.584
B16: 40968 | C16: 0.301 | D16: 0.873 | E16: 1.979 | F16: 3.086 | G16: =E16-C16 -> 1.678
... B52: 42062 | C52: 0.622 | D52: 1.499 | E52: 1.998 | F52: 2.597 | G52: =E52-C52 -> 1.376

Sheet ppm risk premium
C3: asOf | D3: AVGWAC | G3: asOf | H3: RawRate | I3: Points | J3: Rate | K3: Accum Rate | L3: Count | M3: avg. Rate | O3: Date | P3: Avg WAC | Q3: Survey Rate | R3: Risk Premium
B4: =WORKDAY(C4,-1,) -> 36922 | C4: 36923 | D4: 7.5672077 | G4: 42088 | H4: 3.69 | I4: 0.6 | J4: 3.59 | K4: =IF(MONTH(G4)=MONTH(G5),J4+K5,J4) -> 66.1 | L4: =IF(MONTH(G4)=MONTH(G5),L5+1,1) -> 18 | M4: =K4/L4 -> 3.6722222 | O4: 40633 | P4: =VLOOKUP(O4,$B$4:$D$259,3,0) -> 5.5269247 | Q4: =VLOOKUP(O4,$G$4:$M$1060,7,0) -> 4.7580435 | R4: =P4-Q4 -> 0.76888122
B5: =WORKDAY(C5,-1,) -> 36950 | C5: 36951 | D5: 7.5507361 | G5: 42087 | H5: 3.69 | I5: 0.6 | J5: 3.59 | K5: =IF(MONTH(G5)=MONTH(G6),J5+K6,J5) -> 62.51 | L5: =IF(MONTH(G5)=MONTH(G6),L6+1,1) -> 17 | M5: =K5/L5 -> 3.6770588 | O5: 40662 | P5: =VLOOKUP(O5,$B$4:$D$259,3,0) -> 5.516896 | Q5: =VLOOKUP(O5,$G$4:$M$1060,7,0) -> 4.74725 | R5: =P5-Q5 -> 0.76964596
B6: =WORKDAY(C6,-1,) -> 36980 | C6: 36982 | D6: 7.5247913 | G6: 42086 | H6: 3.69 | I6: 0.6 | J6: 3.59 | K6: =IF(MONTH(G6)=MONTH(G7),J6+K7,J6) -> 58.92 | L6: =IF(MONTH(G6)=MONTH(G7),L7+1,1) -> 16 | M6: =K6/L6 -> 3.6825 | O6: 40694 | P6: =VLOOKUP(O6,$B$4:$D$259,3,0) -> 5.5064525 | Q6: =VLOOKUP(O6,$G$4:$M$1060,7,0) -> 4.5395238 | R6: =P6-Q6 -> 0.96692871
B7: =WORKDAY(C7,-1,) -> 37011 | C7: 37012 | D7: 7.4992216 | G7: 42083 | H7: 3.69 | I7: 0.6 | J7: 3.59 | K7: =IF(MONTH(G7)=MONTH(G8),J7+K8,J7) -> 55.33 | L7: =IF(MONTH(G7)=MONTH(G8),L8+1,1) -> 15 | M7: =K7/L7 -> 3.6886667 | O7: 40724 | P7: =VLOOKUP(O7,$B$4:$D$259,3,0) -> 5.4966047 | Q7: =VLOOKUP(O7,$G$4:$M$1060,7,0) -> 4.4363636 | R7: =P7-Q7 -> 1.060241
B8: =WORKDAY(C8,-1,) -> 37042 | C8: 37043 | D8: 7.4751311 | G8: 42082 | H8: 3.69 | I8: 0.6 | J8: 3.59 | K8: =IF(MONTH(G8)=MONTH(G9),J8+K9,J8) -> 51.74 | L8: =IF(MONTH(G8)=MONTH(G9),L9+1,1) -> 14 | M8: =K8/L8 -> 3.6957143 | O8: 40753 | P8: =VLOOKUP(O8,$B$4:$D$259,3,0) -> 5.4853483 | Q8: =VLOOKUP(O8,$G$4:$M$1060,7,0) -> 4.45775 | R8: =P8-Q8 -> 1.0275983
B9: =WORKDAY(C9,-1,) -> 37071 | C9: 37073 | D9: 7.457631 | G9: 42081 | H9: 3.78 | I9: 0.6 | J9: 3.68 | K9: =IF(MONTH(G9)=MONTH(G10),J9+K10,J9) -> 48.15 | L9: =IF(MONTH(G9)=MONTH(G10),L10+1,1) -> 13 | M9: =K9/L9 -> 3.7038462 | O9: 40786 | P9: =VLOOKUP(O9,$B$4:$D$259,3,0) -> 5.4705693 | Q9: =VLOOKUP(O9,$G$4:$M$1060,7,0) -> 4.1769565 | R9: =P9-Q9 -> 1.2936128
B10: =WORKDAY(C10,-1,) -> 37103 | C10: 37104 | D10: 7.4436499 | G10: 42080 | H10: 3.78 | I10: 0.6 | J10: 3.68 | K10: =IF(MONTH(G10)=MONTH(G11),J10+K11,J10) -> 44.47 | L10: =IF(MONTH(G10)=MONTH(G11),L11+1,1) -> 12 | M10: =K10/L10 -> 3.7058333 | O10: 40816 | P10: =VLOOKUP(O10,$B$4:$D$259,3,0) -> 5.4564254 | Q10: =VLOOKUP(O10,$G$4:$M$1060,7,0) -> 3.9897619 | R10: =P10-Q10 -> 1.4666635
B11: =WORKDAY(C11,-1,) -> 37134 | C11: 37135 | D11: 7.4274568 | G11: 42079 | H11: 3.78 | I11: 0.6 | J11: 3.68 | K11: =IF(MONTH(G11)=MONTH(G12),J11+K12,J11) -> 40.79 | L11: =IF(MONTH(G11)=MONTH(G12),L12+1,1) -> 11 | M11: =K11/L11 -> 3.7081818 | O11: 40847 | P11: =VLOOKUP(O11,$B$4:$D$259,3,0) -> 5.4364669 | Q11: =VLOOKUP(O11,$G$4:$M$1060,7,0) -> 4.01375 | R11: =P11-Q11 -> 1.4227169
B12: =WORKDAY(C12,-1,) -> 37162 | C12: 37165 | D12: 7.4102585 | G12: 42076 | H12: 3.78 | I12: 0.6 | J12: 3.68 | K12: =IF(MONTH(G12)=MONTH(G13),J12+K13,J12) -> 37.11 | L12: =IF(MONTH(G12)=MONTH(G13),L13+1,1) -> 10 | M12: =K12/L12 -> 3.711 | O12: 40877 | P12: =VLOOKUP(O12,$B$4:$D$259,3,0) -> 5.4070811 | Q12: =VLOOKUP(O12,$G$4:$M$1060,7,0) -> 3.9175 | R12: =P12-Q12 -> 1.4895811
B13: =WORKDAY(C13,-1,) -> 37195 | C13: 37196 | D13: 7.3806635 | G13: 42075 | H13: 3.78 | I13: 0.6 | J13: 3.68 | K13: =IF(MONTH(G13)=MONTH(G14),J13+K14,J13) -> 33.43 | L13: =IF(MONTH(G13)=MONTH(G14),L14+1,1) -> 9 | M13: =K13/L13 -> 3.7144444 | O13: 40907 | P13: =VLOOKUP(O13,$B$4:$D$259,3,0) -> 5.3841265 | Q13: =VLOOKUP(O13,$G$4:$M$1060,7,0) -> 3.8771429 | R13: =P13-Q13 -> 1.5069836
B14: =WORKDAY(C14,-1,) -> 37225 | C14: 37226 | D14: 7.3401035 | G14: 42074 | H14: 3.86 | I14: 0.6 | J14: 3.76 | K14: =IF(MONTH(G14)=MONTH(G15),J14+K15,J14) -> 29.75 | L14: =IF(MONTH(G14)=MONTH(G15),L15+1,1) -> 8 | M14: =K14/L14 -> 3.71875 | O14: 40939 | P14: =VLOOKUP(O14,$B$4:$D$259,3,0) -> 5.3594349 | Q14: =VLOOKUP(O14,$G$4:$M$1060,7,0) -> 3.846 | R14: =P14-Q14 -> 1.5134349
B15: =WORKDAY(C15,-1,) -> 37256 | C15: 37257 | D15: 7.3028699 | G15: 42073 | H15: 3.86 | I15: 0.6 | J15: 3.76 | K15: =IF(MONTH(G15)=MONTH(G16),J15+K16,J15) -> 25.99 | L15: =IF(MONTH(G15)=MONTH(G16),L16+1,1) -> 7 | M15: =K15/L15 -> 3.7128571 | O15: 40968 | P15: =VLOOKUP(O15,$B$4:$D$259,3,0) -> 5.3179672 | Q15: =VLOOKUP(O15,$G$4:$M$1060,7,0) -> 3.8435 | R15: =P15-Q15 -> 1.4744672
... B51: =WORKDAY(C51,-1,) -> 38352 | C51: 38353 | D51: 6.0967224 | G51: 42019 | H51: 3.63 | I51: 0.7 | J51: 3.555 | K51: =IF(MONTH(G51)=MONTH(G52),J51+K52,J51) -> 35.875 | L51: =IF(MONTH(G51)=MONTH(G52),L52+1,1) -> 10 | M51: =K51/L51 -> 3.5875 | O51: 42062 | P51: =VLOOKUP(O51,$B$4:$D$259,3,0) -> 4.5240642 | Q51: =VLOOKUP(O51,$G$4:$M$1060,7,0) -> 3.6281579 | R51: =P51-Q51 -> 0.89590633
B52: =WORKDAY(C52,-1,) -> 38383 | C52: 38384 | D52: 6.0882423 | G52: 42018 | H52: 3.66 | I52: 0.6 | J52: 3.56 | K52: =IF(MONTH(G52)=MONTH(G53),J52+K53,J52) -> 32.32 | L52: =IF(MONTH(G52)=MONTH(G53),L53+1,1) -> 9 | M52: =K52/L52 -> 3.5911111
B53: =WORKDAY(C53,-1,) -> 38411 | C53: 38412 | D53: 6.0785939 | G53: 42017 | H53: 3.66 | I53: 0.6 | J53: 3.56 | K53: =IF(MONTH(G53)=MONTH(G54),J53+K54,J53) -> 28.76 | L53: =IF(MONTH(G53)=MONTH(G54),L54+1,1) -> 8 | M53: =K53/L53 -> 3.595
B54: =WORKDAY(C54,-1,) -> 38442 | C54: 38443 | D54: 6.0668001 | G54: 42016 | H54: 3.66 | I54: 0.6 | J54: 3.56 | K54: =IF(MONTH(G54)=MONTH(G55),J54+K55,J54) -> 25.2 | L54: =IF(MONTH(G54)=MONTH(G55),L55+1,1) -> 7 | M54: =K54/L54 -> 3.6
B55: =WORKDAY(C55,-1,) -> 38471 | C55: 38473 | D55: 6.0593568 | G55: 42013 | H55: 3.66 | I55: 0.6 | J55: 3.56 | K55: =IF(MONTH(G55)=MONTH(G56),J55+K56,J55) -> 21.64 | L55: =IF(MONTH(G55)=MONTH(G56),L56+1,1) -> 6 | M55: =K55/L55 -> 3.6066667
B56: =WORKDAY(C56,-1,) -> 38503 | C56: 38504 | D56: 6.0534153 | G56: 42012 | H56: 3.66 | I56: 0.6 | J56: 3.56 | K56: =IF(MONTH(G56)=MONTH(G57),J56+K57,J56) -> 18.08 | L56: =IF(MONTH(G56)=MONTH(G57),L57+1,1) -> 5 | M56: =K56/L56 -> 3.616
B57: =WORKDAY(C57,-1,) -> 38533 | C57: 38534 | D57: 6.0442837 | G57: 42011 | H57: 3.73 | I57: 0.6 | J57: 3.63 | K57: =IF(MONTH(G57)=MONTH(G58),J57+K58,J57) -> 14.52 | L57: =IF(MONTH(G57)=MONTH(G58),L58+1,1) -> 4 | M57: =K57/L57 -> 3.63
B58: =WORKDAY(C58,-1,) -> 38562 | C58: 38565 | D58: 6.0330389 | G58: 42010 | H58: 3.73 | I58: 0.6 | J58: 3.63 | K58: =IF(MONTH(G58)=MONTH(G59),J58+K59,J58) -> 10.89 | L58: =IF(MONTH(G58)=MONTH(G59),L59+1,1) -> 3 | M58: =K58/L58 -> 3.63
B59: =WORKDAY(C59,-1,) -> 38595 | C59: 38596 | D59: 6.0224193 | G59: 42009 | H59: 3.73 | I59: 0.6 | J59: 3.63 | K59: =IF(MONTH(G59)=MONTH(G60),J59+K60,J59) -> 7.26 | L59: =IF(MONTH(G59)=MONTH(G60),L60+1,1) -> 2 | M59: =K59/L59 -> 3.63
B60: =WORKDAY(C60,-1,) -> 38625 | C60: 38626 | D60: 6.0150666 | G60: 42006 | H60: 3.73 | I60: 0.6 | J60: 3.63 | K60: =IF(MONTH(G60)=MONTH(G61),J60+K61,J60) -> 3.63 | L60: =IF(MONTH(G60)=MONTH(G61),L61+1,1) -> 1 | M60: =K60/L60 -> 3.63
B61: =WORKDAY(C61,-1,) -> 38656 | C61: 38657 | D61: 6.0095922 | G61: 42004 | H61: 3.87 | I61: 0.6 | J61: 3.77 | K61: =IF(MONTH(G61)=MONTH(G62),J61+K62,J61) -> 82.55 | L61: =IF(MONTH(G61)=MONTH(G62),L62+1,1) -> 22 | M61: =K61/L61 -> 3.7522727
B62: =WORKDAY(C62,-1,) -> 38686 | C62: 38687 | D62: 6.0081037 | G62: 42002 | H62: 3.87 | I62: 0.6 | J62: 3.77 | K62: =IF(MONTH(G62)=MONTH(G63),J62+K63,J62) -> 78.78 | L62: =IF(MONTH(G62)=MONTH(G63),L63+1,1) -> 21 | M62: =K62/L62 -> 3.7514286
B63: =WORKDAY(C63,-1,) -> 38716 | C63: 38718 | D63: 6.0114448 | G63: 41999 | H63: 3.87 | I63: 0.6 | J63: 3.77 | K63: =IF(MONTH(G63)=MONTH(G64),J63+K64,J63) -> 75.01 | L63: =IF(MONTH(G63)=MONTH(G64),L64+1,1) -> 20 | M63: =K63/L63 -> 3.7505
... B234: =WORKDAY(C234,-1,) -> 41333 | C234: 41334 | D234: 4.8553418 | G234: 41752 | H234: 4.33 | I234: 0.6 | J234: 4.23 | K234: =IF(MONTH(G234)=MONTH(G235),J234+K235,J234) -> 67.89 | L234: =IF(MONTH(G234)=MONTH(G235),L235+1,1) -> 16 | M234: =K234/L234 -> 4.243125
B235: =WORKDAY(C235,-2,) -> 41361 | C235: 41365 | D235: 4.8154791 | G235: 41751 | H235: 4.33 | I235: 0.6 | J235: 4.23 | K235: =IF(MONTH(G235)=MONTH(G236),J235+K236,J235) -> 63.66 | L235: =IF(MONTH(G235)=MONTH(G236),L236+1,1) -> 15 | M235: =K235/L235 -> 4.244
B236: =WORKDAY(C236,-1,) -> 41394 | C236: 41395 | D236: 4.7738505 | G236: 41750 | H236: 4.33 | I236: 0.6 | J236: 4.23 | K236: =IF(MONTH(G236)=MONTH(G237),J236+K237,J236) -> 59.43 | L236: =IF(MONTH(G236)=MONTH(G237),L237+1,1) -> 14 | M236: =K236/L236 -> 4.245
B237: =WORKDAY(C237,-1,) -> 41425 | C237: 41426 | D237: 4.7354436 | G237: 41746 | H237: 4.33 | I237: 0.6 | J237: 4.23 | K237: =IF(MONTH(G237)=MONTH(G238),J237+K238,J237) -> 55.2 | L237: =IF(MONTH(G237)=MONTH(G238),L238+1,1) -> 13 | M237: =K237/L237 -> 4.2461538
B238: =WORKDAY(C238,-1,) -> 41453 | C238: 41456 | D238: 4.697971 | G238: 41745 | H238: 4.27 | I238: 0.7 | J238: 4.195 | K238: =IF(MONTH(G238)=MONTH(G239),J238+K239,J238) -> 50.97 | L238: =IF(MONTH(G238)=MONTH(G239),L239+1,1) -> 12 | M238: =K238/L238 -> 4.2475
B239: =WORKDAY(C239,-1,) -> 41486 | C239: 41487 | D239: 4.670504 | G239: 41744 | H239: 4.27 | I239: 0.7 | J239: 4.195 | K239: =IF(MONTH(G239)=MONTH(G240),J239+K240,J239) -> 46.775 | L239: =IF(MONTH(G239)=MONTH(G240),L240+1,1) -> 11 | M239: =K239/L239 -> 4.2522727
B240: =WORKDAY(C240,-1,) -> 41516 | C240: 41518 | D240: 4.653429 | G240: 41743 | H240: 4.27 | I240: 0.7 | J240: 4.195 | K240: =IF(MONTH(G240)=MONTH(G241),J240+K241,J240) -> 42.58 | L240: =IF(MONTH(G240)=MONTH(G241),L241+1,1) -> 10 | M240: =K240/L240 -> 4.258
B241: =WORKDAY(C241,-1,) -> 41547 | C241: 41548 | D241: 4.6436536 | G241: 41740 | H241: 4.27 | I241: 0.7 | J241: 4.195 | K241: =IF(MONTH(G241)=MONTH(G242),J241+K242,J241) -> 38.385 | L241: =IF(MONTH(G241)=MONTH(G242),L242+1,1) -> 9 | M241: =K241/L241 -> 4.265
B242: =WORKDAY(C242,-1,) -> 41578 | C242: 41579 | D242: 4.6346558 | G242: 41739 | H242: 4.27 | I242: 0.7 | J242: 4.195 | K242: =IF(MONTH(G242)=MONTH(G243),J242+K243,J242) -> 34.19 | L242: =IF(MONTH(G242)=MONTH(G243),L243+1,1) -> 8 | M242: =K242/L242 -> 4.27375
B243: =WORKDAY(C243,-1,) -> 41607 | C243: 41609 | D243: 4.6259752 | G243: 41738 | H243: 4.34 | I243: 0.7 | J243: 4.265 | K243: =IF(MONTH(G243)=MONTH(G244),J243+K244,J243) -> 29.995 | L243: =IF(MONTH(G243)=MONTH(G244),L244+1,1) -> 7 | M243: =K243/L243 -> 4.285
B244: =WORKDAY(C244,-1,) -> 41639 | C244: 41640 | D244: 4.6181105 | G244: 41737 | H244: 4.34 | I244: 0.7 | J244: 4.265 | K244: =IF(MONTH(G244)=MONTH(G245),J244+K245,J244) -> 25.73 | L244: =IF(MONTH(G244)=MONTH(G245),L245+1,1) -> 6 | M244: =K244/L244 -> 4.2883333
B245: =WORKDAY(C245,-1,) -> 41670 | C245: 41671 | D245: 4.6123161 | G245: 41736 | H245: 4.34 | I245: 0.7 | J245: 4.265 | K245: =IF(MONTH(G245)=MONTH(G246),J245+K246,J245) -> 21.465 | L245: =IF(MONTH(G245)=MONTH(G246),L246+1,1) -> 5 | M245: =K245/L245 -> 4.293
B246: =WORKDAY(C246,-1,) -> 41698 | C246: 41699 | D246: 4.6074732 | G246: 41733 | H246: 4.34 | I246: 0.7 | J246: 4.265 | K246: =IF(MONTH(G246)=MONTH(G247),J246+K247,J246) -> 17.2 | L246: =IF(MONTH(G246)=MONTH(G247),L247+1,1) -> 4 | M246: =K246/L246 -> 4.3
B247: =WORKDAY(C247,-1,) -> 41729 | C247: 41730 | D247: 4.6020514 | G247: 41732 | H247: 4.34 | I247: 0.7 | J247: 4.265 | K247: =IF(MONTH(G247)=MONTH(G248),J247+K248,J247) -> 12.935 | L247: =IF(MONTH(G247)=MONTH(G248),L248+1,1) -> 3 | M247: =K247/L247 -> 4.3116667
...
