Workbook
Name temp: 'ppm risk premium'!#REF!
Name temp: 'Refi%'!$AA$3:$AB$236
Name temp_1: 'ppm risk premium'!#REF!
Name temp_2: 'ppm risk premium'!#REF!
Name temp1: 'LIBOR 1m'!#REF!

Sheet Data Set
B3: IOS Index
B4: Date | C4: Monthly Hedge Return (%) | D4: OAS | E4: IOS + TBA Carry (%) | F4: Realized Vol (Annualized %) | G4: Yield Curve 10-2 (bps) | H4: Prepayment Risk Premium (bps) | I4: Px/Coupon | J4: LIBOR 1m | K4: Refi Pct Pool | L4: Refi Pct Loan | M4: Refi Index | N4: CC | O4: CC Changes (bps)
B5: 40633 | C5: ='Return&Carry'!C3*100 -> 3.2147753 | D5: 12.454245 | E5: ='Return&Carry'!D3*100 -> 1.0991114 | F5: =VLOOKUP(TEXT(B5,"yyyy-mm-dd"),OneWeekMtgRatesDataTable7[],4,0)*SQRT(225)*100 -> 74.358832 | G5: =VLOOKUP(B5,'Yield Curve'!B5:G52,6,0)*100 -> 266.4 | H5: =VLOOKUP(B5,'ppm risk premium'!$C$3:$F$51,4,0)*100 -> 74.369809 | I5: 5.4040031 | J5: =VLOOKUP(B5,'LIBOR 1m'!D:F,3,0) -> 0.24345 | K5: =VLOOKUP(B5,'Refi%'!L:N,2,0) -> 0.59322571 | L5: =VLOOKUP(B5,'Refi%'!L:N,3,0) -> 0.42282959 | M5: =VLOOKUP(B5,'Refi%'!L:P,4,0) -> 2194.4 | N5: =VLOOKUP(B5,'Realized Vol'!H:J,2,0) -> 4.2632122 | O5: =VLOOKUP(B5,'Realized Vol'!H:J,3,0) -> 3.2379962
B6: 40662 | C6: ='Return&Carry'!C4*100 -> 3.9945301 | D6: -13.523942 | E6: ='Return&Carry'!D4*100 -> 1.0984369 | F6: =VLOOKUP(TEXT(B6,"yyyy-mm-dd"),OneWeekMtgRatesDataTable7[],4,0)*SQRT(225)*100 -> 60.151042 | G6: =VLOOKUP(B6,'Yield Curve'!B6:G53,6,0)*100 -> 268.7 | H6: =VLOOKUP(B6,'ppm risk premium'!$C$3:$F$51,4,0)*100 -> 89.19247 | I6: 5.4712823 | J6: =VLOOKUP(B6,'LIBOR 1m'!D:F,3,0) -> 0.21025 | K6: =VLOOKUP(B6,'Refi%'!L:N,2,0) -> 0.59445921 | L6: =VLOOKUP(B6,'Refi%'!L:N,3,0) -> 0.44565512 | M6: =VLOOKUP(B6,'Refi%'!L:P,4,0) -> 2220.1 | N6: =VLOOKUP(B6,'Realized Vol'!H:J,2,0) -> 4.0911415 | O6: =VLOOKUP(B6,'Realized Vol'!H:J,3,0) -> -17.207069
B7: 40694 | C7: ='Return&Carry'!C5*100 -> 3.6836949 | D7: -39.195911 | E7: ='Return&Carry'!D5*100 -> 1.2359979 | F7: =VLOOKUP(TEXT(B7,"yyyy-mm-dd"),OneWeekMtgRatesDataTable7[],4,0)*SQRT(225)*100 -> 48.820059 | G7: =VLOOKUP(B7,'Yield Curve'!B7:G54,6,0)*100 -> 258.5 | H7: =VLOOKUP(B7,'ppm risk premium'!$C$3:$F$51,4,0)*100 -> 106.6896 | I7: 5.4954374 | J7: =VLOOKUP(B7,'LIBOR 1m'!D:F,3,0) -> 0.19043 | K7: =VLOOKUP(B7,'Refi%'!L:N,2,0) -> 0.61599364 | L7: =VLOOKUP(B7,'Refi%'!L:N,3,0) -> 0.50568534 | M7: =VLOOKUP(B7,'Refi%'!L:P,4,0) -> 2619.7 | N7: =VLOOKUP(B7,'Realized Vol'!H:J,2,0) -> 3.9323543 | O7: =VLOOKUP(B7,'Realized Vol'!H:J,3,0) -> -15.878724
B8: 40724 | C8: ='Return&Carry'!C6*100 -> -0.89725231 | D8: -71.812763 | E8: ='Return&Carry'!D6*100 -> 1.1611305 | F8: =VLOOKUP(TEXT(B8,"yyyy-mm-dd"),OneWeekMtgRatesDataTable7[],4,0)*SQRT(225)*100 -> 51.642384 | G8: =VLOOKUP(B8,'Yield Curve'!B8:G55,6,0)*100 -> 270 | H8: =VLOOKUP(B8,'ppm risk premium'!$C$3:$F$51,4,0)*100 -> 98.145252 | I8: 5.5415672 | J8: =VLOOKUP(B8,'LIBOR 1m'!D:F,3,0) -> 0.18555 | K8: =VLOOKUP(B8,'Refi%'!L:N,2,0) -> 0.69050447 | L8: =VLOOKUP(B8,'Refi%'!L:N,3,0) -> 0.55445083 | M8: =VLOOKUP(B8,'Refi%'!L:P,4,0) -> 2527.5 | N8: =VLOOKUP(B8,'Realized Vol'!H:J,2,0) -> 4.0210178 | O8: =VLOOKUP(B8,'Realized Vol'!H:J,3,0) -> 8.8663527
B9: 40753 | C9: ='Return&Carry'!C7*100 -> -0.70542452 | D9: 14.555567 | E9: ='Return&Carry'!D7*100 -> 0.94859999 | F9: =VLOOKUP(TEXT(B9,"yyyy-mm-dd"),OneWeekMtgRatesDataTable7[],4,0)*SQRT(225)*100 -> 60.008169 | G9: =VLOOKUP(B9,'Yield Curve'!B9:G56,6,0)*100 -> 243.9 | H9: =VLOOKUP(B9,'ppm risk premium'!$C$3:$F$51,4,0)*100 -> 115.66047 | I9: 5.2080149 | J9: =VLOOKUP(B9,'LIBOR 1m'!D:F,3,0) -> 0.1911 | K9: =VLOOKUP(B9,'Refi%'!L:N,2,0) -> 0.61660059 | L9: =VLOOKUP(B9,'Refi%'!L:N,3,0) -> 0.52333295 | M9: =VLOOKUP(B9,'Refi%'!L:P,4,0) -> 2974.1 | N9: =VLOOKUP(B9,'Realized Vol'!H:J,2,0) -> 3.8088239 | O9: =VLOOKUP(B9,'Realized Vol'!H:J,3,0) -> -21.219393
B10: 40786 | C10: ='Return&Carry'!C8*100 -> -12.940149 | D10: 413.13076 | E10: ='Return&Carry'!D8*100 -> 0.98897456 | F10: =VLOOKUP(TEXT(B10,"yyyy-mm-dd"),OneWeekMtgRatesDataTable7[],4,0)*SQRT(225)*100 -> 99.218155 | G10: =VLOOKUP(B10,'Yield Curve'!B10:G57,6,0)*100 -> 202.2 | H10: =VLOOKUP(B10,'ppm risk premium'!$C$3:$F$51,4,0)*100 -> 134.03483 | I10: 4.1199718 | J10: =VLOOKUP(B10,'LIBOR 1m'!D:F,3,0) -> 0.2215 | K10: =VLOOKUP(B10,'Refi%'!L:N,2,0) -> 0.84714025 | L10: =VLOOKUP(B10,'Refi%'!L:N,3,0) -> 0.73013076 | M10: =VLOOKUP(B10,'Refi%'!L:P,4,0) -> 3601.3 | N10: =VLOOKUP(B10,'Realized Vol'!H:J,2,0) -> 3.4273948 | O10: =VLOOKUP(B10,'Realized Vol'!H:J,3,0) -> -38.142906
B11: 40816 | C11: ='Return&Carry'!C9*100 -> -10.646399 | D11: 707.36595 | E11: ='Return&Carry'!D9*100 -> 1.4023414 | F11: =VLOOKUP(TEXT(B11,"yyyy-mm-dd"),OneWeekMtgRatesDataTable7[],4,0)*SQRT(225)*100 -> 121.17161 | G11: =VLOOKUP(B11,'Yield Curve'!B11:G58,6,0)*100 -> 167.3 | H11: =VLOOKUP(B11,'ppm risk premium'!$C$3:$F$51,4,0)*100 -> 158.05693 | I11: 3.3173716 | J11: =VLOOKUP(B11,'LIBOR 1m'!D:F,3,0) -> 0.23944 | K11: =VLOOKUP(B11,'Refi%'!L:N,2,0) -> 0.94644262 | L11: =VLOOKUP(B11,'Refi%'!L:N,3,0) -> 0.83535228 | M11: =VLOOKUP(B11,'Refi%'!L:P,4,0) -> 4241.8 | N11: =VLOOKUP(B11,'Realized Vol'!H:J,2,0) -> 3.0385262 | O11: =VLOOKUP(B11,'Realized Vol'!H:J,3,0) -> -38.886865
B12: 40847 | C12: ='Return&Carry'!C10*100 -> 2.3593585 | D12: 688.11427 | E12: ='Return&Carry'!D10*100 -> 1.2905992 | F12: =VLOOKUP(TEXT(B12,"yyyy-mm-dd"),OneWeekMtgRatesDataTable7[],4,0)*SQRT(225)*100 -> 126.4888 | G12: =VLOOKUP(B12,'Yield Curve'!B12:G59,6,0)*100 -> 190.8 | H12: =VLOOKUP(B12,'ppm risk premium'!$C$3:$F$51,4,0)*100 -> 153.14254 | I12: 3.4720778 | J12: =VLOOKUP(B12,'LIBOR 1m'!D:F,3,0) -> 0.24528 | K12: =VLOOKUP(B12,'Refi%'!L:N,2,0) -> 0.86512672 | L12: =VLOOKUP(B12,'Refi%'!L:N,3,0) -> 0.7703392 | M12: =VLOOKUP(B12,'Refi%'!L:P,4,0) -> 3695 | N12: =VLOOKUP(B12,'Realized Vol'!H:J,2,0) -> 3.251577 | O12: =VLOOKUP(B12,'Realized Vol'!H:J,3,0) -> 21.305085
B13: 40877 | C13: ='Return&Carry'!C11*100 -> 1.4407939 | D13: 623.10169 | E13: ='Return&Carry'!D11*100 -> 0.70135917 | F13: =VLOOKUP(TEXT(B13,"yyyy-mm-dd"),OneWeekMtgRatesDataTable7[],4,0)*SQRT(225)*100 -> 107.84839 | G13: =VLOOKUP(B13,'Yield Curve'!B13:G60,6,0)*100 -> 180.9 | H13: =VLOOKUP(B13,'ppm risk premium'!$C$3:$F$51,4,0)*100 -> 151.14669 | I13: 3.4446943 | J13: =VLOOKUP(B13,'LIBOR 1m'!D:F,3,0) -> 0.27144 | K13: =VLOOKUP(B13,'Refi%'!L:N,2,0) -> 0.94997171 | L13: =VLOOKUP(B13,'Refi%'!L:N,3,0) -> 0.80850149 | M13: =VLOOKUP(B13,'Refi%'!L:P,4,0) -> 2941.3 | N13: =VLOOKUP(B13,'Realized Vol'!H:J,2,0) -> 3.1770193 | O13: =VLOOKUP(B13,'Realized Vol'!H:J,3,0) -> -7.4557679
B14: 40907 | C14: ='Return&Carry'!C12*100 -> 0.5832688 | D14: 610.59818 | E14: ='Return&Carry'!D12*100 -> 0.39545841 | F14: =VLOOKUP(TEXT(B14,"yyyy-mm-dd"),OneWeekMtgRatesDataTable7[],4,0)*SQRT(225)*100 -> 84.15733 | G14: =VLOOKUP(B14,'Yield Curve'!B14:G61,6,0)*100 -> 162.9 | H14: =VLOOKUP(B14,'ppm risk premium'!$C$3:$F$51,4,0)*100 -> 154.70811 | I14: 3.3659589 | J14: =VLOOKUP(B14,'LIBOR 1m'!D:F,3,0) -> 0.2953 | K14: =VLOOKUP(B14,'Refi%'!L:N,2,0) -> 0.9476226 | L14: =VLOOKUP(B14,'Refi%'!L:N,3,0) -> 0.81734633 | M14: =VLOOKUP(B14,'Refi%'!L:P,4,0) -> 3608.1 | N14: =VLOOKUP(B14,'Realized Vol'!H:J,2,0) -> 3.0169009 | O14: =VLOOKUP(B14,'Realized Vol'!H:J,3,0) -> -16.011846
B15: 40939 | C15: ='Return&Carry'!C13*100 -> -3.0247515 | D15: 465.33199 | E15: ='Return&Carry'!D13*100 -> 0.93155585 | F15: =VLOOKUP(TEXT(B15,"yyyy-mm-dd"),OneWeekMtgRatesDataTable7[],4,0)*SQRT(225)*100 -> 67.218531 | G15: =VLOOKUP(B15,'Yield Curve'!B15:G62,6,0)*100 -> 158.4 | H15: =VLOOKUP(B15,'ppm risk premium'!$C$3:$F$51,4,0)*100 -> 156.41265 | I15: 3.0653812 | J15: =VLOOKUP(B15,'LIBOR 1m'!D:F,3,0) -> 0.26475 | K15: =VLOOKUP(B15,'Refi%'!L:N,2,0) -> 0.91861521 | L15: =VLOOKUP(B15,'Refi%'!L:N,3,0) -> 0.78339394 | M15: =VLOOKUP(B15,'Refi%'!L:P,4,0) -> 4184.3 | N15: =VLOOKUP(B15,'Realized Vol'!H:J,2,0) -> 2.7762953 | O15: =VLOOKUP(B15,'Realized Vol'!H:J,3,0) -> -24.060559
B16: 40968 | C16: ='Return&Carry'!C14*100 -> 11.557044 | D16: 220.00245 | E16: ='Return&Carry'!D14*100 -> 1.7106233 | F16: =VLOOKUP(TEXT(B16,"yyyy-mm-dd"),OneWeekMtgRatesDataTable7[],4,0)*SQRT(225)*100 -> 70.470813 | G16: =VLOOKUP(B16,'Yield Curve'!B16:G63,6,0)*100 -> 167.8 | H16: =VLOOKUP(B16,'ppm risk premium'!$C$3:$F$51,4,0)*100 -> 150.94349 | I16: 3.4491554 | J16: =VLOOKUP(B16,'LIBOR 1m'!D:F,3,0) -> 0.2435 | K16: =VLOOKUP(B16,'Refi%'!L:N,2,0) -> 0.90921329 | L16: =VLOOKUP(B16,'Refi%'!L:N,3,0) -> 0.76669717 | M16: =VLOOKUP(B16,'Refi%'!L:P,4,0) -> 4379.1 | N16: =VLOOKUP(B16,'Realized Vol'!H:J,2,0) -> 2.8817315 | O16: =VLOOKUP(B16,'Realized Vol'!H:J,3,0) -> 10.543628
... B52: 42062 | C52: ='Return&Carry'!C50*100 -> 11.15765 | D52: -86.739531 | E52: ='Return&Carry'!D50*100 -> 1.62244 | F52: =VLOOKUP(TEXT(B52,"yyyy-mm-dd"),OneWeekMtgRatesDataTable7[],4,0)*SQRT(225)*100 -> 73.252678 | G52: =VLOOKUP(B52,'Yield Curve'!B52:G99,6,0)*100 -> 137.6 | H52: =VLOOKUP(B52,'ppm risk premium'!$C$3:$F$51,4,0)*100 -> 88.618659 | I52: 5.5060135 | J52: =VLOOKUP(B52,'LIBOR 1m'!D:F,3,0) -> 0.173 | K52: =VLOOKUP(B52,'Refi%'!L:N,2,0) -> 0.61098575 | L52: =VLOOKUP(B52,'Refi%'!L:N,3,0) -> 0.56144623 | M52: =VLOOKUP(B52,'Refi%'!L:P,4,0) -> 1740.3 | N52: =VLOOKUP(B52,'Realized Vol'!H:J,2,0) -> 2.7365986 | O52: =VLOOKUP(B52,'Realized Vol'!H:J,3,0) -> 28.392978
B53: 42094 | C53: -0.7 | D53: -96.814517 | E53: ='Return&Carry'!D51*100 -> 0.98971 | F53: =VLOOKUP(TEXT(B53,"yyyy-mm-dd"),OneWeekMtgRatesDataTable7[],4,0)*SQRT(225)*100 -> 78.458334 | G53: =VLOOKUP(B53,'Yield Curve'!B53:G100,6,0)*100 -> 137.9 | H53: =VLOOKUP(B53,'ppm risk premium'!$C$3:$F$52,4,0)*100 -> 92.381279 | I53: 5.3690219 | J53: =VLOOKUP(B53,'LIBOR 1m'!D:F,3,0) -> 0.17625 | K53: =VLOOKUP(B53,'Refi%'!L:N,2,0) -> 0.64195316 | L53: =VLOOKUP(B53,'Refi%'!L:N,3,0) -> 0.61985541 | M53: =VLOOKUP(B53,'Refi%'!L:P,4,0) -> 1941.6 | N53: =VLOOKUP(B53,'Realized Vol'!H:J,2,0) -> 2.6610352 | O53: =VLOOKUP(B53,'Realized Vol'!H:J,3,0) -> -7.556341
B54: 42124 | C54: ='Return&Carry'!C52*100 -> 5.20696 | D54: 27.782091 | E54: ='Return&Carry'!D52*100 -> 0.23842 | F54: =VLOOKUP(TEXT(B54,"yyyy-mm-dd"),OneWeekMtgRatesDataTable7[],4,0)*SQRT(225)*100 -> 69.088668 | G54: =VLOOKUP(B54,'Yield Curve'!B54:G101,6,0)*100 -> 146.7 | H54: =VLOOKUP(B54,'ppm risk premium'!$C$3:$F$53,4,0)*100 -> 80.976701 | I54: 5.5645995 | J54: =VLOOKUP(B54,'LIBOR 1m'!D:F,3,0) -> 0.181 | K54: =VLOOKUP(B54,'Refi%'!L:N,2,0) -> 0.63639403 | L54: =VLOOKUP(B54,'Refi%'!L:N,3,0) -> 0.60887631 | M54: =VLOOKUP(B54,'Refi%'!L:P,4,0) -> 1559.4 | N54: =VLOOKUP(B54,'Realized Vol'!H:J,2,0) -> 2.7480147 | O54: =VLOOKUP(B54,'Realized Vol'!H:J,3,0) -> 8.6979562
B55: 42153 | C55: ='Return&Carry'!C53*100 -> 1.25011 | D55: 27 | E55: ='Return&Carry'!D53*100 -> 0.36718 | F55: =VLOOKUP(TEXT(B55,"yyyy-mm-dd"),OneWeekMtgRatesDataTable7[],4,0)*SQRT(225)*100 -> 68.401578 | G55: =VLOOKUP(B55,'Yield Curve'!B55:G102,6,0)*100 -> 149.2 | H55: =VLOOKUP(B55,'ppm risk premium'!$C$3:$F$54,4,0)*100 -> 72.745831 | I55: 5.6626092 | J55: =VLOOKUP(B55,'LIBOR 1m'!D:F,3,0) -> 0.184 | K55: =VLOOKUP(B55,'Refi%'!L:N,2,0) -> 0.54951677 | L55: =VLOOKUP(B55,'Refi%'!L:N,3,0) -> 0.49518214 | M55: =VLOOKUP(B55,'Refi%'!L:P,4,0) -> 1233.9 | N55: =VLOOKUP(B55,'Realized Vol'!H:J,2,0) -> 2.8125589 | O55: =VLOOKUP(B55,'Realized Vol'!H:J,3,0) -> 6.4544219
B56: 42185 | C56: ='Return&Carry'!C54*100 -> 4.67899 | D56: ='Return&Carry'!I55 -> 10 | E56: ='Return&Carry'!D54*100 -> 0.32145 | F56: =VLOOKUP(TEXT(B56,"yyyy-mm-dd"),OneWeekMtgRatesDataTable7[],4,0)*SQRT(225)*100 -> 75.446781 | G56: =VLOOKUP(B56,'Yield Curve'!B56:G103,6,0)*100 -> 169.8 | H56: =VLOOKUP(B56,'ppm risk premium'!C:F,4,0)*100 -> 50.563257 | I56: 6.1637474 | J56: =VLOOKUP(B56,'LIBOR 1m'!D:F,3,0) -> 0.1865 | K56: =VLOOKUP(B56,'Refi%'!L:N,2,0) -> 0.44996576 | L56: =VLOOKUP(B56,'Refi%'!L:N,3,0) -> 0.39696022 | M56: =VLOOKUP(B56,'Refi%'!L:P,4,0) -> 1246.1 | N56: =VLOOKUP(B56,'Realized Vol'!H:J,2,0) -> 3.0732804 | O56: =VLOOKUP(B56,'Realized Vol'!H:J,3,0) -> 26.07215
B57: 42216 | C57: ='Return&Carry'!C55*100 -> -1.54512 | D57: ='Return&Carry'!I56 -> 14 | E57: ='Return&Carry'!D55*100 -> 0.1851 | F57: =VLOOKUP(TEXT(B57,"yyyy-mm-dd"),OneWeekMtgRatesDataTable7[],4,0)*SQRT(225)*100 -> 82.06165 | G57: =VLOOKUP(B57,'Yield Curve'!B57:G104,6,0)*100 -> 153.1 | H57: =VLOOKUP(B57,'ppm risk premium'!C:F,4,0)*100 -> 66.456346 | I57: 5.9295802 | J57: =VLOOKUP(B57,'LIBOR 1m'!D:F,3,0) -> 0.19175 | K57: 0.4991227 | L57: 0.42269076 | M57: 1418 | N57: =VLOOKUP(B57,'Realized Vol'!H:J,2,0) -> 2.9155081 | O57: =VLOOKUP(B57,'Realized Vol'!H:J,3,0) -> -15.777232
B58: 42247 | C58: ='Return&Carry'!C56*100 -> 0.1421 | D58: ='Return&Carry'!I57 -> 21 | E58: ='Return&Carry'!D56*100 -> 0.48585 | F58: =VLOOKUP(TEXT(B58,"yyyy-mm-dd"),OneWeekMtgRatesDataTable7[],4,0)*SQRT(225)*100 -> 76.130205 | G58: =VLOOKUP(B58,'Yield Curve'!B58:G105,6,0)*100 -> 146.2 | H58: =VLOOKUP(B58,'ppm risk premium'!C:F,4,0)*100 -> 67.716229 | I58: 5.9246894 | J58: =VLOOKUP(B58,'LIBOR 1m'!D:F,3,0) -> 0.19855 | K58: 0.54776588 | L58: 0.53237291 | M58: 1545.5 | N58: =VLOOKUP(B58,'Realized Vol'!H:J,2,0) -> 2.934447 | O58: =VLOOKUP(B58,'Realized Vol'!H:J,3,0) -> 1.8938914
B59: 42277 | C59: ='Return&Carry'!C57*100 -> -1.24888 | D59: ='Return&Carry'!I58 -> 40 | E59: ='Return&Carry'!D57*100 -> 0.60951 | F59: =VLOOKUP(TEXT(B59,"yyyy-mm-dd"),OneWeekMtgRatesDataTable7[],4,0)*SQRT(225)*100 -> 67.08368 | G59: =VLOOKUP(B59,'Yield Curve'!B59:G106,6,0)*100 -> 141.5 | H59: =VLOOKUP(B59,'ppm risk premium'!C:F,4,0)*100 -> 70.972281 | I59: 5.7022764 | J59: =VLOOKUP(B59,'LIBOR 1m'!D:F,3,0) -> 0.193 | K59: 0.51886914 | L59: 0.48860275 | M59: 1589.5 | N59: =VLOOKUP(B59,'Realized Vol'!H:J,2,0) -> 2.8018988 | O59: =VLOOKUP(B59,'Realized Vol'!H:J,3,0) -> -13.254823
B60: 42307 | C60: ='Return&Carry'!C58*100 -> 0.19308467 | D60: ='Return&Carry'!I59 -> 42.354177 | E60: ='Return&Carry'!D58*100 -> 0.55736056 | F60: =VLOOKUP(TEXT(B60,"yyyy-mm-dd"),OneWeekMtgRatesDataTable7[],4,0)*SQRT(225)*100 -> 66.169248 | G60: =VLOOKUP(B60,'Yield Curve'!B60:G107,6,0)*100 -> 141.6 | H60: =VLOOKUP(B60,'ppm risk premium'!C:F,4,0)*100 -> 68.255604 | I60: 5.6929226 | J60: =VLOOKUP(B60,'LIBOR 1m'!D:F,3,0) -> 0.192 | K60: 0.57894029 | L60: 0.5525566 | M60: 1534.5 | N60: =VLOOKUP(B60,'Realized Vol'!H:J,2,0) -> 2.8444181 | O60: =VLOOKUP(B60,'Realized Vol'!H:J,3,0) -> 4.2519296

Sheet Return&Carry
G1: IOS Index
B2: Date | C2: Monthly Hedge Return (%) | D2: IOS + TBA Carry (%) | G2: IOS | K2: IOS + TBA*
B3: 40633 | C3: =K4 -> 0.032147753 | D3: =J4 -> 0.010991114 | G3: Date | H3: Monthly Return (%) | I3: OAS | J3: IOS + TBA Carry (%) | K3: Monthly Return (%)
B4: 40662 | C4: =K5 -> 0.039945301 | D4: =J5 -> 0.010984369 | G4: 40633 | H4: 0.036885208 | I4: 12.454245 | J4: 0.010991114 | K4: 0.032147753
B5: 40694 | C5: =K6 -> 0.036836949 | D5: =J6 -> 0.012359979 | G5: 40662 | H5: 0.01824177 | I5: -13.523942 | J5: 0.010984369 | K5: 0.039945301
B6: 40724 | C6: =K7 -> -0.0089725231 | D6: =J7 -> 0.011611305 | G6: 40694 | H6: 0.0095136889 | I6: -39.195911 | J6: 0.012359979 | K6: 0.036836949
B7: 40753 | C7: =K8 -> -0.0070542452 | D7: =J8 -> 0.0094859999 | G7: 40724 | H7: 0.014594354 | I7: -71.812763 | J7: 0.011611305 | K7: -0.0089725231
B8: 40786 | C8: =K9 -> -0.12940149 | D8: =J9 -> 0.0098897456 | G8: 40753 | H8: -0.056499118 | I8: 14.555567 | J8: 0.0094859999 | K8: -0.0070542452
B9: 40816 | C9: =K10 -> -0.10646399 | D9: =J10 -> 0.014023414 | G9: 40786 | H9: -0.20415555 | I9: 413.13076 | J9: 0.0098897456 | K9: -0.12940149
B10: 40847 | C10: =K11 -> 0.023593585 | D10: =J11 -> 0.012905992 | G10: 40816 | H10: -0.18608869 | I10: 707.36595 | J10: 0.014023414 | K10: -0.10646399
B11: 40877 | C11: =K12 -> 0.014407939 | D11: =J12 -> 0.0070135917 | G11: 40847 | H11: 0.052849339 | I11: 688.11427 | J11: 0.012905992 | K11: 0.023593585
B12: 40907 | C12: =K13 -> 0.005832688 | D12: =J13 -> 0.0039545841 | G12: 40877 | H12: -0.0070201413 | I12: 623.10169 | J12: 0.0070135917 | K12: 0.014407939
B13: 40939 | C13: =K14 -> -0.030247515 | D13: =J14 -> 0.0093155585 | G13: 40907 | H13: -0.027877514 | I13: 610.59818 | J13: 0.0039545841 | K13: 0.005832688
B14: 40968 | C14: =K15 -> 0.11557044 | D14: =J15 -> 0.017106233 | G14: 40939 | H14: -0.088730633 | I14: 465.33199 | J14: 0.0093155585 | K14: -0.030247515
B15: 40998 | C15: =K16 -> 0.07140025 | D15: =J16 -> 0.010372253 | G15: 40968 | H15: 0.1267261 | I15: 220.00245 | J15: 0.017106233 | K15: 0.11557044
... B53: 42153 | C53: =K54 -> 0.0125011 | D53: =J54 -> 0.0036718 | G53: 42124 | H53: 0.060751 | I53: 28 | J53: 0.0023842 | K53: 0.0520696
B54: =G55 -> 42185 | C54: =K55 -> 0.0467899 | D54: =J55 -> 0.0032145 | G54: 42153 | H54: 0.017461 | I54: 27 | J54: 0.0036718 | K54: 0.0125011
B55: 42216 | C55: =K56 -> -0.0154512 | D55: =J56 -> 0.001851 | G55: 42185 | H55: 0.091753 | I55: 10 | J55: 0.0032145 | K55: 0.0467899 | N55: 0.0031759822
B56: 42247 | C56: =K57 -> 0.001421 | D56: =J57 -> 0.0048585 | G56: 42216 | H56: -0.043299 | I56: 14 | J56: 0.001851 | K56: -0.0154512
B57: 42277 | C57: =K58 -> -0.0124888 | D57: =J58 -> 0.0060951 | G57: 42247 | H57: -0.002052 | I57: 21 | J57: 0.0048585 | K57: 0.001421
B58: 42278 | C58: =K59 -> 0.0019308467 | D58: =J59 -> 0.0055736056 | G58: 42277 | H58: -0.039848 | I58: 40 | J58: 0.0060951 | K58: -0.0124888
G59: 42307 | H59: 0.0036548713 | I59: 42.354177 | J59: 0.0055736056 | K59: 0.0019308467

Sheet Realized Vol
A1: AsOfDate | B1: SeriesNumValue | C1: dy | D1: vol1 | H1: Current Coupon Monthly Changes
A2: 2015-11-12 | B2: 3.0415503 | C2: =B2-B3 -> 0.017462237 | D2: =STDEV(C2:C61) -> 0.042656771 | H2: Date | I2: Current Coupon | J2: Changes
A3: 2015-11-10 | B3: 3.0240881 | C3: =B3-B4 -> -0.015383296 | D3: =STDEV(C3:C62) -> 0.042706147 | H3: 40602 | I3: =VLOOKUP(TEXT(H3,"yyyy-mm-dd"),A:B,2,0) -> 4.2308322
A4: 2015-11-09 | B4: 3.0394714 | C4: =B4-B5 -> 0.026773404 | D4: =STDEV(C4:C63) -> 0.042804954 | H4: ='Data Set'!B5 -> 40633 | I4: =VLOOKUP(TEXT(H4,"yyyy-mm-dd"),A:B,2,0) -> 4.2632122 | J4: =(I4-I3)*100 -> 3.2379962
A5: 2015-11-06 | B5: 3.012698 | C5: =B5-B6 -> 0.07389531 | D5: =STDEV(C5:C64) -> 0.042751077 | H5: ='Data Set'!B6 -> 40662 | I5: =VLOOKUP(TEXT(H5,"yyyy-mm-dd"),A:B,2,0) -> 4.0911415 | J5: =(I5-I4)*100 -> -17.207069
A6: 2015-11-05 | B6: 2.9388027 | C6: =B6-B7 -> 0.0047396519 | D6: =STDEV(C6:C65) -> 0.042277783 | H6: ='Data Set'!B7 -> 40694 | I6: =VLOOKUP(TEXT(H6,"yyyy-mm-dd"),A:B,2,0) -> 3.9323543 | J6: =(I6-I5)*100 -> -15.878724
A7: 2015-11-04 | B7: 2.934063 | C7: =B7-B8 -> 0.035764648 | D7: =STDEV(C7:C66) -> 0.042277762 | H7: ='Data Set'!B8 -> 40724 | I7: =VLOOKUP(TEXT(H7,"yyyy-mm-dd"),A:B,2,0) -> 4.0210178 | J7: =(I7-I6)*100 -> 8.8663527
A8: 2015-11-03 | B8: 2.8982984 | C8: =B8-B9 -> 0.033251564 | D8: =STDEV(C8:C67) -> 0.043468742 | H8: ='Data Set'!B9 -> 40753 | I8: =VLOOKUP(TEXT(H8,"yyyy-mm-dd"),A:B,2,0) -> 3.8088239 | J8: =(I8-I7)*100 -> -21.219393
A9: 2015-11-02 | B9: 2.8650468 | C9: =B9-B10 -> 0.020628718 | D9: =STDEV(C9:C68) -> 0.043783297 | H9: ='Data Set'!B10 -> 40786 | I9: =VLOOKUP(TEXT(H9,"yyyy-mm-dd"),A:B,2,0) -> 3.4273948 | J9: =(I9-I8)*100 -> -38.142906
A10: 2015-10-30 | B10: 2.8444181 | C10: =B10-B11 -> -0.031624885 | D10: =STDEV(C10:C69) -> 0.044112832 | H10: ='Data Set'!B11 -> 40816 | I10: =VLOOKUP(TEXT(H10,"yyyy-mm-dd"),A:B,2,0) -> 3.0385262 | J10: =(I10-I9)*100 -> -38.886865
A11: 2015-10-29 | B11: 2.876043 | C11: =B11-B12 -> 0.080230942 | D11: =STDEV(C11:C70) -> 0.044178451 | H11: ='Data Set'!B12 -> 40847 | I11: =VLOOKUP(TEXT(H11,"yyyy-mm-dd"),A:B,2,0) -> 3.251577 | J11: =(I11-I10)*100 -> 21.305085
A12: 2015-10-28 | B12: 2.795812 | C12: =B12-B13 -> 0.071828736 | D12: =STDEV(C12:C71) -> 0.043380459 | H12: ='Data Set'!B13 -> 40877 | I12: =VLOOKUP(TEXT(H12,"yyyy-mm-dd"),A:B,2,0) -> 3.1770193 | J12: =(I12-I11)*100 -> -7.4557679
A13: 2015-10-27 | B13: 2.7239833 | C13: =B13-B14 -> -0.031874277 | D13: =STDEV(C13:C72) -> 0.043423644 | H13: ='Data Set'!B14 -> 40907 | I13: =VLOOKUP(TEXT(H13,"yyyy-mm-dd"),A:B,2,0) -> 3.0169009 | J13: =(I13-I12)*100 -> -16.011846
A14: 2015-10-26 | B14: 2.7558576 | C14: =B14-B15 -> -0.015417786 | D14: =STDEV(C14:C73) -> 0.043398198 | H14: ='Data Set'!B15 -> 40939 | I14: =VLOOKUP(TEXT(H14,"yyyy-mm-dd"),A:B,2,0) -> 2.7762953 | J14: =(I14-I13)*100 -> -24.060559
A15: 2015-10-23 | B15: 2.7712754 | C15: =B15-B16 -> 0.053911108 | D15: =STDEV(C15:C74) -> 0.044476035 | H15: ='Data Set'!B16 -> 40968 | I15: =VLOOKUP(TEXT(H15,"yyyy-mm-dd"),A:B,2,0) -> 2.8817315 | J15: =(I15-I14)*100 -> 10.543628
... A58: 2015-08-24 | B58: 2.7900435 | C58: =B58-B59 -> -0.044436878 | D58: =STDEV(C58:C117) -> 0.054144114 | H58: ='Data Set'!B59 -> 42277 | I58: =VLOOKUP(TEXT(H58,"yyyy-mm-dd"),A:B,2,0) -> 2.8018988 | J58: =(I58-I57)*100 -> -13.254823
A59: 2015-08-21 | B59: 2.8344804 | C59: =B59-B60 -> -0.025386991 | D59: =STDEV(C59:C118) -> 0.053965849 | H59: 42307 | I59: =VLOOKUP(TEXT(H59,"yyyy-mm-dd"),A:B,2,0) -> 2.8444181 | J59: =(I59-I58)*100 -> 4.2519296
A60: 2015-08-20 | B60: 2.8598674 | C60: =B60-B61 -> -0.030017996 | D60: =STDEV(C60:C119) -> 0.053867643
A61: 2015-08-19 | B61: 2.8898854 | C61: =B61-B62 -> -0.069772917 | D61: =STDEV(C61:C120) -> 0.053724558
A62: 2015-08-18 | B62: 2.9596583 | C62: =B62-B63 -> 0.02391476 | D62: =STDEV(C62:C121) -> 0.053217223
A63: 2015-08-17 | B63: 2.9357435 | C63: =B63-B64 -> -0.026539816 | D63: =STDEV(C63:C122) -> 0.053281657
A64: 2015-08-14 | B64: 2.9622833 | C64: =B64-B65 -> 0.020734681 | D64: =STDEV(C64:C123) -> 0.053579038
A65: 2015-08-13 | B65: 2.9415487 | C65: =B65-B66 -> 0.055205418 | D65: =STDEV(C65:C124) -> 0.053536881
A66: 2015-08-12 | B66: 2.8863432 | C66: =B66-B67 -> -0.0031085308 | D66: =STDEV(C66:C125) -> 0.053214277
A67: 2015-08-11 | B67: 2.8894518 | C67: =B67-B68 -> -0.085848591 | D67: =STDEV(C67:C126) -> 0.053837922
A68: 2015-08-10 | B68: 2.9753004 | C68: =B68-B69 -> 0.051798467 | D68: =STDEV(C68:C127) -> 0.05369774
A69: 2015-08-07 | B69: 2.9235019 | C69: =B69-B70 -> -0.048462947 | D69: =STDEV(C69:C128) -> 0.053705504
A70: 2015-08-06 | B70: 2.9719648 | C70: =B70-B71 -> -0.036946635 | D70: =STDEV(C70:C129) -> 0.053412597
A71: 2015-08-05 | B71: 3.0089115 | C71: =B71-B72 -> 0.049654773 | D71: =STDEV(C71:C130) -> 0.053220317
... A1634: 2009-05-07 | B1634: 4.0854192 | C1634: =B1634-B1635 -> 4.0854192 | D1634: =STDEV(C1634:C1693) -> #DIV/0!

Sheet Yield Curve
C3: Treasury Yields
B4: Date | C4: 2 | D4: 5 | E4: 10 | F4: 30 | G4: 10-2
B5: 40633 | C5: 0.786 | D5: 2.223 | E5: 3.45 | F5: 4.507 | G5: =E5-C5 -> 2.664
B6: 40662 | C6: 0.605 | D6: 1.97 | E6: 3.292 | F6: 4.404 | G6: =E6-C6 -> 2.687
B7: 40694 | C7: 0.465 | D7: 1.686 | E7: 3.05 | F7: 4.215 | G7: =E7-C7 -> 2.585
B8: 40724 | C8: 0.458 | D8: 1.754 | E8: 3.158 | F8: 4.382 | G8: =E8-C8 -> 2.7
B9: 40753 | C9: 0.363 | D9: 1.369 | E9: 2.802 | F9: 4.133 | G9: =E9-C9 -> 2.439
B10: 40786 | C10: 0.2 | D10: 0.95 | E10: 2.222 | F10: 3.595 | G10: =E10-C10 -> 2.022
B11: 40816 | C11: 0.251 | D11: 0.963 | E11: 1.924 | F11: 2.92 | G11: =E11-C11 -> 1.673
B12: 40847 | C12: 0.258 | D12: 1.006 | E12: 2.166 | F12: 3.199 | G12: =E12-C12 -> 1.908
B13: 40877 | C13: 0.254 | D13: 0.949 | E13: 2.063 | F13: 3.061 | G13: =E13-C13 -> 1.809
B14: 40907 | C14: 0.247 | D14: 0.837 | E14: 1.876 | F14: 2.89 | G14: =E14-C14 -> 1.629
B15: 40939 | C15: 0.215 | D15: 0.709 | E15: 1.799 | F15: 2.934 | G15: =E15-C15 -> 1.584
B16: 40968 | C16: 0.301 | D16: 0.873 | E16: 1.979 | F16: 3.086 | G16: =E16-C16 -> 1.678
... B60: 42307 | C60: 0.732 | D60: 1.525 | E60: 2.148 | F60: 2.931 | G60: =E60-C60 -> 1.416

Sheet ppm risk premium
C3: Date | D3: Avg WAC | E3: Survey Rate | F3: Risk Premium | H3: asOf | I3: MonthEnd | J3: AVGWAC | L3: asOf | M3: Column1 | N3: RawRate | O3: Points | P3: Rate
C4: 40633 | D4: =VLOOKUP(C4,I:J,2,0) -> 5.5386981 | E4: =VLOOKUP(C4,M:P,4,0) -> 4.795 | F4: =D4-E4 -> 0.74369809 | H4: 42309 | I4: =IF(WEEKDAY(DATE(YEAR(H4),MONTH(H4)+1,0),2)=6,DATE(YEAR(H4),MONTH(H4)+1,0)-1,IF(WEEKDAY(DATE(YEAR(H4),MONTH(H4)+1,0),2)=7,DATE(YEAR(H4),MONTH(H4)+1,0)-2,DATE(YEAR(H4),MONTH(H4)+1,0))) -> 42338 | J4: 4.4474052 | L4: 2015-11-10 | M4: =DATE(YEAR(OneWeekMtgRatesDataTable75[[#This Row],[asOf]]),MONTH(OneWeekMtgRatesDataTable75[[#This Row],[asOf]]),DAY(OneWeekMtgRatesDataTable75[[#This Row],[asOf]])) -> 42318 | N4: 3.98 | O4: 0.6 | P4: 3.88
C5: 40662 | D5: =VLOOKUP(C5,I:J,2,0) -> 5.5269247 | E5: =VLOOKUP(C5,M:P,4,0) -> 4.635 | F5: =D5-E5 -> 0.8919247 | H5: 42278 | I5: =IF(WEEKDAY(DATE(YEAR(H5),MONTH(H5)+1,0),2)=6,DATE(YEAR(H5),MONTH(H5)+1,0)-1,IF(WEEKDAY(DATE(YEAR(H5),MONTH(H5)+1,0),2)=7,DATE(YEAR(H5),MONTH(H5)+1,0)-2,DATE(YEAR(H5),MONTH(H5)+1,0))) -> 42307 | J5: 4.452556 | L5: 2015-11-09 | M5: =DATE(YEAR(OneWeekMtgRatesDataTable75[[#This Row],[asOf]]),MONTH(OneWeekMtgRatesDataTable75[[#This Row],[asOf]]),DAY(OneWeekMtgRatesDataTable75[[#This Row],[asOf]])) -> 42317 | N5: 3.98 | O5: 0.6 | P5: 3.88
C6: 40694 | D6: =VLOOKUP(C6,I:J,2,0) -> 5.516896 | E6: =VLOOKUP(C6,M:P,4,0) -> 4.45 | F6: =D6-E6 -> 1.066896 | H6: 42248 | I6: =IF(WEEKDAY(DATE(YEAR(H6),MONTH(H6)+1,0),2)=6,DATE(YEAR(H6),MONTH(H6)+1,0)-1,IF(WEEKDAY(DATE(YEAR(H6),MONTH(H6)+1,0),2)=7,DATE(YEAR(H6),MONTH(H6)+1,0)-2,DATE(YEAR(H6),MONTH(H6)+1,0))) -> 42277 | J6: 4.4597228 | L6: 2015-11-06 | M6: =DATE(YEAR(OneWeekMtgRatesDataTable75[[#This Row],[asOf]]),MONTH(OneWeekMtgRatesDataTable75[[#This Row],[asOf]]),DAY(OneWeekMtgRatesDataTable75[[#This Row],[asOf]])) -> 42314 | N6: 3.98 | O6: 0.6 | P6: 3.88
C7: 40724 | D7: =VLOOKUP(C7,I:J,2,0) -> 5.5064525 | E7: =VLOOKUP(C7,M:P,4,0) -> 4.525 | F7: =D7-E7 -> 0.98145252 | H7: 42217 | I7: =IF(WEEKDAY(DATE(YEAR(H7),MONTH(H7)+1,0),2)=6,DATE(YEAR(H7),MONTH(H7)+1,0)-1,IF(WEEKDAY(DATE(YEAR(H7),MONTH(H7)+1,0),2)=7,DATE(YEAR(H7),MONTH(H7)+1,0)-2,DATE(YEAR(H7),MONTH(H7)+1,0))) -> 42247 | J7: 4.4671623 | L7: 2015-11-05 | M7: =DATE(YEAR(OneWeekMtgRatesDataTable75[[#This Row],[asOf]]),MONTH(OneWeekMtgRatesDataTable75[[#This Row],[asOf]]),DAY(OneWeekMtgRatesDataTable75[[#This Row],[asOf]])) -> 42313 | N7: 3.98 | O7: 0.6 | P7: 3.88
C8: 40753 | D8: =VLOOKUP(C8,I:J,2,0) -> 5.4966047 | E8: =VLOOKUP(C8,M:P,4,0) -> 4.34 | F8: =D8-E8 -> 1.1566047 | H8: 42186 | I8: =IF(WEEKDAY(DATE(YEAR(H8),MONTH(H8)+1,0),2)=6,DATE(YEAR(H8),MONTH(H8)+1,0)-1,IF(WEEKDAY(DATE(YEAR(H8),MONTH(H8)+1,0),2)=7,DATE(YEAR(H8),MONTH(H8)+1,0)-2,DATE(YEAR(H8),MONTH(H8)+1,0))) -> 42216 | J8: 4.4745635 | L8: 2015-11-04 | M8: =DATE(YEAR(OneWeekMtgRatesDataTable75[[#This Row],[asOf]]),MONTH(OneWeekMtgRatesDataTable75[[#This Row],[asOf]]),DAY(OneWeekMtgRatesDataTable75[[#This Row],[asOf]])) -> 42312 | N8: 3.87 | O8: 0.6 | P8: 3.77
C9: 40786 | D9: =VLOOKUP(C9,I:J,2,0) -> 5.4853483 | E9: =VLOOKUP(C9,M:P,4,0) -> 4.145 | F9: =D9-E9 -> 1.3403483 | H9: 42156 | I9: =IF(WEEKDAY(DATE(YEAR(H9),MONTH(H9)+1,0),2)=6,DATE(YEAR(H9),MONTH(H9)+1,0)-1,IF(WEEKDAY(DATE(YEAR(H9),MONTH(H9)+1,0),2)=7,DATE(YEAR(H9),MONTH(H9)+1,0)-2,DATE(YEAR(H9),MONTH(H9)+1,0))) -> 42185 | J9: 4.4856326 | L9: 2015-11-03 | M9: =DATE(YEAR(OneWeekMtgRatesDataTable75[[#This Row],[asOf]]),MONTH(OneWeekMtgRatesDataTable75[[#This Row],[asOf]]),DAY(OneWeekMtgRatesDataTable75[[#This Row],[asOf]])) -> 42311 | N9: 3.87 | O9: 0.6 | P9: 3.77
C10: 40816 | D10: =VLOOKUP(C10,I:J,2,0) -> 5.4705693 | E10: =VLOOKUP(C10,M:P,4,0) -> 3.89 | F10: =D10-E10 -> 1.5805693 | H10: 42125 | I10: =IF(WEEKDAY(DATE(YEAR(H10),MONTH(H10)+1,0),2)=6,DATE(YEAR(H10),MONTH(H10)+1,0)-1,IF(WEEKDAY(DATE(YEAR(H10),MONTH(H10)+1,0),2)=7,DATE(YEAR(H10),MONTH(H10)+1,0)-2,DATE(YEAR(H10),MONTH(H10)+1,0))) -> 42153 | J10: 4.4974583 | L10: 2015-11-02 | M10: =DATE(YEAR(OneWeekMtgRatesDataTable75[[#This Row],[asOf]]),MONTH(OneWeekMtgRatesDataTable75[[#This Row],[asOf]]),DAY(OneWeekMtgRatesDataTable75[[#This Row],[asOf]])) -> 42310 | N10: 3.87 | O10: 0.6 | P10: 3.77
C11: 40847 | D11: =VLOOKUP(C11,I:J,2,0) -> 5.4564254 | E11: =VLOOKUP(C11,M:P,4,0) -> 3.925 | F11: =D11-E11 -> 1.5314254 | H11: 42095 | I11: =IF(WEEKDAY(DATE(YEAR(H11),MONTH(H11)+1,0),2)=6,DATE(YEAR(H11),MONTH(H11)+1,0)-1,IF(WEEKDAY(DATE(YEAR(H11),MONTH(H11)+1,0),2)=7,DATE(YEAR(H11),MONTH(H11)+1,0)-2,DATE(YEAR(H11),MONTH(H11)+1,0))) -> 42124 | J11: 4.509767 | L11: 2015-10-30 | M11: =DATE(YEAR(OneWeekMtgRatesDataTable75[[#This Row],[asOf]]),MONTH(OneWeekMtgRatesDataTable75[[#This Row],[asOf]]),DAY(OneWeekMtgRatesDataTable75[[#This Row],[asOf]])) -> 42307 | N11: 3.87 | O11: 0.6 | P11: 3.77
C12: 40877 | D12: =VLOOKUP(C12,I:J,2,0) -> 5.4364669 | E12: =VLOOKUP(C12,M:P,4,0) -> 3.925 | F12: =D12-E12 -> 1.5114669 | H12: 42064 | I12: =IF(WEEKDAY(DATE(YEAR(H12),MONTH(H12)+1,0),2)=6,DATE(YEAR(H12),MONTH(H12)+1,0)-1,IF(WEEKDAY(DATE(YEAR(H12),MONTH(H12)+1,0),2)=7,DATE(YEAR(H12),MONTH(H12)+1,0)-2,DATE(YEAR(H12),MONTH(H12)+1,0))) -> 42094 | J12: 4.5238128 | L12: 2015-10-29 | M12: =DATE(YEAR(OneWeekMtgRatesDataTable75[[#This Row],[asOf]]),MONTH(OneWeekMtgRatesDataTable75[[#This Row],[asOf]]),DAY(OneWeekMtgRatesDataTable75[[#This Row],[asOf]])) -> 42306 | N12: 3.87 | O12: 0.6 | P12: 3.77
C13: 40907 | D13: =VLOOKUP(C13,I:J,2,0) -> 5.4070811 | E13: =VLOOKUP(C13,M:P,4,0) -> 3.86 | F13: =D13-E13 -> 1.5470811 | H13: 42036 | I13: =IF(WEEKDAY(DATE(YEAR(H13),MONTH(H13)+1,0),2)=6,DATE(YEAR(H13),MONTH(H13)+1,0)-1,IF(WEEKDAY(DATE(YEAR(H13),MONTH(H13)+1,0),2)=7,DATE(YEAR(H13),MONTH(H13)+1,0)-2,DATE(YEAR(H13),MONTH(H13)+1,0))) -> 42062 | J13: 4.5361866 | L13: 2015-10-28 | M13: =DATE(YEAR(OneWeekMtgRatesDataTable75[[#This Row],[asOf]]),MONTH(OneWeekMtgRatesDataTable75[[#This Row],[asOf]]),DAY(OneWeekMtgRatesDataTable75[[#This Row],[asOf]])) -> 42305 | N13: 3.76 | O13: 0.6 | P13: 3.66
C14: 40939 | D14: =VLOOKUP(C14,I:J,2,0) -> 5.3841265 | E14: =VLOOKUP(C14,M:P,4,0) -> 3.82 | F14: =D14-E14 -> 1.5641265 | H14: 42005 | I14: =IF(WEEKDAY(DATE(YEAR(H14),MONTH(H14)+1,0),2)=6,DATE(YEAR(H14),MONTH(H14)+1,0)-1,IF(WEEKDAY(DATE(YEAR(H14),MONTH(H14)+1,0),2)=7,DATE(YEAR(H14),MONTH(H14)+1,0)-2,DATE(YEAR(H14),MONTH(H14)+1,0))) -> 42034 | J14: 4.5446755 | L14: 2015-10-27 | M14: =DATE(YEAR(OneWeekMtgRatesDataTable75[[#This Row],[asOf]]),MONTH(OneWeekMtgRatesDataTable75[[#This Row],[asOf]]),DAY(OneWeekMtgRatesDataTable75[[#This Row],[asOf]])) -> 42304 | N14: 3.76 | O14: 0.6 | P14: 3.66
C15: 40968 | D15: =VLOOKUP(C15,I:J,2,0) -> 5.3594349 | E15: =VLOOKUP(C15,M:P,4,0) -> 3.85 | F15: =D15-E15 -> 1.5094349 | H15: 41974 | I15: =IF(WEEKDAY(DATE(YEAR(H15),MONTH(H15)+1,0),2)=6,DATE(YEAR(H15),MONTH(H15)+1,0)-1,IF(WEEKDAY(DATE(YEAR(H15),MONTH(H15)+1,0),2)=7,DATE(YEAR(H15),MONTH(H15)+1,0)-2,DATE(YEAR(H15),MONTH(H15)+1,0))) -> 42004 | J15: 4.5528472 | L15: 2015-10-26 | M15: =DATE(YEAR(OneWeekMtgRatesDataTable75[[#This Row],[asOf]]),MONTH(OneWeekMtgRatesDataTable75[[#This Row],[asOf]]),DAY(OneWeekMtgRatesDataTable75[[#This Row],[asOf]])) -> 42303 | N15: 3.76 | O15: 0.6 | P15: 3.66
... C59: 42307 | D59: =VLOOKUP(C59,I:J,2,0) -> 4.452556 | E59: =VLOOKUP(C59,M:P,4,0) -> 3.77 | F59: =D59-E59 -> 0.68255604 | H59: 40634 | I59: =IF(WEEKDAY(DATE(YEAR(H59),MONTH(H59)+1,0),2)=6,DATE(YEAR(H59),MONTH(H59)+1,0)-1,IF(WEEKDAY(DATE(YEAR(H59),MONTH(H59)+1,0),2)=7,DATE(YEAR(H59),MONTH(H59)+1,0)-2,DATE(YEAR(H59),MONTH(H59)+1,0))) -> 40662 | J59: 5.5269247 | L59: 2015-08-21 | M59: =DATE(YEAR(OneWeekMtgRatesDataTable75[[#This Row],[asOf]]),MONTH(OneWeekMtgRatesDataTable75[[#This Row],[asOf]]),DAY(OneWeekMtgRatesDataTable75[[#This Row],[asOf]])) -> 42237 | N59: 3.84 | O59: 0.6 | P59: 3.74
H60: 40603 | I60: =IF(WEEKDAY(DATE(YEAR(H60),MONTH(H60)+1,0),2)=6,DATE(YEAR(H60),MONTH(H60)+1,0)-1,IF(WEEKDAY(DATE(YEAR(H60),MONTH(H60)+1,0),2)=7,DATE(YEAR(H60),MONTH(H60)+1,0)-2,DATE(YEAR(H60),MONTH(H60)+1,0))) -> 40633 | J60: 5.5386981 | L60: 2015-08-20 | M60: =DATE(YEAR(OneWeekMtgRatesDataTable75[[#This Row],[asOf]]),MONTH(OneWeekMtgRatesDataTable75[[#This Row],[asOf]]),DAY(OneWeekMtgRatesDataTable75[[#This Row],[asOf]])) -> 42236 | N60: 3.84 | O60: 0.6 | P60: 3.74
H61: 40575 | I61: =IF(WEEKDAY(DATE(YEAR(H61),MONTH(H61)+1,0),2)=6,DATE(YEAR(H61),MONTH(H61)+1,0)-1,IF(WEEKDAY(DATE(YEAR(H61),MONTH(H61)+1,0),2)=7,DATE(YEAR(H61),MONTH(H61)+1,0)-2,DATE(YEAR(H61),MONTH(H61)+1,0))) -> 40602 | J61: 5.5560536 | L61: 2015-08-19 | M61: =DATE(YEAR(OneWeekMtgRatesDataTable75[[#This Row],[asOf]]),MONTH(OneWeekMtgRatesDataTable75[[#This Row],[asOf]]),DAY(OneWeekMtgRatesDataTable75[[#This Row],[asOf]])) -> 42235 | N61: 3.93 | O61: 0.6 | P61: 3.83
H62: 40544 | I62: =IF(WEEKDAY(DATE(YEAR(H62),MONTH(H62)+1,0),2)=6,DATE(YEAR(H62),MONTH(H62)+1,0)-1,IF(WEEKDAY(DATE(YEAR(H62),MONTH(H62)+1,0),2)=7,DATE(YEAR(H62),MONTH(H62)+1,0)-2,DATE(YEAR(H62),MONTH(H62)+1,0))) -> 40574 | J62: 5.5763437 | L62: 2015-08-18 | M62: =DATE(YEAR(OneWeekMtgRatesDataTable75[[#This Row],[asOf]]),MONTH(OneWeekMtgRatesDataTable75[[#This Row],[asOf]]),DAY(OneWeekMtgRatesDataTable75[[#This Row],[asOf]])) -> 42234 | N62: 3.93 | O62: 0.6 | P62: 3.83
H63: 40513 | I63: =IF(WEEKDAY(DATE(YEAR(H63),MONTH(H63)+1,0),2)=6,DATE(YEAR(H63),MONTH(H63)+1,0)-1,IF(WEEKDAY(DATE(YEAR(H63),MONTH(H63)+1,0),2)=7,DATE(YEAR(H63),MONTH(H63)+1,0)-2,DATE(YEAR(H63),MONTH(H63)+1,0))) -> 40543 | J63: 5.6013603 | L63: 2015-08-17 | M63: =DATE(YEAR(OneWeekMtgRatesDataTable75[[#This Row],[asOf]]),MONTH(OneWeekMtgRatesDataTable75[[#This Row],[asOf]]),DAY(OneWeekMtgRatesDataTable75[[#This Row],[asOf]])) -> 42233 | N63: 3.93 | O63: 0.6 | P63: 3.83
H64: 40483 | I64: =IF(WEEKDAY(DATE(YEAR(H64),MONTH(H64)+1,0),2)=6,DATE(YEAR(H64),MONTH(H64)+1,0)-1,IF(WEEKDAY(DATE(YEAR(H64),MONTH(H64)+1,0),2)=7,DATE(YEAR(H64),MONTH(H64)+1,0)-2,DATE(YEAR(H64),MONTH(H64)+1,0))) -> 40512 | J64: 5.6324669 | L64: 2015-08-14 | M64: =DATE(YEAR(OneWeekMtgRatesDataTable75[[#This Row],[asOf]]),MONTH(OneWeekMtgRatesDataTable75[[#This Row],[asOf]]),DAY(OneWeekMtgRatesDataTable75[[#This Row],[asOf]])) -> 42230 | N64: 3.93 | O64: 0.6 | P64: 3.83
H65: 40452 | I65: =IF(WEEKDAY(DATE(YEAR(H65),MONTH(H65)+1,0),2)=6,DATE(YEAR(H65),MONTH(H65)+1,0)-1,IF(WEEKDAY(DATE(YEAR(H65),MONTH(H65)+1,0),2)=7,DATE(YEAR(H65),MONTH(H65)+1,0)-2,DATE(YEAR(H65),MONTH(H65)+1,0))) -> 40480 | J65: 5.6590403 | L65: 2015-08-13 | M65: =DATE(YEAR(OneWeekMtgRatesDataTable75[[#This Row],[asOf]]),MONTH(OneWeekMtgRatesDataTable75[[#This Row],[asOf]]),DAY(OneWeekMtgRatesDataTable75[[#This Row],[asOf]])) -> 42229 | N65: 3.93 | O65: 0.6 | P65: 3.83
H66: 40422 | I66: =IF(WEEKDAY(DATE(YEAR(H66),MONTH(H66)+1,0),2)=6,DATE(YEAR(H66),MONTH(H66)+1,0)-1,IF(WEEKDAY(DATE(YEAR(H66),MONTH(H66)+1,0),2)=7,DATE(YEAR(H66),MONTH(H66)+1,0)-2,DATE(YEAR(H66),MONTH(H66)+1,0))) -> 40451 | J66: 5.6844643 | L66: 2015-08-12 | M66: =DATE(YEAR(OneWeekMtgRatesDataTable75[[#This Row],[asOf]]),MONTH(OneWeekMtgRatesDataTable75[[#This Row],[asOf]]),DAY(OneWeekMtgRatesDataTable75[[#This Row],[asOf]])) -> 42228 | N66: 3.94 | O66: 0.6 | P66: 3.84
H67: 40391 | I67: =IF(WEEKDAY(DATE(YEAR(H67),MONTH(H67)+1,0),2)=6,DATE(YEAR(H67),MONTH(H67)+1,0)-1,IF(WEEKDAY(DATE(YEAR(H67),MONTH(H67)+1,0),2)=7,DATE(YEAR(H67),MONTH(H67)+1,0)-2,DATE(YEAR(H67),MONTH(H67)+1,0))) -> 40421 | J67: 5.7099767 | L67: 2015-08-11 | M67: =DATE(YEAR(OneWeekMtgRatesDataTable75[[#This Row],[asOf]]),MONTH(OneWeekMtgRatesDataTable75[[#This Row],[asOf]]),DAY(OneWeekMtgRatesDataTable75[[#This Row],[asOf]])) -> 42227 | N67: 3.94 | O67: 0.6 | P67: 3.84
H68: 40360 | I68: =IF(WEEKDAY(DATE(YEAR(H68),MONTH(H68)+1,0),2)=6,DATE(YEAR(H68),MONTH(H68)+1,0)-1,IF(WEEKDAY(DATE(YEAR(H68),MONTH(H68)+1,0),2)=7,DATE(YEAR(H68),MONTH(H68)+1,0)-2,DATE(YEAR(H68),MONTH(H68)+1,0))) -> 40389 | J68: 5.7262138 | L68: 2015-08-10 | M68: =DATE(YEAR(OneWeekMtgRatesDataTable75[[#This Row],[asOf]]),MONTH(OneWeekMtgRatesDataTable75[[#This Row],[asOf]]),DAY(OneWeekMtgRatesDataTable75[[#This Row],[asOf]])) -> 42226 | N68: 3.94 | O68: 0.6 | P68: 3.84
H69: 40330 | I69: =IF(WEEKDAY(DATE(YEAR(H69),MONTH(H69)+1,0),2)=6,DATE(YEAR(H69),MONTH(H69)+1,0)-1,IF(WEEKDAY(DATE(YEAR(H69),MONTH(H69)+1,0),2)=7,DATE(YEAR(H69),MONTH(H69)+1,0)-2,DATE(YEAR(H69),MONTH(H69)+1,0))) -> 40359 | J69: 5.7403826 | L69: 2015-08-07 | M69: =DATE(YEAR(OneWeekMtgRatesDataTable75[[#This Row],[asOf]]),MONTH(OneWeekMtgRatesDataTable75[[#This Row],[asOf]]),DAY(OneWeekMtgRatesDataTable75[[#This Row],[asOf]])) -> 42223 | N69: 3.94 | O69: 0.6 | P69: 3.84
H70: 40299 | I70: =IF(WEEKDAY(DATE(YEAR(H70),MONTH(H70)+1,0),2)=6,DATE(YEAR(H70),MONTH(H70)+1,0)-1,IF(WEEKDAY(DATE(YEAR(H70),MONTH(H70)+1,0),2)=7,DATE(YEAR(H70),MONTH(H70)+1,0)-2,DATE(YEAR(H70),MONTH(H70)+1,0))) -> 40329 | J70: 5.7574015 | L70: 2015-08-06 | M70: =DATE(YEAR(OneWeekMtgRatesDataTable75[[#This Row],[asOf]]),MONTH(OneWeekMtgRatesDataTable75[[#This Row],[asOf]]),DAY(OneWeekMtgRatesDataTable75[[#This Row],[asOf]])) -> 42222 | N70: 3.94 | O70: 0.6 | P70: 3.84
H71: 40269 | I71: =IF(WEEKDAY(DATE(YEAR(H71),MONTH(H71)+1,0),2)=6,DATE(YEAR(H71),MONTH(H71)+1,0)-1,IF(WEEKDAY(DATE(YEAR(H71),MONTH(H71)+1,0),2)=7,DATE(YEAR(H71),MONTH(H71)+1,0)-2,DATE(YEAR(H71),MONTH(H71)+1,0))) -> 40298 | J71: 5.7816058 | L71: 2015-08-05 | M71: =DATE(YEAR(OneWeekMtgRatesDataTable75[[#This Row],[asOf]]),MONTH(OneWeekMtgRatesDataTable75[[#This Row],[asOf]]),DAY(OneWeekMtgRatesDataTable75[[#This Row],[asOf]])) -> 42221 | N71: 3.91 | O71: 0.6 | P71: 3.81
... H266: 34335 | I266: =IF(WEEKDAY(DATE(YEAR(H266),MONTH(H266)+1,0),2)=6,DATE(YEAR(H266),MONTH(H266)+1,0)-1,IF(WEEKDAY(DATE(YEAR(H266),MONTH(H266)+1,0),2)=7,DATE(YEAR(H266),MONTH(H266)+1,0)-2,DATE(YEAR(H266),MONTH(H266)+1,0))) -> 34365 | J266: 8.4205053 | L266: 2014-10-24 | M266: =DATE(YEAR(OneWeekMtgRatesDataTable75[[#This Row],[asOf]]),MONTH(OneWeekMtgRatesDataTable75[[#This Row],[asOf]]),DAY(OneWeekMtgRatesDataTable75[[#This Row],[asOf]])) -> 41936 | N266: 3.98 | O266: 0.5 | P266: 3.855
L267: 2014-10-23 | M267: =DATE(YEAR(OneWeekMtgRatesDataTable75[[#This Row],[asOf]]),MONTH(OneWeekMtgRatesDataTable75[[#This Row],[asOf]]),DAY(OneWeekMtgRatesDataTable75[[#This Row],[asOf]])) -> 41935 | N267: 3.98 | O267: 0.5 | P267: 3.855
L268: 2014-10-22 | M268: =DATE(YEAR(OneWeekMtgRatesDataTable75[[#This Row],[asOf]]),MONTH(OneWeekMtgRatesDataTable75[[#This Row],[asOf]]),DAY(OneWeekMtgRatesDataTable75[[#This Row],[asOf]])) -> 41934 | N268: 3.92 | O268: 0.5 | P268: 3.795
L269: 2014-10-21 | M269: =DATE(YEAR(OneWeekMtgRatesDataTable75[[#This Row],[asOf]]),MONTH(OneWeekMtgRatesDataTable75[[#This Row],[asOf]]),DAY(OneWeekMtgRatesDataTable75[[#This Row],[asOf]])) -> 41933 | N269: 3.92 | O269: 0.5 | P269: 3.795
L270: 2014-10-20 | M270: =DATE(YEAR(OneWeekMtgRatesDataTable75[[#This Row],[asOf]]),MONTH(OneWeekMtgRatesDataTable75[[#This Row],[asOf]]),DAY(OneWeekMtgRatesDataTable75[[#This Row],[asOf]])) -> 41932 | N270: 3.92 | O270: 0.5 | P270: 3.795
L271: 2014-10-17 | M271: =DATE(YEAR(OneWeekMtgRatesDataTable75[[#This Row],[asOf]]),MONTH(OneWeekMtgRatesDataTable75[[#This Row],[asOf]]),DAY(OneWeekMtgRatesDataTable75[[#This Row],[asOf]])) -> 41929 | N271: 3.92 | O271: 0.5 | P271: 3.795
L272: 2014-10-16 | M272: =DATE(YEAR(OneWeekMtgRatesDataTable75[[#This Row],[asOf]]),MONTH(OneWeekMtgRatesDataTable75[[#This Row],[asOf]]),DAY(OneWeekMtgRatesDataTable75[[#This Row],[asOf]])) -> 41928 | N272: 3.92 | O272: 0.5 | P272: 3.795
L273: 2014-10-15 | M273: =DATE(YEAR(OneWeekMtgRatesDataTable75[[#This Row],[asOf]]),MONTH(OneWeekMtgRatesDataTable75[[#This Row],[asOf]]),DAY(OneWeekMtgRatesDataTable75[[#This Row],[asOf]])) -> 41927 | N273: 3.97 | O273: 0.5 | P273: 3.845
L274: 2014-10-14 | M274: =DATE(YEAR(OneWeekMtgRatesDataTable75[[#This Row],[asOf]]),MONTH(OneWeekMtgRatesDataTable75[[#This Row],[asOf]]),DAY(OneWeekMtgRatesDataTable75[[#This Row],[asOf]])) -> 41926 | N274: 3.97 | O274: 0.5 | P274: 3.845
L275: 2014-10-10 | M275: =DATE(YEAR(OneWeekMtgRatesDataTable75[[#This Row],[asOf]]),MONTH(OneWeekMtgRatesDataTable75[[#This Row],[asOf]]),DAY(OneWeekMtgRatesDataTable75[[#This Row],[asOf]])) -> 41922 | N275: 3.97 | O275: 0.5 | P275: 3.845
L276: 2014-10-09 | M276: =DATE(YEAR(OneWeekMtgRatesDataTable75[[#This Row],[asOf]]),MONTH(OneWeekMtgRatesDataTable75[[#This Row],[asOf]]),DAY(OneWeekMtgRatesDataTable75[[#This Row],[asOf]])) -> 41921 | N276: 3.97 | O276: 0.5 | P276: 3.845
L277: 2014-10-08 | M277: =DATE(YEAR(OneWeekMtgRatesDataTable75[[#This Row],[asOf]]),MONTH(OneWeekMtgRatesDataTable75[[#This Row],[asOf]]),DAY(OneWeekMtgRatesDataTable75[[#This Row],[asOf]])) -> 41920 | N277: 4.12 | O277: 0.5 | P277: 3.995
L278: 2014-10-07 | M278: =DATE(YEAR(OneWeekMtgRatesDataTable75[[#This Row],[asOf]]),MONTH(OneWeekMtgRatesDataTable75[[#This Row],[asOf]]),DAY(OneWeekMtgRatesDataTable75[[#This Row],[asOf]])) -> 41919 | N278: 4.12 | O278: 0.5 | P278: 3.995
... L3789: 2001-01-01 | M3789: =DATE(YEAR(OneWeekMtgRatesDataTable75[[#This Row],[asOf]]),MONTH(OneWeekMtgRatesDataTable75[[#This Row],[asOf]]),DAY(OneWeekMtgRatesDataTable75[[#This Row],[asOf]])) -> 36892 | N3789: 7.07 | O3789: 1 | P3789: 7.07

Sheet LIBOR 1m
B2: TickerName | C2: asofdate | D2: Column1 | E2: SeriesType | F2: SeriesNumValue
B3: 1 Month LIBOR | C3: 2015-11-12 | D3: =DATE(YEAR(OneWeekMtgRatesDataTable756[[#This Row],[asofdate]]),MONTH(OneWeekMtgRatesDataTable756[[#This Row],[asofdate]]),DAY(OneWeekMtgRatesDataTable756[[#This Row],[asofdate]])) -> 42320 | E3: Rate | F3: 0.197
B4: 1 Month LIBOR | C4: 2015-11-10 | D4: =DATE(YEAR(OneWeekMtgRatesDataTable756[[#This Row],[asofdate]]),MONTH(OneWeekMtgRatesDataTable756[[#This Row],[asofdate]]),DAY(OneWeekMtgRatesDataTable756[[#This Row],[asofdate]])) -> 42318 | E4: Rate | F4: 0.1955
B5: 1 Month LIBOR | C5: 2015-11-09 | D5: =DATE(YEAR(OneWeekMtgRatesDataTable756[[#This Row],[asofdate]]),MONTH(OneWeekMtgRatesDataTable756[[#This Row],[asofdate]]),DAY(OneWeekMtgRatesDataTable756[[#This Row],[asofdate]])) -> 42317 | E5: Rate | F5: 0.197
B6: 1 Month LIBOR | C6: 2015-11-06 | D6: =DATE(YEAR(OneWeekMtgRatesDataTable756[[#This Row],[asofdate]]),MONTH(OneWeekMtgRatesDataTable756[[#This Row],[asofdate]]),DAY(OneWeekMtgRatesDataTable756[[#This Row],[asofdate]])) -> 42314 | E6: Rate | F6: 0.1945
B7: 1 Month LIBOR | C7: 2015-11-05 | D7: =DATE(YEAR(OneWeekMtgRatesDataTable756[[#This Row],[asofdate]]),MONTH(OneWeekMtgRatesDataTable756[[#This Row],[asofdate]]),DAY(OneWeekMtgRatesDataTable756[[#This Row],[asofdate]])) -> 42313 | E7: Rate | F7: 0.19475
B8: 1 Month LIBOR | C8: 2015-11-04 | D8: =DATE(YEAR(OneWeekMtgRatesDataTable756[[#This Row],[asofdate]]),MONTH(OneWeekMtgRatesDataTable756[[#This Row],[asofdate]]),DAY(OneWeekMtgRatesDataTable756[[#This Row],[asofdate]])) -> 42312 | E8: Rate | F8: 0.1932
B9: 1 Month LIBOR | C9: 2015-11-03 | D9: =DATE(YEAR(OneWeekMtgRatesDataTable756[[#This Row],[asofdate]]),MONTH(OneWeekMtgRatesDataTable756[[#This Row],[asofdate]]),DAY(OneWeekMtgRatesDataTable756[[#This Row],[asofdate]])) -> 42311 | E9: Rate | F9: 0.1922
B10: 1 Month LIBOR | C10: 2015-11-02 | D10: =DATE(YEAR(OneWeekMtgRatesDataTable756[[#This Row],[asofdate]]),MONTH(OneWeekMtgRatesDataTable756[[#This Row],[asofdate]]),DAY(OneWeekMtgRatesDataTable756[[#This Row],[asofdate]])) -> 42310 | E10: Rate | F10: 0.19
B11: 1 Month LIBOR | C11: 2015-10-30 | D11: =DATE(YEAR(OneWeekMtgRatesDataTable756[[#This Row],[asofdate]]),MONTH(OneWeekMtgRatesDataTable756[[#This Row],[asofdate]]),DAY(OneWeekMtgRatesDataTable756[[#This Row],[asofdate]])) -> 42307 | E11: Rate | F11: 0.192
B12: 1 Month LIBOR | C12: 2015-10-29 | D12: =DATE(YEAR(OneWeekMtgRatesDataTable756[[#This Row],[asofdate]]),MONTH(OneWeekMtgRatesDataTable756[[#This Row],[asofdate]]),DAY(OneWeekMtgRatesDataTable756[[#This Row],[asofdate]])) -> 42306 | E12: Rate | F12: 0.193
B13: 1 Month LIBOR | C13: 2015-10-28 | D13: =DATE(YEAR(OneWeekMtgRatesDataTable756[[#This Row],[asofdate]]),MONTH(OneWeekMtgRatesDataTable756[[#This Row],[asofdate]]),DAY(OneWeekMtgRatesDataTable756[[#This Row],[asofdate]])) -> 42305 | E13: Rate | F13: 0.1883
B14: 1 Month LIBOR | C14: 2015-10-27 | D14: =DATE(YEAR(OneWeekMtgRatesDataTable756[[#This Row],[asofdate]]),MONTH(OneWeekMtgRatesDataTable756[[#This Row],[asofdate]]),DAY(OneWeekMtgRatesDataTable756[[#This Row],[asofdate]])) -> 42304 | E14: Rate | F14: 0.19075
... B1718: 1 Month LIBOR | C1718: 2009-01-02 | D1718: =DATE(YEAR(OneWeekMtgRatesDataTable756[[#This Row],[asofdate]]),MONTH(OneWeekMtgRatesDataTable756[[#This Row],[asofdate]]),DAY(OneWeekMtgRatesDataTable756[[#This Row],[asofdate]])) -> 39815 | E1718: Rate | F1718: 0.43

Sheet Refi%
W2: Bloomberg Refi Index | AA2: Loan Level Incentive
C3: asOfDate | D3: Pool Level | E3: Loan Level | F3: Refi Index | G3: LL_Incentve | J3: Last Week | K3: asOfDate | M3: Pool Level | N3: Loan Level | X3: MBAVCMRS | AA3: asOfDate | AB3: refinanceible | AC3: bps
C4: 40549 | D4: 0.6240217 | E4: 0.47799603 | F4: =VLOOKUP(C4+1,W:X,2,0) -> 2344.3 | G4: =VLOOKUP(C4,AA:AC,3,0) -> 90.117384 | H4: =MONTH(C4) -> 1 | I4: =IF(H4=H3,0,1) -> 1 | J4: =I5 -> 0 | W4: =_xll.BDH("MBAVCMRS Index","PX LAST","8/10/07",TODAY(),"cols=2;rows=402") -> #NAME? | X4: 2104.1 | AA4: 40549 | AB4: 0.90117384 | AC4: =AB4*100 -> 90.117384
C5: 40556 | D5: 0.62817294 | E5: 0.49650186 | F5: =VLOOKUP(C5+1,W:X,2,0) -> 2528.7 | G5: =VLOOKUP(C5,AA:AC,3,0) -> 95.957973 | H5: =MONTH(C5) -> 1 | I5: =IF(H5=H4,0,1) -> 0 | J5: =I6 -> 0 | W5: 39311 | X5: 1960.1 | AA5: 40556 | AB5: 0.95957973 | AC5: =AB5*100 -> 95.957973
C6: 40563 | D6: 0.62597731 | E6: 0.4802957 | F6: =VLOOKUP(C6+1,W:X,2,0) -> 2129.7 | G6: =VLOOKUP(C6,AA:AC,3,0) -> 93.037678 | H6: =MONTH(C6) -> 1 | I6: =IF(H6=H5,0,1) -> 0 | J6: =I7 -> 0 | W6: 39318 | X6: 1871.4 | AA6: 40563 | AB6: 0.93037678 | AC6: =AB6*100 -> 93.037678
C7: 40570 | D7: 0.62392159 | E7: 0.47679594 | F7: =VLOOKUP(C7+1,W:X,2,0) -> 2371.1 | G7: =VLOOKUP(C7,AA:AC,3,0) -> 89.630668 | H7: =MONTH(C7) -> 1 | I7: =IF(H7=H6,0,1) -> 0 | J7: =I8 -> 1 | K7: =IF(J7=1,EOMONTH(C7,0),"") -> 40574 | L7: =IF(WEEKDAY(K7,2)=6,K7-1,IF(WEEKDAY(K7,2)=7,K7-2,IF(J7=1,K7,""))) -> 40574 | M7: =IF(J7=1,D7,"") -> 0.62392159 | N7: =IF($J7=1,E7,"") -> 0.47679594 | O7: =IF($J7=1,F7,"") -> 2371.1 | P7: =IF($J7=1,G7,"") -> 89.630668 | W7: 39325 | X7: 1892.3 | AA7: 40570 | AB7: 0.89630668 | AC7: =AB7*100 -> 89.630668
C8: 40577 | D8: 0.60653142 | E8: 0.43462013 | F8: =VLOOKUP(C8+1,W:X,2,0) -> 2190.4 | G8: =VLOOKUP(C8,AA:AC,3,0) -> 80.302242 | H8: =MONTH(C8) -> 2 | I8: =IF(H8=H7,0,1) -> 1 | J8: =I9 -> 0 | K8: =IF(J8=1,EOMONTH(C8,0),"") | L8: =IF(WEEKDAY(K8,2)=6,K8-1,IF(WEEKDAY(K8,2)=7,K8-2,IF(J8=1,K8,""))) -> #VALUE! | M8: =IF(J8=1,D8,"") | N8: =IF($J8=1,E8,"") | O8: =IF($J8=1,F8,"") | P8: =IF($J8=1,G8,"") | W8: 39332 | X8: 2009.3 | AA8: 40577 | AB8: 0.80302242 | AC8: =AB8*100 -> 80.302242
C9: 40584 | D9: 0.50868798 | E9: 0.35529177 | F9: =VLOOKUP(C9+1,W:X,2,0) -> 1953.2 | G9: =VLOOKUP(C9,AA:AC,3,0) -> 59.492977 | H9: =MONTH(C9) -> 2 | I9: =IF(H9=H8,0,1) -> 0 | J9: =I10 -> 0 | K9: =IF(J9=1,EOMONTH(C9,0),"") | L9: =IF(WEEKDAY(K9,2)=6,K9-1,IF(WEEKDAY(K9,2)=7,K9-2,IF(J9=1,K9,""))) -> #VALUE! | M9: =IF(J9=1,D9,"") | N9: =IF($J9=1,E9,"") | O9: =IF($J9=1,F9,"") | P9: =IF($J9=1,G9,"") | W9: 39339 | X9: 2091.1 | AA9: 40584 | AB9: 0.59492977 | AC9: =AB9*100 -> 59.492977
C10: 40591 | D10: 0.52965902 | E10: 0.37678804 | F10: =VLOOKUP(C10+1,W:X,2,0) -> 2325.3 | G10: =VLOOKUP(C10,AA:AC,3,0) -> 64.332341 | H10: =MONTH(C10) -> 2 | I10: =IF(H10=H9,0,1) -> 0 | J10: =I11 -> 0 | K10: =IF(J10=1,EOMONTH(C10,0),"") | L10: =IF(WEEKDAY(K10,2)=6,K10-1,IF(WEEKDAY(K10,2)=7,K10-2,IF(J10=1,K10,""))) -> #VALUE! | M10: =IF(J10=1,D10,"") | N10: =IF($J10=1,E10,"") | O10: =IF($J10=1,F10,"") | P10: =IF($J10=1,G10,"") | W10: 39346 | X10: 2172.5 | AA10: 40591 | AB10: 0.64332341 | AC10: =AB10*100 -> 64.332341
C11: 40598 | D11: 0.57709504 | E11: 0.41551494 | F11: =VLOOKUP(C11+1,W:X,2,0) -> 2155.5 | G11: =VLOOKUP(C11,AA:AC,3,0) -> 71.591388 | H11: =MONTH(C11) -> 2 | I11: =IF(H11=H10,0,1) -> 0 | J11: =I12 -> 1 | K11: =IF(J11=1,EOMONTH(C11,0),"") -> 40602 | L11: =IF(WEEKDAY(K11,2)=6,K11-1,IF(WEEKDAY(K11,2)=7,K11-2,IF(J11=1,K11,""))) -> 40602 | M11: =IF(J11=1,D11,"") -> 0.57709504 | N11: =IF($J11=1,E11,"") -> 0.41551494 | O11: =IF($J11=1,F11,"") -> 2155.5 | P11: =IF($J11=1,G11,"") -> 71.591388 | W11: 39353 | X11: 2065.7 | AA11: 40598 | AB11: 0.71591388 | AC11: =AB11*100 -> 71.591388
C12: 40605 | D12: 0.59224776 | E12: 0.42215163 | F12: =VLOOKUP(C12+1,W:X,2,0) -> 2539.4 | G12: =VLOOKUP(C12,AA:AC,3,0) -> 72.287304 | H12: =MONTH(C12) -> 3 | I12: =IF(H12=H11,0,1) -> 1 | J12: =I13 -> 0 | K12: =IF(J12=1,EOMONTH(C12,0),"") | L12: =IF(WEEKDAY(K12,2)=6,K12-1,IF(WEEKDAY(K12,2)=7,K12-2,IF(J12=1,K12,""))) -> #VALUE! | M12: =IF(J12=1,D12,"") | N12: =IF($J12=1,E12,"") | O12: =IF($J12=1,F12,"") | P12: =IF($J12=1,G12,"") | W12: 39360 | X12: 2153.3 | AA12: 40605 | AB12: 0.72287304 | AC12: =AB12*100 -> 72.287304
C13: 40612 | D13: 0.59090571 | E13: 0.42124986 | F13: =VLOOKUP(C13+1,W:X,2,0) -> 2563.6 | G13: =VLOOKUP(C13,AA:AC,3,0) -> 71.325538 | H13: =MONTH(C13) -> 3 | I13: =IF(H13=H12,0,1) -> 0 | J13: =I14 -> 0 | K13: =IF(J13=1,EOMONTH(C13,0),"") | L13: =IF(WEEKDAY(K13,2)=6,K13-1,IF(WEEKDAY(K13,2)=7,K13-2,IF(J13=1,K13,""))) -> #VALUE! | M13: =IF(J13=1,D13,"") | N13: =IF($J13=1,E13,"") | O13: =IF($J13=1,F13,"") | P13: =IF($J13=1,G13,"") | W13: 39367 | X13: 2116.6 | AA13: 40612 | AB13: 0.71325538 | AC13: =AB13*100 -> 71.325538
C14: 40619 | D14: 0.60261779 | E14: 0.46784663 | F14: =VLOOKUP(C14+1,W:X,2,0) -> 2620.8 | G14: =VLOOKUP(C14,AA:AC,3,0) -> 82.866728 | H14: =MONTH(C14) -> 3 | I14: =IF(H14=H13,0,1) -> 0 | J14: =I15 -> 0 | K14: =IF(J14=1,EOMONTH(C14,0),"") | L14: =IF(WEEKDAY(K14,2)=6,K14-1,IF(WEEKDAY(K14,2)=7,K14-2,IF(J14=1,K14,""))) -> #VALUE! | M14: =IF(J14=1,D14,"") | N14: =IF($J14=1,E14,"") | O14: =IF($J14=1,F14,"") | P14: =IF($J14=1,G14,"") | W14: 39374 | X14: 2221.1 | AA14: 40619 | AB14: 0.82866728 | AC14: =AB14*100 -> 82.866728
C15: 40626 | D15: 0.59950596 | E15: 0.4501581 | F15: =VLOOKUP(C15+1,W:X,2,0) -> 2350.7 | G15: =VLOOKUP(C15,AA:AC,3,0) -> 78.057899 | H15: =MONTH(C15) -> 3 | I15: =IF(H15=H14,0,1) -> 0 | J15: =I16 -> 0 | K15: =IF(J15=1,EOMONTH(C15,0),"") | L15: =IF(WEEKDAY(K15,2)=6,K15-1,IF(WEEKDAY(K15,2)=7,K15-2,IF(J15=1,K15,""))) -> #VALUE! | M15: =IF(J15=1,D15,"") | N15: =IF($J15=1,E15,"") | O15: =IF($J15=1,F15,"") | P15: =IF($J15=1,G15,"") | W15: 39381 | X15: 2433.2 | AA15: 40626 | AB15: 0.78057899 | AC15: =AB15*100 -> 78.057899
C16: 40633 | D16: 0.59322571 | E16: 0.42282959 | F16: =VLOOKUP(C16+1,W:X,2,0) -> 2194.4 | G16: =VLOOKUP(C16,AA:AC,3,0) -> 73.24907 | H16: =MONTH(C16) -> 3 | I16: =IF(H16=H15,0,1) -> 0 | J16: =I17 -> 1 | K16: =IF(J16=1,EOMONTH(C16,0),"") -> 40633 | L16: =IF(WEEKDAY(K16,2)=6,K16-1,IF(WEEKDAY(K16,2)=7,K16-2,IF(J16=1,K16,""))) -> 40633 | M16: =IF(J16=1,D16,"") -> 0.59322571 | N16: =IF($J16=1,E16,"") -> 0.42282959 | O16: =IF($J16=1,F16,"") -> 2194.4 | P16: =IF($J16=1,G16,"") -> 73.24907 | W16: 39388 | X16: 2336.2 | AA16: 40633 | AB16: 0.7324907 | AC16: =AB16*100 -> 73.24907
C17: 40640 | D17: 0.58542145 | E17: 0.41477854 | F17: =VLOOKUP(C17+1,W:X,2,0) -> 2010.6 | G17: =VLOOKUP(C17,AA:AC,3,0) -> 71.425856 | H17: =MONTH(C17) -> 4 | I17: =IF(H17=H16,0,1) -> 1 | J17: =I18 -> 0 | K17: =IF(J17=1,EOMONTH(C17,0),"") | L17: =IF(WEEKDAY(K17,2)=6,K17-1,IF(WEEKDAY(K17,2)=7,K17-2,IF(J17=1,K17,""))) -> #VALUE! | M17: =IF(J17=1,D17,"") | N17: =IF($J17=1,E17,"") | O17: =IF($J17=1,F17,"") | P17: =IF($J17=1,G17,"") | W17: 39395 | X17: 2503.6 | AA17: 40640 | AB17: 0.71425856 | AC17: =AB17*100 -> 71.425856
C18: 40647 | D18: 0.58155199 | E18: 0.41340612 | F18: =VLOOKUP(C18+1,W:X,2,0) -> 2065.3 | G18: =VLOOKUP(C18,AA:AC,3,0) -> 69.979165 | H18: =MONTH(C18) -> 4 | I18: =IF(H18=H17,0,1) -> 0 | J18: =I19 -> 0 | K18: =IF(J18=1,EOMONTH(C18,0),"") | L18: =IF(WEEKDAY(K18,2)=6,K18-1,IF(WEEKDAY(K18,2)=7,K18-2,IF(J18=1,K18,""))) -> #VALUE! | M18: =IF(J18=1,D18,"") | N18: =IF($J18=1,E18,"") | O18: =IF($J18=1,F18,"") | P18: =IF($J18=1,G18,"") | W18: 39402 | X18: 2371.1 | AA18: 40647 | AB18: 0.69979165 | AC18: =AB18*100 -> 69.979165
... C49: 40864 | D49: 0.93485324 | E49: 0.8071978 | F49: =VLOOKUP(C49+1,W:X,2,0) -> 3466.8 | G49: =VLOOKUP(C49,AA:AC,3,0) -> 144.85245 | H49: =MONTH(C49) -> 11 | I49: =IF(H49=H48,0,1) -> 0 | J49: =I50 -> 0 | K49: =IF(J49=1,EOMONTH(C49,0),"") | L49: =IF(WEEKDAY(K49,2)=6,K49-1,IF(WEEKDAY(K49,2)=7,K49-2,IF(J49=1,K49,""))) -> #VALUE! | M49: =IF(J49=1,D49,"") | N49: =IF($J49=1,E49,"") | O49: =IF($J49=1,F49,"") | P49: =IF($J49=1,G49,"") | W49: 39619 | X49: 1044.6 | AA49: 40864 | AB49: 1.4485245 | AC49: =AB49*100 -> 144.85245
C50: 40870 | D50: 0.94997171 | E50: 0.80850149 | F50: =VLOOKUP(C50+2,W:X,2,0) -> 2941.3 | G50: =VLOOKUP(C50,AA:AC,3,0) -> 146.78788 | H50: =MONTH(C50) -> 11 | I50: =IF(H50=H49,0,1) -> 0 | J50: =I51 -> 1 | K50: =IF(J50=1,EOMONTH(C50,0),"") -> 40877 | L50: =IF(WEEKDAY(K50,2)=6,K50-1,IF(WEEKDAY(K50,2)=7,K50-2,IF(J50=1,K50,""))) -> 40877 | M50: =IF(J50=1,D50,"") -> 0.94997171 | N50: =IF($J50=1,E50,"") -> 0.80850149 | O50: =IF($J50=1,F50,"") -> 2941.3 | P50: =IF($J50=1,G50,"") -> 146.78788 | W50: 39626 | X50: 1111.3 | AA50: 40870 | AB50: 1.4678788 | AC50: =AB50*100 -> 146.78788
C51: 40878 | D51: 0.91542629 | E51: 0.79441105 | F51: =VLOOKUP(C51+1,W:X,2,0) -> 3394.7 | G51: =VLOOKUP(C51,AA:AC,3,0) -> 142.18347 | H51: =MONTH(C51) -> 12 | I51: =IF(H51=H50,0,1) -> 1 | J51: =I52 -> 0 | K51: =IF(J51=1,EOMONTH(C51,0),"") | L51: =IF(WEEKDAY(K51,2)=6,K51-1,IF(WEEKDAY(K51,2)=7,K51-2,IF(J51=1,K51,""))) -> #VALUE! | M51: =IF(J51=1,D51,"") | N51: =IF($J51=1,E51,"") | O51: =IF($J51=1,F51,"") | P51: =IF($J51=1,G51,"") | W51: 39633 | X51: 1166.5 | AA51: 40878 | AB51: 1.4218347 | AC51: =AB51*100 -> 142.18347
C52: 40885 | D52: 0.92487461 | E52: 0.79445841 | F52: =VLOOKUP(C52+1,W:X,2,0) -> 3708.6 | G52: =VLOOKUP(C52,AA:AC,3,0) -> 143.1491 | H52: =MONTH(C52) -> 12 | I52: =IF(H52=H51,0,1) -> 0 | J52: =I53 -> 0 | K52: =IF(J52=1,EOMONTH(C52,0),"") | L52: =IF(WEEKDAY(K52,2)=6,K52-1,IF(WEEKDAY(K52,2)=7,K52-2,IF(J52=1,K52,""))) -> #VALUE! | M52: =IF(J52=1,D52,"") | N52: =IF($J52=1,E52,"") | O52: =IF($J52=1,F52,"") | P52: =IF($J52=1,G52,"") | W52: 39640 | X52: 1270.6 | AA52: 40885 | AB52: 1.431491 | AC52: =AB52*100 -> 143.1491
C53: 40892 | D53: 0.93969161 | E53: 0.79646175 | F53: =VLOOKUP(C53+1,W:X,2,0) -> 3676.1 | G53: =VLOOKUP(C53,AA:AC,3,0) -> 145.56319 | H53: =MONTH(C53) -> 12 | I53: =IF(H53=H52,0,1) -> 0 | J53: =I54 -> 0 | K53: =IF(J53=1,EOMONTH(C53,0),"") | L53: =IF(WEEKDAY(K53,2)=6,K53-1,IF(WEEKDAY(K53,2)=7,K53-2,IF(J53=1,K53,""))) -> #VALUE! | M53: =IF(J53=1,D53,"") | N53: =IF($J53=1,E53,"") | O53: =IF($J53=1,F53,"") | P53: =IF($J53=1,G53,"") | W53: 39647 | X53: 1213.9 | AA53: 40892 | AB53: 1.4556319 | AC53: =AB53*100 -> 145.56319
C54: 40899 | D54: 0.96019587 | E54: 0.8253704 | F54: =VLOOKUP(C54+1,W:X,2,0) -> 3684.5 | G54: =VLOOKUP(C54,AA:AC,3,0) -> 150.87417 | H54: =MONTH(C54) -> 12 | I54: =IF(H54=H53,0,1) -> 0 | J54: =I55 -> 0 | K54: =IF(J54=1,EOMONTH(C54,0),"") | L54: =IF(WEEKDAY(K54,2)=6,K54-1,IF(WEEKDAY(K54,2)=7,K54-2,IF(J54=1,K54,""))) -> #VALUE! | M54: =IF(J54=1,D54,"") | N54: =IF($J54=1,E54,"") | O54: =IF($J54=1,F54,"") | P54: =IF($J54=1,G54,"") | W54: 39654 | X54: 874.1 | AA54: 40899 | AB54: 1.5087417 | AC54: =AB54*100 -> 150.87417
C55: 40906 | D55: 0.9476226 | E55: 0.81734633 | F55: =VLOOKUP(C55+1,W:X,2,0) -> 3608.1 | G55: =VLOOKUP(C55,AA:AC,3,0) -> 147.01164 | H55: =MONTH(C55) -> 12 | I55: =IF(H55=H54,0,1) -> 0 | J55: =I56 -> 1 | K55: =IF(J55=1,EOMONTH(C55,0),"") -> 40908 | L55: =IF(WEEKDAY(K55,2)=6,K55-1,IF(WEEKDAY(K55,2)=7,K55-2,IF(J55=1,K55,""))) -> 40907 | M55: =IF(J55=1,D55,"") -> 0.9476226 | N55: =IF($J55=1,E55,"") -> 0.81734633 | O55: =IF($J55=1,F55,"") -> 3608.1 | P55: =IF($J55=1,G55,"") -> 147.01164 | W55: 39661 | X55: 897.7 | AA55: 40906 | AB55: 1.4701164 | AC55: =AB55*100 -> 147.01164
C56: 40913 | D56: 0.94481774 | E56: 0.80629912 | F56: =VLOOKUP(C56+1,W:X,2,0) -> 3668.3 | G56: =VLOOKUP(C56,AA:AC,3,0) -> 145.54458 | H56: =MONTH(C56) -> 1 | I56: =IF(H56=H55,0,1) -> 1 | J56: =I57 -> 0 | K56: =IF(J56=1,EOMONTH(C56,0),"") | L56: =IF(WEEKDAY(K56,2)=6,K56-1,IF(WEEKDAY(K56,2)=7,K56-2,IF(J56=1,K56,""))) -> #VALUE! | M56: =IF(J56=1,D56,"") | N56: =IF($J56=1,E56,"") | O56: =IF($J56=1,F56,"") | P56: =IF($J56=1,G56,"") | W56: 39668 | X56: 853.1 | AA56: 40913 | AB56: 1.4554458 | AC56: =AB56*100 -> 145.54458
C57: 40920 | D57: 0.95320352 | E57: 0.81626219 | F57: =VLOOKUP(C57+1,W:X,2,0) -> 4626.5 | G57: =VLOOKUP(C57,AA:AC,3,0) -> 149.88559 | H57: =MONTH(C57) -> 1 | I57: =IF(H57=H56,0,1) -> 0 | J57: =I58 -> 0 | K57: =IF(J57=1,EOMONTH(C57,0),"") | L57: =IF(WEEKDAY(K57,2)=6,K57-1,IF(WEEKDAY(K57,2)=7,K57-2,IF(J57=1,K57,""))) -> #VALUE! | M57: =IF(J57=1,D57,"") | N57: =IF($J57=1,E57,"") | O57: =IF($J57=1,F57,"") | P57: =IF($J57=1,G57,"") | W57: 39675 | X57: 815.2 | AA57: 40920 | AB57: 1.4988559 | AC57: =AB57*100 -> 149.88559
C58: 40927 | D58: 0.95182772 | E58: 0.81461585 | F58: =VLOOKUP(C58+1,W:X,2,0) -> 4326.4 | G58: =VLOOKUP(C58,AA:AC,3,0) -> 148.43859 | H58: =MONTH(C58) -> 1 | I58: =IF(H58=H57,0,1) -> 0 | J58: =I59 -> 0 | K58: =IF(J58=1,EOMONTH(C58,0),"") | L58: =IF(WEEKDAY(K58,2)=6,K58-1,IF(WEEKDAY(K58,2)=7,K58-2,IF(J58=1,K58,""))) -> #VALUE! | M58: =IF(J58=1,D58,"") | N58: =IF($J58=1,E58,"") | O58: =IF($J58=1,F58,"") | P58: =IF($J58=1,G58,"") | W58: 39682 | X58: 793.9 | AA58: 40927 | AB58: 1.4843859 | AC58: =AB58*100 -> 148.43859
C59: 40934 | D59: 0.91861521 | E59: 0.78339394 | F59: =VLOOKUP(C59+1,W:X,2,0) -> 4184.3 | G59: =VLOOKUP(C59,AA:AC,3,0) -> 141.20356 | H59: =MONTH(C59) -> 1 | I59: =IF(H59=H58,0,1) -> 0 | J59: =I60 -> 1 | K59: =IF(J59=1,EOMONTH(C59,0),"") -> 40939 | L59: =IF(WEEKDAY(K59,2)=6,K59-1,IF(WEEKDAY(K59,2)=7,K59-2,IF(J59=1,K59,""))) -> 40939 | M59: =IF(J59=1,D59,"") -> 0.91861521 | N59: =IF($J59=1,E59,"") -> 0.78339394 | O59: =IF($J59=1,F59,"") -> 4184.3 | P59: =IF($J59=1,G59,"") -> 141.20356 | W59: 39689 | X59: 825 | AA59: 40934 | AB59: 1.4120356 | AC59: =AB59*100 -> 141.20356
C60: 40941 | D60: 0.94107838 | E60: 0.79842548 | F60: =VLOOKUP(C60+1,W:X,2,0) -> 4617.1 | G60: =VLOOKUP(C60,AA:AC,3,0) -> 145.72263 | H60: =MONTH(C60) -> 2 | I60: =IF(H60=H59,0,1) -> 1 | J60: =I61 -> 0 | K60: =IF(J60=1,EOMONTH(C60,0),"") | L60: =IF(WEEKDAY(K60,2)=6,K60-1,IF(WEEKDAY(K60,2)=7,K60-2,IF(J60=1,K60,""))) -> #VALUE! | M60: =IF(J60=1,D60,"") | N60: =IF($J60=1,E60,"") | O60: =IF($J60=1,F60,"") | P60: =IF($J60=1,G60,"") | W60: 39696 | X60: 998.3 | AA60: 40941 | AB60: 1.4572263 | AC60: =AB60*100 -> 145.72263
C61: 40948 | D61: 0.94107838 | E61: 0.79842548 | F61: =VLOOKUP(C61+1,W:X,2,0) -> 4716.1 | G61: =VLOOKUP(C61,AA:AC,3,0) -> 145.72263 | H61: =MONTH(C61) -> 2 | I61: =IF(H61=H60,0,1) -> 0 | J61: =I62 -> 0 | K61: =IF(J61=1,EOMONTH(C61,0),"") | L61: =IF(WEEKDAY(K61,2)=6,K61-1,IF(WEEKDAY(K61,2)=7,K61-2,IF(J61=1,K61,""))) -> #VALUE! | M61: =IF(J61=1,D61,"") | N61: =IF($J61=1,E61,"") | O61: =IF($J61=1,F61,"") | P61: =IF($J61=1,G61,"") | W61: 39703 | X61: 2068.5 | AA61: 40948 | AB61: 1.4572263 | AC61: =AB61*100 -> 145.72263
C62: 40955 | D62: 0.94107838 | E62: 0.79842548 | F62: =VLOOKUP(C62+1,W:X,2,0) -> 4466.9 | G62: =VLOOKUP(C62,AA:AC,3,0) -> 145.72263 | H62: =MONTH(C62) -> 2 | I62: =IF(H62=H61,0,1) -> 0 | J62: =I63 -> 0 | K62: =IF(J62=1,EOMONTH(C62,0),"") | L62: =IF(WEEKDAY(K62,2)=6,K62-1,IF(WEEKDAY(K62,2)=7,K62-2,IF(J62=1,K62,""))) -> #VALUE! | M62: =IF(J62=1,D62,"") | N62: =IF($J62=1,E62,"") | O62: =IF($J62=1,F62,"") | P62: =IF($J62=1,G62,"") | W62: 39710 | X62: 1756.8 | AA62: 40955 | AB62: 1.4572263 | AC62: =AB62*100 -> 145.72263
... C119: 41354 | D119: 0.76832709 | E119: 0.72870486 | F119: =VLOOKUP(C119+1,W:X,2,0) -> 4412.9 | G119: =VLOOKUP(C119,AA:AC,3,0) -> 134.85819 | H119: =MONTH(C119) -> 3 | I119: =IF(H119=H118,0,1) -> 0 | J119: =I120 -> 0 | K119: =IF(J119=1,EOMONTH(C119,0),"") | L119: =IF(WEEKDAY(K119,2)=6,K119-1,IF(WEEKDAY(K119,2)=7,K119-2,IF(J119=1,K119,""))) -> #VALUE! | M119: =IF(J119=1,D119,"") | N119: =IF($J119=1,E119,"") | O119: =IF($J119=1,F119,"") | P119: =IF($J119=1,G119,"") | W119: 40109 | X119: 2304 | AA119: 41354 | AB119: 1.3485819 | AC119: =AB119*100 -> 134.85819
C120: 41361 | D120: 0.73085022 | E120: 0.71206287 | F120: =VLOOKUP(C120+1,W:X,2,0) -> 4119.2 | G120: =VLOOKUP(C120,AA:AC,3,0) -> 131.92348 | H120: =MONTH(C120) -> 3 | I120: =IF(H120=H119,0,1) -> 0 | J120: =I121 -> 1 | K120: =IF(J120=1,EOMONTH(C120,0),"") -> 41364 | L120: =IF(WEEKDAY(K120,2)=6,K120-1,IF(WEEKDAY(K120,2)=7,K120-2,IF(J120=1,K120,"")))-1 -> 41361 | M120: =IF(J120=1,D120,"") -> 0.73085022 | N120: =IF($J120=1,E120,"") -> 0.71206287 | O120: =IF($J120=1,F120,"") -> 4119.2 | P120: =IF($J120=1,G120,"") -> 131.92348 | W120: 40116 | X120: 2715.2 | AA120: 41361 | AB120: 1.3192348 | AC120: =AB120*100 -> 131.92348
