Workbook
Name temp: 'ppm risk premium'!#REF!
Name temp: 'Refi%'!$AA$3:$AB$236
Name temp_1: 'ppm risk premium'!#REF!
Name temp_2: 'ppm risk premium'!#REF!
Name temp1: 'LIBOR 1m'!#REF!

Sheet Data Set
B3: IOS Index
B4: Date | C4: Monthly Hedge Return (%) | D4: OAS | E4: IOS + TBA Carry | F4: Realized Vol (Annualized %) | G4: Yield Curve 10-2 (bps) | H4: Prepayment Risk Premium (bps) | I4: Px/Coupon | J4: LIBOR 1m | K4: Refi Pct Pool | L4: Refi Pct Loan | M4: Refi Index | N4: CC | O4: CC Changes (bps) | P4: IOS + TBA + Curve Monthly Return
B5: 40633 | C5: ='Return&Carry'!C3*100 -> 3.2147753 | D5: 12.454245 | E5: ='Return&Carry'!D3*100 -> 1.0991114 | F5: =VLOOKUP(TEXT(B5,"yyyy-mm-dd"),OneWeekMtgRatesDataTable7[],4,0)*SQRT(225)*100 -> 74.358832 | G5: =VLOOKUP(B5,'Yield Curve'!B5:G52,6,0)*100 -> 266.4 | H5: =VLOOKUP(B5,'ppm risk premium'!C:J,8,0)*100 -> 75.537102 | I5: 5.4040031 | J5: =VLOOKUP(B5,'LIBOR 1m'!D:F,3,0) -> 0.24345 | K5: =VLOOKUP(B5,'Refi%'!AE:AF,2,0) -> 0.59330693 | L5: =VLOOKUP(B5,'Refi%'!AH:AI,2,0) -> 0.42787865 | M5: =VLOOKUP(B5,'Refi%'!L:P,4,0) -> 2194.4 | N5: =VLOOKUP(B5,'Realized Vol'!H:J,2,0) -> 4.2632122 | O5: =VLOOKUP(B5,'Realized Vol'!H:J,3,0) -> 0
B6: 40662 | C6: ='Return&Carry'!C4*100 -> 3.9945301 | D6: -13.523942 | E6: ='Return&Carry'!D4*100 -> 1.0984369 | F6: =VLOOKUP(TEXT(B6,"yyyy-mm-dd"),OneWeekMtgRatesDataTable7[],4,0)*SQRT(225)*100 -> 60.151042 | G6: =VLOOKUP(B6,'Yield Curve'!B6:G53,6,0)*100 -> 268.7 | H6: =VLOOKUP(B6,'ppm risk premium'!C:J,8,0)*100 -> 90.935152 | I6: 5.4712823 | J6: =VLOOKUP(B6,'LIBOR 1m'!D:F,3,0) -> 0.21025 | K6: =VLOOKUP(B6,'Refi%'!AE:AF,2,0) -> 0.60214742 | L6: =VLOOKUP(B6,'Refi%'!AH:AI,2,0) -> 0.46921692 | M6: =VLOOKUP(B6,'Refi%'!L:P,4,0) -> 2220.1 | N6: =VLOOKUP(B6,'Realized Vol'!H:J,2,0) -> 4.0911415 | O6: =VLOOKUP(B6,'Realized Vol'!H:J,3,0) -> -17.207069
B7: 40694 | C7: ='Return&Carry'!C5*100 -> 3.6836949 | D7: -39.195911 | E7: ='Return&Carry'!D5*100 -> 1.2359979 | F7: =VLOOKUP(TEXT(B7,"yyyy-mm-dd"),OneWeekMtgRatesDataTable7[],4,0)*SQRT(225)*100 -> 48.820059 | G7: =VLOOKUP(B7,'Yield Curve'!B7:G54,6,0)*100 -> 258.5 | H7: =VLOOKUP(B7,'ppm risk premium'!C:J,8,0)*100 -> 105.18016 | I7: 5.4954374 | J7: =VLOOKUP(B7,'LIBOR 1m'!D:F,3,0) -> 0.19043 | K7: =VLOOKUP(B7,'Refi%'!AE:AF,2,0) -> 0.64966367 | L7: =VLOOKUP(B7,'Refi%'!AH:AI,2,0) -> 0.52390304 | M7: =VLOOKUP(B7,'Refi%'!L:P,4,0) -> 2619.7 | N7: =VLOOKUP(B7,'Realized Vol'!H:J,2,0) -> 3.9323543 | O7: =VLOOKUP(B7,'Realized Vol'!H:J,3,0) -> -15.878724
B8: 40724 | C8: ='Return&Carry'!C6*100 -> -0.89725231 | D8: -71.812763 | E8: ='Return&Carry'!D6*100 -> 1.1611305 | F8: =VLOOKUP(TEXT(B8,"yyyy-mm-dd"),OneWeekMtgRatesDataTable7[],4,0)*SQRT(225)*100 -> 51.642384 | G8: =VLOOKUP(B8,'Yield Curve'!B8:G55,6,0)*100 -> 270 | H8: =VLOOKUP(B8,'ppm risk premium'!C:J,8,0)*100 -> 95.512376 | I8: 5.5415672 | J8: =VLOOKUP(B8,'LIBOR 1m'!D:F,3,0) -> 0.18555 | K8: =VLOOKUP(B8,'Refi%'!AE:AF,2,0) -> 0.60136348 | L8: =VLOOKUP(B8,'Refi%'!AH:AI,2,0) -> 0.50471571 | M8: =VLOOKUP(B8,'Refi%'!L:P,4,0) -> 2527.5 | N8: =VLOOKUP(B8,'Realized Vol'!H:J,2,0) -> 4.0210178 | O8: =VLOOKUP(B8,'Realized Vol'!H:J,3,0) -> 8.8663527
B9: 40753 | C9: ='Return&Carry'!C7*100 -> -0.70542452 | D9: 14.555567 | E9: ='Return&Carry'!D7*100 -> 0.94859999 | F9: =VLOOKUP(TEXT(B9,"yyyy-mm-dd"),OneWeekMtgRatesDataTable7[],4,0)*SQRT(225)*100 -> 60.008169 | G9: =VLOOKUP(B9,'Yield Curve'!B9:G56,6,0)*100 -> 243.9 | H9: =VLOOKUP(B9,'ppm risk premium'!C:J,8,0)*100 -> 113.62597 | I9: 5.2080149 | J9: =VLOOKUP(B9,'LIBOR 1m'!D:F,3,0) -> 0.1911 | K9: =VLOOKUP(B9,'Refi%'!AE:AF,2,0) -> 0.81158019 | L9: =VLOOKUP(B9,'Refi%'!AH:AI,2,0) -> 0.5882383 | M9: =VLOOKUP(B9,'Refi%'!L:P,4,0) -> 2974.1 | N9: =VLOOKUP(B9,'Realized Vol'!H:J,2,0) -> 3.8088239 | O9: =VLOOKUP(B9,'Realized Vol'!H:J,3,0) -> -21.219393
B10: 40786 | C10: ='Return&Carry'!C8*100 -> -12.940149 | D10: 413.13076 | E10: ='Return&Carry'!D8*100 -> 0.98897456 | F10: =VLOOKUP(TEXT(B10,"yyyy-mm-dd"),OneWeekMtgRatesDataTable7[],4,0)*SQRT(225)*100 -> 99.218155 | G10: =VLOOKUP(B10,'Yield Curve'!B10:G57,6,0)*100 -> 202.2 | H10: =VLOOKUP(B10,'ppm risk premium'!C:J,8,0)*100 -> 130.72057 | I10: 4.1199718 | J10: =VLOOKUP(B10,'LIBOR 1m'!D:F,3,0) -> 0.2215 | K10: =VLOOKUP(B10,'Refi%'!AE:AF,2,0) -> 0.84239131 | L10: =VLOOKUP(B10,'Refi%'!AH:AI,2,0) -> 0.71579101 | M10: =VLOOKUP(B10,'Refi%'!L:P,4,0) -> 3601.3 | N10: =VLOOKUP(B10,'Realized Vol'!H:J,2,0) -> 3.4273948 | O10: =VLOOKUP(B10,'Realized Vol'!H:J,3,0) -> -38.142906
B11: 40816 | C11: ='Return&Carry'!C9*100 -> -10.646399 | D11: 707.36595 | E11: ='Return&Carry'!D9*100 -> 1.4023414 | F11: =VLOOKUP(TEXT(B11,"yyyy-mm-dd"),OneWeekMtgRatesDataTable7[],4,0)*SQRT(225)*100 -> 121.17161 | G11: =VLOOKUP(B11,'Yield Curve'!B11:G58,6,0)*100 -> 167.3 | H11: =VLOOKUP(B11,'ppm risk premium'!C:J,8,0)*100 -> 154.82914 | I11: 3.3173716 | J11: =VLOOKUP(B11,'LIBOR 1m'!D:F,3,0) -> 0.23944 | K11: =VLOOKUP(B11,'Refi%'!AE:AF,2,0) -> 0.95732166 | L11: =VLOOKUP(B11,'Refi%'!AH:AI,2,0) -> 0.81810634 | M11: =VLOOKUP(B11,'Refi%'!L:P,4,0) -> 4241.8 | N11: =VLOOKUP(B11,'Realized Vol'!H:J,2,0) -> 3.0385262 | O11: =VLOOKUP(B11,'Realized Vol'!H:J,3,0) -> -38.886865
B12: 40847 | C12: ='Return&Carry'!C10*100 -> 2.3593585 | D12: 688.11427 | E12: ='Return&Carry'!D10*100 -> 1.2905992 | F12: =VLOOKUP(TEXT(B12,"yyyy-mm-dd"),OneWeekMtgRatesDataTable7[],4,0)*SQRT(225)*100 -> 126.4888 | G12: =VLOOKUP(B12,'Yield Curve'!B12:G59,6,0)*100 -> 190.8 | H12: =VLOOKUP(B12,'ppm risk premium'!C:J,8,0)*100 -> 147.63692 | I12: 3.4720778 | J12: =VLOOKUP(B12,'LIBOR 1m'!D:F,3,0) -> 0.24528 | K12: =VLOOKUP(B12,'Refi%'!AE:AF,2,0) -> 0.91081164 | L12: =VLOOKUP(B12,'Refi%'!AH:AI,2,0) -> 0.78009743 | M12: =VLOOKUP(B12,'Refi%'!L:P,4,0) -> 3695 | N12: =VLOOKUP(B12,'Realized Vol'!H:J,2,0) -> 3.251577 | O12: =VLOOKUP(B12,'Realized Vol'!H:J,3,0) -> 21.305085
B13: 40877 | C13: ='Return&Carry'!C11*100 -> 1.4407939 | D13: 623.10169 | E13: ='Return&Carry'!D11*100 -> 0.70135917 | F13: =VLOOKUP(TEXT(B13,"yyyy-mm-dd"),OneWeekMtgRatesDataTable7[],4,0)*SQRT(225)*100 -> 107.84839 | G13: =VLOOKUP(B13,'Yield Curve'!B13:G60,6,0)*100 -> 180.9 | H13: =VLOOKUP(B13,'ppm risk premium'!C:J,8,0)*100 -> 152.67358 | I13: 3.4446943 | J13: =VLOOKUP(B13,'LIBOR 1m'!D:F,3,0) -> 0.27144 | K13: =VLOOKUP(B13,'Refi%'!AE:AF,2,0) -> 0.94713699 | L13: =VLOOKUP(B13,'Refi%'!AH:AI,2,0) -> 0.79059241 | M13: =VLOOKUP(B13,'Refi%'!L:P,4,0) -> 2941.3 | N13: =VLOOKUP(B13,'Realized Vol'!H:J,2,0) -> 3.1770193 | O13: =VLOOKUP(B13,'Realized Vol'!H:J,3,0) -> -7.4557679
B14: 40907 | C14: ='Return&Carry'!C12*100 -> 0.5832688 | D14: 610.59818 | E14: ='Return&Carry'!D12*100 -> 0.39545841 | F14: =VLOOKUP(TEXT(B14,"yyyy-mm-dd"),OneWeekMtgRatesDataTable7[],4,0)*SQRT(225)*100 -> 84.15733 | G14: =VLOOKUP(B14,'Yield Curve'!B14:G61,6,0)*100 -> 162.9 | H14: =VLOOKUP(B14,'ppm risk premium'!C:J,8,0)*100 -> 163.19337 | I14: 3.3659589 | J14: =VLOOKUP(B14,'LIBOR 1m'!D:F,3,0) -> 0.2953 | K14: =VLOOKUP(B14,'Refi%'!AE:AF,2,0) -> 0.96357256 | L14: =VLOOKUP(B14,'Refi%'!AH:AI,2,0) -> 0.83026537 | M14: =VLOOKUP(B14,'Refi%'!L:P,4,0) -> 3608.1 | N14: =VLOOKUP(B14,'Realized Vol'!H:J,2,0) -> 3.0169009 | O14: =VLOOKUP(B14,'Realized Vol'!H:J,3,0) -> -16.011846
B15: 40939 | C15: ='Return&Carry'!C13*100 -> -3.0247515 | D15: 465.33199 | E15: ='Return&Carry'!D13*100 -> 0.93155585 | F15: =VLOOKUP(TEXT(B15,"yyyy-mm-dd"),OneWeekMtgRatesDataTable7[],4,0)*SQRT(225)*100 -> 67.218531 | G15: =VLOOKUP(B15,'Yield Curve'!B15:G62,6,0)*100 -> 158.4 | H15: =VLOOKUP(B15,'ppm risk premium'!C:J,8,0)*100 -> 165.8527 | I15: 3.0653812 | J15: =VLOOKUP(B15,'LIBOR 1m'!D:F,3,0) -> 0.26475 | K15: =VLOOKUP(B15,'Refi%'!AE:AF,2,0) -> 0.95587728 | L15: =VLOOKUP(B15,'Refi%'!AH:AI,2,0) -> 0.8394901 | M15: =VLOOKUP(B15,'Refi%'!L:P,4,0) -> 4184.3 | N15: =VLOOKUP(B15,'Realized Vol'!H:J,2,0) -> 2.7762953 | O15: =VLOOKUP(B15,'Realized Vol'!H:J,3,0) -> -24.060559
B16: 40968 | C16: ='Return&Carry'!C14*100 -> 11.557044 | D16: 220.00245 | E16: ='Return&Carry'!D14*100 -> 1.7106233 | F16: =VLOOKUP(TEXT(B16,"yyyy-mm-dd"),OneWeekMtgRatesDataTable7[],4,0)*SQRT(225)*100 -> 70.470813 | G16: =VLOOKUP(B16,'Yield Curve'!B16:G64,6,0)*100 -> 167.8 | H16: =VLOOKUP(B16,'ppm risk premium'!C:J,8,0)*100 -> 146.65326 | I16: 3.4491554 | J16: =VLOOKUP(B16,'LIBOR 1m'!D:F,3,0) -> 0.2435 | K16: =VLOOKUP(B16,'Refi%'!AE:AF,2,0) -> 0.91287036 | L16: =VLOOKUP(B16,'Refi%'!AH:AI,2,0) -> 0.75098985 | M16: =VLOOKUP(B16,'Refi%'!L:P,4,0) -> 4379.1 | N16: =VLOOKUP(B16,'Realized Vol'!H:J,2,0) -> 2.8817315 | O16: =VLOOKUP(B16,'Realized Vol'!H:J,3,0) -> 10.543628
B17: 40998 | C17: ='Return&Carry'!C15*100 -> 7.140025 | D17: 105.25489 | E17: ='Return&Carry'!D15*100 -> 1.0372253 | F17: =VLOOKUP(TEXT(B17,"yyyy-mm-dd"),OneWeekMtgRatesDataTable7[],4,0)*SQRT(225)*100 -> 75.771275 | G17: =VLOOKUP(B17,'Yield Curve'!B17:G65,6,0)*100 -> 187.6 | H17: =VLOOKUP(B17,'ppm risk premium'!C:J,8,0)*100 -> 143.69569 | I17: 4.0219851 | J17: =VLOOKUP(B17,'LIBOR 1m'!D:F,3,0) -> 0.24125 | K17: =VLOOKUP(B17,'Refi%'!AE:AF,2,0) -> 0.89832187 | L17: =VLOOKUP(B17,'Refi%'!AH:AI,2,0) -> 0.74902453 | M17: =VLOOKUP(B17,'Refi%'!L:P,4,0) -> 3699.5 | N17: =VLOOKUP(B17,'Realized Vol'!H:J,2,0) -> 3.0669216 | O17: =VLOOKUP(B17,'Realized Vol'!H:J,3,0) -> 18.519003
B18: 41029 | C18: ='Return&Carry'!C16*100 -> -2.0065317 | D18: 167.5742 | E18: ='Return&Carry'!D16*100 -> 0.24221037 | F18: =VLOOKUP(TEXT(B18,"yyyy-mm-dd"),OneWeekMtgRatesDataTable7[],4,0)*SQRT(225)*100 -> 76.627445 | G18: =VLOOKUP(B18,'Yield Curve'!B18:G66,6,0)*100 -> 165.5 | H18: =VLOOKUP(B18,'ppm risk premium'!C:J,8,0)*100 -> 152.87223 | I18: 3.7693449 | J18: =VLOOKUP(B18,'LIBOR 1m'!D:F,3,0) -> 0.23875 | K18: =VLOOKUP(B18,'Refi%'!AE:AF,2,0) -> 0.91020621 | L18: =VLOOKUP(B18,'Refi%'!AH:AI,2,0) -> 0.8016259 | M18: =VLOOKUP(B18,'Refi%'!L:P,4,0) -> 3856 | N18: =VLOOKUP(B18,'Realized Vol'!H:J,2,0) -> 2.8585942 | O18: =VLOOKUP(B18,'Realized Vol'!H:J,3,0) -> -20.83274
B19: 41060 | C19: ='Return&Carry'!C17*100 -> -7.1845659 | D19: 286.25597 | E19: ='Return&Carry'!D17*100 -> 0.83669301 | F19: =VLOOKUP(TEXT(B19,"yyyy-mm-dd"),OneWeekMtgRatesDataTable7[],4,0)*SQRT(225)*100 -> 73.169285 | G19: =VLOOKUP(B19,'Yield Curve'!B19:G69,6,0)*100 -> 131.6 | H19: =VLOOKUP(B19,'ppm risk premium'!C:J,8,0)*100 -> 166.16121 | I19: 3.2895729 | J19: =VLOOKUP(B19,'LIBOR 1m'!D:F,3,0) -> 0.23875 | K19: =VLOOKUP(B19,'Refi%'!AE:AF,2,0) -> 0.90149771 | L19: =VLOOKUP(B19,'Refi%'!AH:AI,2,0) -> 0.86801002 | M19: =VLOOKUP(B19,'Refi%'!L:P,4,0) -> 4736 | N19: =VLOOKUP(B19,'Realized Vol'!H:J,2,0) -> 2.6463905 | O19: =VLOOKUP(B19,'Realized Vol'!H:J,3,0) -> -21.220364
B20: 41089 | C20: ='Return&Carry'!C18*100 -> 4.3888393 | D20: 293.967 | E20: ='Return&Carry'!D18*100 -> 1.4315088 | F20: =VLOOKUP(TEXT(B20,"yyyy-mm-dd"),OneWeekMtgRatesDataTable7[],4,0)*SQRT(225)*100 -> 63.355131 | G20: =VLOOKUP(B20,'Yield Curve'!B20:G70,6,0)*100 -> 134.6 | H20: =VLOOKUP(B20,'ppm risk premium'!C:J,8,0)*100 -> 163.87567 | I20: 3.3792319 | J20: =VLOOKUP(B20,'LIBOR 1m'!D:F,3,0) -> 0.24575 | K20: =VLOOKUP(B20,'Refi%'!AE:AF,2,0) -> 0.89196946 | L20: =VLOOKUP(B20,'Refi%'!AH:AI,2,0) -> 0.86325673 | M20: =VLOOKUP(B20,'Refi%'!L:P,4,0) -> 4372.2 | N20: =VLOOKUP(B20,'Realized Vol'!H:J,2,0) -> 2.6237189 | O20: =VLOOKUP(B20,'Realized Vol'!H:J,3,0) -> -2.2671673
B21: 41121 | C21: ='Return&Carry'!C19*100 -> 6.2058843 | D21: 171.7155 | E21: ='Return&Carry'!D19*100 -> 1.1971428 | F21: =VLOOKUP(TEXT(B21,"yyyy-mm-dd"),OneWeekMtgRatesDataTable7[],4,0)*SQRT(225)*100 -> 78.601415 | G21: =VLOOKUP(B21,'Yield Curve'!B21:G71,6,0)*100 -> 127.1 | H21: =VLOOKUP(B21,'ppm risk premium'!C:J,8,0)*100 -> 177.12447 | I21: 3.3233894 | J21: =VLOOKUP(B21,'LIBOR 1m'!D:F,3,0) -> 0.2457 | K21: =VLOOKUP(B21,'Refi%'!AE:AF,2,0) -> 0.9800785 | L21: =VLOOKUP(B21,'Refi%'!AH:AI,2,0) -> 0.89684644 | M21: =VLOOKUP(B21,'Refi%'!L:P,4,0) -> 5492.1 | N21: =VLOOKUP(B21,'Realized Vol'!H:J,2,0) -> 2.3145961 | O21: =VLOOKUP(B21,'Realized Vol'!H:J,3,0) -> -30.912278
B22: 41152 | C22: ='Return&Carry'!C20*100 -> 6.012521 | D22: 79.354764 | E22: ='Return&Carry'!D20*100 -> 0.83837742 | F22: =VLOOKUP(TEXT(B22,"yyyy-mm-dd"),OneWeekMtgRatesDataTable7[],4,0)*SQRT(225)*100 -> 84.442873 | G22: =VLOOKUP(B22,'Yield Curve'!B22:G72,6,0)*100 -> 133.8 | H22: =VLOOKUP(B22,'ppm risk premium'!C:J,8,0)*100 -> 174.96399 | I22: 3.5430709 | J22: =VLOOKUP(B22,'LIBOR 1m'!D:F,3,0) -> 0.2305 | K22: =VLOOKUP(B22,'Refi%'!AE:AF,2,0) -> 0.97362867 | L22: =VLOOKUP(B22,'Refi%'!AH:AI,2,0) -> 0.88562576 | M22: =VLOOKUP(B22,'Refi%'!L:P,4,0) -> 4274.8 | N22: =VLOOKUP(B22,'Realized Vol'!H:J,2,0) -> 2.3689487 | O22: =VLOOKUP(B22,'Realized Vol'!H:J,3,0) -> 5.4352601
B23: 41180 | C23: ='Return&Carry'!C21*100 -> -3.9837098 | D23: 247.78681 | E23: ='Return&Carry'!D21*100 -> -0.206538 | F23: =VLOOKUP(TEXT(B23,"yyyy-mm-dd"),OneWeekMtgRatesDataTable7[],4,0)*SQRT(225)*100 -> 94.746297 | G23: =VLOOKUP(B23,'Yield Curve'!B:G,6,0)*100 -> 140.5 | H23: =VLOOKUP(B23,'ppm risk premium'!C:J,8,0)*100 -> 183.07274 | I23: 3.0962675 | J23: =VLOOKUP(B23,'LIBOR 1m'!D:F,3,0) -> 0.21425 | K23: =VLOOKUP(B23,'Refi%'!AE:AF,2,0) -> 0.96488793 | L23: =VLOOKUP(B23,'Refi%'!AH:AI,2,0) -> 0.91497224 | M23: =VLOOKUP(B23,'Refi%'!L:P,4,0) -> 5965.5 | N23: =VLOOKUP(B23,'Realized Vol'!H:J,2,0) -> 2.039914 | O23: =VLOOKUP(B23,'Realized Vol'!H:J,3,0) -> -32.903463
B24: 41213 | C24: ='Return&Carry'!C22*100 -> 0.15619117 | D24: 309.68944 | E24: ='Return&Carry'!D22*100 -> 0.6272732 | F24: =VLOOKUP(TEXT(B24,"yyyy-mm-dd"),OneWeekMtgRatesDataTable7[],4,0)*SQRT(225)*100 -> 89.651564 | G24: =VLOOKUP(B24,'Yield Curve'!B:G,6,0)*100 -> 140.5 | H24: =VLOOKUP(B24,'ppm risk premium'!C:J,8,0)*100 -> 183.01489 | I24: 3.169573 | J24: =VLOOKUP(B24,'LIBOR 1m'!D:F,3,0) -> 0.212 | K24: =VLOOKUP(B24,'Refi%'!AE:AF,2,0) -> 0.95372451 | L24: =VLOOKUP(B24,'Refi%'!AH:AI,2,0) -> 0.89827016 | M24: =VLOOKUP(B24,'Refi%'!L:P,4,0) -> 4550.7 | N24: =VLOOKUP(B24,'Realized Vol'!H:J,2,0) -> 2.1423497 | O24: =VLOOKUP(B24,'Realized Vol'!H:J,3,0) -> 10.243571
B25: 41243 | C25: ='Return&Carry'!C23*100 -> -3.7250679 | D25: 312.18894 | E25: ='Return&Carry'!D23*100 -> -0.28508676 | F25: =VLOOKUP(TEXT(B25,"yyyy-mm-dd"),OneWeekMtgRatesDataTable7[],4,0)*SQRT(225)*100 -> 93.740889 | G25: =VLOOKUP(B25,'Yield Curve'!B:G,6,0)*100 -> 136 | H25: =VLOOKUP(B25,'ppm risk premium'!C:J,8,0)*100 -> 179.2144 | I25: 3.0258975 | J25: =VLOOKUP(B25,'LIBOR 1m'!D:F,3,0) -> 0.2145 | K25: =VLOOKUP(B25,'Refi%'!AE:AF,2,0) -> 0.92988566 | L25: =VLOOKUP(B25,'Refi%'!AH:AI,2,0) -> 0.89026059 | M25: =VLOOKUP(B25,'Refi%'!L:P,4,0) -> 4943 | N25: =VLOOKUP(B25,'Realized Vol'!H:J,2,0) -> 2.0725335 | O25: =VLOOKUP(B25,'Realized Vol'!H:J,3,0) -> -6.9816196
B26: 41274 | C26: ='Return&Carry'!C24*100 -> 2.6619863 | D26: 327.64422 | E26: ='Return&Carry'!D24*100 -> 0.070328489 | F26: =VLOOKUP(TEXT(B26,"yyyy-mm-dd"),OneWeekMtgRatesDataTable7[],4,0)*SQRT(225)*100 -> 77.697859 | G26: =VLOOKUP(B26,'Yield Curve'!B:G,6,0)*100 -> 149.2 | H26: =VLOOKUP(B26,'ppm risk premium'!C:J,8,0)*100 -> 173.15728 | I26: 3.1411404 | J26: =VLOOKUP(B26,'LIBOR 1m'!D:F,3,0) -> 0.2087 | K26: =VLOOKUP(B26,'Refi%'!AE:AF,2,0) -> 0.9110383 | L26: =VLOOKUP(B26,'Refi%'!AH:AI,2,0) -> 0.8594083 | M26: =VLOOKUP(B26,'Refi%'!L:P,4,0) -> 3488.9 | N26: =VLOOKUP(B26,'Realized Vol'!H:J,2,0) -> 2.1517307 | O26: =VLOOKUP(B26,'Realized Vol'!H:J,3,0) -> 7.9197162
B27: 41305 | C27: ='Return&Carry'!C25*100 -> 2.8918724 | D27: 428.37293 | E27: ='Return&Carry'!D25*100 -> -0.4534384 | F27: =VLOOKUP(TEXT(B27,"yyyy-mm-dd"),OneWeekMtgRatesDataTable7[],4,0)*SQRT(225)*100 -> 73.886217 | G27: =VLOOKUP(B27,'Yield Curve'!B:G,6,0)*100 -> 171.8 | H27: =VLOOKUP(B27,'ppm risk premium'!C:J,8,0)*100 -> 142.18241 | I27: 3.4308576 | J27: =VLOOKUP(B27,'LIBOR 1m'!D:F,3,0) -> 0.1997 | K27: =VLOOKUP(B27,'Refi%'!AE:AF,2,0) -> 0.77474963 | L27: =VLOOKUP(B27,'Refi%'!AH:AI,2,0) -> 0.75499759 | M27: =VLOOKUP(B27,'Refi%'!L:P,4,0) -> 4579 | N27: =VLOOKUP(B27,'Realized Vol'!H:J,2,0) -> 2.5737676 | O27: =VLOOKUP(B27,'Realized Vol'!H:J,3,0) -> 42.203688
B28: 41333 | C28: ='Return&Carry'!C26*100 -> -0.18837838 | D28: 447.98054 | E28: ='Return&Carry'!D26*100 -> -0.44958852 | F28: =VLOOKUP(TEXT(B28,"yyyy-mm-dd"),OneWeekMtgRatesDataTable7[],4,0)*SQRT(225)*100 -> 58.653057 | G28: =VLOOKUP(B28,'Yield Curve'!B:G,6,0)*100 -> 165 | H28: =VLOOKUP(B28,'ppm risk premium'!C:J,8,0)*100 -> 147.2334 | I28: 3.4146508 | J28: =VLOOKUP(B28,'LIBOR 1m'!D:F,3,0) -> 0.2037 | K28: =VLOOKUP(B28,'Refi%'!AE:AF,2,0) -> 0.84309753 | L28: =VLOOKUP(B28,'Refi%'!AH:AI,2,0) -> 0.7712298 | M28: =VLOOKUP(B28,'Refi%'!L:P,4,0) -> 4724.9 | N28: =VLOOKUP(B28,'Realized Vol'!H:J,2,0) -> 2.5448374 | O28: =VLOOKUP(B28,'Realized Vol'!H:J,3,0) -> -2.8930159
B29: 41361 | C29: ='Return&Carry'!C27*100 -> 4.4045396 | D29: 342.66581 | E29: ='Return&Carry'!D27*100 -> 0.37234474 | F29: =VLOOKUP(TEXT(B29,"yyyy-mm-dd"),OneWeekMtgRatesDataTable7[],4,0)*SQRT(225)*100 -> 59.498817 | G29: =VLOOKUP(B29,'Yield Curve'!B:G,6,0)*100 -> 160.9 | H29: =VLOOKUP(B29,'ppm risk premium'!C:J,8,0)*100 -> #N/A | I29: 4.4592698 | J29: =VLOOKUP(B29,'LIBOR 1m'!D:F,3,0) -> 0.2037 | K29: =VLOOKUP(B29,'Refi%'!AE:AF,2,0) -> 0.76515105 | L29: =VLOOKUP(B29,'Refi%'!AH:AI,2,0) -> 0.72944016 | M29: =VLOOKUP(B29,'Refi%'!L:P,4,0) -> 4119.2 | N29: =VLOOKUP(B29,'Realized Vol'!H:J,2,0) -> 2.6143336 | O29: =VLOOKUP(B29,'Realized Vol'!H:J,3,0) -> 6.9496146
B30: 41394 | C30: ='Return&Carry'!C28*100 -> -9.0801514 | D30: 522.2402 | E30: ='Return&Carry'!D28*100 -> 0.25360138 | F30: =VLOOKUP(TEXT(B30,"yyyy-mm-dd"),OneWeekMtgRatesDataTable7[],4,0)*SQRT(225)*100 -> 52.140172 | G30: =VLOOKUP(B30,'Yield Curve'!B:G,6,0)*100 -> 146.4 | H30: =VLOOKUP(B30,'ppm risk premium'!C:J,8,0)*100 -> 155.10957 | I30: 3.9097834 | J30: =VLOOKUP(B30,'LIBOR 1m'!D:F,3,0) -> 0.1982 | K30: =VLOOKUP(B30,'Refi%'!AE:AF,2,0) -> 0.83356731 | L30: =VLOOKUP(B30,'Refi%'!AH:AI,2,0) -> 0.78570359 | M30: =VLOOKUP(B30,'Refi%'!L:P,4,0) -> 4854.1 | N30: =VLOOKUP(B30,'Realized Vol'!H:J,2,0) -> 2.3535374 | O30: =VLOOKUP(B30,'Realized Vol'!H:J,3,0) -> -26.079619
B31: 41425 | C31: ='Return&Carry'!C29*100 -> 7.8437853 | D31: 459.78735 | E31: ='Return&Carry'!D29*100 -> 0.51248107 | F31: =VLOOKUP(TEXT(B31,"yyyy-mm-dd"),OneWeekMtgRatesDataTable7[],4,0)*SQRT(225)*100 -> 73.191195 | G31: =VLOOKUP(B31,'Yield Curve'!B:G,6,0)*100 -> 185.7 | H31: =VLOOKUP(B31,'ppm risk premium'!C:J,8,0)*100 -> 93.167025 | I31: 4.7140275 | J31: =VLOOKUP(B31,'LIBOR 1m'!D:F,3,0) -> 0.19428 | K31: =VLOOKUP(B31,'Refi%'!AE:AF,2,0) -> 0.62532821 | L31: =VLOOKUP(B31,'Refi%'!AH:AI,2,0) -> 0.59469521 | M31: =VLOOKUP(B31,'Refi%'!L:P,4,0) -> 3163.6 | N31: =VLOOKUP(B31,'Realized Vol'!H:J,2,0) -> 2.9573135 | O31: =VLOOKUP(B31,'Realized Vol'!H:J,3,0) -> 60.377611
B32: 41453 | C32: ='Return&Carry'!C30*100 -> 4.9033765 | D32: 381.68905 | E32: ='Return&Carry'!D30*100 -> -0.3514015 | F32: =VLOOKUP(TEXT(B32,"yyyy-mm-dd"),OneWeekMtgRatesDataTable7[],4,0)*SQRT(225)*100 -> 88.427 | G32: =VLOOKUP(B32,'Yield Curve'!B:G,6,0)*100 -> 213.1 | H32: =VLOOKUP(B32,'ppm risk premium'!C:J,8,0)*100 -> 44.143013 | I32: 5.149796 | J32: =VLOOKUP(B32,'LIBOR 1m'!D:F,3,0) -> 0.19465 | K32: =VLOOKUP(B32,'Refi%'!AE:AF,2,0) -> 0.44439106 | L32: =VLOOKUP(B32,'Refi%'!AH:AI,2,0) -> 0.42100631 | M32: =VLOOKUP(B32,'Refi%'!L:P,4,0) -> 2573.4 | N32: =VLOOKUP(B32,'Realized Vol'!H:J,2,0) -> 3.3094497 | O32: =VLOOKUP(B32,'Realized Vol'!H:J,3,0) -> 35.213618
B33: 41486 | C33: ='Return&Carry'!C31*100 -> 4.5699741 | D33: 333.34539 | E33: ='Return&Carry'!D31*100 -> -0.44551319 | F33: =VLOOKUP(TEXT(B33,"yyyy-mm-dd"),OneWeekMtgRatesDataTable7[],4,0)*SQRT(225)*100 -> 111.39248 | G33: =VLOOKUP(B33,'Yield Curve'!B:G,6,0)*100 -> 228.3 | H33: =VLOOKUP(B33,'ppm risk premium'!C:J,8,0)*100 -> 38.950965 | I33: 5.4757381 | J33: =VLOOKUP(B33,'LIBOR 1m'!D:F,3,0) -> 0.18673 | K33: =VLOOKUP(B33,'Refi%'!AE:AF,2,0) -> 0.42516653 | L33: =VLOOKUP(B33,'Refi%'!AH:AI,2,0) -> 0.40693111 | M33: =VLOOKUP(B33,'Refi%'!L:P,4,0) -> 2218.3 | N33: =VLOOKUP(B33,'Realized Vol'!H:J,2,0) -> 3.4095393 | O33: =VLOOKUP(B33,'Realized Vol'!H:J,3,0) -> 10.008959
B34: 41516 | C34: ='Return&Carry'!C32*100 -> 2.4720201 | D34: 273.22546 | E34: ='Return&Carry'!D32*100 -> -0.2463078 | F34: =VLOOKUP(TEXT(B34,"yyyy-mm-dd"),OneWeekMtgRatesDataTable7[],4,0)*SQRT(225)*100 -> 116.17425 | G34: =VLOOKUP(B34,'Yield Curve'!B:G,6,0)*100 -> 236.6 | H34: =VLOOKUP(B34,'ppm risk premium'!C:J,8,0)*100 -> 30.462159 | I34: 5.6687393 | J34: =VLOOKUP(B34,'LIBOR 1m'!D:F,3,0) -> 0.18206 | K34: =VLOOKUP(B34,'Refi%'!AE:AF,2,0) -> 0.39522167 | L34: =VLOOKUP(B34,'Refi%'!AH:AI,2,0) -> 0.36106342 | M34: =VLOOKUP(B34,'Refi%'!L:P,4,0) -> 1909 | N34: =VLOOKUP(B34,'Realized Vol'!H:J,2,0) -> 3.5181083 | O34: =VLOOKUP(B34,'Realized Vol'!H:J,3,0) -> 10.856902
... B50: 42004 | C50: ='Return&Carry'!C48*100 -> -1.582885 | D50: -82.306012 | E50: ='Return&Carry'!D48*100 -> 1.1149482 | F50: =VLOOKUP(TEXT(B50,"yyyy-mm-dd"),OneWeekMtgRatesDataTable7[],4,0)*SQRT(225)*100 -> 56.938654 | G50: =VLOOKUP(B50,'Yield Curve'!B:G,6,0)*100 -> 149.8 | H50: =VLOOKUP(B50,'ppm risk premium'!C:J,8,0)*100 -> 80.850273 | I50: 5.8275205 | J50: =VLOOKUP(B50,'LIBOR 1m'!D:F,3,0) -> 0.17125 | K50: =VLOOKUP(B50,'Refi%'!AE:AF,2,0) -> 0.60249396 | L50: =VLOOKUP(B50,'Refi%'!AH:AI,2,0) -> 0.55220027 | M50: =VLOOKUP(B50,'Refi%'!L:P,4,0) -> 1347.6 | N50: =VLOOKUP(B50,'Realized Vol'!H:J,2,0) -> 2.8338661 | O50: =VLOOKUP(B50,'Realized Vol'!H:J,3,0) -> -1.1819122
B51: 42034 | C51: ='Return&Carry'!C49*100 -> -11.82102 | D51: 64.725409 | E51: ='Return&Carry'!D49*100 -> 1.10378 | F51: =VLOOKUP(TEXT(B51,"yyyy-mm-dd"),OneWeekMtgRatesDataTable7[],4,0)*SQRT(225)*100 -> 60.215273 | G51: =VLOOKUP(B51,'Yield Curve'!B:G,6,0)*100 -> 120.8 | H51: =VLOOKUP(B51,'ppm risk premium'!C:J,8,0)*100 -> 110.71066 | I51: 4.7819497 | J51: =VLOOKUP(B51,'LIBOR 1m'!D:F,3,0) -> 0.17125 | K51: =VLOOKUP(B51,'Refi%'!AE:AF,2,0) -> 0.76666901 | L51: =VLOOKUP(B51,'Refi%'!AH:AI,2,0) -> 0.70593684 | M51: =VLOOKUP(B51,'Refi%'!L:P,4,0) -> 2584.8 | N51: =VLOOKUP(B51,'Realized Vol'!H:J,2,0) -> 2.4526688 | O51: =VLOOKUP(B51,'Realized Vol'!H:J,3,0) -> -38.119735 | P51: =VLOOKUP(B51,'Return&Carry'!B:E,4,0)*100 -> -8.9367824
B52: 42062 | C52: ='Return&Carry'!C50*100 -> 11.15765 | D52: -86.739531 | E52: ='Return&Carry'!D50*100 -> 1.62244 | F52: =VLOOKUP(TEXT(B52,"yyyy-mm-dd"),OneWeekMtgRatesDataTable7[],4,0)*SQRT(225)*100 -> 73.252678 | G52: =VLOOKUP(B52,'Yield Curve'!B:G,6,0)*100 -> 137.6 | H52: =VLOOKUP(B52,'ppm risk premium'!C:J,8,0)*100 -> 89.112937 | I52: 5.5060135 | J52: =VLOOKUP(B52,'LIBOR 1m'!D:F,3,0) -> 0.173 | K52: =VLOOKUP(B52,'Refi%'!AE:AF,2,0) -> 0.62925392 | L52: =VLOOKUP(B52,'Refi%'!AH:AI,2,0) -> 0.60067933 | M52: =VLOOKUP(B52,'Refi%'!L:P,4,0) -> 1740.3 | N52: =VLOOKUP(B52,'Realized Vol'!H:J,2,0) -> 2.7365986 | O52: =VLOOKUP(B52,'Realized Vol'!H:J,3,0) -> 28.392978 | P52: =VLOOKUP(B52,'Return&Carry'!B:E,4,0)*100 -> 5.5289116
B53: 42094 | C53: -0.7 | D53: -96.814517 | E53: ='Return&Carry'!D51*100 -> 0.98971 | F53: =VLOOKUP(TEXT(B53,"yyyy-mm-dd"),OneWeekMtgRatesDataTable7[],4,0)*SQRT(225)*100 -> 78.458334 | G53: =VLOOKUP(B53,'Yield Curve'!B:G,6,0)*100 -> 137.9 | H53: =VLOOKUP(B53,'ppm risk premium'!C:J,8,0)*100 -> 93.534865 | I53: 5.3690219 | J53: =VLOOKUP(B53,'LIBOR 1m'!D:F,3,0) -> 0.17625 | K53: =VLOOKUP(B53,'Refi%'!AE:AF,2,0) -> 0.6427826 | L53: =VLOOKUP(B53,'Refi%'!AH:AI,2,0) -> 0.62973028 | M53: =VLOOKUP(B53,'Refi%'!L:P,4,0) -> 1941.6 | N53: =VLOOKUP(B53,'Realized Vol'!H:J,2,0) -> 2.6610352 | O53: =VLOOKUP(B53,'Realized Vol'!H:J,3,0) -> -7.556341 | P53: =VLOOKUP(B53,'Return&Carry'!B:E,4,0)*100 -> 1.1795069
B54: 42124 | C54: ='Return&Carry'!C52*100 -> 5.20696 | D54: 27.782091 | E54: ='Return&Carry'!D52*100 -> 0.23842 | F54: =VLOOKUP(TEXT(B54,"yyyy-mm-dd"),OneWeekMtgRatesDataTable7[],4,0)*SQRT(225)*100 -> 69.088668 | G54: =VLOOKUP(B54,'Yield Curve'!B:G,6,0)*100 -> 146.7 | H54: =VLOOKUP(B54,'ppm risk premium'!C:J,8,0)*100 -> 85.684588 | I54: 5.5645995 | J54: =VLOOKUP(B54,'LIBOR 1m'!D:F,3,0) -> 0.181 | K54: =VLOOKUP(B54,'Refi%'!AE:AF,2,0) -> 0.60856289 | L54: =VLOOKUP(B54,'Refi%'!AH:AI,2,0) -> 0.59145745 | M54: =VLOOKUP(B54,'Refi%'!L:P,4,0) -> 1559.4 | N54: =VLOOKUP(B54,'Realized Vol'!H:J,2,0) -> 2.7480147 | O54: =VLOOKUP(B54,'Realized Vol'!H:J,3,0) -> 8.6979562 | P54: =VLOOKUP(B54,'Return&Carry'!B:E,4,0)*100 -> 1.1911914
B55: 42153 | C55: ='Return&Carry'!C53*100 -> 1.25011 | D55: 27 | E55: ='Return&Carry'!D53*100 -> 0.36718 | F55: =VLOOKUP(TEXT(B55,"yyyy-mm-dd"),OneWeekMtgRatesDataTable7[],4,0)*SQRT(225)*100 -> 68.401578 | G55: =VLOOKUP(B55,'Yield Curve'!B:G,6,0)*100 -> 149.2 | H55: =VLOOKUP(B55,'ppm risk premium'!C:J,8,0)*100 -> 77.680787 | I55: 5.6626092 | J55: =VLOOKUP(B55,'LIBOR 1m'!D:F,3,0) -> 0.184 | K55: =VLOOKUP(B55,'Refi%'!AE:AF,2,0) -> 0.57203724 | L55: =VLOOKUP(B55,'Refi%'!AH:AI,2,0) -> 0.55658019 | M55: =VLOOKUP(B55,'Refi%'!L:P,4,0) -> 1233.9 | N55: =VLOOKUP(B55,'Realized Vol'!H:J,2,0) -> 2.8125589 | O55: =VLOOKUP(B55,'Realized Vol'!H:J,3,0) -> 6.4544219 | P55: =VLOOKUP(B55,'Return&Carry'!B:E,4,0)*100 -> -1.6640711
B56: 42185 | C56: ='Return&Carry'!C54*100 -> 4.67899 | D56: ='Return&Carry'!I55 -> 10 | E56: ='Return&Carry'!D54*100 -> 0.32145 | F56: =VLOOKUP(TEXT(B56,"yyyy-mm-dd"),OneWeekMtgRatesDataTable7[],4,0)*SQRT(225)*100 -> 75.446781 | G56: =VLOOKUP(B56,'Yield Curve'!B:G,6,0)*100 -> 169.8 | H56: =VLOOKUP(B56,'ppm risk premium'!C:J,8,0)*100 -> 53.102039 | I56: 6.1637474 | J56: =VLOOKUP(B56,'LIBOR 1m'!D:F,3,0) -> 0.1865 | K56: =VLOOKUP(B56,'Refi%'!AE:AF,2,0) -> 0.4424227 | L56: =VLOOKUP(B56,'Refi%'!AH:AI,2,0) -> 0.42167652 | M56: =VLOOKUP(B56,'Refi%'!L:P,4,0) -> 1246.1 | N56: =VLOOKUP(B56,'Realized Vol'!H:J,2,0) -> 3.0732804 | O56: =VLOOKUP(B56,'Realized Vol'!H:J,3,0) -> 26.07215 | P56: =VLOOKUP(B56,'Return&Carry'!B:E,4,0)*100 -> -0.65968608
B57: 42216 | C57: ='Return&Carry'!C55*100 -> -1.54512 | D57: ='Return&Carry'!I56 -> 14 | E57: ='Return&Carry'!D55*100 -> 0.1851 | F57: =VLOOKUP(TEXT(B57,"yyyy-mm-dd"),OneWeekMtgRatesDataTable7[],4,0)*SQRT(225)*100 -> 82.06165 | G57: =VLOOKUP(B57,'Yield Curve'!B:G,6,0)*100 -> 153.1 | H57: =VLOOKUP(B57,'ppm risk premium'!C:J,8,0)*100 -> 66.95469 | I57: 5.9295802 | J57: =VLOOKUP(B57,'LIBOR 1m'!D:F,3,0) -> 0.19175 | K57: =VLOOKUP(B57,'Refi%'!AE:AF,2,0) -> 0.51760959 | L57: =VLOOKUP(B57,'Refi%'!AH:AI,2,0) -> 0.50352879 | M57: 1418 | N57: =VLOOKUP(B57,'Realized Vol'!H:J,2,0) -> 2.9155081 | O57: =VLOOKUP(B57,'Realized Vol'!H:J,3,0) -> -15.777232 | P57: =VLOOKUP(B57,'Return&Carry'!B:E,4,0)*100 -> 1.1808852
...

Sheet Return&Carry
G1: IOS Index
B2: Date | C2: Monthly Hedge Return (%) | D2: IOS + TBA Carry (%) | E2: IOS + TBA + Curve Monthly Return (%) | G2: IOS | K2: IOS + TBA*
B3: 40633 | C3: =K4 -> 0.032147753 | D3: =J4 -> 0.010991114 | G3: Date | H3: Monthly Return (%) | I3: OAS | J3: IOS + TBA Carry (%) | K3: Monthly Return (%)
B4: 40662 | C4: =K5 -> 0.039945301 | D4: =J5 -> 0.010984369 | G4: 40633 | H4: 0.036885208 | I4: 12.454245 | J4: 0.010991114 | K4: 0.032147753
B5: 40694 | C5: =K6 -> 0.036836949 | D5: =J6 -> 0.012359979 | G5: 40662 | H5: 0.01824177 | I5: -13.523942 | J5: 0.010984369 | K5: 0.039945301
B6: 40724 | C6: =K7 -> -0.0089725231 | D6: =J7 -> 0.011611305 | G6: 40694 | H6: 0.0095136889 | I6: -39.195911 | J6: 0.012359979 | K6: 0.036836949
B7: 40753 | C7: =K8 -> -0.0070542452 | D7: =J8 -> 0.0094859999 | G7: 40724 | H7: 0.014594354 | I7: -71.812763 | J7: 0.011611305 | K7: -0.0089725231
B8: 40786 | C8: =K9 -> -0.12940149 | D8: =J9 -> 0.0098897456 | G8: 40753 | H8: -0.056499118 | I8: 14.555567 | J8: 0.0094859999 | K8: -0.0070542452
B9: 40816 | C9: =K10 -> -0.10646399 | D9: =J10 -> 0.014023414 | G9: 40786 | H9: -0.20415555 | I9: 413.13076 | J9: 0.0098897456 | K9: -0.12940149
B10: 40847 | C10: =K11 -> 0.023593585 | D10: =J11 -> 0.012905992 | G10: 40816 | H10: -0.18608869 | I10: 707.36595 | J10: 0.014023414 | K10: -0.10646399
B11: 40877 | C11: =K12 -> 0.014407939 | D11: =J12 -> 0.0070135917 | G11: 40847 | H11: 0.052849339 | I11: 688.11427 | J11: 0.012905992 | K11: 0.023593585
B12: 40907 | C12: =K13 -> 0.005832688 | D12: =J13 -> 0.0039545841 | G12: 40877 | H12: -0.0070201413 | I12: 623.10169 | J12: 0.0070135917 | K12: 0.014407939
B13: 40939 | C13: =K14 -> -0.030247515 | D13: =J14 -> 0.0093155585 | G13: 40907 | H13: -0.027877514 | I13: 610.59818 | J13: 0.0039545841 | K13: 0.005832688
B14: 40968 | C14: =K15 -> 0.11557044 | D14: =J15 -> 0.017106233 | G14: 40939 | H14: -0.088730633 | I14: 465.33199 | J14: 0.0093155585 | K14: -0.030247515
B15: 40998 | C15: =K16 -> 0.07140025 | D15: =J16 -> 0.010372253 | G15: 40968 | H15: 0.1267261 | I15: 220.00245 | J15: 0.017106233 | K15: 0.11557044
... B48: 42004 | C48: =K49 -> -0.01582885 | D48: =J49 -> 0.011149482 | G48: 41971 | H48: -0.033127567 | I48: -67.681506 | J48: 0.010005318 | K48: -0.0029385887
B49: 42034 | C49: =K50 -> -0.1182102 | D49: =J50 -> 0.0110378 | E49: -0.089367824 | G49: 42004 | H49: -0.026017102 | I49: -82.306012 | J49: 0.011149482 | K49: -0.01582885
B50: 42062 | C50: =K51 -> 0.1115765 | D50: =J51 -> 0.0162244 | E50: 0.055289116 | G50: 42034 | H50: -0.187301 | I50: 65 | J50: 0.0110378 | K50: -0.1182102
B51: 42094 | C51: =K52 -> -0.0070144 | D51: =J52 -> 0.0098971 | E51: 0.011795069 | G51: 42062 | H51: 0.167289 | I51: -87 | J51: 0.0162244 | K51: 0.1115765
B52: 42124 | C52: =K53 -> 0.0520696 | D52: =J53 -> 0.0023842 | E52: 0.011911914 | G52: 42094 | H52: -0.026037 | I52: -97 | J52: 0.0098971 | K52: -0.0070144
B53: 42153 | C53: =K54 -> 0.0125011 | D53: =J54 -> 0.0036718 | E53: -0.016640711 | G53: 42124 | H53: 0.060751 | I53: 28 | J53: 0.0023842 | K53: 0.0520696
B54: =G55 -> 42185 | C54: =K55 -> 0.0467899 | D54: =J55 -> 0.0032145 | E54: -0.0065968608 | G54: 42153 | H54: 0.017461 | I54: 27 | J54: 0.0036718 | K54: 0.0125011
B55: 42216 | C55: =K56 -> -0.0154512 | D55: =J56 -> 0.001851 | E55: 0.011808852 | G55: 42185 | H55: 0.091753 | I55: 10 | J55: 0.0032145 | K55: 0.0467899 | N55: 0.0031759822
B56: 42247 | C56: =K57 -> 0.001421 | D56: =J57 -> 0.0048585 | E56: -0.015282507 | G56: 42216 | H56: -0.043299 | I56: 14 | J56: 0.001851 | K56: -0.0154512
B57: 42277 | C57: =K58 -> -0.0124888 | D57: =J58 -> 0.0060951 | E57: -0.015878158 | G57: 42247 | H57: -0.002052 | I57: 21 | J57: 0.0048585 | K57: 0.001421
B58: 42307 | C58: =K59 -> 0.0019308 | D58: =J59 -> 0.0055736 | E58: -0.0013092872 | G58: 42277 | H58: -0.039848 | I58: 40 | J58: 0.0060951 | K58: -0.0124888
B59: 42338 | C59: =K60 -> 0.023941 | D59: =J60 -> 0.0054584 | E59: 0.017776153 | G59: 42307 | H59: 0.0036549 | I59: 42.354177 | J59: 0.0055736 | K59: 0.0019308
B60: 42369 | C60: =K61 -> 0.01144193 | D60: =J61 -> 0.00594921 | E60: 0.013600137 | G60: 42338 | H60: 0.0360099 | I60: 2.7201383 | J60: 0.0054584 | K60: 0.023941
B61: =G62 -> 42398 | C61: =K62 -> -0.04643 | D61: =J62 -> 0.00744 | E61: -0.020553532 | G61: 42369 | H61: 0.01644585 | I61: 5.1687359 | J61: 0.00594921 | K61: 0.01144193
B62: =G63 -> 42429 | C62: =K63 -> -0.013916175 | D62: =J63 -> 0.015813624 | E62: 0.0051569268 | G62: 42398 | H62: -0.10096 | I62: 21.00007 | J62: 0.00744 | K62: -0.04643
B63: =G64 -> 42460 | C63: =K64 -> 0.0371096 | D63: =J64 -> 0.014346 | E63: 0.013334686 | G63: 42429 | H63: -0.05336433 | I63: -7 | J63: 0.015813624 | K63: -0.013916175
B64: =G65 -> 42489 | C64: =K65 -> 0.019170625 | D64: =J65 -> 0.010033953 | E64: 0.012948296 | G64: 42460 | H64: 0.0207068 | I64: -6.080912 | J64: 0.014346 | K64: 0.0371096
B65: =G66 -> 42521 | C65: =K66 -> 0.014548599 | D65: =J66 -> 0.0099210031 | E65: 0.035984196 | G65: 42489 | H65: 0.0071656588 | I65: -12.112024 | J65: 0.010033953 | K65: 0.019170625
B66: =G67 -> 42551 | C66: =K67 -> 0.0016153614 | D66: =J67 -> 0.014593297 | E66: 0.01971612 | G66: 42521 | H66: 0.007286343 | I66: -49.120471 | J66: 0.0099210031 | K66: 0.014548599
B67: =G68 -> 42580 | C67: =K68 -> 0.015508709 | D67: =J68 -> 0.015573207 | E67: 0.041534439 | G67: 42551 | H67: -0.11389447 | I67: -21.292388 | J67: 0.014593297 | K67: 0.0016153614
G68: 42580 | H68: -0.044465962 | I68: 27.775417 | J68: 0.015573207 | K68: 0.015508709

Sheet Realized Vol
A1: AsOfDate | B1: SeriesNumValue | C1: dy | D1: vol1 | H1: Current Coupon Monthly Changes
A2: 2016-08-02 | B2: 2.3285238 | C2: =B2-B3 -> 0.03819809 | D2: =STDEV(C2:C61) -> 0.039786412 | H2: Date | I2: Current Coupon | J2: Changes
A3: 2016-08-01 | B3: 2.2903257 | C3: =B3-B4 -> 0.024449626 | D3: =STDEV(C3:C62) -> 0.039418423 | H3: ='Data Set'!B5 -> 40633 | I3: =VLOOKUP(TEXT(H3,"yyyy-mm-dd"),A:B,2,0) -> 4.2632122
A4: 2016-07-29 | B4: 2.2658761 | C4: =B4-B5 -> -0.055618841 | D4: =STDEV(C4:C63) -> 0.03945317 | H4: ='Data Set'!B6 -> 40662 | I4: =VLOOKUP(TEXT(H4,"yyyy-mm-dd"),A:B,2,0) -> 4.0911415 | J4: =(I4-I3)*100 -> -17.207069
A5: 2016-07-28 | B5: 2.3214949 | C5: =B5-B6 -> -0.020044751 | D5: =STDEV(C5:C64) -> 0.038899874 | H5: ='Data Set'!B7 -> 40694 | I5: =VLOOKUP(TEXT(H5,"yyyy-mm-dd"),A:B,2,0) -> 3.9323543 | J5: =(I5-I4)*100 -> -15.878724
A6: 2016-07-27 | B6: 2.3415397 | C6: =B6-B7 -> -0.04977488 | D6: =STDEV(C6:C65) -> 0.039539366 | H6: ='Data Set'!B8 -> 40724 | I6: =VLOOKUP(TEXT(H6,"yyyy-mm-dd"),A:B,2,0) -> 4.0210178 | J6: =(I6-I5)*100 -> 8.8663527
A7: 2016-07-26 | B7: 2.3913145 | C7: =B7-B8 -> 0.0085805126 | D7: =STDEV(C7:C66) -> 0.039564175 | H7: ='Data Set'!B9 -> 40753 | I7: =VLOOKUP(TEXT(H7,"yyyy-mm-dd"),A:B,2,0) -> 3.8088239 | J7: =(I7-I6)*100 -> -21.219393
A8: 2016-07-25 | B8: 2.382734 | C8: =B8-B9 -> 0.010366099 | D8: =STDEV(C8:C67) -> 0.039580197 | H8: ='Data Set'!B10 -> 40786 | I8: =VLOOKUP(TEXT(H8,"yyyy-mm-dd"),A:B,2,0) -> 3.4273948 | J8: =(I8-I7)*100 -> -38.142906
A9: 2016-07-22 | B9: 2.3723679 | C9: =B9-B10 -> 0.021502193 | D9: =STDEV(C9:C68) -> 0.039948336 | H9: ='Data Set'!B11 -> 40816 | I9: =VLOOKUP(TEXT(H9,"yyyy-mm-dd"),A:B,2,0) -> 3.0385262 | J9: =(I9-I8)*100 -> -38.886865
A10: 2016-07-21 | B10: 2.3508657 | C10: =B10-B11 -> 0.0040876676 | D10: =STDEV(C10:C69) -> 0.040162114 | H10: ='Data Set'!B12 -> 40847 | I10: =VLOOKUP(TEXT(H10,"yyyy-mm-dd"),A:B,2,0) -> 3.251577 | J10: =(I10-I9)*100 -> 21.305085
A11: 2016-07-20 | B11: 2.3467781 | C11: =B11-B12 -> 0.018745035 | D11: =STDEV(C11:C70) -> 0.040227536 | H11: ='Data Set'!B13 -> 40877 | I11: =VLOOKUP(TEXT(H11,"yyyy-mm-dd"),A:B,2,0) -> 3.1770193 | J11: =(I11-I10)*100 -> -7.4557679
A12: 2016-07-19 | B12: 2.328033 | C12: =B12-B13 -> -0.026675417 | D12: =STDEV(C12:C71) -> 0.04013471 | H12: ='Data Set'!B14 -> 40907 | I12: =VLOOKUP(TEXT(H12,"yyyy-mm-dd"),A:B,2,0) -> 3.0169009 | J12: =(I12-I11)*100 -> -16.011846
A13: 2016-07-18 | B13: 2.3547085 | C13: =B13-B14 -> -0.0040487962 | D13: =STDEV(C13:C72) -> 0.040118041 | H13: ='Data Set'!B15 -> 40939 | I13: =VLOOKUP(TEXT(H13,"yyyy-mm-dd"),A:B,2,0) -> 2.7762953 | J13: =(I13-I12)*100 -> -24.060559
A14: 2016-07-15 | B14: 2.3587572 | C14: =B14-B15 -> 0.045484382 | D14: =STDEV(C14:C73) -> 0.040202572 | H14: ='Data Set'!B16 -> 40968 | I14: =VLOOKUP(TEXT(H14,"yyyy-mm-dd"),A:B,2,0) -> 2.8817315 | J14: =(I14-I13)*100 -> 10.543628
A15: 2016-07-14 | B15: 2.3132729 | C15: =B15-B16 -> 0.035189356 | D15: =STDEV(C15:C74) -> 0.041210995 | H15: ='Data Set'!B17 -> 40998 | I15: =VLOOKUP(TEXT(H15,"yyyy-mm-dd"),A:B,2,0) -> 3.0669216 | J15: =(I15-I14)*100 -> 18.519003
... A65: 2016-05-03 | B65: 2.5475266 | C65: =B65-B66 -> -0.060794821 | D65: =STDEV(C65:C124) -> 0.042848646 | H65: ='Data Set'!B67 -> 42521 | I65: =VLOOKUP(TEXT(H65,"yyyy-mm-dd"),A:B,2,0) -> 2.5912536 | J65: =(I65-I64)*100 -> 2.6610926
A66: 2016-05-02 | B66: 2.6083214 | C66: =B66-B67 -> 0.043678695 | D66: =STDEV(C66:C125) -> 0.042141132 | H66: 42551 | I66: =VLOOKUP(TEXT(H66,"yyyy-mm-dd"),A:B,2,0) -> 2.2474864 | J66: =(I66-I65)*100 -> -34.376726
A67: 2016-04-29 | B67: 2.5646427 | C67: =B67-B68 -> -0.017647673 | D67: =STDEV(C67:C126) -> 0.041751503 | H67: 42580 | I67: =VLOOKUP(TEXT(H67,"yyyy-mm-dd"),A:B,2,0) -> 2.2658761 | J67: =(I67-I66)*100 -> 1.8389701
A68: 2016-04-28 | B68: 2.5822904 | C68: =B68-B69 -> -0.047722864 | D68: =STDEV(C68:C127) -> 0.041693693
A69: 2016-04-27 | B69: 2.6300132 | C69: =B69-B70 -> -0.046152892 | D69: =STDEV(C69:C128) -> 0.042879963
A70: 2016-04-26 | B70: 2.6761661 | C70: =B70-B71 -> 0.014642798 | D70: =STDEV(C70:C129) -> 0.04320438
A71: 2016-04-25 | B71: 2.6615233 | C71: =B71-B72 -> 0.0064988294 | D71: =STDEV(C71:C130) -> 0.043843734
A72: 2016-04-22 | B72: 2.6550245 | C72: =B72-B73 -> 0.014548096 | D72: =STDEV(C72:C131) -> 0.043982284
A73: 2016-04-21 | B73: 2.6404764 | C73: =B73-B74 -> 0.015421669 | D73: =STDEV(C73:C132) -> 0.043938861
A74: 2016-04-20 | B74: 2.6250547 | C74: =B74-B75 -> 0.081337936 | D74: =STDEV(C74:C133) -> 0.044137873
A75: 2016-04-19 | B75: 2.5437168 | C75: =B75-B76 -> 0.025603603 | D75: =STDEV(C75:C134) -> 0.042786777
A76: 2016-04-18 | B76: 2.5181132 | C76: =B76-B77 -> 0.0098083207 | D76: =STDEV(C76:C135) -> 0.042779969
A77: 2016-04-15 | B77: 2.5083049 | C77: =B77-B78 -> -0.0047670556 | D77: =STDEV(C77:C136) -> 0.042891471
A78: 2016-04-14 | B78: 2.5130719 | C78: =B78-B79 -> 0.00096758334 | D78: =STDEV(C78:C137) -> 0.043274968
A79: 2016-04-13 | B79: 2.5121043 | C79: =B79-B80 -> -0.013039854 | D79: =STDEV(C79:C138) -> 0.043290061
... A1813: 2009-05-07 | B1813: 4.0854192 | C1813: =B1813-B1814 -> 4.0854192 | D1813: =STDEV(C1813:C1872) -> #DIV/0!

Sheet Yield Curve
C3: Treasury Yields
B4: Date | C4: 2 | D4: 5 | E4: 10 | F4: 30 | G4: 10-2
B5: ='Data Set'!B5 -> 40633 | C5: =[1]!YBHIST("2 Year Treasury",$B5,"YldtoMat","govt","") -> 0.786 | D5: =[1]!YBHIST("5 Year Treasury",$B5,"YldtoMat","govt","") -> 2.223 | E5: =[1]!YBHIST("10 Year Treasury",$B5,"YldtoMat","govt","") -> 3.45 | F5: =[1]!YBHIST("30 Year Treasury",$B5,"YldtoMat","govt","") -> 4.507 | G5: =E5-C5 -> 2.664
B6: ='Data Set'!B6 -> 40662 | C6: =[1]!YBHIST("2 Year Treasury",$B6,"YldtoMat","govt","") -> 0.605 | D6: =[1]!YBHIST("5 Year Treasury",$B6,"YldtoMat","govt","") -> 1.97 | E6: =[1]!YBHIST("10 Year Treasury",$B6,"YldtoMat","govt","") -> 3.292 | F6: =[1]!YBHIST("30 Year Treasury",$B6,"YldtoMat","govt","") -> 4.404 | G6: =E6-C6 -> 2.687
B7: ='Data Set'!B7 -> 40694 | C7: =[1]!YBHIST("2 Year Treasury",$B7,"YldtoMat","govt","") -> 0.465 | D7: =[1]!YBHIST("5 Year Treasury",$B7,"YldtoMat","govt","") -> 1.686 | E7: =[1]!YBHIST("10 Year Treasury",$B7,"YldtoMat","govt","") -> 3.05 | F7: =[1]!YBHIST("30 Year Treasury",$B7,"YldtoMat","govt","") -> 4.215 | G7: =E7-C7 -> 2.585
B8: ='Data Set'!B8 -> 40724 | C8: =[1]!YBHIST("2 Year Treasury",$B8,"YldtoMat","govt","") -> 0.458 | D8: =[1]!YBHIST("5 Year Treasury",$B8,"YldtoMat","govt","") -> 1.754 | E8: =[1]!YBHIST("10 Year Treasury",$B8,"YldtoMat","govt","") -> 3.158 | F8: =[1]!YBHIST("30 Year Treasury",$B8,"YldtoMat","govt","") -> 4.382 | G8: =E8-C8 -> 2.7
B9: ='Data Set'!B9 -> 40753 | C9: =[1]!YBHIST("2 Year Treasury",$B9,"YldtoMat","govt","") -> 0.363 | D9: =[1]!YBHIST("5 Year Treasury",$B9,"YldtoMat","govt","") -> 1.369 | E9: =[1]!YBHIST("10 Year Treasury",$B9,"YldtoMat","govt","") -> 2.802 | F9: =[1]!YBHIST("30 Year Treasury",$B9,"YldtoMat","govt","") -> 4.133 | G9: =E9-C9 -> 2.439
B10: ='Data Set'!B10 -> 40786 | C10: =[1]!YBHIST("2 Year Treasury",$B10,"YldtoMat","govt","") -> 0.2 | D10: =[1]!YBHIST("5 Year Treasury",$B10,"YldtoMat","govt","") -> 0.95 | E10: =[1]!YBHIST("10 Year Treasury",$B10,"YldtoMat","govt","") -> 2.222 | F10: =[1]!YBHIST("30 Year Treasury",$B10,"YldtoMat","govt","") -> 3.595 | G10: =E10-C10 -> 2.022
B11: ='Data Set'!B11 -> 40816 | C11: =[1]!YBHIST("2 Year Treasury",$B11,"YldtoMat","govt","") -> 0.251 | D11: =[1]!YBHIST("5 Year Treasury",$B11,"YldtoMat","govt","") -> 0.963 | E11: =[1]!YBHIST("10 Year Treasury",$B11,"YldtoMat","govt","") -> 1.924 | F11: =[1]!YBHIST("30 Year Treasury",$B11,"YldtoMat","govt","") -> 2.92 | G11: =E11-C11 -> 1.673
B12: ='Data Set'!B12 -> 40847 | C12: =[1]!YBHIST("2 Year Treasury",$B12,"YldtoMat","govt","") -> 0.258 | D12: =[1]!YBHIST("5 Year Treasury",$B12,"YldtoMat","govt","") -> 1.006 | E12: =[1]!YBHIST("10 Year Treasury",$B12,"YldtoMat","govt","") -> 2.166 | F12: =[1]!YBHIST("30 Year Treasury",$B12,"YldtoMat","govt","") -> 3.199 | G12: =E12-C12 -> 1.908
B13: ='Data Set'!B13 -> 40877 | C13: =[1]!YBHIST("2 Year Treasury",$B13,"YldtoMat","govt","") -> 0.254 | D13: =[1]!YBHIST("5 Year Treasury",$B13,"YldtoMat","govt","") -> 0.949 | E13: =[1]!YBHIST("10 Year Treasury",$B13,"YldtoMat","govt","") -> 2.063 | F13: =[1]!YBHIST("30 Year Treasury",$B13,"YldtoMat","govt","") -> 3.061 | G13: =E13-C13 -> 1.809
B14: ='Data Set'!B14 -> 40907 | C14: =[1]!YBHIST("2 Year Treasury",$B14,"YldtoMat","govt","") -> 0.247 | D14: =[1]!YBHIST("5 Year Treasury",$B14,"YldtoMat","govt","") -> 0.837 | E14: =[1]!YBHIST("10 Year Treasury",$B14,"YldtoMat","govt","") -> 1.876 | F14: =[1]!YBHIST("30 Year Treasury",$B14,"YldtoMat","govt","") -> 2.89 | G14: =E14-C14 -> 1.629
B15: ='Data Set'!B15 -> 40939 | C15: =[1]!YBHIST("2 Year Treasury",$B15,"YldtoMat","govt","") -> 0.215 | D15: =[1]!YBHIST("5 Year Treasury",$B15,"YldtoMat","govt","") -> 0.709 | E15: =[1]!YBHIST("10 Year Treasury",$B15,"YldtoMat","govt","") -> 1.799 | F15: =[1]!YBHIST("30 Year Treasury",$B15,"YldtoMat","govt","") -> 2.934 | G15: =E15-C15 -> 1.584
B16: ='Data Set'!B16 -> 40968 | C16: =[1]!YBHIST("2 Year Treasury",$B16,"YldtoMat","govt","") -> 0.301 | D16: =[1]!YBHIST("5 Year Treasury",$B16,"YldtoMat","govt","") -> 0.873 | E16: =[1]!YBHIST("10 Year Treasury",$B16,"YldtoMat","govt","") -> 1.979 | F16: =[1]!YBHIST("30 Year Treasury",$B16,"YldtoMat","govt","") -> 3.086 | G16: =E16-C16 -> 1.678
... B69: ='Data Set'!B69 -> 42580 | C69: =[1]!YBHIST("2 Year Treasury",$B69,"YldtoMat","govt","") -> 0.663 | D69: =[1]!YBHIST("5 Year Treasury",$B69,"YldtoMat","govt","") -> 1.032 | E69: =[1]!YBHIST("10 Year Treasury",$B69,"YldtoMat","govt","") -> 1.456 | F69: =[1]!YBHIST("30 Year Treasury",$B69,"YldtoMat","govt","") -> 2.181 | G69: =E69-C69 -> 0.793

Sheet ppm risk premium
D3: Avg WAC | E3: Survey Rate | F3: Risk Premium(Weekly) | G3: CurretCoupon | H3: ServSpread | I3: Daily Mtg Rate | J3: Risk Premium(Daily) | L3: asOf | M3: MonthEnd | N3: AVGWAC | P3: asOf | Q3: Column1 | R3: RawRate | S3: Points | T3: Rate | V3: AsOfDate | W3: TickerName | X3: SeriesNumValue | Z3: AsofDate | AA3: ServicingSpread
C4: ='Data Set'!B5 -> 40633 | D4: =VLOOKUP(C4,M:N,2,0) -> 5.5386981 | E4: =VLOOKUP(C4,Q:T,4,0) -> 4.795 | F4: =D4-E4 -> 0.74369809 | G4: =VLOOKUP(TEXT(C4,"yyyy-mm-dd"),V:X,3,0) -> 4.2632122 | H4: =VLOOKUP(TEXT(C4,"yyyy-mm-dd"),Z:AA,2,0) -> 0.52011487 | I4: =G4+H4 -> 4.7833271 | J4: =D4-I4 -> 0.75537102 | L4: 42583 | M4: =IF(WEEKDAY(DATE(YEAR(L4),MONTH(L4)+1,0),2)=6,DATE(YEAR(L4),MONTH(L4)+1,0)-1,IF(WEEKDAY(DATE(YEAR(L4),MONTH(L4)+1,0),2)=7,DATE(YEAR(L4),MONTH(L4)+1,0)-2,DATE(YEAR(L4),MONTH(L4)+1,0))) -> 42613 | N4: 4.0313508 | P4: 2016-07-27 | Q4: =DATE(YEAR(OneWeekMtgRatesDataTable75[[#This Row],[asOf]]),MONTH(OneWeekMtgRatesDataTable75[[#This Row],[asOf]]),DAY(OneWeekMtgRatesDataTable75[[#This Row],[asOf]])) -> 42578 | R4: 3.48 | S4: 0.5 | T4: 3.355 | V4: 2016-08-02 | W4: FN_CMM_30Yr | X4: 2.3285238 | Z4: 2016-08-02 | AA4: 0.98723562
C5: ='Data Set'!B6 -> 40662 | D5: =VLOOKUP(C5,M:N,2,0) -> 5.5269247 | E5: =VLOOKUP(C5,Q:T,4,0) -> 4.635 | F5: =D5-E5 -> 0.8919247 | G5: =VLOOKUP(TEXT(C5,"yyyy-mm-dd"),V:X,3,0) -> 4.0911415 | H5: =VLOOKUP(TEXT(C5,"yyyy-mm-dd"),Z:AA,2,0) -> 0.52643167 | I5: =G5+H5 -> 4.6175732 | J5: =D5-I5 -> 0.90935152 | L5: 42552 | M5: =IF(WEEKDAY(DATE(YEAR(L5),MONTH(L5)+1,0),2)=6,DATE(YEAR(L5),MONTH(L5)+1,0)-1,IF(WEEKDAY(DATE(YEAR(L5),MONTH(L5)+1,0),2)=7,DATE(YEAR(L5),MONTH(L5)+1,0)-2,DATE(YEAR(L5),MONTH(L5)+1,0))) -> 42580 | N5: 4.3772716 | P5: 2016-07-26 | Q5: =DATE(YEAR(OneWeekMtgRatesDataTable75[[#This Row],[asOf]]),MONTH(OneWeekMtgRatesDataTable75[[#This Row],[asOf]]),DAY(OneWeekMtgRatesDataTable75[[#This Row],[asOf]])) -> 42577 | R5: 3.48 | S5: 0.5 | T5: 3.355 | V5: 2016-08-01 | W5: FN_CMM_30Yr | X5: 2.2903257 | Z5: 2016-08-01 | AA5: 0.98723562
C6: ='Data Set'!B7 -> 40694 | D6: =VLOOKUP(C6,M:N,2,0) -> 5.516896 | E6: =VLOOKUP(C6,Q:T,4,0) -> 4.45 | F6: =D6-E6 -> 1.066896 | G6: =VLOOKUP(TEXT(C6,"yyyy-mm-dd"),V:X,3,0) -> 3.9323543 | H6: =VLOOKUP(TEXT(C6,"yyyy-mm-dd"),Z:AA,2,0) -> 0.53274006 | I6: =G6+H6 -> 4.4650943 | J6: =D6-I6 -> 1.0518016 | L6: 42522 | M6: =IF(WEEKDAY(DATE(YEAR(L6),MONTH(L6)+1,0),2)=6,DATE(YEAR(L6),MONTH(L6)+1,0)-1,IF(WEEKDAY(DATE(YEAR(L6),MONTH(L6)+1,0),2)=7,DATE(YEAR(L6),MONTH(L6)+1,0)-2,DATE(YEAR(L6),MONTH(L6)+1,0))) -> 42551 | N6: 4.3888062 | P6: 2016-07-25 | Q6: =DATE(YEAR(OneWeekMtgRatesDataTable75[[#This Row],[asOf]]),MONTH(OneWeekMtgRatesDataTable75[[#This Row],[asOf]]),DAY(OneWeekMtgRatesDataTable75[[#This Row],[asOf]])) -> 42576 | R6: 3.48 | S6: 0.5 | T6: 3.355 | V6: 2016-07-29 | W6: FN_CMM_30Yr | X6: 2.2658761 | Z6: 2016-07-29 | AA6: 0.98723562
C7: ='Data Set'!B8 -> 40724 | D7: =VLOOKUP(C7,M:N,2,0) -> 5.5064525 | E7: =VLOOKUP(C7,Q:T,4,0) -> 4.525 | F7: =D7-E7 -> 0.98145252 | G7: =VLOOKUP(TEXT(C7,"yyyy-mm-dd"),V:X,3,0) -> 4.0210178 | H7: =VLOOKUP(TEXT(C7,"yyyy-mm-dd"),Z:AA,2,0) -> 0.53031097 | I7: =G7+H7 -> 4.5513288 | J7: =D7-I7 -> 0.95512376 | L7: 42491 | M7: =IF(WEEKDAY(DATE(YEAR(L7),MONTH(L7)+1,0),2)=6,DATE(YEAR(L7),MONTH(L7)+1,0)-1,IF(WEEKDAY(DATE(YEAR(L7),MONTH(L7)+1,0),2)=7,DATE(YEAR(L7),MONTH(L7)+1,0)-2,DATE(YEAR(L7),MONTH(L7)+1,0))) -> 42521 | N7: 4.3996487 | P7: 2016-07-22 | Q7: =DATE(YEAR(OneWeekMtgRatesDataTable75[[#This Row],[asOf]]),MONTH(OneWeekMtgRatesDataTable75[[#This Row],[asOf]]),DAY(OneWeekMtgRatesDataTable75[[#This Row],[asOf]])) -> 42573 | R7: 3.48 | S7: 0.5 | T7: 3.355 | V7: 2016-07-28 | W7: FN_CMM_30Yr | X7: 2.3214949 | Z7: 2016-07-28 | AA7: 0.98723562
C8: ='Data Set'!B9 -> 40753 | D8: =VLOOKUP(C8,M:N,2,0) -> 5.4966047 | E8: =VLOOKUP(C8,Q:T,4,0) -> 4.34 | F8: =D8-E8 -> 1.1566047 | G8: =VLOOKUP(TEXT(C8,"yyyy-mm-dd"),V:X,3,0) -> 3.8088239 | H8: =VLOOKUP(TEXT(C8,"yyyy-mm-dd"),Z:AA,2,0) -> 0.55152112 | I8: =G8+H8 -> 4.360345 | J8: =D8-I8 -> 1.1362597 | L8: 42461 | M8: =IF(WEEKDAY(DATE(YEAR(L8),MONTH(L8)+1,0),2)=6,DATE(YEAR(L8),MONTH(L8)+1,0)-1,IF(WEEKDAY(DATE(YEAR(L8),MONTH(L8)+1,0),2)=7,DATE(YEAR(L8),MONTH(L8)+1,0)-2,DATE(YEAR(L8),MONTH(L8)+1,0))) -> 42489 | N8: 4.4094702 | P8: 2016-07-21 | Q8: =DATE(YEAR(OneWeekMtgRatesDataTable75[[#This Row],[asOf]]),MONTH(OneWeekMtgRatesDataTable75[[#This Row],[asOf]]),DAY(OneWeekMtgRatesDataTable75[[#This Row],[asOf]])) -> 42572 | R8: 3.48 | S8: 0.5 | T8: 3.355 | V8: 2016-07-27 | W8: FN_CMM_30Yr | X8: 2.3415397 | Z8: 2016-07-27 | AA8: 0.98469007
C9: ='Data Set'!B10 -> 40786 | D9: =VLOOKUP(C9,M:N,2,0) -> 5.4853483 | E9: =VLOOKUP(C9,Q:T,4,0) -> 4.145 | F9: =D9-E9 -> 1.3403483 | G9: =VLOOKUP(TEXT(C9,"yyyy-mm-dd"),V:X,3,0) -> 3.4273948 | H9: =VLOOKUP(TEXT(C9,"yyyy-mm-dd"),Z:AA,2,0) -> 0.75074778 | I9: =G9+H9 -> 4.1781426 | J9: =D9-I9 -> 1.3072057 | L9: 42430 | M9: =IF(WEEKDAY(DATE(YEAR(L9),MONTH(L9)+1,0),2)=6,DATE(YEAR(L9),MONTH(L9)+1,0)-1,IF(WEEKDAY(DATE(YEAR(L9),MONTH(L9)+1,0),2)=7,DATE(YEAR(L9),MONTH(L9)+1,0)-2,DATE(YEAR(L9),MONTH(L9)+1,0))) -> 42460 | N9: 4.4192941 | P9: 2016-07-20 | Q9: =DATE(YEAR(OneWeekMtgRatesDataTable75[[#This Row],[asOf]]),MONTH(OneWeekMtgRatesDataTable75[[#This Row],[asOf]]),DAY(OneWeekMtgRatesDataTable75[[#This Row],[asOf]])) -> 42571 | R9: 3.45 | S9: 0.5 | T9: 3.325 | V9: 2016-07-26 | W9: FN_CMM_30Yr | X9: 2.3913145 | Z9: 2016-07-26 | AA9: 0.98469007
C10: ='Data Set'!B11 -> 40816 | D10: =VLOOKUP(C10,M:N,2,0) -> 5.4705693 | E10: =VLOOKUP(C10,Q:T,4,0) -> 3.89 | F10: =D10-E10 -> 1.5805693 | G10: =VLOOKUP(TEXT(C10,"yyyy-mm-dd"),V:X,3,0) -> 3.0385262 | H10: =VLOOKUP(TEXT(C10,"yyyy-mm-dd"),Z:AA,2,0) -> 0.88375178 | I10: =G10+H10 -> 3.9222779 | J10: =D10-I10 -> 1.5482914 | L10: 42401 | M10: =IF(WEEKDAY(DATE(YEAR(L10),MONTH(L10)+1,0),2)=6,DATE(YEAR(L10),MONTH(L10)+1,0)-1,IF(WEEKDAY(DATE(YEAR(L10),MONTH(L10)+1,0),2)=7,DATE(YEAR(L10),MONTH(L10)+1,0)-2,DATE(YEAR(L10),MONTH(L10)+1,0))) -> 42429 | N10: 4.4265496 | P10: 2016-07-19 | Q10: =DATE(YEAR(OneWeekMtgRatesDataTable75[[#This Row],[asOf]]),MONTH(OneWeekMtgRatesDataTable75[[#This Row],[asOf]]),DAY(OneWeekMtgRatesDataTable75[[#This Row],[asOf]])) -> 42570 | R10: 3.45 | S10: 0.5 | T10: 3.325 | V10: 2016-07-25 | W10: FN_CMM_30Yr | X10: 2.382734 | Z10: 2016-07-25 | AA10: 0.98469007
C11: ='Data Set'!B12 -> 40847 | D11: =VLOOKUP(C11,M:N,2,0) -> 5.4564254 | E11: =VLOOKUP(C11,Q:T,4,0) -> 3.925 | F11: =D11-E11 -> 1.5314254 | G11: =VLOOKUP(TEXT(C11,"yyyy-mm-dd"),V:X,3,0) -> 3.251577 | H11: =VLOOKUP(TEXT(C11,"yyyy-mm-dd"),Z:AA,2,0) -> 0.72847915 | I11: =G11+H11 -> 3.9800561 | J11: =D11-I11 -> 1.4763692 | L11: 42370 | M11: =IF(WEEKDAY(DATE(YEAR(L11),MONTH(L11)+1,0),2)=6,DATE(YEAR(L11),MONTH(L11)+1,0)-1,IF(WEEKDAY(DATE(YEAR(L11),MONTH(L11)+1,0),2)=7,DATE(YEAR(L11),MONTH(L11)+1,0)-2,DATE(YEAR(L11),MONTH(L11)+1,0))) -> 42398 | N11: 4.4319261 | P11: 2016-07-18 | Q11: =DATE(YEAR(OneWeekMtgRatesDataTable75[[#This Row],[asOf]]),MONTH(OneWeekMtgRatesDataTable75[[#This Row],[asOf]]),DAY(OneWeekMtgRatesDataTable75[[#This Row],[asOf]])) -> 42569 | R11: 3.45 | S11: 0.5 | T11: 3.325 | V11: 2016-07-22 | W11: FN_CMM_30Yr | X11: 2.3723679 | Z11: 2016-07-22 | AA11: 0.98469007
C12: ='Data Set'!B13 -> 40877 | D12: =VLOOKUP(C12,M:N,2,0) -> 5.4364669 | E12: =VLOOKUP(C12,Q:T,4,0) -> 3.925 | F12: =D12-E12 -> 1.5114669 | G12: =VLOOKUP(TEXT(C12,"yyyy-mm-dd"),V:X,3,0) -> 3.1770193 | H12: =VLOOKUP(TEXT(C12,"yyyy-mm-dd"),Z:AA,2,0) -> 0.73271176 | I12: =G12+H12 -> 3.9097311 | J12: =D12-I12 -> 1.5267358 | L12: 42339 | M12: =IF(WEEKDAY(DATE(YEAR(L12),MONTH(L12)+1,0),2)=6,DATE(YEAR(L12),MONTH(L12)+1,0)-1,IF(WEEKDAY(DATE(YEAR(L12),MONTH(L12)+1,0),2)=7,DATE(YEAR(L12),MONTH(L12)+1,0)-2,DATE(YEAR(L12),MONTH(L12)+1,0))) -> 42369 | N12: 4.4390051 | P12: 2016-07-15 | Q12: =DATE(YEAR(OneWeekMtgRatesDataTable75[[#This Row],[asOf]]),MONTH(OneWeekMtgRatesDataTable75[[#This Row],[asOf]]),DAY(OneWeekMtgRatesDataTable75[[#This Row],[asOf]])) -> 42566 | R12: 3.45 | S12: 0.5 | T12: 3.325 | V12: 2016-07-21 | W12: FN_CMM_30Yr | X12: 2.3508657 | Z12: 2016-07-21 | AA12: 0.98469007
C13: ='Data Set'!B14 -> 40907 | D13: =VLOOKUP(C13,M:N,2,0) -> 5.4070811 | E13: =VLOOKUP(C13,Q:T,4,0) -> 3.86 | F13: =D13-E13 -> 1.5470811 | G13: =VLOOKUP(TEXT(C13,"yyyy-mm-dd"),V:X,3,0) -> 3.0169009 | H13: =VLOOKUP(TEXT(C13,"yyyy-mm-dd"),Z:AA,2,0) -> 0.75824651 | I13: =G13+H13 -> 3.7751474 | J13: =D13-I13 -> 1.6319337 | L13: 42309 | M13: =IF(WEEKDAY(DATE(YEAR(L13),MONTH(L13)+1,0),2)=6,DATE(YEAR(L13),MONTH(L13)+1,0)-1,IF(WEEKDAY(DATE(YEAR(L13),MONTH(L13)+1,0),2)=7,DATE(YEAR(L13),MONTH(L13)+1,0)-2,DATE(YEAR(L13),MONTH(L13)+1,0))) -> 42338 | N13: 4.4463923 | P13: 2016-07-14 | Q13: =DATE(YEAR(OneWeekMtgRatesDataTable75[[#This Row],[asOf]]),MONTH(OneWeekMtgRatesDataTable75[[#This Row],[asOf]]),DAY(OneWeekMtgRatesDataTable75[[#This Row],[asOf]])) -> 42565 | R13: 3.45 | S13: 0.5 | T13: 3.325 | V13: 2016-07-20 | W13: FN_CMM_30Yr | X13: 2.3467781 | Z13: 2016-07-20 | AA13: 1.0377974
C14: ='Data Set'!B15 -> 40939 | D14: =VLOOKUP(C14,M:N,2,0) -> 5.3841265 | E14: =VLOOKUP(C14,Q:T,4,0) -> 3.82 | F14: =D14-E14 -> 1.5641265 | G14: =VLOOKUP(TEXT(C14,"yyyy-mm-dd"),V:X,3,0) -> 2.7762953 | H14: =VLOOKUP(TEXT(C14,"yyyy-mm-dd"),Z:AA,2,0) -> 0.9493042 | I14: =G14+H14 -> 3.7255995 | J14: =D14-I14 -> 1.658527 | L14: 42278 | M14: =IF(WEEKDAY(DATE(YEAR(L14),MONTH(L14)+1,0),2)=6,DATE(YEAR(L14),MONTH(L14)+1,0)-1,IF(WEEKDAY(DATE(YEAR(L14),MONTH(L14)+1,0),2)=7,DATE(YEAR(L14),MONTH(L14)+1,0)-2,DATE(YEAR(L14),MONTH(L14)+1,0))) -> 42307 | N14: 4.452556 | P14: 2016-07-13 | Q14: =DATE(YEAR(OneWeekMtgRatesDataTable75[[#This Row],[asOf]]),MONTH(OneWeekMtgRatesDataTable75[[#This Row],[asOf]]),DAY(OneWeekMtgRatesDataTable75[[#This Row],[asOf]])) -> 42564 | R14: 3.42 | S14: 0.5 | T14: 3.295 | V14: 2016-07-19 | W14: FN_CMM_30Yr | X14: 2.328033 | Z14: 2016-07-19 | AA14: 1.0377974
C15: ='Data Set'!B16 -> 40968 | D15: =VLOOKUP(C15,M:N,2,0) -> 5.3594349 | E15: =VLOOKUP(C15,Q:T,4,0) -> 3.85 | F15: =D15-E15 -> 1.5094349 | G15: =VLOOKUP(TEXT(C15,"yyyy-mm-dd"),V:X,3,0) -> 2.8817315 | H15: =VLOOKUP(TEXT(C15,"yyyy-mm-dd"),Z:AA,2,0) -> 1.0111707 | I15: =G15+H15 -> 3.8929022 | J15: =D15-I15 -> 1.4665326 | L15: 42248 | M15: =IF(WEEKDAY(DATE(YEAR(L15),MONTH(L15)+1,0),2)=6,DATE(YEAR(L15),MONTH(L15)+1,0)-1,IF(WEEKDAY(DATE(YEAR(L15),MONTH(L15)+1,0),2)=7,DATE(YEAR(L15),MONTH(L15)+1,0)-2,DATE(YEAR(L15),MONTH(L15)+1,0))) -> 42277 | N15: 4.4597228 | P15: 2016-07-12 | Q15: =DATE(YEAR(OneWeekMtgRatesDataTable75[[#This Row],[asOf]]),MONTH(OneWeekMtgRatesDataTable75[[#This Row],[asOf]]),DAY(OneWeekMtgRatesDataTable75[[#This Row],[asOf]])) -> 42563 | R15: 3.42 | S15: 0.5 | T15: 3.295 | V15: 2016-07-18 | W15: FN_CMM_30Yr | X15: 2.3547085 | Z15: 2016-07-18 | AA15: 1.0377974
... C61: ='Data Set'!B62 -> 42369 | D61: =VLOOKUP(C61,M:N,2,0) -> 4.4390051 | E61: =VLOOKUP(C61,Q:T,4,0) -> 3.87 | F61: =D61-E61 -> 0.56900514 | G61: =VLOOKUP(TEXT(C61,"yyyy-mm-dd"),V:X,3,0) -> 3.0053894 | H61: =VLOOKUP(TEXT(C61,"yyyy-mm-dd"),Z:AA,2,0) -> 0.87590263 | I61: =G61+H61 -> 3.881292 | J61: =D61-I61 -> 0.55771311 | L61: 40848 | M61: =IF(WEEKDAY(DATE(YEAR(L61),MONTH(L61)+1,0),2)=6,DATE(YEAR(L61),MONTH(L61)+1,0)-1,IF(WEEKDAY(DATE(YEAR(L61),MONTH(L61)+1,0),2)=7,DATE(YEAR(L61),MONTH(L61)+1,0)-2,DATE(YEAR(L61),MONTH(L61)+1,0))) -> 40877 | N61: 5.4364669 | P61: 2016-05-05 | Q61: =DATE(YEAR(OneWeekMtgRatesDataTable75[[#This Row],[asOf]]),MONTH(OneWeekMtgRatesDataTable75[[#This Row],[asOf]]),DAY(OneWeekMtgRatesDataTable75[[#This Row],[asOf]])) -> 42495 | R61: 3.57 | S61: 0.5 | T61: 3.445 | V61: 2016-05-11 | W61: FN_CMM_30Yr | X61: 2.5137547 | Z61: 2016-05-10 | AA61: 0.93901474
C62: ='Data Set'!B63 -> 42398 | D62: =VLOOKUP(C62,M:N,2,0) -> 4.4319261 | E62: =T4 -> 3.355 | F62: =D62-E62 -> 1.0769261 | G62: =VLOOKUP(TEXT(C62,"yyyy-mm-dd"),V:X,3,0) -> 2.6475345 | H62: =VLOOKUP(TEXT(C62,"yyyy-mm-dd"),Z:AA,2,0) -> 0.93208019 | I62: =G62+H62 -> 3.5796147 | J62: =D62-I62 -> 0.85231135 | L62: 40817 | M62: =IF(WEEKDAY(DATE(YEAR(L62),MONTH(L62)+1,0),2)=6,DATE(YEAR(L62),MONTH(L62)+1,0)-1,IF(WEEKDAY(DATE(YEAR(L62),MONTH(L62)+1,0),2)=7,DATE(YEAR(L62),MONTH(L62)+1,0)-2,DATE(YEAR(L62),MONTH(L62)+1,0))) -> 40847 | N62: 5.4564254 | P62: 2016-05-04 | Q62: =DATE(YEAR(OneWeekMtgRatesDataTable75[[#This Row],[asOf]]),MONTH(OneWeekMtgRatesDataTable75[[#This Row],[asOf]]),DAY(OneWeekMtgRatesDataTable75[[#This Row],[asOf]])) -> 42494 | R62: 3.61 | S62: 0.6 | T62: 3.51 | V62: 2016-05-10 | W62: FN_CMM_30Yr | X62: 2.5182073 | Z62: 2016-05-09 | AA62: 0.93901474
C63: 42429 | D63: =VLOOKUP(C63,M:N,2,0) -> 4.4265496 | G63: =VLOOKUP(TEXT(C63,"yyyy-mm-dd"),V:X,3,0) -> 2.5273546 | H63: =VLOOKUP(TEXT(C63,"yyyy-mm-dd"),Z:AA,2,0) -> 0.98090022 | I63: =G63+H63 -> 3.5082548 | J63: =D63-I63 -> 0.91829483 | L63: 40787 | M63: =IF(WEEKDAY(DATE(YEAR(L63),MONTH(L63)+1,0),2)=6,DATE(YEAR(L63),MONTH(L63)+1,0)-1,IF(WEEKDAY(DATE(YEAR(L63),MONTH(L63)+1,0),2)=7,DATE(YEAR(L63),MONTH(L63)+1,0)-2,DATE(YEAR(L63),MONTH(L63)+1,0))) -> 40816 | N63: 5.4705693 | P63: 2016-05-03 | Q63: =DATE(YEAR(OneWeekMtgRatesDataTable75[[#This Row],[asOf]]),MONTH(OneWeekMtgRatesDataTable75[[#This Row],[asOf]]),DAY(OneWeekMtgRatesDataTable75[[#This Row],[asOf]])) -> 42493 | R63: 3.61 | S63: 0.6 | T63: 3.51 | V63: 2016-05-09 | W63: FN_CMM_30Yr | X63: 2.5026837 | Z63: 2016-05-06 | AA63: 0.93901474
C64: 42460 | D64: =VLOOKUP(C64,M:N,2,0) -> 4.4192941 | G64: =VLOOKUP(TEXT(C64,"yyyy-mm-dd"),V:X,3,0) -> 2.5397622 | H64: =VLOOKUP(TEXT(C64,"yyyy-mm-dd"),Z:AA,2,0) -> 0.94850785 | I64: =G64+H64 -> 3.48827 | J64: =D64-I64 -> 0.9310241 | L64: 40756 | M64: =IF(WEEKDAY(DATE(YEAR(L64),MONTH(L64)+1,0),2)=6,DATE(YEAR(L64),MONTH(L64)+1,0)-1,IF(WEEKDAY(DATE(YEAR(L64),MONTH(L64)+1,0),2)=7,DATE(YEAR(L64),MONTH(L64)+1,0)-2,DATE(YEAR(L64),MONTH(L64)+1,0))) -> 40786 | N64: 5.4853483 | P64: 2016-05-02 | Q64: =DATE(YEAR(OneWeekMtgRatesDataTable75[[#This Row],[asOf]]),MONTH(OneWeekMtgRatesDataTable75[[#This Row],[asOf]]),DAY(OneWeekMtgRatesDataTable75[[#This Row],[asOf]])) -> 42492 | R64: 3.61 | S64: 0.6 | T64: 3.51 | V64: 2016-05-06 | W64: FN_CMM_30Yr | X64: 2.5169225 | Z64: 2016-05-05 | AA64: 0.93901474
C65: 42489 | D65: =VLOOKUP(C65,M:N,2,0) -> 4.4094702 | G65: =VLOOKUP(TEXT(C65,"yyyy-mm-dd"),V:X,3,0) -> 2.5646427 | H65: =VLOOKUP(TEXT(C65,"yyyy-mm-dd"),Z:AA,2,0) -> 0.90735928 | I65: =G65+H65 -> 3.472002 | J65: =D65-I65 -> 0.93746825 | L65: 40725 | M65: =IF(WEEKDAY(DATE(YEAR(L65),MONTH(L65)+1,0),2)=6,DATE(YEAR(L65),MONTH(L65)+1,0)-1,IF(WEEKDAY(DATE(YEAR(L65),MONTH(L65)+1,0),2)=7,DATE(YEAR(L65),MONTH(L65)+1,0)-2,DATE(YEAR(L65),MONTH(L65)+1,0))) -> 40753 | N65: 5.4966047 | P65: 2016-04-29 | Q65: =DATE(YEAR(OneWeekMtgRatesDataTable75[[#This Row],[asOf]]),MONTH(OneWeekMtgRatesDataTable75[[#This Row],[asOf]]),DAY(OneWeekMtgRatesDataTable75[[#This Row],[asOf]])) -> 42489 | R65: 3.61 | S65: 0.6 | T65: 3.51 | V65: 2016-05-05 | W65: FN_CMM_30Yr | X65: 2.5164664 | Z65: 2016-05-04 | AA65: 0.90735928
C66: 42521 | D66: =VLOOKUP(C66,M:N,2,0) -> 4.3996487 | G66: =VLOOKUP(TEXT(C66,"yyyy-mm-dd"),V:X,3,0) -> 2.5912536 | H66: =VLOOKUP(TEXT(C66,"yyyy-mm-dd"),Z:AA,2,0) -> 0.89462225 | I66: =G66+H66 -> 3.4858759 | J66: =D66-I66 -> 0.91377286 | L66: 40695 | M66: =IF(WEEKDAY(DATE(YEAR(L66),MONTH(L66)+1,0),2)=6,DATE(YEAR(L66),MONTH(L66)+1,0)-1,IF(WEEKDAY(DATE(YEAR(L66),MONTH(L66)+1,0),2)=7,DATE(YEAR(L66),MONTH(L66)+1,0)-2,DATE(YEAR(L66),MONTH(L66)+1,0))) -> 40724 | N66: 5.5064525 | P66: 2016-04-28 | Q66: =DATE(YEAR(OneWeekMtgRatesDataTable75[[#This Row],[asOf]]),MONTH(OneWeekMtgRatesDataTable75[[#This Row],[asOf]]),DAY(OneWeekMtgRatesDataTable75[[#This Row],[asOf]])) -> 42488 | R66: 3.61 | S66: 0.6 | T66: 3.51 | V66: 2016-05-04 | W66: FN_CMM_30Yr | X66: 2.5521453 | Z66: 2016-05-03 | AA66: 0.90735928
C67: 42551 | D67: =VLOOKUP(C67,M:N,2,0) -> 4.3888062 | G67: =VLOOKUP(TEXT(C67,"yyyy-mm-dd"),V:X,3,0) -> 2.2474864 | H67: =VLOOKUP(TEXT(C67,"yyyy-mm-dd"),Z:AA,2,0) -> 0.99018949 | I67: =G67+H67 -> 3.2376759 | J67: =D67-I67 -> 1.1511304 | L67: 40664 | M67: =IF(WEEKDAY(DATE(YEAR(L67),MONTH(L67)+1,0),2)=6,DATE(YEAR(L67),MONTH(L67)+1,0)-1,IF(WEEKDAY(DATE(YEAR(L67),MONTH(L67)+1,0),2)=7,DATE(YEAR(L67),MONTH(L67)+1,0)-2,DATE(YEAR(L67),MONTH(L67)+1,0))) -> 40694 | N67: 5.516896 | P67: 2016-04-27 | Q67: =DATE(YEAR(OneWeekMtgRatesDataTable75[[#This Row],[asOf]]),MONTH(OneWeekMtgRatesDataTable75[[#This Row],[asOf]]),DAY(OneWeekMtgRatesDataTable75[[#This Row],[asOf]])) -> 42487 | R67: 3.66 | S67: 0.6 | T67: 3.56 | V67: 2016-05-03 | W67: FN_CMM_30Yr | X67: 2.5475266 | Z67: 2016-04-29 | AA67: 0.90735928
C68: 42580 | D68: =VLOOKUP(C68,M:N,2,0) -> 4.3772716 | G68: =VLOOKUP(TEXT(C68,"yyyy-mm-dd"),V:X,3,0) -> 2.2658761 | H68: =VLOOKUP(TEXT(C68,"yyyy-mm-dd"),Z:AA,2,0) -> 0.98723562 | I68: =G68+H68 -> 3.2531117 | J68: =D68-I68 -> 1.12416 | L68: 40634 | M68: =IF(WEEKDAY(DATE(YEAR(L68),MONTH(L68)+1,0),2)=6,DATE(YEAR(L68),MONTH(L68)+1,0)-1,IF(WEEKDAY(DATE(YEAR(L68),MONTH(L68)+1,0),2)=7,DATE(YEAR(L68),MONTH(L68)+1,0)-2,DATE(YEAR(L68),MONTH(L68)+1,0))) -> 40662 | N68: 5.5269247 | P68: 2016-04-26 | Q68: =DATE(YEAR(OneWeekMtgRatesDataTable75[[#This Row],[asOf]]),MONTH(OneWeekMtgRatesDataTable75[[#This Row],[asOf]]),DAY(OneWeekMtgRatesDataTable75[[#This Row],[asOf]])) -> 42486 | R68: 3.66 | S68: 0.6 | T68: 3.56 | V68: 2016-05-02 | W68: FN_CMM_30Yr | X68: 2.6083214 | Z68: 2016-04-28 | AA68: 0.90735928
L69: 40603 | M69: =IF(WEEKDAY(DATE(YEAR(L69),MONTH(L69)+1,0),2)=6,DATE(YEAR(L69),MONTH(L69)+1,0)-1,IF(WEEKDAY(DATE(YEAR(L69),MONTH(L69)+1,0),2)=7,DATE(YEAR(L69),MONTH(L69)+1,0)-2,DATE(YEAR(L69),MONTH(L69)+1,0))) -> 40633 | N69: 5.5386981 | P69: 2016-04-25 | Q69: =DATE(YEAR(OneWeekMtgRatesDataTable75[[#This Row],[asOf]]),MONTH(OneWeekMtgRatesDataTable75[[#This Row],[asOf]]),DAY(OneWeekMtgRatesDataTable75[[#This Row],[asOf]])) -> 42485 | R69: 3.66 | S69: 0.6 | T69: 3.56 | V69: 2016-04-29 | W69: FN_CMM_30Yr | X69: 2.5646427 | Z69: 2016-04-27 | AA69: 0.94834769
L70: 40575 | M70: =IF(WEEKDAY(DATE(YEAR(L70),MONTH(L70)+1,0),2)=6,DATE(YEAR(L70),MONTH(L70)+1,0)-1,IF(WEEKDAY(DATE(YEAR(L70),MONTH(L70)+1,0),2)=7,DATE(YEAR(L70),MONTH(L70)+1,0)-2,DATE(YEAR(L70),MONTH(L70)+1,0))) -> 40602 | N70: 5.5560536 | P70: 2016-04-22 | Q70: =DATE(YEAR(OneWeekMtgRatesDataTable75[[#This Row],[asOf]]),MONTH(OneWeekMtgRatesDataTable75[[#This Row],[asOf]]),DAY(OneWeekMtgRatesDataTable75[[#This Row],[asOf]])) -> 42482 | R70: 3.66 | S70: 0.6 | T70: 3.56 | V70: 2016-04-28 | W70: FN_CMM_30Yr | X70: 2.5822904 | Z70: 2016-04-26 | AA70: 0.94834769
