Workbook
Name temp: 'ppm risk premium'!$C$3:$D$261
Name temp: 'Refi%'!$AA$3:$AB$236
Name temp_1: 'ppm risk premium'!$G$4:$J$1065
Name temp1: 'LIBOR 1m'!$B$2:$E$1598

Sheet Data Set
B3: IOS Index
B4: Date | C4: Monthly Hedge Return (%) | D4: OAS | E4: IOS + TBA Carry (%) | F4: Realized Vol (Annualized %) | G4: Yield Curve 10-2 (bps) | H4: Prepayment Risk Premium (bps) | I4: Px/Coupon | J4: LIBOR 1m | K4: Refi Pct Pool | L4: Refi Pct Loan | M4: LL_Incentive | N4: Refi Index
B5: 40633 | C5: ='Return&Carry'!C3*100 -> 3.2147753 | D5: 12.454245 | E5: ='Return&Carry'!D3*100 -> 1.0991114 | F5: =VLOOKUP(TEXT(B5,"yyyy-mm-dd"),OneWeekMtgRatesDataTable7[],4,0)*SQRT(225)*100 -> 74.358832 | G5: =VLOOKUP(B5,'Yield Curve'!B5:G52,5,0)*100 -> 450.7 | H5: =VLOOKUP(B5,'ppm risk premium'!$O$3:$R$51,4,0)*100 -> 74.369809 | I5: 5.4040031 | J5: =VLOOKUP(B5,'LIBOR 1m'!$C$2:$E$4387,3,0) -> 0.24345 | K5: =VLOOKUP(B5,'Refi%'!L:N,2,0) -> 0.59322571 | L5: =VLOOKUP(B5,'Refi%'!L:N,3,0) -> 0.42282959 | M5: =VLOOKUP(B5,'Refi%'!L:P,5,0) -> 73.24907 | N5: =VLOOKUP(B5,'Refi%'!L:P,4,0) -> 2194.4
B6: 40662 | C6: ='Return&Carry'!C4*100 -> 3.9945301 | D6: -13.523942 | E6: ='Return&Carry'!D4*100 -> 1.0984369 | F6: =VLOOKUP(TEXT(B6,"yyyy-mm-dd"),OneWeekMtgRatesDataTable7[],4,0)*SQRT(225)*100 -> 60.151042 | G6: =VLOOKUP(B6,'Yield Curve'!B6:G53,5,0)*100 -> 440.4 | H6: =VLOOKUP(B6,'ppm risk premium'!$O$3:$R$51,4,0)*100 -> 89.19247 | I6: 5.4712823 | J6: =VLOOKUP(B6,'LIBOR 1m'!$C$2:$E$4387,3,0) -> 0.21025 | K6: =VLOOKUP(B6,'Refi%'!L:N,2,0) -> 0.59445921 | L6: =VLOOKUP(B6,'Refi%'!L:N,3,0) -> 0.44565512 | M6: =VLOOKUP(B6,'Refi%'!L:P,5,0) -> 80.106005 | N6: =VLOOKUP(B6,'Refi%'!L:P,4,0) -> 2220.1
B7: 40694 | C7: ='Return&Carry'!C5*100 -> 3.6836949 | D7: -39.195911 | E7: ='Return&Carry'!D5*100 -> 1.2359979 | F7: =VLOOKUP(TEXT(B7,"yyyy-mm-dd"),OneWeekMtgRatesDataTable7[],4,0)*SQRT(225)*100 -> 48.820059 | G7: =VLOOKUP(B7,'Yield Curve'!B7:G54,5,0)*100 -> 421.5 | H7: =VLOOKUP(B7,'ppm risk premium'!$O$3:$R$51,4,0)*100 -> 106.6896 | I7: 5.4954374 | J7: =VLOOKUP(B7,'LIBOR 1m'!$C$2:$E$4387,3,0) -> 0.19043 | K7: =VLOOKUP(B7,'Refi%'!L:N,2,0) -> 0.61599364 | L7: =VLOOKUP(B7,'Refi%'!L:N,3,0) -> 0.50568534 | M7: =VLOOKUP(B7,'Refi%'!L:P,5,0) -> 96.90583 | N7: =VLOOKUP(B7,'Refi%'!L:P,4,0) -> 2619.7
B8: 40724 | C8: ='Return&Carry'!C6*100 -> -0.89725231 | D8: -71.812763 | E8: ='Return&Carry'!D6*100 -> 1.1611305 | F8: =VLOOKUP(TEXT(B8,"yyyy-mm-dd"),OneWeekMtgRatesDataTable7[],4,0)*SQRT(225)*100 -> 51.642384 | G8: =VLOOKUP(B8,'Yield Curve'!B8:G55,5,0)*100 -> 438.2 | H8: =VLOOKUP(B8,'ppm risk premium'!$O$3:$R$51,4,0)*100 -> 98.145252 | I8: 5.5415672 | J8: =VLOOKUP(B8,'LIBOR 1m'!$C$2:$E$4387,3,0) -> 0.18555 | K8: =VLOOKUP(B8,'Refi%'!L:N,2,0) -> 0.69050447 | L8: =VLOOKUP(B8,'Refi%'!L:N,3,0) -> 0.55445083 | M8: =VLOOKUP(B8,'Refi%'!L:P,5,0) -> 105.06415 | N8: =VLOOKUP(B8,'Refi%'!L:P,4,0) -> 2527.5
B9: 40753 | C9: ='Return&Carry'!C7*100 -> -0.70542452 | D9: 14.555567 | E9: ='Return&Carry'!D7*100 -> 0.94859999 | F9: =VLOOKUP(TEXT(B9,"yyyy-mm-dd"),OneWeekMtgRatesDataTable7[],4,0)*SQRT(225)*100 -> 60.008169 | G9: =VLOOKUP(B9,'Yield Curve'!B9:G56,5,0)*100 -> 413.3 | H9: =VLOOKUP(B9,'ppm risk premium'!$O$3:$R$51,4,0)*100 -> 115.66047 | I9: 5.2080149 | J9: =VLOOKUP(B9,'LIBOR 1m'!$C$2:$E$4387,3,0) -> 0.1911 | K9: =VLOOKUP(B9,'Refi%'!L:N,2,0) -> 0.61660059 | L9: =VLOOKUP(B9,'Refi%'!L:N,3,0) -> 0.52333295 | M9: =VLOOKUP(B9,'Refi%'!L:P,5,0) -> 97.844637 | N9: =VLOOKUP(B9,'Refi%'!L:P,4,0) -> 2974.1
B10: 40786 | C10: ='Return&Carry'!C8*100 -> -12.940149 | D10: 413.13076 | E10: ='Return&Carry'!D8*100 -> 0.98897456 | F10: =VLOOKUP(TEXT(B10,"yyyy-mm-dd"),OneWeekMtgRatesDataTable7[],4,0)*SQRT(225)*100 -> 99.218155 | G10: =VLOOKUP(B10,'Yield Curve'!B10:G57,5,0)*100 -> 359.5 | H10: =VLOOKUP(B10,'ppm risk premium'!$O$3:$R$51,4,0)*100 -> 134.03483 | I10: 4.1199718 | J10: =VLOOKUP(B10,'LIBOR 1m'!$C$2:$E$4387,3,0) -> 0.2215 | K10: =VLOOKUP(B10,'Refi%'!L:N,2,0) -> 0.84714025 | L10: =VLOOKUP(B10,'Refi%'!L:N,3,0) -> 0.73013076 | M10: =VLOOKUP(B10,'Refi%'!L:P,5,0) -> 131.04921 | N10: =VLOOKUP(B10,'Refi%'!L:P,4,0) -> 3601.3
B11: 40816 | C11: ='Return&Carry'!C9*100 -> -10.646399 | D11: 707.36595 | E11: ='Return&Carry'!D9*100 -> 1.4023414 | F11: =VLOOKUP(TEXT(B11,"yyyy-mm-dd"),OneWeekMtgRatesDataTable7[],4,0)*SQRT(225)*100 -> 121.17161 | G11: =VLOOKUP(B11,'Yield Curve'!B11:G58,5,0)*100 -> 292 | H11: =VLOOKUP(B11,'ppm risk premium'!$O$3:$R$51,4,0)*100 -> 158.05693 | I11: 3.3173716 | J11: =VLOOKUP(B11,'LIBOR 1m'!$C$2:$E$4387,3,0) -> 0.23944 | K11: =VLOOKUP(B11,'Refi%'!L:N,2,0) -> 0.94644262 | L11: =VLOOKUP(B11,'Refi%'!L:N,3,0) -> 0.83535228 | M11: =VLOOKUP(B11,'Refi%'!L:P,5,0) -> 149.98981 | N11: =VLOOKUP(B11,'Refi%'!L:P,4,0) -> 4241.8
B12: 40847 | C12: ='Return&Carry'!C10*100 -> 2.3593585 | D12: 688.11427 | E12: ='Return&Carry'!D10*100 -> 1.2905992 | F12: =VLOOKUP(TEXT(B12,"yyyy-mm-dd"),OneWeekMtgRatesDataTable7[],4,0)*SQRT(225)*100 -> 126.4888 | G12: =VLOOKUP(B12,'Yield Curve'!B12:G59,5,0)*100 -> 319.9 | H12: =VLOOKUP(B12,'ppm risk premium'!$O$3:$R$51,4,0)*100 -> 153.14254 | I12: 3.4720778 | J12: =VLOOKUP(B12,'LIBOR 1m'!$C$2:$E$4387,3,0) -> 0.24528 | K12: =VLOOKUP(B12,'Refi%'!L:N,2,0) -> 0.86512672 | L12: =VLOOKUP(B12,'Refi%'!L:N,3,0) -> 0.7703392 | M12: =VLOOKUP(B12,'Refi%'!L:P,5,0) -> 135.74535 | N12: =VLOOKUP(B12,'Refi%'!L:P,4,0) -> 3695
B13: 40877 | C13: ='Return&Carry'!C11*100 -> 1.4407939 | D13: 623.10169 | E13: ='Return&Carry'!D11*100 -> 0.70135917 | F13: =VLOOKUP(TEXT(B13,"yyyy-mm-dd"),OneWeekMtgRatesDataTable7[],4,0)*SQRT(225)*100 -> 107.84839 | G13: =VLOOKUP(B13,'Yield Curve'!B13:G60,5,0)*100 -> 306.1 | H13: =VLOOKUP(B13,'ppm risk premium'!$O$3:$R$51,4,0)*100 -> 151.14669 | I13: 3.4446943 | J13: =VLOOKUP(B13,'LIBOR 1m'!$C$2:$E$4387,3,0) -> 0.27144 | K13: =VLOOKUP(B13,'Refi%'!L:N,2,0) -> 0.94997171 | L13: =VLOOKUP(B13,'Refi%'!L:N,3,0) -> 0.80850149 | M13: =VLOOKUP(B13,'Refi%'!L:P,5,0) -> 146.78788 | N13: =VLOOKUP(B13,'Refi%'!L:P,4,0) -> 2941.3
B14: 40907 | C14: ='Return&Carry'!C12*100 -> 0.5832688 | D14: 610.59818 | E14: ='Return&Carry'!D12*100 -> 0.39545841 | F14: =VLOOKUP(TEXT(B14,"yyyy-mm-dd"),OneWeekMtgRatesDataTable7[],4,0)*SQRT(225)*100 -> 84.15733 | G14: =VLOOKUP(B14,'Yield Curve'!B14:G61,5,0)*100 -> 289 | H14: =VLOOKUP(B14,'ppm risk premium'!$O$3:$R$51,4,0)*100 -> 154.70811 | I14: 3.3659589 | J14: =VLOOKUP(B14,'LIBOR 1m'!$C$2:$E$4387,3,0) -> 0.2953 | K14: =VLOOKUP(B14,'Refi%'!L:N,2,0) -> 0.9476226 | L14: =VLOOKUP(B14,'Refi%'!L:N,3,0) -> 0.81734633 | M14: =VLOOKUP(B14,'Refi%'!L:P,5,0) -> 147.01164 | N14: =VLOOKUP(B14,'Refi%'!L:P,4,0) -> 3608.1
B15: 40939 | C15: ='Return&Carry'!C13*100 -> -3.0247515 | D15: 465.33199 | E15: ='Return&Carry'!D13*100 -> 0.93155585 | F15: =VLOOKUP(TEXT(B15,"yyyy-mm-dd"),OneWeekMtgRatesDataTable7[],4,0)*SQRT(225)*100 -> 67.218531 | G15: =VLOOKUP(B15,'Yield Curve'!B15:G62,5,0)*100 -> 293.4 | H15: =VLOOKUP(B15,'ppm risk premium'!$O$3:$R$51,4,0)*100 -> 156.41265 | I15: 3.0653812 | J15: =VLOOKUP(B15,'LIBOR 1m'!$C$2:$E$4387,3,0) -> 0.26475 | K15: =VLOOKUP(B15,'Refi%'!L:N,2,0) -> 0.91861521 | L15: =VLOOKUP(B15,'Refi%'!L:N,3,0) -> 0.78339394 | M15: =VLOOKUP(B15,'Refi%'!L:P,5,0) -> 141.20356 | N15: =VLOOKUP(B15,'Refi%'!L:P,4,0) -> 4184.3
B16: 40968 | C16: ='Return&Carry'!C14*100 -> 11.557044 | D16: 220.00245 | E16: ='Return&Carry'!D14*100 -> 1.7106233 | F16: =VLOOKUP(TEXT(B16,"yyyy-mm-dd"),OneWeekMtgRatesDataTable7[],4,0)*SQRT(225)*100 -> 70.470813 | G16: =VLOOKUP(B16,'Yield Curve'!B16:G63,5,0)*100 -> 308.6 | H16: =VLOOKUP(B16,'ppm risk premium'!$O$3:$R$51,4,0)*100 -> 150.94349 | I16: 3.4491554 | J16: =VLOOKUP(B16,'LIBOR 1m'!$C$2:$E$4387,3,0) -> 0.2435 | K16: =VLOOKUP(B16,'Refi%'!L:N,2,0) -> 0.90921329 | L16: =VLOOKUP(B16,'Refi%'!L:N,3,0) -> 0.76669717 | M16: =VLOOKUP(B16,'Refi%'!L:P,5,0) -> 138.01155 | N16: =VLOOKUP(B16,'Refi%'!L:P,4,0) -> 4379.1
... B52: 42062 | C52: ='Return&Carry'!C50*100 -> 11.157649 | D52: -86.739531 | E52: ='Return&Carry'!D50*100 -> 1.6224449 | F52: =VLOOKUP(TEXT(B52,"yyyy-mm-dd"),OneWeekMtgRatesDataTable7[],4,0)*SQRT(225)*100 -> 73.252678 | G52: =VLOOKUP(B52,'Yield Curve'!B52:G99,5,0)*100 -> 259.7 | H52: =VLOOKUP(B52,'ppm risk premium'!$O$3:$R$51,4,0)*100 -> 88.618659 | I52: 5.4744343 | J52: =VLOOKUP(B52,'LIBOR 1m'!$C$2:$E$4387,3,0) -> 0.173 | K52: =VLOOKUP(B52,'Refi%'!L:N,2,0) -> 0.61098575 | L52: =VLOOKUP(B52,'Refi%'!L:N,3,0) -> 0.56144623 | M52: =VLOOKUP(B52,'Refi%'!L:P,5,0) -> 79.090218 | N52: =VLOOKUP(B52,'Refi%'!L:P,4,0) -> 1740.3
B53: 42094 | C53: ='Return&Carry'!C51*100 -> -0.70144081 | D53: -96.814517 | E53: ='Return&Carry'!D51*100 -> 0.98971487 | F53: =VLOOKUP(TEXT(B53,"yyyy-mm-dd"),OneWeekMtgRatesDataTable7[],4,0)*SQRT(225)*100 -> 78.458334 | G53: =VLOOKUP(B53,'Yield Curve'!B53:G100,5,0)*100 -> 254.4 | H53: =VLOOKUP(B53,'ppm risk premium'!$O$3:$R$52,4,0)*100 -> 92.381279 | I53: 5.3320437 | J53: =VLOOKUP(B53,'LIBOR 1m'!$C$2:$E$4387,3,0) -> 0.17625 | K53: =VLOOKUP(B53,'Refi%'!L:N,2,0) -> 0.64195316 | L53: =VLOOKUP(B53,'Refi%'!L:N,3,0) -> 0.61985541 | M53: =VLOOKUP(B53,'Refi%'!L:P,5,0) -> 88.714641 | N53: =VLOOKUP(B53,'Refi%'!L:P,4,0) -> 1941.6
B54: 42124 | C54: ='Return&Carry'!C52*100 -> 4.8601435 | D54: 27.782091 | E54: ='Return&Carry'!D52*100 -> 0.23403691 | F54: =VLOOKUP(TEXT(B54,"yyyy-mm-dd"),OneWeekMtgRatesDataTable7[],4,0)*SQRT(225)*100 -> 69.088668 | G54: =VLOOKUP(B54,'Yield Curve'!B54:G101,5,0)*100 -> 275 | H54: =VLOOKUP(B54,'ppm risk premium'!$O$3:$R$53,4,0)*100 -> 80.976701 | I54: 5.55 | J54: =VLOOKUP(B54,'LIBOR 1m'!$C$2:$E$4387,3,0) -> 0.181 | K54: =VLOOKUP(B54,'Refi%'!L:N,2,0) -> 0.63639403 | L54: =VLOOKUP(B54,'Refi%'!L:N,3,0) -> 0.60887631 | M54: =VLOOKUP(B54,'Refi%'!L:P,5,0) -> 87.871549 | N54: =VLOOKUP(B54,'Refi%'!L:P,4,0) -> 1559.4
B55: 42153 | C55: ='Return&Carry'!C53*100 -> 1.2029247 | D55: 27 | E55: ='Return&Carry'!D53*100 -> 0.36245947 | F55: =VLOOKUP(TEXT(B55,"yyyy-mm-dd"),OneWeekMtgRatesDataTable7[],4,0)*SQRT(225)*100 -> 68.401578 | G55: =VLOOKUP(B55,'Yield Curve'!B55:G102,5,0)*100 -> 284.7 | H55: =VLOOKUP(B55,'ppm risk premium'!$O$3:$R$54,4,0)*100 -> 72.745831 | I55: 5.6436002 | J55: =VLOOKUP(B55,'LIBOR 1m'!$C$2:$E$4387,3,0) -> 0.184 | K55: =VLOOKUP(B55,'Refi%'!L:N,2,0) -> 0.54951677 | L55: =VLOOKUP(B55,'Refi%'!L:N,3,0) -> 0.49518214 | M55: =VLOOKUP(B55,'Refi%'!L:P,5,0) -> 67.318102 | N55: =VLOOKUP(B55,'Refi%'!L:P,4,0) -> 1233.9

Sheet Realized Vol
A1: AsOfDate | B1: SeriesNumValue | C1: dy | D1: vol1
A2: 2015-06-01 | B2: 2.8873083 | C2: =B2-B3 -> 0.074749329 | D2: =STDEV(C2:C61) -> 0.04416377
A3: 2015-05-29 | B3: 2.8125589 | C3: =B3-B4 -> -0.028808273 | D3: =STDEV(C3:C62) -> 0.045601052
A4: 2015-05-28 | B4: 2.8413672 | C4: =B4-B5 -> -0.0046993183 | D4: =STDEV(C4:C63) -> 0.045459529
A5: 2015-05-27 | B5: 2.8460665 | C5: =B5-B6 -> -0.0040039051 | D5: =STDEV(C5:C64) -> 0.045474592
A6: 2015-05-26 | B6: 2.8500704 | C6: =B6-B7 -> -0.041450577 | D6: =STDEV(C6:C65) -> 0.045797926
A7: 2015-05-22 | B7: 2.891521 | C7: =B7-B8 -> 0.031544972 | D7: =STDEV(C7:C66) -> 0.045976652
A8: 2015-05-21 | B8: 2.859976 | C8: =B8-B9 -> -0.050286283 | D8: =STDEV(C8:C67) -> 0.045979147
A9: 2015-05-20 | B9: 2.9102623 | C9: =B9-B10 -> -0.011186029 | D9: =STDEV(C9:C68) -> 0.04570193
A10: 2015-05-19 | B10: 2.9214484 | C10: =B10-B11 -> 0.031768425 | D10: =STDEV(C10:C69) -> 0.045758005
A11: 2015-05-18 | B11: 2.8896799 | C11: =B11-B12 -> 0.063363232 | D11: =STDEV(C11:C70) -> 0.046296574
A12: 2015-05-15 | B12: 2.8263167 | C12: =B12-B13 -> -0.08057385 | D12: =STDEV(C12:C71) -> 0.045940716
A13: 2015-05-14 | B13: 2.9068905 | C13: =B13-B14 -> -0.051718716 | D13: =STDEV(C13:C72) -> 0.044775139
... A1519: 2009-05-07 | B1519: 4.0854192 | C1519: =B1519-B1520 -> 4.0854192 | D1519: =STDEV(C1519:C1578) -> #DIV/0!

Sheet Yield Curve
C3: Treasury Yields
B4: Date | C4: 2 | D4: 5 | E4: 10 | F4: 30 | G4: 10-2
B5: 40633 | C5: 0.786 | D5: 2.223 | E5: 3.45 | F5: 4.507 | G5: =E5-C5 -> 2.664
B6: 40662 | C6: 0.605 | D6: 1.97 | E6: 3.292 | F6: 4.404 | G6: =E6-C6 -> 2.687
B7: 40694 | C7: 0.465 | D7: 1.686 | E7: 3.05 | F7: 4.215 | G7: =E7-C7 -> 2.585
B8: 40724 | C8: 0.458 | D8: 1.754 | E8: 3.158 | F8: 4.382 | G8: =E8-C8 -> 2.7
B9: 40753 | C9: 0.363 | D9: 1.369 | E9: 2.802 | F9: 4.133 | G9: =E9-C9 -> 2.439
B10: 40786 | C10: 0.2 | D10: 0.95 | E10: 2.222 | F10: 3.595 | G10: =E10-C10 -> 2.022
B11: 40816 | C11: 0.251 | D11: 0.963 | E11: 1.924 | F11: 2.92 | G11: =E11-C11 -> 1.673
B12: 40847 | C12: 0.258 | D12: 1.006 | E12: 2.166 | F12: 3.199 | G12: =E12-C12 -> 1.908
B13: 40877 | C13: 0.254 | D13: 0.949 | E13: 2.063 | F13: 3.061 | G13: =E13-C13 -> 1.809
B14: 40907 | C14: 0.247 | D14: 0.837 | E14: 1.876 | F14: 2.89 | G14: =E14-C14 -> 1.629
B15: 40939 | C15: 0.215 | D15: 0.709 | E15: 1.799 | F15: 2.934 | G15: =E15-C15 -> 1.584
B16: 40968 | C16: 0.301 | D16: 0.873 | E16: 1.979 | F16: 3.086 | G16: =E16-C16 -> 1.678
... B55: 42153 | C55: 0.601 | D55: 1.467 | E55: 2.093 | F55: 2.847 | G55: =E55-C55 -> 1.492

Sheet ppm risk premium
C3: asOf | D3: AVGWAC | G3: asOf | H3: RawRate | I3: Points | J3: Rate | K3: Accum Rate | L3: Count | M3: avg. Rate | O3: Date | P3: Avg WAC | Q3: Survey Rate | R3: Risk Premium
B4: =IF(WEEKDAY(DATE(YEAR(C4),MONTH(C4)+1,0),2)=6,DATE(YEAR(C4),MONTH(C4)+1,0)-1,IF(WEEKDAY(DATE(YEAR(C4),MONTH(C4)+1,0),2)=7,DATE(YEAR(C4),MONTH(C4)+1,0)-2,DATE(YEAR(C4),MONTH(C4)+1,0))) -> 42185 | C4: 42156 | D4: 4.0873809 | G4: 42158 | H4: 3.87 | I4: 0.6 | J4: 3.77 | K4: =IF(MONTH(G4)=MONTH(G5),J4+K5,J4) -> 11.31 | L4: =IF(MONTH(G4)=MONTH(G5),L5+1,1) -> 3 | M4: =K4/L4 -> 3.77 | O4: 40633 | P4: =VLOOKUP(O4,$B$4:$D$259,3,0) -> 5.5386981 | Q4: =VLOOKUP(O4,$G$4:$M$1060,4,0) -> 4.795 | R4: =P4-Q4 -> 0.74369809
B5: =IF(WEEKDAY(DATE(YEAR(C5),MONTH(C5)+1,0),2)=6,DATE(YEAR(C5),MONTH(C5)+1,0)-1,IF(WEEKDAY(DATE(YEAR(C5),MONTH(C5)+1,0),2)=7,DATE(YEAR(C5),MONTH(C5)+1,0)-2,DATE(YEAR(C5),MONTH(C5)+1,0))) -> 42153 | C5: 42125 | D5: 4.4974583 | G5: 42157 | H5: 3.87 | I5: 0.6 | J5: 3.77 | K5: =IF(MONTH(G5)=MONTH(G6),J5+K6,J5) -> 7.54 | L5: =IF(MONTH(G5)=MONTH(G6),L6+1,1) -> 2 | M5: =K5/L5 -> 3.77 | O5: 40662 | P5: =VLOOKUP(O5,$B$4:$D$259,3,0) -> 5.5269247 | Q5: =VLOOKUP(O5,$G$4:$M$1060,4,0) -> 4.635 | R5: =P5-Q5 -> 0.8919247
B6: =IF(WEEKDAY(DATE(YEAR(C6),MONTH(C6)+1,0),2)=6,DATE(YEAR(C6),MONTH(C6)+1,0)-1,IF(WEEKDAY(DATE(YEAR(C6),MONTH(C6)+1,0),2)=7,DATE(YEAR(C6),MONTH(C6)+1,0)-2,DATE(YEAR(C6),MONTH(C6)+1,0))) -> 42124 | C6: 42095 | D6: 4.509767 | G6: 42156 | H6: 3.87 | I6: 0.6 | J6: 3.77 | K6: =IF(MONTH(G6)=MONTH(G7),J6+K7,J6) -> 3.77 | L6: =IF(MONTH(G6)=MONTH(G7),L7+1,1) -> 1 | M6: =K6/L6 -> 3.77 | O6: 40694 | P6: =VLOOKUP(O6,$B$4:$D$259,3,0) -> 5.516896 | Q6: =VLOOKUP(O6,$G$4:$M$1060,4,0) -> 4.45 | R6: =P6-Q6 -> 1.066896
B7: =IF(WEEKDAY(DATE(YEAR(C7),MONTH(C7)+1,0),2)=6,DATE(YEAR(C7),MONTH(C7)+1,0)-1,IF(WEEKDAY(DATE(YEAR(C7),MONTH(C7)+1,0),2)=7,DATE(YEAR(C7),MONTH(C7)+1,0)-2,DATE(YEAR(C7),MONTH(C7)+1,0))) -> 42094 | C7: 42064 | D7: 4.5238128 | G7: 42153 | H7: 3.87 | I7: 0.6 | J7: 3.77 | K7: =IF(MONTH(G7)=MONTH(G8),J7+K8,J7) -> 74.995 | L7: =IF(MONTH(G7)=MONTH(G8),L8+1,1) -> 20 | M7: =K7/L7 -> 3.74975 | O7: 40724 | P7: =VLOOKUP(O7,$B$4:$D$259,3,0) -> 5.5064525 | Q7: =VLOOKUP(O7,$G$4:$M$1060,4,0) -> 4.525 | R7: =P7-Q7 -> 0.98145252
B8: =IF(WEEKDAY(DATE(YEAR(C8),MONTH(C8)+1,0),2)=6,DATE(YEAR(C8),MONTH(C8)+1,0)-1,IF(WEEKDAY(DATE(YEAR(C8),MONTH(C8)+1,0),2)=7,DATE(YEAR(C8),MONTH(C8)+1,0)-2,DATE(YEAR(C8),MONTH(C8)+1,0))) -> 42062 | C8: 42036 | D8: 4.5361866 | G8: 42152 | H8: 3.87 | I8: 0.6 | J8: 3.77 | K8: =IF(MONTH(G8)=MONTH(G9),J8+K9,J8) -> 71.225 | L8: =IF(MONTH(G8)=MONTH(G9),L9+1,1) -> 19 | M8: =K8/L8 -> 3.7486842 | O8: 40753 | P8: =VLOOKUP(O8,$B$4:$D$259,3,0) -> 5.4966047 | Q8: =VLOOKUP(O8,$G$4:$M$1060,4,0) -> 4.34 | R8: =P8-Q8 -> 1.1566047
B9: =IF(WEEKDAY(DATE(YEAR(C9),MONTH(C9)+1,0),2)=6,DATE(YEAR(C9),MONTH(C9)+1,0)-1,IF(WEEKDAY(DATE(YEAR(C9),MONTH(C9)+1,0),2)=7,DATE(YEAR(C9),MONTH(C9)+1,0)-2,DATE(YEAR(C9),MONTH(C9)+1,0))) -> 42034 | C9: 42005 | D9: 4.5446755 | G9: 42151 | H9: 3.87 | I9: 0.6 | J9: 3.77 | K9: =IF(MONTH(G9)=MONTH(G10),J9+K10,J9) -> 67.455 | L9: =IF(MONTH(G9)=MONTH(G10),L10+1,1) -> 18 | M9: =K9/L9 -> 3.7475 | O9: 40786 | P9: =VLOOKUP(O9,$B$4:$D$259,3,0) -> 5.4853483 | Q9: =VLOOKUP(O9,$G$4:$M$1060,4,0) -> 4.145 | R9: =P9-Q9 -> 1.3403483
B10: =IF(WEEKDAY(DATE(YEAR(C10),MONTH(C10)+1,0),2)=6,DATE(YEAR(C10),MONTH(C10)+1,0)-1,IF(WEEKDAY(DATE(YEAR(C10),MONTH(C10)+1,0),2)=7,DATE(YEAR(C10),MONTH(C10)+1,0)-2,DATE(YEAR(C10),MONTH(C10)+1,0))) -> 42004 | C10: 41974 | D10: 4.5528472 | G10: 42150 | H10: 3.87 | I10: 0.6 | J10: 3.77 | K10: =IF(MONTH(G10)=MONTH(G11),J10+K11,J10) -> 63.685 | L10: =IF(MONTH(G10)=MONTH(G11),L11+1,1) -> 17 | M10: =K10/L10 -> 3.7461765 | O10: 40816 | P10: =VLOOKUP(O10,$B$4:$D$259,3,0) -> 5.4705693 | Q10: =VLOOKUP(O10,$G$4:$M$1060,4,0) -> 3.89 | R10: =P10-Q10 -> 1.5805693
B11: =IF(WEEKDAY(DATE(YEAR(C11),MONTH(C11)+1,0),2)=6,DATE(YEAR(C11),MONTH(C11)+1,0)-1,IF(WEEKDAY(DATE(YEAR(C11),MONTH(C11)+1,0),2)=7,DATE(YEAR(C11),MONTH(C11)+1,0)-2,DATE(YEAR(C11),MONTH(C11)+1,0))) -> 41971 | C11: 41944 | D11: 4.5602421 | G11: 42146 | H11: 3.87 | I11: 0.6 | J11: 3.77 | K11: =IF(MONTH(G11)=MONTH(G12),J11+K12,J11) -> 59.915 | L11: =IF(MONTH(G11)=MONTH(G12),L12+1,1) -> 16 | M11: =K11/L11 -> 3.7446875 | O11: 40847 | P11: =VLOOKUP(O11,$B$4:$D$259,3,0) -> 5.4564254 | Q11: =VLOOKUP(O11,$G$4:$M$1060,4,0) -> 3.925 | R11: =P11-Q11 -> 1.5314254
B12: =IF(WEEKDAY(DATE(YEAR(C12),MONTH(C12)+1,0),2)=6,DATE(YEAR(C12),MONTH(C12)+1,0)-1,IF(WEEKDAY(DATE(YEAR(C12),MONTH(C12)+1,0),2)=7,DATE(YEAR(C12),MONTH(C12)+1,0)-2,DATE(YEAR(C12),MONTH(C12)+1,0))) -> 41943 | C12: 41913 | D12: 4.5658944 | G12: 42145 | H12: 3.87 | I12: 0.6 | J12: 3.77 | K12: =IF(MONTH(G12)=MONTH(G13),J12+K13,J12) -> 56.145 | L12: =IF(MONTH(G12)=MONTH(G13),L13+1,1) -> 15 | M12: =K12/L12 -> 3.743 | O12: 40877 | P12: =VLOOKUP(O12,$B$4:$D$259,3,0) -> 5.4364669 | Q12: =VLOOKUP(O12,$G$4:$M$1060,4,0) -> 3.925 | R12: =P12-Q12 -> 1.5114669
B13: =IF(WEEKDAY(DATE(YEAR(C13),MONTH(C13)+1,0),2)=6,DATE(YEAR(C13),MONTH(C13)+1,0)-1,IF(WEEKDAY(DATE(YEAR(C13),MONTH(C13)+1,0),2)=7,DATE(YEAR(C13),MONTH(C13)+1,0)-2,DATE(YEAR(C13),MONTH(C13)+1,0))) -> 41912 | C13: 41883 | D13: 4.5722568 | G13: 42144 | H13: 3.84 | I13: 0.7 | J13: 3.765 | K13: =IF(MONTH(G13)=MONTH(G14),J13+K14,J13) -> 52.375 | L13: =IF(MONTH(G13)=MONTH(G14),L14+1,1) -> 14 | M13: =K13/L13 -> 3.7410714 | O13: 40907 | P13: =VLOOKUP(O13,$B$4:$D$259,3,0) -> 5.4070811 | Q13: =VLOOKUP(O13,$G$4:$M$1060,4,0) -> 3.86 | R13: =P13-Q13 -> 1.5470811
B14: =IF(WEEKDAY(DATE(YEAR(C14),MONTH(C14)+1,0),2)=6,DATE(YEAR(C14),MONTH(C14)+1,0)-1,IF(WEEKDAY(DATE(YEAR(C14),MONTH(C14)+1,0),2)=7,DATE(YEAR(C14),MONTH(C14)+1,0)-2,DATE(YEAR(C14),MONTH(C14)+1,0))) -> 41880 | C14: 41852 | D14: 4.5792979 | G14: 42143 | H14: 3.84 | I14: 0.7 | J14: 3.765 | K14: =IF(MONTH(G14)=MONTH(G15),J14+K15,J14) -> 48.61 | L14: =IF(MONTH(G14)=MONTH(G15),L15+1,1) -> 13 | M14: =K14/L14 -> 3.7392308 | O14: 40939 | P14: =VLOOKUP(O14,$B$4:$D$259,3,0) -> 5.3841265 | Q14: =VLOOKUP(O14,$G$4:$M$1060,4,0) -> 3.82 | R14: =P14-Q14 -> 1.5641265
B15: =IF(WEEKDAY(DATE(YEAR(C15),MONTH(C15)+1,0),2)=6,DATE(YEAR(C15),MONTH(C15)+1,0)-1,IF(WEEKDAY(DATE(YEAR(C15),MONTH(C15)+1,0),2)=7,DATE(YEAR(C15),MONTH(C15)+1,0)-2,DATE(YEAR(C15),MONTH(C15)+1,0))) -> 41851 | C15: 41821 | D15: 4.5858312 | G15: 42142 | H15: 3.84 | I15: 0.7 | J15: 3.765 | K15: =IF(MONTH(G15)=MONTH(G16),J15+K16,J15) -> 44.845 | L15: =IF(MONTH(G15)=MONTH(G16),L16+1,1) -> 12 | M15: =K15/L15 -> 3.7370833 | O15: 40968 | P15: =VLOOKUP(O15,$B$4:$D$259,3,0) -> 5.3594349 | Q15: =VLOOKUP(O15,$G$4:$M$1060,4,0) -> 3.85 | R15: =P15-Q15 -> 1.5094349
... B30: =IF(WEEKDAY(DATE(YEAR(C30),MONTH(C30)+1,0),2)=6,DATE(YEAR(C30),MONTH(C30)+1,0)-1,IF(WEEKDAY(DATE(YEAR(C30),MONTH(C30)+1,0),2)=7,DATE(YEAR(C30),MONTH(C30)+1,0)-2,DATE(YEAR(C30),MONTH(C30)+1,0))) -> 41394 | C30: 41365 | D30: 4.8154791 | G30: 42121 | H30: 3.68 | I30: 0.6 | J30: 3.58 | K30: =IF(MONTH(G30)=MONTH(G31),J30+K31,J30) -> 67.865 | L30: =IF(MONTH(G30)=MONTH(G31),L31+1,1) -> 19 | M30: =K30/L30 -> 3.5718421 | O30: 41425 | P30: =VLOOKUP(O30,$B$4:$D$259,3,0) -> 4.7738505 | Q30: =VLOOKUP(O30,$G$4:$M$1060,4,0) -> 3.835 | R30: =P30-Q30 -> 0.93885054
B31: =IF(WEEKDAY(DATE(YEAR(C31),MONTH(C31)+1,0),2)=6,DATE(YEAR(C31),MONTH(C31)+1,0)-1,IF(WEEKDAY(DATE(YEAR(C31),MONTH(C31)+1,0),2)=7,DATE(YEAR(C31),MONTH(C31)+1,0)-2,DATE(YEAR(C31),MONTH(C31)+1,0)))-1 -> 41361 | C31: 41334 | D31: 4.8553418 | G31: 42118 | H31: 3.68 | I31: 0.6 | J31: 3.58 | K31: =IF(MONTH(G31)=MONTH(G32),J31+K32,J31) -> 64.285 | L31: =IF(MONTH(G31)=MONTH(G32),L32+1,1) -> 18 | M31: =K31/L31 -> 3.5713889 | O31: 41453 | P31: =VLOOKUP(O31,$B$4:$D$259,3,0) -> 4.7354436 | Q31: =VLOOKUP(O31,$G$4:$M$1060,4,0) -> 4.215 | R31: =P31-Q31 -> 0.52044356
B32: =IF(WEEKDAY(DATE(YEAR(C32),MONTH(C32)+1,0),2)=6,DATE(YEAR(C32),MONTH(C32)+1,0)-1,IF(WEEKDAY(DATE(YEAR(C32),MONTH(C32)+1,0),2)=7,DATE(YEAR(C32),MONTH(C32)+1,0)-2,DATE(YEAR(C32),MONTH(C32)+1,0))) -> 41333 | C32: 41306 | D32: 4.8929882 | G32: 42117 | H32: 3.68 | I32: 0.6 | J32: 3.58 | K32: =IF(MONTH(G32)=MONTH(G33),J32+K33,J32) -> 60.705 | L32: =IF(MONTH(G32)=MONTH(G33),L33+1,1) -> 17 | M32: =K32/L32 -> 3.5708824 | O32: 41486 | P32: =VLOOKUP(O32,$B$4:$D$259,3,0) -> 4.697971 | Q32: =VLOOKUP(O32,$G$4:$M$1060,4,0) -> 4.315 | R32: =P32-Q32 -> 0.38297103
B33: =IF(WEEKDAY(DATE(YEAR(C33),MONTH(C33)+1,0),2)=6,DATE(YEAR(C33),MONTH(C33)+1,0)-1,IF(WEEKDAY(DATE(YEAR(C33),MONTH(C33)+1,0),2)=7,DATE(YEAR(C33),MONTH(C33)+1,0)-2,DATE(YEAR(C33),MONTH(C33)+1,0))) -> 41305 | C33: 41275 | D33: 4.9407582 | G33: 42116 | H33: 3.65 | I33: 0.6 | J33: 3.55 | K33: =IF(MONTH(G33)=MONTH(G34),J33+K34,J33) -> 57.125 | L33: =IF(MONTH(G33)=MONTH(G34),L34+1,1) -> 16 | M33: =K33/L33 -> 3.5703125 | O33: 41516 | P33: =VLOOKUP(O33,$B$4:$D$259,3,0) -> 4.670504 | Q33: =VLOOKUP(O33,$G$4:$M$1060,4,0) -> 4.495 | R33: =P33-Q33 -> 0.17550401
B34: =IF(WEEKDAY(DATE(YEAR(C34),MONTH(C34)+1,0),2)=6,DATE(YEAR(C34),MONTH(C34)+1,0)-1,IF(WEEKDAY(DATE(YEAR(C34),MONTH(C34)+1,0),2)=7,DATE(YEAR(C34),MONTH(C34)+1,0)-2,DATE(YEAR(C34),MONTH(C34)+1,0))) -> 41274 | C34: 41244 | D34: 4.9896716 | G34: 42115 | H34: 3.65 | I34: 0.6 | J34: 3.55 | K34: =IF(MONTH(G34)=MONTH(G35),J34+K35,J34) -> 53.575 | L34: =IF(MONTH(G34)=MONTH(G35),L35+1,1) -> 15 | M34: =K34/L34 -> 3.5716667 | O34: 41547 | P34: =VLOOKUP(O34,$B$4:$D$259,3,0) -> 4.653429 | Q34: =VLOOKUP(O34,$G$4:$M$1060,4,0) -> 4.145 | R34: =P34-Q34 -> 0.50842898
B35: =IF(WEEKDAY(DATE(YEAR(C35),MONTH(C35)+1,0),2)=6,DATE(YEAR(C35),MONTH(C35)+1,0)-1,IF(WEEKDAY(DATE(YEAR(C35),MONTH(C35)+1,0),2)=7,DATE(YEAR(C35),MONTH(C35)+1,0)-2,DATE(YEAR(C35),MONTH(C35)+1,0))) -> 41243 | C35: 41214 | D35: 5.027381 | G35: 42114 | H35: 3.65 | I35: 0.6 | J35: 3.55 | K35: =IF(MONTH(G35)=MONTH(G36),J35+K36,J35) -> 50.025 | L35: =IF(MONTH(G35)=MONTH(G36),L36+1,1) -> 14 | M35: =K35/L35 -> 3.5732143 | O35: 41578 | P35: =VLOOKUP(O35,$B$4:$D$259,3,0) -> 4.6436536 | Q35: =VLOOKUP(O35,$G$4:$M$1060,4,0) -> 4.11 | R35: =P35-Q35 -> 0.53365359
B36: =IF(WEEKDAY(DATE(YEAR(C36),MONTH(C36)+1,0),2)=6,DATE(YEAR(C36),MONTH(C36)+1,0)-1,IF(WEEKDAY(DATE(YEAR(C36),MONTH(C36)+1,0),2)=7,DATE(YEAR(C36),MONTH(C36)+1,0)-2,DATE(YEAR(C36),MONTH(C36)+1,0))) -> 41213 | C36: 41183 | D36: 5.0870015 | G36: 42111 | H36: 3.65 | I36: 0.6 | J36: 3.55 | K36: =IF(MONTH(G36)=MONTH(G37),J36+K37,J36) -> 46.475 | L36: =IF(MONTH(G36)=MONTH(G37),L37+1,1) -> 13 | M36: =K36/L36 -> 3.575 | O36: 41607 | P36: =VLOOKUP(O36,$B$4:$D$259,3,0) -> 4.6346558 | Q36: =VLOOKUP(O36,$G$4:$M$1060,4,0) -> 4.335 | R36: =P36-Q36 -> 0.29965584
B37: =IF(WEEKDAY(DATE(YEAR(C37),MONTH(C37)+1,0),2)=6,DATE(YEAR(C37),MONTH(C37)+1,0)-1,IF(WEEKDAY(DATE(YEAR(C37),MONTH(C37)+1,0),2)=7,DATE(YEAR(C37),MONTH(C37)+1,0)-2,DATE(YEAR(C37),MONTH(C37)+1,0))) -> 41180 | C37: 41153 | D37: 5.1180011 | G37: 42110 | H37: 3.65 | I37: 0.6 | J37: 3.55 | K37: =IF(MONTH(G37)=MONTH(G38),J37+K38,J37) -> 42.925 | L37: =IF(MONTH(G37)=MONTH(G38),L38+1,1) -> 12 | M37: =K37/L37 -> 3.5770833 | O37: 41639 | P37: =VLOOKUP(O37,$B$4:$D$259,3,0) -> 4.6259752 | Q37: =VLOOKUP(O37,$G$4:$M$1060,4,0) -> 4.48 | R37: =P37-Q37 -> 0.14597517
B38: =IF(WEEKDAY(DATE(YEAR(C38),MONTH(C38)+1,0),2)=6,DATE(YEAR(C38),MONTH(C38)+1,0)-1,IF(WEEKDAY(DATE(YEAR(C38),MONTH(C38)+1,0),2)=7,DATE(YEAR(C38),MONTH(C38)+1,0)-2,DATE(YEAR(C38),MONTH(C38)+1,0))) -> 41152 | C38: 41122 | D38: 5.1603138 | G38: 42109 | H38: 3.67 | I38: 0.7 | J38: 3.595 | K38: =IF(MONTH(G38)=MONTH(G39),J38+K39,J38) -> 39.375 | L38: =IF(MONTH(G38)=MONTH(G39),L39+1,1) -> 11 | M38: =K38/L38 -> 3.5795455 | O38: 41670 | P38: =VLOOKUP(O38,$B$4:$D$259,3,0) -> 4.6181105 | Q38: =VLOOKUP(O38,$G$4:$M$1060,4,0) -> 4.155 | R38: =P38-Q38 -> 0.46311049
B39: =IF(WEEKDAY(DATE(YEAR(C39),MONTH(C39)+1,0),2)=6,DATE(YEAR(C39),MONTH(C39)+1,0)-1,IF(WEEKDAY(DATE(YEAR(C39),MONTH(C39)+1,0),2)=7,DATE(YEAR(C39),MONTH(C39)+1,0)-2,DATE(YEAR(C39),MONTH(C39)+1,0))) -> 41121 | C39: 41091 | D39: 5.1996688 | G39: 42108 | H39: 3.67 | I39: 0.7 | J39: 3.595 | K39: =IF(MONTH(G39)=MONTH(G40),J39+K40,J39) -> 35.78 | L39: =IF(MONTH(G39)=MONTH(G40),L40+1,1) -> 10 | M39: =K39/L39 -> 3.578 | O39: 41698 | P39: =VLOOKUP(O39,$B$4:$D$259,3,0) -> 4.6123161 | Q39: =VLOOKUP(O39,$G$4:$M$1060,4,0) -> 4.205 | R39: =P39-Q39 -> 0.40731613
B40: =IF(WEEKDAY(DATE(YEAR(C40),MONTH(C40)+1,0),2)=6,DATE(YEAR(C40),MONTH(C40)+1,0)-1,IF(WEEKDAY(DATE(YEAR(C40),MONTH(C40)+1,0),2)=7,DATE(YEAR(C40),MONTH(C40)+1,0)-2,DATE(YEAR(C40),MONTH(C40)+1,0))) -> 41089 | C40: 41061 | D40: 5.234316 | G40: 42107 | H40: 3.67 | I40: 0.7 | J40: 3.595 | K40: =IF(MONTH(G40)=MONTH(G41),J40+K41,J40) -> 32.185 | L40: =IF(MONTH(G40)=MONTH(G41),L41+1,1) -> 9 | M40: =K40/L40 -> 3.5761111 | O40: 41729 | P40: =VLOOKUP(O40,$B$4:$D$259,3,0) -> 4.6074732 | Q40: =VLOOKUP(O40,$G$4:$M$1060,4,0) -> 4.335 | R40: =P40-Q40 -> 0.27247321
B41: =IF(WEEKDAY(DATE(YEAR(C41),MONTH(C41)+1,0),2)=6,DATE(YEAR(C41),MONTH(C41)+1,0)-1,IF(WEEKDAY(DATE(YEAR(C41),MONTH(C41)+1,0),2)=7,DATE(YEAR(C41),MONTH(C41)+1,0)-2,DATE(YEAR(C41),MONTH(C41)+1,0))) -> 41060 | C41: 41030 | D41: 5.2629157 | G41: 42104 | H41: 3.67 | I41: 0.7 | J41: 3.595 | K41: =IF(MONTH(G41)=MONTH(G42),J41+K42,J41) -> 28.59 | L41: =IF(MONTH(G41)=MONTH(G42),L42+1,1) -> 8 | M41: =K41/L41 -> 3.57375 | O41: 41759 | P41: =VLOOKUP(O41,$B$4:$D$259,3,0) -> 4.6020514 | Q41: =VLOOKUP(O41,$G$4:$M$1060,4,0) -> 4.215 | R41: =P41-Q41 -> 0.38705144
B42: =IF(WEEKDAY(DATE(YEAR(C42),MONTH(C42)+1,0),2)=6,DATE(YEAR(C42),MONTH(C42)+1,0)-1,IF(WEEKDAY(DATE(YEAR(C42),MONTH(C42)+1,0),2)=7,DATE(YEAR(C42),MONTH(C42)+1,0)-2,DATE(YEAR(C42),MONTH(C42)+1,0))) -> 41029 | C42: 41000 | D42: 5.2953192 | G42: 42103 | H42: 3.67 | I42: 0.7 | J42: 3.595 | K42: =IF(MONTH(G42)=MONTH(G43),J42+K43,J42) -> 24.995 | L42: =IF(MONTH(G42)=MONTH(G43),L43+1,1) -> 7 | M42: =K42/L42 -> 3.5707143 | O42: 41789 | P42: =VLOOKUP(O42,$B$4:$D$259,3,0) -> 4.5969808 | Q42: =VLOOKUP(O42,$G$4:$M$1060,4,0) -> 4.015 | R42: =P42-Q42 -> 0.58198083
B43: =IF(WEEKDAY(DATE(YEAR(C43),MONTH(C43)+1,0),2)=6,DATE(YEAR(C43),MONTH(C43)+1,0)-1,IF(WEEKDAY(DATE(YEAR(C43),MONTH(C43)+1,0),2)=7,DATE(YEAR(C43),MONTH(C43)+1,0)-2,DATE(YEAR(C43),MONTH(C43)+1,0))) -> 40998 | C43: 40969 | D43: 5.3179672 | G43: 42102 | H43: 3.66 | I43: 0.6 | J43: 3.56 | K43: =IF(MONTH(G43)=MONTH(G44),J43+K44,J43) -> 21.4 | L43: =IF(MONTH(G43)=MONTH(G44),L44+1,1) -> 6 | M43: =K43/L43 -> 3.5666667 | O43: 41820 | P43: =VLOOKUP(O43,$B$4:$D$259,3,0) -> 4.5918834 | Q43: =VLOOKUP(O43,$G$4:$M$1060,4,0) -> 3.995 | R43: =P43-Q43 -> 0.59688339
... B54: =IF(WEEKDAY(DATE(YEAR(C54),MONTH(C54)+1,0),2)=6,DATE(YEAR(C54),MONTH(C54)+1,0)-1,IF(WEEKDAY(DATE(YEAR(C54),MONTH(C54)+1,0),2)=7,DATE(YEAR(C54),MONTH(C54)+1,0)-2,DATE(YEAR(C54),MONTH(C54)+1,0))) -> 40662 | C54: 40634 | D54: 5.5269247 | G54: 42087 | H54: 3.69 | I54: 0.6 | J54: 3.59 | K54: =IF(MONTH(G54)=MONTH(G55),J54+K55,J54) -> 62.51 | L54: =IF(MONTH(G54)=MONTH(G55),L55+1,1) -> 17 | M54: =K54/L54 -> 3.6770588 | O54: 42153 | P54: =VLOOKUP(O54,$B$4:$D$259,3,0) -> 4.4974583 | Q54: =VLOOKUP(O54,$G$4:$M$1060,4,0) -> 3.77 | R54: =P54-Q54 -> 0.72745831
B55: =IF(WEEKDAY(DATE(YEAR(C55),MONTH(C55)+1,0),2)=6,DATE(YEAR(C55),MONTH(C55)+1,0)-1,IF(WEEKDAY(DATE(YEAR(C55),MONTH(C55)+1,0),2)=7,DATE(YEAR(C55),MONTH(C55)+1,0)-2,DATE(YEAR(C55),MONTH(C55)+1,0))) -> 40633 | C55: 40603 | D55: 5.5386981 | G55: 42086 | H55: 3.69 | I55: 0.6 | J55: 3.59 | K55: =IF(MONTH(G55)=MONTH(G56),J55+K56,J55) -> 58.92 | L55: =IF(MONTH(G55)=MONTH(G56),L56+1,1) -> 16 | M55: =K55/L55 -> 3.6825
B56: =IF(WEEKDAY(DATE(YEAR(C56),MONTH(C56)+1,0),2)=6,DATE(YEAR(C56),MONTH(C56)+1,0)-1,IF(WEEKDAY(DATE(YEAR(C56),MONTH(C56)+1,0),2)=7,DATE(YEAR(C56),MONTH(C56)+1,0)-2,DATE(YEAR(C56),MONTH(C56)+1,0))) -> 40602 | C56: 40575 | D56: 5.5560536 | G56: 42083 | H56: 3.69 | I56: 0.6 | J56: 3.59 | K56: =IF(MONTH(G56)=MONTH(G57),J56+K57,J56) -> 55.33 | L56: =IF(MONTH(G56)=MONTH(G57),L57+1,1) -> 15 | M56: =K56/L56 -> 3.6886667
B57: =IF(WEEKDAY(DATE(YEAR(C57),MONTH(C57)+1,0),2)=6,DATE(YEAR(C57),MONTH(C57)+1,0)-1,IF(WEEKDAY(DATE(YEAR(C57),MONTH(C57)+1,0),2)=7,DATE(YEAR(C57),MONTH(C57)+1,0)-2,DATE(YEAR(C57),MONTH(C57)+1,0))) -> 40574 | C57: 40544 | D57: 5.5763437 | G57: 42082 | H57: 3.69 | I57: 0.6 | J57: 3.59 | K57: =IF(MONTH(G57)=MONTH(G58),J57+K58,J57) -> 51.74 | L57: =IF(MONTH(G57)=MONTH(G58),L58+1,1) -> 14 | M57: =K57/L57 -> 3.6957143
B58: =IF(WEEKDAY(DATE(YEAR(C58),MONTH(C58)+1,0),2)=6,DATE(YEAR(C58),MONTH(C58)+1,0)-1,IF(WEEKDAY(DATE(YEAR(C58),MONTH(C58)+1,0),2)=7,DATE(YEAR(C58),MONTH(C58)+1,0)-2,DATE(YEAR(C58),MONTH(C58)+1,0))) -> 40543 | C58: 40513 | D58: 5.6013603 | G58: 42081 | H58: 3.78 | I58: 0.6 | J58: 3.68 | K58: =IF(MONTH(G58)=MONTH(G59),J58+K59,J58) -> 48.15 | L58: =IF(MONTH(G58)=MONTH(G59),L59+1,1) -> 13 | M58: =K58/L58 -> 3.7038462
B59: =IF(WEEKDAY(DATE(YEAR(C59),MONTH(C59)+1,0),2)=6,DATE(YEAR(C59),MONTH(C59)+1,0)-1,IF(WEEKDAY(DATE(YEAR(C59),MONTH(C59)+1,0),2)=7,DATE(YEAR(C59),MONTH(C59)+1,0)-2,DATE(YEAR(C59),MONTH(C59)+1,0))) -> 40512 | C59: 40483 | D59: 5.6324669 | G59: 42080 | H59: 3.78 | I59: 0.6 | J59: 3.68 | K59: =IF(MONTH(G59)=MONTH(G60),J59+K60,J59) -> 44.47 | L59: =IF(MONTH(G59)=MONTH(G60),L60+1,1) -> 12 | M59: =K59/L59 -> 3.7058333
B60: =IF(WEEKDAY(DATE(YEAR(C60),MONTH(C60)+1,0),2)=6,DATE(YEAR(C60),MONTH(C60)+1,0)-1,IF(WEEKDAY(DATE(YEAR(C60),MONTH(C60)+1,0),2)=7,DATE(YEAR(C60),MONTH(C60)+1,0)-2,DATE(YEAR(C60),MONTH(C60)+1,0))) -> 40480 | C60: 40452 | D60: 5.6590403 | G60: 42079 | H60: 3.78 | I60: 0.6 | J60: 3.68 | K60: =IF(MONTH(G60)=MONTH(G61),J60+K61,J60) -> 40.79 | L60: =IF(MONTH(G60)=MONTH(G61),L61+1,1) -> 11 | M60: =K60/L60 -> 3.7081818
B61: =IF(WEEKDAY(DATE(YEAR(C61),MONTH(C61)+1,0),2)=6,DATE(YEAR(C61),MONTH(C61)+1,0)-1,IF(WEEKDAY(DATE(YEAR(C61),MONTH(C61)+1,0),2)=7,DATE(YEAR(C61),MONTH(C61)+1,0)-2,DATE(YEAR(C61),MONTH(C61)+1,0))) -> 40451 | C61: 40422 | D61: 5.6844643 | G61: 42076 | H61: 3.78 | I61: 0.6 | J61: 3.68 | K61: =IF(MONTH(G61)=MONTH(G62),J61+K62,J61) -> 37.11 | L61: =IF(MONTH(G61)=MONTH(G62),L62+1,1) -> 10 | M61: =K61/L61 -> 3.711
B62: =IF(WEEKDAY(DATE(YEAR(C62),MONTH(C62)+1,0),2)=6,DATE(YEAR(C62),MONTH(C62)+1,0)-1,IF(WEEKDAY(DATE(YEAR(C62),MONTH(C62)+1,0),2)=7,DATE(YEAR(C62),MONTH(C62)+1,0)-2,DATE(YEAR(C62),MONTH(C62)+1,0))) -> 40421 | C62: 40391 | D62: 5.7099767 | G62: 42075 | H62: 3.78 | I62: 0.6 | J62: 3.68 | K62: =IF(MONTH(G62)=MONTH(G63),J62+K63,J62) -> 33.43 | L62: =IF(MONTH(G62)=MONTH(G63),L63+1,1) -> 9 | M62: =K62/L62 -> 3.7144444
B63: =IF(WEEKDAY(DATE(YEAR(C63),MONTH(C63)+1,0),2)=6,DATE(YEAR(C63),MONTH(C63)+1,0)-1,IF(WEEKDAY(DATE(YEAR(C63),MONTH(C63)+1,0),2)=7,DATE(YEAR(C63),MONTH(C63)+1,0)-2,DATE(YEAR(C63),MONTH(C63)+1,0))) -> 40389 | C63: 40360 | D63: 5.7262138 | G63: 42074 | H63: 3.86 | I63: 0.6 | J63: 3.76 | K63: =IF(MONTH(G63)=MONTH(G64),J63+K64,J63) -> 29.75 | L63: =IF(MONTH(G63)=MONTH(G64),L64+1,1) -> 8 | M63: =K63/L63 -> 3.71875
B64: =IF(WEEKDAY(DATE(YEAR(C64),MONTH(C64)+1,0),2)=6,DATE(YEAR(C64),MONTH(C64)+1,0)-1,IF(WEEKDAY(DATE(YEAR(C64),MONTH(C64)+1,0),2)=7,DATE(YEAR(C64),MONTH(C64)+1,0)-2,DATE(YEAR(C64),MONTH(C64)+1,0))) -> 40359 | C64: 40330 | D64: 5.7403826 | G64: 42073 | H64: 3.86 | I64: 0.6 | J64: 3.76 | K64: =IF(MONTH(G64)=MONTH(G65),J64+K65,J64) -> 25.99 | L64: =IF(MONTH(G64)=MONTH(G65),L65+1,1) -> 7 | M64: =K64/L64 -> 3.7128571
B65: =IF(WEEKDAY(DATE(YEAR(C65),MONTH(C65)+1,0),2)=6,DATE(YEAR(C65),MONTH(C65)+1,0)-1,IF(WEEKDAY(DATE(YEAR(C65),MONTH(C65)+1,0),2)=7,DATE(YEAR(C65),MONTH(C65)+1,0)-2,DATE(YEAR(C65),MONTH(C65)+1,0))) -> 40329 | C65: 40299 | D65: 5.7574015 | G65: 42072 | H65: 3.86 | I65: 0.6 | J65: 3.76 | K65: =IF(MONTH(G65)=MONTH(G66),J65+K66,J65) -> 22.23 | L65: =IF(MONTH(G65)=MONTH(G66),L66+1,1) -> 6 | M65: =K65/L65 -> 3.705
B66: =IF(WEEKDAY(DATE(YEAR(C66),MONTH(C66)+1,0),2)=6,DATE(YEAR(C66),MONTH(C66)+1,0)-1,IF(WEEKDAY(DATE(YEAR(C66),MONTH(C66)+1,0),2)=7,DATE(YEAR(C66),MONTH(C66)+1,0)-2,DATE(YEAR(C66),MONTH(C66)+1,0))) -> 40298 | C66: 40269 | D66: 5.7816058 | G66: 42069 | H66: 3.86 | I66: 0.6 | J66: 3.76 | K66: =IF(MONTH(G66)=MONTH(G67),J66+K67,J66) -> 18.47 | L66: =IF(MONTH(G66)=MONTH(G67),L67+1,1) -> 5 | M66: =K66/L66 -> 3.694
...

Sheet Return&Carry
B2: Date | C2: Monthly Hedge Return (%) | D2: IOS + TBA Carry (%)
B3: 40633 | C3: 0.032147753 | D3: 0.010991114
B4: 40662 | C4: 0.039945301 | D4: 0.010984369
B5: 40694 | C5: 0.036836949 | D5: 0.012359979
B6: 40724 | C6: -0.0089725231 | D6: 0.011611305
B7: 40753 | C7: -0.0070542452 | D7: 0.0094859999
B8: 40786 | C8: -0.12940149 | D8: 0.0098897456
B9: 40816 | C9: -0.10646399 | D9: 0.014023414
B10: 40847 | C10: 0.023593585 | D10: 0.012905992
B11: 40877 | C11: 0.014407939 | D11: 0.0070135917
B12: 40907 | C12: 0.005832688 | D12: 0.0039545841
B13: 40939 | C13: -0.030247515 | D13: 0.0093155585
B14: 40968 | C14: 0.11557044 | D14: 0.017106233
... B53: 42153 | C53: 0.012029247 | D53: 0.0036245947

Sheet LIBOR 1m
B2: 1 Month LIBOR | C2: 42153 | D2: Rate | E2: 0.184
B3: 1 Month LIBOR | C3: 42152 | D3: Rate | E3: 0.184
B4: 1 Month LIBOR | C4: 42151 | D4: Rate | E4: 0.18535
B5: 1 Month LIBOR | C5: 42150 | D5: Rate | E5: 0.1863
B6: 1 Month LIBOR | C6: 42146 | D6: Rate | E6: 0.18485
B7: 1 Month LIBOR | C7: 42145 | D7: Rate | E7: 0.18475
B8: 1 Month LIBOR | C8: 42144 | D8: Rate | E8: 0.18475
B9: 1 Month LIBOR | C9: 42143 | D9: Rate | E9: 0.18675
B10: 1 Month LIBOR | C10: 42142 | D10: Rate | E10: 0.184
B11: 1 Month LIBOR | C11: 42139 | D11: Rate | E11: 0.1862
B12: 1 Month LIBOR | C12: 42138 | D12: Rate | E12: 0.18335
B13: 1 Month LIBOR | C13: 42137 | D13: Rate | E13: 0.1856
... B1598: 1 Month LIBOR | C1598: 39815 | D1598: Rate | E1598: 0.43

Sheet Refi%
W2: Bloomberg Refi Index | AA2: Loan Level Incentive
C3: asOfDate | D3: Pool Level | E3: Loan Level | F3: Refi Index | G3: LL_Incentve | J3: Last Week | K3: asOfDate | M3: Pool Level | N3: Loan Level | X3: MBAVCMRS | AA3: asOfDate | AB3: refinanceible | AC3: bps
C4: 40549 | D4: 0.6240217 | E4: 0.47799603 | F4: =VLOOKUP(C4+1,W:X,2,0) -> 2344.3 | G4: =VLOOKUP(C4,AA:AC,3,0) -> 90.117384 | H4: =MONTH(C4) -> 1 | I4: =IF(H4=H3,0,1) -> 1 | J4: =I5 -> 0 | W4: =_xll.BDH("MBAVCMRS Index","PX LAST","8/10/07",TODAY(),"cols=2;rows=402") -> #NAME? | X4: 2104.1 | AA4: 40549 | AB4: 0.90117384 | AC4: =AB4*100 -> 90.117384
C5: 40556 | D5: 0.62817294 | E5: 0.49650186 | F5: =VLOOKUP(C5+1,W:X,2,0) -> 2528.7 | G5: =VLOOKUP(C5,AA:AC,3,0) -> 95.957973 | H5: =MONTH(C5) -> 1 | I5: =IF(H5=H4,0,1) -> 0 | J5: =I6 -> 0 | W5: 39311 | X5: 1960.1 | AA5: 40556 | AB5: 0.95957973 | AC5: =AB5*100 -> 95.957973
C6: 40563 | D6: 0.62597731 | E6: 0.4802957 | F6: =VLOOKUP(C6+1,W:X,2,0) -> 2129.7 | G6: =VLOOKUP(C6,AA:AC,3,0) -> 93.037678 | H6: =MONTH(C6) -> 1 | I6: =IF(H6=H5,0,1) -> 0 | J6: =I7 -> 0 | W6: 39318 | X6: 1871.4 | AA6: 40563 | AB6: 0.93037678 | AC6: =AB6*100 -> 93.037678
C7: 40570 | D7: 0.62392159 | E7: 0.47679594 | F7: =VLOOKUP(C7+1,W:X,2,0) -> 2371.1 | G7: =VLOOKUP(C7,AA:AC,3,0) -> 89.630668 | H7: =MONTH(C7) -> 1 | I7: =IF(H7=H6,0,1) -> 0 | J7: =I8 -> 1 | K7: =IF(J7=1,EOMONTH(C7,0),"") -> 40574 | L7: =IF(WEEKDAY(K7,2)=6,K7-1,IF(WEEKDAY(K7,2)=7,K7-2,IF(J7=1,K7,""))) -> 40574 | M7: =IF(J7=1,D7,"") -> 0.62392159 | N7: =IF($J7=1,E7,"") -> 0.47679594 | O7: =IF($J7=1,F7,"") -> 2371.1 | P7: =IF($J7=1,G7,"") -> 89.630668 | W7: 39325 | X7: 1892.3 | AA7: 40570 | AB7: 0.89630668 | AC7: =AB7*100 -> 89.630668
C8: 40577 | D8: 0.60653142 | E8: 0.43462013 | F8: =VLOOKUP(C8+1,W:X,2,0) -> 2190.4 | G8: =VLOOKUP(C8,AA:AC,3,0) -> 80.302242 | H8: =MONTH(C8) -> 2 | I8: =IF(H8=H7,0,1) -> 1 | J8: =I9 -> 0 | K8: =IF(J8=1,EOMONTH(C8,0),"") | L8: =IF(WEEKDAY(K8,2)=6,K8-1,IF(WEEKDAY(K8,2)=7,K8-2,IF(J8=1,K8,""))) -> #VALUE! | M8: =IF(J8=1,D8,"") | N8: =IF($J8=1,E8,"") | O8: =IF($J8=1,F8,"") | P8: =IF($J8=1,G8,"") | W8: 39332 | X8: 2009.3 | AA8: 40577 | AB8: 0.80302242 | AC8: =AB8*100 -> 80.302242
C9: 40584 | D9: 0.50868798 | E9: 0.35529177 | F9: =VLOOKUP(C9+1,W:X,2,0) -> 1953.2 | G9: =VLOOKUP(C9,AA:AC,3,0) -> 59.492977 | H9: =MONTH(C9) -> 2 | I9: =IF(H9=H8,0,1) -> 0 | J9: =I10 -> 0 | K9: =IF(J9=1,EOMONTH(C9,0),"") | L9: =IF(WEEKDAY(K9,2)=6,K9-1,IF(WEEKDAY(K9,2)=7,K9-2,IF(J9=1,K9,""))) -> #VALUE! | M9: =IF(J9=1,D9,"") | N9: =IF($J9=1,E9,"") | O9: =IF($J9=1,F9,"") | P9: =IF($J9=1,G9,"") | W9: 39339 | X9: 2091.1 | AA9: 40584 | AB9: 0.59492977 | AC9: =AB9*100 -> 59.492977
C10: 40591 | D10: 0.52965902 | E10: 0.37678804 | F10: =VLOOKUP(C10+1,W:X,2,0) -> 2325.3 | G10: =VLOOKUP(C10,AA:AC,3,0) -> 64.332341 | H10: =MONTH(C10) -> 2 | I10: =IF(H10=H9,0,1) -> 0 | J10: =I11 -> 0 | K10: =IF(J10=1,EOMONTH(C10,0),"") | L10: =IF(WEEKDAY(K10,2)=6,K10-1,IF(WEEKDAY(K10,2)=7,K10-2,IF(J10=1,K10,""))) -> #VALUE! | M10: =IF(J10=1,D10,"") | N10: =IF($J10=1,E10,"") | O10: =IF($J10=1,F10,"") | P10: =IF($J10=1,G10,"") | W10: 39346 | X10: 2172.5 | AA10: 40591 | AB10: 0.64332341 | AC10: =AB10*100 -> 64.332341
C11: 40598 | D11: 0.57709504 | E11: 0.41551494 | F11: =VLOOKUP(C11+1,W:X,2,0) -> 2155.5 | G11: =VLOOKUP(C11,AA:AC,3,0) -> 71.591388 | H11: =MONTH(C11) -> 2 | I11: =IF(H11=H10,0,1) -> 0 | J11: =I12 -> 1 | K11: =IF(J11=1,EOMONTH(C11,0),"") -> 40602 | L11: =IF(WEEKDAY(K11,2)=6,K11-1,IF(WEEKDAY(K11,2)=7,K11-2,IF(J11=1,K11,""))) -> 40602 | M11: =IF(J11=1,D11,"") -> 0.57709504 | N11: =IF($J11=1,E11,"") -> 0.41551494 | O11: =IF($J11=1,F11,"") -> 2155.5 | P11: =IF($J11=1,G11,"") -> 71.591388 | W11: 39353 | X11: 2065.7 | AA11: 40598 | AB11: 0.71591388 | AC11: =AB11*100 -> 71.591388
C12: 40605 | D12: 0.59224776 | E12: 0.42215163 | F12: =VLOOKUP(C12+1,W:X,2,0) -> 2539.4 | G12: =VLOOKUP(C12,AA:AC,3,0) -> 72.287304 | H12: =MONTH(C12) -> 3 | I12: =IF(H12=H11,0,1) -> 1 | J12: =I13 -> 0 | K12: =IF(J12=1,EOMONTH(C12,0),"") | L12: =IF(WEEKDAY(K12,2)=6,K12-1,IF(WEEKDAY(K12,2)=7,K12-2,IF(J12=1,K12,""))) -> #VALUE! | M12: =IF(J12=1,D12,"") | N12: =IF($J12=1,E12,"") | O12: =IF($J12=1,F12,"") | P12: =IF($J12=1,G12,"") | W12: 39360 | X12: 2153.3 | AA12: 40605 | AB12: 0.72287304 | AC12: =AB12*100 -> 72.287304
C13: 40612 | D13: 0.59090571 | E13: 0.42124986 | F13: =VLOOKUP(C13+1,W:X,2,0) -> 2563.6 | G13: =VLOOKUP(C13,AA:AC,3,0) -> 71.325538 | H13: =MONTH(C13) -> 3 | I13: =IF(H13=H12,0,1) -> 0 | J13: =I14 -> 0 | K13: =IF(J13=1,EOMONTH(C13,0),"") | L13: =IF(WEEKDAY(K13,2)=6,K13-1,IF(WEEKDAY(K13,2)=7,K13-2,IF(J13=1,K13,""))) -> #VALUE! | M13: =IF(J13=1,D13,"") | N13: =IF($J13=1,E13,"") | O13: =IF($J13=1,F13,"") | P13: =IF($J13=1,G13,"") | W13: 39367 | X13: 2116.6 | AA13: 40612 | AB13: 0.71325538 | AC13: =AB13*100 -> 71.325538
C14: 40619 | D14: 0.60261779 | E14: 0.46784663 | F14: =VLOOKUP(C14+1,W:X,2,0) -> 2620.8 | G14: =VLOOKUP(C14,AA:AC,3,0) -> 82.866728 | H14: =MONTH(C14) -> 3 | I14: =IF(H14=H13,0,1) -> 0 | J14: =I15 -> 0 | K14: =IF(J14=1,EOMONTH(C14,0),"") | L14: =IF(WEEKDAY(K14,2)=6,K14-1,IF(WEEKDAY(K14,2)=7,K14-2,IF(J14=1,K14,""))) -> #VALUE! | M14: =IF(J14=1,D14,"") | N14: =IF($J14=1,E14,"") | O14: =IF($J14=1,F14,"") | P14: =IF($J14=1,G14,"") | W14: 39374 | X14: 2221.1 | AA14: 40619 | AB14: 0.82866728 | AC14: =AB14*100 -> 82.866728
C15: 40626 | D15: 0.59950596 | E15: 0.4501581 | F15: =VLOOKUP(C15+1,W:X,2,0) -> 2350.7 | G15: =VLOOKUP(C15,AA:AC,3,0) -> 78.057899 | H15: =MONTH(C15) -> 3 | I15: =IF(H15=H14,0,1) -> 0 | J15: =I16 -> 0 | K15: =IF(J15=1,EOMONTH(C15,0),"") | L15: =IF(WEEKDAY(K15,2)=6,K15-1,IF(WEEKDAY(K15,2)=7,K15-2,IF(J15=1,K15,""))) -> #VALUE! | M15: =IF(J15=1,D15,"") | N15: =IF($J15=1,E15,"") | O15: =IF($J15=1,F15,"") | P15: =IF($J15=1,G15,"") | W15: 39381 | X15: 2433.2 | AA15: 40626 | AB15: 0.78057899 | AC15: =AB15*100 -> 78.057899
C16: 40633 | D16: 0.59322571 | E16: 0.42282959 | F16: =VLOOKUP(C16+1,W:X,2,0) -> 2194.4 | G16: =VLOOKUP(C16,AA:AC,3,0) -> 73.24907 | H16: =MONTH(C16) -> 3 | I16: =IF(H16=H15,0,1) -> 0 | J16: =I17 -> 1 | K16: =IF(J16=1,EOMONTH(C16,0),"") -> 40633 | L16: =IF(WEEKDAY(K16,2)=6,K16-1,IF(WEEKDAY(K16,2)=7,K16-2,IF(J16=1,K16,""))) -> 40633 | M16: =IF(J16=1,D16,"") -> 0.59322571 | N16: =IF($J16=1,E16,"") -> 0.42282959 | O16: =IF($J16=1,F16,"") -> 2194.4 | P16: =IF($J16=1,G16,"") -> 73.24907 | W16: 39388 | X16: 2336.2 | AA16: 40633 | AB16: 0.7324907 | AC16: =AB16*100 -> 73.24907
C17: 40640 | D17: 0.58542145 | E17: 0.41477854 | F17: =VLOOKUP(C17+1,W:X,2,0) -> 2010.6 | G17: =VLOOKUP(C17,AA:AC,3,0) -> 71.425856 | H17: =MONTH(C17) -> 4 | I17: =IF(H17=H16,0,1) -> 1 | J17: =I18 -> 0 | K17: =IF(J17=1,EOMONTH(C17,0),"") | L17: =IF(WEEKDAY(K17,2)=6,K17-1,IF(WEEKDAY(K17,2)=7,K17-2,IF(J17=1,K17,""))) -> #VALUE! | M17: =IF(J17=1,D17,"") | N17: =IF($J17=1,E17,"") | O17: =IF($J17=1,F17,"") | P17: =IF($J17=1,G17,"") | W17: 39395 | X17: 2503.6 | AA17: 40640 | AB17: 0.71425856 | AC17: =AB17*100 -> 71.425856
C18: 40647 | D18: 0.58155199 | E18: 0.41340612 | F18: =VLOOKUP(C18+1,W:X,2,0) -> 2065.3 | G18: =VLOOKUP(C18,AA:AC,3,0) -> 69.979165 | H18: =MONTH(C18) -> 4 | I18: =IF(H18=H17,0,1) -> 0 | J18: =I19 -> 0 | K18: =IF(J18=1,EOMONTH(C18,0),"") | L18: =IF(WEEKDAY(K18,2)=6,K18-1,IF(WEEKDAY(K18,2)=7,K18-2,IF(J18=1,K18,""))) -> #VALUE! | M18: =IF(J18=1,D18,"") | N18: =IF($J18=1,E18,"") | O18: =IF($J18=1,F18,"") | P18: =IF($J18=1,G18,"") | W18: 39402 | X18: 2371.1 | AA18: 40647 | AB18: 0.69979165 | AC18: =AB18*100 -> 69.979165
... C49: 40864 | D49: 0.93485324 | E49: 0.8071978 | F49: =VLOOKUP(C49+1,W:X,2,0) -> 3466.8 | G49: =VLOOKUP(C49,AA:AC,3,0) -> 144.85245 | H49: =MONTH(C49) -> 11 | I49: =IF(H49=H48,0,1) -> 0 | J49: =I50 -> 0 | K49: =IF(J49=1,EOMONTH(C49,0),"") | L49: =IF(WEEKDAY(K49,2)=6,K49-1,IF(WEEKDAY(K49,2)=7,K49-2,IF(J49=1,K49,""))) -> #VALUE! | M49: =IF(J49=1,D49,"") | N49: =IF($J49=1,E49,"") | O49: =IF($J49=1,F49,"") | P49: =IF($J49=1,G49,"") | W49: 39619 | X49: 1044.6 | AA49: 40864 | AB49: 1.4485245 | AC49: =AB49*100 -> 144.85245
C50: 40870 | D50: 0.94997171 | E50: 0.80850149 | F50: =VLOOKUP(C50+2,W:X,2,0) -> 2941.3 | G50: =VLOOKUP(C50,AA:AC,3,0) -> 146.78788 | H50: =MONTH(C50) -> 11 | I50: =IF(H50=H49,0,1) -> 0 | J50: =I51 -> 1 | K50: =IF(J50=1,EOMONTH(C50,0),"") -> 40877 | L50: =IF(WEEKDAY(K50,2)=6,K50-1,IF(WEEKDAY(K50,2)=7,K50-2,IF(J50=1,K50,""))) -> 40877 | M50: =IF(J50=1,D50,"") -> 0.94997171 | N50: =IF($J50=1,E50,"") -> 0.80850149 | O50: =IF($J50=1,F50,"") -> 2941.3 | P50: =IF($J50=1,G50,"") -> 146.78788 | W50: 39626 | X50: 1111.3 | AA50: 40870 | AB50: 1.4678788 | AC50: =AB50*100 -> 146.78788
C51: 40878 | D51: 0.91542629 | E51: 0.79441105 | F51: =VLOOKUP(C51+1,W:X,2,0) -> 3394.7 | G51: =VLOOKUP(C51,AA:AC,3,0) -> 142.18347 | H51: =MONTH(C51) -> 12 | I51: =IF(H51=H50,0,1) -> 1 | J51: =I52 -> 0 | K51: =IF(J51=1,EOMONTH(C51,0),"") | L51: =IF(WEEKDAY(K51,2)=6,K51-1,IF(WEEKDAY(K51,2)=7,K51-2,IF(J51=1,K51,""))) -> #VALUE! | M51: =IF(J51=1,D51,"") | N51: =IF($J51=1,E51,"") | O51: =IF($J51=1,F51,"") | P51: =IF($J51=1,G51,"") | W51: 39633 | X51: 1166.5 | AA51: 40878 | AB51: 1.4218347 | AC51: =AB51*100 -> 142.18347
C52: 40885 | D52: 0.92487461 | E52: 0.79445841 | F52: =VLOOKUP(C52+1,W:X,2,0) -> 3708.6 | G52: =VLOOKUP(C52,AA:AC,3,0) -> 143.1491 | H52: =MONTH(C52) -> 12 | I52: =IF(H52=H51,0,1) -> 0 | J52: =I53 -> 0 | K52: =IF(J52=1,EOMONTH(C52,0),"") | L52: =IF(WEEKDAY(K52,2)=6,K52-1,IF(WEEKDAY(K52,2)=7,K52-2,IF(J52=1,K52,""))) -> #VALUE! | M52: =IF(J52=1,D52,"") | N52: =IF($J52=1,E52,"") | O52: =IF($J52=1,F52,"") | P52: =IF($J52=1,G52,"") | W52: 39640 | X52: 1270.6 | AA52: 40885 | AB52: 1.431491 | AC52: =AB52*100 -> 143.1491
C53: 40892 | D53: 0.93969161 | E53: 0.79646175 | F53: =VLOOKUP(C53+1,W:X,2,0) -> 3676.1 | G53: =VLOOKUP(C53,AA:AC,3,0) -> 145.56319 | H53: =MONTH(C53) -> 12 | I53: =IF(H53=H52,0,1) -> 0 | J53: =I54 -> 0 | K53: =IF(J53=1,EOMONTH(C53,0),"") | L53: =IF(WEEKDAY(K53,2)=6,K53-1,IF(WEEKDAY(K53,2)=7,K53-2,IF(J53=1,K53,""))) -> #VALUE! | M53: =IF(J53=1,D53,"") | N53: =IF($J53=1,E53,"") | O53: =IF($J53=1,F53,"") | P53: =IF($J53=1,G53,"") | W53: 39647 | X53: 1213.9 | AA53: 40892 | AB53: 1.4556319 | AC53: =AB53*100 -> 145.56319
C54: 40899 | D54: 0.96019587 | E54: 0.8253704 | F54: =VLOOKUP(C54+1,W:X,2,0) -> 3684.5 | G54: =VLOOKUP(C54,AA:AC,3,0) -> 150.87417 | H54: =MONTH(C54) -> 12 | I54: =IF(H54=H53,0,1) -> 0 | J54: =I55 -> 0 | K54: =IF(J54=1,EOMONTH(C54,0),"") | L54: =IF(WEEKDAY(K54,2)=6,K54-1,IF(WEEKDAY(K54,2)=7,K54-2,IF(J54=1,K54,""))) -> #VALUE! | M54: =IF(J54=1,D54,"") | N54: =IF($J54=1,E54,"") | O54: =IF($J54=1,F54,"") | P54: =IF($J54=1,G54,"") | W54: 39654 | X54: 874.1 | AA54: 40899 | AB54: 1.5087417 | AC54: =AB54*100 -> 150.87417
C55: 40906 | D55: 0.9476226 | E55: 0.81734633 | F55: =VLOOKUP(C55+1,W:X,2,0) -> 3608.1 | G55: =VLOOKUP(C55,AA:AC,3,0) -> 147.01164 | H55: =MONTH(C55) -> 12 | I55: =IF(H55=H54,0,1) -> 0 | J55: =I56 -> 1 | K55: =IF(J55=1,EOMONTH(C55,0),"") -> 40908 | L55: =IF(WEEKDAY(K55,2)=6,K55-1,IF(WEEKDAY(K55,2)=7,K55-2,IF(J55=1,K55,""))) -> 40907 | M55: =IF(J55=1,D55,"") -> 0.9476226 | N55: =IF($J55=1,E55,"") -> 0.81734633 | O55: =IF($J55=1,F55,"") -> 3608.1 | P55: =IF($J55=1,G55,"") -> 147.01164 | W55: 39661 | X55: 897.7 | AA55: 40906 | AB55: 1.4701164 | AC55: =AB55*100 -> 147.01164
C56: 40913 | D56: 0.94481774 | E56: 0.80629912 | F56: =VLOOKUP(C56+1,W:X,2,0) -> 3668.3 | G56: =VLOOKUP(C56,AA:AC,3,0) -> 145.54458 | H56: =MONTH(C56) -> 1 | I56: =IF(H56=H55,0,1) -> 1 | J56: =I57 -> 0 | K56: =IF(J56=1,EOMONTH(C56,0),"") | L56: =IF(WEEKDAY(K56,2)=6,K56-1,IF(WEEKDAY(K56,2)=7,K56-2,IF(J56=1,K56,""))) -> #VALUE! | M56: =IF(J56=1,D56,"") | N56: =IF($J56=1,E56,"") | O56: =IF($J56=1,F56,"") | P56: =IF($J56=1,G56,"") | W56: 39668 | X56: 853.1 | AA56: 40913 | AB56: 1.4554458 | AC56: =AB56*100 -> 145.54458
C57: 40920 | D57: 0.95320352 | E57: 0.81626219 | F57: =VLOOKUP(C57+1,W:X,2,0) -> 4626.5 | G57: =VLOOKUP(C57,AA:AC,3,0) -> 149.88559 | H57: =MONTH(C57) -> 1 | I57: =IF(H57=H56,0,1) -> 0 | J57: =I58 -> 0 | K57: =IF(J57=1,EOMONTH(C57,0),"") | L57: =IF(WEEKDAY(K57,2)=6,K57-1,IF(WEEKDAY(K57,2)=7,K57-2,IF(J57=1,K57,""))) -> #VALUE! | M57: =IF(J57=1,D57,"") | N57: =IF($J57=1,E57,"") | O57: =IF($J57=1,F57,"") | P57: =IF($J57=1,G57,"") | W57: 39675 | X57: 815.2 | AA57: 40920 | AB57: 1.4988559 | AC57: =AB57*100 -> 149.88559
C58: 40927 | D58: 0.95182772 | E58: 0.81461585 | F58: =VLOOKUP(C58+1,W:X,2,0) -> 4326.4 | G58: =VLOOKUP(C58,AA:AC,3,0) -> 148.43859 | H58: =MONTH(C58) -> 1 | I58: =IF(H58=H57,0,1) -> 0 | J58: =I59 -> 0 | K58: =IF(J58=1,EOMONTH(C58,0),"") | L58: =IF(WEEKDAY(K58,2)=6,K58-1,IF(WEEKDAY(K58,2)=7,K58-2,IF(J58=1,K58,""))) -> #VALUE! | M58: =IF(J58=1,D58,"") | N58: =IF($J58=1,E58,"") | O58: =IF($J58=1,F58,"") | P58: =IF($J58=1,G58,"") | W58: 39682 | X58: 793.9 | AA58: 40927 | AB58: 1.4843859 | AC58: =AB58*100 -> 148.43859
C59: 40934 | D59: 0.91861521 | E59: 0.78339394 | F59: =VLOOKUP(C59+1,W:X,2,0) -> 4184.3 | G59: =VLOOKUP(C59,AA:AC,3,0) -> 141.20356 | H59: =MONTH(C59) -> 1 | I59: =IF(H59=H58,0,1) -> 0 | J59: =I60 -> 1 | K59: =IF(J59=1,EOMONTH(C59,0),"") -> 40939 | L59: =IF(WEEKDAY(K59,2)=6,K59-1,IF(WEEKDAY(K59,2)=7,K59-2,IF(J59=1,K59,""))) -> 40939 | M59: =IF(J59=1,D59,"") -> 0.91861521 | N59: =IF($J59=1,E59,"") -> 0.78339394 | O59: =IF($J59=1,F59,"") -> 4184.3 | P59: =IF($J59=1,G59,"") -> 141.20356 | W59: 39689 | X59: 825 | AA59: 40934 | AB59: 1.4120356 | AC59: =AB59*100 -> 141.20356
C60: 40941 | D60: 0.94107838 | E60: 0.79842548 | F60: =VLOOKUP(C60+1,W:X,2,0) -> 4617.1 | G60: =VLOOKUP(C60,AA:AC,3,0) -> 145.72263 | H60: =MONTH(C60) -> 2 | I60: =IF(H60=H59,0,1) -> 1 | J60: =I61 -> 0 | K60: =IF(J60=1,EOMONTH(C60,0),"") | L60: =IF(WEEKDAY(K60,2)=6,K60-1,IF(WEEKDAY(K60,2)=7,K60-2,IF(J60=1,K60,""))) -> #VALUE! | M60: =IF(J60=1,D60,"") | N60: =IF($J60=1,E60,"") | O60: =IF($J60=1,F60,"") | P60: =IF($J60=1,G60,"") | W60: 39696 | X60: 998.3 | AA60: 40941 | AB60: 1.4572263 | AC60: =AB60*100 -> 145.72263
C61: 40948 | D61: 0.94107838 | E61: 0.79842548 | F61: =VLOOKUP(C61+1,W:X,2,0) -> 4716.1 | G61: =VLOOKUP(C61,AA:AC,3,0) -> 145.72263 | H61: =MONTH(C61) -> 2 | I61: =IF(H61=H60,0,1) -> 0 | J61: =I62 -> 0 | K61: =IF(J61=1,EOMONTH(C61,0),"") | L61: =IF(WEEKDAY(K61,2)=6,K61-1,IF(WEEKDAY(K61,2)=7,K61-2,IF(J61=1,K61,""))) -> #VALUE! | M61: =IF(J61=1,D61,"") | N61: =IF($J61=1,E61,"") | O61: =IF($J61=1,F61,"") | P61: =IF($J61=1,G61,"") | W61: 39703 | X61: 2068.5 | AA61: 40948 | AB61: 1.4572263 | AC61: =AB61*100 -> 145.72263
C62: 40955 | D62: 0.94107838 | E62: 0.79842548 | F62: =VLOOKUP(C62+1,W:X,2,0) -> 4466.9 | G62: =VLOOKUP(C62,AA:AC,3,0) -> 145.72263 | H62: =MONTH(C62) -> 2 | I62: =IF(H62=H61,0,1) -> 0 | J62: =I63 -> 0 | K62: =IF(J62=1,EOMONTH(C62,0),"") | L62: =IF(WEEKDAY(K62,2)=6,K62-1,IF(WEEKDAY(K62,2)=7,K62-2,IF(J62=1,K62,""))) -> #VALUE! | M62: =IF(J62=1,D62,"") | N62: =IF($J62=1,E62,"") | O62: =IF($J62=1,F62,"") | P62: =IF($J62=1,G62,"") | W62: 39710 | X62: 1756.8 | AA62: 40955 | AB62: 1.4572263 | AC62: =AB62*100 -> 145.72263
... C119: 41354 | D119: 0.76832709 | E119: 0.72870486 | F119: =VLOOKUP(C119+1,W:X,2,0) -> 4412.9 | G119: =VLOOKUP(C119,AA:AC,3,0) -> 134.85819 | H119: =MONTH(C119) -> 3 | I119: =IF(H119=H118,0,1) -> 0 | J119: =I120 -> 0 | K119: =IF(J119=1,EOMONTH(C119,0),"") | L119: =IF(WEEKDAY(K119,2)=6,K119-1,IF(WEEKDAY(K119,2)=7,K119-2,IF(J119=1,K119,""))) -> #VALUE! | M119: =IF(J119=1,D119,"") | N119: =IF($J119=1,E119,"") | O119: =IF($J119=1,F119,"") | P119: =IF($J119=1,G119,"") | W119: 40109 | X119: 2304 | AA119: 41354 | AB119: 1.3485819 | AC119: =AB119*100 -> 134.85819
C120: 41361 | D120: 0.73085022 | E120: 0.71206287 | F120: =VLOOKUP(C120+1,W:X,2,0) -> 4119.2 | G120: =VLOOKUP(C120,AA:AC,3,0) -> 131.92348 | H120: =MONTH(C120) -> 3 | I120: =IF(H120=H119,0,1) -> 0 | J120: =I121 -> 1 | K120: =IF(J120=1,EOMONTH(C120,0),"") -> 41364 | L120: =IF(WEEKDAY(K120,2)=6,K120-1,IF(WEEKDAY(K120,2)=7,K120-2,IF(J120=1,K120,"")))-1 -> 41361 | M120: =IF(J120=1,D120,"") -> 0.73085022 | N120: =IF($J120=1,E120,"") -> 0.71206287 | O120: =IF($J120=1,F120,"") -> 4119.2 | P120: =IF($J120=1,G120,"") -> 131.92348 | W120: 40116 | X120: 2715.2 | AA120: 41361 | AB120: 1.3192348 | AC120: =AB120*100 -> 131.92348
C121: 41368 | D121: 0.74812714 | E121: 0.71361317 | F121: =VLOOKUP(C121+1,W:X,2,0) -> 4528.9 | G121: =VLOOKUP(C121,AA:AC,3,0) -> 132.40001 | H121: =MONTH(C121) -> 4 | I121: =IF(H121=H120,0,1) -> 1 | J121: =I122 -> 0 | K121: =IF(J121=1,EOMONTH(C121,0),"") | L121: =IF(WEEKDAY(K121,2)=6,K121-1,IF(WEEKDAY(K121,2)=7,K121-2,IF(J121=1,K121,""))) -> #VALUE! | M121: =IF(J121=1,D121,"") | N121: =IF($J121=1,E121,"") | O121: =IF($J121=1,F121,"") | P121: =IF($J121=1,G121,"") | W121: 40123 | X121: 2996 | AA121: 41368 | AB121: 1.3240001 | AC121: =AB121*100 -> 132.40001
C122: 41375 | D122: 0.81951891 | E122: 0.73719139 | F122: =VLOOKUP(C122+1,W:X,2,0) -> 4726.9 | G122: =VLOOKUP(C122,AA:AC,3,0) -> 143.20343 | H122: =MONTH(C122) -> 4 | I122: =IF(H122=H121,0,1) -> 0 | J122: =I123 -> 0 | K122: =IF(J122=1,EOMONTH(C122,0),"") | L122: =IF(WEEKDAY(K122,2)=6,K122-1,IF(WEEKDAY(K122,2)=7,K122-2,IF(J122=1,K122,""))) -> #VALUE! | M122: =IF(J122=1,D122,"") | N122: =IF($J122=1,E122,"") | O122: =IF($J122=1,F122,"") | P122: =IF($J122=1,G122,"") | W122: 40130 | X122: 3117 | AA122: 41375 | AB122: 1.4320343 | AC122: =AB122*100 -> 143.20343
C123: 41382 | D123: 0.82637993 | E123: 0.76108986 | F123: =VLOOKUP(C123+1,W:X,2,0) -> 4672.1 | G123: =VLOOKUP(C123,AA:AC,3,0) -> 147.62302 | H123: =MONTH(C123) -> 4 | I123: =IF(H123=H122,0,1) -> 0 | J123: =I124 -> 0 | K123: =IF(J123=1,EOMONTH(C123,0),"") | L123: =IF(WEEKDAY(K123,2)=6,K123-1,IF(WEEKDAY(K123,2)=7,K123-2,IF(J123=1,K123,""))) -> #VALUE! | M123: =IF(J123=1,D123,"") | N123: =IF($J123=1,E123,"") | O123: =IF($J123=1,F123,"") | P123: =IF($J123=1,G123,"") | W123: 40137 | X123: 2815.1 | AA123: 41382 | AB123: 1.4762302 | AC123: =AB123*100 -> 147.62302
C124: 41389 | D124: 0.82478602 | E124: 0.75993927 | F124: =VLOOKUP(C124+1,W:X,2,0) -> 4854.1 | G124: =VLOOKUP(C124,AA:AC,3,0) -> 146.14982 | H124: =MONTH(C124) -> 4 | I124: =IF(H124=H123,0,1) -> 0 | J124: =I125 -> 1 | K124: =IF(J124=1,EOMONTH(C124,0),"") -> 41394 | L124: =IF(WEEKDAY(K124,2)=6,K124-1,IF(WEEKDAY(K124,2)=7,K124-2,IF(J124=1,K124,""))) -> 41394 | M124: =IF(J124=1,D124,"") -> 0.82478602 | N124: =IF($J124=1,E124,"") -> 0.75993927 | O124: =IF($J124=1,F124,"") -> 4854.1 | P124: =IF($J124=1,G124,"") -> 146.14982 | W124: 40144 | X124: 2958.4 | AA124: 41389 | AB124: 1.4614982 | AC124: =AB124*100 -> 146.14982
C125: 41396 | D125: 0.81686282 | E125: 0.77520531 | F125: =VLOOKUP(C125+1,W:X,2,0) -> 5279.9 | G125: =VLOOKUP(C125,AA:AC,3,0) -> 151.66865 | H125: =MONTH(C125) -> 5 | I125: =IF(H125=H124,0,1) -> 1 | J125: =I126 -> 0 | K125: =IF(J125=1,EOMONTH(C125,0),"") | L125: =IF(WEEKDAY(K125,2)=6,K125-1,IF(WEEKDAY(K125,2)=7,K125-2,IF(J125=1,K125,""))) -> #VALUE! | M125: =IF(J125=1,D125,"") | N125: =IF($J125=1,E125,"") | O125: =IF($J125=1,F125,"") | P125: =IF($J125=1,G125,"") | W125: 40151 | X125: 3312.7 | AA125: 41396 | AB125: 1.5166865 | AC125: =AB125*100 -> 151.66865
C126: 41403 | D126: 0.80807149 | E126: 0.75094523 | F126: =VLOOKUP(C126+1,W:X,2,0) -> 4797.2 | G126: =VLOOKUP(C126,AA:AC,3,0) -> 144.7713 | H126: =MONTH(C126) -> 5 | I126: =IF(H126=H125,0,1) -> 0 | J126: =I127 -> 0 | K126: =IF(J126=1,EOMONTH(C126,0),"") | L126: =IF(WEEKDAY(K126,2)=6,K126-1,IF(WEEKDAY(K126,2)=7,K126-2,IF(J126=1,K126,""))) -> #VALUE! | M126: =IF(J126=1,D126,"") | N126: =IF($J126=1,E126,"") | O126: =IF($J126=1,F126,"") | P126: =IF($J126=1,G126,"") | W126: 40158 | X126: 3354 | AA126: 41403 | AB126: 1.447713 | AC126: =AB126*100 -> 144.7713
C127: 41410 | D127: 0.77783404 | E127: 0.7215905 | F127: =VLOOKUP(C127+1,W:X,2,0) -> 4241.5 | G127: =VLOOKUP(C127,AA:AC,3,0) -> 135.90326 | H127: =MONTH(C127) -> 5 | I127: =IF(H127=H126,0,1) -> 0 | J127: =I128 -> 0 | K127: =IF(J127=1,EOMONTH(C127,0),"") | L127: =IF(WEEKDAY(K127,2)=6,K127-1,IF(WEEKDAY(K127,2)=7,K127-2,IF(J127=1,K127,""))) -> #VALUE! | M127: =IF(J127=1,D127,"") | N127: =IF($J127=1,E127,"") | O127: =IF($J127=1,F127,"") | P127: =IF($J127=1,G127,"") | W127: 40165 | X127: 2988.7 | AA127: 41410 | AB127: 1.3590326 | AC127: =AB127*100 -> 135.90326
...
