Workbook

Sheet Price D Coupon
G5: 3 | H5: 3 | I5: 3.5 | J5: 3.5 | K5: 3.5 | L5: 3.5 | M5: 4 | N5: 4 | O5: 4 | P5: 4 | Q5: 4 | R5: 4.5 | S5: 4.5 | T5: 4.5 | U5: 5 | V5: 5 | W5: 5.5 | X5: 6 | Y5: 6.5
F6: Px/coupon | AI6: Weight
F7: Date | G7: FN30. 300. 13 | H7: FN30. 300. 12 | I7: FN30. 350. 14 | J7: FN30. 350. 13 | K7: FN30. 350. 12 | L7: FN30. 350. 10 | M7: FN30. 400. 14 | N7: FN30. 400. 13 | O7: FN30. 400. 11 | P7: FN30. 400. 10 | Q7: FN30. 400. 09 | R7: FN30. 450. 11 | S7: FN30. 450. 10 | T7: FN30. 450. 09 | U7: FN30. 500. 10 | V7: FN30. 500. 09 | W7: FN30. 550. 08 | X7: FN30. 600. 08 | Y7: FN30. 650. 67 | Z7: GII30. 400. 10 | AA7: GII30. 450. 10 | AB7: GII30. 500. 10 | AC7: Avg | AE7: Date | AF7: Current Coupon | AI7: Date | AJ7: FN30. 300. 13 | AK7: FN30. 300. 12 | AL7: FN30. 350. 14 | AM7: FN30. 350. 13 | AN7: FN30. 350. 12 | AO7: FN30. 350. 10 | AP7: FN30. 400. 14 | AQ7: FN30. 400. 13 | AR7: FN30. 400. 11 | AS7: FN30. 400. 10 | AT7: FN30. 400. 09 | AU7: FN30. 450. 11 | AV7: FN30. 450. 10 | AW7: FN30. 450. 09 | AX7: FN30. 500. 10 | AY7: FN30. 500. 09 | AZ7: FN30. 550. 08 | BA7: FN30. 600. 08 | BB7: FN30. 650. 67 | BC7: Total
F8: 40633 | G8: =Price!G8/'Price D Coupon'!G$5 -> 0 | H8: =Price!H8/'Price D Coupon'!H$5 -> 0 | I8: =Price!I8/'Price D Coupon'!I$5 -> 0 | J8: =Price!J8/'Price D Coupon'!J$5 -> 0 | K8: =Price!K8/'Price D Coupon'!K$5 -> 0 | L8: =Price!L8/'Price D Coupon'!L$5 -> 7.0884921 | M8: =Price!M8/'Price D Coupon'!M$5 -> 0 | N8: =Price!N8/'Price D Coupon'!N$5 -> 0 | ... Y8: =Price!Y8/'Price D Coupon'!Y$5 -> 3.2810853 | AC8: 23.785472 | AE8: 40633 | AF8: =VLOOKUP(AE8,CurrentCoupon!B4:C1506,2,0) -> 4.2707131 | AI8: 40633 | AJ8: 0 | AK8: 0 | AL8: 0 | AM8: 0 | AN8: 0 | AO8: 0.02740631 | AP8: 0 | AQ8: 0 | AR8: 0 | AS8: 0.14046649 | AT8: 0.12948424 | AU8: 0 | AV8: 0.12975199 | AW8: 0.2882927 | AX8: 0.062968111 | AY8: 0.066411433 | AZ8: 0.070279501 | BA8: 0.036736393 | BB8: 0.048202832 | BC8: =SUM(AJ8:BB8) -> 1 | BE8: Date | BF8: Monthly Return (%)
F9: 40662 | G9: =Price!G9/'Price D Coupon'!G$5 -> 0 | H9: =Price!H9/'Price D Coupon'!H$5 -> 0 | I9: =Price!I9/'Price D Coupon'!I$5 -> 0 | J9: =Price!J9/'Price D Coupon'!J$5 -> 0 | K9: =Price!K9/'Price D Coupon'!K$5 -> 0 | L9: =Price!L9/'Price D Coupon'!L$5 -> 7.1224124 | M9: =Price!M9/'Price D Coupon'!M$5 -> 0 | N9: =Price!N9/'Price D Coupon'!N$5 -> 0 | ... Y9: =Price!Y9/'Price D Coupon'!Y$5 -> 3.3001709 | AC9: 24.080744 | AE9: 40662 | AF9: =VLOOKUP(AE9,CurrentCoupon!$B$4:$C$1468,2,0) -> 4.0711737 | AI9: 40662 | AJ9: 0 | AK9: 0 | AL9: 0 | AM9: 0 | AN9: 0 | AO9: 0.027596454 | AP9: 0 | AQ9: 0 | AR9: 0 | AS9: 0.14136961 | AT9: 0.12997806 | AU9: 0 | AV9: 0.13033036 | AW9: 0.28862028 | AX9: 0.063100659 | AY9: 0.066274006 | AZ9: 0.069072966 | BA9: 0.036075726 | BB9: 0.047581877 | BC9: =SUM(AJ9:BB9) -> 1 | BE9: 40633 | BF9: =G8*AJ8 -> 0
F10: 40694 | G10: =Price!G10/'Price D Coupon'!G$5 -> 0 | H10: =Price!H10/'Price D Coupon'!H$5 -> 0 | I10: =Price!I10/'Price D Coupon'!I$5 -> 0 | J10: =Price!J10/'Price D Coupon'!J$5 -> 0 | K10: =Price!K10/'Price D Coupon'!K$5 -> 0 | L10: =Price!L10/'Price D Coupon'!L$5 -> 7.2636352 | M10: =Price!M10/'Price D Coupon'!M$5 -> 0 | N10: =Price!N10/'Price D Coupon'!N$5 -> 0 | ... Y10: =Price!Y10/'Price D Coupon'!Y$5 -> 3.4043162 | AC10: 24.186373 | AE10: 40694 | AF10: =VLOOKUP(AE10,CurrentCoupon!$B$4:$C$1468,2,0) -> 3.9138663 | AI10: 40694 | AJ10: 0 | AK10: 0 | AL10: 0 | AM10: 0 | AN10: 0 | AO10: 0.027772655 | AP10: 0 | AQ10: 0 | AR10: 0 | AS10: 0.14222877 | AT10: 0.13043914 | AU10: 0 | AV10: 0.13089219 | AW10: 0.2890731 | AX10: 0.063273705 | AY10: 0.066206835 | AZ10: 0.067961286 | BA10: 0.035405405 | BB10: 0.046746918 | BC10: =SUM(AJ10:BB10) -> 1 | BE10: 40662 | BF10: 0.01824177
F11: 40724 | G11: =Price!G11/'Price D Coupon'!G$5 -> 0 | H11: =Price!H11/'Price D Coupon'!H$5 -> 0 | I11: =Price!I11/'Price D Coupon'!I$5 -> 0 | J11: =Price!J11/'Price D Coupon'!J$5 -> 0 | K11: =Price!K11/'Price D Coupon'!K$5 -> 0 | L11: =Price!L11/'Price D Coupon'!L$5 -> 7.3284921 | M11: =Price!M11/'Price D Coupon'!M$5 -> 0 | N11: =Price!N11/'Price D Coupon'!N$5 -> 0 | ... Y11: =Price!Y11/'Price D Coupon'!Y$5 -> 3.4553933 | AC11: 24.450172 | AE11: 40724 | AF11: =VLOOKUP(AE11,CurrentCoupon!$B$4:$C$1468,2,0) -> 4.0109297 | AI11: 40724 | AJ11: 0 | AK11: 0 | AL11: 0 | AM11: 0 | AN11: 0 | AO11: 0.027926502 | AP11: 0 | AQ11: 0 | AR11: 0 | AS11: 0.14295239 | AT11: 0.13080465 | AU11: 0 | AV11: 0.13137858 | AW11: 0.28954874 | AX11: 0.063413193 | AY11: 0.06616714 | AZ11: 0.06697561 | BA11: 0.034766829 | BB11: 0.046066367 | BC11: =SUM(AJ11:BB11) -> 1 | BE11: 40694 | BF11: 0.0095136889
F12: 40753 | G12: =Price!G12/'Price D Coupon'!G$5 -> 0 | H12: =Price!H12/'Price D Coupon'!H$5 -> 0 | I12: =Price!I12/'Price D Coupon'!I$5 -> 0 | J12: =Price!J12/'Price D Coupon'!J$5 -> 0 | K12: =Price!K12/'Price D Coupon'!K$5 -> 0 | L12: =Price!L12/'Price D Coupon'!L$5 -> 7.1242063 | M12: =Price!M12/'Price D Coupon'!M$5 -> 0 | N12: =Price!N12/'Price D Coupon'!N$5 -> 0 | ... Y12: =Price!Y12/'Price D Coupon'!Y$5 -> 3.3604701 | AC12: 23.116972 | AE12: 40753 | AF12: =VLOOKUP(AE12,CurrentCoupon!$B$4:$C$1468,2,0) -> 3.657087 | AI12: 40753 | AJ12: 0 | AK12: 0 | AL12: 0 | AM12: 0 | AN12: 0 | AO12: 0.028075952 | AP12: 0 | AQ12: 0 | AR12: 0 | AS12: 0.14365704 | AT12: 0.13116041 | AU12: 0 | AV12: 0.13186399 | AW12: 0.28990557 | AX12: 0.063549087 | AY12: 0.066127746 | AZ12: 0.06605268 | BA12: 0.034214858 | BB12: 0.045392667 | BC12: =SUM(AJ12:BB12) -> 1 | BE12: 40724 | BF12: 0.014594354
F13: 40786 | G13: =Price!G13/'Price D Coupon'!G$5 -> 0 | H13: =Price!H13/'Price D Coupon'!H$5 -> 0 | I13: =Price!I13/'Price D Coupon'!I$5 -> 0 | J13: =Price!J13/'Price D Coupon'!J$5 -> 0 | K13: =Price!K13/'Price D Coupon'!K$5 -> 0 | L13: =Price!L13/'Price D Coupon'!L$5 -> 6.3027778 | M13: =Price!M13/'Price D Coupon'!M$5 -> 0 | N13: =Price!N13/'Price D Coupon'!N$5 -> 0 | ... Y13: =Price!Y13/'Price D Coupon'!Y$5 -> 3.0720085 | AC13: 18.855772 | AE13: 40786 | AF13: =VLOOKUP(AE13,CurrentCoupon!$B$4:$C$1468,2,0) -> 3.2634227 | AI13: 40786 | AJ13: 0 | AK13: 0 | AL13: 0 | AM13: 0 | AN13: 0 | AO13: 0.028268828 | AP13: 0 | AQ13: 0 | AR13: 0 | AS13: 0.14449103 | AT13: 0.13161044 | AU13: 0 | AV13: 0.13233924 | AW13: 0.289819 | AX13: 0.063677522 | AY13: 0.065940194 | AZ13: 0.065193394 | BA13: 0.033758086 | BB13: 0.044902263 | BC13: =SUM(AJ13:BB13) -> 1 | BE13: 40753 | BF13: -0.056499118
F14: 40816 | G14: =Price!G14/'Price D Coupon'!G$5 -> 0 | H14: =Price!H14/'Price D Coupon'!H$5 -> 0 | I14: =Price!I14/'Price D Coupon'!I$5 -> 0 | J14: =Price!J14/'Price D Coupon'!J$5 -> 0 | K14: =Price!K14/'Price D Coupon'!K$5 -> 0 | L14: =Price!L14/'Price D Coupon'!L$5 -> 5.2637619 | M14: =Price!M14/'Price D Coupon'!M$5 -> 0 | N14: =Price!N14/'Price D Coupon'!N$5 -> 0 | ... Y14: =Price!Y14/'Price D Coupon'!Y$5 -> 2.6832564 | AC14: 15.498617 | AE14: 40816 | AF14: =VLOOKUP(AE14,CurrentCoupon!$B$4:$C$1468,2,0) -> 3.0428156 | AI14: 40816 | AJ14: 0 | AK14: 0 | AL14: 0 | AM14: 0 | AN14: 0 | AO14: 0.028492304 | AP14: 0 | AQ14: 0 | AR14: 0 | AS14: 0.14538344 | AT14: 0.13200486 | AU14: 0 | AV14: 0.13281236 | AW14: 0.28945244 | AX14: 0.063769571 | AY14: 0.065782077 | AZ14: 0.064422398 | BA14: 0.033367229 | BB14: 0.04451333 | BC14: =SUM(AJ14:BB14) -> 1 | BE14: 40786 | BF14: -0.20415555
F15: 40847 | G15: =Price!G15/'Price D Coupon'!G$5 -> 0 | H15: =Price!H15/'Price D Coupon'!H$5 -> 0 | I15: =Price!I15/'Price D Coupon'!I$5 -> 0 | J15: =Price!J15/'Price D Coupon'!J$5 -> 0 | K15: =Price!K15/'Price D Coupon'!K$5 -> 0 | L15: =Price!L15/'Price D Coupon'!L$5 -> 5.1733495 | M15: =Price!M15/'Price D Coupon'!M$5 -> 0 | N15: =Price!N15/'Price D Coupon'!N$5 -> 0 | ... Y15: =Price!Y15/'Price D Coupon'!Y$5 -> 2.5960085 | AC15: 16.119872 | AE15: 40847 | AF15: =VLOOKUP(AE15,CurrentCoupon!$B$4:$C$1468,2,0) -> 3.1403563 | AI15: 40847 | AJ15: 0 | AK15: 0 | AL15: 0 | AM15: 0 | AN15: 0 | AO15: 0.028725425 | AP15: 0 | AQ15: 0 | AR15: 0 | AS15: 0.14628268 | AT15: 0.13244363 | AU15: 0 | AV15: 0.13326506 | AW15: 0.28906694 | AX15: 0.063944654 | AY15: 0.065618839 | AZ15: 0.063584558 | BA15: 0.032958172 | BB15: 0.044110044 | BC15: =SUM(AJ15:BB15) -> 1 | BE15: 40816 | BF15: -0.18608869
F16: 40877 | G16: =Price!G16/'Price D Coupon'!G$5 -> 0 | H16: =Price!H16/'Price D Coupon'!H$5 -> 0 | I16: =Price!I16/'Price D Coupon'!I$5 -> 0 | J16: =Price!J16/'Price D Coupon'!J$5 -> 0 | K16: =Price!K16/'Price D Coupon'!K$5 -> 0 | L16: =Price!L16/'Price D Coupon'!L$5 -> 5.0527778 | M16: =Price!M16/'Price D Coupon'!M$5 -> 0 | N16: =Price!N16/'Price D Coupon'!N$5 -> 0 | ... Y16: =Price!Y16/'Price D Coupon'!Y$5 -> 2.7306239 | AC16: 16.294972 | AE16: 40877 | AF16: =VLOOKUP(AE16,CurrentCoupon!$B$4:$C$1468,2,0) -> 3.1429303 | AI16: 40877 | AJ16: 0 | AK16: 0 | AL16: 0 | AM16: 0 | AN16: 0 | AO16: 0.029113476 | AP16: 0 | AQ16: 0 | AR16: 0 | AS16: 0.14674367 | AT16: 0.13246171 | AU16: 0 | AV16: 0.13350213 | AW16: 0.28777046 | AX16: 0.064358005 | AY16: 0.06568972 | AZ16: 0.063254791 | BA16: 0.032898514 | BB16: 0.044207529 | BC16: =SUM(AJ16:BB16) -> 1 | BE16: 40847 | BF16: 0.052849339
F17: 40907 | G17: =Price!G17/'Price D Coupon'!G$5 -> 0 | H17: =Price!H17/'Price D Coupon'!H$5 -> 0 | I17: =Price!I17/'Price D Coupon'!I$5 -> 0 | J17: =Price!J17/'Price D Coupon'!J$5 -> 0 | K17: =Price!K17/'Price D Coupon'!K$5 -> 0 | L17: =Price!L17/'Price D Coupon'!L$5 -> 4.9109045 | M17: =Price!M17/'Price D Coupon'!M$5 -> 0 | N17: =Price!N17/'Price D Coupon'!N$5 -> 0 | ... Y17: =Price!Y17/'Price D Coupon'!Y$5 -> 2.6712563 | AC17: 15.896817 | AE17: 40907 | AF17: =VLOOKUP(AE17,CurrentCoupon!$B$4:$C$1468,2,0) -> 2.9957031 | AI17: 40907 | AJ17: 0 | AK17: 0 | AL17: 0 | AM17: 0 | AN17: 0 | AO17: 0.029527009 | AP17: 0 | AQ17: 0 | AR17: 0 | AS17: 0.14725219 | AT17: 0.13222635 | AU17: 0 | AV17: 0.13390235 | AW17: 0.28593974 | AX17: 0.064909729 | AY17: 0.065805924 | AZ17: 0.063058815 | BA17: 0.032938146 | BB17: 0.044439745 | BC17: =SUM(AJ17:BB17) -> 1 | BE17: 40877 | BF17: -0.0070201413
F18: 40939 | G18: =Price!G18/'Price D Coupon'!G$5 -> 0 | H18: =Price!H18/'Price D Coupon'!H$5 -> 0 | I18: =Price!I18/'Price D Coupon'!I$5 -> 0 | J18: =Price!J18/'Price D Coupon'!J$5 -> 0 | K18: =Price!K18/'Price D Coupon'!K$5 -> 0 | L18: =Price!L18/'Price D Coupon'!L$5 -> 4.5884921 | M18: =Price!M18/'Price D Coupon'!M$5 -> 0 | N18: =Price!N18/'Price D Coupon'!N$5 -> 0 | ... Y18: =Price!Y18/'Price D Coupon'!Y$5 -> 2.5912393 | AC18: 14.673172 | AE18: 40939 | AF18: =VLOOKUP(AE18,CurrentCoupon!$B$4:$C$1468,2,0) -> 2.7164025 | AI18: 40939 | AJ18: 0 | AK18: 0 | AL18: 0 | AM18: 0 | AN18: 0 | AO18: 0.029942398 | AP18: 0 | AQ18: 0 | AR18: 0 | AS18: 0.14782151 | AT18: 0.13183303 | AU18: 0 | AV18: 0.13443017 | AW18: 0.28368873 | AX18: 0.065593518 | AY18: 0.065946486 | AZ18: 0.062894336 | BA18: 0.033040183 | BB18: 0.044809632 | BC18: =SUM(AJ18:BB18) -> 1 | BE18: 40907 | BF18: -0.027877514
F19: 40968 | G19: =Price!G19/'Price D Coupon'!G$5 -> 0 | H19: =Price!H19/'Price D Coupon'!H$5 -> 0 | I19: =Price!I19/'Price D Coupon'!I$5 -> 0 | J19: =Price!J19/'Price D Coupon'!J$5 -> 0 | K19: =Price!K19/'Price D Coupon'!K$5 -> 0 | L19: =Price!L19/'Price D Coupon'!L$5 -> 5.1153492 | M19: =Price!M19/'Price D Coupon'!M$5 -> 0 | N19: =Price!N19/'Price D Coupon'!N$5 -> 0 | ... Y19: =Price!Y19/'Price D Coupon'!Y$5 -> 2.7330856 | AC19: 16.240573 | AE19: 40968 | AF19: =VLOOKUP(AE19,CurrentCoupon!$B$4:$C$1468,2,0) -> 2.890803 | AI19: 40968 | AJ19: 0 | AK19: 0 | AL19: 0 | AM19: 0 | AN19: 0 | AO19: 0.030392644 | AP19: 0 | AQ19: 0 | AR19: 0 | AS19: 0.14898141 | AT19: 0.13169001 | AU19: 0 | AV19: 0.13497453 | AW19: 0.28152185 | AX19: 0.066073219 | AY19: 0.065906231 | AZ19: 0.062505841 | BA19: 0.032979696 | BB19: 0.044974565 | BC19: =SUM(AJ19:BB19) -> 1 | BE19: 40939 | BF19: -0.088730633
F20: 40998 | G20: =Price!G20/'Price D Coupon'!G$5 -> 0 | H20: =Price!H20/'Price D Coupon'!H$5 -> 0 | I20: =Price!I20/'Price D Coupon'!I$5 -> 0 | J20: =Price!J20/'Price D Coupon'!J$5 -> 0 | K20: =Price!K20/'Price D Coupon'!K$5 -> 0 | L20: =Price!L20/'Price D Coupon'!L$5 -> 5.618127 | M20: =Price!M20/'Price D Coupon'!M$5 -> 0 | N20: =Price!N20/'Price D Coupon'!N$5 -> 0 | ... Y20: =Price!Y20/'Price D Coupon'!Y$5 -> 2.8584786 | AC20: 18.199972 | AE20: 40998 | AF20: =VLOOKUP(AE20,CurrentCoupon!$B$4:$C$1468,2,0) -> 3.1649158 | AI20: 40998 | AJ20: 0 | AK20: 0 | AL20: 0 | AM20: 0 | AN20: 0 | AO20: 0.024725973 | AP20: 0 | AQ20: 0 | AR20: 0.095316183 | AS20: 0.12045299 | AT20: 0.10575842 | AU20: 0.10063007 | AV20: 0.10895323 | AW20: 0.22498873 | AX20: 0.05350766 | AY20: 0.0530391 | AZ20: 0.049932228 | BA20: 0.0264329 | BB20: 0.036262506 | BC20: =SUM(AJ20:BB20) -> 1 | BE20: 40968 | BF20: 0.1267261
F21: 41029 | G21: =Price!G21/'Price D Coupon'!G$5 -> 0 | H21: =Price!H21/'Price D Coupon'!H$5 -> 0 | I21: =Price!I21/'Price D Coupon'!I$5 -> 0 | J21: =Price!J21/'Price D Coupon'!J$5 -> 0 | K21: =Price!K21/'Price D Coupon'!K$5 -> 0 | L21: =Price!L21/'Price D Coupon'!L$5 -> 5.2313492 | M21: =Price!M21/'Price D Coupon'!M$5 -> 0 | N21: =Price!N21/'Price D Coupon'!N$5 -> 0 | ... Y21: =Price!Y21/'Price D Coupon'!Y$5 -> 2.9398549 | AC21: 17.266278 | AE21: 41029 | AF21: =VLOOKUP(AE21,CurrentCoupon!$B$4:$C$1468,2,0) -> 2.873381 | AI21: 41029 | AJ21: 0 | AK21: 0 | AL21: 0 | AM21: 0 | AN21: 0 | AO21: 0.02498952 | AP21: 0 | AQ21: 0 | AR21: 0.096252094 | AS21: 0.12096088 | AT21: 0.10525104 | AU21: 0.10142706 | AV21: 0.10910633 | AW21: 0.22285725 | AX21: 0.053922533 | AY21: 0.053078509 | AZ21: 0.049455516 | BA21: 0.026337565 | BB21: 0.036361706 | BC21: =SUM(AJ21:BB21) -> 1 | BE21: 40998 | BF21: 0.10050254
... F43: 41698 | G43: =Price!G43/'Price D Coupon'!G$5 -> 0 | H43: =Price!H43/'Price D Coupon'!H$5 -> 7.521877 | I43: =Price!I43/'Price D Coupon'!I$5 -> 0 | J43: =Price!J43/'Price D Coupon'!J$5 -> 0 | K43: =Price!K43/'Price D Coupon'!K$5 -> 7.022619 | L43: =Price!L43/'Price D Coupon'!L$5 -> 6.5761905 | M43: =Price!M43/'Price D Coupon'!M$5 -> 0 | N43: =Price!N43/'Price D Coupon'!N$5 -> 0 | ... Y43: =Price!Y43/'Price D Coupon'!Y$5 -> 3.3467949 | AC43: 23.043605 | AE43: 41698 | AF43: =VLOOKUP(AE43,CurrentCoupon!$B$4:$C$1468,2,0) -> 3.3983133 | AI43: 41698 | AJ43: 0 | AK43: 0.19184365 | AL43: 0 | AM43: 0 | AN43: 0.23825886 | AO43: 0.016614291 | AP43: 0 | AQ43: 0 | AR43: 0.064985622 | AS43: 0.07514546 | AT43: 0.053572741 | AU43: 0.069537901 | AV43: 0.066686121 | AW43: 0.11131174 | AX43: 0.036160574 | AY43: 0.031281395 | AZ43: 0.017731279 | BA43: 0.010264369 | BB43: 0.016605998 | BC43: =SUM(AJ43:BB43) -> 1 | BE43: 41670 | BF43: -0.031266772
F44: 41729 | G44: =Price!G44/'Price D Coupon'!G$5 -> 7.7871548 | H44: =Price!H44/'Price D Coupon'!H$5 -> 7.5631944 | I44: =Price!I44/'Price D Coupon'!I$5 -> 0 | J44: =Price!J44/'Price D Coupon'!J$5 -> 7.3340295 | K44: =Price!K44/'Price D Coupon'!K$5 -> 7.0929581 | L44: =Price!L44/'Price D Coupon'!L$5 -> 6.6867063 | M44: =Price!M44/'Price D Coupon'!M$5 -> 0 | N44: =Price!N44/'Price D Coupon'!N$5 -> 6.4172758 | ... Y44: =Price!Y44/'Price D Coupon'!Y$5 -> 3.3532595 | AC44: 23.82194 | AE44: 41729 | AF44: =VLOOKUP(AE44,CurrentCoupon!$B$4:$C$1468,2,0) -> 3.5066269 | AG44: =IF(AF44<$G$5,G44,(H44-G44)/0.5*(AF44-$G$5)+G44) -> 7.5602261 | AI44: 41729 | AJ44: 0.14015953 | AK44: 0.12877118 | AL44: 0 | AM44: 0.09835625 | AN44: 0.15976314 | AO44: 0.011122974 | AP44: 0 | AQ44: 0.093316082 | AR44: 0.04347176 | AS44: 0.050247243 | AT44: 0.035773151 | AU44: 0.046432933 | AV44: 0.04446765 | AW44: 0.074114286 | AX44: 0.024082135 | AY44: 0.02077472 | AZ44: 0.011604631 | BA44: 0.0067031661 | BB44: 0.010839164 | BC44: =SUM(AJ44:BB44) -> 1 | BE44: 41698 | BF44: 0.021801735
F45: 41759 | G45: =Price!G45/'Price D Coupon'!G$5 -> 7.7767381 | H45: =Price!H45/'Price D Coupon'!H$5 -> 7.5684048 | I45: =Price!I45/'Price D Coupon'!I$5 -> 0 | J45: =Price!J45/'Price D Coupon'!J$5 -> 7.2715295 | K45: =Price!K45/'Price D Coupon'!K$5 -> 7.0081349 | L45: =Price!L45/'Price D Coupon'!L$5 -> 6.5840295 | M45: =Price!M45/'Price D Coupon'!M$5 -> 0 | N45: =Price!N45/'Price D Coupon'!N$5 -> 6.3625883 | ... Y45: =Price!Y45/'Price D Coupon'!Y$5 -> 3.3989316 | AC45: 23.537013 | AE45: 41759 | AF45: =VLOOKUP(AE45,CurrentCoupon!$B$4:$C$1468,2,0) -> 3.2758212 | AG45: =IF(AF45<$G$5,G45,(H45-G45)/0.5*(AF45-$G$5)+G45) -> 7.6618126 | AI45: 41759 | AJ45: 0.14062117 | AK45: 0.12911479 | AL45: 0 | AM45: 0.09864385 | AN45: 0.16001339 | AO45: 0.011122388 | AP45: 0 | AQ45: 0.09352348 | AR45: 0.043464161 | AS45: 0.05021791 | AT45: 0.035710082 | AU45: 0.046333066 | AV45: 0.044342722 | AW45: 0.073778213 | AX45: 0.023949658 | AY45: 0.020624509 | AZ45: 0.011370895 | BA45: 0.0065605566 | BB45: 0.010609155 | BC45: =SUM(AJ45:BB45) -> 1 | BE45: 41729 | BF45: 0.021192307
F46: 41789 | G46: =Price!G46/'Price D Coupon'!G$5 -> 7.6753492 | H46: =Price!H46/'Price D Coupon'!H$5 -> 7.4930556 | I46: =Price!I46/'Price D Coupon'!I$5 -> 0 | J46: =Price!J46/'Price D Coupon'!J$5 -> 7.0734127 | K46: =Price!K46/'Price D Coupon'!K$5 -> 6.8412698 | L46: =Price!L46/'Price D Coupon'!L$5 -> 6.3859127 | M46: =Price!M46/'Price D Coupon'!M$5 -> 0 | N46: =Price!N46/'Price D Coupon'!N$5 -> 6.1892361 | ... Y46: =Price!Y46/'Price D Coupon'!Y$5 -> 3.4017094 | AC46: 22.672183 | AE46: 41789 | AF46: =VLOOKUP(AE46,CurrentCoupon!$B$4:$C$1468,2,0) -> 3.2594551 | AG46: =IF(AF46<$G$5,G46,(H46-G46)/0.5*(AF46-$G$5)+G46) -> 7.5807552 | AI46: 41789 | AJ46: 0.14116669 | AK46: 0.12953463 | AL46: 0 | AM46: 0.098992167 | AN46: 0.16034508 | AO46: 0.011125465 | AP46: 0 | AQ46: 0.093649008 | AR46: 0.043463751 | AS46: 0.050174575 | AT46: 0.03561943 | AU46: 0.046201625 | AV46: 0.044177838 | AW46: 0.073323978 | AX46: 0.023813256 | AY46: 0.020456558 | AZ46: 0.011149762 | BA46: 0.0064080309 | BB46: 0.010398151 | BC46: =SUM(AJ46:BB46) -> 1 | BE46: 41759 | BF46: -0.0078448557
F47: 41820 | G47: =Price!G47/'Price D Coupon'!G$5 -> 7.7038214 | H47: =Price!H47/'Price D Coupon'!H$5 -> 7.5059048 | I47: =Price!I47/'Price D Coupon'!I$5 -> 0 | J47: =Price!J47/'Price D Coupon'!J$5 -> 7.1643866 | K47: =Price!K47/'Price D Coupon'!K$5 -> 6.9367063 | L47: =Price!L47/'Price D Coupon'!L$5 -> 6.4858152 | M47: =Price!M47/'Price D Coupon'!M$5 -> 0 | N47: =Price!N47/'Price D Coupon'!N$5 -> 6.2688383 | ... Y47: =Price!Y47/'Price D Coupon'!Y$5 -> 3.4854701 | AC47: 23.378006 | AE47: 41820 | AF47: =VLOOKUP(AE47,CurrentCoupon!$B$4:$C$1468,2,0) -> 3.2580486 | AG47: =IF(AF47<$G$5,G47,(H47-G47)/0.5*(AF47-$G$5)+G47) -> 7.6016772 | AI47: 41820 | AJ47: 0.14171813 | AK47: 0.1299741 | AL47: 0 | AM47: 0.099321696 | AN47: 0.16063179 | AO47: 0.011132259 | AP47: 0 | AQ47: 0.093842231 | AR47: 0.04344704 | AS47: 0.050119115 | AT47: 0.035517133 | AU47: 0.046090472 | AV47: 0.044007694 | AW47: 0.07283799 | AX47: 0.023687647 | AY47: 0.020276544 | AZ47: 0.01092879 | BA47: 0.0062779745 | BB47: 0.010189405 | BC47: =SUM(AJ47:BB47) -> 1 | BE47: 41789 | BF47: -0.029344377
F48: 41851 | G48: =Price!G48/'Price D Coupon'!G$5 -> 7.6829881 | H48: =Price!H48/'Price D Coupon'!H$5 -> 7.4746548 | I48: =Price!I48/'Price D Coupon'!I$5 -> 0 | J48: =Price!J48/'Price D Coupon'!J$5 -> 7.1197438 | K48: =Price!K48/'Price D Coupon'!K$5 -> 6.9143866 | L48: =Price!L48/'Price D Coupon'!L$5 -> 6.5215295 | M48: =Price!M48/'Price D Coupon'!M$5 -> 0 | N48: =Price!N48/'Price D Coupon'!N$5 -> 6.2297758 | ... Y48: =Price!Y48/'Price D Coupon'!Y$5 -> 3.6224902 | AC48: 23.745654 | AE48: 41851 | AF48: =VLOOKUP(AE48,CurrentCoupon!$B$4:$C$1468,2,0) -> 3.2178218 | AG48: =IF(AF48<$G$5,G48,(H48-G48)/0.5*(AF48-$G$5)+G48) -> 7.592229 | AI48: 41851 | AJ48: 0.14230565 | AK48: 0.13040735 | AL48: 0 | AM48: 0.099654655 | AN48: 0.16091603 | AO48: 0.011133829 | AP48: 0 | AQ48: 0.094021309 | AR48: 0.043411461 | AS48: 0.050066548 | AT48: 0.035409749 | AU48: 0.045938062 | AV48: 0.043832975 | AW48: 0.072357057 | AX48: 0.023567107 | AY48: 0.02010048 | AZ48: 0.010733533 | BA48: 0.006156812 | BB48: 0.009987388 | BC48: =SUM(AJ48:BB48) -> 1 | BE48: 41820 | BF48: 0.027757435
F49: 41880 | G49: =Price!G49/'Price D Coupon'!G$5 -> 7.4774326 | H49: =Price!H49/'Price D Coupon'!H$5 -> 7.2899326 | I49: =Price!I49/'Price D Coupon'!I$5 -> 0 | J49: =Price!J49/'Price D Coupon'!J$5 -> 6.8234127 | K49: =Price!K49/'Price D Coupon'!K$5 -> 6.6314501 | L49: =Price!L49/'Price D Coupon'!L$5 -> 6.1894841 | M49: =Price!M49/'Price D Coupon'!M$5 -> 0 | N49: =Price!N49/'Price D Coupon'!N$5 -> 5.9704861 | ... Y49: =Price!Y49/'Price D Coupon'!Y$5 -> 3.5868065 | AC49: 22.581192 | AE49: 41880 | AF49: =VLOOKUP(AE49,CurrentCoupon!$B$4:$C$1468,2,0) -> 3.1253553 | AG49: =IF(AF49<$G$5,G49,(H49-G49)/0.5*(AF49-$G$5)+G49) -> 7.4304243 | AI49: 41880 | AJ49: 0.14298975 | AK49: 0.13095539 | AL49: 0 | AM49: 0.10006002 | AN49: 0.16127149 | AO49: 0.011131859 | AP49: 0 | AQ49: 0.093952745 | AR49: 0.043372777 | AS49: 0.049983064 | AT49: 0.035284097 | AU49: 0.04578056 | AV49: 0.043647075 | AW49: 0.071834871 | AX49: 0.023428339 | AY49: 0.019930638 | AZ49: 0.010528337 | BA49: 0.0060439662 | BB49: 0.0098050215 | BC49: =SUM(AJ49:BB49) -> 1 | BE49: 41851 | BF49: 0.0074645314
F50: 41912 | G50: =Price!G50/'Price D Coupon'!G$5 -> 7.6100714 | H50: =Price!H50/'Price D Coupon'!H$5 -> 7.4381944 | I50: =Price!I50/'Price D Coupon'!I$5 -> 0 | J50: =Price!J50/'Price D Coupon'!J$5 -> 6.9947438 | K50: =Price!K50/'Price D Coupon'!K$5 -> 6.8429581 | L50: =Price!L50/'Price D Coupon'!L$5 -> 6.4277778 | M50: =Price!M50/'Price D Coupon'!M$5 -> 0 | N50: =Price!N50/'Price D Coupon'!N$5 -> 6.1204008 | ... Y50: =Price!Y50/'Price D Coupon'!Y$5 -> 3.7018162 | AC50: 23.630763 | AE50: 41912 | AF50: =VLOOKUP(AE50,CurrentCoupon!$B$4:$C$1468,2,0) -> 3.1361017 | AG50: =IF(AF50<$G$5,G50,(H50-G50)/0.5*(AF50-$G$5)+G50) -> 7.5632859 | AI50: 41912 | AJ50: 0.14373459 | AK50: 0.13153506 | AL50: 0 | AM50: 0.10044565 | AN50: 0.16169414 | AO50: 0.011141527 | AP50: 0 | AQ50: 0.093821049 | AR50: 0.043300392 | AS50: 0.049898277 | AT50: 0.035135695 | AU50: 0.045626976 | AV50: 0.043434667 | AW50: 0.071247425 | AX50: 0.023275456 | AY50: 0.019753502 | AZ50: 0.010365521 | BA50: 0.0059488495 | BB50: 0.0096412185 | BC50: =SUM(AJ50:BB50) -> 1 | BE50: 41880 | BF50: -0.047313023
F51: 41943 | G51: =Price!G51/'Price D Coupon'!G$5 -> 7.4854167 | H51: =Price!H51/'Price D Coupon'!H$5 -> 7.2979167 | I51: =Price!I51/'Price D Coupon'!I$5 -> 0 | J51: =Price!J51/'Price D Coupon'!J$5 -> 6.7502993 | K51: =Price!K51/'Price D Coupon'!K$5 -> 6.6074422 | L51: =Price!L51/'Price D Coupon'!L$5 -> 6.1565476 | M51: =Price!M51/'Price D Coupon'!M$5 -> 0 | N51: =Price!N51/'Price D Coupon'!N$5 -> 5.9065119 | ... Y51: =Price!Y51/'Price D Coupon'!Y$5 -> 3.6040073 | AC51: 22.531622 | AE51: 41943 | AF51: =VLOOKUP(AE51,CurrentCoupon!$B$4:$C$1468,2,0) -> 3.0442418 | AG51: =IF(AF51<$G$5,G51,(H51-G51)/0.5*(AF51-$G$5)+G51) -> 7.468826 | AI51: 41943 | AJ51: 0.14443816 | AK51: 0.13206838 | AL51: 0 | AM51: 0.10079491 | AN51: 0.16203744 | AO51: 0.011135247 | AP51: 0 | AQ51: 0.093803749 | AR51: 0.043269447 | AS51: 0.049812968 | AT51: 0.035004964 | AU51: 0.045468912 | AV51: 0.043218243 | AW51: 0.07071713 | AX51: 0.023134329 | AY51: 0.019568962 | AZ51: 0.01018449 | BA51: 0.0058467279 | BB51: 0.0094959389 | BC51: =SUM(AJ51:BB51) -> 1 | BE51: 41912 | BF51: 0.043121935
F52: 41971 | G52: =Price!G52/'Price D Coupon'!G$5 -> 7.3392381 | H52: =Price!H52/'Price D Coupon'!H$5 -> 7.1621548 | I52: =Price!I52/'Price D Coupon'!I$5 -> 0 | J52: =Price!J52/'Price D Coupon'!J$5 -> 6.5215295 | K52: =Price!K52/'Price D Coupon'!K$5 -> 6.3920635 | L52: =Price!L52/'Price D Coupon'!L$5 -> 5.8965295 | M52: =Price!M52/'Price D Coupon'!M$5 -> 0 | N52: =Price!N52/'Price D Coupon'!N$5 -> 5.7063383 | ... Y52: =Price!Y52/'Price D Coupon'!Y$5 -> 3.5599902 | AC52: 21.730029 | AE52: 41971 | AF52: =VLOOKUP(AE52,CurrentCoupon!$B$4:$C$1468,2,0) -> 2.9250413 | AG52: =IF(AF52<$G$5,G52,(H52-G52)/0.5*(AF52-$G$5)+G52) -> 7.3392381 | AI52: 41971 | AJ52: 0.14515803 | AK52: 0.13265044 | AL52: 0 | AM52: 0.10116958 | AN52: 0.16244464 | AO52: 0.01114175 | AP52: 0 | AQ52: 0.093660938 | AR52: 0.043218251 | AS52: 0.04972537 | AT52: 0.034883358 | AU52: 0.045310101 | AV52: 0.042999053 | AW52: 0.070176318 | AX52: 0.022957063 | AY52: 0.019385706 | AZ52: 0.010016056 | BA52: 0.0057485049 | BB52: 0.009354846 | BC52: =SUM(AJ52:BB52) -> 1 | BE52: 41943 | BF52: -0.039672605
F53: 42004 | G53: =Price!G53/'Price D Coupon'!G$5 -> 7.0138889 | H53: =Price!H53/'Price D Coupon'!H$5 -> 6.9513889 | I53: =Price!I53/'Price D Coupon'!I$5 -> 0 | J53: =Price!J53/'Price D Coupon'!J$5 -> 6.1894841 | K53: =Price!K53/'Price D Coupon'!K$5 -> 6.2921644 | L53: =Price!L53/'Price D Coupon'!L$5 -> 5.7519841 | M53: =Price!M53/'Price D Coupon'!M$5 -> 0 | N53: =Price!N53/'Price D Coupon'!N$5 -> 5.4157986 | ... Y53: =Price!Y53/'Price D Coupon'!Y$5 -> 3.5603632 | AC53: 21.293508 | AE53: 42004 | AF53: =VLOOKUP(AE53,CurrentCoupon!$B$4:$C$1468,2,0) -> 2.6962701 | AG53: =IF(AF53<$G$5,G53,(H53-G53)/0.5*(AF53-$G$5)+G53) -> 7.0138889 | AI53: 42004 | AJ53: 0.14591158 | AK53: 0.13322884 | AL53: 0 | AM53: 0.10151672 | AN53: 0.16283379 | AO53: 0.011139471 | AP53: 0 | AQ53: 0.093517444 | AR53: 0.043181261 | AS53: 0.049636892 | AT53: 0.034774424 | AU53: 0.045154192 | AV53: 0.042787229 | AW53: 0.069639651 | AX53: 0.022783041 | AY53: 0.01919267 | AZ53: 0.0098399953 | BA53: 0.0056382197 | BB53: 0.0092245901 | BC53: =SUM(AJ53:BB53) -> 1 | BE53: 41971 | BF53: -0.033127567
F54: 42034 | G54: =Price!G54/'Price D Coupon'!G$5 -> 5.8940992 | H54: =Price!H54/'Price D Coupon'!H$5 -> 5.8524326 | I54: =Price!I54/'Price D Coupon'!I$5 -> 0 | J54: =Price!J54/'Price D Coupon'!J$5 -> 4.8948413 | K54: =Price!K54/'Price D Coupon'!K$5 -> 5.0734127 | L54: =Price!L54/'Price D Coupon'!L$5 -> 4.546627 | M54: =Price!M54/'Price D Coupon'!M$5 -> 0 | N54: =Price!N54/'Price D Coupon'!N$5 -> 4.2829861 | ... Y54: =Price!Y54/'Price D Coupon'!Y$5 -> 3.4594017 | AC54: 17.742956 | AE54: 42034 | AF54: =VLOOKUP(AE54,CurrentCoupon!$B$4:$C$1468,2,0) -> 2.5386092 | AG54: =IF(AF54<$G$5,G54,(H54-G54)/0.5*(AF54-$G$5)+G54) -> 5.8940992 | AI54: 42034 | AJ54: 0.1467089 | AK54: 0.1338754 | AL54: 0 | AM54: 0.10176797 | AN54: 0.1633136 | AO54: 0.011157228 | AP54: 0 | AQ54: 0.092870263 | AR54: 0.043174954 | AS54: 0.049576038 | AT54: 0.034657797 | AU54: 0.045038886 | AV54: 0.042605814 | AW54: 0.069138471 | AX54: 0.022670742 | AY54: 0.019042072 | AZ54: 0.0097161724 | BA54: 0.0055692771 | BB54: 0.0091164247 | BC54: =SUM(AJ54:BB54) -> 1 | BE54: 42004 | BF54: -0.026017102
F55: 42062 | G55: =Price!G55/'Price D Coupon'!G$5 -> 6.5815992 | H55: =Price!H55/'Price D Coupon'!H$5 -> 6.5243056 | I55: =Price!I55/'Price D Coupon'!I$5 -> 0 | J55: =Price!J55/'Price D Coupon'!J$5 -> 5.7296644 | K55: =Price!K55/'Price D Coupon'!K$5 -> 5.8323413 | L55: =Price!L55/'Price D Coupon'!L$5 -> 5.363593 | M55: =Price!M55/'Price D Coupon'!M$5 -> 0 | N55: =Price!N55/'Price D Coupon'!N$5 -> 5.0134564 | ... Y55: =Price!Y55/'Price D Coupon'!Y$5 -> 3.7935372 | AC55: 20.530641 | AE55: 42062 | AF55: =VLOOKUP(AE55,CurrentCoupon!$B$4:$C$1468,2,0) -> 2.8341999 | AG55: =IF(AF55<$G$5,G55,(H55-G55)/0.5*(AF55-$G$5)+G55) -> 6.5815992 | AI55: 42062 | AJ55: 0.147653 | AK55: 0.13465479 | AL55: 0 | AM55: 0.10210331 | AN55: 0.16389333 | AO55: 0.011178399 | AP55: 0 | AQ55: 0.092170981 | AR55: 0.043127725 | AS55: 0.049492497 | AT55: 0.034505449 | AU55: 0.044865757 | AV55: 0.042362049 | AW55: 0.068507645 | AX55: 0.022522098 | AY55: 0.018883043 | AZ55: 0.0095794762 | BA55: 0.0054880754 | BB55: 0.0090123686 | BC55: =SUM(AJ55:BB55) -> 1 | BE55: 42034 | BF55: -0.18730149
F56: 42094 | G56: =Price!G56/'Price D Coupon'!G$5 -> 6.4225714 | H56: =Price!H56/'Price D Coupon'!H$5 -> 6.3756944 | I56: =Price!I56/'Price D Coupon'!I$5 -> 4.7536723 | J56: =Price!J56/'Price D Coupon'!J$5 -> 5.5483152 | K56: =Price!K56/'Price D Coupon'!K$5 -> 5.6777778 | L56: =Price!L56/'Price D Coupon'!L$5 -> 5.2313492 | M56: =Price!M56/'Price D Coupon'!M$5 -> 4.4824653 | N56: =Price!N56/'Price D Coupon'!N$5 -> 4.8547758 | ... Y56: =Price!Y56/'Price D Coupon'!Y$5 -> 3.9854701 | AC56: 19.969247 | AE56: 42094 | AF56: =VLOOKUP(AE56,CurrentCoupon!$B$4:$C$1468,2,0) -> 2.6512827 | AG56: =IF(AF56<$G$5,G56,(H56-G56)/0.5*(AF56-$G$5)+G56) -> 6.4225714 | AI56: 42094 | AJ56: 0.14849148 | AK56: 0.1353443 | AL56: 0 | AM56: 0.10231681 | AN56: 0.16435025 | AO56: 0.011190124 | AP56: 0 | AQ56: 0.091594999 | AR56: 0.043110237 | AS56: 0.049415117 | AT56: 0.034341268 | AU56: 0.044714081 | AV56: 0.042190048 | AW56: 0.067955841 | AX56: 0.022388694 | AY56: 0.018764085 | AZ56: 0.0094829009 | BA56: 0.0054262526 | BB56: 0.0089235168 | BC56: =SUM(AJ56:BB56) -> 1 | BE56: 42062 | BF56: 0.16728926
F57: 42124 | G57: =Price!G57/'Price D Coupon'!G$5 -> 6.7090278 | H57: =Price!H57/'Price D Coupon'!H$5 -> 6.6413214 | I57: =Price!I57/'Price D Coupon'!I$5 -> 5.3027778 | J57: =Price!J57/'Price D Coupon'!J$5 -> 5.9009921 | K57: =Price!K57/'Price D Coupon'!K$5 -> 5.9947438 | L57: =Price!L57/'Price D Coupon'!L$5 -> 5.5527778 | M57: =Price!M57/'Price D Coupon'!M$5 -> 4.861373 | N57: =Price!N57/'Price D Coupon'!N$5 -> 5.1633681 | ... Y57: =Price!Y57/'Price D Coupon'!Y$5 -> 4.1176825 | AC57: 21.080266 | AE57: 42124 | AF57: =VLOOKUP(AE57,CurrentCoupon!$B$4:$C$1468,2,0) -> 2.841676 | AG57: =IF(AF57<$G$5,G57,(H57-G57)/0.5*(AF57-$G$5)+G57) -> 6.7090278 | AI57: 42124 | AJ57: 0.12423967 | AK57: 0.11316002 | AL57: 0.065143517 | AM57: 0.084910023 | AN57: 0.13692327 | AO57: 0.0092723001 | AP57: 0.10517165 | AQ57: 0.074925706 | AR57: 0.035687714 | AS57: 0.040903895 | AT57: 0.028249893 | AU57: 0.037025462 | AV57: 0.034861126 | AW57: 0.055879071 | AX57: 0.018510317 | AY57: 0.015493011 | AZ57: 0.0078094838 | BA57: 0.0044720981 | BB57: 0.0073617784 | BC57: =SUM(AJ57:BB57) -> 1
AI61: Weighted Average Px
AI62: Date | AJ62: FN30. 300. 13 | AK62: FN30. 300. 12 | AL62: FN30. 350. 14 | AM62: FN30. 350. 13 | AN62: FN30. 350. 12 | AO62: FN30. 350. 10 | AP62: FN30. 400. 14 | AQ62: FN30. 400. 13 | AR62: FN30. 400. 11 | AS62: FN30. 400. 10 | AT62: FN30. 400. 09 | AU62: FN30. 450. 11 | AV62: FN30. 450. 10 | AW62: FN30. 450. 09 | AX62: FN30. 500. 10 | AY62: FN30. 500. 09 | AZ62: FN30. 550. 08 | BA62: FN30. 600. 08 | BB62: FN30. 650. 67 | BC62: Total
AI63: 40633 | AJ63: =G8*AJ8 -> 0 | AK63: =H8*AK8 -> 0 | AL63: =I8*AL8 -> 0 | AM63: =J8*AM8 -> 0 | AN63: =K8*AN8 -> 0 | AO63: =L8*AO8 -> 0.19426941 | AP63: =M8*AP8 -> 0 | AQ63: =N8*AQ8 -> 0 | ... BB63: =Y8*BB8 -> 0.1581576 | BC63: =SUM(AJ63:BB63) -> 5.4040031
AI64: 40662 | AJ64: =G9*AJ9 -> 0 | AK64: =H9*AK9 -> 0 | AL64: =I9*AL9 -> 0 | AM64: =J9*AM9 -> 0 | AN64: =K9*AN9 -> 0 | AO64: =L9*AO9 -> 0.19655332 | AP64: =M9*AP9 -> 0 | AQ64: =N9*AQ9 -> 0 | ... BB64: =Y9*BB9 -> 0.15702833 | BC64: =SUM(AJ64:BB64) -> 5.4712823
AI65: 40694 | AJ65: =G10*AJ10 -> 0 | AK65: =H10*AK10 -> 0 | AL65: =I10*AL10 -> 0 | AM65: =J10*AM10 -> 0 | AN65: =K10*AN10 -> 0 | AO65: =L10*AO10 -> 0.20173044 | AP65: =M10*AP10 -> 0 | AQ65: =N10*AQ10 -> 0 | ... BB65: =Y10*BB10 -> 0.15914129 | BC65: =SUM(AJ65:BB65) -> 5.4954374
AI66: 40724 | AJ66: =G11*AJ11 -> 0 | AK66: =H11*AK11 -> 0 | AL66: =I11*AL11 -> 0 | AM66: =J11*AM11 -> 0 | AN66: =K11*AN11 -> 0 | AO66: =L11*AO11 -> 0.20465915 | AP66: =M11*AP11 -> 0 | AQ66: =N11*AQ11 -> 0 | ... BB66: =Y11*BB11 -> 0.15917742 | BC66: =SUM(AJ66:BB66) -> 5.5415672
AI67: 40753 | AJ67: =G12*AJ12 -> 0 | AK67: =H12*AK12 -> 0 | AL67: =I12*AL12 -> 0 | AM67: =J12*AM12 -> 0 | AN67: =K12*AN12 -> 0 | AO67: =L12*AO12 -> 0.20001887 | AP67: =M12*AP12 -> 0 | AQ67: =N12*AQ12 -> 0 | ... BB67: =Y12*BB12 -> 0.1525407 | BC67: =SUM(AJ67:BB67) -> 5.2080149
AI68: 40786 | AJ68: =G13*AJ13 -> 0 | AK68: =H13*AK13 -> 0 | AL68: =I13*AL13 -> 0 | AM68: =J13*AM13 -> 0 | AN68: =K13*AN13 -> 0 | AO68: =L13*AO13 -> 0.17817214 | AP68: =M13*AP13 -> 0 | AQ68: =N13*AQ13 -> 0 | ... BB68: =Y13*BB13 -> 0.13794014 | BC68: =SUM(AJ68:BB68) -> 4.1199718
...

Sheet Price
G5: 3 | H5: 3.5 | I5: 4 | J5: 3 | K5: 3.5 | L5: 4 | M5: 4.5 | N5: 3.5 | O5: 4 | P5: 4.5 | Q5: 5 | R5: 4 | S5: 4.5 | T5: 5 | U5: 5.5 | V5: 6 | W5: 6.5 | X5: 4 | Y5: 4.5 | Z5: 5
F6: IOS Price (%)
F7: Date | G7: FN30. 300. 13 | H7: FN30. 300. 12 | I7: FN30. 350. 14 | J7: FN30. 350. 13 | K7: FN30. 350. 12 | L7: FN30. 350. 10 | M7: FN30. 400. 14 | N7: FN30. 400. 13 | O7: FN30. 400. 11 | P7: FN30. 400. 10 | Q7: FN30. 400. 09 | R7: FN30. 450. 11 | S7: FN30. 450. 10 | T7: FN30. 450. 09 | U7: FN30. 500. 10 | V7: FN30. 500. 09 | W7: FN30. 550. 08 | X7: FN30. 600. 08 | Y7: FN30. 650. 67 | Z7: GII30. 400. 10 | AA7: GII30. 450. 10 | AB7: GII30. 500. 10 | AC7: Avg
F8: 40633 | L8: 24.809722 | P8: 25.996111 | Q8: 24.191111 | S8: 26.1825 | T8: 24.4485 | U8: 25.97089 | V8: 24.16189 | W8: 20.548277 | X8: 20.218667 | Y8: 21.327055 | AC8: 23.785472
F9: 40662 | L9: 24.928443 | P9: 26.261222 | Q9: 24.351222 | S9: 26.348 | T9: 24.707001 | U9: 26.527778 | V9: 24.980777 | W9: 20.867556 | X9: 20.384334 | Y9: 21.451111 | AC9: 24.080744
F10: 40694 | L10: 25.422723 | P10: 26.617111 | Q10: 24.668112 | S10: 26.538501 | T10: 24.5735 | U10: 26.618889 | V10: 24.59589 | W10: 20.216279 | X10: 20.484666 | Y10: 22.128056 | AC10: 24.186373
F11: 40724 | L11: 25.649722 | P11: 26.887112 | Q11: 24.613111 | S11: 26.9175 | T11: 24.5815 | U11: 27.333889 | V11: 24.931888 | W11: 20.290278 | X11: 20.836667 | Y11: 22.460057 | AC11: 24.450172
F12: 40753 | L12: 24.934722 | P12: 25.727112 | Q12: 23.32011 | S12: 25.065499 | T12: 22.6755 | U12: 25.388889 | V12: 22.857889 | W12: 19.352278 | X12: 20.004667 | Y12: 21.843056 | AC12: 23.116972
F13: 40786 | L13: 22.059722 | P13: 21.273111 | Q13: 19.336111 | S13: 18.5495 | T13: 16.8625 | U13: 19.575889 | V13: 17.419889 | W13: 16.071278 | X13: 17.441667 | Y13: 19.968056 | AC13: 18.855772
F14: 40816 | L14: 18.423167 | P14: 16.921333 | Q14: 14.936333 | S14: 15.1685 | T14: 13.3095 | U14: 16.682668 | V14: 14.338667 | W14: 13.070833 | X14: 14.694 | Y14: 17.441167 | AC14: 15.498617
F15: 40847 | L15: 18.106723 | P15: 16.69511 | Q15: 15.273111 | S15: 16.3625 | T15: 14.1435 | U15: 19.263889 | V15: 17.044889 | W15: 12.993278 | X15: 14.441667 | Y15: 16.874056 | AC15: 16.119872
F16: 40877 | L16: 17.684722 | P16: 16.227112 | Q16: 14.320111 | S16: 16.7375 | T16: 13.8315 | U16: 19.919889 | V16: 17.372888 | W16: 13.634278 | X16: 15.472667 | Y16: 17.749056 | AC16: 16.294972
F17: 40907 | L17: 17.188166 | P17: 15.842333 | Q17: 13.639333 | S17: 16.7315 | T17: 13.5285 | U17: 19.853667 | V17: 16.932668 | W17: 12.882833 | X17: 15.006 | Y17: 17.363166 | AC17: 15.896817
F18: 40939 | L18: 16.059722 | P18: 14.539111 | Q18: 12.023111 | S18: 15.2375 | T18: 12.1595 | U18: 17.951889 | V18: 15.107889 | W18: 12.509278 | X18: 14.300667 | Y18: 16.843056 | AC18: 14.673172
F19: 40968 | L19: 17.903722 | P19: 16.836111 | Q19: 13.633111 | S19: 17.2065 | T19: 13.7535 | U19: 19.77989 | V19: 16.65489 | W19: 13.415278 | X19: 15.457667 | Y19: 17.765057 | AC19: 16.240573
F20: 40998 | L20: 19.663444 | O20: 20.378222 | P20: 18.831221 | Q20: 15.722222 | R20: 20.733999 | S20: 18.812 | T20: 15.328 | U20: 21.418779 | V20: 18.511777 | W20: 14.117556 | X20: 16.302333 | Y20: 18.580111 | AC20: 18.199972
F21: 41029 | L21: 18.309722 | O21: 19.07011 | P21: 17.53911 | Q21: 14.508111 | R21: 19.3935 | S21: 17.440499 | T21: 14.0815 | U21: 20.716888 | V21: 17.857889 | W21: 13.540278 | X21: 15.628667 | Y21: 19.109057 | AC21: 17.266278
F22: 41060 | L22: 15.418722 | O22: 16.711111 | P22: 15.023111 | Q22: 11.899111 | R22: 17.2375 | S22: 15.2685 | T22: 12.1285 | U22: 18.747888 | V22: 15.982889 | W22: 12.181278 | X22: 14.191667 | Y22: 18.312056 | AC22: 15.258528
F23: 41089 | L23: 15.835444 | O23: 16.410222 | P23: 15.425222 | Q23: 12.519222 | R23: 17.327999 | S23: 15.766 | T23: 12.969 | U23: 19.043779 | V23: 16.386777 | W23: 12.305556 | X23: 14.067333 | Y23: 17.84511 | AC23: 15.491805
F24: 41121 | L24: 13.825722 | O24: 15.227111 | P24: 14.711111 | Q24: 12.211111 | R24: 17.6125 | S24: 15.8155 | T24: 13.1285 | U24: 18.93589 | V24: 16.247889 | W24: 12.274278 | X24: 13.894667 | Y24: 18.109057 | AC24: 15.166111
F25: 41152 | L25: 14.947889 | O25: 16.510445 | P25: 15.806444 | Q25: 13.244444 | R25: 18.541001 | S25: 16.525 | T25: 14.056 | U25: 19.836556 | V25: 17.508555 | W25: 12.758111 | X25: 14.460667 | Y25: 18.303222 | AC25: 16.041528
F26: 41180 | L26: 11.731722 | O26: 13.773111 | P26: 13.149111 | Q26: 11.227111 | R26: 16.0185 | S26: 14.3935 | T26: 12.4255 | U26: 18.872888 | V26: 16.701889 | W26: 11.743278 | X26: 13.910667 | Y26: 17.655056 | AC26: 14.300194
F27: 41213 | L27: 11.856722 | O27: 13.899111 | P27: 13.399111 | Q27: 11.242111 | R27: 16.596499 | S27: 15.0815 | T27: 12.8315 | U27: 18.716888 | V27: 16.747888 | W27: 12.353278 | X27: 14.582667 | Y27: 17.906056 | AC27: 14.601111
F28: 41243 | L28: 12.032167 | O28: 13.858333 | P28: 13.124333 | Q28: 10.842333 | R28: 15.4505 | S28: 14.4345 | T28: 12.0595 | U28: 17.447667 | V28: 15.322667 | W28: 11.304833 | X28: 13.631 | Y28: 16.817167 | AC28: 13.860417
F29: 41274 | L29: 12.241444 | O29: 14.238222 | P29: 13.300222 | Q29: 11.316222 | R29: 16.094 | S29: 14.922 | T29: 12.844 | U29: 17.824779 | V29: 15.652778 | W29: 11.993556 | X29: 14.302333 | Y29: 17.330111 | AC29: 14.338306
F30: 41305 | L30: 14.809722 | O30: 16.383112 | P30: 15.367111 | Q30: 13.070111 | R30: 17.471499 | S30: 16.1905 | T30: 13.6435 | U30: 18.122888 | V30: 15.919889 | W30: 12.087278 | X30: 13.894667 | Y30: 16.687056 | AC30: 15.303944
F31: 41333 | L31: 15.122722 | O31: 16.070111 | P31: 15.195111 | Q31: 13.070111 | R31: 17.315499 | S31: 16.0965 | T31: 13.6285 | U31: 17.90489 | V31: 16.060889 | W31: 12.337278 | X31: 13.894667 | Y31: 16.327056 | AC31: 15.251944
F32: 41361 | H32: 19.033333 | K32: 19.262721 | L32: 16.465722 | O32: 17.149111 | P32: 16.227112 | Q32: 14.023111 | R32: 17.8625 | S32: 16.7995 | T32: 14.3625 | U32: 18.325889 | V32: 16.638889 | W32: 12.665278 | X32: 14.254667 | Y32: 16.077056 | AC32: 16.367671
F33: 41394 | H33: 17.580334 | K33: 16.793721 | L33: 13.715722 | O33: 15.102111 | P33: 13.867111 | Q33: 11.258111 | R33: 15.6435 | S33: 14.0185 | T33: 11.7535 | U33: 15.951889 | V33: 14.654889 | W33: 11.040278 | X33: 12.660667 | Y33: 14.452056 | AC33: 14.178028
F34: 41425 | H34: 20.347001 | K34: 20.392167 | L34: 18.188166 | O34: 19.139333 | P34: 17.702333 | Q34: 15.842333 | R34: 18.496499 | S34: 16.6685 | T34: 15.0125 | U34: 16.166667 | V34: 14.822667 | W34: 11.695833 | X34: 12.147 | Y34: 13.973167 | AC34: 16.471012
F35: 41453 | H35: 20.830334 | K35: 21.184722 | L35: 19.637721 | O35: 21.008112 | P35: 20.023111 | Q35: 18.617111 | R35: 20.7685 | S35: 19.690499 | T35: 18.2375 | U35: 18.68589 | V35: 17.388889 | W35: 13.274278 | X35: 13.613667 | Y35: 14.874056 | AC35: 18.416742
F36: 41486 | H36: 21.611332 | K36: 22.700723 | L36: 21.387721 | O36: 22.852112 | P36: 21.602112 | Q36: 20.399111 | R36: 21.815499 | S36: 20.4565 | T36: 19.003501 | U36: 19.591888 | V36: 18.201889 | W36: 14.774278 | X36: 14.769667 | Y36: 15.874056 | AC36: 19.645742
F37: 41516 | H37: 21.769 | K37: 22.860167 | L37: 21.548167 | O37: 23.545333 | P37: 22.467332 | Q37: 21.280334 | R37: 23.3245 | S37: 21.809501 | T37: 20.403501 | U37: 21.494666 | V37: 19.807668 | W37: 16.132833 | X37: 16.006 | Y37: 16.926168 | AC37: 20.669655
F38: 41547 | H38: 22.127333 | K38: 23.356723 | L38: 21.700723 | O38: 23.149111 | P38: 22.117111 | Q38: 20.69511 | R38: 23.1125 | S38: 21.471499 | T38: 19.878501 | U38: 21.013889 | V38: 19.201889 | W38: 15.540278 | X38: 15.832667 | Y38: 17.343056 | AC38: 20.467171
F39: 41578 | H39: 21.814583 | K39: 22.840972 | L39: 21.153472 | O39: 22.539242 | P39: 21.539242 | Q39: 19.632992 | R39: 22.721881 | S39: 20.815631 | T39: 18.83125 | U39: 20.27952 | V39: 18.15452 | W39: 15.227778 | X39: 15.754167 | Y39: 17.843056 | AC39: 19.939165
F40: 41607 | H40: 22.619798 | K40: 24.303825 | L40: 22.928825 | O40: 24.550353 | P40: 23.534722 | Q40: 21.753472 | R40: 24.671881 | S40: 22.609381 | T40: 20.6875 | U40: 21.605909 | V40: 19.605909 | W40: 16.993056 | X40: 17.380214 | Y40: 19.282992 | AC40: 21.609131
F41: 41639 | H41: 22.885417 | K41: 24.897575 | L41: 23.506944 | O41: 25.800353 | P41: 24.940972 | Q41: 23.425353 | R41: 26.296881 | S41: 24.734381 | T41: 23.53125 | U41: 23.980909 | V41: 22.137159 | W41: 18.946187 | X41: 19.395833 | Y41: 21.048611 | AC41: 23.251988
F42: 41670 | H42: 22.51875 | K42: 24.391667 | L42: 22.751048 | O42: 24.717714 | P42: 23.748964 | Q42: 22.373964 | R42: 24.934381 | S42: 23.465631 | T42: 22.028131 | U42: 22.822917 | V42: 21.338548 | W42: 19.320833 | X42: 19.44375 | Y42: 20.957298 | AC42: 22.486685
F43: 41698 | H43: 22.565631 | K43: 24.579167 | L43: 23.016667 | O43: 25.123964 | P43: 24.170833 | Q43: 22.842714 | R43: 25.246881 | S43: 23.934381 | T43: 22.60625 | U43: 24.026048 | V43: 22.494798 | W43: 20.008333 | X43: 20.240631 | Y43: 21.754167 | AC43: 23.043605
F44: 41729 | G44: 23.361464 | H44: 22.689583 | J44: 25.669103 | K44: 24.825353 | L44: 23.403472 | N44: 25.669103 | O44: 25.507992 | P44: 24.617361 | Q44: 23.461111 | R44: 25.846881 | S44: 24.815631 | T44: 23.45625 | U44: 24.857639 | V44: 23.43577 | W44: 20.790278 | X44: 20.769798 | Y44: 21.796187 | AC44: 23.82194
...

Sheet CurrentCoupon
B3: AsOf | C3: SeriesNumValue
B4: 42130 | C4: 2.8101077
B5: 42129 | C5: 2.861778
B6: 42128 | C6: 2.9193052
B7: 42125 | C7: 2.8756485
B8: 42124 | C8: 2.841676
B9: 42123 | C9: 2.8064099
B10: 42122 | C10: 2.7480147
B11: 42121 | C11: 2.7467459
B12: 42118 | C12: 2.6991415
B13: 42117 | C13: 2.6437338
B14: 42116 | C14: 2.6295592
B15: 42115 | C15: 2.6562876
... B1504: 39940 | C1504: 3.9994906
B1505: #VALUE! | C1505: 4.1292621
B1506: #VALUE! | C1506: 4.0854192
