Workbook

Sheet Price D Coupon
G5: 3 | H5: 3.5 | I5: 4 | J5: 3 | K5: 3.5 | L5: 4 | M5: 4.5 | N5: 3.5 | O5: 4 | P5: 4.5 | Q5: 5 | R5: 4 | S5: 4.5 | T5: 5 | U5: 5.5 | V5: 6 | W5: 6.5 | X5: 4 | Y5: 4.5 | Z5: 5
F6: IOS Unhedged 1m Return (%) | AG6: Weight
F7: Date | G7: FN30. 300. 13 | H7: FN30. 350. 13 | I7: FN30. 400. 13 | J7: FN30. 300. 12 | K7: FN30. 350. 12 | L7: FN30. 400. 11 | M7: FN30. 450. 11 | N7: FN30. 350. 10 | O7: FN30. 400. 10 | P7: FN30. 450. 10 | Q7: FN30. 500. 10 | R7: FN30. 400. 09 | S7: FN30. 450. 09 | T7: FN30. 500. 09 | U7: FN30. 550. 08 | V7: FN30. 600. 08 | W7: FN30. 650. 67 | X7: GII30. 400. 10 | Y7: GII30. 450. 10 | Z7: GII30. 500. 10 | AA7: Avg | AC7: Date | AD7: Current Coupon | AG7: Date | AH7: FN30. 300. 13 | AI7: FN30. 350. 13 | AJ7: FN30. 400. 13 | AK7: FN30. 300. 12 | AL7: FN30. 350. 12 | AM7: FN30. 400. 11 | AN7: FN30. 450. 11 | AO7: FN30. 350. 10 | AP7: FN30. 400. 10 | AQ7: FN30. 450. 10 | AR7: FN30. 500. 10 | AS7: FN30. 400. 09 | AT7: FN30. 450. 09 | AU7: FN30. 500. 09 | AV7: FN30. 550. 08 | AW7: FN30. 600. 08 | AX7: FN30. 650. 67 | AY7: GII30. 400. 10 | AZ7: GII30. 450. 10 | BA7: GII30. 500. 10 | BB7: Total
F8: 40633 | G8: =Price!G8/'Price D Coupon'!G$5 -> 0 | H8: =Price!H8/'Price D Coupon'!H$5 -> 0 | I8: =Price!I8/'Price D Coupon'!I$5 -> 0 | J8: =Price!J8/'Price D Coupon'!J$5 -> 0 | K8: =Price!K8/'Price D Coupon'!K$5 -> 0 | L8: =Price!L8/'Price D Coupon'!L$5 -> 0 | M8: =Price!M8/'Price D Coupon'!M$5 -> 0 | N8: =Price!N8/'Price D Coupon'!N$5 -> 7.0884921 | ... W8: =Price!W8/'Price D Coupon'!W$5 -> 3.2810853 | AA8: 23.785472 | AC8: 40633 | AD8: =VLOOKUP(AC8,CurrentCoupon!$B$4:$C$1468,2,0) -> 4.2632122 | AG8: 40633 | AH8: 0 | AI8: 0 | AJ8: 0 | AK8: 0 | AL8: 0 | AM8: 0 | AN8: 0 | AO8: 0.02740631 | AP8: 0.14046649 | AQ8: 0.12975199 | AR8: 0.062968111 | AS8: 0.12948424 | AT8: 0.2882927 | AU8: 0.066411433 | AV8: 0.070279501 | AW8: 0.036736393 | AX8: 0.048202832 | BB8: 1 | BD8: Date | BE8: Monthly Return (%)
F9: 40662 | G9: =Price!G9/'Price D Coupon'!G$5 -> 0 | H9: =Price!H9/'Price D Coupon'!H$5 -> 0 | I9: =Price!I9/'Price D Coupon'!I$5 -> 0 | J9: =Price!J9/'Price D Coupon'!J$5 -> 0 | K9: =Price!K9/'Price D Coupon'!K$5 -> 0 | L9: =Price!L9/'Price D Coupon'!L$5 -> 0 | M9: =Price!M9/'Price D Coupon'!M$5 -> 0 | N9: =Price!N9/'Price D Coupon'!N$5 -> 7.1224124 | ... W9: =Price!W9/'Price D Coupon'!W$5 -> 3.3001709 | AA9: 24.080744 | AC9: 40662 | AD9: =VLOOKUP(AC9,CurrentCoupon!$B$4:$C$1468,2,0) -> 4.0911415 | AG9: 40662 | AH9: 0 | AI9: 0 | AJ9: 0 | AK9: 0 | AL9: 0 | AM9: 0 | AN9: 0 | AO9: 0.027596454 | AP9: 0.14136961 | AQ9: 0.13033036 | AR9: 0.063100659 | AS9: 0.12997806 | AT9: 0.28862028 | AU9: 0.066274006 | AV9: 0.069072966 | AW9: 0.036075726 | AX9: 0.047581877 | BB9: 1 | BD9: 40633 | BE9: =G8*AH8 -> 0
F10: 40694 | G10: =Price!G10/'Price D Coupon'!G$5 -> 0 | H10: =Price!H10/'Price D Coupon'!H$5 -> 0 | I10: =Price!I10/'Price D Coupon'!I$5 -> 0 | J10: =Price!J10/'Price D Coupon'!J$5 -> 0 | K10: =Price!K10/'Price D Coupon'!K$5 -> 0 | L10: =Price!L10/'Price D Coupon'!L$5 -> 0 | M10: =Price!M10/'Price D Coupon'!M$5 -> 0 | N10: =Price!N10/'Price D Coupon'!N$5 -> 7.2636352 | ... W10: =Price!W10/'Price D Coupon'!W$5 -> 3.4043162 | AA10: 24.186373 | AC10: 40694 | AD10: =VLOOKUP(AC10,CurrentCoupon!$B$4:$C$1468,2,0) -> 3.9323543 | AG10: 40694 | AH10: 0 | AI10: 0 | AJ10: 0 | AK10: 0 | AL10: 0 | AM10: 0 | AN10: 0 | AO10: 0.027772655 | AP10: 0.14222877 | AQ10: 0.13089219 | AR10: 0.063273705 | AS10: 0.13043914 | AT10: 0.2890731 | AU10: 0.066206835 | AV10: 0.067961286 | AW10: 0.035405405 | AX10: 0.046746918 | BB10: 1 | BD10: 40662 | BE10: 0.01824177
F11: 40724 | G11: =Price!G11/'Price D Coupon'!G$5 -> 0 | H11: =Price!H11/'Price D Coupon'!H$5 -> 0 | I11: =Price!I11/'Price D Coupon'!I$5 -> 0 | J11: =Price!J11/'Price D Coupon'!J$5 -> 0 | K11: =Price!K11/'Price D Coupon'!K$5 -> 0 | L11: =Price!L11/'Price D Coupon'!L$5 -> 0 | M11: =Price!M11/'Price D Coupon'!M$5 -> 0 | N11: =Price!N11/'Price D Coupon'!N$5 -> 7.3284921 | ... W11: =Price!W11/'Price D Coupon'!W$5 -> 3.4553933 | AA11: 25.45371 | AC11: 40724 | AD11: =VLOOKUP(AC11,CurrentCoupon!$B$4:$C$1468,2,0) -> 4.0210178 | AG11: 40724 | AH11: 0 | AI11: 0 | AJ11: 0 | AK11: 0 | AL11: 0 | AM11: 0 | AN11: 0 | AO11: 0.027926502 | AP11: 0.14295239 | AQ11: 0.13137858 | AR11: 0.063413193 | AS11: 0.13080465 | AT11: 0.28954874 | AU11: 0.06616714 | AV11: 0.06697561 | AW11: 0.034766829 | AX11: 0.046066367 | BB11: 1 | BD11: 40694 | BE11: 0.0095136889
F12: 40753 | G12: =Price!G12/'Price D Coupon'!G$5 -> 0 | H12: =Price!H12/'Price D Coupon'!H$5 -> 0 | I12: =Price!I12/'Price D Coupon'!I$5 -> 0 | J12: =Price!J12/'Price D Coupon'!J$5 -> 0 | K12: =Price!K12/'Price D Coupon'!K$5 -> 0 | L12: =Price!L12/'Price D Coupon'!L$5 -> 0 | M12: =Price!M12/'Price D Coupon'!M$5 -> 0 | N12: =Price!N12/'Price D Coupon'!N$5 -> 7.1242063 | ... W12: =Price!W12/'Price D Coupon'!W$5 -> 3.3604701 | AA12: 24.156786 | AC12: 40753 | AD12: =VLOOKUP(AC12,CurrentCoupon!$B$4:$C$1468,2,0) -> 3.8088239 | AG12: 40753 | AH12: 0 | AI12: 0 | AJ12: 0 | AK12: 0 | AL12: 0 | AM12: 0 | AN12: 0 | AO12: 0.028075952 | AP12: 0.14365704 | AQ12: 0.13186399 | AR12: 0.063549087 | AS12: 0.13116041 | AT12: 0.28990557 | AU12: 0.066127746 | AV12: 0.06605268 | AW12: 0.034214858 | AX12: 0.045392667 | BB12: 1 | BD12: 40724 | BE12: 0.014594354
F13: 40786 | G13: =Price!G13/'Price D Coupon'!G$5 -> 0 | H13: =Price!H13/'Price D Coupon'!H$5 -> 0 | I13: =Price!I13/'Price D Coupon'!I$5 -> 0 | J13: =Price!J13/'Price D Coupon'!J$5 -> 0 | K13: =Price!K13/'Price D Coupon'!K$5 -> 0 | L13: =Price!L13/'Price D Coupon'!L$5 -> 0 | M13: =Price!M13/'Price D Coupon'!M$5 -> 0 | N13: =Price!N13/'Price D Coupon'!N$5 -> 6.3027778 | ... W13: =Price!W13/'Price D Coupon'!W$5 -> 3.0720085 | AA13: 19.978787 | AC13: 40786 | AD13: =VLOOKUP(AC13,CurrentCoupon!$B$4:$C$1468,2,0) -> 3.4273948 | AG13: 40786 | AH13: 0 | AI13: 0 | AJ13: 0 | AK13: 0 | AL13: 0 | AM13: 0 | AN13: 0 | AO13: 0.028268828 | AP13: 0.14449103 | AQ13: 0.13233924 | AR13: 0.063677522 | AS13: 0.13161044 | AT13: 0.289819 | AU13: 0.065940194 | AV13: 0.065193394 | AW13: 0.033758086 | AX13: 0.044902263 | BB13: 1 | BD13: 40753 | BE13: -0.056499118
F14: 40816 | G14: =Price!G14/'Price D Coupon'!G$5 -> 0 | H14: =Price!H14/'Price D Coupon'!H$5 -> 0 | I14: =Price!I14/'Price D Coupon'!I$5 -> 0 | J14: =Price!J14/'Price D Coupon'!J$5 -> 0 | K14: =Price!K14/'Price D Coupon'!K$5 -> 0 | L14: =Price!L14/'Price D Coupon'!L$5 -> 0 | M14: =Price!M14/'Price D Coupon'!M$5 -> 0 | N14: =Price!N14/'Price D Coupon'!N$5 -> 5.2637619 | ... W14: =Price!W14/'Price D Coupon'!W$5 -> 2.6832564 | AA14: 16.636436 | AC14: 40816 | AD14: =VLOOKUP(AC14,CurrentCoupon!$B$4:$C$1468,2,0) -> 3.0385262 | AG14: 40816 | AH14: 0 | AI14: 0 | AJ14: 0 | AK14: 0 | AL14: 0 | AM14: 0 | AN14: 0 | AO14: 0.028492304 | AP14: 0.14538344 | AQ14: 0.13281236 | AR14: 0.063769571 | AS14: 0.13200486 | AT14: 0.28945244 | AU14: 0.065782077 | AV14: 0.064422398 | AW14: 0.033367229 | AX14: 0.04451333 | BB14: 1 | BD14: 40786 | BE14: -0.20415555
F15: 40847 | G15: =Price!G15/'Price D Coupon'!G$5 -> 0 | H15: =Price!H15/'Price D Coupon'!H$5 -> 0 | I15: =Price!I15/'Price D Coupon'!I$5 -> 0 | J15: =Price!J15/'Price D Coupon'!J$5 -> 0 | K15: =Price!K15/'Price D Coupon'!K$5 -> 0 | L15: =Price!L15/'Price D Coupon'!L$5 -> 0 | M15: =Price!M15/'Price D Coupon'!M$5 -> 0 | N15: =Price!N15/'Price D Coupon'!N$5 -> 5.1733495 | ... W15: =Price!W15/'Price D Coupon'!W$5 -> 2.5960085 | AA15: 17.298479 | AC15: 40847 | AD15: =VLOOKUP(AC15,CurrentCoupon!$B$4:$C$1468,2,0) -> 3.251577 | AG15: 40847 | AH15: 0 | AI15: 0 | AJ15: 0 | AK15: 0 | AL15: 0 | AM15: 0 | AN15: 0 | AO15: 0.028725425 | AP15: 0.14628268 | AQ15: 0.13326506 | AR15: 0.063944654 | AS15: 0.13244363 | AT15: 0.28906694 | AU15: 0.065618839 | AV15: 0.063584558 | AW15: 0.032958172 | AX15: 0.044110044 | BB15: 1 | BD15: 40816 | BE15: -0.18608869
F16: 40877 | G16: =Price!G16/'Price D Coupon'!G$5 -> 0 | H16: =Price!H16/'Price D Coupon'!H$5 -> 0 | I16: =Price!I16/'Price D Coupon'!I$5 -> 0 | J16: =Price!J16/'Price D Coupon'!J$5 -> 0 | K16: =Price!K16/'Price D Coupon'!K$5 -> 0 | L16: =Price!L16/'Price D Coupon'!L$5 -> 0 | M16: =Price!M16/'Price D Coupon'!M$5 -> 0 | N16: =Price!N16/'Price D Coupon'!N$5 -> 5.0527778 | ... W16: =Price!W16/'Price D Coupon'!W$5 -> 2.7306239 | AA16: 17.409094 | AC16: 40877 | AD16: =VLOOKUP(AC16,CurrentCoupon!$B$4:$C$1468,2,0) -> 3.1770193 | AG16: 40877 | AH16: 0 | AI16: 0 | AJ16: 0 | AK16: 0 | AL16: 0 | AM16: 0 | AN16: 0 | AO16: 0.029113476 | AP16: 0.14674367 | AQ16: 0.13350213 | AR16: 0.064358005 | AS16: 0.13246171 | AT16: 0.28777046 | AU16: 0.06568972 | AV16: 0.063254791 | AW16: 0.032898514 | AX16: 0.044207529 | BB16: 1 | BD16: 40847 | BE16: 0.052849339
F17: 40907 | G17: =Price!G17/'Price D Coupon'!G$5 -> 0 | H17: =Price!H17/'Price D Coupon'!H$5 -> 0 | I17: =Price!I17/'Price D Coupon'!I$5 -> 0 | J17: =Price!J17/'Price D Coupon'!J$5 -> 0 | K17: =Price!K17/'Price D Coupon'!K$5 -> 0 | L17: =Price!L17/'Price D Coupon'!L$5 -> 0 | M17: =Price!M17/'Price D Coupon'!M$5 -> 0 | N17: =Price!N17/'Price D Coupon'!N$5 -> 4.9109045 | ... W17: =Price!W17/'Price D Coupon'!W$5 -> 2.6712563 | AA17: 17.012436 | AC17: 40907 | AD17: =VLOOKUP(AC17,CurrentCoupon!$B$4:$C$1468,2,0) -> 3.0169009 | AG17: 40907 | AH17: 0 | AI17: 0 | AJ17: 0 | AK17: 0 | AL17: 0 | AM17: 0 | AN17: 0 | AO17: 0.029527009 | AP17: 0.14725219 | AQ17: 0.13390235 | AR17: 0.064909729 | AS17: 0.13222635 | AT17: 0.28593974 | AU17: 0.065805924 | AV17: 0.063058815 | AW17: 0.032938146 | AX17: 0.044439745 | BB17: 1 | BD17: 40877 | BE17: -0.0070201413
F18: 40939 | G18: =Price!G18/'Price D Coupon'!G$5 -> 0 | H18: =Price!H18/'Price D Coupon'!H$5 -> 0 | I18: =Price!I18/'Price D Coupon'!I$5 -> 0 | J18: =Price!J18/'Price D Coupon'!J$5 -> 0 | K18: =Price!K18/'Price D Coupon'!K$5 -> 0 | L18: =Price!L18/'Price D Coupon'!L$5 -> 0 | M18: =Price!M18/'Price D Coupon'!M$5 -> 0 | N18: =Price!N18/'Price D Coupon'!N$5 -> 4.5884921 | ... W18: =Price!W18/'Price D Coupon'!W$5 -> 2.5912393 | AA18: 15.700017 | AC18: 40939 | AD18: =VLOOKUP(AC18,CurrentCoupon!$B$4:$C$1468,2,0) -> 2.7762953 | AG18: 40939 | AH18: 0 | AI18: 0 | AJ18: 0 | AK18: 0 | AL18: 0 | AM18: 0 | AN18: 0 | AO18: 0.029942398 | AP18: 0.14782151 | AQ18: 0.13443017 | AR18: 0.065593518 | AS18: 0.13183303 | AT18: 0.28368873 | AU18: 0.065946486 | AV18: 0.062894336 | AW18: 0.033040183 | AX18: 0.044809632 | BB18: 1 | BD18: 40907 | BE18: -0.027877514
F19: 40968 | G19: =Price!G19/'Price D Coupon'!G$5 -> 0 | H19: =Price!H19/'Price D Coupon'!H$5 -> 0 | I19: =Price!I19/'Price D Coupon'!I$5 -> 0 | J19: =Price!J19/'Price D Coupon'!J$5 -> 0 | K19: =Price!K19/'Price D Coupon'!K$5 -> 0 | L19: =Price!L19/'Price D Coupon'!L$5 -> 0 | M19: =Price!M19/'Price D Coupon'!M$5 -> 0 | N19: =Price!N19/'Price D Coupon'!N$5 -> 5.1153492 | ... W19: =Price!W19/'Price D Coupon'!W$5 -> 2.7330856 | AA19: 17.081171 | AC19: 40968 | AD19: =VLOOKUP(AC19,CurrentCoupon!$B$4:$C$1468,2,0) -> 2.8817315 | AG19: 40968 | AH19: 0 | AI19: 0 | AJ19: 0 | AK19: 0 | AL19: 0 | AM19: 0 | AN19: 0 | AO19: 0.030392644 | AP19: 0.14898141 | AQ19: 0.13497453 | AR19: 0.066073219 | AS19: 0.13169001 | AT19: 0.28152185 | AU19: 0.065906231 | AV19: 0.062505841 | AW19: 0.032979696 | AX19: 0.044974565 | BB19: 1 | BD19: 40939 | BE19: -0.088730633
F20: 40998 | G20: =Price!G20/'Price D Coupon'!G$5 -> 0 | H20: =Price!H20/'Price D Coupon'!H$5 -> 0 | I20: =Price!I20/'Price D Coupon'!I$5 -> 0 | J20: =Price!J20/'Price D Coupon'!J$5 -> 0 | K20: =Price!K20/'Price D Coupon'!K$5 -> 0 | L20: =Price!L20/'Price D Coupon'!L$5 -> 5.0945556 | M20: =Price!M20/'Price D Coupon'!M$5 -> 4.6075553 | N20: =Price!N20/'Price D Coupon'!N$5 -> 5.618127 | ... W20: =Price!W20/'Price D Coupon'!W$5 -> 2.8584786 | AA20: 18.743311 | AC20: 40998 | AD20: =VLOOKUP(AC20,CurrentCoupon!$B$4:$C$1468,2,0) -> 3.0669216 | AG20: 40998 | AH20: 0 | AI20: 0 | AJ20: 0 | AK20: 0 | AL20: 0 | AM20: 0.095316183 | AN20: 0.10063007 | AO20: 0.024725973 | AP20: 0.12045299 | AQ20: 0.10895323 | AR20: 0.05350766 | AS20: 0.10575842 | AT20: 0.22498873 | AU20: 0.0530391 | AV20: 0.049932228 | AW20: 0.0264329 | AX20: 0.036262506 | BB20: 1 | BD20: 40968 | BE20: 0.1267261
F21: 41029 | G21: =Price!G21/'Price D Coupon'!G$5 -> 0 | H21: =Price!H21/'Price D Coupon'!H$5 -> 0 | I21: =Price!I21/'Price D Coupon'!I$5 -> 0 | J21: =Price!J21/'Price D Coupon'!J$5 -> 0 | K21: =Price!K21/'Price D Coupon'!K$5 -> 0 | L21: =Price!L21/'Price D Coupon'!L$5 -> 4.7675275 | M21: =Price!M21/'Price D Coupon'!M$5 -> 4.3096667 | N21: =Price!N21/'Price D Coupon'!N$5 -> 5.2313492 | ... W21: =Price!W21/'Price D Coupon'!W$5 -> 2.9398549 | AA21: 17.815722 | AC21: 41029 | AD21: =VLOOKUP(AC21,CurrentCoupon!$B$4:$C$1468,2,0) -> 2.8585942 | AG21: 41029 | AH21: 0 | AI21: 0 | AJ21: 0 | AK21: 0 | AL21: 0 | AM21: 0.096252094 | AN21: 0.10142706 | AO21: 0.02498952 | AP21: 0.12096088 | AQ21: 0.10910633 | AR21: 0.053922533 | AS21: 0.10525104 | AT21: 0.22285725 | AU21: 0.053078509 | AV21: 0.049455516 | AW21: 0.026337565 | AX21: 0.036361706 | BB21: 1 | BD21: 40998 | BE21: 0.10050254
... F43: 41698 | G43: =Price!G43/'Price D Coupon'!G$5 -> 0 | H43: =Price!H43/'Price D Coupon'!H$5 -> 0 | I43: =Price!I43/'Price D Coupon'!I$5 -> 0 | J43: =Price!J43/'Price D Coupon'!J$5 -> 7.521877 | K43: =Price!K43/'Price D Coupon'!K$5 -> 7.022619 | L43: =Price!L43/'Price D Coupon'!L$5 -> 6.2809911 | M43: =Price!M43/'Price D Coupon'!M$5 -> 5.610418 | N43: =Price!N43/'Price D Coupon'!N$5 -> 6.5761905 | ... W43: =Price!W43/'Price D Coupon'!W$5 -> 3.3467949 | AA43: 23.153006 | AC43: 41698 | AD43: =VLOOKUP(AC43,CurrentCoupon!$B$4:$C$1468,2,0) -> 3.3514862 | AG43: 41698 | AH43: 0 | AI43: 0 | AJ43: 0 | AK43: 0.19184365 | AL43: 0.23825886 | AM43: 0.064985622 | AN43: 0.069537901 | AO43: 0.016614291 | AP43: 0.07514546 | AQ43: 0.066686121 | AR43: 0.036160574 | AS43: 0.053572741 | AT43: 0.11131174 | AU43: 0.031281395 | AV43: 0.017731279 | AW43: 0.010264369 | AX43: 0.016605998 | BB43: 1 | BD43: 41670 | BE43: -0.031266772
F44: 41729 | G44: =Price!G44/'Price D Coupon'!G$5 -> 7.7871548 | H44: =Price!H44/'Price D Coupon'!H$5 -> 7.3340295 | I44: =Price!I44/'Price D Coupon'!I$5 -> 6.6348105 | J44: =Price!J44/'Price D Coupon'!J$5 -> 7.5631944 | K44: =Price!K44/'Price D Coupon'!K$5 -> 7.0929581 | L44: =Price!L44/'Price D Coupon'!L$5 -> 6.376998 | M44: =Price!M44/'Price D Coupon'!M$5 -> 5.7437513 | N44: =Price!N44/'Price D Coupon'!N$5 -> 6.6867063 | ... W44: =Price!W44/'Price D Coupon'!W$5 -> 3.3532595 | AA44: 23.738136 | AC44: 41729 | AD44: =VLOOKUP(AC44,CurrentCoupon!$B$4:$C$1468,2,0) -> 3.4468594 | AE44: =IF(AD44<$G$5,G44,(H44-G44)/0.5*(AD44-$G$5)+G44) -> 7.3821882 | AG44: 41729 | AH44: 0.14015953 | AI44: 0.09835625 | AJ44: 0.093316082 | AK44: 0.12877118 | AL44: 0.15976314 | AM44: 0.04347176 | AN44: 0.046432933 | AO44: 0.011122974 | AP44: 0.050247243 | AQ44: 0.04446765 | AR44: 0.024082135 | AS44: 0.035773151 | AT44: 0.074114286 | AU44: 0.02077472 | AV44: 0.011604631 | AW44: 0.0067031661 | AX44: 0.010839164 | BB44: 1 | BD44: 41698 | BE44: 0.021801735
F45: 41759 | G45: =Price!G45/'Price D Coupon'!G$5 -> 7.7767381 | H45: =Price!H45/'Price D Coupon'!H$5 -> 7.2715295 | I45: =Price!I45/'Price D Coupon'!I$5 -> 6.439498 | J45: =Price!J45/'Price D Coupon'!J$5 -> 7.5684048 | K45: =Price!K45/'Price D Coupon'!K$5 -> 7.0081349 | L45: =Price!L45/'Price D Coupon'!L$5 -> 6.298873 | M45: =Price!M45/'Price D Coupon'!M$5 -> 5.6152778 | N45: =Price!N45/'Price D Coupon'!N$5 -> 6.5840295 | ... W45: =Price!W45/'Price D Coupon'!W$5 -> 3.3989316 | AA45: 23.390709 | AC45: 41759 | AD45: =VLOOKUP(AC45,CurrentCoupon!$B$4:$C$1468,2,0) -> 3.327427 | AE45: =IF(AD45<$G$5,G45,(H45-G45)/0.5*(AD45-$G$5)+G45) -> 7.4459003 | AG45: 41759 | AH45: 0.14062117 | AI45: 0.09864385 | AJ45: 0.09352348 | AK45: 0.12911479 | AL45: 0.16001339 | AM45: 0.043464161 | AN45: 0.046333066 | AO45: 0.011122388 | AP45: 0.05021791 | AQ45: 0.044342722 | AR45: 0.023949658 | AS45: 0.035710082 | AT45: 0.073778213 | AU45: 0.020624509 | AV45: 0.011370895 | AW45: 0.0065605566 | AX45: 0.010609155 | BB45: 1 | BD45: 41729 | BE45: 0.021192307
F46: 41789 | G46: =Price!G46/'Price D Coupon'!G$5 -> 7.6753492 | H46: =Price!H46/'Price D Coupon'!H$5 -> 7.0734127 | I46: =Price!I46/'Price D Coupon'!I$5 -> 6.1180556 | J46: =Price!J46/'Price D Coupon'!J$5 -> 7.4930556 | K46: =Price!K46/'Price D Coupon'!K$5 -> 6.8412698 | L46: =Price!L46/'Price D Coupon'!L$5 -> 6.0789931 | M46: =Price!M46/'Price D Coupon'!M$5 -> 5.3402778 | N46: =Price!N46/'Price D Coupon'!N$5 -> 6.3859127 | ... W46: =Price!W46/'Price D Coupon'!W$5 -> 3.4017094 | AA46: 22.340791 | AC46: 41789 | AD46: =VLOOKUP(AC46,CurrentCoupon!$B$4:$C$1468,2,0) -> 3.132717 | AE46: =IF(AD46<$G$5,G46,(H46-G46)/0.5*(AD46-$G$5)+G46) -> 7.5155747 | AG46: 41789 | AH46: 0.14116669 | AI46: 0.098992167 | AJ46: 0.093649008 | AK46: 0.12953463 | AL46: 0.16034508 | AM46: 0.043463751 | AN46: 0.046201625 | AO46: 0.011125465 | AP46: 0.050174575 | AQ46: 0.044177838 | AR46: 0.023813256 | AS46: 0.03561943 | AT46: 0.073323978 | AU46: 0.020456558 | AV46: 0.011149762 | AW46: 0.0064080309 | AX46: 0.010398151 | BB46: 1 | BD46: 41759 | BE46: -0.0078448557
F47: 41820 | G47: =Price!G47/'Price D Coupon'!G$5 -> 7.7038214 | H47: =Price!H47/'Price D Coupon'!H$5 -> 7.1643866 | I47: =Price!I47/'Price D Coupon'!I$5 -> 6.3184028 | J47: =Price!J47/'Price D Coupon'!J$5 -> 7.5059048 | K47: =Price!K47/'Price D Coupon'!K$5 -> 6.9367063 | L47: =Price!L47/'Price D Coupon'!L$5 -> 6.2285605 | M47: =Price!M47/'Price D Coupon'!M$5 -> 5.5770847 | N47: =Price!N47/'Price D Coupon'!N$5 -> 6.4858152 | ... W47: =Price!W47/'Price D Coupon'!W$5 -> 3.4854701 | AA47: 23.100269 | AC47: 41820 | AD47: =VLOOKUP(AC47,CurrentCoupon!$B$4:$C$1468,2,0) -> 3.1600586 | AE47: =IF(AD47<$G$5,G47,(H47-G47)/0.5*(AD47-$G$5)+G47) -> 7.5311391 | AG47: 41820 | AH47: 0.14171813 | AI47: 0.099321696 | AJ47: 0.093842231 | AK47: 0.1299741 | AL47: 0.16063179 | AM47: 0.04344704 | AN47: 0.046090472 | AO47: 0.011132259 | AP47: 0.050119115 | AQ47: 0.044007694 | AR47: 0.023687647 | AS47: 0.035517133 | AT47: 0.07283799 | AU47: 0.020276544 | AV47: 0.01092879 | AW47: 0.0062779745 | AX47: 0.010189405 | BB47: 1 | BD47: 41789 | BE47: -0.029344377
F48: 41851 | G48: =Price!G48/'Price D Coupon'!G$5 -> 7.6829881 | H48: =Price!H48/'Price D Coupon'!H$5 -> 7.1197438 | I48: =Price!I48/'Price D Coupon'!I$5 -> 6.330123 | J48: =Price!J48/'Price D Coupon'!J$5 -> 7.4746548 | K48: =Price!K48/'Price D Coupon'!K$5 -> 6.9143866 | L48: =Price!L48/'Price D Coupon'!L$5 -> 6.251998 | M48: =Price!M48/'Price D Coupon'!M$5 -> 5.6569444 | N48: =Price!N48/'Price D Coupon'!N$5 -> 6.5215295 | ... W48: =Price!W48/'Price D Coupon'!W$5 -> 3.6224902 | AA48: 23.624167 | AC48: 41851 | AD48: =VLOOKUP(AC48,CurrentCoupon!$B$4:$C$1468,2,0) -> 3.2761066 | AE48: =IF(AD48<$G$5,G48,(H48-G48)/0.5*(AD48-$G$5)+G48) -> 7.3719572 | AG48: 41851 | AH48: 0.14230565 | AI48: 0.099654655 | AJ48: 0.094021309 | AK48: 0.13040735 | AL48: 0.16091603 | AM48: 0.043411461 | AN48: 0.045938062 | AO48: 0.011133829 | AP48: 0.050066548 | AQ48: 0.043832975 | AR48: 0.023567107 | AS48: 0.035409749 | AT48: 0.072357057 | AU48: 0.02010048 | AV48: 0.010733533 | AW48: 0.006156812 | AX48: 0.009987388 | BB48: 1 | BD48: 41820 | BE48: 0.027757435
F49: 41880 | G49: =Price!G49/'Price D Coupon'!G$5 -> 7.4774326 | H49: =Price!H49/'Price D Coupon'!H$5 -> 6.8234127 | I49: =Price!I49/'Price D Coupon'!I$5 -> 5.8524306 | J49: =Price!J49/'Price D Coupon'!J$5 -> 7.2899326 | K49: =Price!K49/'Price D Coupon'!K$5 -> 6.6314501 | L49: =Price!L49/'Price D Coupon'!L$5 -> 5.8563383 | M49: =Price!M49/'Price D Coupon'!M$5 -> 5.2916667 | N49: =Price!N49/'Price D Coupon'!N$5 -> 6.1894841 | ... W49: =Price!W49/'Price D Coupon'!W$5 -> 3.5868065 | AA49: 22.35274 | AC49: 41880 | AD49: =VLOOKUP(AC49,CurrentCoupon!$B$4:$C$1468,2,0) -> 3.0803372 | AE49: =IF(AD49<$G$5,G49,(H49-G49)/0.5*(AD49-$G$5)+G49) -> 7.3723483 | AG49: 41880 | AH49: 0.14298975 | AI49: 0.10006002 | AJ49: 0.093952745 | AK49: 0.13095539 | AL49: 0.16127149 | AM49: 0.043372777 | AN49: 0.04578056 | AO49: 0.011131859 | AP49: 0.049983064 | AQ49: 0.043647075 | AR49: 0.023428339 | AS49: 0.035284097 | AT49: 0.071834871 | AU49: 0.019930638 | AV49: 0.010528337 | AW49: 0.0060439662 | AX49: 0.0098050215 | BB49: 1 | BD49: 41851 | BE49: 0.0074645314
F50: 41912 | G50: =Price!G50/'Price D Coupon'!G$5 -> 7.6100714 | H50: =Price!H50/'Price D Coupon'!H$5 -> 6.9947438 | I50: =Price!I50/'Price D Coupon'!I$5 -> 6.1699653 | J50: =Price!J50/'Price D Coupon'!J$5 -> 7.4381944 | K50: =Price!K50/'Price D Coupon'!K$5 -> 6.8429581 | L50: =Price!L50/'Price D Coupon'!L$5 -> 6.1035605 | M50: =Price!M50/'Price D Coupon'!M$5 -> 5.6569444 | N50: =Price!N50/'Price D Coupon'!N$5 -> 6.4277778 | ... W50: =Price!W50/'Price D Coupon'!W$5 -> 3.7018162 | AA50: 23.47435 | AC50: 41912 | AD50: =VLOOKUP(AC50,CurrentCoupon!$B$4:$C$1468,2,0) -> 3.2078957 | AE50: =IF(AD50<$G$5,G50,(H50-G50)/0.5*(AD50-$G$5)+G50) -> 7.3542235 | AG50: 41912 | AH50: 0.14373459 | AI50: 0.10044565 | AJ50: 0.093821049 | AK50: 0.13153506 | AL50: 0.16169414 | AM50: 0.043300392 | AN50: 0.045626976 | AO50: 0.011141527 | AP50: 0.049898277 | AQ50: 0.043434667 | AR50: 0.023275456 | AS50: 0.035135695 | AT50: 0.071247425 | AU50: 0.019753502 | AV50: 0.010365521 | AW50: 0.0059488495 | AX50: 0.0096412185 | BB50: 1 | BD50: 41880 | BE50: -0.047313023
F51: 41943 | G51: =Price!G51/'Price D Coupon'!G$5 -> 7.4854167 | H51: =Price!H51/'Price D Coupon'!H$5 -> 6.7502993 | I51: =Price!I51/'Price D Coupon'!I$5 -> 5.7302083 | J51: =Price!J51/'Price D Coupon'!J$5 -> 7.2979167 | K51: =Price!K51/'Price D Coupon'!K$5 -> 6.6074422 | L51: =Price!L51/'Price D Coupon'!L$5 -> 5.8083333 | M51: =Price!M51/'Price D Coupon'!M$5 -> 5.3534736 | N51: =Price!N51/'Price D Coupon'!N$5 -> 6.1565476 | ... W51: =Price!W51/'Price D Coupon'!W$5 -> 3.6040073 | AA51: 22.330396 | AC51: 41943 | AD51: =VLOOKUP(AC51,CurrentCoupon!$B$4:$C$1468,2,0) -> 3.0097405 | AE51: =IF(AD51<$G$5,G51,(H51-G51)/0.5*(AD51-$G$5)+G51) -> 7.4710958 | AG51: 41943 | AH51: 0.14443816 | AI51: 0.10079491 | AJ51: 0.093803749 | AK51: 0.13206838 | AL51: 0.16203744 | AM51: 0.043269447 | AN51: 0.045468912 | AO51: 0.011135247 | AP51: 0.049812968 | AQ51: 0.043218243 | AR51: 0.023134329 | AS51: 0.035004964 | AT51: 0.07071713 | AU51: 0.019568962 | AV51: 0.01018449 | AW51: 0.0058467279 | AX51: 0.0094959389 | BB51: 1 | BD51: 41912 | BE51: 0.043121935
F52: 41971 | G52: =Price!G52/'Price D Coupon'!G$5 -> 7.3392381 | H52: =Price!H52/'Price D Coupon'!H$5 -> 6.5215295 | I52: =Price!I52/'Price D Coupon'!I$5 -> 5.4121528 | J52: =Price!J52/'Price D Coupon'!J$5 -> 7.1621548 | K52: =Price!K52/'Price D Coupon'!K$5 -> 6.3920635 | L52: =Price!L52/'Price D Coupon'!L$5 -> 5.5371528 | M52: =Price!M52/'Price D Coupon'!M$5 -> 5.1326402 | N52: =Price!N52/'Price D Coupon'!N$5 -> 5.8965295 | ... W52: =Price!W52/'Price D Coupon'!W$5 -> 3.5599902 | AA52: 21.502842 | AC52: 41971 | AD52: =VLOOKUP(AC52,CurrentCoupon!$B$4:$C$1468,2,0) -> 2.8456853 | AE52: =IF(AD52<$G$5,G52,(H52-G52)/0.5*(AD52-$G$5)+G52) -> 7.3392381 | AG52: 41971 | AH52: 0.14515803 | AI52: 0.10116958 | AJ52: 0.093660938 | AK52: 0.13265044 | AL52: 0.16244464 | AM52: 0.043218251 | AN52: 0.045310101 | AO52: 0.01114175 | AP52: 0.04972537 | AQ52: 0.042999053 | AR52: 0.022957063 | AS52: 0.034883358 | AT52: 0.070176318 | AU52: 0.019385706 | AV52: 0.010016056 | AW52: 0.0057485049 | AX52: 0.009354846 | BB52: 1 | BD52: 41943 | BE52: -0.039672605
F53: 42004 | G53: =Price!G53/'Price D Coupon'!G$5 -> 7.0138889 | H53: =Price!H53/'Price D Coupon'!H$5 -> 6.1894841 | I53: =Price!I53/'Price D Coupon'!I$5 -> 5.0672758 | J53: =Price!J53/'Price D Coupon'!J$5 -> 6.9513889 | K53: =Price!K53/'Price D Coupon'!K$5 -> 6.2921644 | L53: =Price!L53/'Price D Coupon'!L$5 -> 5.4383681 | M53: =Price!M53/'Price D Coupon'!M$5 -> 5.0659736 | N53: =Price!N53/'Price D Coupon'!N$5 -> 5.7519841 | ... W53: =Price!W53/'Price D Coupon'!W$5 -> 3.5603632 | AA53: 21.200167 | AC53: 42004 | AD53: =VLOOKUP(AC53,CurrentCoupon!$B$4:$C$1468,2,0) -> 2.8338661 | AE53: =IF(AD53<$G$5,G53,(H53-G53)/0.5*(AD53-$G$5)+G53) -> 7.0138889 | AG53: 42004 | AH53: 0.14591158 | AI53: 0.10151672 | AJ53: 0.093517444 | AK53: 0.13322884 | AL53: 0.16283379 | AM53: 0.043181261 | AN53: 0.045154192 | AO53: 0.011139471 | AP53: 0.049636892 | AQ53: 0.042787229 | AR53: 0.022783041 | AS53: 0.034774424 | AT53: 0.069639651 | AU53: 0.01919267 | AV53: 0.0098399953 | AW53: 0.0056382197 | AX53: 0.0092245901 | BB53: 1 | BD53: 41971 | BE53: -0.033127567
F54: 42034 | G54: =Price!G54/'Price D Coupon'!G$5 -> 5.8940992 | H54: =Price!H54/'Price D Coupon'!H$5 -> 4.8948413 | I54: =Price!I54/'Price D Coupon'!I$5 -> 3.7938381 | J54: =Price!J54/'Price D Coupon'!J$5 -> 5.8524326 | K54: =Price!K54/'Price D Coupon'!K$5 -> 5.0734127 | L54: =Price!L54/'Price D Coupon'!L$5 -> 4.2899306 | M54: =Price!M54/'Price D Coupon'!M$5 -> 4.1284736 | N54: =Price!N54/'Price D Coupon'!N$5 -> 4.546627 | ... W54: =Price!W54/'Price D Coupon'!W$5 -> 3.4594017 | AA54: 17.653291 | AC54: 42034 | AD54: =VLOOKUP(AC54,CurrentCoupon!$B$4:$C$1468,2,0) -> 2.4526688 | AE54: =IF(AD54<$G$5,G54,(H54-G54)/0.5*(AD54-$G$5)+G54) -> 5.8940992 | AG54: 42034 | AH54: 0.1467089 | AI54: 0.10176797 | AJ54: 0.092870263 | AK54: 0.1338754 | AL54: 0.1633136 | AM54: 0.043174954 | AN54: 0.045038886 | AO54: 0.011157228 | AP54: 0.049576038 | AQ54: 0.042605814 | AR54: 0.022670742 | AS54: 0.034657797 | AT54: 0.069138471 | AU54: 0.019042072 | AV54: 0.0097161724 | AW54: 0.0055692771 | AX54: 0.0091164247 | BB54: 1 | BD54: 42004 | BE54: -0.026017102
F55: 42062 | G55: =Price!G55/'Price D Coupon'!G$5 -> 6.5815992 | H55: =Price!H55/'Price D Coupon'!H$5 -> 5.7296644 | I55: =Price!I55/'Price D Coupon'!I$5 -> 4.6610258 | J55: =Price!J55/'Price D Coupon'!J$5 -> 6.5243056 | K55: =Price!K55/'Price D Coupon'!K$5 -> 5.8323413 | L55: =Price!L55/'Price D Coupon'!L$5 -> 5.0907133 | M55: =Price!M55/'Price D Coupon'!M$5 -> 4.7916667 | N55: =Price!N55/'Price D Coupon'!N$5 -> 5.363593 | ... W55: =Price!W55/'Price D Coupon'!W$5 -> 3.7935372 | AA55: 20.308623 | AC55: 42062 | AD55: =VLOOKUP(AC55,CurrentCoupon!$B$4:$C$1468,2,0) -> 2.7365986 | AE55: =IF(AD55<$G$5,G55,(H55-G55)/0.5*(AD55-$G$5)+G55) -> 6.5815992 | AG55: 42062 | AH55: 0.147653 | AI55: 0.10210331 | AJ55: 0.092170981 | AK55: 0.13465479 | AL55: 0.16389333 | AM55: 0.043127725 | AN55: 0.044865757 | AO55: 0.011178399 | AP55: 0.049492497 | AQ55: 0.042362049 | AR55: 0.022522098 | AS55: 0.034505449 | AT55: 0.068507645 | AU55: 0.018883043 | AV55: 0.0095794762 | AW55: 0.0054880754 | AX55: 0.0090123686 | BB55: 1 | BD55: 42034 | BE55: -0.18730149
F56: 42094 | G56: =Price!G56/'Price D Coupon'!G$5 -> 6.4225714 | H56: =Price!H56/'Price D Coupon'!H$5 -> 5.5483152 | I56: =Price!I56/'Price D Coupon'!I$5 -> 4.455123 | J56: =Price!J56/'Price D Coupon'!J$5 -> 6.3756944 | K56: =Price!K56/'Price D Coupon'!K$5 -> 5.6777778 | L56: =Price!L56/'Price D Coupon'!L$5 -> 4.9277778 | M56: =Price!M56/'Price D Coupon'!M$5 -> 4.6951402 | N56: =Price!N56/'Price D Coupon'!N$5 -> 5.2313492 | ... W56: =Price!W56/'Price D Coupon'!W$5 -> 3.9854701 | AA56: 21.308623 | AC56: 42094 | AD56: =VLOOKUP(AC56,CurrentCoupon!$B$4:$C$1468,2,0) -> 2.6610352 | AG56: 42094 | AH56: 0.14849148 | AI56: 0.10231681 | AJ56: 0.091594999 | AK56: 0.1353443 | AL56: 0.16435025 | AM56: 0.043110237 | AN56: 0.044714081 | AO56: 0.011190124 | AP56: 0.049415117 | AQ56: 0.042190048 | AR56: 0.022388694 | AS56: 0.034341268 | AT56: 0.067955841 | AU56: 0.018764085 | AV56: 0.0094829009 | AW56: 0.0054262526 | AX56: 0.0089235168 | BB56: 1 | BD56: 42062 | BE56: 0.16728926
AG59: Weight
AG60: Date | AH60: FN30. 300. 13 | AI60: FN30. 350. 13 | AJ60: FN30. 400. 13 | AK60: FN30. 300. 12 | AL60: FN30. 350. 12 | AM60: FN30. 400. 11 | AN60: FN30. 450. 11 | AO60: FN30. 350. 10 | AP60: FN30. 400. 10 | AQ60: FN30. 450. 10 | AR60: FN30. 500. 10 | AS60: FN30. 400. 09 | AT60: FN30. 450. 09 | AU60: FN30. 500. 09 | AV60: FN30. 550. 08 | AW60: FN30. 600. 08 | AX60: FN30. 650. 67 | AY60: GII30. 400. 10 | AZ60: GII30. 450. 10 | BA60: GII30. 500. 10 | BB60: Total
AG61: 40633 | AH61: =AH8*G8 -> 0 | AI61: =AI8*H8 -> 0 | AJ61: =AJ8*I8 -> 0 | AK61: =AK8*J8 -> 0 | AL61: =AL8*K8 -> 0 | AM61: =AM8*L8 -> 0 | AN61: =AN8*M8 -> 0 | AO61: =AO8*N8 -> 0.19426941 | ... AX61: =AX8*W8 -> 0.1581576 | BB61: =SUM(AH61:AX61) -> 5.4040031
AG62: 40662 | AH62: =AH9*G9 -> 0 | AI62: =AI9*H9 -> 0 | AJ62: =AJ9*I9 -> 0 | AK62: =AK9*J9 -> 0 | AL62: =AL9*K9 -> 0 | AM62: =AM9*L9 -> 0 | AN62: =AN9*M9 -> 0 | AO62: =AO9*N9 -> 0.19655332 | ... AX62: =AX9*W9 -> 0.15702833 | BB62: =SUM(AH62:AX62) -> 5.4712823
AG63: 40694 | AH63: =AH10*G10 -> 0 | AI63: =AI10*H10 -> 0 | AJ63: =AJ10*I10 -> 0 | AK63: =AK10*J10 -> 0 | AL63: =AL10*K10 -> 0 | AM63: =AM10*L10 -> 0 | AN63: =AN10*M10 -> 0 | AO63: =AO10*N10 -> 0.20173044 | ... AX63: =AX10*W10 -> 0.15914129 | BB63: =SUM(AH63:AX63) -> 5.4954374
AG64: 40724 | AH64: =AH11*G11 -> 0 | AI64: =AI11*H11 -> 0 | AJ64: =AJ11*I11 -> 0 | AK64: =AK11*J11 -> 0 | AL64: =AL11*K11 -> 0 | AM64: =AM11*L11 -> 0 | AN64: =AN11*M11 -> 0 | AO64: =AO11*N11 -> 0.20465915 | ... AX64: =AX11*W11 -> 0.15917742 | BB64: =SUM(AH64:AX64) -> 5.5415672
AG65: 40753 | AH65: =AH12*G12 -> 0 | AI65: =AI12*H12 -> 0 | AJ65: =AJ12*I12 -> 0 | AK65: =AK12*J12 -> 0 | AL65: =AL12*K12 -> 0 | AM65: =AM12*L12 -> 0 | AN65: =AN12*M12 -> 0 | AO65: =AO12*N12 -> 0.20001887 | ... AX65: =AX12*W12 -> 0.1525407 | BB65: =SUM(AH65:AX65) -> 5.2080149
AG66: 40786 | AH66: =AH13*G13 -> 0 | AI66: =AI13*H13 -> 0 | AJ66: =AJ13*I13 -> 0 | AK66: =AK13*J13 -> 0 | AL66: =AL13*K13 -> 0 | AM66: =AM13*L13 -> 0 | AN66: =AN13*M13 -> 0 | AO66: =AO13*N13 -> 0.17817214 | ... AX66: =AX13*W13 -> 0.13794014 | BB66: =SUM(AH66:AX66) -> 4.1199718
AG67: 40816 | AH67: =AH14*G14 -> 0 | AI67: =AI14*H14 -> 0 | AJ67: =AJ14*I14 -> 0 | AK67: =AK14*J14 -> 0 | AL67: =AL14*K14 -> 0 | AM67: =AM14*L14 -> 0 | AN67: =AN14*M14 -> 0 | AO67: =AO14*N14 -> 0.1499767 | ... AX67: =AX14*W14 -> 0.11944068 | BB67: =SUM(AH67:AX67) -> 3.3173716
...

Sheet Price
G5: 3 | H5: 3.5 | I5: 4 | J5: 3 | K5: 3.5 | L5: 4 | M5: 4.5 | N5: 3.5 | O5: 4 | P5: 4.5 | Q5: 5 | R5: 4 | S5: 4.5 | T5: 5 | U5: 5.5 | V5: 6 | W5: 6.5 | X5: 4 | Y5: 4.5 | Z5: 5
F6: IOS Unhedged 1m Return (%)
F7: Date | G7: FN30. 300. 13 | H7: FN30. 350. 13 | I7: FN30. 400. 13 | J7: FN30. 300. 12 | K7: FN30. 350. 12 | L7: FN30. 400. 11 | M7: FN30. 450. 11 | N7: FN30. 350. 10 | O7: FN30. 400. 10 | P7: FN30. 450. 10 | Q7: FN30. 500. 10 | R7: FN30. 400. 09 | S7: FN30. 450. 09 | T7: FN30. 500. 09 | U7: FN30. 550. 08 | V7: FN30. 600. 08 | W7: FN30. 650. 67 | X7: GII30. 400. 10 | Y7: GII30. 450. 10 | Z7: GII30. 500. 10 | AA7: Avg
F8: 40633 | N8: 24.809722 | O8: 25.996111 | P8: 26.1825 | Q8: 25.97089 | R8: 24.191111 | S8: 24.4485 | T8: 24.16189 | U8: 20.548277 | V8: 20.218667 | W8: 21.327055 | AA8: 23.785472
F9: 40662 | N9: 24.928443 | O9: 26.261222 | P9: 26.348 | Q9: 26.527778 | R9: 24.351222 | S9: 24.707001 | T9: 24.980777 | U9: 20.867556 | V9: 20.384334 | W9: 21.451111 | AA9: 24.080744
F10: 40694 | N10: 25.422723 | O10: 26.617111 | P10: 26.538501 | Q10: 26.618889 | R10: 24.668112 | S10: 24.5735 | T10: 24.59589 | U10: 20.216279 | V10: 20.484666 | W10: 22.128056 | AA10: 24.186373
F11: 40724 | N11: 25.649722 | O11: 26.887112 | P11: 26.9175 | Q11: 27.333889 | R11: 24.613111 | S11: 24.5815 | T11: 24.931888 | U11: 20.290278 | V11: 20.836667 | W11: 22.460057 | X11: 27.977112 | Y11: 29.038501 | Z11: 29.38089 | AA11: 25.45371
F12: 40753 | N12: 24.934722 | O12: 25.727112 | P12: 25.065499 | Q12: 25.388889 | R12: 23.32011 | S12: 22.6755 | T12: 22.857889 | U12: 19.352278 | V12: 20.004667 | W12: 21.843056 | X12: 27.19511 | Y12: 27.878501 | Z12: 27.794889 | AA12: 24.156786
F13: 40786 | N13: 22.059722 | O13: 21.273111 | P13: 18.5495 | Q13: 19.575889 | R13: 19.336111 | S13: 16.8625 | T13: 17.419889 | U13: 16.071278 | V13: 17.441667 | W13: 19.968056 | X13: 24.227112 | Y13: 23.784501 | Z13: 23.15489 | AA13: 19.978787
F14: 40816 | N14: 18.423167 | O14: 16.921333 | P14: 15.1685 | Q14: 16.682668 | R14: 14.936333 | S14: 13.3095 | T14: 14.338667 | U14: 13.070833 | V14: 14.694 | W14: 17.441167 | X14: 21.483333 | Y14: 20.4815 | Z14: 19.322667 | AA14: 16.636436
F15: 40847 | N15: 18.106723 | O15: 16.69511 | P15: 16.3625 | Q15: 19.263889 | R15: 15.273111 | S15: 14.1435 | T15: 17.044889 | U15: 12.993278 | V15: 14.441667 | W15: 16.874056 | X15: 21.930111 | Y15: 21.0185 | Z15: 20.732889 | AA15: 17.298479
F16: 40877 | N16: 17.684722 | O16: 16.227112 | P16: 16.7375 | Q16: 19.919889 | R16: 14.320111 | S16: 13.8315 | T16: 17.372888 | U16: 13.634278 | V16: 15.472667 | W16: 17.749056 | X16: 21.555111 | Y16: 20.815499 | Z16: 20.997888 | AA16: 17.409094
F17: 40907 | N17: 17.188166 | O17: 15.842333 | P17: 16.7315 | Q17: 19.853667 | R17: 13.639333 | S17: 13.5285 | T17: 16.932668 | U17: 12.882833 | V17: 15.006 | W17: 17.363166 | X17: 21.217332 | Y17: 20.340499 | Z17: 20.635667 | AA17: 17.012436
F18: 40939 | N18: 16.059722 | O18: 14.539111 | P18: 15.2375 | Q18: 17.951889 | R18: 12.023111 | S18: 12.1595 | T18: 15.107889 | U18: 12.509278 | V18: 14.300667 | W18: 16.843056 | X18: 19.94511 | Y18: 18.8935 | Z18: 18.52989 | AA18: 15.700017
F19: 40968 | N19: 17.903722 | O19: 16.836111 | P19: 17.2065 | Q19: 19.77989 | R19: 13.633111 | S19: 13.7535 | T19: 16.65489 | U19: 13.415278 | V19: 15.457667 | W19: 17.765057 | X19: 20.680111 | Y19: 19.7995 | Z19: 19.169889 | AA19: 17.081171
F20: 40998 | L20: 20.378222 | M20: 20.733999 | N20: 19.663444 | O20: 18.831221 | P20: 18.812 | Q20: 21.418779 | R20: 15.722222 | S20: 15.328 | T20: 18.511777 | U20: 14.117556 | V20: 16.302333 | W20: 18.580111 | X20: 21.363223 | Y20: 20.656 | Z20: 20.730777 | AA20: 18.743311
F21: 41029 | L21: 19.07011 | M21: 19.3935 | N21: 18.309722 | O21: 17.53911 | P21: 17.440499 | Q21: 20.716888 | R21: 14.508111 | S21: 14.0815 | T21: 17.857889 | U21: 13.540278 | V21: 15.628667 | W21: 19.109057 | X21: 20.367111 | Y21: 19.7685 | Z21: 19.90489 | AA21: 17.815722
F22: 41060 | L22: 16.711111 | M22: 17.2375 | N22: 15.418722 | O22: 15.023111 | P22: 15.2685 | Q22: 18.747888 | R22: 11.899111 | S22: 12.1285 | T22: 15.982889 | U22: 12.181278 | V22: 14.191667 | W22: 18.312056 | X22: 18.711111 | Y22: 18.0815 | Z22: 18.232889 | AA22: 15.875189
F23: 41089 | L23: 16.410222 | M23: 17.327999 | N23: 15.835444 | O23: 15.425222 | P23: 15.766 | Q23: 19.043779 | R23: 12.519222 | S23: 12.969 | T23: 16.386777 | U23: 12.305556 | V23: 14.067333 | W23: 17.84511 | X23: 18.878222 | Y23: 18.297001 | Z23: 18.386777 | AA23: 16.097578
F24: 41121 | L24: 15.227111 | M24: 17.6125 | N24: 13.825722 | O24: 14.711111 | P24: 15.8155 | Q24: 18.93589 | R24: 12.211111 | S24: 13.1285 | T24: 16.247889 | U24: 12.274278 | V24: 13.894667 | W24: 18.109057 | X24: 18.055111 | Y24: 17.940499 | Z24: 17.997888 | AA24: 15.732456
F25: 41152 | L25: 16.510445 | M25: 18.541001 | N25: 14.947889 | O25: 15.806444 | P25: 16.525 | Q25: 19.836556 | R25: 13.244444 | S25: 14.056 | T25: 17.508555 | U25: 12.758111 | V25: 14.460667 | W25: 18.303222 | X25: 18.869444 | Y25: 18.806 | Z25: 19.086556 | AA25: 16.617356
F26: 41180 | L26: 13.773111 | M26: 16.0185 | N26: 11.731722 | O26: 13.149111 | P26: 14.3935 | Q26: 18.872888 | R26: 11.227111 | S26: 12.4255 | T26: 16.701889 | U26: 11.743278 | V26: 13.910667 | W26: 17.655056 | X26: 17.44511 | Y26: 17.2995 | Z26: 18.40489 | AA26: 14.983455
F27: 41213 | L27: 13.899111 | M27: 16.596499 | N27: 11.856722 | O27: 13.399111 | P27: 15.0815 | Q27: 18.716888 | R27: 11.242111 | S27: 12.8315 | T27: 16.747888 | U27: 12.353278 | V27: 14.582667 | W27: 17.906056 | X27: 17.524111 | Y27: 17.659501 | Z27: 19.044889 | AA27: 15.296122
F28: 41243 | L28: 13.858333 | M28: 15.4505 | N28: 12.032167 | O28: 13.124333 | P28: 14.4345 | Q28: 17.447667 | R28: 10.842333 | S28: 12.0595 | T28: 15.322667 | U28: 11.304833 | V28: 13.631 | W28: 16.817167 | X28: 17.233333 | Y28: 17.2315 | Z28: 18.494666 | AA28: 14.618967
F29: 41274 | L29: 14.238222 | M29: 16.094 | N29: 12.241444 | O29: 13.300222 | P29: 14.922 | Q29: 17.824779 | R29: 11.316222 | S29: 12.844 | T29: 15.652778 | U29: 11.993556 | V29: 14.302333 | W29: 17.330111 | X29: 17.566222 | Y29: 17.452999 | Z29: 18.761777 | AA29: 15.056044
F30: 41305 | L30: 16.383112 | M30: 17.471499 | N30: 14.809722 | O30: 15.367111 | P30: 16.1905 | Q30: 18.122888 | R30: 13.070111 | S30: 13.6435 | T30: 15.919889 | U30: 12.087278 | V30: 13.894667 | W30: 16.687056 | X30: 18.78911 | Y30: 18.6755 | Z30: 19.513889 | AA30: 16.041722
F31: 41333 | L31: 16.070111 | M31: 17.315499 | N31: 15.122722 | O31: 15.195111 | P31: 16.0965 | Q31: 17.90489 | R31: 13.070111 | S31: 13.6285 | T31: 16.060889 | U31: 12.337278 | V31: 13.894667 | W31: 16.327056 | X31: 18.82011 | Y31: 18.7995 | Z31: 19.52989 | AA31: 16.011522
F32: 41361 | J32: 19.033333 | K32: 19.262721 | L32: 17.149111 | M32: 17.8625 | N32: 16.465722 | O32: 16.227112 | P32: 16.7995 | Q32: 18.325889 | R32: 14.023111 | S32: 14.3625 | T32: 16.638889 | U32: 12.665278 | V32: 14.254667 | W32: 16.077056 | X32: 19.53911 | Y32: 19.5495 | Z32: 20.325889 | AA32: 16.974229
F33: 41394 | J33: 17.580334 | K33: 16.793721 | L33: 15.102111 | M33: 15.6435 | N33: 13.715722 | O33: 13.867111 | P33: 14.0185 | Q33: 15.951889 | R33: 11.258111 | S33: 11.7535 | T33: 14.654889 | U33: 11.040278 | V33: 12.660667 | W33: 14.452056 | X33: 17.852112 | Y33: 17.628501 | Z33: 16.466888 | AA33: 14.731758
F34: 41425 | J34: 20.347001 | K34: 20.392167 | L34: 19.139333 | M34: 18.496499 | N34: 18.188166 | O34: 17.702333 | P34: 16.6685 | Q34: 16.166667 | R34: 15.842333 | S34: 15.0125 | T34: 14.822667 | U34: 11.695833 | V34: 12.147 | W34: 13.973167 | X34: 20.530334 | Y34: 18.5435 | Z34: 16.822667 | AA34: 16.852392
F35: 41453 | J35: 20.830334 | K35: 21.184722 | L35: 21.008112 | M35: 20.7685 | N35: 19.637721 | O35: 20.023111 | P35: 19.690499 | Q35: 18.68589 | R35: 18.617111 | S35: 18.2375 | T35: 17.388889 | U35: 13.274278 | V35: 13.613667 | W35: 14.874056 | X35: 22.211111 | Y35: 20.9255 | Z35: 20.607889 | AA35: 18.916405
F36: 41486 | J36: 21.611332 | K36: 22.700723 | L36: 22.852112 | M36: 21.815499 | N36: 21.387721 | O36: 21.602112 | P36: 20.4565 | Q36: 19.591888 | R36: 20.399111 | S36: 19.003501 | T36: 18.201889 | U36: 14.774278 | V36: 14.769667 | W36: 15.874056 | X36: 23.102112 | Y36: 22.0185 | Z36: 21.091888 | AA36: 20.073699
F37: 41516 | J37: 21.769 | K37: 22.860167 | L37: 23.545333 | M37: 23.3245 | N37: 21.548167 | O37: 22.467332 | P37: 21.809501 | Q37: 21.494666 | R37: 21.280334 | S37: 20.403501 | T37: 19.807668 | U37: 16.132833 | V37: 16.006 | W37: 16.926168 | X37: 23.342332 | Y37: 23.184501 | Z37: 23.010667 | AA37: 21.11251
F38: 41547 | J38: 22.127333 | K38: 23.356723 | L38: 23.149111 | M38: 23.1125 | N38: 21.700723 | O38: 22.117111 | P38: 21.471499 | Q38: 21.013889 | R38: 20.69511 | S38: 19.878501 | T38: 19.201889 | U38: 15.540278 | V38: 15.832667 | W38: 17.343056 | X38: 22.78911 | Y38: 22.534501 | Z38: 22.794889 | AA38: 20.862288
F39: 41578 | J39: 21.814583 | K39: 22.840972 | L39: 22.539242 | M39: 22.721881 | N39: 21.153472 | O39: 21.539242 | P39: 20.815631 | Q39: 20.27952 | R39: 19.632992 | S39: 18.83125 | T39: 18.15452 | U39: 15.227778 | V39: 15.754167 | W39: 17.843056 | X39: 22.382992 | Y39: 22.096881 | Z39: 22.09202 | AA39: 20.336482
F40: 41607 | J40: 22.619798 | K40: 24.303825 | L40: 24.550353 | M40: 24.671881 | N40: 22.928825 | O40: 23.534722 | P40: 22.609381 | Q40: 21.605909 | R40: 21.753472 | S40: 20.6875 | T40: 19.605909 | U40: 16.993056 | V40: 17.380214 | W40: 19.282992 | X40: 23.409722 | Y40: 22.203131 | Z40: 22.387159 | AA40: 21.795756
F41: 41639 | J41: 22.885417 | K41: 24.897575 | L41: 25.800353 | M41: 26.296881 | N41: 23.506944 | O41: 24.940972 | P41: 24.734381 | Q41: 23.980909 | R41: 23.425353 | S41: 23.53125 | T41: 22.137159 | U41: 18.946187 | V41: 19.395833 | W41: 21.048611 | X41: 24.440972 | Y41: 23.671881 | Z41: 23.684028 | AA41: 23.372042
F42: 41670 | J42: 22.51875 | K42: 24.391667 | L42: 24.717714 | M42: 24.934381 | N42: 22.751048 | O42: 23.748964 | P42: 23.465631 | Q42: 22.822917 | R42: 22.373964 | S42: 22.028131 | T42: 21.338548 | U42: 19.320833 | V42: 19.44375 | W42: 20.957298 | X42: 23.592714 | Y42: 22.903131 | Z42: 23.041667 | AA42: 22.608889
F43: 41698 | J43: 22.565631 | K43: 24.579167 | L43: 25.123964 | M43: 25.246881 | N43: 23.016667 | O43: 24.170833 | P43: 23.934381 | Q43: 24.026048 | R43: 22.842714 | S43: 22.60625 | T43: 22.494798 | U43: 20.008333 | V43: 20.240631 | W43: 21.754167 | X43: 23.842714 | Y43: 23.403131 | Z43: 23.744798 | AA43: 23.153006
F44: 41729 | G44: 23.361464 | H44: 25.669103 | I44: 26.539242 | J44: 22.689583 | K44: 24.825353 | L44: 25.507992 | M44: 25.846881 | N44: 23.403472 | O44: 24.617361 | P44: 24.815631 | Q44: 24.857639 | R44: 23.461111 | S44: 23.45625 | T44: 23.43577 | U44: 20.790278 | V44: 20.769798 | W44: 21.796187 | X44: 24.320492 | Y44: 24.190631 | Z44: 24.763889 | AA44: 23.738136
...

Sheet CurrentCoupon
B3: Asof | C3: Coupon
B4: 42096 | C4: 2.6512827
B5: 42095 | C5: 2.5992658
B6: 42094 | C6: 2.6610352
B7: 42093 | C7: 2.6906214
B8: 42090 | C8: 2.6934832
B9: 42089 | C9: 2.7519991
B10: 42088 | C10: 2.6641694
B11: 42087 | C11: 2.6098467
B12: 42086 | C12: 2.6575095
B13: 42083 | C13: 2.6717729
B14: 42082 | C14: 2.7095566
B15: 42081 | C15: 2.6928489
... B1484: 39934 | C1484: 4.0858866
