Workbook
Name temp: CurrentCoupon!$B$3:$D$1080

Sheet Price D Coupon
G5: 3 | H5: 3 | I5: 3.5 | J5: 3.5 | K5: 3.5 | L5: 3.5 | M5: 4 | N5: 4 | O5: 4 | P5: 4 | Q5: 4 | R5: 4.5 | S5: 4.5 | T5: 4.5 | U5: 5 | V5: 5 | W5: 5.5 | X5: 6 | Y5: 6.5
F6: Px/coupon | AI6: Weight
F7: Date | G7: FN30. 300. 13 | H7: FN30. 300. 12 | I7: FN30. 350. 14 | J7: FN30. 350. 13 | K7: FN30. 350. 12 | L7: FN30. 350. 10 | M7: FN30. 400. 14 | N7: FN30. 400. 13 | O7: FN30. 400. 11 | P7: FN30. 400. 10 | Q7: FN30. 400. 09 | R7: FN30. 450. 11 | S7: FN30. 450. 10 | T7: FN30. 450. 09 | U7: FN30. 500. 10 | V7: FN30. 500. 09 | W7: FN30. 550. 08 | X7: FN30. 600. 08 | Y7: FN30. 650. 67 | Z7: GII30. 400. 10 | AA7: GII30. 450. 10 | AB7: GII30. 500. 10 | AC7: Avg | AE7: Date | AF7: Current Coupon | AI7: Date | AJ7: FN30. 300. 13 | AK7: FN30. 300. 12 | AL7: FN30. 350. 14 | AM7: FN30. 350. 13 | AN7: FN30. 350. 12 | AO7: FN30. 350. 10 | AP7: FN30. 400. 14 | AQ7: FN30. 400. 13 | AR7: FN30. 400. 11 | AS7: FN30. 400. 10 | AT7: FN30. 400. 09 | AU7: FN30. 450. 11 | AV7: FN30. 450. 10 | AW7: FN30. 450. 09 | AX7: FN30. 500. 10 | AY7: FN30. 500. 09 | AZ7: FN30. 550. 08 | BA7: FN30. 600. 08 | BB7: FN30. 650. 67 | BC7: Total
F8: 40633 | G8: =Price!G8/'Price D Coupon'!G$5 -> 8.27 | H8: =Price!H8/'Price D Coupon'!H$5 -> 8.6666667 | I8: =Price!I8/'Price D Coupon'!I$5 -> 6.9114286 | J8: =Price!J8/'Price D Coupon'!J$5 -> 7.48 | K8: =Price!K8/'Price D Coupon'!K$5 -> 6.9857143 | L8: =Price!L8/'Price D Coupon'!L$5 -> 7.42 | M8: =Price!M8/'Price D Coupon'!M$5 -> 6.04 | N8: =Price!N8/'Price D Coupon'!N$5 -> 5.1375 | ... Y8: =Price!Y8/'Price D Coupon'!Y$5 -> 0 | AC8: 23.785472 | AE8: =F8 -> 40633 | AF8: =VLOOKUP(AE8,CurrentCoupon!temp,3,0) -> #N/A | AI8: =F8 -> 40633 | AJ8: 0 | AK8: 0 | AL8: 0 | AM8: 0 | AN8: 0 | AO8: 0.02740631 | AP8: 0 | AQ8: 0 | AR8: 0 | AS8: 0.14046649 | AT8: 0.12948424 | AU8: 0 | AV8: 0.12975199 | AW8: 0.2882927 | AX8: 0.062968111 | AY8: 0.066411433 | AZ8: 0.070279501 | BA8: 0.036736393 | BB8: 0.048202832 | BC8: =SUM(AJ8:BB8) -> 1 | BE8: Date | BF8: Monthly Return (%)
F9: 40662 | G9: =Price!G9/'Price D Coupon'!G$5 -> 8.31 | H9: =Price!H9/'Price D Coupon'!H$5 -> 8.7533333 | I9: =Price!I9/'Price D Coupon'!I$5 -> 6.9571429 | J9: =Price!J9/'Price D Coupon'!J$5 -> 7.5285714 | K9: =Price!K9/'Price D Coupon'!K$5 -> 7.06 | L9: =Price!L9/'Price D Coupon'!L$5 -> 7.58 | M9: =Price!M9/'Price D Coupon'!M$5 -> 6.245 | N9: =Price!N9/'Price D Coupon'!N$5 -> 5.2175 | ... Y9: =Price!Y9/'Price D Coupon'!Y$5 -> 0 | AC9: 24.080744 | AE9: =F9 -> 40662 | AF9: =VLOOKUP(AE9,CurrentCoupon!temp,3,0) -> 4.0911415 | AI9: =F9 -> 40662 | AJ9: 0 | AK9: 0 | AL9: 0 | AM9: 0 | AN9: 0 | AO9: 0.027596454 | AP9: 0 | AQ9: 0 | AR9: 0 | AS9: 0.14136961 | AT9: 0.12997806 | AU9: 0 | AV9: 0.13033036 | AW9: 0.28862028 | AX9: 0.063100659 | AY9: 0.066274006 | AZ9: 0.069072966 | BA9: 0.036075726 | BB9: 0.047581877 | BC9: =SUM(AJ9:BB9) -> 1 | BE9: 40633 | BF9: =G8*AJ8 -> 0
F10: 40694 | G10: =Price!G10/'Price D Coupon'!G$5 -> 8.4733333 | H10: =Price!H10/'Price D Coupon'!H$5 -> 8.8733333 | I10: =Price!I10/'Price D Coupon'!I$5 -> 7.0485714 | J10: =Price!J10/'Price D Coupon'!J$5 -> 7.5828571 | K10: =Price!K10/'Price D Coupon'!K$5 -> 7.02 | L10: =Price!L10/'Price D Coupon'!L$5 -> 7.6057143 | M10: =Price!M10/'Price D Coupon'!M$5 -> 6.15 | N10: =Price!N10/'Price D Coupon'!N$5 -> 5.055 | ... Y10: =Price!Y10/'Price D Coupon'!Y$5 -> 0 | AC10: 24.186373 | AE10: =F10 -> 40694 | AF10: =VLOOKUP(AE10,CurrentCoupon!temp,3,0) -> 3.9323543 | AI10: =F10 -> 40694 | AJ10: 0 | AK10: 0 | AL10: 0 | AM10: 0 | AN10: 0 | AO10: 0.027772655 | AP10: 0 | AQ10: 0 | AR10: 0 | AS10: 0.14222877 | AT10: 0.13043914 | AU10: 0 | AV10: 0.13089219 | AW10: 0.2890731 | AX10: 0.063273705 | AY10: 0.066206835 | AZ10: 0.067961286 | BA10: 0.035405405 | BB10: 0.046746918 | BC10: =SUM(AJ10:BB10) -> 1 | BE10: 40662 | BF10: 0.01824177
F11: 40724 | G11: =Price!G11/'Price D Coupon'!G$5 -> 8.55 | H11: =Price!H11/'Price D Coupon'!H$5 -> 8.9633333 | I11: =Price!I11/'Price D Coupon'!I$5 -> 7.0314286 | J11: =Price!J11/'Price D Coupon'!J$5 -> 7.6914286 | K11: =Price!K11/'Price D Coupon'!K$5 -> 7.0228571 | L11: =Price!L11/'Price D Coupon'!L$5 -> 7.8085714 | M11: =Price!M11/'Price D Coupon'!M$5 -> 6.2325 | N11: =Price!N11/'Price D Coupon'!N$5 -> 5.0725 | ... Y11: =Price!Y11/'Price D Coupon'!Y$5 -> 0 | AC11: 24.450172 | AE11: =F11 -> 40724 | AF11: =VLOOKUP(AE11,CurrentCoupon!temp,3,0) -> 4.0210178 | AI11: =F11 -> 40724 | AJ11: 0 | AK11: 0 | AL11: 0 | AM11: 0 | AN11: 0 | AO11: 0.027926502 | AP11: 0 | AQ11: 0 | AR11: 0 | AS11: 0.14295239 | AT11: 0.13080465 | AU11: 0 | AV11: 0.13137858 | AW11: 0.28954874 | AX11: 0.063413193 | AY11: 0.06616714 | AZ11: 0.06697561 | BA11: 0.034766829 | BB11: 0.046066367 | BC11: =SUM(AJ11:BB11) -> 1 | BE11: 40694 | BF11: 0.0095136889
F12: 40753 | G12: =Price!G12/'Price D Coupon'!G$5 -> 8.31 | H12: =Price!H12/'Price D Coupon'!H$5 -> 8.5766667 | I12: =Price!I12/'Price D Coupon'!I$5 -> 6.6628571 | J12: =Price!J12/'Price D Coupon'!J$5 -> 7.1628571 | K12: =Price!K12/'Price D Coupon'!K$5 -> 6.48 | L12: =Price!L12/'Price D Coupon'!L$5 -> 7.2542857 | M12: =Price!M12/'Price D Coupon'!M$5 -> 5.715 | N12: =Price!N12/'Price D Coupon'!N$5 -> 4.8375 | ... Y12: =Price!Y12/'Price D Coupon'!Y$5 -> 0 | AC12: 23.116972 | AE12: =F12 -> 40753 | AF12: =VLOOKUP(AE12,CurrentCoupon!temp,3,0) -> 3.8088239 | AI12: =F12 -> 40753 | AJ12: 0 | AK12: 0 | AL12: 0 | AM12: 0 | AN12: 0 | AO12: 0.028075952 | AP12: 0 | AQ12: 0 | AR12: 0 | AS12: 0.14365704 | AT12: 0.13116041 | AU12: 0 | AV12: 0.13186399 | AW12: 0.28990557 | AX12: 0.063549087 | AY12: 0.066127746 | AZ12: 0.06605268 | BA12: 0.034214858 | BB12: 0.045392667 | BC12: =SUM(AJ12:BB12) -> 1 | BE12: 40724 | BF12: 0.014594354
F13: 40786 | G13: =Price!G13/'Price D Coupon'!G$5 -> 7.3533333 | H13: =Price!H13/'Price D Coupon'!H$5 -> 7.09 | I13: =Price!I13/'Price D Coupon'!I$5 -> 5.5257143 | J13: =Price!J13/'Price D Coupon'!J$5 -> 5.3 | K13: =Price!K13/'Price D Coupon'!K$5 -> 4.8171429 | L13: =Price!L13/'Price D Coupon'!L$5 -> 5.5942857 | M13: =Price!M13/'Price D Coupon'!M$5 -> 4.355 | N13: =Price!N13/'Price D Coupon'!N$5 -> 4.0175 | ... Y13: =Price!Y13/'Price D Coupon'!Y$5 -> 0 | AC13: 18.855772 | AE13: =F13 -> 40786 | AF13: =VLOOKUP(AE13,CurrentCoupon!temp,3,0) -> 3.4273948 | AI13: =F13 -> 40786 | AJ13: 0 | AK13: 0 | AL13: 0 | AM13: 0 | AN13: 0 | AO13: 0.028268828 | AP13: 0 | AQ13: 0 | AR13: 0 | AS13: 0.14449103 | AT13: 0.13161044 | AU13: 0 | AV13: 0.13233924 | AW13: 0.289819 | AX13: 0.063677522 | AY13: 0.065940194 | AZ13: 0.065193394 | BA13: 0.033758086 | BB13: 0.044902263 | BC13: =SUM(AJ13:BB13) -> 1 | BE13: 40753 | BF13: -0.056499118
F14: 40816 | G14: =Price!G14/'Price D Coupon'!G$5 -> 6.14 | H14: =Price!H14/'Price D Coupon'!H$5 -> 5.64 | I14: =Price!I14/'Price D Coupon'!I$5 -> 4.2685714 | J14: =Price!J14/'Price D Coupon'!J$5 -> 4.3342857 | K14: =Price!K14/'Price D Coupon'!K$5 -> 3.8028571 | L14: =Price!L14/'Price D Coupon'!L$5 -> 4.7657143 | M14: =Price!M14/'Price D Coupon'!M$5 -> 3.585 | N14: =Price!N14/'Price D Coupon'!N$5 -> 3.2675 | ... Y14: =Price!Y14/'Price D Coupon'!Y$5 -> 0 | AC14: 15.498617 | AE14: =F14 -> 40816 | AF14: =VLOOKUP(AE14,CurrentCoupon!temp,3,0) -> 3.0385262 | AI14: =F14 -> 40816 | AJ14: 0 | AK14: 0 | AL14: 0 | AM14: 0 | AN14: 0 | AO14: 0.028492304 | AP14: 0 | AQ14: 0 | AR14: 0 | AS14: 0.14538344 | AT14: 0.13200486 | AU14: 0 | AV14: 0.13281236 | AW14: 0.28945244 | AX14: 0.063769571 | AY14: 0.065782077 | AZ14: 0.064422398 | BA14: 0.033367229 | BB14: 0.04451333 | BC14: =SUM(AJ14:BB14) -> 1 | BE14: 40786 | BF14: -0.20415555
F15: 40847 | G15: =Price!G15/'Price D Coupon'!G$5 -> 6.0366667 | H15: =Price!H15/'Price D Coupon'!H$5 -> 5.5666667 | I15: =Price!I15/'Price D Coupon'!I$5 -> 4.3628571 | J15: =Price!J15/'Price D Coupon'!J$5 -> 4.6742857 | K15: =Price!K15/'Price D Coupon'!K$5 -> 4.04 | L15: =Price!L15/'Price D Coupon'!L$5 -> 5.5028571 | M15: =Price!M15/'Price D Coupon'!M$5 -> 4.26 | N15: =Price!N15/'Price D Coupon'!N$5 -> 3.2475 | ... Y15: =Price!Y15/'Price D Coupon'!Y$5 -> 0 | AC15: 16.119872 | AE15: =F15 -> 40847 | AF15: =VLOOKUP(AE15,CurrentCoupon!temp,3,0) -> 3.251577 | AI15: =F15 -> 40847 | AJ15: 0 | AK15: 0 | AL15: 0 | AM15: 0 | AN15: 0 | AO15: 0.028725425 | AP15: 0 | AQ15: 0 | AR15: 0 | AS15: 0.14628268 | AT15: 0.13244363 | AU15: 0 | AV15: 0.13326506 | AW15: 0.28906694 | AX15: 0.063944654 | AY15: 0.065618839 | AZ15: 0.063584558 | BA15: 0.032958172 | BB15: 0.044110044 | BC15: =SUM(AJ15:BB15) -> 1 | BE15: 40816 | BF15: -0.18608869
F16: 40877 | G16: =Price!G16/'Price D Coupon'!G$5 -> 5.8933333 | H16: =Price!H16/'Price D Coupon'!H$5 -> 5.41 | I16: =Price!I16/'Price D Coupon'!I$5 -> 4.0914286 | J16: =Price!J16/'Price D Coupon'!J$5 -> 4.7828571 | K16: =Price!K16/'Price D Coupon'!K$5 -> 3.9514286 | L16: =Price!L16/'Price D Coupon'!L$5 -> 5.6914286 | M16: =Price!M16/'Price D Coupon'!M$5 -> 4.3425 | N16: =Price!N16/'Price D Coupon'!N$5 -> 3.4075 | ... Y16: =Price!Y16/'Price D Coupon'!Y$5 -> 0 | AC16: 16.294972 | AE16: =F16 -> 40877 | AF16: =VLOOKUP(AE16,CurrentCoupon!temp,3,0) -> 3.1770193 | AI16: =F16 -> 40877 | AJ16: 0 | AK16: 0 | AL16: 0 | AM16: 0 | AN16: 0 | AO16: 0.029113476 | AP16: 0 | AQ16: 0 | AR16: 0 | AS16: 0.14674367 | AT16: 0.13246171 | AU16: 0 | AV16: 0.13350213 | AW16: 0.28777046 | AX16: 0.064358005 | AY16: 0.06568972 | AZ16: 0.063254791 | BA16: 0.032898514 | BB16: 0.044207529 | BC16: =SUM(AJ16:BB16) -> 1 | BE16: 40847 | BF16: 0.052849339
F17: 40907 | G17: =Price!G17/'Price D Coupon'!G$5 -> 5.73 | H17: =Price!H17/'Price D Coupon'!H$5 -> 5.28 | I17: =Price!I17/'Price D Coupon'!I$5 -> 3.8971429 | J17: =Price!J17/'Price D Coupon'!J$5 -> 4.78 | K17: =Price!K17/'Price D Coupon'!K$5 -> 3.8657143 | L17: =Price!L17/'Price D Coupon'!L$5 -> 5.6714286 | M17: =Price!M17/'Price D Coupon'!M$5 -> 4.2325 | N17: =Price!N17/'Price D Coupon'!N$5 -> 3.22 | ... Y17: =Price!Y17/'Price D Coupon'!Y$5 -> 0 | AC17: 15.896817 | AE17: =F17 -> 40907 | AF17: =VLOOKUP(AE17,CurrentCoupon!temp,3,0) -> 3.0169009 | AI17: =F17 -> 40907 | AJ17: 0 | AK17: 0 | AL17: 0 | AM17: 0 | AN17: 0 | AO17: 0.029527009 | AP17: 0 | AQ17: 0 | AR17: 0 | AS17: 0.14725219 | AT17: 0.13222635 | AU17: 0 | AV17: 0.13390235 | AW17: 0.28593974 | AX17: 0.064909729 | AY17: 0.065805924 | AZ17: 0.063058815 | BA17: 0.032938146 | BB17: 0.044439745 | BC17: =SUM(AJ17:BB17) -> 1 | BE17: 40877 | BF17: -0.0070201413
F18: 40939 | G18: =Price!G18/'Price D Coupon'!G$5 -> 5.3533333 | H18: =Price!H18/'Price D Coupon'!H$5 -> 4.8466667 | I18: =Price!I18/'Price D Coupon'!I$5 -> 3.4342857 | J18: =Price!J18/'Price D Coupon'!J$5 -> 4.3542857 | K18: =Price!K18/'Price D Coupon'!K$5 -> 3.4742857 | L18: =Price!L18/'Price D Coupon'!L$5 -> 5.1285714 | M18: =Price!M18/'Price D Coupon'!M$5 -> 3.7775 | N18: =Price!N18/'Price D Coupon'!N$5 -> 3.1275 | ... Y18: =Price!Y18/'Price D Coupon'!Y$5 -> 0 | AC18: 14.673172 | AE18: =F18 -> 40939 | AF18: =VLOOKUP(AE18,CurrentCoupon!temp,3,0) -> 2.7762953 | AI18: =F18 -> 40939 | AJ18: 0 | AK18: 0 | AL18: 0 | AM18: 0 | AN18: 0 | AO18: 0.029942398 | AP18: 0 | AQ18: 0 | AR18: 0 | AS18: 0.14782151 | AT18: 0.13183303 | AU18: 0 | AV18: 0.13443017 | AW18: 0.28368873 | AX18: 0.065593518 | AY18: 0.065946486 | AZ18: 0.062894336 | BA18: 0.033040183 | BB18: 0.044809632 | BC18: =SUM(AJ18:BB18) -> 1 | BE18: 40907 | BF18: -0.027877514
F19: 40968 | G19: =Price!G19/'Price D Coupon'!G$5 -> 5.9666667 | H19: =Price!H19/'Price D Coupon'!H$5 -> 5.6133333 | I19: =Price!I19/'Price D Coupon'!I$5 -> 3.8942857 | J19: =Price!J19/'Price D Coupon'!J$5 -> 4.9171429 | K19: =Price!K19/'Price D Coupon'!K$5 -> 3.9285714 | L19: =Price!L19/'Price D Coupon'!L$5 -> 5.6514286 | M19: =Price!M19/'Price D Coupon'!M$5 -> 4.1625 | N19: =Price!N19/'Price D Coupon'!N$5 -> 3.355 | ... Y19: =Price!Y19/'Price D Coupon'!Y$5 -> 0 | AC19: 16.240573 | AE19: =F19 -> 40968 | AF19: =VLOOKUP(AE19,CurrentCoupon!temp,3,0) -> 2.8817315 | AI19: =F19 -> 40968 | AJ19: 0 | AK19: 0 | AL19: 0 | AM19: 0 | AN19: 0 | AO19: 0.030392644 | AP19: 0 | AQ19: 0 | AR19: 0 | AS19: 0.14898141 | AT19: 0.13169001 | AU19: 0 | AV19: 0.13497453 | AW19: 0.28152185 | AX19: 0.066073219 | AY19: 0.065906231 | AZ19: 0.062505841 | BA19: 0.032979696 | BB19: 0.044974565 | BC19: =SUM(AJ19:BB19) -> 1 | BE19: 40939 | BF19: -0.088730633
F20: 40998 | G20: =Price!G20/'Price D Coupon'!G$5 -> 6.5533333 | H20: =Price!H20/'Price D Coupon'!H$5 -> 6.7933333 | I20: =Price!I20/'Price D Coupon'!I$5 -> 5.38 | J20: =Price!J20/'Price D Coupon'!J$5 -> 4.4914286 | K20: =Price!K20/'Price D Coupon'!K$5 -> 5.9228571 | L20: =Price!L20/'Price D Coupon'!L$5 -> 5.3742857 | M20: =Price!M20/'Price D Coupon'!M$5 -> 3.8325 | N20: =Price!N20/'Price D Coupon'!N$5 -> 5.355 | ... Y20: =Price!Y20/'Price D Coupon'!Y$5 -> 0 | AC20: 18.199972 | AE20: =F20 -> 40998 | AF20: =VLOOKUP(AE20,CurrentCoupon!temp,3,0) -> 3.0669216 | AI20: =F20 -> 40998 | AJ20: 0 | AK20: 0 | AL20: 0 | AM20: 0 | AN20: 0 | AO20: 0.024725973 | AP20: 0 | AQ20: 0 | AR20: 0.095316183 | AS20: 0.12045299 | AT20: 0.10575842 | AU20: 0.10063007 | AV20: 0.10895323 | AW20: 0.22498873 | AX20: 0.05350766 | AY20: 0.0530391 | AZ20: 0.049932228 | BA20: 0.0264329 | BB20: 0.036262506 | BC20: =SUM(AJ20:BB20) -> 1 | BE20: 40968 | BF20: 0.1267261
F21: 41029 | G21: =Price!G21/'Price D Coupon'!G$5 -> 6.1033333 | H21: =Price!H21/'Price D Coupon'!H$5 -> 6.3566667 | I21: =Price!I21/'Price D Coupon'!I$5 -> 5.0114286 | J21: =Price!J21/'Price D Coupon'!J$5 -> 4.1457143 | K21: =Price!K21/'Price D Coupon'!K$5 -> 5.54 | L21: =Price!L21/'Price D Coupon'!L$5 -> 4.9828571 | M21: =Price!M21/'Price D Coupon'!M$5 -> 3.52 | N21: =Price!N21/'Price D Coupon'!N$5 -> 5.18 | ... Y21: =Price!Y21/'Price D Coupon'!Y$5 -> 0 | AC21: 17.266278 | AE21: =F21 -> 41029 | AF21: =VLOOKUP(AE21,CurrentCoupon!temp,3,0) -> 2.8585942 | AI21: =F21 -> 41029 | AJ21: 0 | AK21: 0 | AL21: 0 | AM21: 0 | AN21: 0 | AO21: 0.02498952 | AP21: 0 | AQ21: 0 | AR21: 0.096252094 | AS21: 0.12096088 | AT21: 0.10525104 | AU21: 0.10142706 | AV21: 0.10910633 | AW21: 0.22285725 | AX21: 0.053922533 | AY21: 0.053078509 | AZ21: 0.049455516 | BA21: 0.026337565 | BB21: 0.036361706 | BC21: =SUM(AJ21:BB21) -> 1 | BE21: 40998 | BF21: 0.10050254
... F43: 41698 | G43: =Price!G43/'Price D Coupon'!G$5 -> 7.5233333 | H43: =Price!H43/'Price D Coupon'!H$5 -> 8.1933333 | I43: =Price!I43/'Price D Coupon'!I$5 -> 6.5771429 | J43: =Price!J43/'Price D Coupon'!J$5 -> 7.1771429 | K43: =Price!K43/'Price D Coupon'!K$5 -> 6.9057143 | L43: =Price!L43/'Price D Coupon'!L$5 -> 6.5257143 | M43: =Price!M43/'Price D Coupon'!M$5 -> 6.3125 | N43: =Price!N43/'Price D Coupon'!N$5 -> 5.9825 | ... Y43: =Price!Y43/'Price D Coupon'!Y$5 -> 0 | AC43: 23.043605 | AE43: =F43 -> 41698 | AF43: =VLOOKUP(AE43,CurrentCoupon!temp,3,0) -> 3.3514862 | AI43: =F43 -> 41698 | AJ43: 0 | AK43: 0.19184365 | AL43: 0 | AM43: 0 | AN43: 0.23825886 | AO43: 0.016614291 | AP43: 0 | AQ43: 0 | AR43: 0.064985622 | AS43: 0.07514546 | AT43: 0.053572741 | AU43: 0.069537901 | AV43: 0.066686121 | AW43: 0.11131174 | AX43: 0.036160574 | AY43: 0.031281395 | AZ43: 0.017731279 | BA43: 0.010264369 | BB43: 0.016605998 | BC43: =SUM(AJ43:BB43) -> 1 | BE43: 41670 | BF43: -0.031266772
F44: 41729 | G44: =Price!G44/'Price D Coupon'!G$5 -> 7.7866667 | H44: =Price!H44/'Price D Coupon'!H$5 -> 7.5633333 | I44: =Price!I44/'Price D Coupon'!I$5 -> 7.3342857 | J44: =Price!J44/'Price D Coupon'!J$5 -> 7.0942857 | K44: =Price!K44/'Price D Coupon'!K$5 -> 6.6857143 | L44: =Price!L44/'Price D Coupon'!L$5 -> 7.3342857 | M44: =Price!M44/'Price D Coupon'!M$5 -> 6.3775 | N44: =Price!N44/'Price D Coupon'!N$5 -> 6.155 | ... Y44: =Price!Y44/'Price D Coupon'!Y$5 -> 0 | AC44: 23.82194 | AE44: =F44 -> 41729 | AF44: =VLOOKUP(AE44,CurrentCoupon!temp,3,0) -> 3.4468594 | AG44: =IF(AF44<$G$5,G44,(H44-G44)/0.5*(AF44-$G$5)+G44) -> 7.5870695 | AI44: =F44 -> 41729 | AJ44: 0.14015953 | AK44: 0.12877118 | AL44: 0 | AM44: 0.09835625 | AN44: 0.15976314 | AO44: 0.011122974 | AP44: 0 | AQ44: 0.093316082 | AR44: 0.04347176 | AS44: 0.050247243 | AT44: 0.035773151 | AU44: 0.046432933 | AV44: 0.04446765 | AW44: 0.074114286 | AX44: 0.024082135 | AY44: 0.02077472 | AZ44: 0.011604631 | BA44: 0.0067031661 | BB44: 0.010839164 | BC44: =SUM(AJ44:BB44) -> 1 | BE44: 41698 | BF44: 0.021801735
F45: 41759 | G45: =Price!G45/'Price D Coupon'!G$5 -> 7.7766667 | H45: =Price!H45/'Price D Coupon'!H$5 -> 7.57 | I45: =Price!I45/'Price D Coupon'!I$5 -> 7.2714286 | J45: =Price!J45/'Price D Coupon'!J$5 -> 7.0085714 | K45: =Price!K45/'Price D Coupon'!K$5 -> 6.5828571 | L45: =Price!L45/'Price D Coupon'!L$5 -> 7.2714286 | M45: =Price!M45/'Price D Coupon'!M$5 -> 6.3 | N45: =Price!N45/'Price D Coupon'!N$5 -> 6.0675 | ... Y45: =Price!Y45/'Price D Coupon'!Y$5 -> 0 | AC45: 23.537013 | AE45: =F45 -> 41759 | AF45: =VLOOKUP(AE45,CurrentCoupon!temp,3,0) -> 3.327427 | AG45: =IF(AF45<$G$5,G45,(H45-G45)/0.5*(AF45-$G$5)+G45) -> 7.6413302 | AI45: =F45 -> 41759 | AJ45: 0.14062117 | AK45: 0.12911479 | AL45: 0 | AM45: 0.09864385 | AN45: 0.16001339 | AO45: 0.011122388 | AP45: 0 | AQ45: 0.09352348 | AR45: 0.043464161 | AS45: 0.05021791 | AT45: 0.035710082 | AU45: 0.046333066 | AV45: 0.044342722 | AW45: 0.073778213 | AX45: 0.023949658 | AY45: 0.020624509 | AZ45: 0.011370895 | BA45: 0.0065605566 | BB45: 0.010609155 | BC45: =SUM(AJ45:BB45) -> 1 | BE45: 41729 | BF45: 0.021192307
F46: 41789 | G46: =Price!G46/'Price D Coupon'!G$5 -> 7.6766667 | H46: =Price!H46/'Price D Coupon'!H$5 -> 7.4933333 | I46: =Price!I46/'Price D Coupon'!I$5 -> 7.0742857 | J46: =Price!J46/'Price D Coupon'!J$5 -> 6.84 | K46: =Price!K46/'Price D Coupon'!K$5 -> 6.3857143 | L46: =Price!L46/'Price D Coupon'!L$5 -> 7.0742857 | M46: =Price!M46/'Price D Coupon'!M$5 -> 6.08 | N46: =Price!N46/'Price D Coupon'!N$5 -> 5.8375 | ... Y46: =Price!Y46/'Price D Coupon'!Y$5 -> 0 | AC46: 22.672183 | AE46: =F46 -> 41789 | AF46: =VLOOKUP(AE46,CurrentCoupon!temp,3,0) -> 3.132717 | AG46: =IF(AF46<$G$5,G46,(H46-G46)/0.5*(AF46-$G$5)+G46) -> 7.6280037 | AI46: =F46 -> 41789 | AJ46: 0.14116669 | AK46: 0.12953463 | AL46: 0 | AM46: 0.098992167 | AN46: 0.16034508 | AO46: 0.011125465 | AP46: 0 | AQ46: 0.093649008 | AR46: 0.043463751 | AS46: 0.050174575 | AT46: 0.03561943 | AU46: 0.046201625 | AV46: 0.044177838 | AW46: 0.073323978 | AX46: 0.023813256 | AY46: 0.020456558 | AZ46: 0.011149762 | BA46: 0.0064080309 | BB46: 0.010398151 | BC46: =SUM(AJ46:BB46) -> 1 | BE46: 41759 | BF46: -0.0078448557
F47: 41820 | G47: =Price!G47/'Price D Coupon'!G$5 -> 7.7033333 | H47: =Price!H47/'Price D Coupon'!H$5 -> 7.5066667 | I47: =Price!I47/'Price D Coupon'!I$5 -> 7.1657143 | J47: =Price!J47/'Price D Coupon'!J$5 -> 6.9371429 | K47: =Price!K47/'Price D Coupon'!K$5 -> 6.4857143 | L47: =Price!L47/'Price D Coupon'!L$5 -> 7.1657143 | M47: =Price!M47/'Price D Coupon'!M$5 -> 6.2275 | N47: =Price!N47/'Price D Coupon'!N$5 -> 6.0575 | ... Y47: =Price!Y47/'Price D Coupon'!Y$5 -> 0 | AC47: 23.378006 | AE47: =F47 -> 41820 | AF47: =VLOOKUP(AE47,CurrentCoupon!temp,3,0) -> 3.1600586 | AG47: =IF(AF47<$G$5,G47,(H47-G47)/0.5*(AF47-$G$5)+G47) -> 7.6403769 | AI47: =F47 -> 41820 | AJ47: 0.14171813 | AK47: 0.1299741 | AL47: 0 | AM47: 0.099321696 | AN47: 0.16063179 | AO47: 0.011132259 | AP47: 0 | AQ47: 0.093842231 | AR47: 0.04344704 | AS47: 0.050119115 | AT47: 0.035517133 | AU47: 0.046090472 | AV47: 0.044007694 | AW47: 0.07283799 | AX47: 0.023687647 | AY47: 0.020276544 | AZ47: 0.01092879 | BA47: 0.0062779745 | BB47: 0.010189405 | BC47: =SUM(AJ47:BB47) -> 1 | BE47: 41789 | BF47: -0.029344377
F48: 41851 | G48: =Price!G48/'Price D Coupon'!G$5 -> 7.6833333 | H48: =Price!H48/'Price D Coupon'!H$5 -> 7.4733333 | I48: =Price!I48/'Price D Coupon'!I$5 -> 7.12 | J48: =Price!J48/'Price D Coupon'!J$5 -> 6.9142857 | K48: =Price!K48/'Price D Coupon'!K$5 -> 6.5228571 | L48: =Price!L48/'Price D Coupon'!L$5 -> 7.12 | M48: =Price!M48/'Price D Coupon'!M$5 -> 6.2525 | N48: =Price!N48/'Price D Coupon'!N$5 -> 6.095 | ... Y48: =Price!Y48/'Price D Coupon'!Y$5 -> 0 | AC48: 23.745654 | AE48: =F48 -> 41851 | AF48: =VLOOKUP(AE48,CurrentCoupon!temp,3,0) -> 3.2761066 | AG48: =IF(AF48<$G$5,G48,(H48-G48)/0.5*(AF48-$G$5)+G48) -> 7.5673686 | AI48: =F48 -> 41851 | AJ48: 0.14230565 | AK48: 0.13040735 | AL48: 0 | AM48: 0.099654655 | AN48: 0.16091603 | AO48: 0.011133829 | AP48: 0 | AQ48: 0.094021309 | AR48: 0.043411461 | AS48: 0.050066548 | AT48: 0.035409749 | AU48: 0.045938062 | AV48: 0.043832975 | AW48: 0.072357057 | AX48: 0.023567107 | AY48: 0.02010048 | AZ48: 0.010733533 | BA48: 0.006156812 | BB48: 0.009987388 | BC48: =SUM(AJ48:BB48) -> 1 | BE48: 41820 | BF48: 0.027757435
F49: 41880 | G49: =Price!G49/'Price D Coupon'!G$5 -> 7.4766667 | H49: =Price!H49/'Price D Coupon'!H$5 -> 7.29 | I49: =Price!I49/'Price D Coupon'!I$5 -> 6.8228571 | J49: =Price!J49/'Price D Coupon'!J$5 -> 6.6314286 | K49: =Price!K49/'Price D Coupon'!K$5 -> 6.1885714 | L49: =Price!L49/'Price D Coupon'!L$5 -> 6.8228571 | M49: =Price!M49/'Price D Coupon'!M$5 -> 5.8575 | N49: =Price!N49/'Price D Coupon'!N$5 -> 5.7575 | ... Y49: =Price!Y49/'Price D Coupon'!Y$5 -> 0 | AC49: 22.581192 | AE49: =F49 -> 41880 | AF49: =VLOOKUP(AE49,CurrentCoupon!temp,3,0) -> 3.0803372 | AG49: =IF(AF49<$G$5,G49,(H49-G49)/0.5*(AF49-$G$5)+G49) -> 7.4466741 | AI49: =F49 -> 41880 | AJ49: 0.14298975 | AK49: 0.13095539 | AL49: 0 | AM49: 0.10006002 | AN49: 0.16127149 | AO49: 0.011131859 | AP49: 0 | AQ49: 0.093952745 | AR49: 0.043372777 | AS49: 0.049983064 | AT49: 0.035284097 | AU49: 0.04578056 | AV49: 0.043647075 | AW49: 0.071834871 | AX49: 0.023428339 | AY49: 0.019930638 | AZ49: 0.010528337 | BA49: 0.0060439662 | BB49: 0.0098050215 | BC49: =SUM(AJ49:BB49) -> 1 | BE49: 41851 | BF49: 0.0074645314
F50: 41912 | G50: =Price!G50/'Price D Coupon'!G$5 -> 7.61 | H50: =Price!H50/'Price D Coupon'!H$5 -> 7.4366667 | I50: =Price!I50/'Price D Coupon'!I$5 -> 6.9942857 | J50: =Price!J50/'Price D Coupon'!J$5 -> 6.8428571 | K50: =Price!K50/'Price D Coupon'!K$5 -> 6.4285714 | L50: =Price!L50/'Price D Coupon'!L$5 -> 6.9942857 | M50: =Price!M50/'Price D Coupon'!M$5 -> 6.1025 | N50: =Price!N50/'Price D Coupon'!N$5 -> 5.975 | ... Y50: =Price!Y50/'Price D Coupon'!Y$5 -> 0 | AC50: 23.630763 | AE50: =F50 -> 41912 | AF50: =VLOOKUP(AE50,CurrentCoupon!temp,3,0) -> 3.2078957 | AG50: =IF(AF50<$G$5,G50,(H50-G50)/0.5*(AF50-$G$5)+G50) -> 7.5379295 | AI50: =F50 -> 41912 | AJ50: 0.14373459 | AK50: 0.13153506 | AL50: 0 | AM50: 0.10044565 | AN50: 0.16169414 | AO50: 0.011141527 | AP50: 0 | AQ50: 0.093821049 | AR50: 0.043300392 | AS50: 0.049898277 | AT50: 0.035135695 | AU50: 0.045626976 | AV50: 0.043434667 | AW50: 0.071247425 | AX50: 0.023275456 | AY50: 0.019753502 | AZ50: 0.010365521 | BA50: 0.0059488495 | BB50: 0.0096412185 | BC50: =SUM(AJ50:BB50) -> 1 | BE50: 41880 | BF50: -0.047313023
F51: 41943 | G51: =Price!G51/'Price D Coupon'!G$5 -> 7.4866667 | H51: =Price!H51/'Price D Coupon'!H$5 -> 7.2966667 | I51: =Price!I51/'Price D Coupon'!I$5 -> 6.7514286 | J51: =Price!J51/'Price D Coupon'!J$5 -> 6.6085714 | K51: =Price!K51/'Price D Coupon'!K$5 -> 6.1571429 | L51: =Price!L51/'Price D Coupon'!L$5 -> 6.7514286 | M51: =Price!M51/'Price D Coupon'!M$5 -> 5.8075 | N51: =Price!N51/'Price D Coupon'!N$5 -> 5.6875 | ... Y51: =Price!Y51/'Price D Coupon'!Y$5 -> 0 | AC51: 22.531622 | AE51: =F51 -> 41943 | AF51: =VLOOKUP(AE51,CurrentCoupon!temp,3,0) -> 3.0097405 | AG51: =IF(AF51<$G$5,G51,(H51-G51)/0.5*(AF51-$G$5)+G51) -> 7.4829653 | AI51: =F51 -> 41943 | AJ51: 0.14443816 | AK51: 0.13206838 | AL51: 0 | AM51: 0.10079491 | AN51: 0.16203744 | AO51: 0.011135247 | AP51: 0 | AQ51: 0.093803749 | AR51: 0.043269447 | AS51: 0.049812968 | AT51: 0.035004964 | AU51: 0.045468912 | AV51: 0.043218243 | AW51: 0.07071713 | AX51: 0.023134329 | AY51: 0.019568962 | AZ51: 0.01018449 | BA51: 0.0058467279 | BB51: 0.0094959389 | BC51: =SUM(AJ51:BB51) -> 1 | BE51: 41912 | BF51: 0.043121935
F52: 41971 | G52: =Price!G52/'Price D Coupon'!G$5 -> 7.34 | H52: =Price!H52/'Price D Coupon'!H$5 -> 7.1633333 | I52: =Price!I52/'Price D Coupon'!I$5 -> 6.5228571 | J52: =Price!J52/'Price D Coupon'!J$5 -> 6.3914286 | K52: =Price!K52/'Price D Coupon'!K$5 -> 5.8971429 | L52: =Price!L52/'Price D Coupon'!L$5 -> 6.5228571 | M52: =Price!M52/'Price D Coupon'!M$5 -> 5.5375 | N52: =Price!N52/'Price D Coupon'!N$5 -> 5.42 | ... Y52: =Price!Y52/'Price D Coupon'!Y$5 -> 0 | AC52: 21.730029 | AE52: =F52 -> 41971 | AF52: =VLOOKUP(AE52,CurrentCoupon!temp,3,0) -> 2.8456853 | AG52: =IF(AF52<$G$5,G52,(H52-G52)/0.5*(AF52-$G$5)+G52) -> 7.34 | AI52: =F52 -> 41971 | AJ52: 0.14515803 | AK52: 0.13265044 | AL52: 0 | AM52: 0.10116958 | AN52: 0.16244464 | AO52: 0.01114175 | AP52: 0 | AQ52: 0.093660938 | AR52: 0.043218251 | AS52: 0.04972537 | AT52: 0.034883358 | AU52: 0.045310101 | AV52: 0.042999053 | AW52: 0.070176318 | AX52: 0.022957063 | AY52: 0.019385706 | AZ52: 0.010016056 | BA52: 0.0057485049 | BB52: 0.009354846 | BC52: =SUM(AJ52:BB52) -> 1 | BE52: 41943 | BF52: -0.039672605
F53: 42004 | G53: =Price!G53/'Price D Coupon'!G$5 -> 7.0133333 | H53: =Price!H53/'Price D Coupon'!H$5 -> 6.95 | I53: =Price!I53/'Price D Coupon'!I$5 -> 6.1885714 | J53: =Price!J53/'Price D Coupon'!J$5 -> 6.2914286 | K53: =Price!K53/'Price D Coupon'!K$5 -> 5.7514286 | L53: =Price!L53/'Price D Coupon'!L$5 -> 6.1885714 | M53: =Price!M53/'Price D Coupon'!M$5 -> 5.4375 | N53: =Price!N53/'Price D Coupon'!N$5 -> 5.3175 | ... Y53: =Price!Y53/'Price D Coupon'!Y$5 -> 0 | AC53: 21.293508 | AE53: =F53 -> 42004 | AF53: =VLOOKUP(AE53,CurrentCoupon!temp,3,0) -> 2.8338661 | AG53: =IF(AF53<$G$5,G53,(H53-G53)/0.5*(AF53-$G$5)+G53) -> 7.0133333 | AI53: =F53 -> 42004 | AJ53: 0.14591158 | AK53: 0.13322884 | AL53: 0 | AM53: 0.10151672 | AN53: 0.16283379 | AO53: 0.011139471 | AP53: 0 | AQ53: 0.093517444 | AR53: 0.043181261 | AS53: 0.049636892 | AT53: 0.034774424 | AU53: 0.045154192 | AV53: 0.042787229 | AW53: 0.069639651 | AX53: 0.022783041 | AY53: 0.01919267 | AZ53: 0.0098399953 | BA53: 0.0056382197 | BB53: 0.0092245901 | BC53: =SUM(AJ53:BB53) -> 1 | BE53: 41971 | BF53: -0.033127567
F54: 42034 | G54: =Price!G54/'Price D Coupon'!G$5 -> 5.8933333 | H54: =Price!H54/'Price D Coupon'!H$5 -> 5.8533333 | I54: =Price!I54/'Price D Coupon'!I$5 -> 0 | J54: =Price!J54/'Price D Coupon'!J$5 -> 4.8942857 | K54: =Price!K54/'Price D Coupon'!K$5 -> 5.0742857 | L54: =Price!L54/'Price D Coupon'!L$5 -> 4.5457143 | M54: =Price!M54/'Price D Coupon'!M$5 -> 0 | N54: =Price!N54/'Price D Coupon'!N$5 -> 4.2825 | ... Y54: =Price!Y54/'Price D Coupon'!Y$5 -> 3.46 | AC54: 17.742956 | AE54: =F54 -> 42034 | AF54: =VLOOKUP(AE54,CurrentCoupon!temp,3,0) -> 2.4526688 | AG54: =IF(AF54<$G$5,G54,(H54-G54)/0.5*(AF54-$G$5)+G54) -> 5.8933333 | AI54: =F54 -> 42034 | AJ54: 0.1467089 | AK54: 0.1338754 | AL54: 0 | AM54: 0.10176797 | AN54: 0.1633136 | AO54: 0.011157228 | AP54: 0 | AQ54: 0.092870263 | AR54: 0.043174954 | AS54: 0.049576038 | AT54: 0.034657797 | AU54: 0.045038886 | AV54: 0.042605814 | AW54: 0.069138471 | AX54: 0.022670742 | AY54: 0.019042072 | AZ54: 0.0097161724 | BA54: 0.0055692771 | BB54: 0.0091164247 | BC54: =SUM(AJ54:BB54) -> 1 | BE54: 42004 | BF54: -0.026017102
F55: 42062 | G55: =Price!G55/'Price D Coupon'!G$5 -> 6.58 | H55: =Price!H55/'Price D Coupon'!H$5 -> 6.5233333 | I55: =Price!I55/'Price D Coupon'!I$5 -> 0 | J55: =Price!J55/'Price D Coupon'!J$5 -> 5.7285714 | K55: =Price!K55/'Price D Coupon'!K$5 -> 5.8314286 | L55: =Price!L55/'Price D Coupon'!L$5 -> 5.3628571 | M55: =Price!M55/'Price D Coupon'!M$5 -> 0 | N55: =Price!N55/'Price D Coupon'!N$5 -> 5.0125 | ... Y55: =Price!Y55/'Price D Coupon'!Y$5 -> 3.7938462 | AC55: 20.530641 | AE55: =F55 -> 42062 | AF55: =VLOOKUP(AE55,CurrentCoupon!temp,3,0) -> 2.7365986 | AG55: =IF(AF55<$G$5,G55,(H55-G55)/0.5*(AF55-$G$5)+G55) -> 6.58 | AI55: =F55 -> 42062 | AJ55: 0.147653 | AK55: 0.13465479 | AL55: 0 | AM55: 0.10210331 | AN55: 0.16389333 | AO55: 0.011178399 | AP55: 0 | AQ55: 0.092170981 | AR55: 0.043127725 | AS55: 0.049492497 | AT55: 0.034505449 | AU55: 0.044865757 | AV55: 0.042362049 | AW55: 0.068507645 | AX55: 0.022522098 | AY55: 0.018883043 | AZ55: 0.0095794762 | BA55: 0.0054880754 | BB55: 0.0090123686 | BC55: =SUM(AJ55:BB55) -> 1 | BE55: 42034 | BF55: -0.18730149
F56: 42094 | G56: =Price!G56/'Price D Coupon'!G$5 -> 6.4233333 | H56: =Price!H56/'Price D Coupon'!H$5 -> 6.3766667 | I56: =Price!I56/'Price D Coupon'!I$5 -> 4.7542857 | J56: =Price!J56/'Price D Coupon'!J$5 -> 5.5485714 | K56: =Price!K56/'Price D Coupon'!K$5 -> 5.6771429 | L56: =Price!L56/'Price D Coupon'!L$5 -> 5.2314286 | M56: =Price!M56/'Price D Coupon'!M$5 -> 4.4825 | N56: =Price!N56/'Price D Coupon'!N$5 -> 4.855 | ... Y56: =Price!Y56/'Price D Coupon'!Y$5 -> 3.9861538 | AC56: 19.969247 | AE56: =F56 -> 42094 | AF56: =VLOOKUP(AE56,CurrentCoupon!temp,3,0) -> 2.6610352 | AG56: =IF(AF56<$G$5,G56,(H56-G56)/0.5*(AF56-$G$5)+G56) -> 6.4233333 | AI56: =F56 -> 42094 | AJ56: 0.14849148 | AK56: 0.1353443 | AL56: 0 | AM56: 0.10231681 | AN56: 0.16435025 | AO56: 0.011190124 | AP56: 0 | AQ56: 0.091594999 | AR56: 0.043110237 | AS56: 0.049415117 | AT56: 0.034341268 | AU56: 0.044714081 | AV56: 0.042190048 | AW56: 0.067955841 | AX56: 0.022388694 | AY56: 0.018764085 | AZ56: 0.0094829009 | BA56: 0.0054262526 | BB56: 0.0089235168 | BC56: =SUM(AJ56:BB56) -> 1 | BE56: 42062 | BF56: 0.16728926
F57: 42124 | G57: =Price!G57/'Price D Coupon'!G$5 -> 6.71 | H57: =Price!H57/'Price D Coupon'!H$5 -> 6.64 | I57: =Price!I57/'Price D Coupon'!I$5 -> 5.5571429 | J57: =Price!J57/'Price D Coupon'!J$5 -> 5.9 | K57: =Price!K57/'Price D Coupon'!K$5 -> 5.9942857 | L57: =Price!L57/'Price D Coupon'!L$5 -> 5.5514286 | M57: =Price!M57/'Price D Coupon'!M$5 -> 4.8625 | N57: =Price!N57/'Price D Coupon'!N$5 -> 5.1625 | ... Y57: =Price!Y57/'Price D Coupon'!Y$5 -> 4.1169231 | AC57: 21.080266 | AE57: =F57 -> 42124 | AF57: =VLOOKUP(AE57,CurrentCoupon!temp,3,0) -> 2.7480147 | AG57: =IF(AF57<$G$5,G57,(H57-G57)/0.5*(AF57-$G$5)+G57) -> 6.71 | AI57: =F57 -> 42124 | AJ57: 0.12423967 | AK57: 0.11316002 | AL57: 0.065143517 | AM57: 0.084910023 | AN57: 0.13692327 | AO57: 0.0092723001 | AP57: 0.10517165 | AQ57: 0.074925706 | AR57: 0.035687714 | AS57: 0.040903895 | AT57: 0.028249893 | AU57: 0.037025462 | AV57: 0.034861126 | AW57: 0.055879071 | AX57: 0.018510317 | AY57: 0.015493011 | AZ57: 0.0078094838 | BA57: 0.0044720981 | BB57: 0.0073617784 | BC57: =SUM(AJ57:BB57) -> 1
F58: 42153 | G58: =Price!G58/'Price D Coupon'!G$5 -> 6.73 | H58: =Price!H58/'Price D Coupon'!H$5 -> 6.6033333 | I58: =Price!I58/'Price D Coupon'!I$5 -> 5.8628571 | J58: =Price!J58/'Price D Coupon'!J$5 -> 6.0514286 | K58: =Price!K58/'Price D Coupon'!K$5 -> 6.0257143 | L58: =Price!L58/'Price D Coupon'!L$5 -> 5.6057143 | M58: =Price!M58/'Price D Coupon'!M$5 -> 5.13 | N58: =Price!N58/'Price D Coupon'!N$5 -> 5.295 | ... Y58: =Price!Y58/'Price D Coupon'!Y$5 -> 4.0569231 | AC58: 22.080266 | AE58: =F58 -> 42153 | AF58: =VLOOKUP(AE58,CurrentCoupon!temp,3,0) -> 2.8125589 | AI58: =F58 -> 42153 | AJ58: 0.12572491 | AK58: 0.11440387 | AL58: 0.064891298 | AM58: 0.085184799 | AN58: 0.13772832 | AO58: 0.0092726415 | AP58: 0.10452851 | AQ58: 0.073838407 | AR58: 0.035574654 | AS58: 0.040704536 | AT58: 0.02797973 | AU58: 0.036917105 | AV58: 0.034665704 | AW58: 0.055241854 | AX58: 0.018443405 | AY58: 0.015403647 | AZ58: 0.0077284877 | BA58: 0.0044400971 | BB58: 0.0073280297 | BC58: =SUM(AJ58:BB58) -> 1
F59: 42185 | G59: =Price!G59/'Price D Coupon'!G$5 -> 7.0933333 | H59: =Price!H59/'Price D Coupon'!H$5 -> 6.95 | I59: =Price!I59/'Price D Coupon'!I$5 -> 6.7171429 | J59: =Price!J59/'Price D Coupon'!J$5 -> 6.6371429 | K59: =Price!K59/'Price D Coupon'!K$5 -> 6.5114286 | L59: =Price!L59/'Price D Coupon'!L$5 -> 6.1342857 | M59: =Price!M59/'Price D Coupon'!M$5 -> 5.8775 | N59: =Price!N59/'Price D Coupon'!N$5 -> 5.8075 | ... Y59: =Price!Y59/'Price D Coupon'!Y$5 -> 4.1876923 | AC59: 23.080266 | AE59: =F59 -> 42185 | AF59: =VLOOKUP(AE59,CurrentCoupon!temp,3,0) -> 3.0732804 | AI59: =F59 -> 42185 | AJ59: 0.12678695 | AK59: 0.11532294 | AL59: 0.064927038 | AM59: 0.085499811 | AN59: 0.13825039 | AO59: 0.0092660239 | AP59: 0.10430482 | AQ59: 0.073277879 | AR59: 0.035456813 | AS59: 0.040529201 | AT59: 0.027703885 | AU59: 0.036717726 | AV59: 0.034408628 | AW59: 0.054618212 | AX59: 0.01832071 | AY59: 0.015284585 | AZ59: 0.0076473588 | BA59: 0.0043982432 | BB59: 0.007278789 | BC59: =SUM(AJ59:BB59) -> 1
F60: 42216 | G60: =Price!G60/'Price D Coupon'!G$5 -> 6.9066667 | H60: =Price!H60/'Price D Coupon'!H$5 -> 6.7366667 | I60: =Price!I60/'Price D Coupon'!I$5 -> 6.3342857 | J60: =Price!J60/'Price D Coupon'!J$5 -> 6.3885714 | K60: =Price!K60/'Price D Coupon'!K$5 -> 6.2628571 | L60: =Price!L60/'Price D Coupon'!L$5 -> 5.8571429 | M60: =Price!M60/'Price D Coupon'!M$5 -> 5.5425 | N60: =Price!N60/'Price D Coupon'!N$5 -> 5.59 | ... Y60: =Price!Y60/'Price D Coupon'!Y$5 -> 4.1707692 | AC60: 24.080266 | AE60: =F60 -> 42216 | AF60: =VLOOKUP(AE60,CurrentCoupon!temp,3,0) -> 2.9155081 | AI60: =F60 -> 42216 | AJ60: 0.12772296 | AK60: 0.11613134 | AL60: 0.064959658 | AM60: 0.085765656 | AN60: 0.13866824 | AO60: 0.0092606069 | AP60: 0.10418188 | AQ60: 0.072856605 | AR60: 0.035344316 | AS60: 0.040369113 | AT60: 0.027459824 | AU60: 0.036558359 | AV60: 0.034177569 | AW60: 0.054036209 | AX60: 0.018193765 | AY60: 0.015148787 | AZ60: 0.0075678071 | BA60: 0.0043576778 | BB60: 0.007239622 | BC60: =SUM(AJ60:BB60) -> 1
F61: 42247 | G61: =Price!G61/'Price D Coupon'!G$5 -> 6.95 | H61: =Price!H61/'Price D Coupon'!H$5 -> 6.76 | I61: =Price!I61/'Price D Coupon'!I$5 -> 6.3114286 | J61: =Price!J61/'Price D Coupon'!J$5 -> 6.3514286 | K61: =Price!K61/'Price D Coupon'!K$5 -> 6.24 | L61: =Price!L61/'Price D Coupon'!L$5 -> 5.8171429 | M61: =Price!M61/'Price D Coupon'!M$5 -> 5.5225 | N61: =Price!N61/'Price D Coupon'!N$5 -> 5.5575 | ... Y61: =Price!Y61/'Price D Coupon'!Y$5 -> 4.1615385 | AC61: 24.080266 | AE61: =F61 -> 42247 | AF61: =VLOOKUP(AE61,CurrentCoupon!temp,3,0) -> #N/A | AI61: =F61 -> 42247 | AJ61: 0.12772296 | AK61: 0.11613134 | AL61: 0.064959658 | AM61: 0.085765656 | AN61: 0.13866824 | AO61: 0.0092606069 | AP61: 0.10418188 | AQ61: 0.072856605 | AR61: 0.035344316 | AS61: 0.040369113 | AT61: 0.027459824 | AU61: 0.036558359 | AV61: 0.034177569 | AW61: 0.054036209 | AX61: 0.018193765 | AY61: 0.015148787 | AZ61: 0.0075678071 | BA61: 0.0043576778 | BB61: 0.007239622 | BC61: =SUM(AJ61:BB61) -> 1
F62: 42277 | G62: =Price!G62/'Price D Coupon'!G$5 -> 6.7766667 | H62: =Price!H62/'Price D Coupon'!H$5 -> 6.5933333 | I62: =Price!I62/'Price D Coupon'!I$5 -> 5.9857143 | J62: =Price!J62/'Price D Coupon'!J$5 -> 6.12 | K62: =Price!K62/'Price D Coupon'!K$5 -> 6.0171429 | L62: =Price!L62/'Price D Coupon'!L$5 -> 5.5514286 | M62: =Price!M62/'Price D Coupon'!M$5 -> 5.2375 | N62: =Price!N62/'Price D Coupon'!N$5 -> 5.355 | ... Y62: =Price!Y62/'Price D Coupon'!Y$5 -> 4.0461538 | AC62: 24.080266 | AE62: =F62 -> 42277 | AF62: =VLOOKUP(AE62,CurrentCoupon!temp,3,0) -> #N/A | AI62: 42277 | AJ62: 0.12919628 | AK62: 0.11738741 | AL62: 0.065560709 | AM62: 0.086272954 | AN62: 0.139202 | AO62: 0.009255837 | AP62: 0.10431996 | AQ62: 0.072339114 | AR62: 0.035101492 | AS62: 0.040034355 | AT62: 0.027077082 | AU62: 0.036168606 | AV62: 0.03364021 | AW62: 0.052933918 | AX62: 0.01787747 | AY62: 0.014877037 | AZ62: 0.007358487 | BA62: 0.004263108 | BB62: 0.007133965 | BC62: =SUM(AJ62:BB62) -> 1
F63: 42307 | G63: =Price!G63/'Price D Coupon'!G$5 -> 6.8055556 | H63: =Price!H63/'Price D Coupon'!H$5 -> 6.6440992 | I63: =Price!I63/'Price D Coupon'!I$5 -> 5.6493073 | J63: =Price!J63/'Price D Coupon'!J$5 -> 6.0823413 | K63: =Price!K63/'Price D Coupon'!K$5 -> 6.0153787 | L63: =Price!L63/'Price D Coupon'!L$5 -> 5.5734127 | M63: =Price!M63/'Price D Coupon'!M$5 -> 5.2274306 | N63: =Price!N63/'Price D Coupon'!N$5 -> 5.3220486 | ... Y63: =Price!Y63/'Price D Coupon'!Y$5 -> 4.0940171 | AC63: 25.080266 | AE63: =F63 -> 42307 | AI63: 42307 | AJ63: 0.12976281 | AK63: 0.117865 | AL63: 0.065868953 | AM63: 0.086467604 | AN63: 0.13940283 | AO63: 0.0092574447 | AP63: 0.10436448 | AQ63: 0.07216283 | AR63: 0.035025929 | AS63: 0.039928897 | AT63: 0.026964805 | AU63: 0.03600221 | AV63: 0.033433781 | AW63: 0.052489573 | AX63: 0.017738765 | AY63: 0.014729515 | AZ63: 0.007262384 | BA63: 0.0042107499 | BB63: 0.0070614359 | BC63: =SUM(AJ63:BB63) -> 1
AI66: Weighted Average Px
AI67: Date | AJ67: FN30. 300. 13 | AK67: FN30. 300. 12 | AL67: FN30. 350. 14 | AM67: FN30. 350. 13 | AN67: FN30. 350. 12 | AO67: FN30. 350. 10 | AP67: FN30. 400. 14 | AQ67: FN30. 400. 13 | AR67: FN30. 400. 11 | AS67: FN30. 400. 10 | AT67: FN30. 400. 09 | AU67: FN30. 450. 11 | AV67: FN30. 450. 10 | AW67: FN30. 450. 09 | AX67: FN30. 500. 10 | AY67: FN30. 500. 09 | AZ67: FN30. 550. 08 | BA67: FN30. 600. 08 | BB67: FN30. 650. 67 | BC67: Total
...

Sheet Price
G5: 3 | H5: 3.5 | I5: 4 | J5: 3 | K5: 3.5 | L5: 4 | M5: 4.5 | N5: 3.5 | O5: 4 | P5: 4.5 | Q5: 5 | R5: 4 | S5: 4.5 | T5: 5 | U5: 5.5 | V5: 6 | W5: 6.5 | X5: 4 | Y5: 4.5 | Z5: 5
F6: IOS Price (%)
F7: Date | G7: FN30. 300. 13 | H7: FN30. 300. 12 | I7: FN30. 350. 14 | J7: FN30. 350. 13 | K7: FN30. 350. 12 | L7: FN30. 350. 10 | M7: FN30. 400. 14 | N7: FN30. 400. 13 | O7: FN30. 400. 11 | P7: FN30. 400. 10 | Q7: FN30. 400. 09 | R7: FN30. 450. 11 | S7: FN30. 450. 10 | T7: FN30. 450. 09 | U7: FN30. 500. 10 | V7: FN30. 500. 09 | W7: FN30. 550. 08 | X7: FN30. 600. 08 | Y7: FN30. 650. 67 | Z7: GII30. 400. 10 | AA7: GII30. 450. 10 | AB7: GII30. 500. 10 | AC7: Avg
F8: 40633 | G8: 24.81 | H8: 26 | I8: 24.19 | J8: 26.18 | K8: 24.45 | L8: 25.97 | M8: 24.16 | N8: 20.55 | O8: 20.22 | P8: 21.33 | Q8: 23.79 | AC8: 23.785472
F9: 40662 | G9: 24.93 | H9: 26.26 | I9: 24.35 | J9: 26.35 | K9: 24.71 | L9: 26.53 | M9: 24.98 | N9: 20.87 | O9: 20.38 | P9: 21.45 | Q9: 24.08 | AC9: 24.080744
F10: 40694 | G10: 25.42 | H10: 26.62 | I10: 24.67 | J10: 26.54 | K10: 24.57 | L10: 26.62 | M10: 24.6 | N10: 20.22 | O10: 20.48 | P10: 22.13 | Q10: 24.19 | AC10: 24.186373
F11: 40724 | G11: 25.65 | H11: 26.89 | I11: 24.61 | J11: 26.92 | K11: 24.58 | L11: 27.33 | M11: 24.93 | N11: 20.29 | O11: 20.84 | P11: 22.46 | Q11: 24.45 | AC11: 24.450172
F12: 40753 | G12: 24.93 | H12: 25.73 | I12: 23.32 | J12: 25.07 | K12: 22.68 | L12: 25.39 | M12: 22.86 | N12: 19.35 | O12: 20 | P12: 21.84 | Q12: 23.12 | AC12: 23.116972
F13: 40786 | G13: 22.06 | H13: 21.27 | I13: 19.34 | J13: 18.55 | K13: 16.86 | L13: 19.58 | M13: 17.42 | N13: 16.07 | O13: 17.44 | P13: 19.97 | Q13: 18.86 | AC13: 18.855772
F14: 40816 | G14: 18.42 | H14: 16.92 | I14: 14.94 | J14: 15.17 | K14: 13.31 | L14: 16.68 | M14: 14.34 | N14: 13.07 | O14: 14.69 | P14: 17.44 | Q14: 15.5 | AC14: 15.498617
F15: 40847 | G15: 18.11 | H15: 16.7 | I15: 15.27 | J15: 16.36 | K15: 14.14 | L15: 19.26 | M15: 17.04 | N15: 12.99 | O15: 14.44 | P15: 16.87 | Q15: 16.12 | AC15: 16.119872
F16: 40877 | G16: 17.68 | H16: 16.23 | I16: 14.32 | J16: 16.74 | K16: 13.83 | L16: 19.92 | M16: 17.37 | N16: 13.63 | O16: 15.47 | P16: 17.75 | Q16: 16.29 | AC16: 16.294972
F17: 40907 | G17: 17.19 | H17: 15.84 | I17: 13.64 | J17: 16.73 | K17: 13.53 | L17: 19.85 | M17: 16.93 | N17: 12.88 | O17: 15.01 | P17: 17.36 | Q17: 15.9 | AC17: 15.896817
F18: 40939 | G18: 16.06 | H18: 14.54 | I18: 12.02 | J18: 15.24 | K18: 12.16 | L18: 17.95 | M18: 15.11 | N18: 12.51 | O18: 14.3 | P18: 16.84 | Q18: 14.67 | AC18: 14.673172
F19: 40968 | G19: 17.9 | H19: 16.84 | I19: 13.63 | J19: 17.21 | K19: 13.75 | L19: 19.78 | M19: 16.65 | N19: 13.42 | O19: 15.46 | P19: 17.77 | Q19: 16.24 | AC19: 16.240573
F20: 40998 | G20: 19.66 | H20: 20.38 | I20: 18.83 | J20: 15.72 | K20: 20.73 | L20: 18.81 | M20: 15.33 | N20: 21.42 | O20: 18.51 | P20: 14.12 | Q20: 16.3 | R20: 18.58 | S20: 18.2 | AC20: 18.199972
F21: 41029 | G21: 18.31 | H21: 19.07 | I21: 17.54 | J21: 14.51 | K21: 19.39 | L21: 17.44 | M21: 14.08 | N21: 20.72 | O21: 17.86 | P21: 13.54 | Q21: 15.63 | R21: 19.11 | S21: 17.27 | AC21: 17.266278
F22: 41060 | G22: 15.42 | H22: 16.71 | I22: 15.02 | J22: 11.9 | K22: 17.24 | L22: 15.27 | M22: 12.13 | N22: 18.75 | O22: 15.98 | P22: 12.18 | Q22: 14.19 | R22: 18.31 | S22: 15.26 | AC22: 15.258528
F23: 41089 | G23: 15.84 | H23: 16.41 | I23: 15.43 | J23: 12.52 | K23: 17.33 | L23: 15.77 | M23: 12.97 | N23: 19.04 | O23: 16.39 | P23: 12.31 | Q23: 14.07 | R23: 17.85 | S23: 15.49 | AC23: 15.491805
F24: 41121 | G24: 13.83 | H24: 15.23 | I24: 14.71 | J24: 12.21 | K24: 17.61 | L24: 15.82 | M24: 13.13 | N24: 18.94 | O24: 16.25 | P24: 12.27 | Q24: 13.89 | R24: 18.11 | S24: 15.17 | AC24: 15.166111
F25: 41152 | G25: 14.95 | H25: 16.51 | I25: 15.81 | J25: 13.24 | K25: 18.54 | L25: 16.53 | M25: 14.06 | N25: 19.84 | O25: 17.51 | P25: 12.76 | Q25: 14.46 | R25: 18.3 | S25: 16.04 | AC25: 16.041528
F26: 41180 | G26: 11.73 | H26: 13.77 | I26: 13.15 | J26: 11.23 | K26: 16.02 | L26: 14.39 | M26: 12.43 | N26: 18.87 | O26: 16.7 | P26: 11.74 | Q26: 13.91 | R26: 17.66 | S26: 14.3 | AC26: 14.300194
F27: 41213 | G27: 11.86 | H27: 13.9 | I27: 13.4 | J27: 11.24 | K27: 16.6 | L27: 15.08 | M27: 12.83 | N27: 18.72 | O27: 16.75 | P27: 12.35 | Q27: 14.58 | R27: 17.91 | S27: 14.6 | AC27: 14.601111
F28: 41243 | G28: 12.03 | H28: 13.86 | I28: 13.12 | J28: 10.84 | K28: 15.45 | L28: 14.43 | M28: 12.06 | N28: 17.45 | O28: 15.32 | P28: 11.3 | Q28: 13.63 | R28: 16.82 | S28: 13.86 | AC28: 13.860417
F29: 41274 | G29: 12.24 | H29: 14.24 | I29: 13.3 | J29: 11.32 | K29: 16.09 | L29: 14.92 | M29: 12.84 | N29: 17.82 | O29: 15.65 | P29: 11.99 | Q29: 14.3 | R29: 17.33 | S29: 14.34 | AC29: 14.338306
F30: 41305 | G30: 14.81 | H30: 16.38 | I30: 15.37 | J30: 13.07 | K30: 17.47 | L30: 16.19 | M30: 13.64 | N30: 18.12 | O30: 15.92 | P30: 12.09 | Q30: 13.89 | R30: 16.69 | S30: 15.3 | AC30: 15.303944
F31: 41333 | G31: 15.12 | H31: 16.07 | I31: 15.2 | J31: 13.07 | K31: 17.32 | L31: 16.1 | M31: 13.63 | N31: 17.9 | O31: 16.06 | P31: 12.34 | Q31: 13.89 | R31: 16.33 | S31: 15.25 | AC31: 15.251944
F32: 41361 | G32: 19.03 | H32: 19.26 | I32: 16.47 | J32: 17.15 | K32: 16.23 | L32: 14.02 | M32: 17.86 | N32: 16.8 | O32: 14.36 | P32: 18.33 | Q32: 16.64 | R32: 12.67 | S32: 14.25 | T32: 16.08 | U32: 16.37 | AC32: 16.367671
F33: 41394 | G33: 17.58 | H33: 16.79 | I33: 13.72 | J33: 15.1 | K33: 13.87 | L33: 11.26 | M33: 15.64 | N33: 14.02 | O33: 11.75 | P33: 15.95 | Q33: 14.65 | R33: 11.04 | S33: 12.66 | T33: 14.45 | U33: 14.18 | AC33: 14.178028
F34: 41425 | G34: 20.35 | H34: 20.39 | I34: 18.19 | J34: 19.14 | K34: 17.7 | L34: 15.84 | M34: 18.5 | N34: 16.67 | O34: 15.01 | P34: 16.17 | Q34: 14.82 | R34: 11.7 | S34: 12.15 | T34: 13.97 | U34: 16.47 | AC34: 16.471012
F35: 41453 | G35: 20.83 | H35: 21.18 | I35: 19.64 | J35: 21.01 | K35: 20.02 | L35: 18.62 | M35: 20.77 | N35: 19.69 | O35: 18.24 | P35: 18.69 | Q35: 17.39 | R35: 13.27 | S35: 13.61 | T35: 14.87 | U35: 18.42 | AC35: 18.416742
F36: 41486 | G36: 21.61 | H36: 22.7 | I36: 21.39 | J36: 22.85 | K36: 21.6 | L36: 20.4 | M36: 21.82 | N36: 20.46 | O36: 19 | P36: 19.59 | Q36: 18.2 | R36: 14.77 | S36: 14.77 | T36: 15.87 | U36: 19.65 | AC36: 19.645742
F37: 41516 | G37: 21.77 | H37: 22.86 | I37: 21.55 | J37: 23.55 | K37: 22.47 | L37: 21.28 | M37: 23.32 | N37: 21.81 | O37: 20.4 | P37: 21.49 | Q37: 19.81 | R37: 16.13 | S37: 16.01 | T37: 16.93 | U37: 20.67 | AC37: 20.669655
F38: 41547 | G38: 22.13 | H38: 23.36 | I38: 21.7 | J38: 23.15 | K38: 22.12 | L38: 20.7 | M38: 23.11 | N38: 21.47 | O38: 19.88 | P38: 21.01 | Q38: 19.2 | R38: 15.54 | S38: 15.83 | T38: 17.34 | U38: 20.47 | AC38: 20.467171
F39: 41578 | G39: 21.81 | H39: 22.84 | I39: 21.15 | J39: 22.54 | K39: 21.54 | L39: 19.63 | M39: 22.72 | N39: 20.82 | O39: 18.83 | P39: 20.28 | Q39: 18.15 | R39: 15.23 | S39: 15.75 | T39: 17.84 | U39: 19.94 | AC39: 19.939165
F40: 41607 | G40: 22.62 | H40: 24.3 | I40: 22.93 | J40: 24.55 | K40: 23.53 | L40: 21.75 | M40: 24.67 | N40: 22.61 | O40: 20.69 | P40: 21.61 | Q40: 19.61 | R40: 16.99 | S40: 17.38 | T40: 19.28 | U40: 21.61 | AC40: 21.609131
F41: 41639 | G41: 22.89 | H41: 24.9 | I41: 23.51 | J41: 25.8 | K41: 24.94 | L41: 23.43 | M41: 26.3 | N41: 24.73 | O41: 23.53 | P41: 23.98 | Q41: 22.14 | R41: 18.95 | S41: 19.4 | T41: 21.05 | U41: 23.25 | AC41: 23.251988
F42: 41670 | G42: 22.52 | H42: 24.39 | I42: 22.75 | J42: 24.72 | K42: 23.75 | L42: 22.37 | M42: 24.93 | N42: 23.47 | O42: 22.03 | P42: 22.82 | Q42: 21.34 | R42: 19.32 | S42: 19.44 | T42: 20.96 | U42: 22.49 | AC42: 22.486685
F43: 41698 | G43: 22.57 | H43: 24.58 | I43: 23.02 | J43: 25.12 | K43: 24.17 | L43: 22.84 | M43: 25.25 | N43: 23.93 | O43: 22.61 | P43: 24.03 | Q43: 22.49 | R43: 20.01 | S43: 20.24 | T43: 21.75 | U43: 23.04 | AC43: 23.043605
F44: 41729 | G44: 23.36 | H44: 22.69 | I44: 25.67 | J44: 24.83 | K44: 23.4 | L44: 25.67 | M44: 25.51 | N44: 24.62 | O44: 23.46 | P44: 25.85 | Q44: 24.82 | R44: 23.46 | S44: 24.86 | T44: 23.44 | U44: 20.79 | V44: 20.77 | W44: 21.8 | X44: 23.82 | AC44: 23.82194
...

Sheet CurrentCoupon
B3: 42216 | C3: FN_CMM_30Yr | D3: 2.9155081
B4: 42215 | C4: FN_CMM_30Yr | D4: 2.9944455
B5: 42214 | C5: FN_CMM_30Yr | D5: 2.9952167
B6: 42213 | C6: FN_CMM_30Yr | D6: 2.9700274
B7: 42212 | C7: FN_CMM_30Yr | D7: 2.976882
B8: 42209 | C8: FN_CMM_30Yr | D8: 3.0088074
B9: 42208 | C9: FN_CMM_30Yr | D9: 3.0015244
B10: 42207 | C10: FN_CMM_30Yr | D10: 3.0272723
B11: 42206 | C11: FN_CMM_30Yr | D11: 3.0409986
B12: 42205 | C12: FN_CMM_30Yr | D12: 3.0702686
B13: 42202 | C13: FN_CMM_30Yr | D13: 3.050865
B14: 42201 | C14: FN_CMM_30Yr | D14: 3.0642371
... B1102: 40613 | C1102: FN_CMM_30Yr | D1102: 4.213995
