Workbook

Sheet Distribution of data
A1: count() | B1: bucket | I1: count() | J1: tag | K1: loansize | L1: fico | M1: lien | N1: invest | O1: cltv | P1: state | Q1: asOf | R1: Ticker | S1: Orig Date | T1: wala | U1: TPO | V1: butnout | X1: burnout adj
A2: 1096925 | B2: 'Done' | C2: <= 417 >= 740 no lien no invest cltv <= 80
A3: 466351 | B3: 'FICO' | I3: =SUM('Burnout 2016 Corres+CW'!AR3:AR36) -> 5900556 | J3: Burnout | K3: (175,417] | L3: [740,860] | M3: no | N3: no | O3: (0,80] | P3: not in ('NY','PR') | Q3: [20160401,20161201] | R3: All 4 | S3: post HARP | U3: CORRES, CASHWINDOW | V3: [0,2000]
A4: 230769 | B4: '2nd Lien' | I4: =SUM('Burnout 2016 Corres+CW'!AR123:AR148) -> 352957 | J4: Burnout | K4: (175,417] | L4: [740,860] | M4: no | N4: no | O4: (0,80] | P4: not in ('NY','PR') | Q4: [20160401,20161201] | R4: All 4 | S4: post HARP | U4: CORRES, CASHWINDOW | V4: (2000,4000]
A5: 144409 | B5: 'INV' | I5: =SUM('Burnout 2016 Corres+CW'!AR216:AR235) -> 222544 | J5: Burnout | K5: (175,417] | L5: [740,860] | M5: no | N5: no | O5: (0,80] | P5: not in ('NY','PR') | Q5: [20160401,20161201] | R5: All 4 | S5: post HARP | U5: CORRES, CASHWINDOW | V5: (4000,6000]
A6: 124596 | B6: 'CLTV' | I6: =SUM('Burnout 2016 Corres+CW'!AR302:AR313) -> 71951 | J6: Burnout | K6: (175,417] | L6: [740,860] | M6: no | N6: no | O6: (0,80] | P6: not in ('NY','PR') | Q6: [20160401,20161201] | R6: All 4 | S6: post HARP | U6: CORRES, CASHWINDOW | V6: (6000,8000]
A7: 57525 | B7: 'Jumbo' | I7: =SUM('Burnout 2016 Broker'!AR3:AR35) -> 973220 | J7: Burnout | K7: (175,417] | L7: [740,860] | M7: no | N7: no | O7: (0,80] | P7: not in ('NY','PR') | Q7: [20160401,20161201] | R7: All 4 | S7: post HARP | U7: Broker | V7: [0,2000]
A8: 2 | B8: 'Not Done' | I8: =SUM('Burnout 2016 Broker'!AR123:AR144) -> 60198 | J8: Burnout | K8: (175,417] | L8: [740,860] | M8: no | N8: no | O8: (0,80] | P8: not in ('NY','PR') | Q8: [20160401,20161201] | R8: All 4 | S8: post HARP | U8: Broker | V8: (2000,4000]
I9: =SUM('Burnout 2016 Broker'!AR205:AR223) -> 51888 | J9: Burnout | K9: (175,417] | L9: [740,860] | M9: no | N9: no | O9: (0,80] | P9: not in ('NY','PR') | Q9: [20160401,20161201] | R9: All 4 | S9: post HARP | U9: Broker | V9: (4000,6000]
A10: =SUM(A2:A8) -> 2120577 | B10: total | I10: =SUM('Burnout 2016 Broker'!AR279:AR289) -> 16460 | J10: Burnout | K10: (175,417] | L10: [740,860] | M10: no | N10: no | O10: (0,80] | P10: not in ('NY','PR') | Q10: [20160401,20161201] | R10: All 4 | S10: post HARP | U10: Broker | V10: (6000,8000]
I11: =SUM('Burnout 2016 NonCW'!AR3:AR36) -> 1415021 | J11: Burnout | K11: (175,417] | L11: [740,860] | M11: no | N11: no | O11: (0,80] | P11: not in ('NY','PR') | Q11: [20160401,20161201] | R11: All 4 | S11: post HARP | U11: NonCashWindow | V11: [0,2000]
I12: =SUM('Burnout 2016 NonCW'!AR123:AR148) -> 320886 | J12: Burnout | K12: (175,417] | L12: [740,860] | M12: no | N12: no | O12: (0,80] | P12: not in ('NY','PR') | Q12: [20160401,20161201] | R12: All 4 | S12: post HARP | U12: NonCashWindow | V12: (2000,4000] | X12: 1.15
I13: =SUM('Burnout 2016 NonCW'!AR214:AR233) -> 221665 | J13: Burnout | K13: (175,417] | L13: [740,860] | M13: no | N13: no | O13: (0,80] | P13: not in ('NY','PR') | Q13: [20160401,20161201] | R13: All 4 | S13: post HARP | U13: NonCashWindow | V13: (4000,6000] | X13: 1.2
I14: =SUM('Burnout 2016 NonCW'!AR292:AR302) -> 79327 | J14: Burnout | K14: (175,417] | L14: [740,860] | M14: no | N14: no | O14: (0,80] | P14: not in ('NY','PR') | Q14: [20160401,20161201] | R14: All 4 | S14: post HARP | U14: NonCashWindow | V14: (6000,8000] | X14: 1.05

Sheet Baseline
A1: WALA [12,24) | C1: CORRES+CASHWINDOW | F1: low media | AS1: tover | AT1: cash | AW1: refi
A2: modelId | B2: SFACTOR_PREPAY_TRACKING_CPR | C2: PREPAY_CPR1 | D2: PREPAY_TRACKING_CPR1 | E2: PREPAY_SMM1 | F2: PREPAY_TRACKING_SMM1 | G2: PCT_LOANTYPE | H2: _ORIGNOTERATE | I2: _ZEROSATO | J2: _SATO | K2: _REFI_INCENTIVE_Fixed | L2: _Fixed_cost | M2: _LOANAGE | N2: _LTV | O2: _CLTV | P2: _AVG_LOANSIZE_SCHAMBALANCE | Q2: _WACLS | R2: _FICO | S2: PCT_ISSECONDLIEN | T2: _OrigCombLTV | U2: PCT_SVC | V2: PCT_TPO | W2: PCT_GEO | X2: PCT_LOANPURPOSE | Y2: PCT_OCC | Z2: curtailsmm | AA2: defaultsmm | AB2: toverSmm | AC2: cashoutSmm | AD2: refiSmm | AE2: cumHPA | AF2: cumHPA05Pct | AG2: cumHPA15Pct | AH2: cumHPA20Pct | AI2: cumHPA25Pct | AJ2: cumHPA30Pct | AK2: cumHPA35Pct | AL2: cumHPA40Pct | AM2: adjtoverSmm | AN2: adjRefiSmm | AO2: groupByColumn | AP2: curve | AQ2: Balance | AR2: LoanCount | AS2: PCT_BROKER | AT2: PCT_CORRES | AU2: PCT_NonRETAIL | AV2: PCT_RETAIL | AW2: PCT_CashWindow | AX2: PCT_NonCashWindow
A3: 97 | B3: 0.98839691 | C3: 96.635073 | D3: 13.068622 | E3: 0.24621417 | F3: 0.011603087 | G3: 0 | H3: 3.4287964 | I3: 3.9170498 | J3: -60.571903 | K3: -108.57802 | L3: 100 | M3: 13.372006 | N3: 76.773096 | O3: 12.785692 | P3: 34194.875 | Q3: 31481.298 | R3: 792.65593 | S3: 0 | T3: 0 | U3: 0.060023573 | V3: 0.43037133 | W3: 0 | X3: 0.060023573 | Y3: 0 | Z3: 0.0055161513 | AA3: 1.2412019e-05 | AB3: 0.0060745137 | AC3: 0 | AD3: 0 | AE3: 0.059792222 | AF3: 0.39695938 | AG3: 1 | AH3: 1 | AI3: 1 | AJ3: 1 | AK3: 1 | AL3: 1 | AM3: 0 | AN3: 0 | AO3: 04:-125--100 | AP3: =-125--100 -> -25 | AQ3: 188887.79 | AR3: 6 | AS3: 0 | AT3: 56.962867 | AU3: 56.962867 | AV3: 43.037133 | AW3: 43.037133 | AX3: 0
A4: 97 | B4: 0.98844184 | C4: 49.843412 | D4: 13.021188 | E4: 0.055879709 | F4: 0.011558155 | G4: 0 | H4: 3.4420778 | I4: 3.9164769 | J4: -59.517626 | K4: -81.597641 | L4: 68.465589 | M4: 14.548948 | N4: 71.385986 | O4: 24.934341 | P4: 117969.24 | Q4: 40852.783 | R4: 786.04463 | S4: 0 | T4: 0 | U4: 0.027485084 | V4: 0.68664472 | W4: 0 | X4: 0.058346254 | Y4: 0 | Z4: 0.0043983283 | AA4: 3.4939807e-05 | AB4: 0.007099851 | AC4: 3.07944e-06 | AD4: 2.1947121e-05 | AE4: 0.092113583 | AF4: 0.20636363 | AG4: 0.92741588 | AH4: 1 | AI4: 1 | AJ4: 1 | AK4: 1 | AL4: 1 | AM4: 0 | AN4: 0 | AO4: 05:-100--75 | AP4: =-100--75 -> -25 | AQ4: 6005359.1 | AR4: 147 | AS4: 0 | AT4: 31.335528 | AU4: 31.335528 | AV4: 68.664472 | AW4: 68.664472 | AX4: 0
A5: 97 | B5: 0.99124721 | C5: 38.81742 | D5: 10.012176 | E5: 0.040115492 | F5: 0.0087527875 | G5: 0 | H5: 3.4962707 | I5: 3.8952664 | J5: -53.707825 | K5: -57.582086 | L5: 45.414254 | M5: 15.142775 | N5: 73.296276 | O5: 43.30325 | P5: 173908.24 | Q5: 63191.424 | R5: 782.07674 | S5: 0 | T5: 0 | U5: 0.054816654 | V5: 0.72447447 | W5: 0 | X5: 0.21958318 | Y5: 0 | Z5: 0.0023777527 | AA5: 3.843875e-05 | AB5: 0.0061975188 | AC5: 2.517301e-06 | AD5: 0.00013654951 | AE5: 0.087867306 | AF5: 0.19207694 | AG5: 0.95406742 | AH5: 0.99472364 | AI5: 1 | AJ5: 1 | AK5: 1 | AL5: 1 | AM5: 0 | AN5: 0 | AO5: 06:-75--50 | AP5: =-75--50 -> -25 | AQ5: 43286126 | AR5: 685 | AS5: 0 | AT5: 27.552553 | AU5: 27.552553 | AV5: 72.447447 | AW5: 72.447447 | AX5: 0
A6: 97 | B6: 0.99390274 | C6: 9.3616256 | D6: 7.0762609 | E6: 0.0081575869 | F6: 0.0060972558 | G6: 0 | H6: 3.4645783 | I6: 3.9281772 | J6: -54.768892 | K6: -31.153905 | L6: 18.985438 | M6: 14.446285 | N6: 73.016693 | O6: 63.087717 | P6: 251793.26 | Q6: 201489.6 | R6: 781.12105 | S6: 0 | T6: 0 | U6: 0.05384346 | V6: 0.61549503 | W6: 0 | X6: 0.51591271 | Y6: 0 | Z6: 0.00053383381 | AA6: 3.2372878e-05 | AB6: 0.0050501465 | AC6: 9.784867e-07 | AD6: 0.00047990951 | AE6: 0.08095162 | AF6: 0.19860855 | AG6: 0.95610793 | AH6: 0.99846457 | AI6: 1 | AJ6: 1 | AK6: 1 | AL6: 1 | AM6: 0 | AN6: 0 | AO6: 07:-50--25 | AP6: =-50--25 -> -25 | AQ6: 1.3604578e+09 | AR6: 6752 | AS6: 0 | AT6: 38.450497 | AU6: 38.450497 | AV6: 61.549503 | AW6: 61.549503 | AX6: 0
A7: 97 | B7: 0.99378325 | C7: 7.416952 | D7: 7.2102337 | E7: 0.0064014336 | F7: 0.006216748 | G7: 0 | H7: 3.524119 | I7: 3.9299141 | J7: -48.414066 | K7: -22.221985 | L7: 16.498899 | M7: 14.36346 | N7: 73.1865 | O7: 65.100598 | P7: 268436.49 | Q7: 239394.87 | R7: 780.93529 | S7: 0 | T7: 0 | U7: 0.068865837 | V7: 0.6104547 | W7: 0 | X7: 0.5618934 | Y7: 0 | Z7: 0.00040143177 | AA7: 3.2732743e-05 | AB7: 0.0049308652 | AC7: 7.3330338e-07 | AD7: 0.00085097056 | AE7: 0.08062327 | AF7: 0.16681883 | AG7: 0.96699982 | AH7: 0.99933097 | AI7: 1 | AJ7: 1 | AK7: 1 | AL7: 1 | AM7: 0 | AN7: 0 | AO7: 08-1:-25--20 | AP7: =-25--20 -> -5 | AQ7: 1.5658819e+09 | AR7: 6541 | AS7: 0 | AT7: 38.95453 | AU7: 38.95453 | AV7: 61.04547 | AW7: 61.04547 | AX7: 0
A8: 97 | B8: 0.99345355 | C8: 4.8879394 | D8: 7.5789684 | E8: 0.0041674922 | F8: 0.0065464462 | G8: 0 | H8: 3.5557883 | I8: 3.9208747 | J8: -45.581681 | K8: -17.210662 | L8: 15.961582 | M8: 14.483489 | N8: 71.60487 | O8: 63.81283 | P8: 272723.21 | Q8: 249028.12 | R8: 781.78181 | S8: 0 | T8: 0 | U8: 0.078276983 | V8: 0.60553234 | W8: 0 | X8: 0.54899391 | Y8: 0 | Z8: 0.00038737513 | AA8: 3.3488465e-05 | AB8: 0.0050609118 | AC8: 9.2107342e-07 | AD8: 0.0010637355 | AE8: 0.082238649 | AF8: 0.16530941 | AG8: 0.96394511 | AH8: 0.99885027 | AI8: 1 | AJ8: 1 | AK8: 1 | AL8: 1 | AM8: 0 | AN8: 0 | AO8: 08-2:-20--15 | AP8: =-20--15 -> -5 | AQ8: 2.7221264e+09 | AR8: 10931 | AS8: 0 | AT8: 39.446766 | AU8: 39.446766 | AV8: 60.553234 | AW8: 60.553234 | AX8: 0
A9: 97 | B9: 0.99328989 | C9: 8.259733 | D9: 7.7615092 | E9: 0.0071583219 | F9: 0.0067101086 | G9: 0 | H9: 3.5954185 | I9: 3.9147199 | J9: -41.886543 | K9: -12.281778 | L9: 15.428091 | M9: 14.550842 | N9: 72.17644 | O9: 64.441153 | P9: 279936.8 | Q9: 258280.9 | R9: 781.46676 | S9: 0 | T9: 0 | U9: 0.087735292 | V9: 0.60964009 | W9: 0 | X9: 0.54254679 | Y9: 0 | Z9: 0.00037560677 | AA9: 3.3985792e-05 | AB9: 0.0050442272 | AC9: 1.084469e-06 | AD9: 0.0012551902 | AE9: 0.083439747 | AF9: 0.14859681 | AG9: 0.96165329 | AH9: 0.99909455 | AI9: 1 | AJ9: 1 | AK9: 1 | AL9: 1 | AM9: 0 | AN9: 0 | AO9: 08-3:-15--10 | AP9: =-15--10 -> -5 | AQ9: 4.5837111e+09 | AR9: 17747 | AS9: 0 | AT9: 39.035991 | AU9: 39.035991 | AV9: 60.964009 | AW9: 60.964009 | AX9: 0
A10: 97 | B10: 0.99296879 | C10: 7.9191916 | D10: 8.1186917 | E10: 0.0068517227 | F10: 0.007031212 | G10: 0 | H10: 3.6231364 | I10: 3.8984104 | J10: -39.585383 | K10: -7.4062628 | L10: 15.296341 | M10: 14.911876 | N10: 71.109777 | O10: 63.291883 | P10: 281675.24 | Q10: 260533.88 | R10: 781.48996 | S10: 0 | T10: 0 | U10: 0.091236558 | V10: 0.60130514 | W10: 0 | X10: 0.55636662 | Y10: 0 | Z10: 0.00037442918 | AA10: 3.4860008e-05 | AB10: 0.0051831359 | AC10: 1.5032299e-06 | AD10: 0.0014372692 | AE10: 0.086115169 | AF10: 0.14110782 | AG10: 0.95021425 | AH10: 0.99893123 | AI10: 1 | AJ10: 1 | AK10: 1 | AL10: 1 | AM10: 0 | AN10: 0 | AO10: 08-4:-10--5 | AP10: =-10--5 -> -5 | AQ10: 6.6326715e+09 | AR10: 25458 | AS10: 0 | AT10: 39.869486 | AU10: 39.869486 | AV10: 60.130514 | AW10: 60.130514 | AX10: 0
A11: 97 | B11: 0.99281459 | C11: 8.6514849 | D11: 8.2897601 | E11: 0.0075123203 | F11: 0.0071854061 | G11: 0 | H11: 3.6551722 | I11: 3.8826854 | J11: -36.811228 | K11: -2.3916674 | L11: 15.050831 | M11: 15.210302 | N11: 71.233243 | O11: 63.416485 | P11: 286027.38 | Q11: 264953.55 | R11: 781.41774 | S11: 0 | T11: 0 | U11: 0.092835681 | V11: 0.59536817 | W11: 0 | X11: 0.56119432 | Y11: 0 | Z11: 0.00037069367 | AA11: 3.581818e-05 | AB11: 0.0051417377 | AC11: 1.8486999e-06 | AD11: 0.0016352936 | AE11: 0.087190228 | AF11: 0.13675479 | AG11: 0.95105333 | AH11: 0.99888108 | AI11: 1 | AJ11: 1 | AK11: 1 | AL11: 1 | AM11: 0 | AN11: 0 | AO11: 08:-25-0 | AP11: =-25-0 -> -25 | AQ11: 9.7982474e+09 | AR11: 36981 | AS11: 0 | AT11: 40.463183 | AU11: 40.463183 | AV11: 59.536817 | AW11: 59.536817 | AX11: 0
A12: 97 | B12: 0.99252654 | C12: 9.6587779 | D12: 8.6085537 | E12: 0.0084289694 | F12: 0.0074734586 | G12: 0 | H12: 3.6936876 | I12: 3.8737928 | J12: -33.806205 | K12: 2.6121767 | L12: 15.059416 | M12: 15.398367 | N12: 71.20197 | O12: 63.30499 | P12: 284835.16 | Q12: 264994.1 | R12: 781.44475 | S12: 0 | T12: 0 | U12: 0.099676388 | V12: 0.6006954 | W12: 0 | X12: 0.56479509 | Y12: 0 | Z12: 0.0003703554 | AA12: 3.6686619e-05 | AB12: 0.0052090767 | AC12: 3.0870021e-06 | AD12: 0.0018542384 | AE12: 0.089425468 | AF12: 0.1246349 | AG12: 0.94265683 | AH12: 0.99742834 | AI12: 1 | AJ12: 1 | AK12: 1 | AL12: 1 | AM12: 0 | AN12: 0 | AO12: 09-1:0-5 | AP12: 0-5 | AQ12: 1.2626439e+10 | AR12: 47648 | AS12: 0 | AT12: 39.93046 | AU12: 39.93046 | AV12: 60.06954 | AW12: 60.06954 | AX12: 0
A13: 97 | B13: 0.99219486 | C13: 11.895024 | D13: 8.9743772 | E13: 0.010497939 | F13: 0.0078051429 | G13: 0 | H13: 3.7178014 | I13: 3.8530514 | J13: -32.195354 | K13: 7.6142859 | L13: 14.558583 | M13: 15.821745 | N13: 70.946759 | O13: 62.934601 | P13: 293115.39 | Q13: 274145.15 | R13: 781.38453 | S13: 0 | T13: 0 | U13: 0.1010385 | V13: 0.60196444 | W13: 0 | X13: 0.55814045 | Y13: 0 | Z13: 0.00037043941 | AA13: 3.8612944e-05 | AB13: 0.0052327257 | AC13: 4.0688358e-06 | AD13: 0.0021592816 | AE13: 0.091144609 | AF13: 0.12017603 | AG13: 0.93715128 | AH13: 0.99640248 | AI13: 1 | AJ13: 1 | AK13: 1 | AL13: 1 | AM13: 0 | AN13: 0 | AO13: 09-2:5-10 | AP13: 43230 | AQ13: 1.600432e+10 | AR13: 58379 | AS13: 0 | AT13: 39.803556 | AU13: 39.803556 | AV13: 60.196444 | AW13: 60.196444 | AX13: 0
A14: 97 | B14: 0.99187172 | C14: 13.619226 | D14: 9.3294821 | E14: 0.012126299 | F14: 0.0081282798 | G14: 0 | H14: 3.7551712 | I14: 3.8414164 | J14: -29.577044 | K14: 12.555816 | L14: 14.66393 | M14: 16.07843 | N14: 70.781193 | O14: 62.654426 | P14: 292854.45 | Q14: 272182.21 | R14: 781.20433 | S14: 0 | T14: 0 | U14: 0.11061444 | V14: 0.5989312 | W14: 0 | X14: 0.57020664 | Y14: 0 | Z14: 0.00037059973 | AA14: 4.1935797e-05 | AB14: 0.005219016 | AC14: 5.8672202e-06 | AD14: 0.0024908466 | AE14: 0.093267643 | AF14: 0.11238082 | AG14: 0.92893431 | AH14: 0.99520282 | AI14: 1 | AJ14: 1 | AK14: 1 | AL14: 1 | AM14: 0 | AN14: 0 | AO14: 09-3:10-15 | AP14: 43388 | AQ14: 1.7351616e+10 | AR14: 63750 | AS14: 0 | AT14: 40.10688 | AU14: 40.10688 | AV14: 59.89312 | AW14: 59.89312 | AX14: 0
A15: 97 | B15: 0.99145545 | C15: 12.96156 | D15: 9.7850591 | E15: 0.011501704 | F15: 0.008544547 | G15: 0 | H15: 3.793177 | I15: 3.8307621 | J15: -27.475239 | K15: 17.559079 | L15: 14.863894 | M15: 16.339959 | N15: 70.435491 | O15: 62.357252 | P15: 287175.28 | Q15: 268515.14 | R15: 781.17369 | S15: 0 | T15: 0 | U15: 0.11020424 | V15: 0.59692517 | W15: 0 | X15: 0.55869535 | Y15: 0 | Z15: 0.00037026406 | AA15: 4.4001409e-05 | AB15: 0.0052680609 | AC15: 7.3344628e-06 | AD15: 0.0028548717 | AE15: 0.093673786 | AF15: 0.1216746 | AG15: 0.92555841 | AH15: 0.99393651 | AI15: 1 | AJ15: 1 | AK15: 1 | AL15: 1 | AM15: 0 | AN15: 0 | AO15: 09-4:15-20 | AP15: 15-20 | AQ15: 1.900926e+10 | AR15: 70794 | AS15: 0 | AT15: 40.307483 | AU15: 40.307483 | AV15: 59.692517 | AW15: 59.692517 | AX15: 0
A16: 97 | B16: 0.99104263 | C16: 14.637116 | D16: 10.234797 | E16: 0.013101649 | F16: 0.0089573731 | G16: 0 | H16: 3.8324935 | I16: 3.8215182 | J16: -25.058838 | K16: 22.492715 | L16: 14.619027 | M16: 16.595066 | N16: 72.560471 | O16: 64.111066 | P16: 291993.22 | Q16: 273045.97 | R16: 780.70105 | S16: 0 | T16: 0 | U16: 0.11739366 | V16: 0.59923875 | W16: 0 | X16: 0.53772358 | Y16: 0 | Z16: 0.00037045613 | AA16: 4.7841729e-05 | AB16: 0.0052312754 | AC16: 9.0230904e-06 | AD16: 0.0032987623 | AE16: 0.095232533 | AF16: 0.10930375 | AG16: 0.92375779 | AH16: 0.99317013 | AI16: 1 | AJ16: 1 | AK16: 1 | AL16: 1 | AM16: 0 | AN16: 0 | AO16: 09:0-25 | AP16: 0-25 | AQ16: 2.13724e+10 | AR16: 78274 | AS16: 0 | AT16: 40.076125 | AU16: 40.076125 | AV16: 59.923875 | AW16: 59.923875 | AX16: 0
A17: 97 | B17: 0.99054164 | C17: 14.604826 | D17: 10.777818 | E17: 0.013070546 | F17: 0.009458361 | G17: 0 | H17: 3.8802513 | I17: 3.8260683 | J17: -23.149488 | K17: 27.497283 | L17: 14.783174 | M17: 16.760813 | N17: 71.002037 | O17: 62.66057 | P17: 290042.05 | Q17: 270022.6 | R17: 780.65055 | S17: 0 | T17: 0 | U17: 0.12762314 | V17: 0.60434038 | W17: 0 | X17: 0.54144113 | Y17: 0 | Z17: 0.00037040792 | AA17: 5.2756991e-05 | AB17: 0.0052657744 | AC17: 1.1995207e-05 | AD17: 0.003757412 | AE17: 0.096874647 | AF17: 0.10769357 | AG17: 0.91569525 | AH17: 0.99057482 | AI17: 1 | AJ17: 1 | AK17: 1 | AL17: 1 | AM17: 0 | AN17: 0 | AO17: 10-1:25-30 | AP17: 25-30 | AQ17: 2.1784883e+10 | AR17: 80678 | AS17: 0 | AT17: 39.565962 | AU17: 39.565962 | AV17: 60.434038 | AW17: 60.434038 | AX17: 0
A18: 97 | B18: 0.9900634 | C18: 17.054965 | D18: 11.293377 | E18: 0.015461887 | F18: 0.0099366049 | G18: 0 | H18: 3.9333662 | I18: 3.8273207 | J18: -21.054766 | K18: 32.544834 | L18: 14.719492 | M18: 16.945081 | N18: 72.455906 | O18: 63.979812 | P18: 289962.49 | Q18: 271195.83 | R18: 780.30113 | S18: 0 | T18: 0 | U18: 0.13215231 | V18: 0.60288165 | W18: 0 | X18: 0.50110059 | Y18: 0 | Z18: 0.00036949258 | AA18: 5.8408594e-05 | AB18: 0.0052867022 | AC18: 1.4083395e-05 | AD18: 0.0042079037 | AE18: 0.096559649 | AF18: 0.10969443 | AG18: 0.91444607 | AH18: 0.98982817 | AI18: 1 | AJ18: 1 | AK18: 1 | AL18: 1 | AM18: 0 | AN18: 0 | AO18: 10-2:30-35 | AP18: 30-35 | AQ18: 2.3345622e+10 | AR18: 86084 | AS18: 0 | AT18: 39.711835 | AU18: 39.711835 | AV18: 60.288165 | AW18: 60.288165 | AX18: 0
A19: 97 | B19: 0.98956159 | C19: 17.472775 | D19: 11.831396 | E19: 0.01587612 | F19: 0.010438409 | G19: 0 | H19: 3.9887988 | I19: 3.8342699 | J19: -18.859196 | K19: 37.532819 | L19: 14.890849 | M19: 17.238109 | N19: 73.129167 | O19: 64.378678 | P19: 287507.92 | Q19: 268087.65 | R19: 780.22666 | S19: 0 | T19: 0 | U19: 0.14165558 | V19: 0.59860947 | W19: 0 | X19: 0.48035418 | Y19: 0 | Z19: 0.00037065483 | AA19: 6.2691e-05 | AB19: 0.0053581156 | AC19: 1.8733744e-05 | AD19: 0.004628199 | AE19: 0.099074579 | AF19: 0.098689398 | AG19: 0.90334815 | AH19: 0.98636649 | AI19: 1 | AJ19: 1 | AK19: 1 | AL19: 1 | AM19: 0 | AN19: 0 | AO19: 10-3:35-40 | AP19: 35-40 | AQ19: 2.3599756e+10 | AR19: 88030 | AS19: 0 | AT19: 40.139053 | AU19: 40.139053 | AV19: 59.860947 | AW19: 59.860947 | AX19: 0
A20: 97 | B20: 0.98904609 | C20: 19.256804 | D20: 12.380986 | E20: 0.017666787 | F20: 0.010953911 | G20: 0 | H20: 4.0333097 | I20: 3.832988 | J20: -16.933643 | K20: 42.527555 | L20: 15.030478 | M20: 17.424412 | N20: 72.829279 | O20: 64.077189 | P20: 283449.61 | Q20: 265599.94 | R20: 779.89642 | S20: 0 | T20: 0 | U20: 0.14429394 | V20: 0.59294043 | W20: 0 | X20: 0.4624459 | Y20: 0 | Z20: 0.00036993666 | AA20: 6.5548211e-05 | AB20: 0.005443187 | AC20: 2.5274335e-05 | AD20: 0.0050499501 | AE20: 0.10018495 | AF20: 0.1043867 | AG20: 0.89247886 | AH20: 0.9818066 | AI20: 1 | AJ20: 1 | AK20: 1 | AL20: 1 | AM20: 0 | AN20: 0 | AO20: 10-4:40-45 | AP20: 40-45 | AQ20: 2.3903729e+10 | AR20: 89999 | AS20: 0 | AT20: 40.704451 | AU20: 40.704451 | AV20: 59.295549 | AW20: 59.295549 | AX20: 0
A21: 97 | B21: 0.98854525 | C21: 21.38762 | D21: 12.91193 | E21: 0.019853684 | F21: 0.011454745 | G21: 0 | H21: 4.0756897 | I21: 3.8275303 | J21: -14.680369 | K21: 47.487928 | L21: 14.784285 | M21: 17.649351 | N21: 74.412996 | O21: 65.367046 | P21: 289059.93 | Q21: 270029.11 | R21: 779.61414 | S21: 0 | T21: 0 | U21: 0.14711552 | V21: 0.58810781 | W21: 0 | X21: 0.44142328 | Y21: 0 | Z21: 0.00036961207 | AA21: 6.8708407e-05 | AB21: 0.0054225893 | AC21: 3.2519154e-05 | AD21: 0.0055613017 | AE21: 0.10202995 | AF21: 0.097177046 | AG21: 0.88462842 | AH21: 0.97743111 | AI21: 1 | AJ21: 1 | AK21: 1 | AL21: 1 | AM21: 0 | AN21: 0 | AO21: 10:25-50 | AP21: 25-50 | AQ21: 2.5012257e+10 | AR21: 92628 | AS21: 0 | AT21: 41.188502 | AU21: 41.188502 | AV21: 58.811498 | AW21: 58.811498 | AX21: 0
A22: 97 | B22: 0.98797844 | C22: 21.844648 | D22: 13.509266 | E22: 0.020329809 | F22: 0.012021565 | G22: 0 | H22: 4.1162904 | I22: 3.8250034 | J22: -12.697177 | K22: 52.465594 | L22: 15.01716 | M22: 17.858718 | N22: 73.733427 | O22: 64.600006 | P22: 283932.11 | Q22: 265847.61 | R22: 779.4181 | S22: 0 | T22: 0 | U22: 0.14961168 | V22: 0.5771239 | W22: 0 | X22: 0.45869187 | Y22: 0 | Z22: 0.00037027866 | AA22: 6.9688069e-05 | AB22: 0.0054943338 | AC22: 4.4868516e-05 | AD22: 0.0060423809 | AE22: 0.10498919 | AF22: 0.093444582 | AG22: 0.86841661 | AH22: 0.96867738 | AI22: 1 | AJ22: 1 | AK22: 1 | AL22: 1 | AM22: 0 | AN22: 0 | AO22: 11-1:50-55 | AP22: 50-55 | AQ22: 2.339778e+10 | AR22: 88012 | AS22: 0 | AT22: 42.286845 | AU22: 42.286845 | AV22: 57.713155 | AW22: 57.713155 | AX22: 0
A23: 97 | B23: 0.98733231 | C23: 25.082143 | D23: 14.1856 | E23: 0.023777577 | F23: 0.012667694 | G23: 0 | H23: 4.1452802 | I23: 3.811939 | J23: -10.28406 | K23: 57.480826 | L23: 14.438664 | M23: 17.856393 | N23: 74.381849 | O23: 65.11985 | P23: 293108.98 | Q23: 276498.8 | R23: 778.95854 | S23: 0 | T23: 0 | U23: 0.15108265 | V23: 0.57695188 | W23: 0 | X23: 0.46632902 | Y23: 0 | Z23: 0.00036919673 | AA23: 7.2425856e-05 | AB23: 0.0054649508 | AC23: 5.5520356e-05 | AD23: 0.0067055855 | AE23: 0.10656911 | AF23: 0.083564264 | AG23: 0.86605027 | AH23: 0.9624726 | AI23: 1 | AJ23: 1 | AK23: 1 | AL23: 1 | AM23: 0 | AN23: 0 | AO23: 11-2:55-60 | AP23: 55-60 | AQ23: 2.2377877e+10 | AR23: 80933 | AS23: 0 | AT23: 42.304014 | AU23: 42.304014 | AV23: 57.695986 | AW23: 57.695986 | AX23: 0
A24: 97 | B24: 0.98672236 | C24: 25.678761 | D24: 14.819605 | E24: 0.02442781 | F24: 0.013277638 | G24: 0 | H24: 4.1715759 | I24: 3.8064635 | J24: -7.9445009 | K24: 62.390237 | L24: 14.296382 | M24: 18.025439 | N24: 74.543544 | O24: 65.017459 | P24: 297842.77 | Q24: 279246.36 | R24: 778.6258 | S24: 0 | T24: 0 | U24: 0.1655487 | V24: 0.58941463 | W24: 0 | X24: 0.49759965 | Y24: 0 | Z24: 0.00036918747 | AA24: 7.6977537e-05 | AB24: 0.0054438374 | AC24: 6.7859739e-05 | AD24: 0.0073197602 | AE24: 0.11036 | AF24: 0.068871881 | AG24: 0.85240549 | AH24: 0.95461999 | AI24: 1 | AJ24: 1 | AK24: 1 | AL24: 1 | AM24: 0 | AN24: 0 | AO24: 11-3:60-65 | AP24: 60-65 | AQ24: 1.7494505e+10 | AR24: 62649 | AS24: 0 | AT24: 41.055489 | AU24: 41.055489 | AV24: 58.944511 | AW24: 58.944511 | AX24: 0
A25: 97 | B25: 0.98614148 | C25: 25.732334 | D25: 15.419403 | E25: 0.024486431 | F25: 0.013858515 | G25: 0 | H25: 4.2076933 | I25: 3.8090937 | J25: -5.0515423 | K25: 67.437798 | L25: 14.773111 | M25: 18.14047 | N25: 75.050091 | O25: 65.386412 | P25: 287814.41 | Q25: 270237.23 | R25: 777.84026 | S25: 0 | T25: 0 | U25: 0.17876355 | V25: 0.59239971 | W25: 0 | X25: 0.51347696 | Y25: 0 | Z25: 0.0003685446 | AA25: 8.2212533e-05 | AB25: 0.0055341895 | AC25: 7.917242e-05 | AD25: 0.0077943809 | AE25: 0.11240211 | AF25: 0.071716434 | AG25: 0.83279078 | AH25: 0.94929456 | AI25: 1 | AJ25: 1 | AK25: 1 | AL25: 1 | AM25: 0 | AN25: 0 | AO25: 11-4:65-70 | AP25: 65-70 | AQ25: 1.3415387e+10 | AR25: 49643 | AS25: 0 | AT25: 40.760029 | AU25: 40.760029 | AV25: 59.239971 | AW25: 59.239971 | AX25: 0
A26: 97 | B26: 0.98548019 | C26: 28.913425 | D26: 16.097522 | E26: 0.028038717 | F26: 0.014519809 | G26: 0 | H26: 4.2395864 | I26: 3.8105994 | J26: -2.3814145 | K26: 72.406061 | L26: 14.570543 | M26: 18.278509 | N26: 77.971379 | O26: 67.791666 | P26: 291264.86 | Q26: 274004.12 | R26: 777.26793 | S26: 0 | T26: 0 | U26: 0.17551211 | V26: 0.57909797 | W26: 0 | X26: 0.49760423 | Y26: 0 | Z26: 0.00036876269 | AA26: 8.875363e-05 | AB26: 0.0055168837 | AC26: 8.5784378e-05 | AD26: 0.0084596096 | AE26: 0.11453738 | AF26: 0.059446717 | AG26: 0.82399413 | AH26: 0.94859901 | AI26: 1 | AJ26: 1 | AK26: 1 | AL26: 1 | AM26: 0 | AN26: 0 | AO26: 11:50-75 | AP26: 50-75 | AQ26: 1.1261843e+10 | AR26: 41101 | AS26: 0 | AT26: 42.090203 | AU26: 42.090203 | AV26: 57.909797 | AW26: 57.909797 | AX26: 0
... A32: 97 | B32: 0.96171818 | C32: 94.051204 | D32: 37.40006 | E32: 0.20955967 | F32: 0.038281819 | G32: 0 | H32: 5.1176123 | I32: 3.8034605 | J32: 72.032955 | K32: 203.70254 | L32: 15.29575 | M32: 22.005306 | N32: 91.060496 | O32: 74.911131 | P32: 287554.11 | Q32: 261070.33 | R32: 771.00948 | S32: 0 | T32: 0 | U32: 0.063892119 | V32: 0.6831468 | W32: 0 | X32: 0.351038 | Y32: 0 | Z32: 0.00036019193 | AA32: 0.00057121596 | AB32: 0.0062610961 | AC32: 0.0012560033 | AD32: 0.029833294 | AE32: 0.18245448 | AF32: 0 | AG32: 0.18677956 | AH32: 0.55165766 | AI32: 1 | AJ32: 1 | AK32: 1 | AL32: 1 | AM32: 0 | AN32: 0 | AO32: 17:200-225 | AP32: 200-225 | AQ32: 3916055 | AR32: 15 | AS32: 0 | AT32: 31.68532 | AU32: 31.68532 | AV32: 68.31468 | AW32: 68.31468 | AX32: 0
F36: high media
A37: modelId | B37: SFACTOR_PREPAY_TRACKING_CPR | C37: PREPAY_CPR1 | D37: PREPAY_TRACKING_CPR1 | E37: PREPAY_SMM1 | F37: PREPAY_TRACKING_SMM1 | G37: PCT_LOANTYPE | H37: _ORIGNOTERATE | I37: _ZEROSATO | J37: _SATO | K37: _REFI_INCENTIVE_Fixed | L37: _Fixed_cost | M37: _LOANAGE | N37: _LTV | O37: _CLTV | P37: _AVG_LOANSIZE_SCHAMBALANCE | Q37: _WACLS | R37: _FICO | S37: PCT_ISSECONDLIEN | T37: _OrigCombLTV | U37: PCT_SVC | V37: PCT_TPO | W37: PCT_GEO | X37: PCT_LOANPURPOSE | Y37: PCT_OCC | Z37: curtailsmm | AA37: defaultsmm | AB37: toverSmm | AC37: cashoutSmm | AD37: refiSmm | AE37: cumHPA | AF37: cumHPA05Pct | AG37: cumHPA15Pct | AH37: cumHPA20Pct | AI37: cumHPA25Pct | AJ37: cumHPA30Pct | AK37: cumHPA35Pct | AL37: cumHPA40Pct | AM37: adjtoverSmm | AN37: adjRefiSmm | AO37: groupByColumn | AP37: curve | AQ37: Balance | AR37: LoanCount | AS37: PCT_BROKER | AT37: PCT_CORRES | AU37: PCT_NonRETAIL | AV37: PCT_RETAIL | AW37: PCT_CashWindow | AX37: PCT_NonCashWindow
A38: 96 | B38: 0.98839691 | C38: 96.635073 | D38: 13.068622 | E38: 0.24621417 | F38: 0.011603087 | G38: 0 | H38: 3.4287964 | I38: 3.9170498 | J38: -60.571903 | K38: -108.57802 | L38: 100 | M38: 13.372006 | N38: 76.773096 | O38: 12.785692 | P38: 34194.875 | Q38: 31481.298 | R38: 792.65593 | S38: 0 | T38: 0 | U38: 0.060023573 | V38: 0.43037133 | W38: 0 | X38: 0.060023573 | Y38: 0 | Z38: 0.0055161513 | AA38: 1.2412019e-05 | AB38: 0.0060745137 | AC38: 0 | AD38: 0 | AE38: 0.059792222 | AF38: 0.39695938 | AG38: 1 | AH38: 1 | AI38: 1 | AJ38: 1 | AK38: 1 | AL38: 1 | AM38: 0 | AN38: 0 | AO38: 04:-125--100 | AP38: =-125--100 -> -25 | AQ38: 188887.79 | AR38: 6 | AS38: 0 | AT38: 56.962867 | AU38: 56.962867 | AV38: 43.037133 | AW38: 43.037133 | AX38: 0
A39: 96 | B39: 0.98826771 | C39: 49.843412 | D39: 13.204884 | E39: 0.055879709 | F39: 0.011732287 | G39: 0 | H39: 3.4420778 | I39: 3.9164769 | J39: -59.517626 | K39: -81.597641 | L39: 68.465589 | M39: 14.548948 | N39: 71.385986 | O39: 24.934341 | P39: 117969.24 | Q39: 40852.783 | R39: 786.04463 | S39: 0 | T39: 0 | U39: 0.027485084 | V39: 0.68664472 | W39: 0 | X39: 0.058346254 | Y39: 0 | Z39: 0.0043983283 | AA39: 3.4939807e-05 | AB39: 0.007099851 | AC39: 3.07944e-06 | AD39: 0.00019607821 | AE39: 0.092113583 | AF39: 0.20636363 | AG39: 0.92741588 | AH39: 1 | AI39: 1 | AJ39: 1 | AK39: 1 | AL39: 1 | AM39: 0 | AN39: 0 | AO39: 05:-100--75 | AP39: =-100--75 -> -25 | AQ39: 6005359.1 | AR39: 147 | AS39: 0 | AT39: 31.335528 | AU39: 31.335528 | AV39: 68.664472 | AW39: 68.664472 | AX39: 0
A40: 96 | B40: 0.99029962 | C40: 38.81742 | D40: 11.039063 | E40: 0.040115492 | F40: 0.0097003799 | G40: 0 | H40: 3.4962707 | I40: 3.8952664 | J40: -53.707825 | K40: -57.582086 | L40: 45.414254 | M40: 15.142775 | N40: 73.296276 | O40: 43.30325 | P40: 173908.24 | Q40: 63191.424 | R40: 782.07674 | S40: 0 | T40: 0 | U40: 0.054816654 | V40: 0.72447447 | W40: 0 | X40: 0.21958318 | Y40: 0 | Z40: 0.0023777527 | AA40: 3.843875e-05 | AB40: 0.0061975188 | AC40: 2.517301e-06 | AD40: 0.0010841412 | AE40: 0.087867306 | AF40: 0.19207694 | AG40: 0.95406742 | AH40: 0.99472364 | AI40: 1 | AJ40: 1 | AK40: 1 | AL40: 1 | AM40: 0 | AN40: 0 | AO40: 06:-75--50 | AP40: =-75--50 -> -25 | AQ40: 43286126 | AR40: 685 | AS40: 0 | AT40: 27.552553 | AU40: 27.552553 | AV40: 72.447447 | AW40: 72.447447 | AX40: 0
A41: 96 | B41: 0.99020777 | C41: 9.3616256 | D41: 11.138029 | E41: 0.0081575869 | F41: 0.0097922328 | G41: 0 | H41: 3.4645783 | I41: 3.9281772 | J41: -54.768892 | K41: -31.153905 | L41: 18.985438 | M41: 14.446285 | N41: 73.016693 | O41: 63.087717 | P41: 251793.26 | Q41: 201489.6 | R41: 781.12105 | S41: 0 | T41: 0 | U41: 0.05384346 | V41: 0.61549503 | W41: 0 | X41: 0.51591271 | Y41: 0 | Z41: 0.00053383381 | AA41: 3.2372878e-05 | AB41: 0.0050501465 | AC41: 9.784867e-07 | AD41: 0.0041748865 | AE41: 0.08095162 | AF41: 0.19860855 | AG41: 0.95610793 | AH41: 0.99846457 | AI41: 1 | AJ41: 1 | AK41: 1 | AL41: 1 | AM41: 0 | AN41: 0 | AO41: 07:-50--25 | AP41: =-50--25 -> -25 | AQ41: 1.3604578e+09 | AR41: 6752 | AS41: 0 | AT41: 38.450497 | AU41: 38.450497 | AV41: 61.549503 | AW41: 61.549503 | AX41: 0
A42: 96 | B42: 0.98750826 | C42: 7.416952 | D42: 14.001907 | E42: 0.0064014336 | F42: 0.012491744 | G42: 0 | H42: 3.524119 | I42: 3.9299141 | J42: -48.414066 | K42: -22.221985 | L42: 16.498899 | M42: 14.36346 | N42: 73.1865 | O42: 65.100598 | P42: 268436.49 | Q42: 239394.87 | R42: 780.93529 | S42: 0 | T42: 0 | U42: 0.068865837 | V42: 0.6104547 | W42: 0 | X42: 0.5618934 | Y42: 0 | Z42: 0.00040143177 | AA42: 3.2732743e-05 | AB42: 0.0049308652 | AC42: 7.3330338e-07 | AD42: 0.007125967 | AE42: 0.08062327 | AF42: 0.16681883 | AG42: 0.96699982 | AH42: 0.99933097 | AI42: 1 | AJ42: 1 | AK42: 1 | AL42: 1 | AM42: 0 | AN42: 0 | AO42: 08-1:-25--20 | AP42: =-25--20 -> -5 | AQ42: 1.5658819e+09 | AR42: 6541 | AS42: 0 | AT42: 38.95453 | AU42: 38.95453 | AV42: 61.04547 | AW42: 61.04547 | AX42: 0
A43: 96 | B43: 0.98587441 | C43: 4.8879394 | D43: 15.693878 | E43: 0.0041674922 | F43: 0.014125593 | G43: 0 | H43: 3.5557883 | I43: 3.9208747 | J43: -45.581681 | K43: -17.210662 | L43: 15.961582 | M43: 14.483489 | N43: 71.60487 | O43: 63.81283 | P43: 272723.21 | Q43: 249028.12 | R43: 781.78181 | S43: 0 | T43: 0 | U43: 0.078276983 | V43: 0.60553234 | W43: 0 | X43: 0.54899391 | Y43: 0 | Z43: 0.00038737513 | AA43: 3.3488465e-05 | AB43: 0.0050609118 | AC43: 9.2107342e-07 | AD43: 0.0086428822 | AE43: 0.082238649 | AF43: 0.16530941 | AG43: 0.96394511 | AH43: 0.99885027 | AI43: 1 | AJ43: 1 | AK43: 1 | AL43: 1 | AM43: 0 | AN43: 0 | AO43: 08-2:-20--15 | AP43: =-20--15 -> -5 | AQ43: 2.7221264e+09 | AR43: 10931 | AS43: 0 | AT43: 39.446766 | AU43: 39.446766 | AV43: 60.553234 | AW43: 60.553234 | AX43: 0
A44: 96 | B44: 0.98462513 | C44: 8.259733 | D44: 16.966955 | E44: 0.0071583219 | F44: 0.015374875 | G44: 0 | H44: 3.5954185 | I44: 3.9147199 | J44: -41.886543 | K44: -12.281778 | L44: 15.428091 | M44: 14.550842 | N44: 72.17644 | O44: 64.441153 | P44: 279936.8 | Q44: 258280.9 | R44: 781.46676 | S44: 0 | T44: 0 | U44: 0.087735292 | V44: 0.60964009 | W44: 0 | X44: 0.54254679 | Y44: 0 | Z44: 0.00037560677 | AA44: 3.3985792e-05 | AB44: 0.0050442272 | AC44: 1.084469e-06 | AD44: 0.009919956 | AE44: 0.083439747 | AF44: 0.14859681 | AG44: 0.96165329 | AH44: 0.99909455 | AI44: 1 | AJ44: 1 | AK44: 1 | AL44: 1 | AM44: 0 | AN44: 0 | AO44: 08-3:-15--10 | AP44: =-15--10 -> -5 | AQ44: 4.5837111e+09 | AR44: 17747 | AS44: 0 | AT44: 39.035991 | AU44: 39.035991 | AV44: 60.964009 | AW44: 60.964009 | AX44: 0
A45: 96 | B45: 0.98330492 | C45: 7.9191916 | D45: 18.29314 | E45: 0.0068517227 | F45: 0.016695085 | G45: 0 | H45: 3.6231364 | I45: 3.8984104 | J45: -39.585383 | K45: -7.4062628 | L45: 15.296341 | M45: 14.911876 | N45: 71.109777 | O45: 63.291883 | P45: 281675.24 | Q45: 260533.88 | R45: 781.48996 | S45: 0 | T45: 0 | U45: 0.091236558 | V45: 0.60130514 | W45: 0 | X45: 0.55636662 | Y45: 0 | Z45: 0.00037442918 | AA45: 3.4860008e-05 | AB45: 0.0051831359 | AC45: 1.5032299e-06 | AD45: 0.011101142 | AE45: 0.086115169 | AF45: 0.14110782 | AG45: 0.95021425 | AH45: 0.99893123 | AI45: 1 | AJ45: 1 | AK45: 1 | AL45: 1 | AM45: 0 | AN45: 0 | AO45: 08-4:-10--5 | AP45: =-10--5 -> -5 | AQ45: 6.6326715e+09 | AR45: 25458 | AS45: 0 | AT45: 39.869486 | AU45: 39.869486 | AV45: 60.130514 | AW45: 60.130514 | AX45: 0
A46: 96 | B46: 0.98219018 | C46: 8.6514849 | D46: 19.397773 | E46: 0.0075123203 | F46: 0.017809822 | G46: 0 | H46: 3.6551722 | I46: 3.8826854 | J46: -36.811228 | K46: -2.3916674 | L46: 15.050831 | M46: 15.210302 | N46: 71.233243 | O46: 63.416485 | P46: 286027.38 | Q46: 264953.55 | R46: 781.41774 | S46: 0 | T46: 0 | U46: 0.092835681 | V46: 0.59536817 | W46: 0 | X46: 0.56119432 | Y46: 0 | Z46: 0.00037069367 | AA46: 3.581818e-05 | AB46: 0.0051417377 | AC46: 1.8486999e-06 | AD46: 0.012259709 | AE46: 0.087190228 | AF46: 0.13675479 | AG46: 0.95105333 | AH46: 0.99888108 | AI46: 1 | AJ46: 1 | AK46: 1 | AL46: 1 | AM46: 0 | AN46: 0 | AO46: 08:-25-0 | AP46: =-25-0 -> -25 | AQ46: 9.7982474e+09 | AR46: 36981 | AS46: 0 | AT46: 40.463183 | AU46: 40.463183 | AV46: 59.536817 | AW46: 59.536817 | AX46: 0
A47: 96 | B47: 0.98105311 | C47: 9.6587779 | D47: 20.510416 | E47: 0.0084289694 | F47: 0.01894689 | G47: 0 | H47: 3.6936876 | I47: 3.8737928 | J47: -33.806205 | K47: 2.6121767 | L47: 15.059416 | M47: 15.398367 | N47: 71.20197 | O47: 63.30499 | P47: 284835.16 | Q47: 264994.1 | R47: 781.44475 | S47: 0 | T47: 0 | U47: 0.099676388 | V47: 0.6006954 | W47: 0 | X47: 0.56479509 | Y47: 0 | Z47: 0.0003703554 | AA47: 3.6686619e-05 | AB47: 0.0052090767 | AC47: 3.0870021e-06 | AD47: 0.01332767 | AE47: 0.089425468 | AF47: 0.1246349 | AG47: 0.94265683 | AH47: 0.99742834 | AI47: 1 | AJ47: 1 | AK47: 1 | AL47: 1 | AM47: 0 | AN47: 0 | AO47: 09-1:0-5 | AP47: 0-5 | AQ47: 1.2626439e+10 | AR47: 47648 | AS47: 0 | AT47: 39.93046 | AU47: 39.93046 | AV47: 60.06954 | AW47: 60.06954 | AX47: 0
A48: 96 | B48: 0.97970182 | C48: 11.895024 | D48: 21.814361 | E48: 0.010497939 | F48: 0.020298177 | G48: 0 | H48: 3.7178014 | I48: 3.8530514 | J48: -32.195354 | K48: 7.6142859 | L48: 14.558583 | M48: 15.821745 | N48: 70.946759 | O48: 62.934601 | P48: 293115.39 | Q48: 274145.15 | R48: 781.38453 | S48: 0 | T48: 0 | U48: 0.1010385 | V48: 0.60196444 | W48: 0 | X48: 0.55814045 | Y48: 0 | Z48: 0.00037043941 | AA48: 3.8612944e-05 | AB48: 0.0052327257 | AC48: 4.0688358e-06 | AD48: 0.014652316 | AE48: 0.091144609 | AF48: 0.12017603 | AG48: 0.93715128 | AH48: 0.99640248 | AI48: 1 | AJ48: 1 | AK48: 1 | AL48: 1 | AM48: 0 | AN48: 0 | AO48: 09-2:5-10 | AP48: 43230 | AQ48: 1.600432e+10 | AR48: 58379 | AS48: 0 | AT48: 39.803556 | AU48: 39.803556 | AV48: 60.196444 | AW48: 60.196444 | AX48: 0
...

Sheet Burnout 2013 Corres+Cashwindow_
A1: burnout 0-2000 | C1: CORRES+CASHWINDOW | F1: low media | AS1: tover | AT1: cash | AW1: refi
A2: modelId | B2: SFACTOR_PREPAY_TRACKING_CPR | C2: PREPAY_CPR1 | D2: PREPAY_TRACKING_CPR1 | E2: PREPAY_SMM1 | F2: PREPAY_TRACKING_SMM1 | G2: PCT_LOANTYPE | H2: _ORIGNOTERATE | I2: _ZEROSATO | J2: _SATO | K2: _REFI_INCENTIVE_Fixed | L2: _Fixed_cost | M2: _LOANAGE | N2: _LTV | O2: _CLTV | P2: _AVG_LOANSIZE_SCHAMBALANCE | Q2: _WACLS | R2: _FICO | S2: PCT_ISSECONDLIEN | T2: _OrigCombLTV | U2: PCT_SVC | V2: PCT_TPO | W2: PCT_GEO | X2: PCT_LOANPURPOSE | Y2: PCT_OCC | Z2: curtailsmm | AA2: defaultsmm | AB2: toverSmm | AC2: cashoutSmm | AD2: refiSmm | AE2: cumHPA | AF2: cumHPA05Pct | AG2: cumHPA15Pct | AH2: cumHPA20Pct | AI2: cumHPA25Pct | AJ2: cumHPA30Pct | AK2: cumHPA35Pct | AL2: cumHPA40Pct | AM2: adjtoverSmm | AN2: adjRefiSmm | AO2: groupByColumn | AP2: curve | AQ2: Balance | AR2: LoanCount | AS2: PCT_BROKER | AT2: PCT_CORRES | AU2: PCT_NonRETAIL | AV2: PCT_RETAIL | AW2: PCT_CashWindow | AX2: PCT_NonCashWindow | AY2: _Burnout_Fixed
A3: 97 | B3: 0.99833297 | C3: 0.26130405 | D3: 1.9821991 | E3: 0.0002180146 | F3: 0.0016670325 | G3: 0 | H3: 3.25 | I3: 3.7357636 | J3: -40.509727 | K3: -155.50095 | L3: 14.562552 | M3: 3.2725683 | N3: 80 | O3: 77.654292 | P3: 291131.11 | Q3: 274125.36 | R3: 774.19702 | S3: 0 | T3: 0 | U3: 0 | V3: 0.45074387 | W3: 0 | X3: 0 | Y3: 0 | Z3: 0.0001606861 | AA3: 5.3411715e-06 | AB3: 0.001500988 | AC3: 0 | AD3: 0 | AE3: 0.024554217 | AF3: 1 | AG3: 1 | AH3: 1 | AI3: 1 | AJ3: 1 | AK3: 1 | AL3: 1 | AM3: 0 | AN3: 0 | AO3: 02:-175--150 | AP3: =-175--150 -> -25 | AQ3: 822376.09 | AR3: 3 | AS3: 0 | AT3: 54.925613 | AU3: 54.925613 | AV3: 45.074387 | AW3: 45.074387 | AX3: 0 | AY3: 0
A4: 97 | B4: 0.99842362 | C4: 0.16230364 | D4: 1.8753433 | E4: 0.00013535375 | F4: 0.0015763819 | G4: 0 | H4: 3.5272566 | I4: 3.8043425 | J4: -22.033008 | K4: -133.73728 | L4: 15.318144 | M4: 4.2985068 | N4: 78.869899 | O4: 77.21009 | P4: 278644.18 | Q4: 260629.58 | R4: 780.52698 | S4: 0 | T4: 0 | U4: 0.044210759 | V4: 0.62073294 | W4: 0 | X4: 0.4786667 | Y4: 0 | Z4: 0.00021594279 | AA4: 1.9980674e-05 | AB4: 0.001338924 | AC4: 0 | AD4: 1.5205842e-06 | AE4: 0.013634735 | AF4: 0.95578924 | AG4: 1 | AH4: 1 | AI4: 1 | AJ4: 1 | AK4: 1 | AL4: 1 | AM4: 0 | AN4: 0 | AO4: 03:-150--125 | AP4: =-150--125 -> -25 | AQ4: 5994480.4 | AR4: 23 | AS4: 0 | AT4: 37.926706 | AU4: 37.926706 | AV4: 62.073294 | AW4: 62.073294 | AX4: 0 | AY4: 0
A5: 97 | B5: 0.9980806 | C5: 0.18121177 | D5: 2.2791191 | E5: 0.00015113537 | F5: 0.0019193993 | G5: 0 | H5: 3.6597934 | I5: 3.8379448 | J5: -23.588857 | K5: -109.75521 | L5: 15.30596 | M5: 4.9024314 | N5: 79.067811 | O5: 77.25009 | P5: 287089.08 | Q5: 248393.64 | R5: 779.35781 | S5: 0 | T5: 0 | U5: 0.066477551 | V5: 0.5786861 | W5: 0 | X5: 0.66174794 | Y5: 0 | Z5: 0.00026488139 | AA5: 2.0234425e-05 | AB5: 0.0014553005 | AC5: 0 | AD5: 0.00017896852 | AE5: 0.010841057 | AF5: 0.97253224 | AG5: 1 | AH5: 1 | AI5: 1 | AJ5: 1 | AK5: 1 | AL5: 1 | AM5: 0 | AN5: 0 | AO5: 04:-125--100 | AP5: =-125--100 -> -25 | AQ5: 24342577 | AR5: 98 | AS5: 0 | AT5: 42.13139 | AU5: 42.13139 | AV5: 57.86861 | AW5: 57.86861 | AX5: 0 | AY5: 0
A6: 97 | B6: 0.99802284 | C6: 3.6078533 | D6: 2.3469599 | E6: 0.0030574376 | F6: 0.0019771593 | G6: 0 | H6: 3.2951592 | I6: 3.8031731 | J6: -51.130374 | K6: -82.887944 | L6: 16.468467 | M6: 4.5559092 | N6: 78.442481 | O6: 76.520646 | P6: 264670.5 | Q6: 238741.99 | R6: 779.20984 | S6: 0 | T6: 0 | U6: 0.021720415 | V6: 0.72115303 | W6: 0 | X6: 0.55872654 | Y6: 0 | Z6: 0.00028078566 | AA6: 1.604513e-05 | AB6: 0.0014023499 | AC6: 0 | AD6: 0.00027796719 | AE6: 0.012095997 | AF6: 0.97058986 | AG6: 1 | AH6: 1 | AI6: 1 | AJ6: 1 | AK6: 1 | AL6: 1 | AM6: 0 | AN6: 0 | AO6: 05:-100--75 | AP6: =-100--75 -> -25 | AQ6: 1.9147108e+08 | AR6: 802 | AS6: 0 | AT6: 27.884697 | AU6: 27.884697 | AV6: 72.115303 | AW6: 72.115303 | AX6: 0 | AY6: 0.020677368
A7: 97 | B7: 0.99829917 | C7: 2.5251789 | D7: 2.0220101 | E7: 0.0021290709 | F7: 0.0017008291 | G7: 0 | H7: 3.4176098 | I7: 3.8696585 | J7: -46.76069 | K7: -57.590534 | L7: 16.353256 | M7: 4.4696039 | N7: 77.304998 | O7: 75.810597 | P7: 264339.53 | Q7: 242223.69 | R7: 780.28507 | S7: 0 | T7: 0 | U7: 0.047430635 | V7: 0.53831607 | W7: 0 | X7: 0.53935504 | Y7: 0 | Z7: 0.00023385913 | AA7: 1.8005624e-05 | AB7: 0.0013467223 | AC7: 0 | AD7: 0.00010223164 | AE7: 0.0099080295 | AF7: 0.97156969 | AG7: 0.99997862 | AH7: 1 | AI7: 1 | AJ7: 1 | AK7: 1 | AL7: 1 | AM7: 0 | AN7: 0 | AO7: 06:-75--50 | AP7: =-75--50 -> -25 | AQ7: 2.0998372e+09 | AR7: 8669 | AS7: 0 | AT7: 46.168393 | AU7: 46.168393 | AV7: 53.831607 | AW7: 53.831607 | AX7: 0 | AY7: 0.033571794
A8: 97 | B8: 0.99793548 | C8: 2.2766196 | D8: 2.4494838 | E8: 0.001917272 | F8: 0.0020645182 | G8: 0 | H8: 3.6403841 | I8: 3.9312025 | J8: -37.175533 | K8: -33.319482 | L8: 15.413077 | M8: 4.7861354 | N8: 74.92019 | O8: 73.22133 | P8: 278474.32 | Q8: 258664.79 | R8: 781.87721 | S8: 0 | T8: 0 | U8: 0.095435758 | V8: 0.39247208 | W8: 0 | X8: 0.62046666 | Y8: 0 | Z8: 0.0002312847 | AA8: 2.1392131e-05 | AB8: 0.0015898255 | AC8: 4.7241305e-09 | AD8: 0.00022199631 | AE8: 0.014420522 | AF8: 0.93978349 | AG8: 0.9998606 | AH8: 0.99999508 | AI8: 0.99999664 | AJ8: 1 | AK8: 1 | AL8: 1 | AM8: 0 | AN8: 0 | AO8: 07:-50--25 | AP8: =-50--25 -> -25 | AQ8: 2.2563329e+10 | AR8: 87230 | AS8: 0 | AT8: 60.752792 | AU8: 60.752792 | AV8: 39.247208 | AW8: 39.247208 | AX8: 0 | AY8: 0.024667824
A9: 97 | B9: 0.99751193 | C9: 2.9023812 | D9: 2.9451661 | E9: 0.0024514348 | F9: 0.002488072 | G9: 0 | H9: 3.706346 | I9: 3.9369143 | J9: -33.716192 | K9: -22.334933 | L9: 14.857801 | M9: 5.0207812 | N9: 71.926174 | O9: 70.058762 | P9: 288330.77 | Q9: 268583.17 | R9: 782.78234 | S9: 0 | T9: 0 | U9: 0.1044504 | V9: 0.36785414 | W9: 0 | X9: 0.70138515 | Y9: 0 | Z9: 0.0002396446 | AA9: 2.201004e-05 | AB9: 0.0017620538 | AC9: 5.5977508e-09 | AD9: 0.00046434322 | AE9: 0.017770583 | AF9: 0.90284197 | AG9: 0.99985315 | AH9: 0.99997747 | AI9: 1 | AJ9: 1 | AK9: 1 | AL9: 1 | AM9: 0 | AN9: 0 | AO9: 08-1:-25--20 | AP9: =-25--20 -> -5 | AQ9: 1.2758775e+10 | AR9: 47504 | AS9: 0 | AT9: 63.214586 | AU9: 63.214586 | AV9: 36.785414 | AW9: 36.785414 | AX9: 0 | AY9: 0.028662294
A10: 97 | B10: 0.99729572 | C10: 3.2032131 | D10: 3.1973015 | E10: 0.0027093552 | F10: 0.0027042798 | G10: 0 | H10: 3.7392656 | I10: 3.9359698 | J10: -32.212527 | K10: -17.367272 | L10: 14.50223 | M10: 5.200665 | N10: 70.594399 | O10: 68.707242 | P10: 295249.41 | Q10: 274993.91 | R10: 783.20152 | S10: 0 | T10: 0 | U10: 0.10321728 | V10: 0.36824829 | W10: 0 | X10: 0.72838232 | Y10: 0 | Z10: 0.00024584604 | AA10: 2.3257115e-05 | AB10: 0.0018292368 | AC10: 5.1401836e-09 | AD10: 0.00060591994 | AE10: 0.018369623 | AF10: 0.89009889 | AG10: 0.99978465 | AH10: 0.99997442 | AI10: 1 | AJ10: 1 | AK10: 1 | AL10: 1 | AM10: 0 | AN10: 0 | AO10: 08-2:-20--15 | AP10: =-20--15 -> -5 | AQ10: 17092521430 | AR10: 62156 | AS10: 0 | AT10: 63.175171 | AU10: 63.175171 | AV10: 36.824829 | AW10: 36.824829 | AX10: 0 | AY10: 0.041647693
A11: 97 | B11: 0.99703313 | C11: 4.5170378 | D11: 3.5027179 | E11: 0.0038444545 | F11: 0.0029668687 | G11: 0 | H11: 3.763594 | I11: 3.9206934 | J11: -30.353496 | K11: -12.402038 | L11: 14.443703 | M11: 5.5812302 | N11: 69.030042 | O11: 67.08445 | P11: 296549.13 | Q11: 276032.09 | R11: 783.22658 | S11: 0 | T11: 0 | U11: 0.094269616 | V11: 0.3601719 | W11: 0 | X11: 0.7388216 | Y11: 0 | Z11: 0.00025529552 | AA11: 2.5119771e-05 | AB11: 0.0019324644 | AC11: 4.9397321e-09 | AD11: 0.00075396938 | AE11: 0.019124926 | AF11: 0.8740921 | AG11: 0.99968867 | AH11: 0.99997655 | AI11: 1 | AJ11: 1 | AK11: 1 | AL11: 1 | AM11: 0 | AN11: 0 | AO11: 08-3:-15--10 | AP11: =-15--10 -> -5 | AQ11: 2.0836834e+10 | AR11: 75487 | AS11: 0 | AT11: 63.98281 | AU11: 63.98281 | AV11: 36.01719 | AW11: 36.01719 | AX11: 0 | AY11: 0.33634651
A12: 97 | B12: 0.99679391 | C12: 5.5688374 | D12: 3.7801851 | E12: 0.0047635395 | F12: 0.0032060889 | G12: 0 | H12: 3.7981737 | I12: 3.9037512 | J12: -27.922121 | K12: -7.4908218 | L12: 14.421523 | M12: 5.9852692 | N12: 69.510003 | O12: 67.501154 | P12: 297178.13 | Q12: 276508.02 | R12: 783.02563 | S12: 0 | T12: 0 | U12: 0.083687209 | V12: 0.35376725 | W12: 0 | X12: 0.7433794 | Y12: 0 | Z12: 0.00026209042 | AA12: 2.6911623e-05 | AB12: 0.0020148024 | AC12: 7.2078782e-09 | AD12: 0.00090226268 | AE12: 0.019365974 | AF12: 0.85335759 | AG12: 0.99948205 | AH12: 0.99998624 | AI12: 1 | AJ12: 1 | AK12: 1 | AL12: 1 | AM12: 0 | AN12: 0 | AO12: 08-4:-10--5 | AP12: =-10--5 -> -5 | AQ12: 2.3515901e+10 | AR12: 85046 | AS12: 0 | AT12: 64.623275 | AU12: 64.623275 | AV12: 35.376725 | AW12: 35.376725 | AX12: 0 | AY12: 1.6271224
A13: 97 | B13: 0.99653298 | C13: 7.1644601 | D13: 4.0820002 | E13: 0.0061759041 | F13: 0.00346702 | G13: 0 | H13: 3.8170273 | I13: 3.8825951 | J13: -26.300375 | K13: -2.4075089 | L13: 14.189775 | M13: 6.3344277 | N13: 68.355222 | O13: 66.29816 | P13: 301559.68 | Q13: 280888.12 | R13: 783.0112 | S13: 0 | T13: 0 | U13: 0.072013208 | V13: 0.34742339 | W13: 0 | X13: 0.74814443 | Y13: 0 | Z13: 0.00027086981 | AA13: 2.8370681e-05 | AB13: 0.0020925006 | AC13: 8.6823745e-09 | AD13: 0.0010752557 | AE13: 0.020306574 | AF13: 0.83709037 | AG13: 0.9991445 | AH13: 0.99998979 | AI13: 0.99999753 | AJ13: 1 | AK13: 1 | AL13: 1 | AM13: 0 | AN13: 0 | AO13: 08:-25-0 | AP13: =-25-0 -> -25 | AQ13: 2.7364682e+10 | AR13: 97422 | AS13: 0 | AT13: 65.257661 | AU13: 65.257661 | AV13: 34.742339 | AW13: 34.742339 | AX13: 0 | AY13: 3.8281215
A14: 97 | B14: 0.99620234 | C14: 8.8521007 | D14: 4.4632021 | E14: 0.0076941417 | F14: 0.0037976618 | G14: 0 | H14: 3.8637792 | I14: 3.8745511 | J14: -24.547966 | K14: 2.5749501 | L14: 14.34917 | M14: 6.9661342 | N14: 69.504712 | O14: 67.290785 | P14: 299077.72 | Q14: 278046.68 | R14: 782.79281 | S14: 0 | T14: 0 | U14: 0.059893911 | V14: 0.34156872 | W14: 0 | X14: 0.74353845 | Y14: 0 | Z14: 0.00028202297 | AA14: 3.183605e-05 | AB14: 0.0021957464 | AC14: 1.8329034e-08 | AD14: 0.0012880237 | AE14: 0.020230836 | AF14: 0.82736883 | AG14: 0.99877998 | AH14: 0.99996516 | AI14: 1 | AJ14: 1 | AK14: 1 | AL14: 1 | AM14: 0 | AN14: 0 | AO14: 09-1:0-5 | AP14: 0-5 | AQ14: 2.8507014e+10 | AR14: 102526 | AS14: 0 | AT14: 65.843128 | AU14: 65.843128 | AV14: 34.156872 | AW14: 34.156872 | AX14: 0 | AY14: 6.5534176
A15: 97 | B15: 0.995818 | C15: 10.904271 | D15: 4.9045654 | E15: 0.0095754262 | F15: 0.0041819996 | G15: 0 | H15: 3.9014199 | I15: 3.864134 | J15: -23.498066 | K15: 7.540442 | L15: 14.609501 | M15: 7.6447099 | N15: 68.92636 | O15: 66.691838 | P15: 293821.84 | Q15: 273049.64 | R15: 782.7708 | S15: 0 | T15: 0 | U15: 0.056353209 | V15: 0.3349724 | W15: 0 | X15: 0.74153986 | Y15: 0 | Z15: 0.000294315 | AA15: 3.5237191e-05 | AB15: 0.0023060552 | AC15: 4.8883762e-08 | AD15: 0.0015463292 | AE15: 0.019958804 | AF15: 0.81921162 | AG15: 0.99804752 | AH15: 0.99991392 | AI15: 0.99998862 | AJ15: 1 | AK15: 1 | AL15: 1 | AM15: 0 | AN15: 0 | AO15: 09-2:5-10 | AP15: 43230 | AQ15: 3.0239974e+10 | AR15: 110749 | AS15: 0 | AT15: 66.50276 | AU15: 66.50276 | AV15: 33.49724 | AW15: 33.49724 | AX15: 0 | AY15: 11.31499
A16: 97 | B16: 0.9952584 | C16: 14.002827 | D16: 5.5438582 | E16: 0.012492625 | F16: 0.0047416036 | G16: 0 | H16: 3.9578852 | I16: 3.8699165 | J16: -22.980733 | K16: 12.527276 | L16: 14.707416 | M16: 8.6019845 | N16: 69.31381 | O16: 66.948659 | P16: 292211.26 | Q16: 271327.41 | R16: 782.55568 | S16: 0 | T16: 0 | U16: 0.048480184 | V16: 0.32608776 | W16: 0 | X16: 0.74323334 | Y16: 0 | Z16: 0.00030836331 | AA16: 3.9228681e-05 | AB16: 0.0024557607 | AC16: 1.2838962e-07 | AD16: 0.0019381086 | AE16: 0.019745186 | AF16: 0.81163826 | AG16: 0.9967414 | AH16: 0.99972331 | AI16: 0.99995143 | AJ16: 1 | AK16: 1 | AL16: 1 | AM16: 0 | AN16: 0 | AO16: 09-3:10-15 | AP16: 43388 | AQ16: 3.4873712e+10 | AR16: 128530 | AS16: 0 | AT16: 67.38927 | AU16: 67.38927 | AV16: 32.61073 | AW16: 32.61073 | AX16: 0 | AY16: 19.077563
A17: 97 | B17: 0.99463567 | C17: 17.244109 | D17: 6.2506293 | E17: 0.015649174 | F17: 0.0053643298 | G17: 0 | H17: 4.0147816 | I17: 3.8798009 | J17: -22.760576 | K17: 17.528626 | L17: 14.725807 | M17: 9.7205173 | N17: 69.437098 | O17: 66.990268 | P17: 291290.28 | Q17: 271047.98 | R17: 782.6742 | S17: 0 | T17: 0 | U17: 0.042086768 | V17: 0.31382781 | W17: 0 | X17: 0.75251585 | Y17: 0 | Z17: 0.00032247629 | AA17: 4.3168092e-05 | AB17: 0.0025730807 | AC17: 2.5216964e-07 | AD17: 0.0024253388 | AE17: 0.018708914 | AF17: 0.80916352 | AG17: 0.99408256 | AH17: 0.99968214 | AI17: 0.99994157 | AJ17: 1 | AK17: 1 | AL17: 1 | AM17: 0 | AN17: 0 | AO17: 09-4:15-20 | AP17: 15-20 | AQ17: 3.8504534e+10 | AR17: 142058 | AS17: 0 | AT17: 68.614687 | AU17: 68.614687 | AV17: 31.385313 | AW17: 31.385313 | AX17: 0 | AY17: 32.921262
A18: 97 | B18: 0.99397648 | C18: 21.069423 | D18: 6.9935008 | E18: 0.019523686 | F18: 0.0060235197 | G18: 0 | H18: 4.043684 | I18: 3.8720952 | J18: -22.362804 | K18: 22.543948 | L18: 14.47741 | M18: 10.47453 | N18: 67.823588 | O18: 65.233278 | P18: 296099.13 | Q18: 275599.6 | R18: 782.70335 | S18: 0 | T18: 0 | U18: 0.040518232 | V18: 0.31265171 | W18: 0 | X18: 0.75911106 | Y18: 0 | Z18: 0.00033241406 | AA18: 4.5092679e-05 | AB18: 0.0026704932 | AC18: 5.2559592e-07 | AD18: 0.0029749807 | AE18: 0.020591337 | AF18: 0.79097261 | AG18: 0.99085171 | AH18: 0.99938978 | AI18: 0.999863 | AJ18: 1 | AK18: 1 | AL18: 1 | AM18: 0 | AN18: 0 | AO18: 09:0-25 | AP18: 0-25 | AQ18: 4.2866486e+10 | AR18: 155539 | AS18: 0 | AT18: 68.733949 | AU18: 68.733949 | AV18: 31.266051 | AW18: 31.266051 | AX18: 0 | AY18: 51.265645
A19: 97 | B19: 0.99334906 | C19: 23.063402 | D19: 7.6955562 | E19: 0.021612081 | F19: 0.0066509423 | G19: 0 | H19: 4.080554 | I19: 3.8625394 | J19: -21.393001 | K19: 27.523059 | L19: 14.579448 | M19: 11.278876 | N19: 68.399355 | O19: 65.529784 | P19: 294526.49 | Q19: 273743.06 | R19: 782.53593 | S19: 0 | T19: 0 | U19: 0.038080922 | V19: 0.31095846 | W19: 0 | X19: 0.75527821 | Y19: 0 | Z19: 0.00034120649 | AA19: 4.8394569e-05 | AB19: 0.002743361 | AC19: 8.3452158e-07 | AD19: 0.0035171324 | AE19: 0.022744783 | AF19: 0.77371183 | AG19: 0.98435998 | AH19: 0.99926501 | AI19: 0.99978341 | AJ19: 1 | AK19: 1 | AL19: 1 | AM19: 0 | AN19: 0 | AO19: 10-1:25-30 | AP19: 25-30 | AQ19: 4.3570041e+10 | AR19: 159164 | AS19: 0 | AT19: 68.902598 | AU19: 68.902598 | AV19: 31.097402 | AW19: 31.097402 | AX19: 0 | AY19: 73.319059
A20: 97 | B20: 0.99276784 | C20: 25.027503 | D20: 8.3415774 | E20: 0.023718264 | F20: 0.0072321641 | G20: 0 | H20: 4.1027406 | I20: 3.8402996 | J20: -20.75564 | K20: 32.511491 | L20: 14.592738 | M20: 11.839008 | N20: 68.156254 | O20: 65.177773 | P20: 293515.87 | Q20: 273384.45 | R20: 782.6238 | S20: 0 | T20: 0 | U20: 0.036990865 | V20: 0.31948025 | W20: 0 | X20: 0.75414459 | Y20: 0 | Z20: 0.00034765967 | AA20: 5.1752209e-05 | AB20: 0.0027994829 | AC20: 1.3959302e-06 | AD20: 0.0040318601 | AE20: 0.024530157 | AF20: 0.75628599 | AG20: 0.97965777 | AH20: 0.99872128 | AI20: 0.99974782 | AJ20: 1 | AK20: 1 | AL20: 1 | AM20: 0 | AN20: 0 | AO20: 10-2:30-35 | AP20: 30-35 | AQ20: 4.3981817e+10 | AR20: 160879 | AS20: 0 | AT20: 68.048233 | AU20: 68.048233 | AV20: 31.951767 | AW20: 31.951767 | AX20: 0 | AY20: 94.54859
A21: 97 | B21: 0.99209712 | C21: 27.830949 | D21: 9.0819204 | E21: 0.026813857 | F21: 0.0079028825 | G21: 0 | H21: 4.1348421 | I21: 3.827725 | J21: -20.038956 | K21: 37.477156 | L21: 14.487705 | M21: 12.607813 | N21: 67.879502 | O21: 64.682708 | P21: 295895.42 | Q21: 275423.54 | R21: 782.57786 | S21: 0 | T21: 0 | U21: 0.033245687 | V21: 0.31884608 | W21: 0 | X21: 0.74620281 | Y21: 0 | Z21: 0.0003534843 | AA21: 5.6024627e-05 | AB21: 0.0028690502 | AC21: 1.6527383e-06 | AD21: 0.0046226575 | AE21: 0.026445154 | AF21: 0.73125549 | AG21: 0.97947389 | AH21: 0.99839829 | AI21: 0.99967124 | AJ21: 1 | AK21: 1 | AL21: 1 | AM21: 0 | AN21: 0 | AO21: 10-3:35-40 | AP21: 35-40 | AQ21: 4.4207957e+10 | AR21: 160509 | AS21: 0 | AT21: 68.114534 | AU21: 68.114534 | AV21: 31.885466 | AW21: 31.885466 | AX21: 0 | AY21: 118.1742
A22: 97 | B22: 0.99144967 | C22: 31.45781 | D22: 9.7913692 | E22: 0.030986491 | F22: 0.0085503261 | G22: 0 | H22: 4.1831056 | I22: 3.8234898 | J22: -19.308467 | K22: 42.441471 | L22: 14.535832 | M22: 13.466146 | N22: 68.134365 | O22: 64.854192 | P22: 295673.58 | Q22: 274474.32 | R22: 782.37062 | S22: 0 | T22: 0 | U22: 0.029554947 | V22: 0.31628243 | W22: 0 | X22: 0.73742217 | Y22: 0 | Z22: 0.00035962518 | AA22: 6.1795145e-05 | AB22: 0.0029245869 | AC22: 2.2833316e-06 | AD22: 0.0052020225 | AE22: 0.026782477 | AF22: 0.72475109 | AG22: 0.97632537 | AH22: 0.99778689 | AI22: 0.9997711 | AJ22: 1 | AK22: 1 | AL22: 1 | AM22: 0 | AN22: 0 | AO22: 10-4:40-45 | AP22: 40-45 | AQ22: 4.0881577e+10 | AR22: 148945 | AS22: 0 | AT22: 68.371757 | AU22: 68.371757 | AV22: 31.628243 | AW22: 31.628243 | AX22: 0 | AY22: 144.31374
A23: 97 | B23: 0.99072239 | C23: 33.304222 | D23: 10.58225 | E23: 0.033189121 | F23: 0.0092776097 | G23: 0 | H23: 4.2389415 | I23: 3.8269869 | J23: -18.56358 | K23: 47.518166 | L23: 14.521738 | M23: 14.59814 | N23: 67.828227 | O23: 64.551916 | P23: 295745.68 | Q23: 274652.3 | R23: 782.20509 | S23: 0 | T23: 0 | U23: 0.023834157 | V23: 0.30543286 | W23: 0 | X23: 0.72540982 | Y23: 0 | Z23: 0.00036543652 | AA23: 6.9434013e-05 | AB23: 0.0030125581 | AC23: 2.5641522e-06 | AD23: 0.0058276038 | AE23: 0.0254136 | AF23: 0.72717763 | AG23: 0.97756361 | AH23: 0.99767709 | AI23: 0.9998045 | AJ23: 1 | AK23: 1 | AL23: 1 | AM23: 0 | AN23: 0 | AO23: 10:25-50 | AP23: 25-50 | AQ23: 3.919096e+10 | AR23: 142693 | AS23: 0 | AT23: 69.456714 | AU23: 69.456714 | AV23: 30.543286 | AW23: 30.543286 | AX23: 0 | AY23: 174.12595
A24: 97 | B24: 0.99008101 | C24: 33.412905 | D24: 11.274432 | E24: 0.033320507 | F24: 0.0099189865 | G24: 0 | H24: 4.3180088 | I24: 3.8417096 | J24: -17.463033 | K24: 52.504461 | L24: 14.887496 | M24: 16.089802 | N24: 69.557278 | O24: 66.210126 | P24: 289074.81 | Q24: 268000.81 | R24: 781.78016 | S24: 0 | T24: 0 | U24: 0.019533417 | V24: 0.29306856 | W24: 0 | X24: 0.70769 | Y24: 0 | Z24: 0.00037173065 | AA24: 8.2806942e-05 | AB24: 0.0031134834 | AC24: 2.6524879e-06 | AD24: 0.0063482996 | AE24: 0.021343834 | AF24: 0.74321936 | AG24: 0.97898505 | AH24: 0.99781394 | AI24: 0.99980767 | AJ24: 1 | AK24: 1 | AL24: 1 | AM24: 0 | AN24: 0 | AO24: 11-1:50-55 | AP24: 50-55 | AQ24: 3.5465887e+10 | AR24: 132335 | AS24: 0 | AT24: 70.693144 | AU24: 70.693144 | AV24: 29.306856 | AW24: 29.306856 | AX24: 0 | AY24: 205.96089
A25: 97 | B25: 0.98941934 | C25: 35.483123 | D25: 11.983369 | E25: 0.035861457 | F25: 0.01058066 | G25: 0 | H25: 4.3828476 | I25: 3.8523699 | J25: -17.323485 | K25: 57.483953 | L25: 15.128447 | M25: 17.615636 | N25: 69.370722 | O25: 66.117421 | P25: 284722.57 | Q25: 263601.22 | R25: 781.65219 | S25: 0 | T25: 0 | U25: 0.016827545 | V25: 0.27475101 | W25: 0 | X25: 0.70253618 | Y25: 0 | Z25: 0.00037826165 | AA25: 9.7685403e-05 | AB25: 0.0031965205 | AC25: 3.2926443e-06 | AD25: 0.0069048864 | AE25: 0.017894567 | AF25: 0.76065412 | AG25: 0.97939804 | AH25: 0.9974502 | AI25: 0.99959005 | AJ25: 1 | AK25: 1 | AL25: 1 | AM25: 0 | AN25: 0 | AO25: 11-2:55-60 | AP25: 55-60 | AQ25: 3.4266578e+10 | AR25: 129994 | AS25: 0 | AT25: 72.524899 | AU25: 72.524899 | AV25: 27.475101 | AW25: 27.475101 | AX25: 0 | AY25: 247.53419
A26: 97 | B26: 0.98867875 | C26: 36.916194 | D26: 12.770695 | E26: 0.037664536 | F26: 0.011321247 | G26: 0 | H26: 4.4570138 | I26: 3.873694 | J26: -17.37229 | K26: 62.493872 | L26: 15.300089 | M26: 19.219581 | N26: 69.640995 | O26: 66.478468 | P26: 281394.51 | Q26: 260887.2 | R26: 781.25669 | S26: 0 | T26: 0 | U26: 0.015796997 | V26: 0.25155199 | W26: 0 | X26: 0.69517778 | Y26: 0 | Z26: 0.00038188402 | AA26: 0.00011628449 | AB26: 0.003282456 | AC26: 3.3856391e-06 | AD26: 0.0075372228 | AE26: 0.012960875 | AF26: 0.77964598 | AG26: 0.98196677 | AH26: 0.99752558 | AI26: 0.99960562 | AJ26: 1 | AK26: 1 | AL26: 1 | AM26: 0 | AN26: 0 | AO26: 11-3:60-65 | AP26: 60-65 | AQ26: 3.5359608e+10 | AR26: 135536 | AS26: 0 | AT26: 74.844801 | AU26: 74.844801 | AV26: 25.155199 | AW26: 25.155199 | AX26: 0 | AY26: 297.70248
A27: 97 | B27: 0.98805992 | C27: 37.34521 | D27: 13.423621 | E27: 0.038211625 | F27: 0.011940076 | G27: 0 | H27: 4.5265381 | I27: 3.8931776 | J27: -17.357444 | K27: 67.507788 | L27: 15.524625 | M27: 20.507183 | N27: 69.628969 | O27: 66.643585 | P27: 277328.62 | Q27: 257076.01 | R27: 781.11713 | S27: 0 | T27: 0 | U27: 0.016723574 | V27: 0.23597175 | W27: 0 | X27: 0.69099868 | Y27: 0 | Z27: 0.00038698645 | AA27: 0.00013357149 | AB27: 0.0033189158 | AC27: 3.9252188e-06 | AD27: 0.0080966625 | AE27: 0.007362507 | AF27: 0.80371152 | AG27: 0.98172644 | AH27: 0.99727104 | AI27: 0.99956676 | AJ27: 1 | AK27: 1 | AL27: 1 | AM27: 0 | AN27: 0 | AO27: 11-4:65-70 | AP27: 65-70 | AQ27: 3.6614566e+10 | AR27: 142427 | AS27: 0 | AT27: 76.402825 | AU27: 76.402825 | AV27: 23.597175 | AW27: 23.597175 | AX27: 0 | AY27: 353.87949
A28: 97 | B28: 0.98724113 | C28: 38.800417 | D28: 14.280642 | E28: 0.040093265 | F28: 0.012758865 | G28: 0 | H28: 4.5629607 | I28: 3.8915188 | J28: -17.338162 | K28: 72.521817 | L28: 15.200947 | M28: 21.458715 | N28: 68.415455 | O28: 65.44972 | P28: 282548.22 | Q28: 262505.17 | R28: 781.02953 | S28: 0 | T28: 0 | U28: 0.016188388 | V28: 0.22642586 | W28: 0 | X28: 0.69552406 | Y28: 0 | Z28: 0.00038991503 | AA28: 0.00014459484 | AB28: 0.0033562306 | AC28: 4.5622395e-06 | AD28: 0.0088635481 | AE28: 0.0062719663 | AF28: 0.79883958 | AG28: 0.98129144 | AH28: 0.99689562 | AI28: 0.99964418 | AJ28: 1 | AK28: 1 | AL28: 1 | AM28: 0 | AN28: 0 | AO28: 11:50-75 | AP28: 50-75 | AQ28: 3.9348475e+10 | AR28: 149896 | AS28: 0 | AT28: 77.357414 | AU28: 77.357414 | AV28: 22.642586 | AW28: 22.642586 | AX28: 0 | AY28: 414.10153
... A36: 97 | B36: 0.96185187 | C36: 84.603245 | D36: 37.295557 | E36: 0.14437047 | F36: 0.038148132 | G36: 0 | H36: 5.75 | I36: 4.1387574 | J36: 54.4553 | K36: 254.14738 | L36: 23.888925 | M36: 31.426217 | N36: 95 | O36: 57.497761 | P36: 170045.7 | Q36: 166421.72 | R36: 782 | S36: 0 | T36: 0 | U36: 0 | V36: 0 | W36: 0 | X36: 0 | Y36: 0 | Z36: 0.0016004217 | AA36: 0.0016422781 | AB36: 0.0061079827 | AC36: 0 | AD36: 0.028797429 | AE36: -0.06000343 | AF36: 1 | AG36: 1 | AH36: 1 | AI36: 1 | AJ36: 1 | AK36: 1 | AL36: 1 | AM36: 0 | AN36: 0 | AO36: 999:>= 250 | AP36: >= 250 | AQ36: 332843.44 | AR36: 2 | AS36: 0 | AT36: 100 | AU36: 100 | AV36: 0 | AW36: 0 | AX36: 0 | AY36: 1089.0234
F40: high media
A41: modelId | B41: SFACTOR_PREPAY_TRACKING_CPR | C41: PREPAY_CPR1 | D41: PREPAY_TRACKING_CPR1 | E41: PREPAY_SMM1 | F41: PREPAY_TRACKING_SMM1 | G41: PCT_LOANTYPE | H41: _ORIGNOTERATE | I41: _ZEROSATO | J41: _SATO | K41: _REFI_INCENTIVE_Fixed | L41: _Fixed_cost | M41: _LOANAGE | N41: _LTV | O41: _CLTV | P41: _AVG_LOANSIZE_SCHAMBALANCE | Q41: _WACLS | R41: _FICO | S41: PCT_ISSECONDLIEN | T41: _OrigCombLTV | U41: PCT_SVC | V41: PCT_TPO | W41: PCT_GEO | X41: PCT_LOANPURPOSE | Y41: PCT_OCC | Z41: curtailsmm | AA41: defaultsmm | AB41: toverSmm | AC41: cashoutSmm | AD41: refiSmm | AE41: cumHPA | AF41: cumHPA05Pct | AG41: cumHPA15Pct | AH41: cumHPA20Pct | AI41: cumHPA25Pct | AJ41: cumHPA30Pct | AK41: cumHPA35Pct | AL41: cumHPA40Pct | AM41: adjtoverSmm | AN41: adjRefiSmm | AO41: groupByColumn | AP41: curve | AQ41: Balance | AR41: LoanCount | AS41: PCT_BROKER | AT41: PCT_CORRES | AU41: PCT_NonRETAIL | AV41: PCT_RETAIL | AW41: PCT_CashWindow | AX41: PCT_NonCashWindow | AY41: _Burnout_Fixed
A42: 96 | B42: 0.99833297 | C42: 0.26130405 | D42: 1.9821991 | E42: 0.0002180146 | F42: 0.0016670325 | G42: 0 | H42: 3.25 | I42: 3.7357636 | J42: -40.509727 | K42: -155.50095 | L42: 14.562552 | M42: 3.2725683 | N42: 80 | O42: 77.654292 | P42: 291131.11 | Q42: 274125.36 | R42: 774.19702 | S42: 0 | T42: 0 | U42: 0 | V42: 0.45074387 | W42: 0 | X42: 0 | Y42: 0 | Z42: 0.0001606861 | AA42: 5.3411715e-06 | AB42: 0.001500988 | AC42: 0 | AD42: 0 | AE42: 0.024554217 | AF42: 1 | AG42: 1 | AH42: 1 | AI42: 1 | AJ42: 1 | AK42: 1 | AL42: 1 | AM42: 0 | AN42: 0 | AO42: 02:-175--150 | AP42: =-175--150 -> -25 | AQ42: 822376.09 | AR42: 3 | AS42: 0 | AT42: 54.925613 | AU42: 54.925613 | AV42: 45.074387 | AW42: 45.074387 | AX42: 0 | AY42: 0
A43: 96 | B43: 0.99840708 | C43: 0.16230364 | D43: 1.8948401 | E43: 0.00013535375 | F43: 0.0015929152 | G43: 0 | H43: 3.5272566 | I43: 3.8043425 | J43: -22.033008 | K43: -133.73728 | L43: 15.318144 | M43: 4.2985068 | N43: 78.869899 | O43: 77.21009 | P43: 278644.18 | Q43: 260629.58 | R43: 780.52698 | S43: 0 | T43: 0 | U43: 0.044210759 | V43: 0.62073294 | W43: 0 | X43: 0.4786667 | Y43: 0 | Z43: 0.00021594279 | AA43: 1.9980674e-05 | AB43: 0.001338924 | AC43: 0 | AD43: 1.8054137e-05 | AE43: 0.013634735 | AF43: 0.95578924 | AG43: 1 | AH43: 1 | AI43: 1 | AJ43: 1 | AK43: 1 | AL43: 1 | AM43: 0 | AN43: 0 | AO43: 03:-150--125 | AP43: =-150--125 -> -25 | AQ43: 5994480.4 | AR43: 23 | AS43: 0 | AT43: 37.926706 | AU43: 37.926706 | AV43: 62.073294 | AW43: 62.073294 | AX43: 0 | AY43: 0
A44: 96 | B44: 0.99672241 | C44: 0.18121177 | D44: 3.8629782 | E44: 0.00015113537 | F44: 0.0032775921 | G44: 0 | H44: 3.6597934 | I44: 3.8379448 | J44: -23.588857 | K44: -109.75521 | L44: 15.30596 | M44: 4.9024314 | N44: 79.067811 | O44: 77.25009 | P44: 287089.08 | Q44: 248393.64 | R44: 779.35781 | S44: 0 | T44: 0 | U44: 0.066477551 | V44: 0.5786861 | W44: 0 | X44: 0.66174794 | Y44: 0 | Z44: 0.00026488139 | AA44: 2.0234425e-05 | AB44: 0.0014553005 | AC44: 0 | AD44: 0.0015371609 | AE44: 0.010841057 | AF44: 0.97253224 | AG44: 1 | AH44: 1 | AI44: 1 | AJ44: 1 | AK44: 1 | AL44: 1 | AM44: 0 | AN44: 0 | AO44: 04:-125--100 | AP44: =-125--100 -> -25 | AQ44: 24342577 | AR44: 98 | AS44: 0 | AT44: 42.13139 | AU44: 42.13139 | AV44: 57.86861 | AW44: 57.86861 | AX44: 0 | AY44: 0
