Workbook

Sheet Distribution of data
A1: count() | B1: bucket | I1: count() | J1: tag | K1: loansize | L1: fico | M1: lien | N1: invest | O1: cltv | P1: state | Q1: asOf | R1: Ticker | S1: Orig Date
A2: 1096925 | B2: 'Done' | C2: <= 417 >= 740 no lien no invest cltv <= 80 | I2: =SUM(Baseline!AR3:AR23) -> 22217161 | J2: Baseline | M2: no | N2: no | O2: <=80 | P2: not in ('NY','PR') | Q2: 20120101~20130401 | R2: All 4 | S2: post HARP
A3: 466351 | B3: 'FICO'
A4: 230769 | B4: '2nd Lien'
A5: 144409 | B5: 'INV'
A6: 124596 | B6: 'CLTV'
A7: 57525 | B7: 'Jumbo'
A8: 2 | B8: 'Not Done'
A10: =SUM(A2:A8) -> 2120577 | B10: total

Sheet Baseline
AS1: tover | AT1: cash | AU1: refi
A2: modelId | B2: SFACTOR_PREPAY_TRACKING_CPR | C2: PREPAY_CPR1 | D2: PREPAY_TRACKING_CPR1 | E2: PREPAY_SMM1 | F2: PREPAY_TRACKING_SMM1 | G2: PCT_LOANTYPE | H2: _ORIGNOTERATE | I2: _ZEROSATO | J2: _SATO | K2: _REFI_INCENTIVE_Fixed | L2: _Fixed_cost | M2: _LOANAGE | N2: _LTV | O2: _CLTV | P2: _AVG_LOANSIZE_SCHAMBALANCE | Q2: _WACLS | R2: _FICO | S2: PCT_ISSECONDLIEN | T2: _OrigCombLTV | U2: PCT_SVC | V2: PCT_TPO | W2: PCT_GEO | X2: PCT_LOANPURPOSE | Y2: PCT_OCC | Z2: curtailsmm | AA2: defaultsmm | AB2: toverSmm | AC2: cashoutSmm | AD2: refiSmm | AE2: cumHPA | AF2: cumHPA05Pct | AG2: cumHPA15Pct | AH2: cumHPA20Pct | AI2: cumHPA25Pct | AJ2: cumHPA30Pct | AK2: cumHPA35Pct | AL2: cumHPA40Pct | AM2: adjtoverSmm | AN2: adjRefiSmm | AO2: groupByColumn | AP2: curve | AQ2: Balance | AR2: LoanCount | AS2: 1 | AT2: 1 | AU2: 1
A3: 98 | B3: 0.99806849 | C3: 0.092090315 | D3: 2.2933469 | E3: 7.6774339e-05 | F3: 0.0019315099 | G3: 0 | H3: 3.4569557 | I3: 3.8259591 | J3: -31.051339 | K3: -210.10341 | L3: 84.205223 | M3: 3.5826897 | N3: 67.015166 | O3: 65.634357 | P3: 48707.682 | Q3: 46420.824 | R3: 624.54182 | S3: 0 | T3: 0 | U3: 0 | V3: 0.92203846 | W3: 0 | X3: 0.43761892 | Y3: 0 | Z3: 0.00024696394 | AA3: 3.1533414e-05 | AB3: 0.0016530022 | AC3: 0 | AD3: 0 | AE3: 0.014337635 | AF3: 0.97063516 | AG3: 1 | AH3: 1 | AI3: 1 | AJ3: 1 | AK3: 1 | AL3: 1 | AM3: 0 | AN3: 0 | AO3: 00:<= -200 | AP3: <= -200 | AQ3: 1299783.1 | AR3: 28 | AS3: =Z3+AA3+AB3*$AS$2+AC3*$AT$2+AD3*$AU$2 -> 0.0019314995 | AT3: =100*(1-(1-AS3)^12) -> 2.2933347 | AU3: =AT3-D3 -> -1.2111268e-05 | AV3: =G3-D3 -> -2.2933469 | AW3: =1-(1-D3/100)^(1/12) -> 0.0019315099 | AX3: =AW3-AS3 -> 1.0309665e-08
A4: 98 | B4: 0.99776068 | C4: 0.13796486 | D4: 2.6543391 | E4: 0.00011504348 | F4: 0.0022393246 | G4: 0 | H4: 3.5058606 | I4: 3.8063444 | J4: -34.537816 | K4: -183.49351 | L4: 66.102854 | M4: 4.3831729 | N4: 65.531613 | O4: 64.370228 | P4: 72495.237 | Q4: 57973.386 | R4: 620.14645 | S4: 0 | T4: 0 | U4: 0 | V4: 0.9693893 | W4: 0 | X4: 0.58817712 | Y4: 0 | Z4: 0.00021688998 | AA4: 7.6288097e-05 | AB4: 0.0019461369 | AC4: 0 | AD4: 0 | AE4: 0.012180986 | AF4: 0.93845464 | AG4: 1 | AH4: 1 | AI4: 1 | AJ4: 1 | AK4: 1 | AL4: 1 | AM4: 0 | AN4: 0 | AO4: 01:-200--175 | AP4: =-200--175 -> -25 | AQ4: 9681555.4 | AR4: 167 | AS4: =Z4+AA4+AB4*$AS$2+AC4*$AT$2+AD4*$AU$2 -> 0.002239315 | AT4: =100*(1-(1-AS4)^12) -> 2.6543279 | AU4: =AT4-D4 -> -1.1260369e-05
A5: 98 | B5: 0.99761863 | C5: 4.3222443 | D5: 2.8205094 | E5: 0.003675259 | F5: 0.0023813683 | G5: 0 | H5: 3.5629793 | I5: 3.8042961 | J5: -31.577849 | K5: -159.82718 | L5: 54.142286 | M5: 4.7900651 | N5: 68.671483 | O5: 67.126493 | P5: 106752.08 | Q5: 71270.183 | R5: 634.67306 | S5: 0 | T5: 0 | U5: 0.0015533315 | V5: 0.92093816 | W5: 0 | X5: 0.64684153 | Y5: 0 | Z5: 0.00023880255 | AA5: 4.2835961e-05 | AB5: 0.0020983206 | AC5: 0 | AD5: 1.3994478e-06 | AE5: 0.015362132 | AF5: 0.91473578 | AG5: 0.99837071 | AH5: 1 | AI5: 1 | AJ5: 1 | AK5: 1 | AL5: 1 | AM5: 0 | AN5: 0 | AO5: 02:-175--150 | AP5: =-175--150 -> -25 | AQ5: 52454854 | AR5: 736 | AS5: =Z5+AA5+AB5*$AS$2+AC5*$AT$2+AD5*$AU$2 -> 0.0023813586 | AT5: =100*(1-(1-AS5)^12) -> 2.8204981 | AU5: =AT5-D5 -> -1.1368105e-05
A6: 98 | B6: 0.99732882 | C6: 1.2749129 | D6: 3.1587394 | E6: 0.0010686866 | F6: 0.0026711791 | G6: 0 | H6: 3.7207187 | I6: 3.8306517 | J6: -19.908072 | K6: -134.65638 | L6: 47.082083 | M6: 4.9686064 | N6: 71.470345 | O6: 69.744362 | P6: 133631.3 | Q6: 82427.319 | R6: 648.51863 | S6: 0 | T6: 0 | U6: 0.018220658 | V6: 0.88050799 | W6: 0 | X6: 0.61708959 | Y6: 0 | Z6: 0.00024608812 | AA6: 3.8959847e-05 | AB6: 0.0022680289 | AC6: 2.8807664e-07 | AD6: 0.00011780309 | AE6: 0.016631309 | AF6: 0.91763825 | AG6: 0.99697658 | AH6: 0.99918748 | AI6: 1 | AJ6: 1 | AK6: 1 | AL6: 1 | AM6: 0 | AN6: 0 | AO6: 03:-150--125 | AP6: =-150--125 -> -25 | AQ6: 2.0821141e+08 | AR6: 2526 | AS6: =Z6+AA6+AB6*$AS$2+AC6*$AT$2+AD6*$AU$2 -> 0.002671168 | AT6: =100*(1-(1-AS6)^12) -> 3.1587265 | AU6: =AT6-D6 -> -1.2916068e-05
A7: 98 | B7: 0.99685939 | C7: 2.7571323 | D7: 3.7043098 | E7: 0.0023271668 | F7: 0.0031406097 | G7: 0 | H7: 3.8017651 | I7: 3.853782 | J7: -16.944442 | K7: -109.49499 | L7: 40.122735 | M7: 5.6155597 | N7: 73.128263 | O7: 71.309159 | P7: 165107.93 | Q7: 96961.937 | R7: 664.99815 | S7: 0 | T7: 0 | U7: 0.026523137 | V7: 0.79977422 | W7: 0 | X7: 0.59916573 | Y7: 0 | Z7: 0.00024879711 | AA7: 4.8420359e-05 | AB7: 0.002420932 | AC7: 4.3616789e-08 | AD7: 0.00042240581 | AE7: 0.015710025 | AF7: 0.91627132 | AG7: 0.99839816 | AH7: 0.99955775 | AI7: 0.99993372 | AJ7: 1 | AK7: 1 | AL7: 1 | AM7: 0 | AN7: 0 | AO7: 04:-125--100 | AP7: =-125--100 -> -25 | AQ7: 8.9204982e+08 | AR7: 9200 | AS7: =Z7+AA7+AB7*$AS$2+AC7*$AT$2+AD7*$AU$2 -> 0.003140599 | AT7: =100*(1-(1-AS7)^12) -> 3.7042973 | AU7: =AT7-D7 -> -1.2498914e-05
A8: 98 | B8: 0.9965171 | C8: 2.992061 | D8: 4.100342 | E8: 0.0025282457 | F8: 0.0034829015 | G8: 0 | H8: 3.8241908 | I8: 3.8772392 | J8: -18.732559 | K8: -84.411816 | L8: 36.933092 | M8: 6.2667887 | N8: 73.943831 | O8: 72.201543 | P8: 166104.26 | Q8: 106231.51 | R8: 689.51474 | S8: 0 | T8: 0 | U8: 0.039425428 | V8: 0.71877499 | W8: 0 | X8: 0.55214232 | Y8: 0 | Z8: 0.00025585705 | AA8: 5.237498e-05 | AB8: 0.0024956458 | AC8: 1.2493931e-07 | AD8: 0.00067888802 | AE8: 0.012887689 | AF8: 0.92985017 | AG8: 0.9980393 | AH8: 0.99973629 | AI8: 0.99996548 | AJ8: 1 | AK8: 1 | AL8: 1 | AM8: 0 | AN8: 0 | AO8: 05:-100--75 | AP8: =-100--75 -> -25 | AQ8: 3.9263167e+09 | AR8: 36960 | AS8: =Z8+AA8+AB8*$AS$2+AC8*$AT$2+AD8*$AU$2 -> 0.0034828908 | AT8: =100*(1-(1-AS8)^12) -> 4.1003298 | AU8: =AT8-D8 -> -1.2261101e-05
A9: 98 | B9: 0.99687647 | C9: 3.0077223 | D9: 3.684505 | E9: 0.0025416663 | F9: 0.0031235263 | G9: 0 | H9: 3.7987734 | I9: 3.9120659 | J9: -24.303316 | K9: -59.172205 | L9: 31.062558 | M9: 5.9580022 | N9: 74.369318 | O9: 72.67932 | P9: 189029.78 | Q9: 127097.14 | R9: 727.42314 | S9: 0 | T9: 0 | U9: 0.073630733 | V9: 0.5837367 | W9: 0 | X9: 0.52730184 | Y9: 0 | Z9: 0.00024742279 | AA9: 4.5071191e-05 | AB9: 0.0023466594 | AC9: 1.1780021e-07 | AD9: 0.00048424477 | AE9: 0.011775561 | AF9: 0.94189802 | AG9: 0.99880773 | AH9: 0.99983918 | AI9: 0.99998589 | AJ9: 0.99999998 | AK9: 1 | AL9: 1 | AM9: 0 | AN9: 0 | AO9: 06:-75--50 | AP9: =-75--50 -> -25 | AQ9: 1.9323213e+10 | AR9: 152035 | AS9: =Z9+AA9+AB9*$AS$2+AC9*$AT$2+AD9*$AU$2 -> 0.0031235159 | AT9: =100*(1-(1-AS9)^12) -> 3.6844929 | AU9: =AT9-D9 -> -1.2056098e-05
A10: 98 | B10: 0.99635378 | C10: 3.0465129 | D10: 4.2887765 | E10: 0.0025749156 | F10: 0.003646221 | G10: 0 | H10: 3.8147644 | I10: 3.9385801 | J10: -26.943148 | K10: -34.356062 | L10: 24.159281 | M10: 5.8762244 | N10: 72.298183 | O10: 70.509369 | P10: 229148.32 | Q10: 164440.23 | R10: 754.61184 | S10: 0 | T10: 0 | U10: 0.13975763 | V10: 0.45987101 | W10: 0 | X10: 0.61722512 | Y10: 0 | Z10: 0.00024573447 | AA10: 3.8118664e-05 | AB10: 0.0022919001 | AC10: 1.0216152e-07 | AD10: 0.0010703511 | AE10: 0.014552108 | AF10: 0.91839615 | AG10: 0.99898628 | AH10: 0.99988081 | AI10: 0.99997991 | AJ10: 1 | AK10: 1 | AL10: 1 | AM10: 0 | AN10: 0 | AO10: 07:-50--25 | AP10: =-50--25 -> -25 | AQ10: 9.815717e+10 | AR10: 596917 | AS10: =Z10+AA10+AB10*$AS$2+AC10*$AT$2+AD10*$AU$2 -> 0.0036462065 | AT10: =100*(1-(1-AS10)^12) -> 4.2887597 | AU10: =AT10-D10 -> -1.6744106e-05
A11: 98 | B11: 0.99334296 | C11: 5.2697496 | D11: 7.7023516 | E11: 0.0045012392 | F11: 0.0066570367 | G11: 0 | H11: 3.8997695 | I11: 3.9244333 | J11: -23.784484 | K11: -10.820083 | L11: 19.797883 | M11: 6.9226044 | N11: 68.57088 | O11: 66.568097 | P11: 271664.65 | Q11: 200930.81 | R11: 764.9943 | S11: 0 | T11: 0 | U11: 0.15402655 | V11: 0.41729223 | W11: 0 | X11: 0.72158606 | Y11: 0 | Z11: 0.00027101314 | AA11: 4.0886132e-05 | AB11: 0.0024542207 | AC11: 1.1884696e-07 | AD11: 0.0038907835 | AE11: 0.017736578 | AF11: 0.8542861 | AG11: 0.99868628 | AH11: 0.99983324 | AI11: 0.99997476 | AJ11: 1 | AK11: 1 | AL11: 1 | AM11: 0 | AN11: 0 | AO11: 08:-25-0 | AP11: =-25-0 -> -25 | AQ11: 3.2765687e+11 | AR11: 1630695 | AS11: =Z11+AA11+AB11*$AS$2+AC11*$AT$2+AD11*$AU$2 -> 0.0066570223 | AT11: =100*(1-(1-AS11)^12) -> 7.7023356 | AU11: =AT11-D11 -> -1.6047219e-05
A12: 98 | B12: 0.98826856 | C12: 14.230549 | D12: 13.203989 | E12: 0.0127108 | F12: 0.011731437 | G12: 0 | H12: 4.092106 | I12: 3.9055033 | J12: -17.959354 | K12: 13.555598 | L12: 19.269107 | M12: 10.06682 | N12: 67.645969 | O12: 65.338776 | P12: 274763.8 | Q12: 206665.96 | R12: 766.06867 | S12: 0 | T12: 0 | U12: 0.094194071 | V12: 0.44876224 | W12: 0 | X12: 0.75055309 | Y12: 0 | Z12: 0.00032098313 | AA12: 5.9362939e-05 | AB12: 0.002908468 | AC12: 5.1754544e-07 | AD12: 0.0084420919 | AE12: 0.016974883 | AF12: 0.80684778 | AG12: 0.99343143 | AH12: 0.99937511 | AI12: 0.99986742 | AJ12: 1 | AK12: 1 | AL12: 1 | AM12: 0 | AN12: 0 | AO12: 09:0-25 | AP12: 0-25 | AQ12: 5.8444183e+11 | AR12: 2827954 | AS12: =Z12+AA12+AB12*$AS$2+AC12*$AT$2+AD12*$AU$2 -> 0.011731424 | AT12: =100*(1-(1-AS12)^12) -> 13.203975 | AU12: =AT12-D12 -> -1.4610197e-05
A13: 98 | B13: 0.98149776 | C13: 23.084292 | D13: 20.077 | E13: 0.021634221 | F13: 0.018502236 | G13: 0 | H13: 4.3013655 | I13: 3.8907638 | J13: -12.962709 | K13: 37.537227 | L13: 19.082687 | M13: 13.903486 | N13: 66.898751 | O13: 64.143027 | P13: 279145.36 | Q13: 208659.87 | R13: 765.4327 | S13: 0 | T13: 0 | U13: 0.060224109 | V13: 0.4837846 | W13: 0 | X13: 0.75792403 | Y13: 0 | Z13: 0.00035648606 | AA13: 9.1421628e-05 | AB13: 0.0032866486 | AC13: 1.9370144e-06 | AD13: 0.014765729 | AE13: 0.018127673 | AF13: 0.76245016 | AG13: 0.98164697 | AH13: 0.99828672 | AI13: 0.99972066 | AJ13: 1 | AK13: 1 | AL13: 1 | AM13: 0 | AN13: 0 | AO13: 10:25-50 | AP13: 25-50 | AQ13: 7.472229e+11 | AR13: 3581057 | AS13: =Z13+AA13+AB13*$AS$2+AC13*$AT$2+AD13*$AU$2 -> 0.018502222 | AT13: =100*(1-(1-AS13)^12) -> 20.076987 | AU13: =AT13-D13 -> -1.322679e-05
A14: 98 | B14: 0.97492846 | C14: 28.839474 | D14: 26.26512 | E14: 0.027954496 | F14: 0.02507154 | G14: 0 | H14: 4.5960169 | I14: 3.9180779 | J14: -9.2438109 | K14: 62.796666 | L14: 20.299243 | M14: 19.677076 | N14: 67.019398 | O14: 64.363632 | P14: 260390.45 | Q14: 196254.87 | R14: 763.12414 | S14: 0 | T14: 0 | U14: 0.03594444 | V14: 0.51021173 | W14: 0 | X14: 0.74362544 | Y14: 0 | Z14: 0.00038391033 | AA14: 0.00016132671 | AB14: 0.0037636712 | AC14: 3.668686e-06 | AD14: 0.020758949 | AE14: 0.0058391084 | AF14: 0.79667798 | AG14: 0.98225323 | AH14: 0.99760974 | AI14: 0.99963778 | AJ14: 1 | AK14: 1 | AL14: 1 | AM14: 0 | AN14: 0 | AO14: 11:50-75 | AP14: 50-75 | AQ14: 770690893908 | AR14: 3926990 | AS14: =Z14+AA14+AB14*$AS$2+AC14*$AT$2+AD14*$AU$2 -> 0.025071526 | AT14: =100*(1-(1-AS14)^12) -> 26.265107 | AU14: =AT14-D14 -> -1.2799557e-05
A15: 98 | B15: 0.96936611 | C15: 33.406296 | D15: 31.15792 | E15: 0.033312512 | F15: 0.030633891 | G15: 0 | H15: 4.791122 | I15: 3.8841704 | J15: -4.6873593 | K15: 86.878109 | L15: 20.239311 | M15: 23.783221 | N15: 66.368215 | O15: 63.494071 | P15: 262190.68 | Q15: 196925.56 | R15: 761.61047 | S15: 0 | T15: 0 | U15: 0.036516799 | V15: 0.53617257 | W15: 0 | X15: 0.7437349 | Y15: 0 | Z15: 0.00039716039 | AA15: 0.00023615771 | AB15: 0.0040716785 | AC15: 6.18061e-06 | AD15: 0.025922699 | AE15: 0.0030144264 | AF15: 0.79352002 | AG15: 0.97934279 | AH15: 0.99674262 | AI15: 0.99955088 | AJ15: 1 | AK15: 1 | AL15: 1 | AM15: 0 | AN15: 0 | AO15: 12:75-100 | AP15: 75-100 | AQ15: 7.1288529e+11 | AR15: 3620075 | AS15: =Z15+AA15+AB15*$AS$2+AC15*$AT$2+AD15*$AU$2 -> 0.030633876 | AT15: =100*(1-(1-AS15)^12) -> 31.157908 | AU15: =AT15-D15 -> -1.2518001e-05
A16: 98 | B16: 0.96578006 | C16: 35.639811 | D16: 34.152573 | E16: 0.036056803 | F16: 0.034219941 | G16: 0 | H16: 4.956288 | I16: 3.8076926 | J16: 0.39050219 | K16: 112.14473 | L16: 20.65996 | M16: 27.802723 | N16: 67.357672 | O16: 63.940192 | P16: 251518.28 | Q16: 193033.21 | R16: 760.01571 | S16: 0 | T16: 0 | U16: 0.038827873 | V16: 0.54406378 | W16: 0 | X16: 0.7244486 | Y16: 0 | Z16: 0.0004100959 | AA16: 0.00035096382 | AB16: 0.0043468884 | AC16: 1.046485e-05 | AD16: 0.029101513 | AE16: 0.005152293 | AF16: 0.78441536 | AG16: 0.97611389 | AH16: 0.99567029 | AI16: 0.99927908 | AJ16: 1 | AK16: 1 | AL16: 1 | AM16: 0 | AN16: 0 | AO16: 13:100-125 | AP16: 100-125 | AQ16: 5.7471005e+11 | AR16: 2977260 | AS16: =Z16+AA16+AB16*$AS$2+AC16*$AT$2+AD16*$AU$2 -> 0.034219926 | AT16: =100*(1-(1-AS16)^12) -> 34.152561 | AU16: =AT16-D16 -> -1.2314844e-05
A17: 98 | B17: 0.96184914 | C17: 37.643354 | D17: 37.297688 | E17: 0.038593851 | F17: 0.038150856 | G17: 0 | H17: 5.0854574 | I17: 3.735274 | J17: 6.4569428 | K17: 135.9264 | L17: 19.61892 | M17: 30.983888 | N17: 67.344642 | O17: 63.348267 | P17: 263489.46 | Q17: 203342.24 | R17: 758.42407 | S17: 0 | T17: 0 | U17: 0.043427291 | V17: 0.54957219 | W17: 0 | X17: 0.72778022 | Y17: 0 | Z17: 0.00041909082 | AA17: 0.00047007054 | AB17: 0.0043074939 | AC17: 1.4602354e-05 | AD17: 0.032939584 | AE17: 0.010922763 | AF17: 0.76300385 | AG17: 0.97215272 | AH17: 0.99449153 | AI17: 0.9992527 | AJ17: 1 | AK17: 1 | AL17: 1 | AM17: 0 | AN17: 0 | AO17: 14:125-150 | AP17: 125-150 | AQ17: 3.6452105e+11 | AR17: 1792648 | AS17: =Z17+AA17+AB17*$AS$2+AC17*$AT$2+AD17*$AU$2 -> 0.038150841 | AT17: =100*(1-(1-AS17)^12) -> 37.297677 | AU17: =AT17-D17 -> -1.1894442e-05
A18: 98 | B18: 0.96064058 | C18: 37.308279 | D18: 38.236609 | E18: 0.038164395 | F18: 0.039359422 | G18: 0 | H18: 5.2855985 | I18: 3.7024559 | J18: 21.181201 | K18: 160.76807 | L18: 19.601503 | M18: 33.659577 | N18: 68.637572 | O18: 64.320748 | P18: 263101.08 | Q18: 203543.53 | R18: 754.91787 | S18: 0 | T18: 0 | U18: 0.044097438 | V18: 0.57795406 | W18: 0 | X18: 0.73390816 | Y18: 0 | Z18: 0.00042920481 | AA18: 0.00070972241 | AB18: 0.0043514435 | AC18: 1.6244167e-05 | AD18: 0.033852792 | AE18: 0.011331964 | AF18: 0.76945711 | AG18: 0.97318186 | AH18: 0.994393 | AI18: 0.99914984 | AJ18: 1 | AK18: 1 | AL18: 1 | AM18: 0 | AN18: 0 | AO18: 15:150-175 | AP18: 150-175 | AQ18: 1.5855552e+11 | AR18: 778976 | AS18: =Z18+AA18+AB18*$AS$2+AC18*$AT$2+AD18*$AU$2 -> 0.039359407 | AT18: =100*(1-(1-AS18)^12) -> 38.236597 | AU18: =AT18-D18 -> -1.1790156e-05
A19: 98 | B19: 0.95882957 | C19: 37.281344 | D19: 39.619455 | E19: 0.038129965 | F19: 0.04117043 | G19: 0 | H19: 5.4479177 | I19: 3.6793061 | J19: 36.051659 | K19: 184.3137 | L19: 18.30781 | M19: 35.854217 | N19: 68.779815 | O19: 63.935762 | P19: 285327.35 | Q19: 217825.44 | R19: 753.53227 | S19: 0 | T19: 0 | U19: 0.048056833 | V19: 0.57387732 | W19: 0 | X19: 0.74297823 | Y19: 0 | Z19: 0.00043881353 | AA19: 0.00091418706 | AB19: 0.004184 | AC19: 2.7898943e-05 | AD19: 0.035605516 | AE19: 0.016435228 | AF19: 0.73657635 | AG19: 0.96562999 | AH19: 0.99026845 | AI19: 0.99857479 | AJ19: 1 | AK19: 1 | AL19: 1 | AM19: 0 | AN19: 0 | AO19: 16:175-200 | AP19: 175-200 | AQ19: 4.8694441e+10 | AR19: 223548 | AS19: =Z19+AA19+AB19*$AS$2+AC19*$AT$2+AD19*$AU$2 -> 0.041170415 | AT19: =100*(1-(1-AS19)^12) -> 39.619444 | AU19: =AT19-D19 -> -1.1548306e-05
A20: 98 | B20: 0.96229009 | C20: 33.99807 | D20: 36.951876 | E20: 0.034031303 | F20: 0.037709908 | G20: 0 | H20: 5.6692933 | I20: 3.6801605 | J20: 57.971358 | K20: 209.47668 | L20: 19.62848 | M20: 37.124704 | N20: 71.347138 | O20: 65.753368 | P20: 274581.62 | Q20: 203001.94 | R20: 747.79701 | S20: 0 | T20: 0 | U20: 0.041761584 | V20: 0.57622509 | W20: 0 | X20: 0.72145098 | Y20: 0 | Z20: 0.00044848196 | AA20: 0.0011513451 | AB20: 0.0043530187 | AC20: 5.3544943e-05 | AD20: 0.031703502 | AE20: 0.022257897 | AF20: 0.70474574 | AG20: 0.94604557 | AH20: 0.98192147 | AI20: 0.99679256 | AJ20: 1 | AK20: 1 | AL20: 1 | AM20: 0 | AN20: 0 | AO20: 17:200-225 | AP20: 200-225 | AQ20: 9.6724336e+09 | AR20: 47647 | AS20: =Z20+AA20+AB20*$AS$2+AC20*$AT$2+AD20*$AU$2 -> 0.037709893 | AT20: =100*(1-(1-AS20)^12) -> 36.951864 | AU20: =AT20-D20 -> -1.2079908e-05
A21: 98 | B21: 0.96374565 | C21: 34.60653 | D21: 35.797911 | E21: 0.034776548 | F21: 0.036254351 | G21: 0 | H21: 5.8339386 | I21: 3.6733633 | J21: 74.859506 | K21: 234.09083 | L21: 19.311055 | M21: 37.518983 | N21: 73.738855 | O21: 67.068518 | P21: 283698.14 | Q21: 206436.36 | R21: 744.02081 | S21: 0 | T21: 0 | U21: 0.039948662 | V21: 0.57985751 | W21: 0 | X21: 0.69584656 | Y21: 0 | Z21: 0.00045645534 | AA21: 0.0015258347 | AB21: 0.0043354417 | AC21: 8.7785584e-05 | AD21: 0.029848819 | AE21: 0.033306719 | AF21: 0.64441777 | AG21: 0.9164811 | AH21: 0.97021915 | AI21: 0.99648925 | AJ21: 1 | AK21: 1 | AL21: 1 | AM21: 0 | AN21: 0 | AO21: 18:225-250 | AP21: 225-250 | AQ21: 1.9687836e+09 | AR21: 9537 | AS21: =Z21+AA21+AB21*$AS$2+AC21*$AT$2+AD21*$AU$2 -> 0.036254336 | AT21: =100*(1-(1-AS21)^12) -> 35.797898 | AU21: =AT21-D21 -> -1.2253833e-05
A22: 98 | B22: 0.99445562 | C22: 9.3464518 | D22: 6.4540758 | E22: 0.0081437509 | F22: 0.0055443814 | G22: 0 | H22: 5.0704588 | I22: 3.8715771 | J22: 30.320976 | K22: 22.163272 | L22: 68.510263 | M22: 65.745878 | N22: 204858.77 | O22: 152149.08 | P22: 521.10781 | Q22: 0 | R22: 0 | S22: 0.017875035 | T22: 0.96176481 | U22: 0 | V22: 0.9529481 | W22: 0 | X22: 0.00037915454 | Y22: 0.00060823388 | Z22: 0.0045569835 | AA22: 0 | AB22: 0 | AC22: 0.010175269 | AD22: 0.78892998 | AE22: 0.98033617 | AF22: 0.99564632 | AG22: 0.99962063 | AH22: 1 | AI22: 1 | AJ22: 1 | AK22: 0 | AL22: 0 | AM22: 9999 | AN22: 9999 | AO22: 9.9338134e+08 | AP22: 6529 | AS22: =Z22+AA22+AB22*$AS$2+AC22*$AT$2+AD22*$AU$2 -> 0.80366224 | AT22: =100*(1-(1-AS22)^12) -> 100 | AU22: =AT22-D22 -> 93.545924
A23: 98 | B23: 0.96536522 | C23: 40.155376 | D23: 34.491179 | E23: 0.041882524 | F23: 0.034634778 | G23: 0 | H23: 6.05283 | I23: 3.6813876 | J23: 97.903876 | K23: 266.60609 | L23: 19.706999 | M23: 37.195258 | N23: 77.555809 | O23: 69.301072 | P23: 283929.01 | Q23: 202298.86 | R23: 737.62142 | S23: 0 | T23: 0 | U23: 0.033945458 | V23: 0.6058772 | W23: 0 | X23: 0.68939494 | Y23: 0 | Z23: 0.00046863604 | AA23: 0.0016635186 | AB23: 0.0044681419 | AC23: 0.00013057364 | AD23: 0.027903893 | AE23: 0.04962426 | AF23: 0.55533571 | AG23: 0.86195429 | AH23: 0.95911828 | AI23: 0.99498918 | AJ23: 1 | AK23: 1 | AL23: 1 | AM23: 0 | AN23: 0 | AO23: 999:>= 250 | AP23: >= 250 | AQ23: 4.4606898e+08 | AR23: 2205 | AS23: =Z23+AA23+AB23*$AS$2+AC23*$AT$2+AD23*$AU$2 -> 0.034634763 | AT23: =100*(1-(1-AS23)^12) -> 34.491166 | AU23: =AT23-D23 -> -1.2743933e-05
K26: turn | L26: cash | M26: refi | R26: turn | W26: cash | AB26: refi
A27: incentive | B27: =AQ2 -> Balance | C27: =AO2 -> groupByColumn | D27: =E2 -> PREPAY_SMM1 | E27: =F2 -> PREPAY_TRACKING_SMM1 | F27: ratio | G27: =C2 -> PREPAY_CPR1 | H27: =D2 -> PREPAY_TRACKING_CPR1 | K27: adj | L27: adj | M27: adj | N27: mdl_smm | O27: mdl_cpr | P27: ratio | R27: x | T27: Knot | U27: adj Knot | W27: x | X27: adj x | Y27: Knot | Z27: adj Knot | AB27: x | AC27: adj x | AD27: Knot | AE27: adj Knot
A28: =K3 -> -210.10341 | B28: =AQ3/1000000000 -> 0.0012997831 | C28: =AO3 -> 00:<= -200 | D28: =E3 -> 7.6774339e-05 | E28: =Z3+AA3+AB3+AC3+AD3 -> 0.0019314995 | F28: =D28/E28 -> 0.039748567 | G28: =(1-(1-D28)^12)*100 -> 0.092090315 | H28: =(1-(1-E28)^12)*100 -> 2.2933347 | K28: 0.62 | L28: 1 | M28: 1 | N28: =Z3+AA3+AB3*K28+AC3*L28+AD3*M28 -> 0.0013033587 | O28: =100*(1-(1-N28)^12) -> 1.5528673 | P28: =D28/N28 -> 0.058904995 | R28: -300 | S28: =A28 -> -210.10341 | T28: =VLOOKUP(ROUNDDOWN(S28,0),'Spline Pre-Adj'!A:B,2,0) -> 0.8313445 | U28: =T28*K28 -> 0.51543359 | W28: -300 | X28: =A28 -> -210.10341 | Y28: =VLOOKUP(ROUNDDOWN(X28,0),'Spline Pre-Adj'!F:G,2,0) -> 0 | Z28: =Y28*L28 -> 0
A29: =K4 -> -183.49351 | B29: =AQ4/1000000000 -> 0.0096815554 | C29: =AO4 -> 01:-200--175 | D29: =E4 -> 0.00011504348 | E29: =Z4+AA4+AB4+AC4+AD4 -> 0.002239315 | F29: =D29/E29 -> 0.051374409 | G29: =(1-(1-D29)^12)*100 -> 0.13796486 | H29: =(1-(1-E29)^12)*100 -> 2.6543279 | K29: 0.62 | L29: 1 | M29: 1 | N29: =Z4+AA4+AB4*K29+AC4*L29+AD4*M29 -> 0.001499783 | O29: =100*(1-(1-N29)^12) -> 1.7849678 | P29: =D29/N29 -> 0.076706756 | R29: -200 | S29: =A29 -> -183.49351 | T29: =VLOOKUP(ROUNDDOWN(S29,0),'Spline Pre-Adj'!A:B,2,0) -> 0.86903552 | U29: =T29*K29 -> 0.53880202
A30: =K5 -> -159.82718 | B30: =AQ5/1000000000 -> 0.052454854 | C30: =AO5 -> 02:-175--150 | D30: =E5 -> 0.003675259 | E30: =Z5+AA5+AB5+AC5+AD5 -> 0.0023813586 | F30: =D30/E30 -> 1.5433455 | G30: =(1-(1-D30)^12)*100 -> 4.3222443 | H30: =(1-(1-E30)^12)*100 -> 2.8204981 | K30: 0.62 | L30: 1 | M30: 1 | N30: =Z5+AA5+AB5*K30+AC5*L30+AD5*M30 -> 0.0015839967 | O30: =100*(1-(1-N30)^12) -> 1.8843235 | P30: =D30/N30 -> 2.3202441 | S30: =A30 -> -159.82718 | T30: =VLOOKUP(ROUNDDOWN(S30,0),'Spline Pre-Adj'!A:B,2,0) -> 0.90492421 | U30: =T30*K30 -> 0.56105301 | W30: -150 | X30: =A30 -> -159.82718 | Y30: =VLOOKUP(ROUNDDOWN(X30,0),'Spline Pre-Adj'!F:G,2,0) -> 0 | Z30: =Y30*L30 -> 0
A31: =K6 -> -134.65638 | B31: =AQ6/1000000000 -> 0.20821141 | C31: =AO6 -> 03:-150--125 | D31: =E6 -> 0.0010686866 | E31: =Z6+AA6+AB6+AC6+AD6 -> 0.002671168 | F31: =D31/E31 -> 0.40008214 | G31: =(1-(1-D31)^12)*100 -> 1.2749129 | H31: =(1-(1-E31)^12)*100 -> 3.1587265 | K31: 0.62 | L31: 1 | M31: 1 | N31: =Z6+AA6+AB6*K31+AC6*L31+AD6*M31 -> 0.001809317 | O31: =100*(1-(1-N31)^12) -> 2.1497043 | P31: =D31/N31 -> 0.59065746 | S31: =A31 -> -134.65638 | T31: =VLOOKUP(ROUNDDOWN(S31,0),'Spline Pre-Adj'!A:B,2,0) -> 0.95169666 | U31: =T31*K31 -> 0.59005193
A32: =K7 -> -109.49499 | B32: =AQ7/1000000000 -> 0.89204982 | C32: =AO7 -> 04:-125--100 | D32: =E7 -> 0.0023271668 | E32: =Z7+AA7+AB7+AC7+AD7 -> 0.003140599 | F32: =D32/E32 -> 0.74099458 | G32: =(1-(1-D32)^12)*100 -> 2.7571323 | H32: =(1-(1-E32)^12)*100 -> 3.7042973 | K32: 0.62 | L32: 1 | M32: 1 | N32: =Z7+AA7+AB7*K32+AC7*L32+AD7*M32 -> 0.0022206448 | O32: =100*(1-(1-N32)^12) -> 2.6324671 | P32: =D32/N32 -> 1.047969 | R32: -100 | S32: =A32 -> -109.49499 | T32: =VLOOKUP(ROUNDDOWN(S32,0),'Spline Pre-Adj'!A:B,2,0) -> 1.0160041 | U32: =T32*K32 -> 0.62992255 | AB32: -116 | AC32: =A32 -> -109.49499 | AD32: =VLOOKUP(ROUNDDOWN(AC32,0),'Spline Pre-Adj'!K:L,2,0) -> 0 | AE32: =AD32*M32 -> 0
A33: =K8 -> -84.411816 | B33: =AQ8/1000000000 -> 3.9263167 | C33: =AO8 -> 05:-100--75 | D33: =E8 -> 0.0025282457 | E33: =Z8+AA8+AB8+AC8+AD8 -> 0.0034828908 | F33: =D33/E33 -> 0.72590437 | G33: =(1-(1-D33)^12)*100 -> 2.992061 | H33: =(1-(1-E33)^12)*100 -> 4.1003298 | K33: 0.62 | L33: 1 | M33: 1 | N33: =Z8+AA8+AB8*K33+AC8*L33+AD8*M33 -> 0.0025345454 | O33: =100*(1-(1-N33)^12) -> 2.9994128 | P33: =D33/N33 -> 0.99751445 | S33: =A33 -> -84.411816 | T33: =VLOOKUP(ROUNDDOWN(S33,0),'Spline Pre-Adj'!A:B,2,0) -> 1.1287852 | U33: =T33*K33 -> 0.69984683 | W33: -92 | X33: =A33 -> -84.411816 | Y33: =VLOOKUP(ROUNDDOWN(X33,0),'Spline Pre-Adj'!F:G,2,0) -> 0.025380127 | Z33: =Y33*L33 -> 0.025380127 | AC33: =A33 -> -84.411816 | AD33: =VLOOKUP(ROUNDDOWN(AC33,0),'Spline Pre-Adj'!K:L,2,0) -> 0 | AE33: =AD33*M33 -> 0
A34: =K9 -> -59.172205 | B34: =AQ9/1000000000 -> 19.323213 | C34: =AO9 -> 06:-75--50 | D34: =E9 -> 0.0025416663 | E34: =Z9+AA9+AB9+AC9+AD9 -> 0.0031235159 | F34: =D34/E34 -> 0.81371965 | G34: =(1-(1-D34)^12)*100 -> 3.0077223 | H34: =(1-(1-E34)^12)*100 -> 3.6844929 | K34: 0.72 | L34: 1 | M34: 1 | N34: =Z9+AA9+AB9*K34+AC9*L34+AD9*M34 -> 0.0024664513 | O34: =100*(1-(1-N34)^12) -> 2.9199195 | P34: =D34/N34 -> 1.0304952 | R34: -50 | S34: =A34 -> -59.172205 | T34: =VLOOKUP(ROUNDDOWN(S34,0),'Spline Pre-Adj'!A:B,2,0) -> 1.2708434 | U34: =T34*K34 -> 0.91500726 | W34: -69 | X34: =A34 -> -59.172205 | Y34: =VLOOKUP(ROUNDDOWN(X34,0),'Spline Pre-Adj'!F:G,2,0) -> 0.17428261 | Z34: =Y34*L34 -> 0.17428261 | AB34: -51 | AC34: =A34 -> -59.172205 | AD34: =VLOOKUP(ROUNDDOWN(AC34,0),'Spline Pre-Adj'!K:L,2,0) -> 0 | AE34: =AD34*M34 -> 0
A35: =K10 -> -34.356062 | B35: =AQ10/1000000000 -> 98.15717 | C35: =AO10 -> 07:-50--25 | D35: =E10 -> 0.0025749156 | E35: =Z10+AA10+AB10+AC10+AD10 -> 0.0036462065 | F35: =D35/E35 -> 0.7061903 | G35: =(1-(1-D35)^12)*100 -> 3.0465129 | H35: =(1-(1-E35)^12)*100 -> 4.2887597 | K35: 0.75 | L35: 1 | M35: 0.54 | N35: =Z10+AA10+AB10*K35+AC10*L35+AD10*M35 -> 0.00258087 | O35: =100*(1-(1-N35)^12) -> 3.0534581 | P35: =D35/N35 -> 0.9976929 | R35: -35 | S35: =A35 -> -34.356062 | T35: =VLOOKUP(ROUNDDOWN(S35,0),'Spline Pre-Adj'!A:B,2,0) -> 1.287 | U35: =T35*K35 -> 0.96525 | W35: -44 | X35: =A35 -> -34.356062 | Y35: =VLOOKUP(ROUNDDOWN(X35,0),'Spline Pre-Adj'!F:G,2,0) -> 0.30095486 | Z35: =Y35*L35 -> 0.30095486 | AC35: =A35 -> -34.356062 | AD35: =VLOOKUP(ROUNDDOWN(AC35,0),'Spline Pre-Adj'!K:L,2,0) -> 0.35838252 | AE35: =AD35*M35 -> 0.19352656
A36: =K11 -> -10.820083 | B36: =AQ11/1000000000 -> 327.65687 | C36: =AO11 -> 08:-25-0 | D36: =E11 -> 0.0045012392 | E36: =Z11+AA11+AB11+AC11+AD11 -> 0.0066570223 | F36: =D36/E36 -> 0.67616405 | G36: =(1-(1-D36)^12)*100 -> 5.2697496 | H36: =(1-(1-E36)^12)*100 -> 7.7023356 | K36: 0.75 | L36: 1 | M36: 0.6 | N36: =Z11+AA11+AB11*K36+AC11*L36+AD11*M36 -> 0.0044871537 | O36: =100*(1-(1-N36)^12) -> 5.2536642 | P36: =D36/N36 -> 1.0031391 | R36: 0 | S36: =A36 -> -10.820083 | T36: =VLOOKUP(ROUNDDOWN(S36,0),'Spline Pre-Adj'!A:B,2,0) -> 1.287 | U36: =T36*K36 -> 0.96525 | W36: -20 | X36: =A36 -> -10.820083 | Y36: =VLOOKUP(ROUNDDOWN(X36,0),'Spline Pre-Adj'!F:G,2,0) -> 0.50716096 | Z36: =Y36*L36 -> 0.50716096 | AB36: -16 | AC36: =A36 -> -10.820083 | AD36: =VLOOKUP(ROUNDDOWN(AC36,0),'Spline Pre-Adj'!K:L,2,0) -> 1.1294598 | AE36: =AD36*M36 -> 0.67767586
A37: =K12 -> 13.555598 | B37: =AQ12/1000000000 -> 584.44183 | C37: =AO12 -> 09:0-25 | D37: =E12 -> 0.0127108 | E37: =Z12+AA12+AB12+AC12+AD12 -> 0.011731424 | F37: =D37/E37 -> 1.0834832 | G37: =(1-(1-D37)^12)*100 -> 14.230549 | H37: =(1-(1-E37)^12)*100 -> 13.203975 | K37: 0.75 | L37: 1 | M37: 1.2 | N37: =Z12+AA12+AB12*K37+AC12*L37+AD12*M37 -> 0.012692725 | O37: =100*(1-(1-N37)^12) -> 14.211703 | P37: =D37/N37 -> 1.0014241 | S37: =A37 -> 13.555598 | T37: =VLOOKUP(ROUNDDOWN(S37,0),'Spline Pre-Adj'!A:B,2,0) -> 1.287 | U37: =T37*K37 -> 0.96525 | W37: 5 | X37: =A37 -> 13.555598 | Y37: =VLOOKUP(ROUNDDOWN(X37,0),'Spline Pre-Adj'!F:G,2,0) -> 0.93625961 | Z37: =Y37*L37 -> 0.93625961 | AB37: 19 | AC37: =A37 -> 13.555598 | AD37: =VLOOKUP(ROUNDDOWN(AC37,0),'Spline Pre-Adj'!K:L,2,0) -> 1.6638145 | AE37: =AD37*M37 -> 1.9965774
A38: =K13 -> 37.537227 | B38: =AQ13/1000000000 -> 747.2229 | C38: =AO13 -> 10:25-50 | D38: =E13 -> 0.021634221 | E38: =Z13+AA13+AB13+AC13+AD13 -> 0.018502222 | F38: =D38/E38 -> 1.1692769 | G38: =(1-(1-D38)^12)*100 -> 23.084292 | H38: =(1-(1-E38)^12)*100 -> 20.076987 | K38: 0.75 | L38: 1 | M38: 1.27 | N38: =Z13+AA13+AB13*K38+AC13*L38+AD13*M38 -> 0.021667307 | O38: =100*(1-(1-N38)^12) -> 23.115499 | P38: =D38/N38 -> 0.99847302 | R38: 50 | S38: =A38 -> 37.537227 | T38: =VLOOKUP(ROUNDDOWN(S38,0),'Spline Pre-Adj'!A:B,2,0) -> 1.287 | U38: =T38*K38 -> 0.96525 | W38: 28 | X38: =A38 -> 37.537227 | Y38: =VLOOKUP(ROUNDDOWN(X38,0),'Spline Pre-Adj'!F:G,2,0) -> 1.8953738 | Z38: =Y38*L38 -> 1.8953738 | AC38: =A38 -> 37.537227 | AD38: =VLOOKUP(ROUNDDOWN(AC38,0),'Spline Pre-Adj'!K:L,2,0) -> 2.4264029 | AE38: =AD38*M38 -> 3.0815317
A39: =K14 -> 62.796666 | B39: =AQ14/1000000000 -> 770.69089 | C39: =AO14 -> 11:50-75 | D39: =E14 -> 0.027954496 | E39: =Z14+AA14+AB14+AC14+AD14 -> 0.025071526 | F39: =D39/E39 -> 1.1149898 | G39: =(1-(1-D39)^12)*100 -> 28.839474 | H39: =(1-(1-E39)^12)*100 -> 26.265107 | K39: 1 | L39: 1 | M39: 1.14 | N39: =Z14+AA14+AB14*K39+AC14*L39+AD14*M39 -> 0.027977779 | O39: =100*(1-(1-N39)^12) -> 28.859925 | P39: =D39/N39 -> 0.99916781 | W39: 54 | X39: =A39 -> 62.796666 | Y39: =VLOOKUP(ROUNDDOWN(X39,0),'Spline Pre-Adj'!F:G,2,0) -> 3.3799458 | Z39: =Y39*L39 -> 3.3799458 | AC39: =A39 -> 62.796666 | AD39: =VLOOKUP(ROUNDDOWN(AC39,0),'Spline Pre-Adj'!K:L,2,0) -> 3.3536482 | AE39: =AD39*M39 -> 3.823159
A40: =K15 -> 86.878109 | B40: =AQ15/1000000000 -> 712.88529 | C40: =AO15 -> 12:75-100 | D40: =E15 -> 0.033312512 | E40: =Z15+AA15+AB15+AC15+AD15 -> 0.030633876 | F40: =D40/E40 -> 1.0874403 | G40: =(1-(1-D40)^12)*100 -> 33.406296 | H40: =(1-(1-E40)^12)*100 -> 31.157908 | K40: 1 | L40: 1 | M40: 1.1 | N40: =Z15+AA15+AB15*K40+AC15*L40+AD15*M40 -> 0.033226146 | O40: =100*(1-(1-N40)^12) -> 33.334866 | P40: =D40/N40 -> 1.0025993 | W40: 79 | X40: =A40 -> 86.878109 | Y40: =VLOOKUP(ROUNDDOWN(X40,0),'Spline Pre-Adj'!F:G,2,0) -> 4.7646641 | Z40: =Y40*L40 -> 4.7646641 | AB40: 84 | AC40: =A40 -> 86.878109 | AD40: =VLOOKUP(ROUNDDOWN(AC40,0),'Spline Pre-Adj'!K:L,2,0) -> 4.1191353 | AE40: =AD40*M40 -> 4.5310488
A41: =K16 -> 112.14473 | B41: =AQ16/1000000000 -> 574.71005 | C41: =AO16 -> 13:100-125 | D41: =E16 -> 0.036056803 | E41: =Z16+AA16+AB16+AC16+AD16 -> 0.034219926 | F41: =D41/E41 -> 1.0536786 | G41: =(1-(1-D41)^12)*100 -> 35.639811 | H41: =(1-(1-E41)^12)*100 -> 34.152561 | K41: 1 | L41: 1 | M41: 1.06 | N41: =Z16+AA16+AB16*K41+AC16*L41+AD16*M41 -> 0.035966017 | O41: =100*(1-(1-N41)^12) -> 35.567034 | P41: =D41/N41 -> 1.0025242 | W41: 103 | X41: =A41 -> 112.14473 | Y41: =VLOOKUP(ROUNDDOWN(X41,0),'Spline Pre-Adj'!F:G,2,0) -> 6.2750976 | Z41: =Y41*L41 -> 6.2750976 | AC41: =A41 -> 112.14473 | AD41: =VLOOKUP(ROUNDDOWN(AC41,0),'Spline Pre-Adj'!K:L,2,0) -> 4.7521567 | AE41: =AD41*M41 -> 5.0372861
A42: =K17 -> 135.9264 | B42: =AQ17/1000000000 -> 364.52105 | C42: =AO17 -> 14:125-150 | D42: =E17 -> 0.038593851 | E42: =Z17+AA17+AB17+AC17+AD17 -> 0.038150841 | F42: =D42/E42 -> 1.0116121 | G42: =(1-(1-D42)^12)*100 -> 37.643354 | H42: =(1-(1-E42)^12)*100 -> 37.297677 | K42: 1 | L42: 1 | M42: 1 | N42: =Z17+AA17+AB17*K42+AC17*L42+AD17*M42 -> 0.038150841 | O42: =100*(1-(1-N42)^12) -> 37.297677 | P42: =D42/N42 -> 1.0116121 | W42: 128 | X42: =A42 -> 135.9264 | Y42: =VLOOKUP(ROUNDDOWN(X42,0),'Spline Pre-Adj'!F:G,2,0) -> 7.6782095 | Z42: =Y42*L42 -> 7.6782095 | AC42: =A42 -> 135.9264 | AD42: =VLOOKUP(ROUNDDOWN(AC42,0),'Spline Pre-Adj'!K:L,2,0) -> 5.2241825 | AE42: =AD42*M42 -> 5.2241825
...

Sheet Spline Pre-Adj
A1: spline | B1: conventional_turnover_incentive | F1: spline | G1: conventional_cashout_incentive | K1: spline | L1: conventional_refinance_himedia_incentive
A3: Row Labels | B3: Average of knotValues | F3: Row Labels | G3: Average of knotValues | K3: Row Labels | L3: Average of knotValues
A4: -730 | B4: 0.7314 | F4: -404 | G4: 0 | K4: -196 | L4: 0
A5: -729 | B5: 0.73142 | F5: -403 | G5: 0 | K5: -195 | L5: 0
A6: -728 | B6: 0.73144 | F6: -402 | G6: 0 | K6: -194 | L6: 0
A7: -727 | B7: 0.73146 | F7: -401 | G7: 0 | K7: -193 | L7: 0
A8: -726 | B8: 0.73148 | F8: -400 | G8: 0 | K8: -192 | L8: 0
A9: -725 | B9: 0.7315 | F9: -399 | G9: 0 | K9: -191 | L9: 0
A10: -724 | B10: 0.73152 | F10: -398 | G10: 0 | K10: -190 | L10: 0
A11: -723 | B11: 0.73154 | F11: -397 | G11: 0 | K11: -189 | L11: 0
A12: -722 | B12: 0.73156 | F12: -396 | G12: 0 | K12: -188 | L12: 0
A13: -721 | B13: 0.73158 | F13: -395 | G13: 0 | K13: -187 | L13: 0
A14: -720 | B14: 0.7316 | F14: -394 | G14: 0 | K14: -186 | L14: 0
A15: -719 | B15: 0.73162 | F15: -393 | G15: 0 | K15: -185 | L15: 0
... A564: -170 | B564: 0.887822 | F564: 156 | G564: 8.687382 | K564: 364 | L564: 7.8860159
A565: -169 | B565: 0.88931903 | F565: 157 | G565: 8.7024887 | K565: Grand Total | L565: 3.6232454
A566: -168 | B566: 0.89082605 | F566: 158 | G566: 8.7168624
A567: -167 | B567: 0.89234358 | F567: 159 | G567: 8.7305213
A568: -166 | B568: 0.89387214 | F568: 160 | G568: 8.7434836
A569: -165 | B569: 0.89541225 | F569: 161 | G569: 8.7557675
A570: -164 | B570: 0.89696442 | F570: 162 | G570: 8.7673913
A571: -163 | B571: 0.89852916 | F571: 163 | G571: 8.7783732
A572: -162 | B572: 0.90010699 | F572: 164 | G572: 8.7887314
A573: -161 | B573: 0.90169843 | F573: 165 | G573: 8.7984842
A574: -160 | B574: 0.903304 | F574: 166 | G574: 8.8076498
A575: -159 | B575: 0.90492421 | F575: 167 | G575: 8.8162464
A576: -158 | B576: 0.90655957 | F576: 168 | G576: 8.8242923
A577: -157 | B577: 0.9082106 | F577: 169 | G577: 8.8318057
... A728: -6 | B728: 1.287 | F728: 320 | G728: 8.9
A729: -5 | B729: 1.287 | F729: Grand Total | G729: 2.9928788
A730: -4 | B730: 1.287
A731: -3 | B731: 1.287
A732: -2 | B732: 1.287
A733: -1 | B733: 1.287
A734: 0 | B734: 1.287
A735: 1 | B735: 1.287
A736: 2 | B736: 1.287
A737: 3 | B737: 1.287
A738: 4 | B738: 1.287
A739: 5 | B739: 1.287
...
