Workbook

Sheet Distribution of data
A1: count() | B1: bucket | I1: count() | J1: tag | K1: loansize | L1: fico | M1: lien | N1: invest | O1: cltv | P1: state | Q1: asOf | R1: Ticker | S1: Orig Date | T1: wala | U1: TPO | V1: burnout
A2: 1096925 | B2: 'Done' | C2: <= 417 >= 740 no lien no invest cltv <= 80 | I2: =SUM(Baseline!AR3:AR17) -> 1235646 | J2: Baseline | K2: (175,417] | L2: [740,860] | M2: no | N2: no | O2: (0,80] | P2: not in ('NY','PR') | Q2: [20120101,20130401] | R2: All 4 | S2: post HARP | T2: [12,24) | U2: CORRES, CASHWINDOW
A3: 466351 | B3: 'FICO' | I3: =SUM(Burnout!AR3:AR34) -> 1232986 | J3: Baseline | K3: (175,417] | L3: [740,860] | M3: no | N3: no | O3: (0,80] | P3: not in ('NY','PR') | Q3: [20120101,20130401] | R3: All 4 | S3: post HARP | U3: CORRES, CASHWINDOW | V3: [0,2000]
A4: 230769 | B4: '2nd Lien'
A5: 144409 | B5: 'INV'
A6: 124596 | B6: 'CLTV'
A7: 57525 | B7: 'Jumbo'
A8: 2 | B8: 'Not Done'
A10: =SUM(A2:A8) -> 2120577 | B10: total

Sheet Actual
A1: WALA [12,24) | C1: BROKER
A2: modelId | B2: SFACTOR_PREPAY_TRACKING_CPR | C2: PREPAY_CPR1 | D2: PREPAY_TRACKING_CPR1 | E2: PREPAY_SMM1 | F2: PREPAY_TRACKING_SMM1 | G2: PCT_LOANTYPE | H2: _ORIGNOTERATE | I2: _ZEROSATO | J2: _SATO | K2: _REFI_INCENTIVE_Fixed | L2: _Fixed_cost | M2: _LOANAGE | N2: _LTV | O2: _CLTV | P2: _AVG_LOANSIZE_SCHAMBALANCE | Q2: _WACLS | R2: _FICO | S2: PCT_ISSECONDLIEN | T2: _OrigCombLTV | U2: PCT_SVC | V2: PCT_TPO | W2: PCT_GEO | X2: PCT_LOANPURPOSE | Y2: PCT_OCC | Z2: curtailsmm | AA2: defaultsmm | AB2: toverSmm | AC2: cashoutSmm | AD2: refiSmm | AE2: cumHPA | AF2: cumHPA05Pct | AG2: cumHPA15Pct | AH2: cumHPA20Pct | AI2: cumHPA25Pct | AJ2: cumHPA30Pct | AK2: cumHPA35Pct | AL2: cumHPA40Pct | AM2: adjtoverSmm | AN2: adjRefiSmm | AO2: groupByColumn | AP2: curve | AQ2: Balance | AR2: LoanCount | AS2: PCT_BROKER | AT2: PCT_CORRES | AU2: PCT_NonRETAIL | AV2: PCT_RETAIL | AW2: PCT_CashWindow | AX2: PCT_NonCashWindow
A3: 4.3 | B3: 0.99354299 | C3: 3.4433222 | D3: 7.4790735 | E3: 0.0029157422 | F3: 0.0064570079 | G3: 0 | H3: 3.9622665 | I3: 4.1506701 | J3: -55.102824 | K3: -57.170377 | L3: 18.591369 | M3: 15.604608 | N3: 77.726934 | O3: 75.492093 | P3: 267072.12 | Q3: 193404.05 | R3: 774.87434 | S3: 0 | T3: 0 | U3: 0.089424414 | V3: 0 | W3: 0 | X3: 0.58543282 | Y3: 0 | Z3: 0.00067107958 | AA3: 7.5421688e-05 | AB3: 0.0025087098 | AC3: 2.9446125e-08 | AD3: 0.0032017562 | AE3: -0.025268185 | AF3: 0.99001879 | AG3: 0.99720024 | AH3: 1 | AI3: 1 | AJ3: 1 | AK3: 1 | AL3: 1 | AM3: 0 | AN3: 0 | AO3: 06:-75--50 | AP3: =-75--50 -> -25 | AQ3: 22048061 | AR3: 114 | AS3: 100 | AT3: 0 | AU3: 100 | AV3: 0 | AW3: 0 | AX3: 0
A4: 4.3 | B4: 0.9934404 | C4: 2.6756426 | D4: 7.5936475 | E4: 0.0022575225 | F4: 0.0065595963 | G4: 0 | H4: 3.91998 | I4: 4.1424648 | J4: -57.659948 | K4: -32.594271 | L4: 14.98906 | M4: 15.424298 | N4: 73.798811 | O4: 72.801415 | P4: 293064.03 | Q4: 263371.78 | R4: 784.82056 | S4: 0 | T4: 0 | U4: 0.08318706 | V4: 0 | W4: 0 | X4: 0.63466923 | Y4: 0 | Z4: 0.00042337918 | AA4: 5.4947755e-05 | AB4: 0.0024369602 | AC4: 1.9932865e-08 | AD4: 0.0036442753 | AE4: -0.020683738 | AF4: 0.98301074 | AG4: 0.99723916 | AH4: 1 | AI4: 1 | AJ4: 1 | AK4: 1 | AL4: 1 | AM4: 0 | AN4: 0 | AO4: 07:-50--25 | AP4: =-50--25 -> -25 | AQ4: 2.4835959e+08 | AR4: 943 | AS4: 100 | AT4: 0 | AU4: 100 | AV4: 0 | AW4: 0 | AX4: 0
A5: 4.3 | B5: 0.98810675 | C5: 14.515411 | D5: 13.374372 | E5: 0.012984471 | F5: 0.01189325 | G5: 0 | H5: 4.0994748 | I5: 4.1233851 | J5: -40.112546 | K5: -8.5065994 | L5: 14.517274 | M5: 15.824699 | N5: 72.180941 | O5: 71.16733 | P5: 297035.51 | Q5: 273997.1 | R5: 782.74924 | S5: 0 | T5: 0 | U5: 0.16198165 | V5: 0 | W5: 0 | X5: 0.71326488 | Y5: 0 | Z5: 0.00037641719 | AA5: 6.1641507e-05 | AB5: 0.0025045364 | AC5: 1.1985382e-07 | AD5: 0.0089505203 | AE5: -0.015473879 | AF5: 0.95973186 | AG5: 0.99363686 | AH5: 0.99969863 | AI5: 1 | AJ5: 1 | AK5: 1 | AL5: 1 | AM5: 0 | AN5: 0 | AO5: 08:-25-0 | AP5: =-25-0 -> -25 | AQ5: 2.0251126e+09 | AR5: 7391 | AS5: 100 | AT5: 0 | AU5: 100 | AV5: 0 | AW5: 0 | AX5: 0
A6: 4.3 | B6: 0.98304592 | C6: 27.048998 | D6: 18.551023 | E6: 0.025939486 | F6: 0.016954085 | G6: 0 | H6: 4.1521468 | I6: 4.0348346 | J6: -30.391947 | K6: 15.744335 | L6: 14.364007 | M6: 15.776989 | N6: 68.038082 | O6: 65.942075 | P6: 298325.63 | Q6: 277825.05 | R6: 783.61193 | S6: 0 | T6: 0 | U6: 0.23317829 | V6: 0 | W6: 0 | X6: 0.8177067 | Y6: 0 | Z6: 0.00036976726 | AA6: 5.8793704e-05 | AB6: 0.0027739843 | AC6: 3.0262744e-06 | AD6: 0.013748499 | AE6: 0.0038239737 | AF6: 0.83514428 | AG6: 0.95178217 | AH6: 0.99513288 | AI6: 0.99904793 | AJ6: 1 | AK6: 1 | AL6: 1 | AM6: 0 | AN6: 0 | AO6: 09:0-25 | AP6: 0-25 | AQ6: 1.0989092e+10 | AR6: 39554 | AS6: 100 | AT6: 0 | AU6: 100 | AV6: 0 | AW6: 0 | AX6: 0
A7: 4.3 | B7: 0.97553016 | C7: 39.511307 | D7: 25.717173 | E7: 0.041027433 | F7: 0.024469838 | G7: 0 | H7: 4.1700427 | I7: 3.886904 | J7: -26.925548 | K7: 37.409975 | L7: 13.639154 | M7: 16.149073 | N7: 64.844231 | O7: 61.095981 | P7: 311881.57 | Q7: 292677.63 | R7: 783.83427 | S7: 0 | T7: 0 | U7: 0.2676584 | V7: 0 | W7: 0 | X7: 0.83998291 | Y7: 0 | Z7: 0.00036821089 | AA7: 5.7737956e-05 | AB7: 0.0030840132 | AC7: 1.0551737e-05 | AD7: 0.020949309 | AE7: 0.034424605 | AF7: 0.65979439 | AG7: 0.8965255 | AH7: 0.98913006 | AI7: 0.99836628 | AJ7: 1 | AK7: 1 | AL7: 1 | AM7: 0 | AN7: 0 | AO7: 10:25-50 | AP7: 25-50 | AQ7: 2.1924188e+10 | AR7: 74909 | AS7: 100 | AT7: 0 | AU7: 100 | AV7: 0 | AW7: 0 | AX7: 0
A8: 4.3 | B8: 0.96749363 | C8: 47.215946 | D8: 32.736821 | E8: 0.051853975 | F8: 0.032506367 | G8: 0 | H8: 4.4546713 | I8: 3.8939111 | J8: -17.636655 | K8: 62.476491 | L8: 14.232973 | M8: 17.622334 | N8: 67.200221 | O8: 63.714954 | P8: 300315.56 | Q8: 280510.29 | R8: 782.16221 | S8: 0 | T8: 0 | U8: 0.24509649 | V8: 0 | W8: 0 | X8: 0.76375298 | Y8: 0 | Z8: 0.00037146776 | AA8: 8.9448587e-05 | AB8: 0.0032444203 | AC8: 9.1333761e-06 | AD8: 0.028791883 | AE8: 0.02481458 | AF8: 0.68593791 | AG8: 0.94531389 | AH8: 0.99334833 | AI8: 0.99910374 | AJ8: 1 | AK8: 1 | AL8: 1 | AM8: 0 | AN8: 0 | AO8: 11:50-75 | AP8: 50-75 | AQ8: 1.7351525e+10 | AR8: 61857 | AS8: 100 | AT8: 0 | AU8: 100 | AV8: 0 | AW8: 0 | AX8: 0
A9: 4.3 | B9: 0.9616878 | C9: 45.770827 | D9: 37.423788 | E9: 0.049717463 | F9: 0.038312201 | G9: 0 | H9: 4.6792015 | I9: 3.8981509 | J9: -11.53115 | K9: 85.668971 | L9: 14.263814 | M9: 17.602014 | N9: 66.442911 | O9: 62.693089 | P9: 299859.64 | Q9: 279920.92 | R9: 780.85805 | S9: 0 | T9: 0 | U9: 0.28399373 | V9: 0 | W9: 0 | X9: 0.69290849 | Y9: 0 | Z9: 0.00037185965 | AA9: 0.00010535088 | AB9: 0.0033641167 | AC9: 1.8856207e-05 | AD9: 0.034452003 | AE9: 0.028319628 | AF9: 0.62658474 | AG9: 0.94565646 | AH9: 0.98872447 | AI9: 0.99818447 | AJ9: 1 | AK9: 1 | AL9: 1 | AM9: 0 | AN9: 0 | AO9: 12:75-100 | AP9: 75-100 | AQ9: 1.1137494e+10 | AR9: 39788 | AS9: 100 | AT9: 0 | AU9: 100 | AV9: 0 | AW9: 0 | AX9: 0
A10: 4.3 | B10: 0.95610776 | C10: 45.909203 | D10: 41.644457 | E10: 0.049919769 | F10: 0.04389224 | G10: 0 | H10: 4.8190174 | I10: 3.7827978 | J10: -7.033373 | K10: 111.76843 | L10: 14.851525 | M10: 18.573443 | N10: 70.047731 | O10: 64.517258 | P10: 288600.21 | Q10: 268853.2 | R10: 779.33271 | S10: 0 | T10: 0 | U10: 0.29515185 | V10: 0 | W10: 0 | X10: 0.61609329 | Y10: 0 | Z10: 0.00037279538 | AA10: 0.00014722462 | AB10: 0.0036961846 | AC10: 3.6742999e-05 | AD10: 0.039639278 | AE10: 0.052894394 | AF10: 0.44589189 | AG10: 0.9189403 | AH10: 0.98503593 | AI10: 0.99699297 | AJ10: 1 | AK10: 1 | AL10: 1 | AM10: 0 | AN10: 0 | AO10: 13:100-125 | AP10: 100-125 | AQ10: 5.7252288e+09 | AR10: 21295 | AS10: 100 | AT10: 0 | AU10: 100 | AV10: 0 | AW10: 0 | AX10: 0
A11: 4.3 | B11: 0.95139204 | C11: 46.476872 | D11: 45.006143 | E11: 0.050754696 | F11: 0.048607957 | G11: 0 | H11: 4.8761355 | I11: 3.6738705 | J11: -6.547352 | K11: 134.37324 | L11: 14.345575 | M11: 20.090596 | N11: 70.80133 | O11: 63.193322 | P11: 297212.06 | Q11: 278337.2 | R11: 778.25756 | S11: 0 | T11: 0 | U11: 0.29020541 | V11: 0 | W11: 0 | X11: 0.61283836 | Y11: 0 | Z11: 0.00037411096 | AA11: 0.00016841151 | AB11: 0.0036857396 | AC11: 8.5910415e-05 | AD11: 0.04429377 | AE11: 0.085370719 | AF11: 0.28253617 | AG11: 0.87003254 | AH11: 0.9662038 | AI11: 0.99610031 | AJ11: 1 | AK11: 1 | AL11: 1 | AM11: 0 | AN11: 0 | AO11: 14:125-150 | AP11: 125-150 | AQ11: 2.6208231e+09 | AR11: 9416 | AS11: 100 | AT11: 0 | AU11: 100 | AV11: 0 | AW11: 0 | AX11: 0
A12: 4.3 | B12: 0.94664668 | C12: 44.242836 | D12: 48.208917 | E12: 0.047514463 | F12: 0.05335332 | G12: 0 | H12: 5.0228991 | I12: 3.6711342 | J12: 6.8476451 | K12: 160.18516 | L12: 14.050936 | M12: 20.067577 | N12: 78.702585 | O12: 68.818309 | P12: 302497.45 | Q12: 284181.94 | R12: 777.14943 | S12: 0 | T12: 0 | U12: 0.23643044 | V12: 0 | W12: 0 | X12: 0.52204473 | Y12: 0 | Z12: 0.00037364661 | AA12: 0.00024360029 | AB12: 0.0038902341 | AC12: 0.00013030684 | AD12: 0.048715516 | AE12: 0.10704924 | AF12: 0.15712908 | AG12: 0.78788788 | AH12: 0.94414223 | AI12: 0.9898934 | AJ12: 1 | AK12: 1 | AL12: 1 | AM12: 0 | AN12: 0 | AO12: 15:150-175 | AP12: 150-175 | AQ12: 4.4019782e+08 | AR12: 1549 | AS12: 100 | AT12: 0 | AU12: 100 | AV12: 0 | AW12: 0 | AX12: 0
A13: 4.3 | B13: 0.94180872 | C13: 53.130436 | D13: 51.297364 | E13: 0.061197489 | F13: 0.058191283 | G13: 0 | H13: 5.046812 | I13: 3.6581714 | J13: 6.4300909 | K13: 183.9435 | L13: 13.884685 | M13: 20.486383 | N13: 85.498759 | O13: 72.57064 | P13: 305684.75 | Q13: 287591.9 | R13: 777.65331 | S13: 0 | T13: 0 | U13: 0.23252351 | V13: 0 | W13: 0 | X13: 0.40200049 | Y13: 0 | Z13: 0.00037498084 | AA13: 0.00032210145 | AB13: 0.0041021819 | AC13: 0.00035720284 | AD13: 0.0530348 | AE13: 0.13942807 | AF13: 0.035231054 | AG13: 0.62060278 | AH13: 0.85157551 | AI13: 0.98674363 | AJ13: 1 | AK13: 1 | AL13: 1 | AM13: 0 | AN13: 0 | AO13: 16:175-200 | AP13: 175-200 | AQ13: 96630878 | AR13: 336 | AS13: 100 | AT13: 0 | AU13: 100 | AV13: 0 | AW13: 0 | AX13: 0
A14: 4.3 | B14: 0.9407424 | C14: 47.495831 | D14: 51.954953 | E14: 0.052273955 | F14: 0.059257599 | G14: 0 | H14: 5.1962175 | I14: 3.6487088 | J14: 17.28872 | K14: 209.55229 | L14: 14.52586 | M14: 20.792683 | N14: 90.120235 | O14: 75.17575 | P14: 294450.4 | Q14: 274910.83 | R14: 775.39517 | S14: 0 | T14: 0 | U14: 0.083777428 | V14: 0 | W14: 0 | X14: 0.28831945 | Y14: 0 | Z14: 0.00037198764 | AA14: 0.00037985115 | AB14: 0.0043843365 | AC14: 0.0005945363 | AD14: 0.053526869 | AE14: 0.16459065 | AF14: 0 | AG14: 0.46714353 | AH14: 0.67606014 | AI14: 0.98161705 | AJ14: 1 | AK14: 1 | AL14: 1 | AM14: 0 | AN14: 0 | AO14: 17:200-225 | AP14: 200-225 | AQ14: 20893223 | AR14: 76 | AS14: 100 | AT14: 0 | AU14: 100 | AV14: 0 | AW14: 0 | AX14: 0
A15: 4.3 | B15: 0.94906051 | C15: 46.592588 | D15: 46.601772 | E15: 0.050925887 | F15: 0.050939488 | G15: 0 | H15: 5.321533 | I15: 3.665408 | J15: 30.474314 | K15: 232.6404 | L15: 17.927401 | M15: 20.850682 | N15: 92.695715 | O15: 75.691523 | P15: 246276.83 | Q15: 222772.75 | R15: 788.41159 | S15: 0 | T15: 0 | U15: 0 | V15: 0 | W15: 0 | X15: 0.34002479 | Y15: 0 | Z15: 0.00040339218 | AA15: 4.2794964e-05 | AB15: 0.004240869 | AC15: 0.00068165279 | AD15: 0.045570761 | AE15: 0.17333363 | AF15: 0 | AG15: 0.29883154 | AH15: 0.63135198 | AI15: 0.95367429 | AJ15: 1 | AK15: 1 | AL15: 1 | AM15: 0 | AN15: 0 | AO15: 18:225-250 | AP15: 225-250 | AQ15: 3787136.8 | AR15: 17 | AS15: 100 | AT15: 0 | AU15: 100 | AV15: 0 | AW15: 0 | AX15: 0
A19: WALA [12,24) | C19: CORRES
A20: modelId | B20: SFACTOR_PREPAY_TRACKING_CPR | C20: PREPAY_CPR1 | D20: PREPAY_TRACKING_CPR1 | E20: PREPAY_SMM1 | F20: PREPAY_TRACKING_SMM1 | G20: PCT_LOANTYPE | H20: _ORIGNOTERATE | I20: _ZEROSATO | J20: _SATO | K20: _REFI_INCENTIVE_Fixed | L20: _Fixed_cost | M20: _LOANAGE | N20: _LTV | O20: _CLTV | P20: _AVG_LOANSIZE_SCHAMBALANCE | Q20: _WACLS | R20: _FICO | S20: PCT_ISSECONDLIEN | T20: _OrigCombLTV | U20: PCT_SVC | V20: PCT_TPO | W20: PCT_GEO | X20: PCT_LOANPURPOSE | Y20: PCT_OCC | Z20: curtailsmm | AA20: defaultsmm | AB20: toverSmm | AC20: cashoutSmm | AD20: refiSmm | AE20: cumHPA | AF20: cumHPA05Pct | AG20: cumHPA15Pct | AH20: cumHPA20Pct | AI20: cumHPA25Pct | AJ20: cumHPA30Pct | AK20: cumHPA35Pct | AL20: cumHPA40Pct | AM20: adjtoverSmm | AN20: adjRefiSmm | AO20: groupByColumn | AP20: curve | AQ20: Balance | AR20: LoanCount | AS20: PCT_BROKER | AT20: PCT_CORRES | AU20: PCT_NonRETAIL | AV20: PCT_RETAIL | AW20: PCT_CashWindow | AX20: PCT_NonCashWindow
A21: 4.3 | B21: 0.9957006 | C21: 1.2100205e-05 | D21: 5.0390158 | E21: 1.0083505e-08 | F21: 0.0042994036 | G21: 0 | H21: 4.0264725 | I21: 4.1375376 | J21: -42.855524 | K21: -108.8538 | L21: 20.131193 | M21: 15.604363 | N21: 76.15288 | O21: 75.620604 | P21: 198516.22 | Q21: 198343.74 | R21: 760.45864 | S21: 0 | T21: 0 | U21: 0 | V21: 0 | W21: 0 | X21: 0.21177999 | Y21: 0 | Z21: 0.00035089724 | AA21: 5.1078517e-05 | AB21: 0.0028684717 | AC21: 0 | AD21: 0.0010289422 | AE21: -0.01596622 | AF21: 1 | AG21: 1 | AH21: 1 | AI21: 1 | AJ21: 1 | AK21: 1 | AL21: 1 | AM21: 0 | AN21: 0 | AO21: 04:-125--100 | AP21: =-125--100 -> -25 | AQ21: 991718.69 | AR21: 5 | AS21: 0 | AT21: 100 | AU21: 100 | AV21: 0 | AW21: 0 | AX21: 0
A22: 4.3 | B22: 0.99034254 | C22: 7.935874 | D22: 10.99278 | E22: 0.0068667181 | F22: 0.0096574553 | G22: 0 | H22: 4.1493576 | I22: 4.0940505 | J22: -33.386672 | K22: -83.205891 | L22: 15.783595 | M22: 15.690168 | N22: 76.749332 | O22: 75.908226 | P22: 298964.84 | Q22: 222085.04 | R22: 780.43588 | S22: 0 | T22: 0 | U22: 0 | V22: 0 | W22: 0 | X22: 0.37109602 | Y22: 0 | Z22: 0.00053542522 | AA22: 7.7502751e-05 | AB22: 0.0026030463 | AC22: 0 | AD22: 0.0064414668 | AE22: -0.026461015 | AF22: 1 | AG22: 1 | AH22: 1 | AI22: 1 | AJ22: 1 | AK22: 1 | AL22: 1 | AM22: 0 | AN22: 0 | AO22: 05:-100--75 | AP22: =-100--75 -> -25 | AQ22: 6218381 | AR22: 28 | AS22: 0 | AT22: 100 | AU22: 100 | AV22: 0 | AW22: 0 | AX22: 0
A23: 4.3 | B23: 0.99531194 | C23: 1.8301087 | D23: 5.4828571 | E23: 0.0015380347 | F23: 0.0046880567 | G23: 0 | H23: 3.8986259 | I23: 4.1473096 | J23: -59.670289 | K23: -56.905879 | L23: 17.18523 | M23: 15.245911 | N23: 77.854851 | O23: 76.716765 | P23: 263061.8 | Q23: 226873.4 | R23: 780.81197 | S23: 0 | T23: 0 | U23: 0.0025098134 | V23: 0 | W23: 0 | X23: 0.46038548 | Y23: 0 | Z23: 0.00047411809 | AA23: 6.1413376e-05 | AB23: 0.0024185358 | AC23: 0 | AD23: 0.0017339791 | AE23: -0.022969111 | AF23: 0.996552 | AG23: 1 | AH23: 1 | AI23: 1 | AJ23: 1 | AK23: 1 | AL23: 1 | AM23: 0 | AN23: 0 | AO23: 06:-75--50 | AP23: =-75--50 -> -25 | AQ23: 1.3952714e+08 | AR23: 615 | AS23: 0 | AT23: 100 | AU23: 100 | AV23: 0 | AW23: 0 | AX23: 0
A24: 4.3 | B24: 0.99386722 | C24: 3.4070807 | D24: 7.116109 | E24: 0.0028845605 | F24: 0.0061327803 | G24: 0 | H24: 3.8995117 | I24: 4.1447021 | J24: -60.114068 | K24: -33.387746 | L24: 15.955751 | M24: 15.468515 | N24: 73.341274 | O24: 71.959297 | P24: 273610.41 | Q24: 248811.56 | R24: 782.10208 | S24: 0 | T24: 0 | U24: 0.0013918239 | V24: 0 | W24: 0 | X24: 0.58737228 | Y24: 0 | Z24: 0.00039633253 | AA24: 5.7272475e-05 | AB24: 0.0025387935 | AC24: 2.1988534e-08 | AD24: 0.0031403457 | AE24: -0.015273165 | AF24: 0.98396189 | AG24: 0.99979739 | AH24: 0.99996869 | AI24: 0.99999042 | AJ24: 1 | AK24: 1 | AL24: 1 | AM24: 0 | AN24: 0 | AO24: 07:-50--25 | AP24: =-50--25 -> -25 | AQ24: 1.6254859e+09 | AR24: 6533 | AS24: 0 | AT24: 100 | AU24: 100 | AV24: 0 | AW24: 0 | AX24: 0
A25: 4.3 | B25: 0.9884728 | C25: 8.6868546 | D25: 12.988493 | E25: 0.0075443498 | F25: 0.011527198 | G25: 0 | H25: 4.097073 | I25: 4.1260145 | J25: -41.673293 | K25: -9.3602837 | L25: 15.303898 | M25: 16.096379 | N25: 72.187814 | O25: 71.033906 | P25: 281961.47 | Q25: 260269.92 | R25: 781.85441 | S25: 0 | T25: 0 | U25: 0.002782606 | V25: 0 | W25: 0 | X25: 0.6832404 | Y25: 0 | Z25: 0.00037474785 | AA25: 6.7008715e-05 | AB25: 0.0026069832 | AC25: 3.167863e-08 | AD25: 0.008478412 | AE25: -0.014262052 | AF25: 0.97210268 | AG25: 0.99863121 | AH25: 0.99987521 | AI25: 1 | AJ25: 1 | AK25: 1 | AL25: 1 | AM25: 0 | AN25: 0 | AO25: 08:-25-0 | AP25: =-25-0 -> -25 | AQ25: 9.6437813e+09 | AR25: 37053 | AS25: 0 | AT25: 100 | AU25: 100 | AV25: 0 | AW25: 0 | AX25: 0
A26: 4.3 | B26: 0.98339762 | C26: 18.623934 | D26: 18.20065 | E26: 0.017027448 | F26: 0.016602377 | G26: 0 | H26: 4.2061544 | I26: 4.0684698 | J26: -31.261201 | K26: 15.159426 | L26: 15.015325 | M26: 16.531355 | N26: 69.194667 | O26: 67.652827 | P26: 286199.29 | Q26: 265730.87 | R26: 782.34245 | S26: 0 | T26: 0 | U26: 0.0089632365 | V26: 0 | W26: 0 | X26: 0.76936148 | Y26: 0 | Z26: 0.00037298469 | AA26: 7.4133431e-05 | AB26: 0.0027640145 | AC26: 4.0375178e-07 | AD26: 0.013390826 | AE26: -0.0086907056 | AF26: 0.92529766 | AG26: 0.99384479 | AH26: 0.99955192 | AI26: 0.99983997 | AJ26: 1 | AK26: 1 | AL26: 1 | AM26: 0 | AN26: 0 | AO26: 09:0-25 | AP26: 0-25 | AQ26: 3.8876693e+10 | AR26: 146301 | AS26: 0 | AT26: 100 | AU26: 100 | AV26: 0 | AW26: 0 | AX26: 0
A27: 4.3 | B27: 0.97636692 | C27: 30.172729 | D27: 24.948964 | E27: 0.029485364 | F27: 0.023633078 | G27: 0 | H27: 4.2307505 | I27: 3.9141908 | J27: -26.990777 | K27: 37.381619 | L27: 14.422594 | M27: 17.06351 | N27: 67.386444 | O27: 64.475774 | P27: 297412.58 | Q27: 276705.53 | R27: 782.18971 | S27: 0 | T27: 0 | U27: 0.017089004 | V27: 0 | W27: 0 | X27: 0.75444376 | Y27: 0 | Z27: 0.00037191187 | AA27: 7.6173822e-05 | AB27: 0.0030566284 | AC27: 3.0381204e-06 | AD27: 0.020125312 | AE27: 0.014020201 | AF27: 0.79792715 | AG27: 0.97128841 | AH27: 0.99714665 | AI27: 0.99948034 | AJ27: 1 | AK27: 1 | AL27: 1 | AM27: 0 | AN27: 0 | AO27: 10:25-50 | AP27: 25-50 | AQ27: 6.1816015e+10 | AR27: 223400 | AS27: 0 | AT27: 100 | AU27: 100 | AV27: 0 | AW27: 0 | AX27: 0
A28: 4.3 | B28: 0.96874993 | C28: 38.013898 | D28: 31.6812 | E28: 0.039071235 | F28: 0.031250067 | G28: 0 | H28: 4.4691529 | I28: 3.8899297 | J28: -17.585481 | K28: 62.663639 | L28: 14.904888 | M28: 17.433619 | N28: 69.566621 | O28: 66.270424 | P28: 287889.79 | Q28: 267833.15 | R28: 780.90567 | S28: 0 | T28: 0 | U28: 0.012379923 | V28: 0 | W28: 0 | X28: 0.65513568 | Y28: 0 | Z28: 0.00037347868 | AA28: 0.00010165557 | AB28: 0.0031882111 | AC28: 6.1303928e-06 | AD28: 0.027580577 | AE28: 0.018520793 | AF28: 0.75933386 | AG28: 0.97296663 | AH28: 0.99568006 | AI28: 0.99918144 | AJ28: 1 | AK28: 1 | AL28: 1 | AM28: 0 | AN28: 0 | AO28: 11:50-75 | AP28: 50-75 | AQ28: 6.0848478e+10 | AR28: 227188 | AS28: 0 | AT28: 100 | AU28: 100 | AV28: 0 | AW28: 0 | AX28: 0
A29: 4.3 | B29: 0.96283573 | C29: 42.416214 | D29: 36.521539 | E29: 0.0449524 | F29: 0.037164268 | G29: 0 | H29: 4.669899 | I29: 3.8733774 | J29: -11.114419 | K29: 86.082824 | L29: 14.804271 | M29: 16.938335 | N29: 69.317804 | O29: 65.421495 | P29: 290106.53 | Q29: 269690.96 | R29: 780.16361 | S29: 0 | T29: 0 | U29: 0.014929732 | V29: 0 | W29: 0 | X29: 0.57816443 | Y29: 0 | Z29: 0.0003715959 | AA29: 0.00012118595 | AB29: 0.0033233774 | AC29: 1.1990445e-05 | AD29: 0.033336103 | AE29: 0.028739178 | AF29: 0.66722427 | AG29: 0.96394033 | AH29: 0.99288434 | AI29: 0.99892184 | AJ29: 1 | AK29: 1 | AL29: 1 | AM29: 0 | AN29: 0 | AO29: 12:75-100 | AP29: 75-100 | AQ29: 4.55179e+10 | AR29: 168778 | AS29: 0 | AT29: 100 | AU29: 100 | AV29: 0 | AW29: 0 | AX29: 0
A30: 4.3 | B30: 0.95762744 | C30: 42.856373 | D30: 40.521638 | E30: 0.045562891 | F30: 0.042372557 | G30: 0 | H30: 4.8031244 | I30: 3.7630665 | J30: -6.4548522 | K30: 111.90903 | L30: 15.277825 | M30: 18.004782 | N30: 72.048793 | O30: 66.634559 | P30: 281058.31 | Q30: 261352.89 | R30: 779.37482 | S30: 0 | T30: 0 | U30: 0.01546372 | V30: 0 | W30: 0 | X30: 0.50506534 | Y30: 0 | Z30: 0.00037175511 | AA30: 0.00016338236 | AB30: 0.0035742012 | AC30: 2.7048051e-05 | AD30: 0.038236155 | AE30: 0.049620894 | AF30: 0.5097601 | AG30: 0.94271147 | AH30: 0.98829344 | AI30: 0.99772965 | AJ30: 1 | AK30: 1 | AL30: 1 | AM30: 0 | AN30: 0 | AO30: 13:100-125 | AP30: 100-125 | AQ30: 2.802095e+10 | AR30: 107215 | AS30: 0 | AT30: 100 | AU30: 100 | AV30: 0 | AW30: 0 | AX30: 0
A31: 4.3 | B31: 0.95271962 | C31: 44.800986 | D31: 44.07818 | E31: 0.048312694 | F31: 0.047280382 | G31: 0 | H31: 4.8804013 | I31: 3.6765996 | J31: -4.9590254 | K31: 134.28061 | L31: 14.635412 | M31: 19.561149 | N31: 71.76419 | O31: 64.964183 | P31: 292491.52 | Q31: 272829.41 | R31: 778.75703 | S31: 0 | T31: 0 | U31: 0.017311252 | V31: 0 | W31: 0 | X31: 0.51891916 | Y31: 0 | Z31: 0.0003723305 | AA31: 0.00019811131 | AB31: 0.0035194468 | AC31: 6.8018786e-05 | AD31: 0.043122459 | AE31: 0.071315724 | AF31: 0.39506961 | AG31: 0.90346476 | AH31: 0.97245124 | AI31: 0.99591568 | AJ31: 1 | AK31: 1 | AL31: 1 | AM31: 0 | AN31: 0 | AO31: 14:125-150 | AP31: 125-150 | AQ31: 1.2692843e+10 | AR31: 46523 | AS31: 0 | AT31: 100 | AU31: 100 | AV31: 0 | AW31: 0 | AX31: 0
A32: 4.3 | B32: 0.9490703 | C32: 41.981394 | D32: 46.595165 | E32: 0.044353499 | F32: 0.050929704 | G32: 0 | H32: 5.0437272 | I32: 3.6813844 | J32: 9.9071253 | K32: 160.87385 | L32: 15.119569 | M32: 19.507703 | N32: 79.542842 | O32: 70.442227 | P32: 283310.92 | Q32: 264098.56 | R32: 776.92982 | S32: 0 | T32: 0 | U32: 0.016870534 | V32: 0 | W32: 0 | X32: 0.47603545 | Y32: 0 | Z32: 0.00037700592 | AA32: 0.00027635962 | AB32: 0.003803571 | AC32: 0.00014882352 | AD32: 0.046323928 | AE32: 0.092884957 | AF32: 0.28597376 | AG32: 0.80432464 | AH32: 0.93778902 | AI32: 0.99023488 | AJ32: 1 | AK32: 1 | AL32: 1 | AM32: 0 | AN32: 0 | AO32: 15:150-175 | AP32: 150-175 | AQ32: 2.58843e+09 | AR32: 9801 | AS32: 0 | AT32: 100 | AU32: 100 | AV32: 0 | AW32: 0 | AX32: 0
A33: 4.3 | B33: 0.94285433 | C33: 48.655806 | D33: 50.644539 | E33: 0.054036721 | F33: 0.057145668 | G33: 0 | H33: 5.0710696 | I33: 3.6599799 | J33: 12.2848 | K33: 183.22998 | L33: 14.003319 | M33: 19.98188 | N33: 83.336593 | O33: 71.286178 | P33: 302371.03 | Q33: 285150.39 | R33: 776.21487 | S33: 0 | T33: 0 | U33: 0.017358684 | V33: 0 | W33: 0 | X33: 0.46148792 | Y33: 0 | Z33: 0.00037680602 | AA33: 0.00032732859 | AB33: 0.0039005728 | AC33: 0.00043364357 | AD33: 0.0521073 | AE33: 0.12971425 | AF33: 0.16588024 | AG33: 0.61762235 | AH33: 0.80205726 | AI33: 0.96116652 | AJ33: 1 | AK33: 1 | AL33: 1 | AM33: 0 | AN33: 0 | AO33: 16:175-200 | AP33: 175-200 | AQ33: 6.8692728e+08 | AR33: 2409 | AS33: 0 | AT33: 100 | AU33: 100 | AV33: 0 | AW33: 0 | AX33: 0
A34: 4.3 | B34: 0.9407399 | C34: 38.318358 | D34: 51.956483 | E34: 0.039465443 | F34: 0.059260097 | G34: 0 | H34: 5.1605718 | I34: 3.6692646 | J34: 17.585612 | K34: 209.41141 | L34: 14.520526 | M34: 20.232747 | N34: 90.534831 | O34: 75.341532 | P34: 296660.31 | Q34: 274999.14 | R34: 775.31983 | S34: 0 | T34: 0 | U34: 0.015751738 | V34: 0 | W34: 0 | X34: 0.29437842 | Y34: 0 | Z34: 0.00037945678 | AA34: 0.00042470513 | AB34: 0.0042613109 | AC34: 0.00072566888 | AD34: 0.053468938 | AE34: 0.16225249 | AF34: 0.036592112 | AG34: 0.4165709 | AH34: 0.69329744 | AI34: 0.92631746 | AJ34: 1 | AK34: 1 | AL34: 1 | AM34: 0 | AN34: 0 | AO34: 17:200-225 | AP34: 200-225 | AQ34: 1.2347462e+08 | AR34: 449 | AS34: 0 | AT34: 100 | AU34: 100 | AV34: 0 | AW34: 0 | AX34: 0
A35: 4.3 | B35: 0.93891144 | C35: 22.828421 | D35: 53.065137 | E35: 0.021363411 | F35: 0.061088562 | G35: 0 | H35: 5.2641041 | I35: 3.6465013 | J35: 27.398546 | K35: 231.7946 | L35: 13.76739 | M35: 20.801174 | N35: 92.494129 | O35: 74.555659 | P35: 310947.98 | Q35: 290043.59 | R35: 776.17564 | S35: 0 | T35: 0 | U35: 0 | V35: 0 | W35: 0 | X35: 0.15312933 | Y35: 0 | Z35: 0.00038271758 | AA35: 0.00052407484 | AB35: 0.0044067446 | AC35: 0.0013321278 | AD35: 0.054442879 | AE35: 0.19808292 | AF35: 0 | AG35: 0.17645629 | AH35: 0.38832439 | AI35: 0.9097973 | AJ35: 1 | AK35: 1 | AL35: 1 | AM35: 0 | AN35: 0 | AO35: 18:225-250 | AP35: 225-250 | AQ35: 22913444 | AR35: 79 | AS35: 0 | AT35: 100 | AU35: 100 | AV35: 0 | AW35: 0 | AX35: 0
A38: WALA [12,24) | C38: CashWindow
A39: modelId | B39: SFACTOR_PREPAY_TRACKING_CPR | C39: PREPAY_CPR1 | D39: PREPAY_TRACKING_CPR1 | E39: PREPAY_SMM1 | F39: PREPAY_TRACKING_SMM1 | G39: PCT_LOANTYPE | H39: _ORIGNOTERATE | I39: _ZEROSATO | J39: _SATO | K39: _REFI_INCENTIVE_Fixed | L39: _Fixed_cost | M39: _LOANAGE | N39: _LTV | O39: _CLTV | P39: _AVG_LOANSIZE_SCHAMBALANCE | Q39: _WACLS | R39: _FICO | S39: PCT_ISSECONDLIEN | T39: _OrigCombLTV | U39: PCT_SVC | V39: PCT_TPO | W39: PCT_GEO | X39: PCT_LOANPURPOSE | Y39: PCT_OCC | Z39: curtailsmm | AA39: defaultsmm | AB39: toverSmm | AC39: cashoutSmm | AD39: refiSmm | AE39: cumHPA | AF39: cumHPA05Pct | AG39: cumHPA15Pct | AH39: cumHPA20Pct | AI39: cumHPA25Pct | AJ39: cumHPA30Pct | AK39: cumHPA35Pct | AL39: cumHPA40Pct | AM39: adjtoverSmm | AN39: adjRefiSmm | AO39: groupByColumn | AP39: curve | AQ39: Balance | AR39: LoanCount | AS39: PCT_BROKER | AT39: PCT_CORRES | AU39: PCT_NonRETAIL | AV39: PCT_RETAIL | AW39: PCT_CashWindow | AX39: PCT_NonCashWindow
A40: 4.3 | B40: 0.99661762 | C40: 0 | D40: 3.9841936 | E40: 0 | F40: 0.00338238 | G40: 0 | H40: 3.875 | I40: 4.118472 | J40: -64.0619 | K40: -131.95 | L40: 13.16 | M40: 17 | N40: 80 | O40: 77.08 | P40: 303250.44 | Q40: 303250.44 | R40: 773 | S40: 0 | T40: 0 | U40: 0 | V40: 1 | W40: 0 | X40: 1 | Y40: 0 | Z40: 0.00035183 | AA40: 7.792e-05 | AB40: 0.00295262 | AC40: 0 | AD40: 0 | AE40: 0.011207683 | AF40: 1 | AG40: 1 | AH40: 1 | AI40: 1 | AJ40: 1 | AK40: 1 | AL40: 1 | AM40: 0 | AN40: 0 | AO40: 03:-150--125 | AP40: =-150--125 -> -25 | AQ40: 303250.44 | AR40: 1 | AS40: 0 | AT40: 0 | AU40: 0 | AV40: 100 | AW40: 100 | AX40: 0
A41: 4.3 | B41: 0.99173453 | C41: 0 | D41: 9.4798618 | E41: 0 | F41: 0.0082654715 | G41: 0 | H41: 3.875 | I41: 3.8717773 | J41: -56.468943 | K41: -111.35086 | L41: 14.328815 | M41: 17.880294 | N41: 80 | O41: 75.620345 | P41: 284673.47 | Q41: 278674.78 | R41: 771.88117 | S41: 0 | T41: 0 | U41: 0 | V41: 1 | W41: 0 | X41: 1 | Y41: 0 | Z41: 0.00035334788 | AA41: 5.3605208e-05 | AB41: 0.0031742462 | AC41: 0 | AD41: 0.0046842576 | AE41: 0.029306717 | AF41: 1 | AG41: 1 | AH41: 1 | AI41: 1 | AJ41: 1 | AK41: 1 | AL41: 1 | AM41: 0 | AN41: 0 | AO41: 04:-125--100 | AP41: =-125--100 -> -25 | AQ41: 1114699.1 | AR41: 4 | AS41: 0 | AT41: 0 | AU41: 0 | AV41: 100 | AW41: 100 | AX41: 0
A42: 4.3 | B42: 0.98992819 | C42: 12.107777 | D42: 11.438635 | E42: 0.010697278 | F42: 0.01007181 | G42: 0 | H42: 4.2120764 | I42: 3.9473309 | J42: -23.140697 | K42: -83.452033 | L42: 19.208546 | M42: 17.333171 | N42: 79.615477 | O42: 76.037526 | P42: 239079.34 | Q42: 193572.8 | R42: 765.54682 | S42: 0 | T42: 0 | U42: 0 | V42: 1 | W42: 0 | X42: 0.97979815 | Y42: 0 | Z42: 0.00056887345 | AA42: 8.1948978e-05 | AB42: 0.0030977716 | AC42: 0 | AD42: 0.0063232008 | AE42: -0.0002056697 | AF42: 1 | AG42: 1 | AH42: 1 | AI42: 1 | AJ42: 1 | AK42: 1 | AL42: 1 | AM42: 0 | AN42: 0 | AO42: 05:-100--75 | AP42: =-100--75 -> -25 | AQ42: 2322873.6 | AR42: 12 | AS42: 0 | AT42: 0 | AU42: 0 | AV42: 100 | AW42: 100 | AX42: 0
A43: 4.3 | B43: 0.98934761 | C43: 27.432198 | D43: 12.059911 | E43: 0.026366898 | F43: 0.010652392 | G43: 0 | H43: 4.2156057 | I43: 4.0468354 | J43: -26.571952 | K43: -57.932898 | L43: 22.942908 | M43: 16.539877 | N43: 78.81004 | O43: 71.950413 | P43: 243355.1 | Q43: 154364.35 | R43: 774.26727 | S43: 0 | T43: 0 | U43: 0.08578669 | V43: 1 | W43: 0 | X43: 0.62733873 | Y43: 0 | Z43: 0.0010454839 | AA43: 8.0260524e-05 | AB43: 0.002838117 | AC43: 0 | AD43: 0.0066885165 | AE43: -0.01057977 | AF43: 0.95511436 | AG43: 0.99661868 | AH43: 1 | AI43: 1 | AJ43: 1 | AK43: 1 | AL43: 1 | AM43: 0 | AN43: 0 | AO43: 06:-75--50 | AP43: =-75--50 -> -25 | AQ43: 13275334 | AR43: 86 | AS43: 0 | AT43: 0 | AU43: 0 | AV43: 100 | AW43: 100 | AX43: 0
A44: 4.3 | B44: 0.99372916 | C44: 2.6972 | D44: 7.2708179 | E44: 0.0022759411 | F44: 0.0062708358 | G44: 0 | H44: 4.0130121 | I44: 4.124413 | J44: -49.480846 | K44: -32.313402 | L44: 17.404312 | M44: 15.583407 | N44: 77.145531 | O44: 74.947546 | P44: 263811.83 | Q44: 223674.18 | R44: 781.04806 | S44: 0 | T44: 0 | U44: 0.0047215107 | V44: 1 | W44: 0 | X44: 0.5513044 | Y44: 0 | Z44: 0.00047030754 | AA44: 5.2422737e-05 | AB44: 0.0026297805 | AC44: 3.0524064e-07 | AD44: 0.0031180062 | AE44: -0.014876592 | AF44: 0.97128747 | AG44: 0.99033606 | AH44: 0.99969298 | AI44: 0.99969298 | AJ44: 1 | AK44: 1 | AL44: 1 | AM44: 0 | AN44: 0 | AO44: 07:-50--25 | AP44: =-50--25 -> -25 | AQ44: 1.9616225e+08 | AR44: 877 | AS44: 0 | AT44: 0 | AU44: 0 | AV44: 100 | AW44: 100 | AX44: 0
A45: 4.3 | B45: 0.99009166 | C45: 10.272771 | D45: 11.262988 | E45: 0.0089923175 | F45: 0.0099083449 | G45: 0 | H45: 4.1238862 | I45: 4.1160383 | J45: -38.460418 | K45: -8.5277656 | L45: 16.482102 | M45: 15.981391 | N45: 74.178548 | O45: 72.813875 | P45: 262234.84 | Q45: 241347.2 | R45: 781.322 | S45: 0 | T45: 0 | U45: 0.019790794 | V45: 1 | W45: 0 | X45: 0.71355362 | Y45: 0 | Z45: 0.00038681295 | AA45: 5.6034209e-05 | AB45: 0.0026655013 | AC45: 1.5856603e-07 | AD45: 0.0067998237 | AE45: -0.013449962 | AF45: 0.9617047 | AG45: 0.99077334 | AH45: 0.999711 | AI45: 0.99996719 | AJ45: 1 | AK45: 1 | AL45: 1 | AM45: 0 | AN45: 0 | AO45: 08:-25-0 | AP45: =-25-0 -> -25 | AQ45: 2.0574849e+09 | AR45: 8525 | AS45: 0 | AT45: 0 | AU45: 0 | AV45: 100 | AW45: 100 | AX45: 0
...

Sheet Baseline
A1: WALA [12,24) | C1: CORRES+CASHWINDOW | AS1: tover | AT1: cash | AW1: refi
A2: modelId | B2: SFACTOR_PREPAY_TRACKING_CPR | C2: PREPAY_CPR1 | D2: PREPAY_TRACKING_CPR1 | E2: PREPAY_SMM1 | F2: PREPAY_TRACKING_SMM1 | G2: PCT_LOANTYPE | H2: _ORIGNOTERATE | I2: _ZEROSATO | J2: _SATO | K2: _REFI_INCENTIVE_Fixed | L2: _Fixed_cost | M2: _LOANAGE | N2: _LTV | O2: _CLTV | P2: _AVG_LOANSIZE_SCHAMBALANCE | Q2: _WACLS | R2: _FICO | S2: PCT_ISSECONDLIEN | T2: _OrigCombLTV | U2: PCT_SVC | V2: PCT_TPO | W2: PCT_GEO | X2: PCT_LOANPURPOSE | Y2: PCT_OCC | Z2: curtailsmm | AA2: defaultsmm | AB2: toverSmm | AC2: cashoutSmm | AD2: refiSmm | AE2: cumHPA | AF2: cumHPA05Pct | AG2: cumHPA15Pct | AH2: cumHPA20Pct | AI2: cumHPA25Pct | AJ2: cumHPA30Pct | AK2: cumHPA35Pct | AL2: cumHPA40Pct | AM2: adjtoverSmm | AN2: adjRefiSmm | AO2: groupByColumn | AP2: curve | AQ2: Balance | AR2: LoanCount | AS2: PCT_BROKER | AT2: PCT_CORRES | AU2: PCT_NonRETAIL | AV2: PCT_RETAIL | AW2: PCT_CashWindow | AX2: PCT_NonCashWindow
A3: 96 | B3: 0.99661762 | C3: 0 | D3: 3.9841936 | E3: 0 | F3: 0.00338238 | G3: 0 | H3: 3.875 | I3: 4.118472 | J3: -64.0619 | K3: -131.95 | L3: 13.16 | M3: 17 | N3: 80 | O3: 77.08 | P3: 303250.44 | Q3: 303250.44 | R3: 773 | S3: 0 | T3: 0 | U3: 0 | V3: 1 | W3: 0 | X3: 1 | Y3: 0 | Z3: 0.00035183 | AA3: 7.792e-05 | AB3: 0.00295262 | AC3: 0 | AD3: 0 | AE3: 0.011207683 | AF3: 1 | AG3: 1 | AH3: 1 | AI3: 1 | AJ3: 1 | AK3: 1 | AL3: 1 | AM3: 0 | AN3: 0 | AO3: 03:-150--125 | AP3: =-150--125 -> -25 | AQ3: 303250.44 | AR3: 1 | AS3: 0 | AT3: 0 | AU3: 0 | AV3: 100 | AW3: 100 | AX3: 0
A4: 96 | B4: 0.99252822 | C4: 5.6968752e-06 | D4: 8.6066971 | E4: 4.7473962e-09 | F4: 0.0074717783 | G4: 0 | H4: 3.9463145 | I4: 3.9968994 | J4: -50.059634 | K4: -110.17523 | L4: 17.060622 | M4: 16.808767 | N4: 78.188745 | O4: 75.620467 | P4: 244109.93 | Q4: 234046.42 | R4: 766.50335 | S4: 0 | T4: 0 | U4: 0 | V4: 0.52919184 | W4: 0 | X4: 0.62889958 | Y4: 0 | Z4: 0.0003521941 | AA4: 5.2415621e-05 | AB4: 0.0030302851 | AC4: 0 | AD4: 0.0040368678 | AE4: 0.007991849 | AF4: 1 | AG4: 1 | AH4: 1 | AI4: 1 | AJ4: 1 | AK4: 1 | AL4: 1 | AM4: 0 | AN4: 0 | AO4: 04:-125--100 | AP4: =-125--100 -> -25 | AQ4: 2106417.8 | AR4: 9 | AS4: 0 | AT4: 47.080816 | AU4: 47.080816 | AV4: 52.919184 | AW4: 52.919184 | AX4: 0
A5: 96 | B5: 0.9854146 | C5: 6.7240517 | D5: 16.164509 | E5: 0.005783867 | F5: 0.0145854 | G5: 0 | H5: 4.2182657 | I5: 4.013573 | J5: -25.41889 | K5: -83.743459 | L5: 15.531015 | M5: 16.933544 | N5: 77.580947 | O5: 76.058289 | P5: 294714 | Q5: 232023.63 | R5: 776.08752 | S5: 0 | T5: 0 | U5: 0 | V5: 0.32998978 | W5: 0 | X5: 0.59746948 | Y5: 0 | Z5: 0.00049507274 | AA5: 8.312075e-05 | AB5: 0.0028162319 | AC5: 0 | AD5: 0.011190961 | AE5: -0.016614367 | AF5: 1 | AG5: 1 | AH5: 1 | AI5: 1 | AJ5: 1 | AK5: 1 | AL5: 1 | AM5: 0 | AN5: 0 | AO5: 05:-100--75 | AP5: =-100--75 -> -25 | AQ5: 6960708.8 | AR5: 30 | AS5: 0 | AT5: 67.001022 | AU5: 67.001022 | AV5: 32.998978 | AW5: 32.998978 | AX5: 0
A6: 96 | B6: 0.99302902 | C6: 5.2786397 | D6: 8.0517863 | E6: 0.0045090249 | F6: 0.0069709777 | G6: 0 | H6: 3.9477649 | I6: 4.1009703 | J6: -54.901747 | K6: -56.696947 | L6: 17.807148 | M6: 16.26908 | N6: 78.049954 | O6: 76.132956 | P6: 262092.09 | Q6: 215006.84 | R6: 779.43956 | S6: 0 | T6: 0 | U6: 0.01112109 | V6: 0.10269525 | W6: 0 | X6: 0.47395975 | Y6: 0 | Z6: 0.00054578086 | AA6: 7.3191027e-05 | AB6: 0.0025300283 | AC6: 0 | AD6: 0.0038219663 | AE6: -0.020708407 | AF6: 0.99013984 | AG6: 0.99958902 | AH6: 1 | AI6: 1 | AJ6: 1 | AK6: 1 | AL6: 1 | AM6: 0 | AN6: 0 | AO6: 06:-75--50 | AP6: =-75--50 -> -25 | AQ6: 1.0922347e+08 | AR6: 508 | AS6: 0 | AT6: 89.730475 | AU6: 89.730475 | AV6: 10.269525 | AW6: 10.269525 | AX6: 0
A7: 96 | B7: 0.99230135 | C7: 3.4916301 | D7: 8.8570662 | E7: 0.0029573223 | F7: 0.0076986466 | G7: 0 | H7: 3.8980515 | I7: 4.1131381 | J7: -60.5987 | K7: -33.134227 | L7: 16.339431 | M7: 16.249137 | N7: 74.492152 | O7: 72.612313 | P7: 269597.48 | Q7: 241873.07 | R7: 781.68626 | S7: 0 | T7: 0 | U7: 0.0015742685 | V7: 0.10414133 | W7: 0 | X7: 0.56299853 | Y7: 0 | Z7: 0.00041375709 | AA7: 6.3290386e-05 | AB7: 0.0026439115 | AC7: 6.9562929e-08 | AD7: 0.0045776036 | AE7: -0.011974575 | AF7: 0.97730546 | AG7: 0.99838128 | AH7: 0.99991916 | AI7: 0.99994485 | AJ7: 1 | AK7: 1 | AL7: 1 | AM7: 0 | AN7: 0 | AO7: 07:-50--25 | AP7: =-50--25 -> -25 | AQ7: 1.3745647e+09 | AR7: 5683 | AS7: 0 | AT7: 89.585867 | AU7: 89.585867 | AV7: 10.414133 | AW7: 10.414133 | AX7: 0
A8: 96 | B8: 0.98517734 | C8: 8.9858228 | D8: 16.406414 | E8: 0.0078155401 | F8: 0.014822662 | G8: 0 | H8: 4.0839912 | I8: 4.0992866 | J8: -42.802675 | K8: -9.077472 | L8: 15.562581 | M8: 16.684523 | N8: 72.801902 | O8: 71.302563 | P8: 277573.09 | Q8: 255801.73 | R8: 781.6394 | S8: 0 | T8: 0 | U8: 0.0055783667 | V8: 0.17335332 | W8: 0 | X8: 0.67387035 | Y8: 0 | Z8: 0.00037869677 | AA8: 6.7589305e-05 | AB8: 0.0027038749 | AC8: 6.6407159e-08 | AD8: 0.011672421 | AE8: -0.010937131 | AF8: 0.96415011 | AG8: 0.99661693 | AH8: 0.99981099 | AI8: 0.9999929 | AJ8: 1 | AK8: 1 | AL8: 1 | AM8: 0 | AN8: 0 | AO8: 08:-25-0 | AP8: =-25-0 -> -25 | AQ8: 9.5132663e+09 | AR8: 37190 | AS8: 0 | AT8: 82.664668 | AU8: 82.664668 | AV8: 17.335332 | AW8: 17.335332 | AX8: 0
A9: 96 | B9: 0.97895773 | C9: 18.38865 | D9: 22.52398 | E9: 0.016790921 | F9: 0.021042266 | G9: 0 | H9: 4.1856762 | I9: 4.0349491 | J9: -31.48218 | K9: 15.556412 | L9: 15.419536 | M9: 16.797045 | N9: 70.287528 | O9: 68.272532 | P9: 278926.35 | Q9: 258748.86 | R9: 782.30504 | S9: 0 | T9: 0 | U9: 0.018630946 | V9: 0.22529398 | W9: 0 | X9: 0.7659469 | Y9: 0 | Z9: 0.00037470468 | AA9: 7.2227262e-05 | AB9: 0.0028529876 | AC9: 7.4895964e-07 | AD9: 0.017741583 | AE9: -0.0021583667 | AF9: 0.90462044 | AG9: 0.98731819 | AH9: 0.9990021 | AI9: 0.9997661 | AJ9: 1 | AK9: 1 | AL9: 1 | AM9: 0 | AN9: 0 | AO9: 09:0-25 | AP9: 0-25 | AQ9: 4.3439276e+10 | AR9: 167882 | AS9: 0 | AT9: 77.470602 | AU9: 77.470602 | AV9: 22.529398 | AW9: 22.529398 | AX9: 0
A10: 96 | B10: 0.97148998 | C10: 30.040524 | D10: 29.325964 | E10: 0.029332373 | F10: 0.028510022 | G10: 0 | H10: 4.2143899 | I10: 3.8971895 | J10: -25.950779 | K10: 37.631504 | L10: 14.739426 | M10: 16.897771 | N10: 67.763986 | O10: 64.590286 | P10: 291283.19 | Q10: 270760.84 | R10: 782.49323 | S10: 0 | T10: 0 | U10: 0.026265113 | V10: 0.29598121 | W10: 0 | X10: 0.77482505 | Y10: 0 | Z10: 0.00037210515 | AA10: 7.1539095e-05 | AB10: 0.0030783518 | AC10: 3.8252828e-06 | AD10: 0.024984187 | AE10: 0.018675681 | AF10: 0.78093487 | AG10: 0.95971894 | AH10: 0.99639404 | AI10: 0.99938141 | AJ10: 1 | AK10: 1 | AL10: 1 | AM10: 0 | AN10: 0 | AO10: 10:25-50 | AP10: 25-50 | AQ10: 8.4135411e+10 | AR10: 310737 | AS10: 0 | AT10: 70.401879 | AU10: 70.401879 | AV10: 29.598121 | AW10: 29.598121 | AX10: 0
A11: 96 | B11: 0.96304728 | C11: 38.503459 | D11: 36.353973 | E11: 0.039705981 | F11: 0.036952722 | G11: 0 | H11: 4.4368642 | I11: 3.8641721 | J11: -16.151405 | K11: 62.402857 | L11: 15.006188 | M11: 17.333592 | N11: 69.32168 | O11: 65.791755 | P11: 285956.09 | Q11: 266022.72 | R11: 781.36518 | S11: 0 | T11: 0 | U11: 0.017246459 | V11: 0.26913712 | W11: 0 | X11: 0.68911647 | Y11: 0 | Z11: 0.00037305399 | AA11: 9.3431204e-05 | AB11: 0.0032090483 | AC11: 6.5567071e-06 | AD11: 0.033270617 | AE11: 0.022898189 | AF11: 0.74905845 | AG11: 0.96768233 | AH11: 0.99533969 | AI11: 0.99918041 | AJ11: 1 | AK11: 1 | AL11: 1 | AM11: 0 | AN11: 0 | AO11: 11:50-75 | AP11: 50-75 | AQ11: 7.8589496e+10 | AR11: 295424 | AS11: 0 | AT11: 73.086288 | AU11: 73.086288 | AV11: 26.913712 | AW11: 26.913712 | AX11: 0
A12: 96 | B12: 0.95601851 | C12: 42.321031 | D12: 41.70979 | E12: 0.044820945 | F12: 0.043981488 | G12: 0 | H12: 4.6559703 | I12: 3.8591563 | J12: -9.7638859 | K12: 86.123758 | L12: 14.913043 | M12: 17.0088 | N12: 69.232774 | O12: 65.248225 | P12: 287995.72 | Q12: 267721.99 | R12: 780.41619 | S12: 0 | T12: 0 | U12: 0.020502104 | V12: 0.22821933 | W12: 0 | X12: 0.60331037 | Y12: 0 | Z12: 0.00037169276 | AA12: 0.00011387914 | AB12: 0.0033322116 | AC12: 1.201048e-05 | AD12: 0.04015168 | AE12: 0.030369194 | AF12: 0.66788664 | AG12: 0.96158044 | AH12: 0.99290723 | AI12: 0.99891846 | AJ12: 1 | AK12: 1 | AL12: 1 | AM12: 0 | AN12: 0 | AO12: 12:75-100 | AP12: 75-100 | AQ12: 5.6874592e+10 | AR12: 212439 | AS12: 0 | AT12: 77.178067 | AU12: 77.178067 | AV12: 22.821933 | AW12: 22.821933 | AX12: 0
A13: 96 | B13: 0.95189661 | C13: 43.12208 | D13: 44.655134 | E13: 0.04593351 | F13: 0.048103395 | G13: 0 | H13: 4.8030413 | I13: 3.7634676 | J13: -5.7722298 | K13: 111.83503 | L13: 15.334443 | M13: 18.015841 | N13: 71.743211 | O13: 66.415984 | P13: 280024.33 | Q13: 260387.68 | R13: 779.64711 | S13: 0 | T13: 0 | U13: 0.020326776 | V13: 0.19832743 | W13: 0 | X13: 0.5239136 | Y13: 0 | Z13: 0.00037232537 | AA13: 0.00015299831 | AB13: 0.0035511637 | AC13: 2.5455984e-05 | AD13: 0.044001437 | AE13: 0.0483106 | AF13: 0.52474891 | AG13: 0.94444348 | AH13: 0.98895168 | AI13: 0.99789176 | AJ13: 1 | AK13: 1 | AL13: 1 | AM13: 0 | AN13: 0 | AO13: 13:100-125 | AP13: 100-125 | AQ13: 3.4432625e+10 | AR13: 132236 | AS13: 0 | AT13: 80.167257 | AU13: 80.167257 | AV13: 19.832743 | AW13: 19.832743 | AX13: 0
A14: 96 | B14: 0.94783045 | C14: 44.269541 | D14: 47.426383 | E14: 0.047552488 | F14: 0.052169555 | G14: 0 | H14: 4.8889524 | I14: 3.6792057 | J14: -3.8986406 | K14: 134.42076 | L14: 14.770577 | M14: 19.531062 | N14: 71.612656 | O14: 64.954466 | P14: 290001.43 | Q14: 270333.94 | R14: 778.9718 | S14: 0 | T14: 0 | U14: 0.02522111 | V14: 0.19016647 | W14: 0 | X14: 0.54162081 | Y14: 0 | Z14: 0.00037264217 | AA14: 0.00018728601 | AB14: 0.003504326 | AC14: 6.1669801e-05 | AD14: 0.048043616 | AE14: 0.069205256 | AF14: 0.41271197 | AG14: 0.90810374 | AH14: 0.97485773 | AI14: 0.99639125 | AJ14: 1 | AK14: 1 | AL14: 1 | AM14: 0 | AN14: 0 | AO14: 14:125-150 | AP14: 125-150 | AQ14: 1.5644766e+10 | AR14: 57872 | AS14: 0 | AT14: 80.983353 | AU14: 80.983353 | AV14: 19.016647 | AW14: 19.016647 | AX14: 0
A15: 96 | B15: 0.94467187 | C15: 42.416446 | D15: 49.490649 | E15: 0.04495272 | F15: 0.055328132 | G15: 0 | H15: 5.0523345 | I15: 3.6782356 | J15: 10.451198 | K15: 160.53489 | L15: 15.095943 | M15: 19.642718 | N15: 78.39791 | O15: 69.638817 | P15: 283783.99 | Q15: 264513.08 | R15: 777.32325 | S15: 0 | T15: 0 | U15: 0.017271692 | V15: 0.20360918 | W15: 0 | X15: 0.51465179 | Y15: 0 | Z15: 0.00037609829 | AA15: 0.00026329363 | AB15: 0.0037406843 | AC15: 0.00013096224 | AD15: 0.050817078 | AE15: 0.089601936 | AF15: 0.30801846 | AG15: 0.82214205 | AH15: 0.94504783 | AI15: 0.99151767 | AJ15: 1 | AK15: 1 | AL15: 1 | AM15: 0 | AN15: 0 | AO15: 15:150-175 | AP15: 150-175 | AQ15: 3.2484851e+09 | AR15: 12281 | AS15: 0 | AT15: 79.639082 | AU15: 79.639082 | AV15: 20.360918 | AW15: 20.360918 | AX15: 0
A16: 96 | B16: 0.93912402 | C16: 49.699111 | D16: 52.937456 | E16: 0.055653653 | F16: 0.060875978 | G16: 0 | H16: 5.08771 | I16: 3.6602132 | J16: 14.433686 | K16: 183.23039 | L16: 14.066214 | M16: 20.006563 | N16: 82.573291 | O16: 70.81271 | P16: 301542.67 | Q16: 283874.48 | R16: 776.71346 | S16: 0 | T16: 0 | U16: 0.014774893 | V16: 0.14884716 | W16: 0 | X16: 0.49026382 | Y16: 0 | Z16: 0.00037924852 | AA16: 0.00032323157 | AB16: 0.0038561489 | AC16: 0.00039488146 | AD16: 0.055922451 | AE16: 0.12536342 | AF16: 0.18089512 | AG16: 0.64354096 | AH16: 0.82094044 | AI16: 0.96473361 | AJ16: 1 | AK16: 1 | AL16: 1 | AM16: 0 | AN16: 0 | AO16: 16:175-200 | AP16: 175-200 | AQ16: 8.0705515e+08 | AR16: 2843 | AS16: 0 | AT16: 85.115284 | AU16: 85.115284 | AV16: 14.884716 | AW16: 14.884716 | AX16: 0
A17: 96 | B17: 0.93745664 | C17: 40.294314 | D17: 53.930419 | E17: 0.042068089 | F17: 0.062543363 | G17: 0 | H17: 5.1697091 | I17: 3.6671452 | J17: 19.100507 | K17: 209.2428 | L17: 14.634743 | M17: 20.249616 | N17: 89.708323 | O17: 74.667695 | P17: 293970.51 | Q17: 272848.93 | R17: 775.48884 | S17: 0 | T17: 0 | U17: 0.01394964 | V17: 0.11440628 | W17: 0 | X17: 0.31912774 | Y17: 0 | Z17: 0.00038583756 | AA17: 0.00041282419 | AB17: 0.0042255695 | AC17: 0.00068701308 | AD17: 0.056832102 | AE17: 0.15845744 | AF17: 0.047185182 | AG17: 0.44358389 | AH17: 0.70975847 | AI17: 0.93055656 | AJ17: 1 | AK17: 1 | AL17: 1 | AM17: 0 | AN17: 0 | AO17: 17:200-225 | AP17: 200-225 | AQ17: 1.394258e+08 | AR17: 511 | AS17: 0 | AT17: 88.559372 | AU17: 88.559372 | AV17: 11.440628 | AW17: 11.440628 | AX17: 0
A18: 96 | B18: 0.93452588 | C18: 22.261828 | D18: 55.629327 | E18: 0.020766655 | F18: 0.065474117 | G18: 0 | H18: 5.2637101 | I18: 3.6463383 | J18: 27.126595 | K18: 231.8549 | L18: 13.891115 | M18: 20.806704 | N18: 92.564127 | O18: 74.572096 | P18: 308393.03 | Q18: 287462.08 | R18: 776.67354 | S18: 0 | T18: 0 | U18: 0 | V18: 0.02793355 | W18: 0 | X18: 0.14885189 | Y18: 0 | Z18: 0.00038200278 | AA18: 0.00051270754 | AB18: 0.0044189107 | AC18: 0.0013464358 | AD18: 0.058814042 | AE18: 0.19904467 | AF18: 0 | AG18: 0.17152724 | AH18: 0.37747711 | AI18: 0.91231698 | AJ18: 1 | AK18: 1 | AL18: 1 | AM18: 0 | AN18: 0 | AO18: 18:225-250 | AP18: 225-250 | AQ18: 23571890 | AR18: 82 | AS18: 0 | AT18: 97.206645 | AU18: 97.206645 | AV18: 2.793355 | AW18: 2.793355 | AX18: 0
K25: turn | L25: cash | M25: refi | R25: turn | W25: cash | AB25: refi
A26: incentive | B26: =AQ2 -> Balance | C26: =AO2 -> groupByColumn | D26: =E2 -> PREPAY_SMM1 | E26: =F2 -> PREPAY_TRACKING_SMM1 | F26: ratio | G26: =C2 -> PREPAY_CPR1 | H26: =D2 -> PREPAY_TRACKING_CPR1 | K26: adj | L26: adj | M26: adj | N26: mdl_smm | O26: mdl_cpr | P26: ratio | R26: x | T26: Knot | U26: adj Knot | W26: x | X26: adj x | Y26: Knot | Z26: adj Knot | AB26: x | AC26: adj x | AD26: Knot | AE26: adj Knot
A27: =K3 -> -131.95 | B27: =AQ3/1000000000 -> 0.00030325044 | C27: =AO3 -> 03:-150--125 | D27: =E3 -> 0 | E27: =Z3+AA3+AB3+AC3+AD3 -> 0.00338237 | F27: =D27/E27 -> 0 | G27: =(1-(1-D27)^12)*100 -> 0 | H27: =(1-(1-E27)^12)*100 -> 3.984182 | K27: 1 | L27: 1 | M27: 1 | N27: =Z3+AA3+AB3*K27+AC3*L27+AD3*M27 -> 0.00338237 | O27: =100*(1-(1-N27)^12) -> 3.984182 | P27: =D27/N27 -> 0 | S27: =A27 -> -131.95 | T27: =VLOOKUP(ROUNDDOWN(S27,0),'Spline Pre-Adj'!A:B,2,0) -> 0.95832877 | U27: =T27*K27 -> 0.95832877
A28: =K4 -> -110.17523 | B28: =AQ4/1000000000 -> 0.0021064178 | C28: =AO4 -> 04:-125--100 | D28: =E4 -> 4.7473962e-09 | E28: =Z4+AA4+AB4+AC4+AD4 -> 0.0074717626 | F28: =D28/E28 -> 6.3537835e-07 | G28: =(1-(1-D28)^12)*100 -> 5.6968754e-06 | H28: =(1-(1-E28)^12)*100 -> 8.6066798 | K28: 1 | L28: 1 | M28: 1 | N28: =Z4+AA4+AB4*K28+AC4*L28+AD4*M28 -> 0.0074717626 | O28: =100*(1-(1-N28)^12) -> 8.6066798 | P28: =D28/N28 -> 6.3537835e-07 | S28: =A28 -> -110.17523 | T28: =VLOOKUP(ROUNDDOWN(S28,0),'Spline Pre-Adj'!A:B,2,0) -> 1.012994 | U28: =T28*K28 -> 1.012994 | X28: =A28 -> -110.17523 | Y28: =VLOOKUP(ROUNDDOWN(X28,0),'Spline Pre-Adj'!F:G,2,0) -> 0 | Z28: =Y28*L28 -> 0
A29: =K5 -> -83.743459 | B29: =AQ5/1000000000 -> 0.0069607088 | C29: =AO5 -> 05:-100--75 | D29: =E5 -> 0.005783867 | E29: =Z5+AA5+AB5+AC5+AD5 -> 0.014585386 | F29: =D29/E29 -> 0.3965522 | G29: =(1-(1-D29)^12)*100 -> 6.7240517 | H29: =(1-(1-E29)^12)*100 -> 16.164495 | K29: 1 | L29: 1 | M29: 1 | N29: =Z5+AA5+AB5*K29+AC5*L29+AD5*M29 -> 0.014585386 | O29: =100*(1-(1-N29)^12) -> 16.164495 | P29: =D29/N29 -> 0.3965522 | S29: =A29 -> -83.743459 | T29: =VLOOKUP(ROUNDDOWN(S29,0),'Spline Pre-Adj'!A:B,2,0) -> 1.1352282 | U29: =T29*K29 -> 1.1352282 | X29: =A29 -> -83.743459 | Y29: =VLOOKUP(ROUNDDOWN(X29,0),'Spline Pre-Adj'!F:G,2,0) -> 0.031256267 | Z29: =Y29*L29 -> 0.031256267
A30: =K6 -> -56.696947 | B30: =AQ6/1000000000 -> 0.10922347 | C30: =AO6 -> 06:-75--50 | D30: =E6 -> 0.0045090249 | E30: =Z6+AA6+AB6+AC6+AD6 -> 0.0069709665 | F30: =D30/E30 -> 0.64682922 | G30: =(1-(1-D30)^12)*100 -> 5.2786397 | H30: =(1-(1-E30)^12)*100 -> 8.0517738 | K30: 1 | L30: 1 | M30: 0.5 | N30: =Z6+AA6+AB6*K30+AC6*L30+AD6*M30 -> 0.0050599834 | O30: =100*(1-(1-N30)^12) -> 5.9058153 | P30: =D30/N30 -> 0.89111456 | S30: =A30 -> -56.696947 | T30: =VLOOKUP(ROUNDDOWN(S30,0),'Spline Pre-Adj'!A:B,2,0) -> 1.2795489 | U30: =T30*K30 -> 1.2795489 | X30: =A30 -> -56.696947 | Y30: =VLOOKUP(ROUNDDOWN(X30,0),'Spline Pre-Adj'!F:G,2,0) -> 0.18862313 | Z30: =Y30*L30 -> 0.18862313 | AC30: =A30 -> -56.696947 | AD30: =VLOOKUP(ROUNDDOWN(AC30,0),'Spline Pre-Adj'!K:L,2,0) -> 0 | AE30: =AD30*M30 -> 0
A31: =K7 -> -33.134227 | B31: =AQ7/1000000000 -> 1.3745647 | C31: =AO7 -> 07:-50--25 | D31: =E7 -> 0.0029573223 | E31: =Z7+AA7+AB7+AC7+AD7 -> 0.0076986322 | F31: =D31/E31 -> 0.38413608 | G31: =(1-(1-D31)^12)*100 -> 3.4916301 | H31: =(1-(1-E31)^12)*100 -> 8.8570502 | K31: 1 | L31: 1 | M31: 0.5 | N31: =Z7+AA7+AB7*K31+AC7*L31+AD7*M31 -> 0.0054098304 | O31: =100*(1-(1-N31)^12) -> 6.3020802 | P31: =D31/N31 -> 0.54665713 | S31: =A31 -> -33.134227 | T31: =VLOOKUP(ROUNDDOWN(S31,0),'Spline Pre-Adj'!A:B,2,0) -> 1.287 | U31: =T31*K31 -> 1.287 | X31: =A31 -> -33.134227 | Y31: =VLOOKUP(ROUNDDOWN(X31,0),'Spline Pre-Adj'!F:G,2,0) -> 0.30615061 | Z31: =Y31*L31 -> 0.30615061 | AC31: =A31 -> -33.134227 | AD31: =VLOOKUP(ROUNDDOWN(AC31,0),'Spline Pre-Adj'!K:L,2,0) -> 0.39387319 | AE31: =AD31*M31 -> 0.1969366
A32: =K8 -> -9.077472 | B32: =AQ8/1000000000 -> 9.5132663 | C32: =AO8 -> 08:-25-0 | D32: =E8 -> 0.0078155401 | E32: =Z8+AA8+AB8+AC8+AD8 -> 0.014822648 | F32: =D32/E32 -> 0.52727017 | G32: =(1-(1-D32)^12)*100 -> 8.9858228 | H32: =(1-(1-E32)^12)*100 -> 16.406399 | K32: 1 | L32: 1 | M32: 0.55 | N32: =Z8+AA8+AB8*K32+AC8*L32+AD8*M32 -> 0.0095700587 | O32: =100*(1-(1-N32)^12) -> 10.898476 | P32: =D32/N32 -> 0.81666585 | S32: =A32 -> -9.077472 | T32: =VLOOKUP(ROUNDDOWN(S32,0),'Spline Pre-Adj'!A:B,2,0) -> 1.287 | U32: =T32*K32 -> 1.287 | X32: =A32 -> -9.077472 | Y32: =VLOOKUP(ROUNDDOWN(X32,0),'Spline Pre-Adj'!F:G,2,0) -> 0.51930077 | Z32: =Y32*L32 -> 0.51930077 | AC32: =A32 -> -9.077472 | AD32: =VLOOKUP(ROUNDDOWN(AC32,0),'Spline Pre-Adj'!K:L,2,0) -> 1.1530058 | AE32: =AD32*M32 -> 0.6341532
A33: =K9 -> 15.556412 | B33: =AQ9/1000000000 -> 43.439276 | C33: =AO9 -> 09:0-25 | D33: =E9 -> 0.016790921 | E33: =Z9+AA9+AB9+AC9+AD9 -> 0.021042252 | F33: =D33/E33 -> 0.7979622 | G33: =(1-(1-D33)^12)*100 -> 18.38865 | H33: =(1-(1-E33)^12)*100 -> 22.523967 | K33: 1 | L33: 1 | M33: 0.8 | N33: =Z9+AA9+AB9*K33+AC9*L33+AD9*M33 -> 0.017493935 | O33: =100*(1-(1-N33)^12) -> 19.086147 | P33: =D33/N33 -> 0.95981386 | S33: =A33 -> 15.556412 | T33: =VLOOKUP(ROUNDDOWN(S33,0),'Spline Pre-Adj'!A:B,2,0) -> 1.287 | U33: =T33*K33 -> 1.287 | X33: =A33 -> 15.556412 | Y33: =VLOOKUP(ROUNDDOWN(X33,0),'Spline Pre-Adj'!F:G,2,0) -> 0.98856376 | Z33: =Y33*L33 -> 0.98856376 | AC33: =A33 -> 15.556412 | AD33: =VLOOKUP(ROUNDDOWN(AC33,0),'Spline Pre-Adj'!K:L,2,0) -> 1.7164152 | AE33: =AD33*M33 -> 1.3731322
A34: =K10 -> 37.631504 | B34: =AQ10/1000000000 -> 84.135411 | C34: =AO10 -> 10:25-50 | D34: =E10 -> 0.029332373 | E34: =Z10+AA10+AB10+AC10+AD10 -> 0.028510008 | F34: =D34/E34 -> 1.0288448 | G34: =(1-(1-D34)^12)*100 -> 30.040524 | H34: =(1-(1-E34)^12)*100 -> 29.325951 | K34: 1 | L34: 1 | M34: 1.05 | N34: =Z10+AA10+AB10*K34+AC10*L34+AD10*M34 -> 0.029759218 | O34: =100*(1-(1-N34)^12) -> 30.408803 | P34: =D34/N34 -> 0.98565673 | S34: =A34 -> 37.631504 | T34: =VLOOKUP(ROUNDDOWN(S34,0),'Spline Pre-Adj'!A:B,2,0) -> 1.287 | U34: =T34*K34 -> 1.287 | X34: =A34 -> 37.631504 | Y34: =VLOOKUP(ROUNDDOWN(X34,0),'Spline Pre-Adj'!F:G,2,0) -> 1.8953738 | Z34: =Y34*L34 -> 1.8953738 | AC34: =A34 -> 37.631504 | AD34: =VLOOKUP(ROUNDDOWN(AC34,0),'Spline Pre-Adj'!K:L,2,0) -> 2.4264029 | AE34: =AD34*M34 -> 2.5477231
A35: =K11 -> 62.402857 | B35: =AQ11/1000000000 -> 78.589496 | C35: =AO11 -> 11:50-75 | D35: =E11 -> 0.039705981 | E35: =Z11+AA11+AB11+AC11+AD11 -> 0.036952707 | F35: =D35/E35 -> 1.074508 | G35: =(1-(1-D35)^12)*100 -> 38.503459 | H35: =(1-(1-E35)^12)*100 -> 36.353962 | K35: 1 | L35: 1 | M35: 1.1 | N35: =Z11+AA11+AB11*K35+AC11*L35+AD11*M35 -> 0.040279769 | O35: =100*(1-(1-N35)^12) -> 38.942953 | P35: =D35/N35 -> 0.98575492 | S35: =A35 -> 62.402857 | T35: =VLOOKUP(ROUNDDOWN(S35,0),'Spline Pre-Adj'!A:B,2,0) -> 1.287 | U35: =T35*K35 -> 1.287 | X35: =A35 -> 62.402857 | Y35: =VLOOKUP(ROUNDDOWN(X35,0),'Spline Pre-Adj'!F:G,2,0) -> 3.3799458 | Z35: =Y35*L35 -> 3.3799458 | AC35: =A35 -> 62.402857 | AD35: =VLOOKUP(ROUNDDOWN(AC35,0),'Spline Pre-Adj'!K:L,2,0) -> 3.3536482 | AE35: =AD35*M35 -> 3.689013
A36: =K12 -> 86.123758 | B36: =AQ12/1000000000 -> 56.874592 | C36: =AO12 -> 12:75-100 | D36: =E12 -> 0.044820945 | E36: =Z12+AA12+AB12+AC12+AD12 -> 0.043981474 | F36: =D36/E36 -> 1.0190869 | G36: =(1-(1-D36)^12)*100 -> 42.321031 | H36: =(1-(1-E36)^12)*100 -> 41.709779 | K36: 1 | L36: 1 | M36: 1.02 | N36: =Z12+AA12+AB12*K36+AC12*L36+AD12*M36 -> 0.044784507 | O36: =100*(1-(1-N36)^12) -> 42.294622 | P36: =D36/N36 -> 1.0008136 | S36: =A36 -> 86.123758 | T36: =VLOOKUP(ROUNDDOWN(S36,0),'Spline Pre-Adj'!A:B,2,0) -> 1.287 | U36: =T36*K36 -> 1.287 | X36: =A36 -> 86.123758 | Y36: =VLOOKUP(ROUNDDOWN(X36,0),'Spline Pre-Adj'!F:G,2,0) -> 4.7646641 | Z36: =Y36*L36 -> 4.7646641 | AC36: =A36 -> 86.123758 | AD36: =VLOOKUP(ROUNDDOWN(AC36,0),'Spline Pre-Adj'!K:L,2,0) -> 4.1191353 | AE36: =AD36*M36 -> 4.201518
A37: =K13 -> 111.83503 | B37: =AQ13/1000000000 -> 34.432625 | C37: =AO13 -> 13:100-125 | D37: =E13 -> 0.04593351 | E37: =Z13+AA13+AB13+AC13+AD13 -> 0.04810338 | F37: =D37/E37 -> 0.95489152 | G37: =(1-(1-D37)^12)*100 -> 43.12208 | H37: =(1-(1-E37)^12)*100 -> 44.655124 | K37: 1 | L37: 1 | M37: 0.95 | N37: =Z13+AA13+AB13*K37+AC13*L37+AD13*M37 -> 0.045903308 | O37: =100*(1-(1-N37)^12) -> 43.10047 | P37: =D37/N37 -> 1.0006579 | X37: =A37 -> 111.83503 | Y37: =VLOOKUP(ROUNDDOWN(X37,0),'Spline Pre-Adj'!F:G,2,0) -> 6.2168085 | Z37: =Y37*L37 -> 6.2168085 | AC37: =A37 -> 111.83503 | AD37: =VLOOKUP(ROUNDDOWN(AC37,0),'Spline Pre-Adj'!K:L,2,0) -> 4.729914 | AE37: =AD37*M37 -> 4.4934183
A38: =K14 -> 134.42076 | B38: =AQ14/1000000000 -> 15.644766 | C38: =AO14 -> 14:125-150 | D38: =E14 -> 0.047552488 | E38: =Z14+AA14+AB14+AC14+AD14 -> 0.05216954 | F38: =D38/E38 -> 0.91149908 | G38: =(1-(1-D38)^12)*100 -> 44.269541 | H38: =(1-(1-E38)^12)*100 -> 47.426374 | K38: 1 | L38: 1 | M38: 0.92 | N38: =Z14+AA14+AB14*K38+AC14*L38+AD14*M38 -> 0.048326051 | O38: =100*(1-(1-N38)^12) -> 44.810282 | P38: =D38/N38 -> 0.98399284 | X38: =A38 -> 134.42076 | Y38: =VLOOKUP(ROUNDDOWN(X38,0),'Spline Pre-Adj'!F:G,2,0) -> 7.6066289 | Z38: =Y38*L38 -> 7.6066289 | AC38: =A38 -> 134.42076 | AD38: =VLOOKUP(ROUNDDOWN(AC38,0),'Spline Pre-Adj'!K:L,2,0) -> 5.205107 | AE38: =AD38*M38 -> 4.7886984
A39: =K15 -> 160.53489 | B39: =AQ15/1000000000 -> 3.2484851 | C39: =AO15 -> 15:150-175 | D39: =E15 -> 0.04495272 | E39: =Z15+AA15+AB15+AC15+AD15 -> 0.055328117 | F39: =D39/E39 -> 0.81247515 | G39: =(1-(1-D39)^12)*100 -> 42.416446 | H39: =(1-(1-E39)^12)*100 -> 49.490639 | K39: 1 | L39: 1 | M39: 0.9 | N39: =Z15+AA15+AB15*K39+AC15*L39+AD15*M39 -> 0.050246409 | O39: =100*(1-(1-N39)^12) -> 46.13194 | P39: =D39/N39 -> 0.89464542 | X39: =A39 -> 160.53489 | Y39: =VLOOKUP(ROUNDDOWN(X39,0),'Spline Pre-Adj'!F:G,2,0) -> 8.7434836 | Z39: =Y39*L39 -> 8.7434836 | AC39: =A39 -> 160.53489 | AD39: =VLOOKUP(ROUNDDOWN(AC39,0),'Spline Pre-Adj'!K:L,2,0) -> 5.6662697 | AE39: =AD39*M39 -> 5.0996428
A40: =K16 -> 183.23039 | B40: =AQ16/1000000000 -> 0.80705515 | C40: =AO16 -> 16:175-200 | D40: =E16 -> 0.055653653 | E40: =Z16+AA16+AB16+AC16+AD16 -> 0.060875962 | F40: =D40/E40 -> 0.91421394 | G40: =(1-(1-D40)^12)*100 -> 49.699111 | H40: =(1-(1-E40)^12)*100 -> 52.937447 | K40: 1 | L40: 1 | M40: 0.9 | N40: =Z16+AA16+AB16*K40+AC16*L40+AD16*M40 -> 0.055283716 | O40: =100*(1-(1-N40)^12) -> 49.462144 | P40: =D40/N40 -> 1.0066916 | X40: =A40 -> 183.23039 | Y40: =VLOOKUP(ROUNDDOWN(X40,0),'Spline Pre-Adj'!F:G,2,0) -> 8.8912891 | Z40: =Y40*L40 -> 8.8912891 | AC40: =A40 -> 183.23039 | AD40: =VLOOKUP(ROUNDDOWN(AC40,0),'Spline Pre-Adj'!K:L,2,0) -> 6.0276934 | AE40: =AD40*M40 -> 5.4249241
A41: =K17 -> 209.2428 | B41: =AQ17/1000000000 -> 0.1394258 | C41: =AO17 -> 17:200-225 | D41: =E17 -> 0.042068089 | E41: =Z17+AA17+AB17+AC17+AD17 -> 0.062543346 | F41: =D41/E41 -> 0.67262294 | G41: =(1-(1-D41)^12)*100 -> 40.294314 | H41: =(1-(1-E41)^12)*100 -> 53.930409 | K41: 1 | L41: 1 | M41: 1.05 | N41: =Z17+AA17+AB17*K41+AC17*L41+AD17*M41 -> 0.065384951 | O41: =100*(1-(1-N41)^12) -> 55.578498 | P41: =D41/N41 -> 0.643391 | X41: =A41 -> 209.2428 | Y41: =VLOOKUP(ROUNDDOWN(X41,0),'Spline Pre-Adj'!F:G,2,0) -> 8.9 | Z41: =Y41*L41 -> 8.9 | AC41: =A41 -> 209.2428 | AD41: =VLOOKUP(ROUNDDOWN(AC41,0),'Spline Pre-Adj'!K:L,2,0) -> 6.3657669 | AE41: =AD41*M41 -> 6.6840552
A67: WALA [12,24) | C67: BROKER | AS67: tover | AT67: cash | AW67: refi
A68: modelId | B68: SFACTOR_PREPAY_TRACKING_CPR | C68: PREPAY_CPR1 | D68: PREPAY_TRACKING_CPR1 | E68: PREPAY_SMM1 | F68: PREPAY_TRACKING_SMM1 | G68: PCT_LOANTYPE | H68: _ORIGNOTERATE | I68: _ZEROSATO | J68: _SATO | K68: _REFI_INCENTIVE_Fixed | L68: _Fixed_cost | M68: _LOANAGE | N68: _LTV | O68: _CLTV | P68: _AVG_LOANSIZE_SCHAMBALANCE | Q68: _WACLS | R68: _FICO | S68: PCT_ISSECONDLIEN | T68: _OrigCombLTV | U68: PCT_SVC | V68: PCT_TPO | W68: PCT_GEO | X68: PCT_LOANPURPOSE | Y68: PCT_OCC | Z68: curtailsmm | AA68: defaultsmm | AB68: toverSmm | AC68: cashoutSmm | AD68: refiSmm | AE68: cumHPA | AF68: cumHPA05Pct | AG68: cumHPA15Pct | AH68: cumHPA20Pct | AI68: cumHPA25Pct | AJ68: cumHPA30Pct | AK68: cumHPA35Pct | AL68: cumHPA40Pct | AM68: adjtoverSmm | AN68: adjRefiSmm | AO68: groupByColumn | AP68: curve | AQ68: Balance | AR68: LoanCount | AS68: PCT_BROKER | AT68: PCT_CORRES | AU68: PCT_NonRETAIL | AV68: PCT_RETAIL | AW68: PCT_CashWindow | AX68: PCT_NonCashWindow
A69: 96 | B69: 0.99182842 | C69: 3.8957922 | D69: 9.3769677 | E69: 0.003305947 | F69: 0.0081715784 | G69: 0 | H69: 3.9675065 | I69: 4.1283936 | J69: -54.678879 | K69: -56.682817 | L69: 18.767246 | M69: 16.274611 | N69: 77.853085 | O69: 75.207731 | P69: 267569.16 | Q69: 188541.3 | R69: 773.89744 | S69: 0 | T69: 0 | U69: 0.071689611 | V69: 0 | W69: 0 | X69: 0.5444671 | Y69: 0 | Z69: 0.0007036877 | AA69: 8.8031509e-05 | AB69: 0.0025907227 | AC69: 3.7428656e-08 | AD69: 0.0047890873 | AE69: -0.022818134 | AF69: 0.98731299 | AG69: 0.99644125 | AH69: 1 | AI69: 1 | AJ69: 1 | AK69: 1 | AL69: 1 | AM69: 0 | AN69: 0 | AO69: 06:-75--50 | AP69: =-75--50 -> -25 | AQ69: 17345800 | AR69: 92 | AS69: 100 | AT69: 0 | AU69: 100 | AV69: 0 | AW69: 0 | AX69: 0
A70: 96 | B70: 0.99146676 | C70: 2.5593301 | D70: 9.7727093 | E70: 0.00215821 | F70: 0.0085332374 | G70: 0 | H70: 3.8999139 | I70: 4.1100912 | J70: -59.796144 | K70: -32.151317 | L70: 15.206687 | M70: 16.277653 | N70: 74.240428 | O70: 72.758628 | P70: 291058.35 | Q70: 258641.71 | R70: 784.51618 | S70: 0 | T70: 0 | U70: 0.067353074 | V70: 0 | W70: 0 | X70: 0.6198173 | Y70: 0 | Z70: 0.00044165102 | AA70: 6.54869e-05 | AB70: 0.0025421345 | AC70: 2.7072769e-08 | AD70: 0.0054839232 | AE70: -0.017049304 | AF70: 0.97692522 | AG70: 0.99625024 | AH70: 1 | AI70: 1 | AJ70: 1 | AK70: 1 | AL70: 1 | AM70: 0 | AN70: 0 | AO70: 07:-50--25 | AP70: =-50--25 -> -25 | AQ70: 1.8285969e+08 | AR70: 707 | AS70: 100 | AT70: 0 | AU70: 100 | AV70: 0 | AW70: 0 | AX70: 0
A71: 96 | B71: 0.98853892 | C71: 9.4220487 | D71: 12.918625 | E71: 0.0082127038 | F71: 0.011461079 | G71: 0 | H71: 3.9787687 | I71: 4.11636 | J71: -52.192348 | K71: -22.234953 | L71: 15.058437 | M71: 16.143549 | N71: 73.258944 | O71: 71.898842 | P71: 289927.42 | Q71: 263943.27 | R71: 783.4957 | S71: 0 | T71: 0 | U71: 0.12846874 | V71: 0 | W71: 0 | X71: 0.65047953 | Y71: 0 | Z71: 0.00038934545 | AA71: 5.3528718e-05 | AB71: 0.0025274232 | AC71: 0 | AD71: 0.0084907668 | AE71: -0.013797444 | AF71: 0.98291916 | AG71: 1 | AH71: 1 | AI71: 1 | AJ71: 1 | AK71: 1 | AL71: 1 | AM71: 0 | AN71: 0 | AO71: 08-1:-25--20 | AP71: =-25--20 -> -5 | AQ71: 1.0425759e+08 | AR71: 395 | AS71: 100 | AT71: 0 | AU71: 100 | AV71: 0 | AW71: 0 | AX71: 0
...

Sheet Burnout
A1: WALA [12,24) | C1: CORRES+CASHWINDOW | F1: Burnout 0-2000 | AS1: tover | AT1: cash | AW1: refi
A2: modelId | B2: SFACTOR_PREPAY_TRACKING_CPR | C2: PREPAY_CPR1 | D2: PREPAY_TRACKING_CPR1 | E2: PREPAY_SMM1 | F2: PREPAY_TRACKING_SMM1 | G2: PCT_LOANTYPE | H2: _ORIGNOTERATE | I2: _ZEROSATO | J2: _SATO | K2: _REFI_INCENTIVE_Fixed | L2: _Fixed_cost | M2: _LOANAGE | N2: _LTV | O2: _CLTV | P2: _AVG_LOANSIZE_SCHAMBALANCE | Q2: _WACLS | R2: _FICO | S2: PCT_ISSECONDLIEN | T2: _OrigCombLTV | U2: PCT_SVC | V2: PCT_TPO | W2: PCT_GEO | X2: PCT_LOANPURPOSE | Y2: PCT_OCC | Z2: curtailsmm | AA2: defaultsmm | AB2: toverSmm | AC2: cashoutSmm | AD2: refiSmm | AE2: cumHPA | AF2: cumHPA05Pct | AG2: cumHPA15Pct | AH2: cumHPA20Pct | AI2: cumHPA25Pct | AJ2: cumHPA30Pct | AK2: cumHPA35Pct | AL2: cumHPA40Pct | AM2: adjtoverSmm | AN2: adjRefiSmm | AO2: groupByColumn | AP2: curve | AQ2: Balance | AR2: LoanCount | AS2: PCT_BROKER | AT2: PCT_CORRES | AU2: PCT_NonRETAIL | AV2: PCT_RETAIL | AW2: PCT_CashWindow | AX2: PCT_NonCashWindow | AY2: _Burnout_Fixed
A3: 96 | B3: 0.99661762 | C3: 0 | D3: 3.9841936 | E3: 0 | F3: 0.00338238 | G3: 0 | H3: 3.875 | I3: 4.118472 | J3: -64.0619 | K3: -131.95 | L3: 13.16 | M3: 17 | N3: 80 | O3: 77.08 | P3: 303250.44 | Q3: 303250.44 | R3: 773 | S3: 0 | T3: 0 | U3: 0 | V3: 1 | W3: 0 | X3: 1 | Y3: 0 | Z3: 0.00035183 | AA3: 7.792e-05 | AB3: 0.00295262 | AC3: 0 | AD3: 0 | AE3: 0.011207683 | AF3: 1 | AG3: 1 | AH3: 1 | AI3: 1 | AJ3: 1 | AK3: 1 | AL3: 1 | AM3: 0 | AN3: 0 | AO3: 03:-150--125 | AP3: =-150--125 -> -25 | AQ3: 303250.44 | AR3: 1 | AS3: 0 | AT3: 0 | AU3: 0 | AV3: 100 | AW3: 100 | AX3: 0 | AY3: 0
A4: 96 | B4: 0.99252822 | C4: 5.6968752e-06 | D4: 8.6066971 | E4: 4.7473962e-09 | F4: 0.0074717783 | G4: 0 | H4: 3.9463145 | I4: 3.9968994 | J4: -50.059634 | K4: -110.17523 | L4: 17.060622 | M4: 16.808767 | N4: 78.188745 | O4: 75.620467 | P4: 244109.93 | Q4: 234046.42 | R4: 766.50335 | S4: 0 | T4: 0 | U4: 0 | V4: 0.52919184 | W4: 0 | X4: 0.62889958 | Y4: 0 | Z4: 0.0003521941 | AA4: 5.2415621e-05 | AB4: 0.0030302851 | AC4: 0 | AD4: 0.0040368678 | AE4: 0.007991849 | AF4: 1 | AG4: 1 | AH4: 1 | AI4: 1 | AJ4: 1 | AK4: 1 | AL4: 1 | AM4: 0 | AN4: 0 | AO4: 04:-125--100 | AP4: =-125--100 -> -25 | AQ4: 2106417.8 | AR4: 9 | AS4: 0 | AT4: 47.080816 | AU4: 47.080816 | AV4: 52.919184 | AW4: 52.919184 | AX4: 0 | AY4: 0
A5: 96 | B5: 0.9854146 | C5: 6.7240517 | D5: 16.164509 | E5: 0.005783867 | F5: 0.0145854 | G5: 0 | H5: 4.2182657 | I5: 4.013573 | J5: -25.41889 | K5: -83.743459 | L5: 15.531015 | M5: 16.933544 | N5: 77.580947 | O5: 76.058289 | P5: 294714 | Q5: 232023.63 | R5: 776.08752 | S5: 0 | T5: 0 | U5: 0 | V5: 0.32998978 | W5: 0 | X5: 0.59746948 | Y5: 0 | Z5: 0.00049507274 | AA5: 8.312075e-05 | AB5: 0.0028162319 | AC5: 0 | AD5: 0.011190961 | AE5: -0.016614367 | AF5: 1 | AG5: 1 | AH5: 1 | AI5: 1 | AJ5: 1 | AK5: 1 | AL5: 1 | AM5: 0 | AN5: 0 | AO5: 05:-100--75 | AP5: =-100--75 -> -25 | AQ5: 6960708.8 | AR5: 30 | AS5: 0 | AT5: 67.001022 | AU5: 67.001022 | AV5: 32.998978 | AW5: 32.998978 | AX5: 0 | AY5: 0
