Workbook
Name temp: 'Mtg raqte'!$A$1:$B$2388

Sheet Todal
B1: x_vals | C1: y_vals.act | D1: y_vals.mdl | H1: Actrual | I1: Old Incentive | J1: New Incentive
A2: [1,] | B2: 40118 | C2: -0.36701962 | D2: 0.052114436 | F2: [1,] | G2: 40118 | H2: -0.50848642 | I2: 1.1304446 | J2: 0.052114436
A3: [2,] | B3: 40148 | C3: -0.48821855 | D3: 0.089836457 | F3: [2,] | G3: 40148 | H3: -0.54000383 | I3: 0.1698283 | J3: 0.089836457
A4: [3,] | B4: 40179 | C4: -0.26037928 | D4: 0.09735677 | F4: [3,] | G4: 40179 | H4: -0.30696336 | I4: 0.30582991 | J4: 0.09735677
A5: [4,] | B5: 40210 | C5: -0.31125135 | D5: 0.10175987 | F5: [4,] | G5: 40210 | H5: -0.34670114 | I5: 0.19108154 | J5: 0.10175987
A6: [5,] | B6: 40238 | C6: 0.68911261 | D6: 0.092217594 | F6: [5,] | G6: 40238 | H6: 0.65360554 | I6: 0.17449891 | J6: 0.092217594
A7: [6,] | B7: 40269 | C7: 0.21997723 | D7: 0.12343518 | F7: [6,] | G7: 40269 | H7: 0.15140105 | I7: 0.23155091 | J7: 0.12343518
A8: [7,] | B8: 40299 | C8: -0.24771667 | D8: 0.15514511 | F8: [7,] | G8: 40299 | H8: -0.3506318 | I8: 0.28818892 | J8: 0.15514511
A9: [8,] | B9: 40330 | C9: 0.14542008 | D9: 0.15067342 | F9: [8,] | G9: 40330 | H9: 0.020385456 | I9: 0.26789071 | J9: 0.15067342
A10: [9,] | B10: 40360 | C10: -0.4970271 | D10: 0.19787775 | F10: [9,] | G10: 40360 | H10: -0.66074793 | I10: 0.38343281 | J10: 0.19787775
A11: [10,] | B11: 40391 | C11: 0.35759356 | D11: 0.22415656 | F11: [10,] | G11: 40391 | H11: 0.18745042 | I11: 0.56407595 | J11: 0.22415656
A12: [11,] | B12: 40422 | C12: 0.21424199 | D12: 0.21771222 | F12: [11,] | G12: 40422 | H12: 0.035678105 | I12: 0.77420041 | J12: 0.21771222
A13: [12,] | B13: 40452 | C13: -0.10653993 | D13: 0.25086003 | F13: [12,] | G13: 40452 | H13: -0.23361074 | I13: 1.1321043 | J13: 0.25086003
... A75: [74,] | B75: 42339 | C75: -1.0663584 | D75: 20.998038 | F75: [74,] | G75: 42339 | H75: -1.3856856 | I75: 21.092522 | J75: 20.998038
A76: [75,] | B76: 42370 | C76: 0.65676929 | D76: 17.826981

Sheet 2010
C1: y_vals.act | D1: 2010 | E1: 2011 | F1: 2012 | G1: 2013 | Q1: x_vals | R1: y_vals.act | S1: new incent. | T1: old model | X1: 2010 | Y1: 2011 | Z1: 2012 | AA1: 2013
A2: [1,] | B2: 40210 | C2: -0.33351698 | D2: 0.15481256 | E2: =VLOOKUP(B2,'2011'!$B:$D,3,0) -> #N/A | F2: =VLOOKUP(B2,'2012'!$B:$D,3,0) -> #N/A | G2: =VLOOKUP(B2,'2013'!$B:$D,3,0) -> #N/A | P2: [1,] | Q2: 40210 | R2: -0.29930391 | S2: 0.08419429 | T2: 0.15481256 | W2: 40210 | X2: 0.08419429 | Y2: =VLOOKUP(W2,'2011'!$Q:$S,3,0) -> #N/A | Z2: =VLOOKUP(W2,'2012'!$Q:$S,3,0) -> #N/A | AA2: =VLOOKUP(W2,'2013'!$Q:$S,3,0) -> #N/A
A3: [2,] | B3: 40238 | C3: -0.19825028 | D3: 0.14582839 | E3: =VLOOKUP(B3,'2011'!$B:$D,3,0) -> #N/A | F3: =VLOOKUP(B3,'2012'!$B:$D,3,0) -> #N/A | G3: =VLOOKUP(B3,'2013'!$B:$D,3,0) -> #N/A | P3: [2,] | Q3: 40238 | R3: -0.16376761 | S3: 0.074498098 | T3: 0.14582839 | W3: 40238 | X3: 0.074498098 | Y3: =VLOOKUP(W3,'2011'!$Q:$S,3,0) -> #N/A | Z3: =VLOOKUP(W3,'2012'!$Q:$S,3,0) -> #N/A | AA3: =VLOOKUP(W3,'2013'!$Q:$S,3,0) -> #N/A
A4: [3,] | B4: 40269 | C4: -0.42298696 | D4: 0.20248738 | E4: =VLOOKUP(B4,'2011'!$B:$D,3,0) -> #N/A | F4: =VLOOKUP(B4,'2012'!$B:$D,3,0) -> #N/A | G4: =VLOOKUP(B4,'2013'!$B:$D,3,0) -> #N/A | P4: [3,] | Q4: 40269 | R4: -0.35552137 | S4: 0.10661352 | T4: 0.20248738 | W4: 40269 | X4: 0.10661352 | Y4: =VLOOKUP(W4,'2011'!$Q:$S,3,0) -> #N/A | Z4: =VLOOKUP(W4,'2012'!$Q:$S,3,0) -> #N/A | AA4: =VLOOKUP(W4,'2013'!$Q:$S,3,0) -> #N/A
A5: [4,] | B5: 40299 | C5: -0.12818666 | D5: 0.27007153 | E5: =VLOOKUP(B5,'2011'!$B:$D,3,0) -> #N/A | F5: =VLOOKUP(B5,'2012'!$B:$D,3,0) -> #N/A | G5: =VLOOKUP(B5,'2013'!$B:$D,3,0) -> #N/A | P5: [4,] | Q5: 40299 | R5: -0.028179103 | S5: 0.14487329 | T5: 0.27007153 | W5: 40299 | X5: 0.14487329 | Y5: =VLOOKUP(W5,'2011'!$Q:$S,3,0) -> #N/A | Z5: =VLOOKUP(W5,'2012'!$Q:$S,3,0) -> #N/A | AA5: =VLOOKUP(W5,'2013'!$Q:$S,3,0) -> #N/A
A6: [5,] | B6: 40330 | C6: -0.19962833 | D6: 0.25785303 | E6: =VLOOKUP(B6,'2011'!$B:$D,3,0) -> #N/A | F6: =VLOOKUP(B6,'2012'!$B:$D,3,0) -> #N/A | G6: =VLOOKUP(B6,'2013'!$B:$D,3,0) -> #N/A | P6: [5,] | Q6: 40330 | R6: -0.079404521 | S6: 0.14594717 | T6: 0.25785303 | W6: 40330 | X6: 0.14594717 | Y6: =VLOOKUP(W6,'2011'!$Q:$S,3,0) -> #N/A | Z6: =VLOOKUP(W6,'2012'!$Q:$S,3,0) -> #N/A | AA6: =VLOOKUP(W6,'2013'!$Q:$S,3,0) -> #N/A
A7: [6,] | B7: 40360 | C7: -0.50933053 | D7: 0.37533117 | E7: =VLOOKUP(B7,'2011'!$B:$D,3,0) -> #N/A | F7: =VLOOKUP(B7,'2012'!$B:$D,3,0) -> #N/A | G7: =VLOOKUP(B7,'2013'!$B:$D,3,0) -> #N/A | P7: [6,] | Q7: 40360 | R7: -0.35229909 | S7: 0.19343846 | T7: 0.37533117 | W7: 40360 | X7: 0.19343846 | Y7: =VLOOKUP(W7,'2011'!$Q:$S,3,0) -> #N/A | Z7: =VLOOKUP(W7,'2012'!$Q:$S,3,0) -> #N/A | AA7: =VLOOKUP(W7,'2013'!$Q:$S,3,0) -> #N/A
A8: [7,] | B8: 40391 | C8: -0.10648677 | D8: 0.55862215 | E8: =VLOOKUP(B8,'2011'!$B:$D,3,0) -> #N/A | F8: =VLOOKUP(B8,'2012'!$B:$D,3,0) -> #N/A | G8: =VLOOKUP(B8,'2013'!$B:$D,3,0) -> #N/A | P8: [7,] | Q8: 40391 | R8: 0.057089694 | S8: 0.22033895 | T8: 0.55862215 | W8: 40391 | X8: 0.22033895 | Y8: =VLOOKUP(W8,'2011'!$Q:$S,3,0) -> #N/A | Z8: =VLOOKUP(W8,'2012'!$Q:$S,3,0) -> #N/A | AA8: =VLOOKUP(W8,'2013'!$Q:$S,3,0) -> #N/A
A9: [8,] | B9: 40422 | C9: -0.68376273 | D9: 0.77216452 | E9: =VLOOKUP(B9,'2011'!$B:$D,3,0) -> #N/A | F9: =VLOOKUP(B9,'2012'!$B:$D,3,0) -> #N/A | G9: =VLOOKUP(B9,'2013'!$B:$D,3,0) -> #N/A | P9: [8,] | Q9: 40422 | R9: -0.51088095 | S9: 0.21490523 | T9: 0.77216452 | W9: 40422 | X9: 0.21490523 | Y9: =VLOOKUP(W9,'2011'!$Q:$S,3,0) -> #N/A | Z9: =VLOOKUP(W9,'2012'!$Q:$S,3,0) -> #N/A | AA9: =VLOOKUP(W9,'2013'!$Q:$S,3,0) -> #N/A
A10: [9,] | B10: 40452 | C10: -0.20535035 | D10: 1.1213877 | E10: =VLOOKUP(B10,'2011'!$B:$D,3,0) -> #N/A | F10: =VLOOKUP(B10,'2012'!$B:$D,3,0) -> #N/A | G10: =VLOOKUP(B10,'2013'!$B:$D,3,0) -> #N/A | P10: [9,] | Q10: 40452 | R10: -0.082476419 | S10: 0.247816 | T10: 1.1213877 | W10: 40452 | X10: 0.247816 | Y10: =VLOOKUP(W10,'2011'!$Q:$S,3,0) -> #N/A | Z10: =VLOOKUP(W10,'2012'!$Q:$S,3,0) -> #N/A | AA10: =VLOOKUP(W10,'2013'!$Q:$S,3,0) -> #N/A
A11: [10,] | B11: 40483 | C11: 0.98639441 | D11: 1.3312034 | E11: =VLOOKUP(B11,'2011'!$B:$D,3,0) -> #N/A | F11: =VLOOKUP(B11,'2012'!$B:$D,3,0) -> #N/A | G11: =VLOOKUP(B11,'2013'!$B:$D,3,0) -> #N/A | P11: [10,] | Q11: 40483 | R11: 1.0911336 | S11: 0.2627694 | T11: 1.3312034 | W11: 40483 | X11: 0.2627694 | Y11: =VLOOKUP(W11,'2011'!$Q:$S,3,0) -> #N/A | Z11: =VLOOKUP(W11,'2012'!$Q:$S,3,0) -> #N/A | AA11: =VLOOKUP(W11,'2013'!$Q:$S,3,0) -> #N/A
A12: [11,] | B12: 40513 | C12: 0.53509756 | D12: 2.5007028 | E12: =VLOOKUP(B12,'2011'!$B:$D,3,0) -> #N/A | F12: =VLOOKUP(B12,'2012'!$B:$D,3,0) -> #N/A | G12: =VLOOKUP(B12,'2013'!$B:$D,3,0) -> #N/A | P12: [11,] | Q12: 40513 | R12: 0.6417762 | S12: 0.27938924 | T12: 2.5007028 | W12: 40513 | X12: 0.27938924 | Y12: =VLOOKUP(W12,'2011'!$Q:$S,3,0) -> #N/A | Z12: =VLOOKUP(W12,'2012'!$Q:$S,3,0) -> #N/A | AA12: =VLOOKUP(W12,'2013'!$Q:$S,3,0) -> #N/A
A13: [12,] | B13: 40544 | C13: 0.78465566 | D13: 0.95911759 | E13: =VLOOKUP(B13,'2011'!$B:$D,3,0) -> #N/A | F13: =VLOOKUP(B13,'2012'!$B:$D,3,0) -> #N/A | G13: =VLOOKUP(B13,'2013'!$B:$D,3,0) -> #N/A | P13: [12,] | Q13: 40544 | R13: 0.86342221 | S13: 0.22557251 | T13: 0.95911759 | W13: 40544 | X13: 0.22557251 | Y13: =VLOOKUP(W13,'2011'!$Q:$S,3,0) -> #N/A | Z13: =VLOOKUP(W13,'2012'!$Q:$S,3,0) -> #N/A | AA13: =VLOOKUP(W13,'2013'!$Q:$S,3,0) -> #N/A
... A72: [71,] | B72: 42339 | C72: 6.285171 | D72: 25.336162 | E72: =VLOOKUP(B72,'2011'!$B:$D,3,0) -> 28.823522 | F72: =VLOOKUP(B72,'2012'!$B:$D,3,0) -> 26.075538 | G72: =VLOOKUP(B72,'2013'!$B:$D,3,0) -> 15.19625 | P72: [71,] | Q72: 42339 | R72: 6.2899135 | S72: 25.344572 | T72: 25.336162 | W72: 42339 | X72: 25.344572 | Y72: =VLOOKUP(W72,'2011'!$Q:$S,3,0) -> 28.802294 | Z72: =VLOOKUP(W72,'2012'!$Q:$S,3,0) -> 14.024736 | AA72: =VLOOKUP(W72,'2013'!$Q:$S,3,0) -> 8.6049359

Sheet 2011
C1: y_vals.act | D1: y_vals.mdl | E1: new | R1: y_vals.act | S1: y_vals.mdl
A2: [1,] | B2: 40575 | C2: -0.3623055 | D2: 0.34458872 | E2: 0.053105186 | P2: [1,] | Q2: 40575 | R2: -0.3075554 | S2: 0.053105186
A3: [2,] | B3: 40603 | C3: 0.25939161 | D3: 0.076333496 | E3: 0.032744013 | P3: [2,] | Q3: 40603 | R3: 0.28138835 | S3: 0.032744013
A4: [3,] | B4: 40634 | C4: -0.043455852 | D4: 0.087454634 | E4: 0.028445395 | P4: [3,] | Q4: 40634 | R4: -0.0033352639 | S4: 0.028445395
A5: [4,] | B5: 40664 | C5: -0.07254888 | D5: 0.13993343 | E5: 0.060916005 | P5: [4,] | Q5: 40664 | R5: -0.0097861344 | S5: 0.060916005
A6: [5,] | B6: 40695 | C6: -0.26813665 | D6: 0.18151557 | E6: 0.084321906 | P6: [5,] | Q6: 40695 | R6: -0.17892247 | S6: 0.084321906
A7: [6,] | B7: 40725 | C7: 0.71702261 | D7: 0.26891525 | E7: 0.1471714 | P7: [6,] | Q7: 40725 | R7: 0.85785463 | S7: 0.1471714
A8: [7,] | B8: 40756 | C8: 0.41610317 | D8: 0.36957362 | E8: 0.19735386 | P8: [7,] | Q8: 40756 | R8: 0.6035848 | S8: 0.19735386
A9: [8,] | B9: 40787 | C9: 0.11736873 | D9: 0.37838663 | E9: 0.20783269 | P9: [8,] | Q9: 40787 | R9: 0.34801211 | S9: 0.20783269
A10: [9,] | B10: 40817 | C10: 0.32563844 | D10: 1.0002773 | E10: 0.37671182 | P10: [9,] | Q10: 40817 | R10: 0.56281325 | S10: 0.37671182
A11: [10,] | B11: 40848 | C11: 0.50087967 | D11: 1.4903771 | E11: 0.38943309 | P11: [10,] | Q11: 40848 | R11: 0.74577886 | S11: 0.38943309
A12: [11,] | B12: 40878 | C12: 0.27157704 | D12: 1.3196528 | E12: 0.36413808 | P12: [11,] | Q12: 40878 | R12: 0.50014809 | S12: 0.36413808
A13: [12,] | B13: 40909 | C13: 1.2777854 | D13: 1.7392308 | E13: 0.40279898 | P13: [12,] | Q13: 40909 | R13: 1.5334685 | S13: 0.40279898
... A60: [59,] | B60: 42339 | C60: 4.7460473 | D60: 28.823522 | E60: 28.802294 | P60: [59,] | Q60: 42339 | R60: 4.7462599 | S60: 28.802294

Sheet 2012
C1: y_vals.act | D1: y_vals.mdl | E1: new | R1: y_vals.act | S1: y_vals.mdl
A2: [1,] | B2: 40940 | C2: -0.2012973 | D2: 0.34626336 | E2: 0.17789402 | P2: [1,] | Q2: 40940 | R2: -0.13687612 | S2: 0.17789402
A3: [2,] | B3: 40969 | C3: -0.31295852 | D3: 0.47260589 | E3: 0.23122436 | P3: [2,] | Q3: 40969 | R3: -0.23038524 | S3: 0.23122436
A4: [3,] | B4: 41000 | C4: 0.13294906 | D4: 0.64573765 | E4: 0.32162539 | P4: [3,] | Q4: 41000 | R4: 0.29150303 | S4: 0.32162539
A5: [4,] | B5: 41030 | C5: -0.088780685 | D5: 0.53649539 | E5: 0.28966187 | P5: [4,] | Q5: 41030 | R5: 0.12012924 | S5: 0.28966187
A6: [5,] | B6: 41061 | C6: -0.39696551 | D6: 0.74633077 | E6: 0.38986143 | P6: [5,] | Q6: 41061 | R6: -0.090412263 | S6: 0.38986143
A7: [6,] | B7: 41091 | C7: 0.17545481 | D7: 1.0450628 | E7: 0.29749787 | P7: [6,] | Q7: 41091 | R7: 0.34759375 | S7: 0.29749787
A8: [7,] | B8: 41122 | C8: -0.034677563 | D8: 1.2865187 | E8: 0.31241537 | P8: [7,] | Q8: 41122 | R8: 0.22692242 | S8: 0.31241537
A9: [8,] | B9: 41153 | C9: -0.14767449 | D9: 1.5240861 | E9: 0.32824471 | P9: [8,] | Q9: 41153 | R9: 0.17928728 | S9: 0.32824471
A10: [9,] | B10: 41183 | C10: 0.19750715 | D10: 1.335952 | E10: 0.30957767 | P10: [9,] | Q10: 41183 | R10: 0.29674386 | S10: 0.30957767
A11: [10,] | B11: 41214 | C11: 0.17043918 | D11: 1.7382085 | E11: 0.35190156 | P11: [10,] | Q11: 41214 | R11: 0.63650333 | S11: 0.35190156
A12: [11,] | B12: 41244 | C12: 0.071029859 | D12: 2.230874 | E12: 0.39587952 | P12: [11,] | Q12: 41244 | R12: 0.59656277 | S12: 0.39587952
A13: [12,] | B13: 41275 | C13: -0.23743691 | D13: 2.2952184 | E13: 0.39838656 | P13: [12,] | Q13: 41275 | R13: 0.61915594 | S13: 0.39838656
... A48: [47,] | B48: 42339 | C48: -1.996689 | D48: 26.075538 | E48: 14.024736 | P48: [47,] | Q48: 42339 | R48: -0.1070584 | S48: 14.024736

Sheet 2013
C1: y_vals.act | D1: y_vals.mdl | E1: new | Q1: x_vals | R1: y_vals.act | S1: y_vals.mdl
A2: [1,] | B2: 41306 | C2: 0.71276848 | D2: 0.3990812 | E2: 0.1293261 | P2: [1,] | Q2: 41306 | R2: 0.33648042 | S2: 0.1293261
A3: [2,] | B3: 41334 | C3: 0.42702927 | D3: 0.35889526 | E3: 0.11624554 | P3: [2,] | Q3: 41334 | R3: 0.24084491 | S3: 0.11624554
A4: [3,] | B4: 41365 | C4: 0.15565906 | D4: 0.80065444 | E4: 0.11231354 | P4: [3,] | Q4: 41365 | R4: 0.24331643 | S4: 0.11231354
A5: [4,] | B5: 41395 | C5: 0.33922573 | D5: 0.55881973 | E5: 0.13088341 | P5: [4,] | Q5: 41395 | R5: 0.31641231 | S5: 0.13088341
A6: [5,] | B6: 41426 | C6: -0.12280804 | D6: 0.84465121 | E6: 0.25197864 | P6: [5,] | Q6: 41426 | R6: 0.25996858 | S6: 0.25197864
A7: [6,] | B7: 41456 | C7: 0.34639649 | D7: 0.75163877 | E7: 0.24809646 | P7: [6,] | Q7: 41456 | R7: 0.54946556 | S7: 0.24809646
A8: [7,] | B8: 41487 | C8: 0.25075416 | D8: 0.48571259 | E8: 0.10386477 | P8: [7,] | Q8: 41487 | R8: 0.59532238 | S8: 0.10386477
A9: [8,] | B9: 41518 | C9: 0.36829233 | D9: 0.51072362 | E9: 0.060066365 | P9: [8,] | Q9: 41518 | R9: 0.91385177 | S9: 0.060066365
A10: [9,] | B10: 41548 | C10: 0.29472671 | D10: 0.47502624 | E10: 0.046097427 | P10: [9,] | Q10: 41548 | R10: 0.61034341 | S10: 0.046097427
A11: [10,] | B11: 41579 | C11: -0.1276394 | D11: 0.47269804 | E11: 0.042162122 | P11: [10,] | Q11: 41579 | R11: 0.38190699 | S11: 0.042162122
A12: [11,] | B12: 41609 | C12: -0.1455771 | D12: 0.58374586 | E12: 0.093919216 | P12: [11,] | Q12: 41609 | R12: 0.29026068 | S12: 0.093919216
A13: [12,] | B13: 41640 | C13: 0.30140286 | D13: 0.5848191 | E13: 0.084039317 | P13: [12,] | Q13: 41640 | R13: 0.89805023 | S13: 0.084039317
... A36: [35,] | B36: 42339 | C36: -4.5239972 | D36: 15.19625 | E36: 8.6049359 | P36: [35,] | Q36: 42339 | R36: -2.4018711 | S36: 8.6049359

Sheet Sheet5
A1: issueId | B1: waCLTV | C1: WAC | D1: surveyrate | E1: llpaAdjustment | F1: pmiAdjustment | G1: refi_incentive
A2: 1564739 | B2: 100.72 | C2: 5.423 | D2: 4.37 | E2: 4.6167 | F2: 0 | G2: -10.11 | H2: =(C2-D2-E2/4)*100 -> -10.1175
A3: 1564739 | B3: 100.57 | C3: 5.423 | D3: 4.362 | E3: 4.6167 | F3: 0 | G3: -9.31 | H3: =(C3-D3-E3/4)*100 -> -9.3175
A4: 1564739 | B4: 99.07 | C4: 5.423 | D4: 4.2274 | E4: 4.3671 | F4: 0 | G4: 10.38 | H4: =(C4-D4-E4/4)*100 -> 10.3825
A5: 1564739 | B5: 97.62 | C5: 5.423 | D5: 4.2487 | E5: 4.3671 | F5: 0 | G5: 4.86 | H5: =(C5-D5-E5/4)*100 -> 8.2525
A6: 1564740 | B6: 100.5 | C6: 5.869 | D6: 4.37 | E6: 4.3997 | F6: 0 | G6: 39.9 | H6: =(C6-D6-E6/4)*100 -> 39.9075
A7: 1564740 | B7: 101.07 | C7: 5.869 | D7: 4.362 | E7: 4.4096 | F7: 0 | G7: 40.45 | H7: =(C7-D7-E7/4)*100 -> 40.46
A8: 1564740 | B8: 99.68 | C8: 5.869 | D8: 4.2274 | E8: 4.1596 | F8: 0 | G8: 60.16 | H8: =(C8-D8-E8/4)*100 -> 60.17
A9: 1564740 | B9: 98.32 | C9: 5.869 | D9: 4.2487 | E9: 4.1596 | F9: 0 | G9: 56.1 | H9: =(C9-D9-E9/4)*100 -> 58.04
A10: 1564740 | B10: 97.97 | C10: 5.869 | D10: 4.05 | E10: 1.9096 | F10: 0 | G10: 169.22 | H10: =(C10-D10-E10/4)*100 -> 134.16
A11: 1564741 | B11: 101.62 | C11: 5.492 | D11: 4.37 | E11: 4.5222 | F11: 0 | G11: -0.85 | H11: =(C11-D11-E11/4)*100 -> -0.855
A12: 1564741 | B12: 101.47 | C12: 5.492 | D12: 4.362 | E12: 4.5222 | F12: 0 | G12: -0.05 | H12: =(C12-D12-E12/4)*100 -> -0.055
A13: 1564741 | B13: 99.95 | C13: 5.492 | D13: 4.2274 | E13: 4.2722 | F13: 0 | G13: 19.65 | H13: =(C13-D13-E13/4)*100 -> 19.655
... A37: 1564744 | B37: 100.84 | C37: 5.898 | D37: 4.2479 | E37: 4 | F37: 0 | G37: 65.01 | H37: =(C37-D37-E37/4)*100 -> 65.01
A38: 1564744 | B38: 100.31 | C38: 5.898 | D38: 4.0675 | E38: 4 | F38: 0 | G38: 83.05
A39: 1564744 | B39: 100.96 | C39: 5.898 | D39: 4.05 | E39: 4 | F39: 0 | G39: 84.8
A40: 1564744 | B40: 99.27 | C40: 5.898 | D40: 4.03 | E40: 4 | F40: 0 | G40: 86.8
A41: 1564744 | B41: 99.36 | C41: 5.898 | D41: 4.0087 | E41: 4 | F41: 0 | G41: 88.93
A42: 1564744 | B42: 99.45 | C42: 5.898 | D42: 4.0375 | E42: 4 | F42: 0 | G42: 86.05
A43: 1564744 | B43: 99.54 | C43: 5.898 | D43: 3.906 | E43: 4 | F43: 0 | G43: 99.2
A44: 1564744 | B44: 99.17 | C44: 5.899 | D44: 3.8725 | E44: 4.25 | F44: 0 | G44: 96.4
A45: 1564744 | B45: 100.12 | C45: 5.855 | D45: 3.754 | E45: 4.25 | F45: 0 | G45: 102.78
A46: 1564744 | B46: 99.85 | C46: 5.855 | D46: 3.5762 | E46: 4.25 | F46: 0 | G46: 120.56
A47: 1564744 | B47: 98.45 | C47: 5.855 | D47: 3.6162 | E47: 4.25 | F47: 0 | G47: 116.56
A48: 1564744 | B48: 97.09 | C48: 5.855 | D48: 3.67 | E48: 4.25 | F48: 0 | G48: 111.18
A49: 1564788 | B49: 101.4 | C49: 5.276 | D49: 4.37 | E49: 4.6039 | F49: 0 | G49: -24.49
... A91: 1565010 | B91: 97.65 | C91: 5.591 | D91: 4.2274 | E91: 4.0705 | F91: 0 | G91: 34.59

Sheet Mtg raqte
B1: seriesValue
A2: 26025 | B2: 7.33
A3: 26032 | B3: 7.31
A4: 26039 | B4: 7.31
A5: 26046 | B5: 7.31
A6: 26053 | B6: 7.29
A7: 26060 | B7: 7.38
A8: 26067 | B8: 7.42
A9: 26074 | B9: 7.44
A10: 26081 | B10: 7.46
A11: 26088 | B11: 7.52
A12: 26095 | B12: 7.52
A13: 26102 | B13: 7.54
... A2388: 42369 | B2388: 4.01

Sheet Refi Model
A1: $baselineConstant
A2: [1] | B2: 1
A4: $adjustmentFactor
A5: [1] | B5: 1
A7: $incentiveSpline
C8: incentiveKnotValues
A9: 1 | B9: -225 | C9: 0.0002101365
A10: 2 | B10: -185 | C10: 0.0003429763 | D10: =C10/$C$9 -> 1.6321596
A11: 3 | B11: -160 | C11: 0.0003422924 | D11: =C11/$C$9 -> 1.628905
A12: 4 | B12: -135 | C12: 0.0002948387 | D12: =C12/$C$9 -> 1.4030818
A13: 5 | B13: -110 | C13: 0.0002914859 | D13: =C13/$C$9 -> 1.3871265
A14: 6 | B14: -40 | C14: 0.0004728854 | D14: =C14/$C$9 -> 2.2503725
A15: 7 | B15: -10 | C15: 0.0006498071 | D15: =C15/$C$9 -> 3.0923095
A16: 8 | B16: 10 | C16: 0.0010156067 | D16: =C16/$C$9 -> 4.8330809
A17: 9 | B17: 35 | C17: 0.0016893167 | D17: =C17/$C$9 -> 8.0391398
A18: 10 | B18: 60 | C18: 0.0028176394 | D18: =C18/$C$9 -> 13.408615
A19: 11 | B19: 85 | C19: 0.0045812566 | D19: =C19/$C$9 -> 21.801337
A20: 12 | B20: 150 | C20: 0.0080888401 | D20: =C20/$C$9 -> 38.493266
A21: 13 | B21: 240 | C21: 0.01182408 | D21: =C21/$C$9 -> 56.268569
... A24: 16 | B24: 700 | C24: 0.017179627 | D24: =C24/$C$9 -> 81.754607
A26: $mediaSpline
B27: mediaKnots | C27: mediaKnotValues
A28: 1 | B28: 11.43207 | C28: 1.430116
A29: 2 | B29: 24.97679 | C29: 3.138367
A30: 3 | B30: 42.06792 | C30: 4.222406
A31: 4 | B31: 69.68944 | C31: 6.109421
A32: 5 | B32: 85.03713 | C32: 9.256326
A34: $creditAvailabilitySpline
B35: creditAvailabilityKnots | C35: creditAvailabilityKnotValues
A36: 1 | B36: 90 | C36: 0.3041769
A37: 2 | B37: 97 | C37: 0.3232733
A38: 3 | B38: 110 | C38: 0.5451245
A39: 4 | B39: 120 | C39: 1.2995568
A41: $walaSpline
B42: walaKnots | C42: walaKnotValues
A43: 1 | B43: 2 | C43: 0.3965332
A44: 2 | B44: 3 | C44: 0.5861352
A45: 3 | B45: 4 | C45: 0.8845445
A46: 4 | B46: 5 | C46: 1.0297436
A47: 5 | B47: 12 | C47: 1.1128417
...

Sheet Sheet2
A1: marketTicker | B1: issueId | C1: OrigCoupon | D1: asOf | E1: issueDate | F1: factor | G1: wala | H1: schamBalance | I1: wac | J1: waoltv | K1: waclSize | L1: waolSize | M1: waocs | N1: currentBalance | O1: waCLTV | P1: SATO | Q1: HPA | R1: HPI | S1: HPA_1YR | T1: HPA_2YR | U1: Pct_OWNER | V1: Pct_2ND | W1: Pct_INV | X1: MtgRate | Y1: burnout | Z1: pmi_begin_base | AA1: pmi_begin_occ | AB1: pmi_end_base | AC1: pmi_end_occ | AD1: llpa_base | AE1: llpa_admc | AF1: llpa_occ | AG1: llpa_ltv | AH1: llpa_loansize | AI1: incentive | AJ1: relative_incentive
A2: FGU6 | B2: 1575310 | C2: 3.5 | D2: 41426 | E2: 40544 | F2: 0.925 | G2: 29 | H2: 1166383.5 | I2: 4.061 | J2: 113 | K2: 291310.68 | L2: 325173 | M2: 788 | N2: 1165242.7 | O2: 87.82 | P2: (NULL) | Q2: 1.1422 | R2: 321.39 | S2: 1.0431 | T2: 1.0416 | U2: 100 | V2: 0 | W2: 0 | X2: 3.3887 | Y2: 2.306 | Z2: 183 | AA2: 0 | AB2: 49 | AC2: 0 | AD2: 25 | AE2: 25 | AF2: 0 | AG2: 0 | AH2: 0 | AI2: 1.8873 | AJ2: (NULL) | AK2: =I2+SUM(Z2:AA2)/100-X2-SUM(AB2:AC2)/100-SUM(AD2:AH2)/100/4 -> 1.8873
A3: FGU6 | B3: 1575311 | C3: 4 | D3: 41426 | E3: 40544 | F3: 0.925 | G3: 29 | H3: 4639203 | I3: 4.364 | J3: 115 | K3: 244131.64 | L3: 283048 | M3: 760 | N3: 4638501.1 | O3: 94.22 | P3: (NULL) | Q3: 1.1422 | R3: 321.39 | S3: 1.0431 | T3: 1.0416 | U3: 100 | V3: 0 | W3: 0 | X3: 3.3887 | Y3: 3.8168 | Z3: 183 | AA3: 0 | AB3: 64 | AC3: 0 | AD3: 25 | AE3: 25 | AF3: 0 | AG3: 0 | AH3: 0 | AI3: 2.0403 | AJ3: (NULL) | AK3: =I3+SUM(Z3:AA3)/100-X3-SUM(AB3:AC3)/100-SUM(AD3:AH3)/100/4 -> 2.0403
A4: FGU6 | B4: 1575796 | C4: 5 | D4: 41426 | E4: 40544 | F4: 0.925 | G4: 29 | H4: 8162580.3 | I4: 5.392 | J4: 116 | K4: 247339.4 | L4: 285545 | M4: 716 | N4: 8162200.1 | O4: 96.94 | P4: (NULL) | Q4: 1.1422 | R4: 321.39 | S4: 1.0431 | T4: 1.0416 | U4: 84.22 | V4: 0 | W4: 15.78 | X4: 3.3887 | Y4: 9.3894 | Z4: 183 | AA4: 0 | AB4: 151 | AC4: 0 | AD4: 100 | AE4: 25 | AF4: 65.0925 | AG4: 50 | AH4: 0 | AI4: 1.723 | AJ4: (NULL) | AK4: =I4+SUM(Z4:AA4)/100-X4-SUM(AB4:AC4)/100-SUM(AD4:AH4)/100/4 -> 1.7230688
A5: FGU6 | B5: 1575797 | C5: 4.5 | D5: 41426 | E5: 40544 | F5: 0.925 | G5: 29 | H5: 19715302 | I5: 4.905 | J5: 116 | K5: 231928.51 | L5: 277231 | M5: 722 | N5: 19713923 | O5: 98.68 | P5: (NULL) | Q5: 1.1422 | R5: 321.39 | S5: 1.0431 | T5: 1.0416 | U5: 85.74 | V5: 4.58 | W5: 9.68 | X5: 3.3887 | Y5: 6.6519 | Z5: 183 | AA5: 0.6412 | AB5: 183 | AC5: 0.6412 | AD5: 1000 | AE5: 25 | AF5: 39.93 | AG5: 50 | AH5: 0 | AI5: -1.271 | AJ5: (NULL) | AK5: =I5+SUM(Z5:AA5)/100-X5-SUM(AB5:AC5)/100-SUM(AD5:AH5)/100/4 -> -1.271025
A6: FGU6 | B6: 1575324 | C6: 4.5 | D6: 41426 | E6: 40544 | F6: 0.925 | G6: 29 | H6: 5317716.5 | I6: 4.98 | J6: 115 | K6: 265871.43 | L6: 298191 | M6: 762 | N6: 5317428.6 | O6: 91.71 | P6: (NULL) | Q6: 1.1422 | R6: 321.39 | S6: 1.0431 | T6: 1.0416 | U6: 88.15 | V6: 7.32 | W6: 4.53 | X6: 3.3887 | Y6: 7.1505 | Z6: 183 | AA6: 1.0248 | AB6: 64 | AC6: 0.8784 | AD6: 25 | AE6: 25 | AF6: 18.6862 | AG6: 0 | AH6: 0 | AI6: 2.611 | AJ6: (NULL) | AK6: =I6+SUM(Z6:AA6)/100-X6-SUM(AB6:AC6)/100-SUM(AD6:AH6)/100/4 -> 2.6110485
A7: FGU6 | B7: 1575879 | C7: 4.5 | D7: 41426 | E7: 40544 | F7: 0.91666667 | G7: 30 | H7: 1458807 | I7: 4.937 | J7: 107 | K7: 291761.33 | L7: 324520 | M7: 738 | N7: 1458806.6 | O7: 94.09 | P7: (NULL) | Q7: 1.1422 | R7: 321.39 | S7: 1.0431 | T7: 1.0416 | U7: 84.14 | V7: 0 | W7: 15.86 | X7: 3.3887 | Y7: 6.8521 | Z7: 183 | AA7: 0 | AB7: 77 | AC7: 0 | AD7: 50 | AE7: 25 | AF7: 65.4225 | AG7: 0 | AH7: 0 | AI7: 2.2572 | AJ7: (NULL) | AK7: =I7+SUM(Z7:AA7)/100-X7-SUM(AB7:AC7)/100-SUM(AD7:AH7)/100/4 -> 2.2572438
A8: FGU6 | B8: 1575880 | C8: 4 | D8: 41426 | E8: 40544 | F8: 0.925 | G8: 29 | H8: 3029744 | I8: 4.517 | J8: 115 | K8: 275423.61 | L8: 318823 | M8: 754 | N8: 3029659.8 | O8: 99.19 | P8: (NULL) | Q8: 1.1422 | R8: 321.39 | S8: 1.0431 | T8: 1.0416 | U8: 100 | V8: 0 | W8: 0 | X8: 3.3887 | Y8: 4.5328 | Z8: 183 | AA8: 0 | AB8: 183 | AC8: 0 | AD8: 1000 | AE8: 25 | AF8: 0 | AG8: 50 | AH8: 0 | AI8: -1.5592 | AJ8: (NULL) | AK8: =I8+SUM(Z8:AA8)/100-X8-SUM(AB8:AC8)/100-SUM(AD8:AH8)/100/4 -> -1.5592
A9: FGU6 | B9: 1575881 | C9: 4.5 | D9: 41426 | E9: 40544 | F9: 0.925 | G9: 29 | H9: 10207567 | I9: 4.917 | J9: 114 | K9: 156621.87 | L9: 204030 | M9: 726 | N9: 10023800 | O9: 99.13 | P9: (NULL) | Q9: 1.1422 | R9: 321.39 | S9: 1.0431 | T9: 1.0416 | U9: 92.67 | V9: 5.79 | W9: 1.54 | X9: 3.3887 | Y9: 6.7734 | Z9: 183 | AA9: 0.8106 | AB9: 183 | AC9: 0.8106 | AD9: 1000 | AE9: 25 | AF9: 6.3525 | AG9: 50 | AH9: 0 | AI9: -1.175 | AJ9: (NULL) | AK9: =I9+SUM(Z9:AA9)/100-X9-SUM(AB9:AC9)/100-SUM(AD9:AH9)/100/4 -> -1.1750813
A10: FGU6 | B10: 1575882 | C10: 5 | D10: 41426 | E10: 40544 | F10: 0.925 | G10: 29 | H10: 1598484.8 | I10: 5.385 | J10: 117 | K10: 177597.78 | L10: 206555 | M10: 738 | N10: 1598380 | O10: 104.63 | P10: (NULL) | Q10: 1.1422 | R10: 321.39 | S10: 1.0431 | T10: 1.0416 | U10: 86.83 | V10: 0 | W10: 13.17 | X10: 3.3887 | Y10: 9.366 | Z10: 183 | AA10: 0 | AB10: 183 | AC10: 0 | AD10: 1000 | AE10: 25 | AF10: 54.3262 | AG10: 50 | AH10: 0 | AI10: -0.827 | AJ10: (NULL) | AK10: =I10+SUM(Z10:AA10)/100-X10-SUM(AB10:AC10)/100-SUM(AD10:AH10)/100/4 -> -0.8270155
A11: FGU6 | B11: 1575624 | C11: 4 | D11: 41426 | E11: 40544 | F11: 0.925 | G11: 29 | H11: 2603542.9 | I11: 4.522 | J11: 114 | K11: 247000.41 | L11: 287185 | M11: 757 | N11: 2223003.6 | O11: 92.48 | P11: (NULL) | Q11: 1.1422 | R11: 321.39 | S11: 1.0431 | T11: 1.0416 | U11: 100 | V11: 0 | W11: 0 | X11: 3.3887 | Y11: 4.6745 | Z11: 183 | AA11: 0 | AB11: 77 | AC11: 0 | AD11: 25 | AE11: 25 | AF11: 0 | AG11: 0 | AH11: 0 | AI11: 2.0683 | AJ11: (NULL) | AK11: =I11+SUM(Z11:AA11)/100-X11-SUM(AB11:AC11)/100-SUM(AD11:AH11)/100/4 -> 2.0683
A12: FGU6 | B12: 1575625 | C12: 4.5 | D12: 41426 | E12: 40544 | F12: 0.925 | G12: 29 | H12: 68561367 | I12: 4.974 | J12: 115 | K12: 245334.84 | L12: 288188 | M12: 744 | N12: 68203085 | O12: 95.98 | P12: (NULL) | Q12: 1.1422 | R12: 321.39 | S12: 1.0431 | T12: 1.0416 | U12: 89.01 | V12: 3.92 | W12: 7.07 | X12: 3.3887 | Y12: 7.0791 | Z12: 183 | AA12: 0.5488 | AB12: 125 | AC12: 0.5488 | AD12: 25 | AE12: 25 | AF12: 29.1637 | AG12: 50 | AH12: 0 | AI12: 1.8423 | AJ12: (NULL) | AK12: =I12+SUM(Z12:AA12)/100-X12-SUM(AB12:AC12)/100-SUM(AD12:AH12)/100/4 -> 1.8423908
A13: FGU6 | B13: 1575626 | C13: 5 | D13: 41426 | E13: 40544 | F13: 0.925 | G13: 29 | H13: 1885659 | I13: 5.404 | J13: 114 | K13: 157095.65 | L13: 182309 | M13: 750 | N13: 1885147.9 | O13: 98.48 | P13: (NULL) | Q13: 1.1422 | R13: 321.39 | S13: 1.0431 | T13: 1.0416 | U13: 93.01 | V13: 6.99 | W13: 0 | X13: 3.3887 | Y13: 9.614 | Z13: 183 | AA13: 0.9786 | AB13: 183 | AC13: 0.9786 | AD13: 1000 | AE13: 25 | AF13: 0 | AG13: 50 | AH13: 0 | AI13: -0.6722 | AJ13: (NULL) | AK13: =I13+SUM(Z13:AA13)/100-X13-SUM(AB13:AC13)/100-SUM(AD13:AH13)/100/4 -> -0.6722
... A44: FGU6 | B44: 1576348 | C44: 5 | D44: 41426 | E44: 40544 | F44: 0.925 | G44: 29 | H44: 2619769.1 | I44: 5.31 | J44: 115 | K44: 238137.69 | L44: 264161 | M44: 767 | N44: 2619514.6 | O44: 98.08 | P44: (NULL) | Q44: 1.1422 | R44: 321.39 | S44: 1.0431 | T44: 1.0416 | U44: 92.84 | V44: 7.16 | W44: 0 | X44: 3.3887 | Y44: 8.9643 | Z44: 183 | AA44: 1.0024 | AB44: 183 | AC44: 0.8592 | AD44: 1000 | AE44: 25 | AF44: 0 | AG44: 50 | AH44: 0 | AI44: -0.7647 | AJ44: (NULL) | AK44: =I44+SUM(Z44:AA44)/100-X44-SUM(AB44:AC44)/100-SUM(AD44:AH44)/100/4 -> -0.764768

Sheet Sheet3
