Workbook

Sheet Sheet1
B1: count(1) | C1: sum(p.bal) | D1: smm | E1: cpr
A2: 1 | B2: 141 | C2: 1.3282474e+09 | D2: 0.00052618146 | E2: =100*(1-(1-D2)^12) -> 0.62959364 | F2: =C2/$I$3 -> 0.00018953919 | G2: =A3-A2 -> 1 | H2: Total count: | I2: =SUM(B2:B155) -> 530865
A3: 2 | B3: 5190 | C3: 9.9950933e+10 | D3: 0.0014934934 | E3: =100*(1-(1-D3)^12) -> 1.7775437 | F3: =C3/$I$3+F2 -> 0.014452409 | G3: =A4-A3 -> 1 | H3: Total bal: | I3: =SUM(C:C) -> 7.0077717e+12
A4: 3 | B4: 9107 | C4: 1.8522856e+11 | D4: 0.001854424 | E4: =100*(1-(1-D4)^12) -> 2.2027518 | F4: =C4/$I$3+F3 -> 0.040884285 | G4: =A5-A4 -> 1
A5: 4 | B5: 10252 | C5: 2.0917535e+11 | D5: 0.0022126738 | E5: =100*(1-(1-D5)^12) -> 2.6231326 | F5: =C5/$I$3+F4 -> 0.070733339 | G5: =A6-A5 -> 1
A6: 5 | B6: 10676 | C6: 2.1690702e+11 | D6: 0.0026471727 | E6: =100*(1-(1-D6)^12) -> 3.1307632 | F6: =C6/$I$3+F5 -> 0.10168569 | G6: =A7-A6 -> 1
A7: 6 | B7: 10821 | C7: 2.0608732e+11 | D7: 0.0028745749 | E7: =100*(1-(1-D7)^12) -> 3.3954721 | F7: =C7/$I$3+F6 -> 0.13109409 | G7: =A8-A7 -> 1
A8: 7 | B8: 10748 | C8: 1.9607423e+11 | D8: 0.0034474094 | E8: =100*(1-(1-D8)^12) -> 4.0593471 | F8: =C8/$I$3+F7 -> 0.15907363 | G8: =A9-A8 -> 1
A9: 8 | B9: 10941 | C9: 1.9095721e+11 | D9: 0.0035462385 | E9: =100*(1-(1-D9)^12) -> 4.1734593 | F9: =C9/$I$3+F8 -> 0.18632298 | G9: =A10-A9 -> 1
A10: 9 | B10: 11093 | C10: 1.8389094e+11 | D10: 0.0040316138 | E10: =100*(1-(1-D10)^12) -> 4.7320894 | F10: =C10/$I$3+F9 -> 0.21256398 | G10: =A11-A10 -> 1
A11: 10 | B11: 11237 | C11: 1.8585075e+11 | D11: 0.0042510273 | E11: =100*(1-(1-D11)^12) -> 4.9836367 | F11: =C11/$I$3+F10 -> 0.23908464 | G11: =A12-A11 -> 1
A12: 11 | B12: 11458 | C12: 1.792338e+11 | D12: 0.0046337629 | E12: =100*(1-(1-D12)^12) -> 5.4209681 | F12: =C12/$I$3+F11 -> 0.26466107 | G12: =A13-A12 -> 1
A13: 12 | B13: 11727 | C13: 1.8245901e+11 | D13: 0.0049982087 | E13: =100*(1-(1-D13)^12) -> 5.8356851 | F13: =C13/$I$3+F12 -> 0.29069774 | G13: =A14-A13 -> 1
A14: 13 | B14: 11999 | C14: 1.8182545e+11 | D14: 0.0052448814 | E14: =100*(1-(1-D14)^12) -> 6.1154368 | F14: =C14/$I$3+F13 -> 0.316644 | G14: =A15-A14 -> 1
A15: 14 | B15: 12324 | C15: 1.8180779e+11 | D15: 0.0055211849 | E15: =100*(1-(1-D15)^12) -> 6.4278881 | F15: =C15/$I$3+F14 -> 0.34258773 | G15: =A16-A15 -> 1
... A155: 337 | B155: 15 | C155: 1585520.5 | D155: 0.036572477 | E155: =100*(1-(1-D155)^12) -> 36.051762 | F155: =C155/$I$3+F154 -> 1 | G155: =A156-A155 -> -337

Sheet Sheet2
B1: count(1) | C1: sum(p.bal) | D1: smm | E1: cpr | I1: count(1) | J1: sum(p.bal) | K1: smm | L1: cpr
A2: 1 | B2: 141 | C2: 1.3282474e+09 | D2: 0.00052618146 | E2: 0.62959364 | F2: 0.00018953919 | H2: 80 | I2: 2604 | J2: 8.8005017e+09 | K2: 0.0069714546 | L2: 8.0523161 | M2: 0.99199057 | O2: Total count: | P2: 530865
A3: 2 | B3: 5190 | C3: 9.9950933e+10 | D3: 0.0014934934 | E3: 1.7775437 | F3: 0.014452409 | H3: 81 | I3: 2636 | J3: 8.7569523e+09 | K3: 0.0074960448 | L3: 8.6335073 | M3: 0.99324018 | O3: Total bal: | P3: 7.0077717e+12
A4: 3 | B4: 9107 | C4: 1.8522856e+11 | D4: 0.001854424 | E4: 2.2027518 | F4: 0.040884285 | H4: 82 | I4: 2614 | J4: 8.4783209e+09 | K4: 0.0076338519 | L4: 8.7856238 | M4: 0.99445002
A5: 4 | B5: 10252 | C5: 2.0917535e+11 | D5: 0.0022126738 | E5: 2.6231326 | F5: 0.070733339 | H5: 83 | I5: 2498 | J5: 7.4681623e+09 | K5: 0.0073679641 | L5: 8.4919189 | M5: 0.99551572
A6: 5 | B6: 10676 | C6: 2.1690702e+11 | D6: 0.0026471727 | E6: 3.1307632 | F6: 0.10168569 | H6: 84 | I6: 2327 | J6: 6.7875299e+09 | K6: 0.0075146845 | L6: 8.6540961 | M6: 0.99648429
A7: 6 | B7: 10821 | C7: 2.0608732e+11 | D7: 0.0028745749 | E7: 3.3954721 | F7: 0.13109409 | H7: 85 | I7: 2106 | J7: 5.9299581e+09 | K7: 0.0072905723 | L7: 8.4062677 | M7: 0.99733049
A8: 7 | B8: 10748 | C8: 1.9607423e+11 | D8: 0.0034474094 | E8: 4.0593471 | F8: 0.15907363 | H8: 86 | I8: 1835 | J8: 4.388464e+09 | K8: 0.0074259898 | L8: 8.556089 | M8: 0.99795672
A9: 8 | B9: 10941 | C9: 1.9095721e+11 | D9: 0.0035462385 | E9: 4.1734593 | F9: 0.18632298 | H9: 87 | I9: 1503 | J9: 3.2707018e+09 | K9: 0.007708338 | L9: 8.8677475 | M9: 0.99842344
A10: 9 | B10: 11093 | C10: 1.8389094e+11 | D10: 0.0040316138 | E10: 4.7320894 | F10: 0.21256398 | H10: 88 | I10: 1221 | J10: 2.4175596e+09 | K10: 0.0065441445 | L10: 7.5763987 | M10: 0.99876842
A11: 10 | B11: 11237 | C11: 1.8585075e+11 | D11: 0.0042510273 | E11: 4.9836367 | F11: 0.23908464 | H11: 89 | I11: 974 | J11: 1.6365297e+09 | K11: 0.0075501508 | L11: 8.6932591 | M11: 0.99900196
A12: 11 | B12: 11458 | C12: 1.792338e+11 | D12: 0.0046337629 | E12: 5.4209681 | F12: 0.26466107 | H12: 90 | I12: 793 | J12: 1.4279916e+09 | K12: 0.0074747953 | L12: 8.6100308 | M12: 0.99920573
A13: 12 | B13: 11727 | C13: 1.8245901e+11 | D13: 0.0049982087 | E13: 5.8356851 | F13: 0.29069774 | H13: 91 | I13: 668 | J13: 1.0289099e+09 | K13: 0.0090522032 | L13: 10.337815 | M13: 0.99935255
A14: 13 | B14: 11999 | C14: 1.8182545e+11 | D14: 0.0052448814 | E14: 6.1154368 | F14: 0.316644 | H14: 92 | I14: 583 | J14: 8.1144143e+08 | K14: 0.010358167 | L14: 11.745564 | M14: 0.99946834
A15: 14 | B15: 12324 | C15: 1.8180779e+11 | D15: 0.0055211849 | E15: 6.4278881 | F15: 0.34258773 | H15: 93 | I15: 482 | J15: 7.2062827e+08 | K15: 0.0073233036 | L15: 8.4425011 | M15: 0.99957118
... A76: 75 | B76: 2406 | C76: 8.7525836e+09 | D76: 0.0068293742 | E76: 7.8943237 | F76: 0.98569158 | H76: 337 | I76: 15 | J76: 1585520.5 | K76: 0.036572477 | L76: 36.051762 | M76: 1
A77: 76 | B77: 2462 | C77: 8.8886884e+09 | D77: 0.0065836053 | E77: 7.6204428 | F77: 0.98695999
A78: 77 | B78: 2482 | C78: 8.9080069e+09 | D78: 0.00757158 | E78: 8.7169146 | F78: 0.98823115
A79: 78 | B79: 2549 | C79: 8.6644751e+09 | D79: 0.0070899864 | E79: 8.1839326 | F79: 0.98946756
A80: 79 | B80: 2573 | C80: 8.8802132e+09 | D80: 0.0081735173 | E80: 9.3790936 | F80: 0.99073475

Sheet Sheet3
B1: age | C1: loan_curtail | D1: pool_cpr | E1: empirical | F1: citi_curtail | G1: empirical | K1: citi_curtail | O1: marketTicker | P1: loanAge_bucket | Q1: wac | R1: schamBalance | S1: age | T1: cpr
B2: 0 | C2: 0 | D2: 0 | E2: 0 | F2: 0 | G2: =E2/100 -> 0 | I2: 1 | J2: 0 | K2: 0 | O2: FGLMC | P2: 1 | Q2: 5.736 | R2: 4.5687397e+13 | S2: 6.1 | T2: 10.54
B3: 6 | C3: 0.006 | D3: 0.1103 | E3: 0.4501036 | F3: 0.003 | G3: =E3/100 -> 0.004501036 | I3: 2 | J3: 6 | K3: 0.003 | O3: FGLMC | P3: 2 | Q3: 5.811 | R3: 4.3390261e+13 | S3: 17.2 | T3: 19.19
B4: 12 | C4: 0.006 | D4: 0.1103 | E4: 0.4501036 | F4: 0.003 | G4: =E4/100 -> 0.004501036 | I4: 3 | J4: 12 | K4: 0.003 | O4: FGLMC | P4: 3 | Q4: 5.85 | R4: 3.3399709e+13 | S4: 29.2 | T4: 20.02
B5: 24 | C5: 0.0052 | D5: 0.194 | E5: 0.4790077 | F5: 0.00438 | G5: =E5/100 -> 0.004790077 | I5: 4 | J5: 24 | K5: 0.00438 | O5: FGLMC | P5: 4 | Q5: 5.905 | R5: 2.5103173e+13 | S5: 41.1 | T5: 20.58
B6: 36 | C6: 0.0052 | D6: 0.2074 | E6: 0.521 | F6: 0.00522 | G6: =E6/100 -> 0.00521 | I6: 5 | J6: 36 | K6: 0.00522 | O6: FGLMC | P6: 5 | Q6: 6.094 | R6: 1.7614724e+13 | S6: 53.1 | T6: 22.8
B7: 48 | C7: 0.0051 | D7: 0.2166 | E7: 0.5700166 | F7: 0.0063 | G7: =E7/100 -> 0.005700166 | I7: 6 | J7: 48 | K7: 0.0063 | O7: FGLMC | P7: 6 | Q7: 6.175 | R7: 1.249675e+13 | S7: 65.1 | T7: 23.81
B8: 60 | C8: 0.005 | D8: 0.2288 | E8: 0.4390171 | F8: 0.00378 | G8: =E8/100 -> 0.004390171 | I8: 7 | J8: 60 | K8: 0.00378 | O8: FGLMC | P8: 7 | Q8: 6.265 | R8: 8.6269534e+12 | S8: 77.1 | T8: 25.21
B9: 72 | C9: 0.0049 | D9: 0.2341 | E9: 0.4160252 | F9: 0.00342 | G9: =E9/100 -> 0.004160252 | I9: 8 | J9: 72 | K9: 0.00342 | O9: FGLMC | P9: 8 | Q9: 6.386 | R9: 5.7090918e+12 | S9: 89 | T9: 26.89
B10: 84 | C10: 0.0045 | D10: 0.2479 | E10: 0.3570398 | F10: 0.00264 | G10: =E10/100 -> 0.003570398 | I10: 9 | J10: 84 | K10: 0.00264 | O10: FGLMC | P10: 9 | Q10: 6.499 | R10: 3.8383026e+12 | S10: 101.1 | T10: 26.38
B11: 96 | C11: 0.0047 | D11: 0.2622 | E11: 0.3940266 | F11: 0.00318 | G11: =E11/100 -> 0.003940266 | I11: 10 | J11: 96 | K11: 0.00318 | O11: FGLMC | P11: 10 | Q11: 6.52 | R11: 2.5581422e+12 | S11: 113 | T11: 30.37
B12: 108 | C12: 0.0048 | D12: 0.2643 | E12: 0.4500041 | F12: 0.0042 | G12: =E12/100 -> 0.004500041 | I12: 11 | J12: 108 | K12: 0.0042 | O12: FGLMC | P12: 11 | Q12: 6.496 | R12: 1.6431732e+12 | S12: 125.1 | T12: 26.26
B13: 120 | C13: 0.0053 | D13: 0.309 | E13: 0.5050029 | F13: 0.0048 | G13: =E13/100 -> 0.005050029 | I13: 12 | J13: 120 | K13: 0.0048 | O13: FGLMC | P13: 12 | Q13: 6.518 | R13: 1.080839e+12 | S13: 137 | T13: 21.75
... B32: 348 | C32: 0.0043 | D32: 0.2515 | E32: 4.0246597 | F32: 0.075 | G32: =E32/100 -> 0.040246597 | I32: 31 | J32: 348 | K32: 0.075 | O32: FGLMC | P32: 31 | Q32: 9.216 | R32: 27433.72 | S32: 360.3 | T32: 88.64
B33: 360 | C33: 0.016 | D33: 0.3078 | E33: 4.591798 | F33: 0.075 | G33: =E33/100 -> 0.04591798 | I33: 32 | J33: 360 | K33: 0.075
I35: >

Sheet model curve
C1: old | D1: Modify 1 | E1: Modify 2 | F1: Modify 3 | AC1: kAgeVector | AD1: curtailment.smooth.cpr
A2: 1 | B2: 0 | C2: 0 | D2: 0 | E2: 0 | F2: 0 | AC2: [1 | AD2: ] | AE2: 0 | AF2: 0
A3: 2 | B3: 1 | C3: 0.08557951 | D3: 0.08557951 | E3: 0.08557951 | F3: 0.08543633 | AC3: [2 | AD3: ] | AE3: 1 | AF3: 0.08543633
A4: 3 | B4: 2 | C4: 0.18360025 | D4: 0.18360025 | E4: 0.18360025 | F4: 0.18337554 | AC4: [3 | AD4: ] | AE4: 2 | AF4: 0.18337554
A5: 4 | B5: 3 | C5: 0.28153283 | D5: 0.28153283 | E5: 0.28153283 | F5: 0.28131474 | AC5: [4 | AD5: ] | AE5: 3 | AF5: 0.28131474
A6: 5 | B6: 4 | C6: 0.36689145 | D6: 0.36689145 | E6: 0.36689145 | F6: 0.36675107 | AC6: [5 | AD6: ] | AE6: 4 | AF6: 0.36675107
A7: 6 | B7: 5 | C7: 0.4272266 | D7: 0.4272266 | E7: 0.4272266 | F7: 0.42718165 | AC7: [6 | AD7: ] | AE7: 5 | AF7: 0.42718165
A8: 7 | B8: 6 | C8: 0.45010359 | D8: 0.45010359 | E8: 0.45010359 | F8: 0.45010359 | AC8: [7 | AD8: ] | AE8: 6 | AF8: 0.45010359
A9: 8 | B9: 7 | C9: 0.45010359 | D9: 0.45010359 | E9: 0.45010359 | F9: 0.45010359 | AC9: [8 | AD9: ] | AE9: 7 | AF9: 0.45010359
A10: 9 | B10: 8 | C10: 0.45010359 | D10: 0.45010359 | E10: 0.45010359 | F10: 0.45010359 | AC10: [9 | AD10: ] | AE10: 8 | AF10: 0.45010359
A11: 10 | B11: 9 | C11: 0.45010359 | D11: 0.45010359 | E11: 0.45010359 | F11: 0.45010359 | AC11: [10 | AD11: ] | AE11: 9 | AF11: 0.45010359
A12: 11 | B12: 10 | C12: 0.45010359 | D12: 0.45010359 | E12: 0.45010359 | F12: 0.45010359 | AC12: [11 | AD12: ] | AE12: 10 | AF12: 0.45010359
A13: 12 | B13: 11 | C13: 0.45010359 | D13: 0.45010359 | E13: 0.45010359 | F13: 0.45010359 | AC13: [12 | AD13: ] | AE13: 11 | AF13: 0.45010359
... A52: 51 | B52: 50 | C52: 0.57570354 | D52: 0.57570354 | E52: 0.59458732 | F52: 0.58865212 | AC52: [51 | AD52: ] | AE52: 50 | AF52: 0.58865212
A53: 52 | B53: 51 | C53: 0.58030371 | D53: 0.58030371 | E53: 0.5982047 | F53: 0.59257941 | L53: 256 | M53: 0.09 | N53: =1-(1-M53)^(1/12) -> 0.0078284203 | AC53: [52 | AD53: ] | AE53: 51 | AF53: 0.59257941
A54: 53 | B54: 52 | C54: 0.58486009 | D54: 0.58486009 | E54: 0.60159793 | F54: 0.5963391 | L54: 354 | M54: 16.41 | AC54: [53 | AD54: ] | AE54: 52 | AF54: 0.5963391
A55: 54 | B55: 53 | C55: 0.58936444 | D55: 0.58936444 | E55: 0.60475094 | F55: 0.59991754 | L55: =AVERAGE(L53:L54) -> 305 | M55: =AVERAGE(M53:M54) -> 8.25 | AC55: [54 | AD55: ] | AE55: 53 | AF55: 0.59991754
A56: 55 | B56: 54 | C56: 0.5938085 | D56: 0.5938085 | E56: 0.60764764 | F56: 0.60330109 | AC56: [55 | AD56: ] | AE56: 54 | AF56: 0.60330109
A57: 56 | B57: 55 | C57: 0.59818402 | D57: 0.59818402 | E57: 0.61027196 | F57: 0.60647608 | AC57: [56 | AD57: ] | AE57: 55 | AF57: 0.60647608
A58: 57 | B58: 56 | C58: 0.60248276 | D58: 0.60248276 | E58: 0.61260781 | F58: 0.60942887 | AC58: [57 | AD58: ] | AE58: 56 | AF58: 0.60942887
A59: 58 | B59: 57 | C59: 0.60669646 | D59: 0.60669646 | E59: 0.61463912 | F59: 0.6121458 | AC59: [58 | AD59: ] | AE59: 57 | AF59: 0.6121458
A60: 59 | B60: 58 | C60: 0.61081689 | D60: 0.61081689 | E60: 0.6163498 | F60: 0.61461322 | AC60: [59 | AD60: ] | AE60: 58 | AF60: 0.61461322
A61: 60 | B61: 59 | C61: 0.6148358 | D61: 0.6148358 | E61: 0.61772377 | F61: 0.61681749 | AC61: [60 | AD61: ] | AE61: 59 | AF61: 0.61681749
A62: 61 | B62: 60 | C62: 0.61874495 | D62: 0.61874495 | E62: 0.61874495 | F62: 0.61874495 | AC62: [61 | AD62: ] | AE62: 60 | AF62: 0.61874495
A63: 62 | B63: 61 | C63: 0.62261267 | D63: 0.62250849 | E63: 0.6195349 | F63: 0.62042122 | AC63: [62 | AD63: ] | AE63: 61 | AF63: 0.62042122
A64: 63 | B64: 62 | C64: 0.62651208 | D64: 0.62610242 | E64: 0.62024823 | F64: 0.62190709 | AC64: [63 | AD64: ] | AE64: 62 | AF64: 0.62190709
A65: 64 | B65: 63 | C65: 0.6304421 | D65: 0.6295363 | E65: 0.62091835 | F65: 0.6232416 | AC65: [64 | AD65: ] | AE65: 63 | AF65: 0.6232416
A66: 65 | B66: 64 | C66: 0.63440166 | D66: 0.63281964 | E66: 0.62157872 | F66: 0.6244638 | AC66: [65 | AD66: ] | AE66: 64 | AF66: 0.6244638
A67: 66 | B67: 65 | C67: 0.63838966 | D67: 0.63596197 | E67: 0.62226274 | F67: 0.62561277 | AC67: [66 | AD67: ] | AE67: 65 | AF67: 0.62561277
... A100: 99 | B100: 98 | C100: 0.77889184 | D100: 0.72286146 | E100: 1.1060606 | F100: 0.87447391 | AC100: [99 | AD100: ] | AE100: 98 | AF100: 0.87447391
A101: 100 | B101: 99 | C101: 0.78320541 | D101: 0.72687207 | E101: 1.1841158 | F101: 0.89476661 | AA101: [100 | AB101: [100 | AC101: ] | AD101: 99 | AF101: 0.89476661
A102: 101 | B102: 100 | C102: 0.78750973 | D102: 0.73107455 | E102: 1.2685409 | F102: 0.91593523 | AA102: [101 | AB102: [101 | AC102: ] | AD102: 100 | AF102: 0.91593523
A103: 102 | B103: 101 | C103: 0.79180371 | D103: 0.73547837 | E103: 1.3590524 | F103: 0.93797054 | AA103: [102 | AB103: [102 | AC103: ] | AD103: 101 | AF103: 0.93797054
A104: 103 | B104: 102 | C104: 0.79608627 | D104: 0.74009302 | E104: 1.4553666 | F104: 0.96086334 | AA104: [103 | AB104: [103 | AC104: ] | AD104: 102 | AF104: 0.96086334
A105: 104 | B105: 103 | C105: 0.80035635 | D105: 0.74492797 | E105: 1.5571999 | F105: 0.9846044 | AA105: [104 | AB105: [104 | AC105: ] | AD105: 103 | AF105: 0.9846044
A106: 105 | B106: 104 | C106: 0.80461287 | D106: 0.74999271 | E106: 1.6642687 | F106: 1.0091845 | AA106: [105 | AB106: [105 | AC106: ] | AD106: 104 | AF106: 1.0091845
A107: 106 | B107: 105 | C107: 0.80885476 | D107: 0.7552967 | E107: 1.7762897 | F107: 1.0345944 | AA107: [106 | AB107: [106 | AC107: ] | AD107: 105 | AF107: 1.0345944
A108: 107 | B108: 106 | C108: 0.81308094 | D108: 0.76084943 | E108: 1.89298 | F108: 1.060825 | AA108: [107 | AB108: [107 | AC108: ] | AD108: 106 | AF108: 1.060825
A109: 108 | B109: 107 | C109: 0.81729034 | D109: 0.76666035 | E109: 2.0140573 | F109: 1.0878669 | AA109: [108 | AB109: [108 | AC109: ] | AD109: 107 | AF109: 1.0878669
A110: 109 | B110: 108 | C110: 0.82148188 | D110: 0.77273892 | E110: 2.13924 | F110: 1.1157111 | AA110: [109 | AB110: [109 | AC110: ] | AD110: 108 | AF110: 1.1157111
...

Sheet total smm
B1: count(1) | C1: sum(p.bal) | D1: smm | E1: cpr new | F1: cpr old | R1: wala | S1: marketTicker | T1: count(1) | U1: sum(p.bal) | V1: smm | W1: cpr new | Y1: marketTicker | Z1: FGLMC
A2: 1 | B2: 508 | C2: 7.2429444e+09 | D2: 0.0016525706 | E2: =100*(1-(1-D2)^12) -> 1.9651591 | F2: =VLOOKUP(A2,Sheet3!B:D,3,0)*100 -> #N/A | R2: 1 | S2: FGLMC | T2: 508 | U2: 7.2429444e+09 | V2: 0.0016525706 | W2: =100*(1-(1-V2)^12) -> 1.9651591
A3: 2 | B3: 20581 | C3: 4.1616615e+11 | D3: 0.0031826954 | E3: =100*(1-(1-D3)^12) -> 3.7530837 | F3: =VLOOKUP(A3,Sheet3!B:D,3,0)*100 -> #N/A | R3: 2 | S3: FGLMC | T3: 19751 | U3: 4.0263747e+11 | V3: 0.0032344398 | W3: =100*(1-(1-V3)^12) -> 3.8130202 | Y3: Row Labels | Z3: Sum of cpr new
A4: 3 | B4: 35915 | C4: 7.568067e+11 | D4: 0.0044137836 | E4: =100*(1-(1-D4)^12) -> 5.1698356 | F4: =VLOOKUP(A4,Sheet3!B:D,3,0)*100 -> #N/A | R4: 2 | S4: FGT6 | T4: 137 | U4: 5.3288349e+09 | V4: 0.0034873049 | W4: =100*(1-(1-V4)^12) -> 4.1054271 | Y4: 1 | Z4: 1.9651591
A5: 4 | B5: 38212 | C5: 7.7954759e+11 | D5: 0.0065330809 | E5: =100*(1-(1-D5)^12) -> 7.5640467 | F5: =VLOOKUP(A5,Sheet3!B:D,3,0)*100 -> #N/A | R5: 2 | S5: FGU6 | T5: 439 | U5: 5.29402e+09 | V5: 0.00033258029 | W5: =100*(1-(1-V5)^12) -> 0.39836713 | Y5: 2 | Z5: 3.8130202
A6: 5 | B6: 38849 | C6: 7.7650777e+11 | D6: 0.0089092956 | E6: =100*(1-(1-D6)^12) -> 10.182527 | F6: =VLOOKUP(A6,Sheet3!B:D,3,0)*100 -> #N/A | R6: 2 | S6: FGU9 | T6: 254 | U6: 2.9058256e+09 | V6: 0.00064679896 | W6: =100*(1-(1-V6)^12) -> 0.7734036 | Y6: 3 | Z6: 5.2368916
A7: 6 | B7: 39097 | C7: 7.7010479e+11 | D7: 0.010217487 | E7: =100*(1-(1-D7)^12) -> 11.5949 | F7: =VLOOKUP(A7,Sheet3!B:D,3,0)*100 -> 11.03 | R7: 3 | S7: FGLMC | T7: 34621 | U7: 7.3599359e+11 | V7: 0.004472469 | W7: =100*(1-(1-V7)^12) -> 5.2368916 | Y7: 4 | Z7: 7.6435037
A8: 7 | B8: 39482 | C8: 7.6719233e+11 | D8: 0.011236564 | E8: =100*(1-(1-D8)^12) -> 12.680996 | F8: =VLOOKUP(A8,Sheet3!B:D,3,0)*100 -> #N/A | R8: 3 | S8: FGT6 | T8: 242 | U8: 9.2724835e+09 | V8: 0.00437913 | W8: =100*(1-(1-V8)^12) -> 5.1302186 | Y8: 5 | Z8: 10.247855
A9: 8 | B9: 39763 | C9: 7.563629e+11 | D9: 0.012004823 | E9: =100*(1-(1-D9)^12) -> 13.491676 | F9: =VLOOKUP(A9,Sheet3!B:D,3,0)*100 -> #N/A | R9: 3 | S9: FGU6 | T9: 669 | U9: 7.4862266e+09 | V9: 0.00088539733 | W9: =100*(1-(1-V9)^12) -> 1.0573181 | Y9: 6 | Z9: 11.590554
A10: 9 | B10: 40050 | C10: 7.4116348e+11 | D10: 0.012322892 | E10: =100*(1-(1-D10)^12) -> 13.825285 | F10: =VLOOKUP(A10,Sheet3!B:D,3,0)*100 -> #N/A | R10: 3 | S10: FGU9 | T10: 383 | U10: 4.0544017e+09 | V10: 0.00035487525 | W10: =100*(1-(1-V10)^12) -> 0.4250201 | Y10: 7 | Z10: 12.610817
A11: 10 | B11: 40204 | C11: 7.32956e+11 | D11: 0.012936914 | E11: =100*(1-(1-D11)^12) -> 14.465971 | F11: =VLOOKUP(A11,Sheet3!B:D,3,0)*100 -> #N/A | R11: 4 | S11: FGLMC | T11: 36834 | U11: 7.5753019e+11 | V11: 0.0066042734 | W11: =100*(1-(1-V11)^12) -> 7.6435037 | Y11: 8 | Z11: 13.475697
A12: 11 | B12: 40434 | C12: 7.2350227e+11 | D12: 0.013974924 | E12: =100*(1-(1-D12)^12) -> 15.539136 | F12: =VLOOKUP(A12,Sheet3!B:D,3,0)*100 -> #N/A | R12: 4 | S12: FGT6 | T12: 273 | U12: 1.0046544e+10 | V12: 0.008237374 | W12: =100*(1-(1-V12)^12) -> 9.449082 | Y12: 9 | Z12: 13.792227
A13: 12 | B13: 40559 | C13: 7.1643806e+11 | D13: 0.014579127 | E13: =100*(1-(1-D13)^12) -> 16.158105 | F13: =VLOOKUP(A13,Sheet3!B:D,3,0)*100 -> 11.03 | R13: 4 | S13: FGU6 | T13: 695 | U13: 7.5196358e+09 | V13: 0.00063188836 | W13: =100*(1-(1-V13)^12) -> 0.7556363 | Y13: 10 | Z13: 14.46567
A14: 13 | B14: 40790 | C14: 7.0291166e+11 | D14: 0.015435156 | E14: =100*(1-(1-D14)^12) -> 17.027936 | F14: =VLOOKUP(A14,Sheet3!B:D,3,0)*100 -> #N/A | R14: 4 | S14: FGU9 | T14: 410 | U14: 4.4512277e+09 | V14: 0.0005396937 | W14: =100*(1-(1-V14)^12) -> 0.64571352 | Y14: 11 | Z14: 15.603704
A15: 14 | B15: 40886 | C15: 6.89628e+11 | D15: 0.015778707 | E15: =100*(1-(1-D15)^12) -> 17.374695 | F15: =VLOOKUP(A15,Sheet3!B:D,3,0)*100 -> #N/A | R15: 5 | S15: FGLMC | T15: 37462 | U15: 7.5452589e+11 | V15: 0.0089693877 | W15: =100*(1-(1-V15)^12) -> 10.247855 | Y15: 12 | Z15: 16.283899
... A360: 359 | B360: 21 | C360: 10431.66 | D360: 0.079117504 | E360: =100*(1-(1-D360)^12) -> 62.807907 | F360: =VLOOKUP(A360,Sheet3!B:D,3,0)*100 -> #N/A | R360: 157 | S360: FGLMC | T360: 16011 | U360: 7.6208272e+09 | V360: 0.017353689 | W360: =100*(1-(1-V360)^12) -> 18.94744 | Y360: 357 | Z360: 99.91377
A361: 360 | F361: =VLOOKUP(A361,Sheet3!B:D,3,0)*100 -> 30.78 | R361: 158 | S361: FGLMC | T361: 15745 | U361: 7.2319712e+09 | V361: 0.016980652 | W361: =100*(1-(1-V361)^12) -> 18.577434 | Y361: 358 | Z361: 50.985974
R362: 159 | S362: FGLMC | T362: 15480 | U362: 6.8534411e+09 | V362: 0.01633048 | W362: =100*(1-(1-V362)^12) -> 17.92884 | Y362: 359 | Z362: 62.807907
R363: 160 | S363: FGLMC | T363: 15180 | U363: 6.1124267e+09 | V363: 0.016861874 | W363: =100*(1-(1-V363)^12) -> 18.459295 | Y363: Grand Total | Z363: 7790.3405
R364: 161 | S364: FGLMC | T364: 14895 | U364: 5.958246e+09 | V364: 0.015385839 | W364: =100*(1-(1-V364)^12) -> 16.97805
R365: 162 | S365: FGLMC | T365: 14643 | U365: 5.6238766e+09 | V365: 0.015853708 | W365: =100*(1-(1-V365)^12) -> 17.450219
R366: 163 | S366: FGLMC | T366: 14444 | U366: 5.2810585e+09 | V366: 0.0162126 | W366: =100*(1-(1-V366)^12) -> 17.81074
R367: 164 | S367: FGLMC | T367: 14205 | U367: 4.709928e+09 | V367: 0.015551175 | W367: =100*(1-(1-V367)^12) -> 17.145188
R368: 165 | S368: FGLMC | T368: 14012 | U368: 4.796002e+09 | V368: 0.016163332 | W368: =100*(1-(1-V368)^12) -> 17.761334
R369: 166 | S369: FGLMC | T369: 13835 | U369: 4.6468349e+09 | V369: 0.016154603 | W369: =100*(1-(1-V369)^12) -> 17.752578
R370: 167 | S370: FGLMC | T370: 13595 | U370: 4.4451902e+09 | V370: 0.014878751 | W370: =100*(1-(1-V370)^12) -> 16.463506
R371: 168 | S371: FGLMC | T371: 13383 | U371: 4.3371582e+09 | V371: 0.015906217 | W371: =100*(1-(1-V371)^12) -> 17.503057
R372: 169 | S372: FGLMC | T372: 13094 | U372: 4.1176234e+09 | V372: 0.016603191 | W372: =100*(1-(1-V372)^12) -> 18.201463
R373: 170 | S373: FGLMC | T373: 12887 | U373: 3.6820521e+09 | V373: 0.015157929 | W373: =100*(1-(1-V373)^12) -> 16.747149
R374: 171 | S374: FGLMC | T374: 12639 | U374: 3.7947197e+09 | V374: 0.015090518 | W374: =100*(1-(1-V374)^12) -> 16.678741
R375: 172 | S375: FGLMC | T375: 12470 | U375: 3.681978e+09 | V375: 0.015317701 | W375: =100*(1-(1-V375)^12) -> 16.909079
... R562: 359 | S562: FGLMC | T562: 21 | U562: 10431.66 | V562: 0.079117504 | W562: =100*(1-(1-V562)^12) -> 62.807907

Sheet Sheet7
A1: loanAge_bucket | B1: wac | C1: schamBalance | D1: age | E1: cpr | X1: marketTicker | Y1: loanAge_bucket | Z1: wac | AA1: schamBalance | AC1: cpr | AF1: marketTicker | AG1: loanAge_bucket | AH1: wac | AI1: schamBalance | AJ1: age | AK1: cpr | AO1: loanAge_bucket | AQ1: FHL CPR | AR1: FNMA CPR | AS1: FNMA bal%
A2: 1 | B2: 5.684 | C2: 114824290697104 | D2: 6.1 | E2: 10.78 | X2: FNCL | Y2: 1 | Z2: 5.651 | AA2: 6.9136894e+13 | AB2: 6.1 | AC2: 10.94 | AD2: =AA2/C2 -> 0.60211035 | AF2: FGLMC | AG2: 1 | AH2: 5.736 | AI2: 4.5687397e+13 | AJ2: 6.1 | AK2: 10.54 | AO2: 1 | AP2: =AO2*12-12 -> 0 | AQ2: 10.54 | AR2: 10.94 | AS2: 0.60211035
A3: 2 | B3: 5.763 | C3: 108912849030637 | D3: 17.2 | E3: 19.22 | X3: FNCL | Y3: 2 | Z3: 5.731 | AA3: 6.5522588e+13 | AB3: 17.2 | AC3: 19.24 | AD3: =AA3/C3 -> 0.60160567 | AF3: FGLMC | AG3: 2 | AH3: 5.811 | AI3: 4.3390261e+13 | AJ3: 17.2 | AK3: 19.19 | AO3: 2 | AP3: =AO3*12-12 -> 12 | AQ3: 19.19 | AR3: 19.24 | AS3: 0.60160567
A4: 3 | B4: 5.79 | C4: 8.3638001e+13 | D4: 29.2 | E4: 20.02 | X4: FNCL | Y4: 3 | Z4: 5.75 | AA4: 50238291417450 | AB4: 29.2 | AC4: 20.02 | AD4: =AA4/C4 -> 0.60066347 | AF4: FGLMC | AG4: 3 | AH4: 5.85 | AI4: 3.3399709e+13 | AJ4: 29.2 | AK4: 20.02 | AO4: 3 | AP4: =AO4*12-12 -> 24 | AQ4: 20.02 | AR4: 20.02 | AS4: 0.60066347
A5: 4 | B5: 5.84 | C5: 6.2955735e+13 | D5: 41.1 | E5: 20.3 | X5: FNCL | Y5: 4 | Z5: 5.798 | AA5: 3.7852562e+13 | AB5: 41.1 | AC5: 20.11 | AD5: =AA5/C5 -> 0.60125677 | AF5: FGLMC | AG5: 4 | AH5: 5.905 | AI5: 2.5103173e+13 | AJ5: 41.1 | AK5: 20.58 | AO5: 4 | AP5: =AO5*12-12 -> 36 | AQ5: 20.58 | AR5: 20.11 | AS5: 0.60125677
A6: 5 | B6: 6.064 | C6: 4.3866467e+13 | D6: 53.1 | E6: 22.23 | X6: FNCL | Y6: 5 | Z6: 6.045 | AA6: 2.6251743e+13 | AB6: 53.1 | AC6: 21.85 | AD6: =AA6/C6 -> 0.59844672 | AF6: FGLMC | AG6: 5 | AH6: 6.094 | AI6: 1.7614724e+13 | AJ6: 53.1 | AK6: 22.8 | AO6: 5 | AP6: =AO6*12-12 -> 48 | AQ6: 22.8 | AR6: 21.85 | AS6: 0.59844672
A7: 6 | B7: 6.181 | C7: 3.1174821e+13 | D7: 65.1 | E7: 23 | X7: FNCL | Y7: 6 | Z7: 6.184 | AA7: 1.8678071e+13 | AB7: 65.2 | AC7: 22.46 | AD7: =AA7/C7 -> 0.59913964 | AF7: FGLMC | AG7: 6 | AH7: 6.175 | AI7: 1.249675e+13 | AJ7: 65.1 | AK7: 23.81 | AO7: 6 | AP7: =AO7*12-12 -> 60 | AQ7: 23.81 | AR7: 22.46 | AS7: 0.59913964
A8: 7 | B8: 6.276 | C8: 2.1976562e+13 | D8: 77.1 | E8: 24.39 | X8: FNCL | Y8: 7 | Z8: 6.284 | AA8: 1.3349608e+13 | AB8: 77.1 | AC8: 23.86 | AD8: =AA8/C8 -> 0.60744754 | AF8: FGLMC | AG8: 7 | AH8: 6.265 | AI8: 8.6269534e+12 | AJ8: 77.1 | AK8: 25.21 | AO8: 7 | AP8: =AO8*12-12 -> 72 | AQ8: 25.21 | AR8: 23.86 | AS8: 0.60744754
A9: 8 | B9: 6.408 | C9: 1.5014737e+13 | D9: 89 | E9: 26.08 | X9: FNCL | Y9: 8 | Z9: 6.422 | AA9: 9.3056452e+12 | AB9: 89 | AC9: 25.58 | AD9: =AA9/C9 -> 0.61976745 | AF9: FGLMC | AG9: 8 | AH9: 6.386 | AI9: 5.7090918e+12 | AJ9: 89 | AK9: 26.89 | AO9: 8 | AP9: =AO9*12-12 -> 84 | AQ9: 26.89 | AR9: 25.58 | AS9: 0.61976745
A10: 9 | B10: 6.534 | C10: 1.0273663e+13 | D10: 101.1 | E10: 26.21 | X10: FNCL | Y10: 9 | Z10: 6.555 | AA10: 6.4353599e+12 | AB10: 101.1 | AC10: 26.11 | AD10: =AA10/C10 -> 0.62639394 | AF10: FGLMC | AG10: 9 | AH10: 6.499 | AI10: 3.8383026e+12 | AJ10: 101.1 | AK10: 26.38 | AO10: 9 | AP10: =AO10*12-12 -> 96 | AQ10: 26.38 | AR10: 26.11 | AS10: 0.62639394
A11: 10 | B11: 6.57 | C11: 6.8851702e+12 | D11: 113 | E11: 30.06 | X11: FNCL | Y11: 10 | Z11: 6.599 | AA11: 4.327028e+12 | AB11: 113 | AC11: 29.88 | AD11: =AA11/C11 -> 0.62845622 | AF11: FGLMC | AG11: 10 | AH11: 6.52 | AI11: 2.5581422e+12 | AJ11: 113 | AK11: 30.37 | AO11: 10 | AP11: =AO11*12-12 -> 108 | AQ11: 30.37 | AR11: 29.88 | AS11: 0.62845622
A12: 11 | B12: 6.572 | C12: 4.4801467e+12 | D12: 125.1 | E12: 25.89 | X12: FNCL | Y12: 11 | Z12: 6.616 | AA12: 2.8369735e+12 | AB12: 125.1 | AC12: 25.67 | AD12: =AA12/C12 -> 0.63323228 | AF12: FGLMC | AG12: 11 | AH12: 6.496 | AI12: 1.6431732e+12 | AJ12: 125.1 | AK12: 26.26 | AO12: 11 | AP12: =AO12*12-12 -> 120 | AQ12: 26.26 | AR12: 25.67 | AS12: 0.63323228
A13: 12 | B13: 6.601 | C13: 2.9988933e+12 | D13: 137 | E13: 21.53 | X13: FNCL | Y13: 12 | Z13: 6.648 | AA13: 1.9180543e+12 | AB13: 137 | AC13: 21.4 | AD13: =AA13/C13 -> 0.63958739 | AF13: FGLMC | AG13: 12 | AH13: 6.518 | AI13: 1.080839e+12 | AJ13: 137 | AK13: 21.75 | AO13: 12 | AP13: =AO13*12-12 -> 132 | AQ13: 21.75 | AR13: 21.4 | AS13: 0.63958739
... A32: 31 | B32: 7.656 | C32: 9.2110361e+08 | D32: 364.5 | E32: 31.36 | X32: FNCL | Y32: 31 | Z32: 7.656 | AA32: 9.2107618e+08 | AB32: 364.5 | AC32: 31.36 | AD32: =AA32/C32 -> 0.99997022 | AF32: FGLMC | AG32: 31 | AH32: 9.216 | AI32: 27433.72 | AJ32: 360.3 | AK32: 88.64 | AO32: 31 | AP32: =AO32*12-12 -> 360 | AQ32: 88.64 | AR32: 31.36 | AS32: 0.99997022
A33: 32 | B33: 7.514 | C33: 3.163458e+08 | D33: 376.3 | E33: 32.15 | X33: FNCL | Y33: 32 | Z33: 7.514 | AA33: 3.163458e+08 | AB33: 376.3 | AC33: 32.15 | AD33: =AA33/C33 -> 1 | AR33: 32.15
A34: 33 | B34: 7.415 | C34: 97792411 | D34: 388.3 | E34: 32.95 | X34: FNCL | Y34: 33 | Z34: 7.415 | AA34: 97792411 | AB34: 388.3 | AC34: 32.95 | AD34: =AA34/C34 -> 1 | AR34: 32.95
A35: 34 | B35: 7.308 | C35: 28339112 | D35: 400.2 | E35: 31.34 | X35: FNCL | Y35: 34 | Z35: 7.308 | AA35: 28339112 | AB35: 400.2 | AC35: 31.34 | AD35: =AA35/C35 -> 1 | AR35: 31.34
A36: 35 | B36: 7.242 | C36: 10127613 | D36: 412.7 | E36: 23.62 | X36: FNCL | Y36: 35 | Z36: 7.242 | AA36: 10127613 | AB36: 412.7 | AC36: 23.62 | AD36: =AA36/C36 -> 1 | AR36: 23.62
A37: 36 | B37: 7.07 | C37: 4115083.1 | D37: 424.5 | E37: 25.52 | X37: FNCL | Y37: 36 | Z37: 7.07 | AA37: 4115083.1 | AB37: 424.5 | AC37: 25.52 | AD37: =AA37/C37 -> 1 | AR37: 25.52
A38: 37 | B38: 7.171 | C38: 1294859.3 | D38: 436.2 | E38: 33.06 | X38: FNCL | Y38: 37 | Z38: 7.171 | AA38: 1294859.3 | AB38: 436.2 | AC38: 33.06 | AD38: =AA38/C38 -> 1 | AR38: 33.06
A39: 38 | B39: 7.58 | C39: 539430.81 | D39: 449 | E39: 11.1 | X39: FNCL | Y39: 38 | Z39: 7.58 | AA39: 539430.81 | AB39: 449 | AC39: 11.1 | AD39: =AA39/C39 -> 1 | AR39: 11.1
A40: 39 | B40: 8.018 | C40: 315093.25 | D40: 460.5 | E40: 7.66 | X40: FNCL | Y40: 39 | Z40: 8.018 | AA40: 315093.25 | AB40: 460.5 | AC40: 7.66 | AD40: =AA40/C40 -> 1 | AR40: 7.66
A41: 40 | B41: 6 | C41: 3972.27 | D41: 469.9 | E41: 82.06 | X41: FNCL | Y41: 40 | Z41: 6 | AA41: 3972.27 | AB41: 469.9 | AC41: 82.06 | AD41: =AA41/C41 -> 1 | AR41: 82.06

Sheet Sheet8
B1: y_vals.act | C1: y_vals.mdl | D1: Diff | AA1: kAgeVector | AB1: curtailment.smooth.cpr
A2: 0 | B2: 1.80572 | C2: 1.628071 | D2: =-C2+B2 -> 0.177649 | Y2: [1 | Z2: ] | AA2: 0 | AB2: 0
A3: 5 | B3: 3.654468 | C3: 3.208568 | D3: =-C3+B3 -> 0.4459 | Y3: [2 | Z3: ] | AA3: 1 | AB3: 0.08557951
A4: 10 | B4: 5.345786 | C4: 5.057708 | D4: =-C4+B4 -> 0.288078 | Y4: [3 | Z4: ] | AA4: 2 | AB4: 0.18360025
A5: 15 | B5: 5.537692 | C5: 5.539425 | D5: =-C5+B5 -> -0.001733 | Y5: [4 | Z5: ] | AA5: 3 | AB5: 0.28153283
A6: 20 | B6: 6.084098 | C6: 6.187201 | D6: =-C6+B6 -> -0.103103 | Y6: [5 | Z6: ] | AA6: 4 | AB6: 0.36689145
A7: 25 | B7: 6.908037 | C7: 6.816203 | D7: =-C7+B7 -> 0.091834 | Y7: [6 | Z7: ] | AA7: 5 | AB7: 0.4272266
A8: 30 | B8: 6.940381 | C8: 7.385508 | D8: =-C8+B8 -> -0.445127 | Y8: [7 | Z8: ] | AA8: 6 | AB8: 0.45010359
A9: 35 | B9: 6.685856 | C9: 7.569638 | D9: =-C9+B9 -> -0.883782 | Y9: [8 | Z9: ] | AA9: 7 | AB9: 0.45010359
A10: 40 | B10: 6.384542 | C10: 7.900025 | D10: =-C10+B10 -> -1.515483 | Y10: [9 | Z10: ] | AA10: 8 | AB10: 0.45010359
A11: 45 | B11: 6.512744 | C11: 8.181716 | D11: =-C11+B11 -> -1.668972 | Y11: [10 | Z11: ] | AA11: 9 | AB11: 0.45010359
A12: 50 | B12: 5.875841 | C12: 8.202722 | D12: =-C12+B12 -> -2.326881 | Y12: [11 | Z12: ] | AA12: 10 | AB12: 0.45010359
A13: 55 | B13: 6.140793 | C13: 8.812471 | D13: =-C13+B13 -> -2.671678 | Y13: [12 | Z13: ] | AA13: 11 | AB13: 0.45010359
... A38: 180 | B38: 7.924864 | C38: 4.235294 | D38: =-C38+B38 -> 3.68957 | Y38: [37 | Z38: ] | AA38: 36 | AB38: 0.51858645
A39: 185 | B39: 17.083347 | C39: 3.919657 | Y39: [38 | Z39: ] | AA39: 37 | AB39: 0.5232215
A40: 190 | B40: 20.167719 | C40: 4.830349 | Y40: [39 | Z40: ] | AA40: 38 | AB40: 0.52790004
A41: 195 | B41: 13.201314 | C41: 5.007078 | D41: =-C41+B41 -> 8.194236 | Y41: [40 | Z41: ] | AA41: 39 | AB41: 0.53261066
A42: 200 | B42: 8.64838 | C42: 5.864136 | D42: =-C42+B42 -> 2.784244 | Y42: [41 | Z42: ] | AA42: 40 | AB42: 0.53734194
A43: 205 | B43: 6.631431 | C43: 3.989366 | D43: =-C43+B43 -> 2.642065 | Y43: [42 | Z43: ] | AA43: 41 | AB43: 0.54208247
A44: 210 | B44: 7.768339 | C44: 4.130826 | D44: =-C44+B44 -> 3.637513 | Y44: [43 | Z44: ] | AA44: 42 | AB44: 0.54682085
A45: 215 | B45: 6.889753 | C45: 3.897173 | D45: =-C45+B45 -> 2.99258 | Y45: [44 | Z45: ] | AA45: 43 | AB45: 0.55154565
A46: 220 | B46: 16.381306 | C46: 4.799746 | D46: =-C46+B46 -> 11.58156 | Y46: [45 | Z46: ] | AA46: 44 | AB46: 0.55624549
A47: 225 | B47: 9.633748 | C47: 4.412053 | D47: =-C47+B47 -> 5.221695 | Y47: [46 | Z47: ] | AA47: 45 | AB47: 0.56090894
A48: 230 | B48: 11.997414 | C48: 4.860947 | D48: =-C48+B48 -> 7.136467 | Y48: [47 | Z48: ] | AA48: 46 | AB48: 0.5655246
A49: 235 | B49: 9.897568 | C49: 4.4573 | D49: =-C49+B49 -> 5.440268 | Y49: [48 | Z49: ] | AA49: 47 | AB49: 0.57008108
A50: 240 | B50: 6.816057 | C50: 4.843693 | D50: =-C50+B50 -> 1.972364 | Y50: [49 | Z50: ] | AA50: 48 | AB50: 0.57456698
A51: 245 | B51: 12.552166 | C51: 4.582027 | D51: =-C51+B51 -> 7.970139 | Y51: [50 | Z51: ] | AA51: 49 | AB51: 0.5789709
A52: 250 | B52: 8.242964 | C52: 4.25482 | D52: =-C52+B52 -> 3.988144 | Y52: [51 | Z52: ] | AA52: 50 | AB52: 0.58328144
... A73: 355 | B73: 90.792086 | C73: 4.81183 | D73: =-C73+B73 -> 85.980256 | Y73: [72 | Z73: ] | AA73: 71 | AB73: 0.63733583
Y74: [73 | Z74: ] | AA74: 72 | AB74: 0.6390371
Y75: [74 | Z75: ] | AA75: 73 | AB75: 0.64092989
Y76: [75 | Z76: ] | AA76: 74 | AB76: 0.64305795
Y77: [76 | Z77: ] | AA77: 75 | AB77: 0.64546502
Y78: [77 | Z78: ] | AA78: 76 | AB78: 0.64819485
Y79: [78 | Z79: ] | AA79: 77 | AB79: 0.65129119
Y80: [79 | Z80: ] | AA80: 78 | AB80: 0.65479774
Y81: [80 | Z81: ] | AA81: 79 | AB81: 0.65875825
Y82: [81 | Z82: ] | AA82: 80 | AB82: 0.6632164
Y83: [82 | Z83: ] | AA83: 81 | AB83: 0.6682159
Y84: [83 | Z84: ] | AA84: 82 | AB84: 0.67380041
...

Sheet Sheet9
