Workbook

Sheet v3
A1: Overall | C1: y_vals.act | D1: v3 | E1: v1 | G1: Conventional | I1: y_vals.act | J1: v3 | K1: v1 | M1: Jumbo | O1: y_vals.act | P1: v3 | Q1: v1 | S1: CQ | U1: y_vals.act | V1: v3 | W1: v1 | Y1: CQ | AA1: y_vals.act | AB1: v3 | AC1: v1 | AE1: History | AF1: x_vals | AG1: y_vals.act | AH1: Actual | AI1: v3 | AJ1: v1
A2: [1,] | B2: 40513 | C2: 2.9403271 | D2: 0 | E2: =VLOOKUP(B2,'v1'!B:D,3,0) -> 2.1523348 | G2: [1,] | H2: 40513 | I2: 2.9436942 | J2: 0 | K2: =VLOOKUP(H2,'v1'!H:J,3,0) -> 2.1546881 | M2: [1,] | N2: 40513 | O2: 8.7425281 | P2: 0 | Q2: =VLOOKUP(N2,'v1'!M:O,3,0) -> 0.81217765 | S2: [1,] | T2: 40513 | U2: 1.0463194 | V2: 0 | W2: =VLOOKUP(T2,'v1'!R:T,3,0) -> 1.4039362 | Y2: [1,] | Z2: 41091 | AA2: 0 | AB2: 0 | AC2: =VLOOKUP(Z2,'v1'!W:Y,3,0) -> 0.3002854 | AE2: [1,] | AF2: 34335 | AG2: 0 | AH2: =VLOOKUP(AF2,LoanLevelHist!B:D,2,0) -> #N/A | AI2: 0.0060496179 | AJ2: =VLOOKUP(AF2,'v1'!AB:AD,3,0) -> 0.004866125
A3: [2,] | B3: 40544 | C3: 2.8515888 | D3: 2.82317 | E3: =VLOOKUP(B3,'v1'!B:D,3,0) -> 2.1791283 | G3: [2,] | H3: 40544 | I3: 2.854404 | J3: 2.8319582 | K3: =VLOOKUP(H3,'v1'!H:J,3,0) -> 2.1831644 | M3: [2,] | N3: 40544 | O3: 2.532783 | P3: 0.58793915 | Q3: =VLOOKUP(N3,'v1'!M:O,3,0) -> 0.3182789 | S3: [2,] | T3: 40544 | U3: 2.0846884 | V3: 0.6998709 | W3: =VLOOKUP(T3,'v1'!R:T,3,0) -> 1.4034489 | Y3: [2,] | Z3: 41122 | AA3: 0 | AB3: 0.02317497 | AC3: =VLOOKUP(Z3,'v1'!W:Y,3,0) -> 0.45887599 | AE3: [2,] | AF3: 34366 | AG3: 0 | AH3: =VLOOKUP(AF3,LoanLevelHist!B:D,2,0) -> #N/A | AI3: =VLOOKUP(AF3,LoanLevelHist!B:D,3,0) -> #N/A | AJ3: =VLOOKUP(AF3,'v1'!AB:AD,3,0) -> 0.21411522
A4: [3,] | B4: 40575 | C4: 3.0092574 | D4: 2.7285569 | E4: =VLOOKUP(B4,'v1'!B:D,3,0) -> 2.2621515 | G4: [3,] | H4: 40575 | I4: 3.0184761 | J4: 2.7390463 | K4: =VLOOKUP(H4,'v1'!H:J,3,0) -> 2.2672433 | M4: [3,] | N4: 40575 | O4: 0 | P4: 0.34360158 | Q4: =VLOOKUP(N4,'v1'!M:O,3,0) -> 0.23491254 | S4: [3,] | T4: 40575 | U4: 1.4608418 | V4: 0.65048797 | W4: =VLOOKUP(T4,'v1'!R:T,3,0) -> 1.5226294 | Y4: [3,] | Z4: 41153 | AA4: 0 | AB4: 0.036082095 | AC4: =VLOOKUP(Z4,'v1'!W:Y,3,0) -> 0.63430868 | AE4: [3,] | AF4: 34394 | AG4: 0 | AH4: =VLOOKUP(AF4,LoanLevelHist!B:D,2,0) -> #N/A | AI4: =VLOOKUP(AF4,LoanLevelHist!B:D,3,0) -> #N/A | AJ4: =VLOOKUP(AF4,'v1'!AB:AD,3,0) -> 0.21726305
A5: [4,] | B5: 40603 | C5: 2.5804835 | D5: 2.7581857 | E5: =VLOOKUP(B5,'v1'!B:D,3,0) -> 2.3374511 | G5: [4,] | H5: 40603 | I5: 2.591815 | J5: 2.7729217 | K5: =VLOOKUP(H5,'v1'!H:J,3,0) -> 2.3459676 | M5: [4,] | N5: 40603 | O5: 0 | P5: 0.18431978 | Q5: =VLOOKUP(N5,'v1'!M:O,3,0) -> 0.13124103 | S5: [4,] | T5: 40603 | U5: 1.3464863 | V5: 0.75332099 | W5: =VLOOKUP(T5,'v1'!R:T,3,0) -> 1.5476715 | Y5: [4,] | Z5: 41183 | AA5: 0.65312716 | AB5: 0.085295921 | AC5: =VLOOKUP(Z5,'v1'!W:Y,3,0) -> 0.82961526 | AE5: [4,] | AF5: 34486 | AG5: 0 | AH5: =VLOOKUP(AF5,LoanLevelHist!B:D,2,0) -> #N/A | AI5: =VLOOKUP(AF5,LoanLevelHist!B:D,3,0) -> #N/A | AJ5: =VLOOKUP(AF5,'v1'!AB:AD,3,0) -> 0.014112837
A6: [5,] | B6: 40634 | C6: 2.2254604 | D6: 2.7331746 | E6: =VLOOKUP(B6,'v1'!B:D,3,0) -> 2.2796873 | G6: [5,] | H6: 40634 | I6: 2.2371486 | J6: 2.7497235 | K6: =VLOOKUP(H6,'v1'!H:J,3,0) -> 2.2890867 | M6: [5,] | N6: 40634 | O6: 0.22696274 | P6: 0.18148117 | Q6: =VLOOKUP(N6,'v1'!M:O,3,0) -> 0.11974373 | S6: [5,] | T6: 40634 | U6: 0.98139408 | V6: 0.82704133 | W6: =VLOOKUP(T6,'v1'!R:T,3,0) -> 1.5496788 | Y6: [5,] | Z6: 41214 | AA6: 0.4869495 | AB6: 0.16871336 | AC6: =VLOOKUP(Z6,'v1'!W:Y,3,0) -> 1.0406365 | AE6: [5,] | AF6: 34516 | AG6: 0 | AH6: =VLOOKUP(AF6,LoanLevelHist!B:D,2,0) -> #N/A | AI6: =VLOOKUP(AF6,LoanLevelHist!B:D,3,0) -> #N/A | AJ6: =VLOOKUP(AF6,'v1'!AB:AD,3,0) -> 0.24276857
A7: [6,] | B7: 40664 | C7: 2.135774 | D7: 2.2432498 | E7: =VLOOKUP(B7,'v1'!B:D,3,0) -> 2.2326217 | G7: [6,] | H7: 40664 | I7: 2.1435584 | J7: 2.2578805 | K7: =VLOOKUP(H7,'v1'!H:J,3,0) -> 2.2427195 | M7: [6,] | N7: 40664 | O7: 0.41511956 | P7: 0.12099501 | Q7: =VLOOKUP(N7,'v1'!M:O,3,0) -> 0.10884532 | S7: [6,] | T7: 40664 | U7: 1.710417 | V7: 0.85858716 | W7: =VLOOKUP(T7,'v1'!R:T,3,0) -> 1.622068 | Y7: [6,] | Z7: 41244 | AA7: 0.89675317 | AB7: 0.19412908 | AC7: =VLOOKUP(Z7,'v1'!W:Y,3,0) -> 1.2221443 | AE7: [6,] | AF7: 34547 | AG7: 0 | AH7: =VLOOKUP(AF7,LoanLevelHist!B:D,2,0) -> #N/A | AI7: =VLOOKUP(AF7,LoanLevelHist!B:D,3,0) -> #N/A | AJ7: =VLOOKUP(AF7,'v1'!AB:AD,3,0) -> 0.25454949
A8: [7,] | B8: 40695 | C8: 2.1134526 | D8: 2.2867877 | E8: =VLOOKUP(B8,'v1'!B:D,3,0) -> 2.233831 | G8: [7,] | H8: 40695 | I8: 2.1173279 | J8: 2.3033898 | K8: =VLOOKUP(H8,'v1'!H:J,3,0) -> 2.2447437 | M8: [7,] | N8: 40695 | O8: 0.14997256 | P8: 0.10474321 | Q8: =VLOOKUP(N8,'v1'!M:O,3,0) -> 0.096631916 | S8: [7,] | T8: 40695 | U8: 2.6223028 | V8: 0.91567293 | W8: =VLOOKUP(T8,'v1'!R:T,3,0) -> 1.7372122 | Y8: [7,] | Z8: 41275 | AA8: 0.8899795 | AB8: 0.27511906 | AC8: =VLOOKUP(Z8,'v1'!W:Y,3,0) -> 1.4605462 | AE8: [7,] | AF8: 34578 | AG8: 0 | AH8: =VLOOKUP(AF8,LoanLevelHist!B:D,2,0) -> #N/A | AI8: =VLOOKUP(AF8,LoanLevelHist!B:D,3,0) -> #N/A | AJ8: =VLOOKUP(AF8,'v1'!AB:AD,3,0) -> 0.26680185
A9: [8,] | B9: 40725 | C9: 2.076756 | D9: 2.233238 | E9: =VLOOKUP(B9,'v1'!B:D,3,0) -> 2.1894364 | G9: [8,] | H9: 40725 | I9: 2.0846664 | J9: 2.2516074 | K9: =VLOOKUP(H9,'v1'!H:J,3,0) -> 2.2009849 | M9: [8,] | N9: 40725 | O9: 0.29877672 | P9: 0.10395251 | Q9: =VLOOKUP(N9,'v1'!M:O,3,0) -> 0.08972298 | S9: [8,] | T9: 40725 | U9: 2.0476761 | V9: 0.90520133 | W9: =VLOOKUP(T9,'v1'!R:T,3,0) -> 1.834349 | Y9: [8,] | Z9: 41306 | AA9: 1.1800204 | AB9: 0.39214765 | AC9: =VLOOKUP(Z9,'v1'!W:Y,3,0) -> 1.6776543 | AE9: [8,] | AF9: 34608 | AG9: 0 | AH9: =VLOOKUP(AF9,LoanLevelHist!B:D,2,0) -> #N/A | AI9: =VLOOKUP(AF9,LoanLevelHist!B:D,3,0) -> #N/A | AJ9: =VLOOKUP(AF9,'v1'!AB:AD,3,0) -> 0.28058556
A10: [9,] | B10: 40756 | C10: 2.0678545 | D10: 2.2390494 | E10: =VLOOKUP(B10,'v1'!B:D,3,0) -> 2.1524204 | G10: [9,] | H10: 40756 | I10: 2.0767136 | J10: 2.2590409 | K10: =VLOOKUP(H10,'v1'!H:J,3,0) -> 2.1637331 | M10: [9,] | N10: 40756 | O10: 0.13344405 | P10: 0.079177911 | Q10: =VLOOKUP(N10,'v1'!M:O,3,0) -> 0.08973857 | S10: [9,] | T10: 40756 | U10: 2.1192492 | V10: 0.92842975 | W10: =VLOOKUP(T10,'v1'!R:T,3,0) -> 1.9552517 | Y10: [9,] | Z10: 41334 | AA10: 1.2525012 | AB10: 0.43687481 | AC10: =VLOOKUP(Z10,'v1'!W:Y,3,0) -> 1.8897288 | AE10: [9,] | AF10: 34639 | AG10: 0 | AH10: =VLOOKUP(AF10,LoanLevelHist!B:D,2,0) -> #N/A | AI10: =VLOOKUP(AF10,LoanLevelHist!B:D,3,0) -> #N/A | AJ10: =VLOOKUP(AF10,'v1'!AB:AD,3,0) -> 0.29522473
A11: [10,] | B11: 40787 | C11: 2.1195307 | D11: 2.3750611 | E11: =VLOOKUP(B11,'v1'!B:D,3,0) -> 2.1118378 | G11: [10,] | H11: 40787 | I11: 2.1306944 | J11: 2.3968835 | K11: =VLOOKUP(H11,'v1'!H:J,3,0) -> 2.1226307 | M11: [10,] | N11: 40787 | O11: 0.19410047 | P11: 0.080473676 | Q11: =VLOOKUP(N11,'v1'!M:O,3,0) -> 0.090452568 | S11: [10,] | T11: 40787 | U11: 1.968303 | V11: 1.1143114 | W11: =VLOOKUP(T11,'v1'!R:T,3,0) -> 2.0691216 | Y11: [10,] | Z11: 41365 | AA11: 1.1485688 | AB11: 0.53783751 | AC11: =VLOOKUP(Z11,'v1'!W:Y,3,0) -> 2.0516141 | AE11: [10,] | AF11: 34669 | AG11: 0 | AH11: =VLOOKUP(AF11,LoanLevelHist!B:D,2,0) -> #N/A | AI11: =VLOOKUP(AF11,LoanLevelHist!B:D,3,0) -> #N/A | AJ11: =VLOOKUP(AF11,'v1'!AB:AD,3,0) -> 0.3115286
A12: [11,] | B12: 40817 | C12: 2.1812705 | D12: 2.2778317 | E12: =VLOOKUP(B12,'v1'!B:D,3,0) -> 2.1322872 | G12: [11,] | H12: 40817 | I12: 2.1940196 | J12: 2.299231 | K12: =VLOOKUP(H12,'v1'!H:J,3,0) -> 2.1427486 | M12: [11,] | N12: 40817 | O12: 0.080194662 | P12: 0.06295567 | Q12: =VLOOKUP(N12,'v1'!M:O,3,0) -> 0.095590107 | S12: [11,] | T12: 40817 | U12: 2.0323255 | V12: 1.1819815 | W12: =VLOOKUP(T12,'v1'!R:T,3,0) -> 2.2106295 | Y12: [11,] | Z12: 41395 | AA12: 1.1727388 | AB12: 0.55973916 | AC12: =VLOOKUP(Z12,'v1'!W:Y,3,0) -> 2.2291296 | AE12: [11,] | AF12: 34700 | AG12: 0 | AH12: =VLOOKUP(AF12,LoanLevelHist!B:D,2,0) -> #N/A | AI12: =VLOOKUP(AF12,LoanLevelHist!B:D,3,0) -> #N/A | AJ12: =VLOOKUP(AF12,'v1'!AB:AD,3,0) -> 0.32733927
A13: [12,] | B13: 40848 | C13: 2.2641557 | D13: 2.286494 | E13: =VLOOKUP(B13,'v1'!B:D,3,0) -> 2.1564726 | G13: [12,] | H13: 40848 | I13: 2.2744068 | J13: 2.3089495 | K13: =VLOOKUP(H13,'v1'!H:J,3,0) -> 2.167375 | M13: [12,] | N13: 40848 | O13: 0 | P13: 0.051645098 | Q13: =VLOOKUP(N13,'v1'!M:O,3,0) -> 0.093902772 | S13: [12,] | T13: 40848 | U13: 2.7040705 | V13: 1.3576979 | W13: =VLOOKUP(T13,'v1'!R:T,3,0) -> 2.3867472 | Y13: [12,] | Z13: 41426 | AA13: 1.3703528 | AB13: 0.61222248 | AC13: =VLOOKUP(Z13,'v1'!W:Y,3,0) -> 2.4255927 | AE13: [12,] | AF13: 34731 | AG13: 0 | AH13: =VLOOKUP(AF13,LoanLevelHist!B:D,2,0) -> #N/A | AI13: =VLOOKUP(AF13,LoanLevelHist!B:D,3,0) -> #N/A | AJ13: =VLOOKUP(AF13,'v1'!AB:AD,3,0) -> 0.3425625
A14: [13,] | B14: 40878 | C14: 2.3807445 | D14: 2.313779 | E14: =VLOOKUP(B14,'v1'!B:D,3,0) -> 2.1827696 | G14: [13,] | H14: 40878 | I14: 2.3940326 | J14: 2.3380659 | K14: =VLOOKUP(H14,'v1'!H:J,3,0) -> 2.1939264 | M14: [13,] | N14: 40878 | O14: 0.22313284 | P14: 0.06447863 | Q14: =VLOOKUP(N14,'v1'!M:O,3,0) -> 0.095957643 | S14: [13,] | T14: 40878 | U14: 2.5757107 | V14: 1.4348664 | W14: =VLOOKUP(T14,'v1'!R:T,3,0) -> 2.5465637 | Y14: [13,] | Z14: 41456 | AA14: 1.3858494 | AB14: 0.66433992 | AC14: =VLOOKUP(Z14,'v1'!W:Y,3,0) -> 2.6571552 | AE14: [13,] | AF14: 34759 | AG14: 0 | AH14: =VLOOKUP(AF14,LoanLevelHist!B:D,2,0) -> #N/A | AI14: =VLOOKUP(AF14,LoanLevelHist!B:D,3,0) -> #N/A | AJ14: =VLOOKUP(AF14,'v1'!AB:AD,3,0) -> 0.35751292
... A45: [44,] | B45: 41821 | C45: 0.71890987 | D45: 0.78938625 | E45: =VLOOKUP(B45,'v1'!B:D,3,0) -> 0.93889907 | G45: [44,] | H45: 41821 | I45: 0.69287565 | J45: 0.7727467 | K45: =VLOOKUP(H45,'v1'!H:J,3,0) -> 0.74684527 | M45: [44,] | N45: 41821 | O45: 0.089049625 | P45: 0.072447388 | Q45: =VLOOKUP(N45,'v1'!M:O,3,0) -> 0.15965077 | S45: [44,] | T45: 41821 | U45: 1.1971972 | V45: 1.212151 | W45: =VLOOKUP(T45,'v1'!R:T,3,0) -> 2.4360087 | Y45: [44,] | Z45: 42401 | AA45: 1.4464891 | AB45: 1.9589249 | AC45: =VLOOKUP(Z45,'v1'!W:Y,3,0) -> 11.364858 | AE45: [44,] | AF45: 35765 | AG45: 0 | AH45: =VLOOKUP(AF45,LoanLevelHist!B:D,2,0) -> #N/A | AI45: =VLOOKUP(AF45,LoanLevelHist!B:D,3,0) -> #N/A | AJ45: =VLOOKUP(AF45,'v1'!AB:AD,3,0) -> 0.55451885
A46: [45,] | B46: 41852 | C46: 0.74288919 | D46: 0.79519371 | E46: =VLOOKUP(B46,'v1'!B:D,3,0) -> 0.94145507 | G46: [45,] | H46: 41852 | I46: 0.71117159 | J46: 0.7713338 | K46: =VLOOKUP(H46,'v1'!H:J,3,0) -> 0.73820704 | M46: [45,] | N46: 41852 | O46: 0.11911886 | P46: 0.074359051 | Q46: =VLOOKUP(N46,'v1'!M:O,3,0) -> 0.16591988 | S46: [45,] | T46: 41852 | U46: 1.2960073 | V46: 1.3452822 | W46: =VLOOKUP(T46,'v1'!R:T,3,0) -> 2.5214116 | AE46: [45,] | AF46: 35796 | AG46: 0 | AH46: =VLOOKUP(AF46,LoanLevelHist!B:D,2,0) -> #N/A | AI46: =VLOOKUP(AF46,LoanLevelHist!B:D,3,0) -> #N/A | AJ46: =VLOOKUP(AF46,'v1'!AB:AD,3,0) -> 0.55100098
A47: [46,] | B47: 41883 | C47: 0.72468512 | D47: 0.76693717 | E47: =VLOOKUP(B47,'v1'!B:D,3,0) -> 0.9335229 | G47: [46,] | H47: 41883 | I47: 0.69269283 | J47: 0.74063961 | K47: =VLOOKUP(H47,'v1'!H:J,3,0) -> 0.72280787 | M47: [46,] | N47: 41883 | O47: 0.082103125 | P47: 0.071561255 | Q47: =VLOOKUP(N47,'v1'!M:O,3,0) -> 0.16965118 | S47: [46,] | T47: 41883 | U47: 1.3282972 | V47: 1.3445969 | W47: =VLOOKUP(T47,'v1'!R:T,3,0) -> 2.537318 | AE47: [46,] | AF47: 35827 | AG47: 0 | AH47: =VLOOKUP(AF47,LoanLevelHist!B:D,2,0) -> #N/A | AI47: =VLOOKUP(AF47,LoanLevelHist!B:D,3,0) -> #N/A | AJ47: =VLOOKUP(AF47,'v1'!AB:AD,3,0) -> 0.55453178
A48: [47,] | B48: 41913 | C48: 0.72620129 | D48: 0.84637329 | E48: =VLOOKUP(B48,'v1'!B:D,3,0) -> 0.93906527 | G48: [47,] | H48: 41913 | I48: 0.68970529 | J48: 0.81327714 | K48: =VLOOKUP(H48,'v1'!H:J,3,0) -> 0.71677494 | M48: [47,] | N48: 41913 | O48: 0.048598743 | P48: 0.089238147 | Q48: =VLOOKUP(N48,'v1'!M:O,3,0) -> 0.17523445 | S48: [47,] | T48: 41913 | U48: 1.3058516 | V48: 1.510781 | W48: =VLOOKUP(T48,'v1'!R:T,3,0) -> 2.6423744 | AE48: [47,] | AF48: 35855 | AG48: 0 | AH48: =VLOOKUP(AF48,LoanLevelHist!B:D,2,0) -> #N/A | AI48: =VLOOKUP(AF48,LoanLevelHist!B:D,3,0) -> #N/A | AJ48: =VLOOKUP(AF48,'v1'!AB:AD,3,0) -> 0.55230636
A49: [48,] | B49: 41944 | C49: 0.68886207 | D49: 0.78431743 | E49: =VLOOKUP(B49,'v1'!B:D,3,0) -> 0.94433406 | G49: [48,] | H49: 41944 | I49: 0.65397914 | J49: 0.74967403 | K49: =VLOOKUP(H49,'v1'!H:J,3,0) -> 0.7108191 | M49: [48,] | N49: 41944 | O49: 0.11785444 | P49: 0.077850527 | Q49: =VLOOKUP(N49,'v1'!M:O,3,0) -> 0.18075821 | S49: [48,] | T49: 41944 | U49: 1.3450918 | V49: 1.4833033 | W49: =VLOOKUP(T49,'v1'!R:T,3,0) -> 2.7450738 | AE49: [48,] | AF49: 35886 | AG49: 0 | AH49: =VLOOKUP(AF49,LoanLevelHist!B:D,2,0) -> #N/A | AI49: =VLOOKUP(AF49,LoanLevelHist!B:D,3,0) -> #N/A | AJ49: =VLOOKUP(AF49,'v1'!AB:AD,3,0) -> 0.53957985
A50: [49,] | B50: 41974 | C50: 0.73175021 | D50: 0.72213247 | E50: =VLOOKUP(B50,'v1'!B:D,3,0) -> 0.95249545 | G50: [49,] | H50: 41974 | I50: 0.69831895 | J50: 0.68597469 | K50: =VLOOKUP(H50,'v1'!H:J,3,0) -> 0.70744131 | M50: [49,] | N50: 41974 | O50: 0.026388849 | P50: 0.06886601 | Q50: =VLOOKUP(N50,'v1'!M:O,3,0) -> 0.1864728 | S50: [49,] | T50: 41974 | U50: 1.346327 | V50: 1.4196072 | W50: =VLOOKUP(T50,'v1'!R:T,3,0) -> 2.8510892 | AE50: [49,] | AF50: 35916 | AG50: 0 | AH50: =VLOOKUP(AF50,LoanLevelHist!B:D,2,0) -> #N/A | AI50: =VLOOKUP(AF50,LoanLevelHist!B:D,3,0) -> #N/A | AJ50: =VLOOKUP(AF50,'v1'!AB:AD,3,0) -> 0.5256341
A51: [50,] | B51: 42005 | C51: 0.687607 | D51: 0.87545112 | E51: =VLOOKUP(B51,'v1'!B:D,3,0) -> 0.95646479 | G51: [50,] | H51: 42005 | I51: 0.64969268 | J51: 0.8276562 | K51: =VLOOKUP(H51,'v1'!H:J,3,0) -> 0.70160083 | M51: [50,] | N51: 42005 | O51: 0.085151275 | P51: 0.10842619 | Q51: =VLOOKUP(N51,'v1'!M:O,3,0) -> 0.19050565 | S51: [50,] | T51: 42005 | U51: 1.3409663 | V51: 1.7658003 | W51: =VLOOKUP(T51,'v1'!R:T,3,0) -> 2.9205375 | AE51: [50,] | AF51: 35947 | AG51: 0 | AH51: =VLOOKUP(AF51,LoanLevelHist!B:D,2,0) -> #N/A | AI51: =VLOOKUP(AF51,LoanLevelHist!B:D,3,0) -> #N/A | AJ51: =VLOOKUP(AF51,'v1'!AB:AD,3,0) -> 0.51556978
A52: [51,] | B52: 42036 | C52: 0.69063 | D52: 0.74022149 | E52: =VLOOKUP(B52,'v1'!B:D,3,0) -> 0.96136132 | G52: [51,] | H52: 42036 | I52: 0.64380936 | J52: 0.69793541 | K52: =VLOOKUP(H52,'v1'!H:J,3,0) -> 0.69745946 | M52: [51,] | N52: 42036 | O52: 0.13158484 | P52: 0.085880329 | Q52: =VLOOKUP(N52,'v1'!M:O,3,0) -> 0.19511252 | S52: [51,] | T52: 42036 | U52: 1.4401413 | V52: 1.5271917 | W52: =VLOOKUP(T52,'v1'!R:T,3,0) -> 2.9859048 | AE52: [51,] | AF52: 35977 | AG52: 0 | AH52: =VLOOKUP(AF52,LoanLevelHist!B:D,2,0) -> #N/A | AI52: =VLOOKUP(AF52,LoanLevelHist!B:D,3,0) -> #N/A | AJ52: =VLOOKUP(AF52,'v1'!AB:AD,3,0) -> 0.50544418
A53: [52,] | B53: 42064 | C53: 0.62462778 | D53: 0.76113451 | E53: =VLOOKUP(B53,'v1'!B:D,3,0) -> 0.96425929 | G53: [52,] | H53: 42064 | I53: 0.58813601 | J53: 0.69828725 | K53: =VLOOKUP(H53,'v1'!H:J,3,0) -> 0.69201004 | M53: [52,] | N53: 42064 | O53: 0.093392531 | P53: 0.071997186 | Q53: =VLOOKUP(N53,'v1'!M:O,3,0) -> 0.20065168 | S53: [52,] | T53: 42064 | U53: 1.1949048 | V53: 1.795876 | W53: =VLOOKUP(T53,'v1'!R:T,3,0) -> 3.052645 | AE53: [52,] | AF53: 36008 | AG53: 0 | AH53: =VLOOKUP(AF53,LoanLevelHist!B:D,2,0) -> #N/A | AI53: =VLOOKUP(AF53,LoanLevelHist!B:D,3,0) -> #N/A | AJ53: =VLOOKUP(AF53,'v1'!AB:AD,3,0) -> 0.49552463
A54: [53,] | B54: 42095 | C54: 0.53754335 | D54: 0.7522321 | E54: =VLOOKUP(B54,'v1'!B:D,3,0) -> 0.94547493 | G54: [53,] | H54: 42095 | I54: 0.50731464 | J54: 0.70445331 | K54: =VLOOKUP(H54,'v1'!H:J,3,0) -> 0.6739559 | M54: [53,] | N54: 42095 | O54: 0.067893245 | P54: 0.090200274 | Q54: =VLOOKUP(N54,'v1'!M:O,3,0) -> 0.19886911 | S54: [53,] | T54: 42095 | U54: 1.1920219 | V54: 1.6187614 | W54: =VLOOKUP(T54,'v1'!R:T,3,0) -> 2.9182594 | AE54: [53,] | AF54: 36039 | AG54: 0 | AH54: =VLOOKUP(AF54,LoanLevelHist!B:D,2,0) -> #N/A | AI54: =VLOOKUP(AF54,LoanLevelHist!B:D,3,0) -> #N/A | AJ54: =VLOOKUP(AF54,'v1'!AB:AD,3,0) -> 0.48977749
A55: [54,] | B55: 42125 | C55: 0.51417879 | D55: 0.59652914 | E55: =VLOOKUP(B55,'v1'!B:D,3,0) -> 0.92029304 | G55: [54,] | H55: 42125 | I55: 0.48334305 | J55: 0.55924288 | K55: =VLOOKUP(H55,'v1'!H:J,3,0) -> 0.65134723 | M55: [54,] | N55: 42125 | O55: 0.076871349 | P55: 0.079032992 | Q55: =VLOOKUP(N55,'v1'!M:O,3,0) -> 0.19862347 | S55: [54,] | T55: 42125 | U55: 1.0176029 | V55: 1.2864559 | W55: =VLOOKUP(T55,'v1'!R:T,3,0) -> 2.796801 | AE55: [54,] | AF55: 36069 | AG55: 0 | AH55: =VLOOKUP(AF55,LoanLevelHist!B:D,2,0) -> #N/A | AI55: =VLOOKUP(AF55,LoanLevelHist!B:D,3,0) -> #N/A | AJ55: =VLOOKUP(AF55,'v1'!AB:AD,3,0) -> 0.48582652
A56: [55,] | B56: 42156 | C56: 0.47831995 | D56: 0.58402859 | E56: =VLOOKUP(B56,'v1'!B:D,3,0) -> 0.89587108 | G56: [55,] | H56: 42156 | I56: 0.44822073 | J56: 0.54618333 | K56: =VLOOKUP(H56,'v1'!H:J,3,0) -> 0.63025236 | M56: [55,] | N56: 42156 | O56: 0.020595158 | P56: 0.080589603 | Q56: =VLOOKUP(N56,'v1'!M:O,3,0) -> 0.19580512 | S56: [55,] | T56: 42156 | U56: 1.1365317 | V56: 1.2654745 | W56: =VLOOKUP(T56,'v1'!R:T,3,0) -> 2.6866429 | AE56: [55,] | AF56: 36100 | AG56: 0 | AH56: =VLOOKUP(AF56,LoanLevelHist!B:D,2,0) -> #N/A | AI56: =VLOOKUP(AF56,LoanLevelHist!B:D,3,0) -> #N/A | AJ56: =VLOOKUP(AF56,'v1'!AB:AD,3,0) -> 0.47617635
A57: [56,] | B57: 42186 | C57: 0.46056295 | D57: 0.63896663 | E57: =VLOOKUP(B57,'v1'!B:D,3,0) -> 0.88740404 | G57: [56,] | H57: 42186 | I57: 0.4219143 | J57: 0.595746 | K57: =VLOOKUP(H57,'v1'!H:J,3,0) -> 0.61883731 | M57: [56,] | N57: 42186 | O57: 0.081415183 | P57: 0.10400208 | Q57: =VLOOKUP(N57,'v1'!M:O,3,0) -> 0.19643845 | S57: [56,] | T57: 42186 | U57: 1.2301638 | V57: 1.4288774 | W57: =VLOOKUP(T57,'v1'!R:T,3,0) -> 2.7054653 | AE57: [56,] | AF57: 36130 | AG57: 0 | AH57: =VLOOKUP(AF57,LoanLevelHist!B:D,2,0) -> #N/A | AI57: =VLOOKUP(AF57,LoanLevelHist!B:D,3,0) -> #N/A | AJ57: =VLOOKUP(AF57,'v1'!AB:AD,3,0) -> 0.46307804
... A64: [63,] | B64: 42401 | C64: 0.48709674 | D64: 0.56516064 | E64: =VLOOKUP(B64,'v1'!B:D,3,0) -> 0.89593135 | G64: [63,] | H64: 42401 | I64: 0.45481421 | J64: 0.51757121 | K64: =VLOOKUP(H64,'v1'!H:J,3,0) -> 0.60158013 | M64: [63,] | N64: 42401 | O64: 0.11530497 | P64: 0.10181188 | Q64: =VLOOKUP(N64,'v1'!M:O,3,0) -> 0.23793581 | S64: [63,] | T64: 42401 | U64: 1.1764374 | V64: 1.5193867 | W64: =VLOOKUP(T64,'v1'!R:T,3,0) -> 3.1382257 | AE64: [63,] | AF64: 36342 | AG64: 0 | AH64: =VLOOKUP(AF64,LoanLevelHist!B:D,2,0) -> 0.029062142 | AI64: =VLOOKUP(AF64,LoanLevelHist!B:D,3,0) -> 0.0059149776 | AJ64: =VLOOKUP(AF64,'v1'!AB:AD,3,0) -> 0.41225808
AE65: [64,] | AF65: 36373 | AG65: 0 | AH65: =VLOOKUP(AF65,LoanLevelHist!B:D,2,0) -> 0.060712974 | AI65: =VLOOKUP(AF65,LoanLevelHist!B:D,3,0) -> 0.011474892 | AJ65: =VLOOKUP(AF65,'v1'!AB:AD,3,0) -> 0.41238628
AE66: [65,] | AF66: 36404 | AG66: 0 | AH66: =VLOOKUP(AF66,LoanLevelHist!B:D,2,0) -> 0.06583242 | AI66: =VLOOKUP(AF66,LoanLevelHist!B:D,3,0) -> 0.019012124 | AJ66: =VLOOKUP(AF66,'v1'!AB:AD,3,0) -> 0.41493057
AE67: [66,] | AF67: 36434 | AG67: 0 | AH67: =VLOOKUP(AF67,LoanLevelHist!B:D,2,0) -> 0.082015385 | AI67: =VLOOKUP(AF67,LoanLevelHist!B:D,3,0) -> 0.037969088 | AJ67: =VLOOKUP(AF67,'v1'!AB:AD,3,0) -> 0.41938624
AE68: [67,] | AF68: 36465 | AG68: 0 | AH68: =VLOOKUP(AF68,LoanLevelHist!B:D,2,0) -> 0.082767818 | AI68: =VLOOKUP(AF68,LoanLevelHist!B:D,3,0) -> 0.066280295 | AJ68: =VLOOKUP(AF68,'v1'!AB:AD,3,0) -> 0.4262688
AE69: [68,] | AF69: 36495 | AG69: 0 | AH69: =VLOOKUP(AF69,LoanLevelHist!B:D,2,0) -> 0.13170375 | AI69: =VLOOKUP(AF69,LoanLevelHist!B:D,3,0) -> 0.10742569 | AJ69: =VLOOKUP(AF69,'v1'!AB:AD,3,0) -> 0.4341158
AE70: [69,] | AF70: 36526 | AG70: 0 | AH70: =VLOOKUP(AF70,LoanLevelHist!B:D,2,0) -> 0.14161341 | AI70: =VLOOKUP(AF70,LoanLevelHist!B:D,3,0) -> 0.13743869 | AJ70: =VLOOKUP(AF70,'v1'!AB:AD,3,0) -> 0.44070557
AE71: [70,] | AF71: 36557 | AG71: 0 | AH71: =VLOOKUP(AF71,LoanLevelHist!B:D,2,0) -> 0.21005513 | AI71: =VLOOKUP(AF71,LoanLevelHist!B:D,3,0) -> 0.17423998 | AJ71: =VLOOKUP(AF71,'v1'!AB:AD,3,0) -> 0.44388874
AE72: [71,] | AF72: 36586 | AG72: 0 | AH72: =VLOOKUP(AF72,LoanLevelHist!B:D,2,0) -> 0.2208505 | AI72: =VLOOKUP(AF72,LoanLevelHist!B:D,3,0) -> 0.23288934 | AJ72: =VLOOKUP(AF72,'v1'!AB:AD,3,0) -> 0.45139982
AE73: [72,] | AF73: 36617 | AG73: 0 | AH73: =VLOOKUP(AF73,LoanLevelHist!B:D,2,0) -> 0.21403561 | AI73: =VLOOKUP(AF73,LoanLevelHist!B:D,3,0) -> 0.21727731 | AJ73: =VLOOKUP(AF73,'v1'!AB:AD,3,0) -> 0.4591474
AE74: [73,] | AF74: 36647 | AG74: 0 | AH74: =VLOOKUP(AF74,LoanLevelHist!B:D,2,0) -> 0.19625704 | AI74: =VLOOKUP(AF74,LoanLevelHist!B:D,3,0) -> 0.29800504 | AJ74: =VLOOKUP(AF74,'v1'!AB:AD,3,0) -> 0.46609717
AE75: [74,] | AF75: 36678 | AG75: 0 | AH75: =VLOOKUP(AF75,LoanLevelHist!B:D,2,0) -> 0.19105319 | AI75: =VLOOKUP(AF75,LoanLevelHist!B:D,3,0) -> 0.29621499 | AJ75: =VLOOKUP(AF75,'v1'!AB:AD,3,0) -> 0.47089258
AE76: [75,] | AF76: 36708 | AG76: 0 | AH76: =VLOOKUP(AF76,LoanLevelHist!B:D,2,0) -> 0.22355436 | AI76: =VLOOKUP(AF76,LoanLevelHist!B:D,3,0) -> 0.34150888 | AJ76: =VLOOKUP(AF76,'v1'!AB:AD,3,0) -> 0.47510527
...

Sheet v2
A1: Overall | B1: x_vals | C1: y_vals.act | D1: v2 | E1: v1 | G1: Conventional | H1: x_vals | I1: y_vals.act | J1: v2 | K1: v1 | M1: Jumbo | N1: x_vals | O1: y_vals.act | P1: v2 | Q1: v1 | S1: CQ | T1: x_vals | U1: y_vals.act | V1: v2 | W1: v1 | Y1: CR | Z1: x_vals | AA1: y_vals.act | AB1: v2 | AC1: v1 | AE1: History | AF1: x_vals | AG1: y_vals.act | AH1: Actual | AI1: v2 | AJ1: v1
A2: [1,] | B2: 40513 | C2: 2.9403271 | D2: 2.1789337 | E2: =VLOOKUP(B2,'v1'!B:D,3,0) -> 2.1523348 | G2: [1,] | H2: 40513 | I2: 2.9436942 | J2: 2.1837727 | K2: =VLOOKUP(H2,'v1'!H:J,3,0) -> 2.1546881 | M2: [1,] | N2: 40513 | O2: 8.7425281 | P2: 0.95424238 | Q2: =VLOOKUP(N2,'v1'!M:O,3,0) -> 0.81217765 | S2: [1,] | T2: 40513 | U2: 1.0463194 | V2: 0.47546789 | W2: =VLOOKUP(T2,'v1'!R:T,3,0) -> 1.4039362 | Y2: [1,] | Z2: 41091 | AA2: 0 | AB2: 0.019407533 | AC2: =VLOOKUP(Z2,'v1'!W:Y,3,0) -> 0.3002854 | AE2: [1,] | AF2: 34335 | AG2: 0 | AH2: =VLOOKUP(AF2,LoanLevelHist!B:D,2,0) -> #N/A | AI2: 0.0060496179 | AJ2: =VLOOKUP(AF2,'v1'!AB:AD,3,0) -> 0.004866125
A3: [2,] | B3: 40544 | C3: 2.8515888 | D3: 3.0633434 | E3: =VLOOKUP(B3,'v1'!B:D,3,0) -> 2.1791283 | G3: [2,] | H3: 40544 | I3: 2.854404 | J3: 3.0736354 | K3: =VLOOKUP(H3,'v1'!H:J,3,0) -> 2.1831644 | M3: [2,] | N3: 40544 | O3: 2.532783 | P3: 0.39519664 | Q3: =VLOOKUP(N3,'v1'!M:O,3,0) -> 0.3182789 | S3: [2,] | T3: 40544 | U3: 2.0846884 | V3: 0.58294191 | W3: =VLOOKUP(T3,'v1'!R:T,3,0) -> 1.4034489 | Y3: [2,] | Z3: 41122 | AA3: 0 | AB3: 0.04816332 | AC3: =VLOOKUP(Z3,'v1'!W:Y,3,0) -> 0.45887599 | AE3: [2,] | AF3: 34366 | AG3: 0 | AH3: =VLOOKUP(AF3,LoanLevelHist!B:D,2,0) -> #N/A | AI3: 0.48688726 | AJ3: =VLOOKUP(AF3,'v1'!AB:AD,3,0) -> 0.21411522
A4: [3,] | B4: 40575 | C4: 3.0092574 | D4: 3.0763807 | E4: =VLOOKUP(B4,'v1'!B:D,3,0) -> 2.2621515 | G4: [3,] | H4: 40575 | I4: 3.0184761 | J4: 3.0887583 | K4: =VLOOKUP(H4,'v1'!H:J,3,0) -> 2.2672433 | M4: [3,] | N4: 40575 | O4: 0 | P4: 0.25489395 | Q4: =VLOOKUP(N4,'v1'!M:O,3,0) -> 0.23491254 | S4: [3,] | T4: 40575 | U4: 1.4608418 | V4: 0.62026705 | W4: =VLOOKUP(T4,'v1'!R:T,3,0) -> 1.5226294 | Y4: [3,] | Z4: 41153 | AA4: 0 | AB4: 0.086499619 | AC4: =VLOOKUP(Z4,'v1'!W:Y,3,0) -> 0.63430868 | AE4: [3,] | AF4: 34394 | AG4: 0 | AH4: =VLOOKUP(AF4,LoanLevelHist!B:D,2,0) -> #N/A | AI4: 0.49171395 | AJ4: =VLOOKUP(AF4,'v1'!AB:AD,3,0) -> 0.21726305
A5: [4,] | B5: 40603 | C5: 2.5804835 | D5: 3.0909954 | E5: =VLOOKUP(B5,'v1'!B:D,3,0) -> 2.3374511 | G5: [4,] | H5: 40603 | I5: 2.591815 | J5: 3.1085472 | K5: =VLOOKUP(H5,'v1'!H:J,3,0) -> 2.3459676 | M5: [4,] | N5: 40603 | O5: 0 | P5: 0.13891763 | Q5: =VLOOKUP(N5,'v1'!M:O,3,0) -> 0.13124103 | S5: [4,] | T5: 40603 | U5: 1.3464863 | V5: 0.63787787 | W5: =VLOOKUP(T5,'v1'!R:T,3,0) -> 1.5476715 | Y5: [4,] | Z5: 41183 | AA5: 0.65312716 | AB5: 0.13095138 | AC5: =VLOOKUP(Z5,'v1'!W:Y,3,0) -> 0.82961526 | AE5: [4,] | AF5: 34486 | AG5: 0 | AH5: =VLOOKUP(AF5,LoanLevelHist!B:D,2,0) -> #N/A | AI5: 0.014352369 | AJ5: =VLOOKUP(AF5,'v1'!AB:AD,3,0) -> 0.014112837
A6: [5,] | B6: 40634 | C6: 2.2254604 | D6: 3.0644642 | E6: =VLOOKUP(B6,'v1'!B:D,3,0) -> 2.2796873 | G6: [5,] | H6: 40634 | I6: 2.2371486 | J6: 3.0846358 | K6: =VLOOKUP(H6,'v1'!H:J,3,0) -> 2.2890867 | M6: [5,] | N6: 40634 | O6: 0.22696274 | P6: 0.12508189 | Q6: =VLOOKUP(N6,'v1'!M:O,3,0) -> 0.11974373 | S6: [5,] | T6: 40634 | U6: 0.98139408 | V6: 0.64923302 | W6: =VLOOKUP(T6,'v1'!R:T,3,0) -> 1.5496788 | Y6: [5,] | Z6: 41214 | AA6: 0.4869495 | AB6: 0.1810008 | AC6: =VLOOKUP(Z6,'v1'!W:Y,3,0) -> 1.0406365 | AE6: [5,] | AF6: 34516 | AG6: 0 | AH6: =VLOOKUP(AF6,LoanLevelHist!B:D,2,0) -> #N/A | AI6: 0.54702956 | AJ6: =VLOOKUP(AF6,'v1'!AB:AD,3,0) -> 0.24276857
A7: [6,] | B7: 40664 | C7: 2.135774 | D7: 2.9898836 | E7: =VLOOKUP(B7,'v1'!B:D,3,0) -> 2.2326217 | G7: [6,] | H7: 40664 | I7: 2.1435584 | J7: 3.0121119 | K7: =VLOOKUP(H7,'v1'!H:J,3,0) -> 2.2427195 | M7: [6,] | N7: 40664 | O7: 0.41511956 | P7: 0.11193749 | Q7: =VLOOKUP(N7,'v1'!M:O,3,0) -> 0.10884532 | S7: [6,] | T7: 40664 | U7: 1.710417 | V7: 0.69058236 | W7: =VLOOKUP(T7,'v1'!R:T,3,0) -> 1.622068 | Y7: [6,] | Z7: 41244 | AA7: 0.89675317 | AB7: 0.22796969 | AC7: =VLOOKUP(Z7,'v1'!W:Y,3,0) -> 1.2221443 | AE7: [6,] | AF7: 34547 | AG7: 0 | AH7: =VLOOKUP(AF7,LoanLevelHist!B:D,2,0) -> #N/A | AI7: 0.57232388 | AJ7: =VLOOKUP(AF7,'v1'!AB:AD,3,0) -> 0.25454949
A8: [7,] | B8: 40695 | C8: 2.1134526 | D8: 2.1803057 | E8: =VLOOKUP(B8,'v1'!B:D,3,0) -> 2.233831 | G8: [7,] | H8: 40695 | I8: 2.1173279 | J8: 2.198028 | K8: =VLOOKUP(H8,'v1'!H:J,3,0) -> 2.2447437 | M8: [7,] | N8: 40695 | O8: 0.14997256 | P8: 0.089934584 | Q8: =VLOOKUP(N8,'v1'!M:O,3,0) -> 0.096631916 | S8: [7,] | T8: 40695 | U8: 2.6223028 | V8: 0.57875714 | W8: =VLOOKUP(T8,'v1'!R:T,3,0) -> 1.7372122 | Y8: [7,] | Z8: 41275 | AA8: 0.8899795 | AB8: 0.28634911 | AC8: =VLOOKUP(Z8,'v1'!W:Y,3,0) -> 1.4605462 | AE8: [7,] | AF8: 34578 | AG8: 0 | AH8: =VLOOKUP(AF8,LoanLevelHist!B:D,2,0) -> #N/A | AI8: 0.5987744 | AJ8: =VLOOKUP(AF8,'v1'!AB:AD,3,0) -> 0.26680185
A9: [8,] | B9: 40725 | C9: 2.076756 | D9: 2.1683789 | E9: =VLOOKUP(B9,'v1'!B:D,3,0) -> 2.1894364 | G9: [8,] | H9: 40725 | I9: 2.0846664 | J9: 2.1880815 | K9: =VLOOKUP(H9,'v1'!H:J,3,0) -> 2.2009849 | M9: [8,] | N9: 40725 | O9: 0.29877672 | P9: 0.082590457 | Q9: =VLOOKUP(N9,'v1'!M:O,3,0) -> 0.08972298 | S9: [8,] | T9: 40725 | U9: 2.0476761 | V9: 0.61825871 | W9: =VLOOKUP(T9,'v1'!R:T,3,0) -> 1.834349 | Y9: [8,] | Z9: 41306 | AA9: 1.1800204 | AB9: 0.33876504 | AC9: =VLOOKUP(Z9,'v1'!W:Y,3,0) -> 1.6776543 | AE9: [8,] | AF9: 34608 | AG9: 0 | AH9: =VLOOKUP(AF9,LoanLevelHist!B:D,2,0) -> #N/A | AI9: 0.62563427 | AJ9: =VLOOKUP(AF9,'v1'!AB:AD,3,0) -> 0.28058556
A10: [9,] | B10: 40756 | C10: 2.0678545 | D10: 2.1616106 | E10: =VLOOKUP(B10,'v1'!B:D,3,0) -> 2.1524204 | G10: [9,] | H10: 40756 | I10: 2.0767136 | J10: 2.1825558 | K10: =VLOOKUP(H10,'v1'!H:J,3,0) -> 2.1637331 | M10: [9,] | N10: 40756 | O10: 0.13344405 | P10: 0.08364079 | Q10: =VLOOKUP(N10,'v1'!M:O,3,0) -> 0.08973857 | S10: [9,] | T10: 40756 | U10: 2.1192492 | V10: 0.66827241 | W10: =VLOOKUP(T10,'v1'!R:T,3,0) -> 1.9552517 | Y10: [9,] | Z10: 41334 | AA10: 1.2525012 | AB10: 0.38776362 | AC10: =VLOOKUP(Z10,'v1'!W:Y,3,0) -> 1.8897288 | AE10: [9,] | AF10: 34639 | AG10: 0 | AH10: =VLOOKUP(AF10,LoanLevelHist!B:D,2,0) -> #N/A | AI10: 0.65458457 | AJ10: =VLOOKUP(AF10,'v1'!AB:AD,3,0) -> 0.29522473
A11: [10,] | B11: 40787 | C11: 2.1195307 | D11: 2.1477006 | E11: =VLOOKUP(B11,'v1'!B:D,3,0) -> 2.1118378 | G11: [10,] | H11: 40787 | I11: 2.1306944 | J11: 2.1696778 | K11: =VLOOKUP(H11,'v1'!H:J,3,0) -> 2.1226307 | M11: [10,] | N11: 40787 | O11: 0.19410047 | P11: 0.083819893 | Q11: =VLOOKUP(N11,'v1'!M:O,3,0) -> 0.090452568 | S11: [10,] | T11: 40787 | U11: 1.968303 | V11: 0.71711799 | W11: =VLOOKUP(T11,'v1'!R:T,3,0) -> 2.0691216 | Y11: [10,] | Z11: 41365 | AA11: 1.1485688 | AB11: 0.42498212 | AC11: =VLOOKUP(Z11,'v1'!W:Y,3,0) -> 2.0516141 | AE11: [10,] | AF11: 34669 | AG11: 0 | AH11: =VLOOKUP(AF11,LoanLevelHist!B:D,2,0) -> #N/A | AI11: 0.68551393 | AJ11: =VLOOKUP(AF11,'v1'!AB:AD,3,0) -> 0.3115286
A12: [11,] | B12: 40817 | C12: 2.1812705 | D12: 2.1646575 | E12: =VLOOKUP(B12,'v1'!B:D,3,0) -> 2.1322872 | G12: [11,] | H12: 40817 | I12: 2.1940196 | J12: 2.1878637 | K12: =VLOOKUP(H12,'v1'!H:J,3,0) -> 2.1427486 | M12: [11,] | N12: 40817 | O12: 0.080194662 | P12: 0.089888964 | Q12: =VLOOKUP(N12,'v1'!M:O,3,0) -> 0.095590107 | S12: [11,] | T12: 40817 | U12: 2.0323255 | V12: 0.7648404 | W12: =VLOOKUP(T12,'v1'!R:T,3,0) -> 2.2106295 | Y12: [11,] | Z12: 41395 | AA12: 1.1727388 | AB12: 0.45798079 | AC12: =VLOOKUP(Z12,'v1'!W:Y,3,0) -> 2.2291296 | AE12: [11,] | AF12: 34700 | AG12: 0 | AH12: =VLOOKUP(AF12,LoanLevelHist!B:D,2,0) -> #N/A | AI12: 0.71773738 | AJ12: =VLOOKUP(AF12,'v1'!AB:AD,3,0) -> 0.32733927
A13: [12,] | B13: 40848 | C13: 2.2641557 | D13: 2.183605 | E13: =VLOOKUP(B13,'v1'!B:D,3,0) -> 2.1564726 | G13: [12,] | H13: 40848 | I13: 2.2744068 | J13: 2.2090625 | K13: =VLOOKUP(H13,'v1'!H:J,3,0) -> 2.167375 | M13: [12,] | N13: 40848 | O13: 0 | P13: 0.089796614 | Q13: =VLOOKUP(N13,'v1'!M:O,3,0) -> 0.093902772 | S13: [12,] | T13: 40848 | U13: 2.7040705 | V13: 0.82233075 | W13: =VLOOKUP(T13,'v1'!R:T,3,0) -> 2.3867472 | Y13: [12,] | Z13: 41426 | AA13: 1.3703528 | AB13: 0.49313106 | AC13: =VLOOKUP(Z13,'v1'!W:Y,3,0) -> 2.4255927 | AE13: [12,] | AF13: 34731 | AG13: 0 | AH13: =VLOOKUP(AF13,LoanLevelHist!B:D,2,0) -> #N/A | AI13: 0.74816648 | AJ13: =VLOOKUP(AF13,'v1'!AB:AD,3,0) -> 0.3425625
... A45: [44,] | B45: 41821 | C45: 0.71890987 | D45: 0.66526278 | E45: =VLOOKUP(B45,'v1'!B:D,3,0) -> 0.93889907 | G45: [44,] | H45: 41821 | I45: 0.69287565 | J45: 0.61922572 | K45: =VLOOKUP(H45,'v1'!H:J,3,0) -> 0.74684527 | M45: [44,] | N45: 41821 | O45: 0.089049625 | P45: 0.13121511 | Q45: =VLOOKUP(N45,'v1'!M:O,3,0) -> 0.15965077 | S45: [44,] | T45: 41821 | U45: 1.1971972 | V45: 1.6425985 | W45: =VLOOKUP(T45,'v1'!R:T,3,0) -> 2.4360087 | Y45: [44,] | Z45: 42401 | AA45: 1.4464891 | AB45: 2.8296875 | AC45: =VLOOKUP(Z45,'v1'!W:Y,3,0) -> 11.364858 | AE45: [44,] | AF45: 35765 | AG45: 0 | AH45: =VLOOKUP(AF45,LoanLevelHist!B:D,2,0) -> #N/A | AI45: 1.1746274 | AJ45: =VLOOKUP(AF45,'v1'!AB:AD,3,0) -> 0.55451885
A46: [45,] | B46: 41852 | C46: 0.74288919 | D46: 0.65182191 | E46: =VLOOKUP(B46,'v1'!B:D,3,0) -> 0.94145507 | G46: [45,] | H46: 41852 | I46: 0.71117159 | J46: 0.60012656 | K46: =VLOOKUP(H46,'v1'!H:J,3,0) -> 0.73820704 | M46: [45,] | N46: 41852 | O46: 0.11911886 | P46: 0.13523768 | Q46: =VLOOKUP(N46,'v1'!M:O,3,0) -> 0.16591988 | S46: [45,] | T46: 41852 | U46: 1.2960073 | V46: 1.7142015 | W46: =VLOOKUP(T46,'v1'!R:T,3,0) -> 2.5214116 | AE46: [45,] | AF46: 35796 | AG46: 0 | AH46: =VLOOKUP(AF46,LoanLevelHist!B:D,2,0) -> #N/A | AI46: 1.172805 | AJ46: =VLOOKUP(AF46,'v1'!AB:AD,3,0) -> 0.55100098
A47: [46,] | B47: 41883 | C47: 0.72468512 | D47: 0.64925035 | E47: =VLOOKUP(B47,'v1'!B:D,3,0) -> 0.9335229 | G47: [46,] | H47: 41883 | I47: 0.69269283 | J47: 0.59365643 | K47: =VLOOKUP(H47,'v1'!H:J,3,0) -> 0.72280787 | M47: [46,] | N47: 41883 | O47: 0.082103125 | P47: 0.13874191 | Q47: =VLOOKUP(N47,'v1'!M:O,3,0) -> 0.16965118 | S47: [46,] | T47: 41883 | U47: 1.3282972 | V47: 1.7765163 | W47: =VLOOKUP(T47,'v1'!R:T,3,0) -> 2.537318 | AE47: [46,] | AF47: 35827 | AG47: 0 | AH47: =VLOOKUP(AF47,LoanLevelHist!B:D,2,0) -> #N/A | AI47: 1.1836824 | AJ47: =VLOOKUP(AF47,'v1'!AB:AD,3,0) -> 0.55453178
A48: [47,] | B48: 41913 | C48: 0.72620129 | D48: 0.64615707 | E48: =VLOOKUP(B48,'v1'!B:D,3,0) -> 0.93906527 | G48: [47,] | H48: 41913 | I48: 0.68970529 | J48: 0.58630493 | K48: =VLOOKUP(H48,'v1'!H:J,3,0) -> 0.71677494 | M48: [47,] | N48: 41913 | O48: 0.048598743 | P48: 0.14256653 | Q48: =VLOOKUP(N48,'v1'!M:O,3,0) -> 0.17523445 | S48: [47,] | T48: 41913 | U48: 1.3058516 | V48: 1.8458767 | W48: =VLOOKUP(T48,'v1'!R:T,3,0) -> 2.6423744 | AE48: [47,] | AF48: 35855 | AG48: 0 | AH48: =VLOOKUP(AF48,LoanLevelHist!B:D,2,0) -> #N/A | AI48: 1.1840482 | AJ48: =VLOOKUP(AF48,'v1'!AB:AD,3,0) -> 0.55230636
A49: [48,] | B49: 41944 | C49: 0.68886207 | D49: 0.64316336 | E49: =VLOOKUP(B49,'v1'!B:D,3,0) -> 0.94433406 | G49: [48,] | H49: 41944 | I49: 0.65397914 | J49: 0.57929486 | K49: =VLOOKUP(H49,'v1'!H:J,3,0) -> 0.7108191 | M49: [48,] | N49: 41944 | O49: 0.11785444 | P49: 0.14657742 | Q49: =VLOOKUP(N49,'v1'!M:O,3,0) -> 0.18075821 | S49: [48,] | T49: 41944 | U49: 1.3450918 | V49: 1.9126629 | W49: =VLOOKUP(T49,'v1'!R:T,3,0) -> 2.7450738 | AE49: [48,] | AF49: 35886 | AG49: 0 | AH49: =VLOOKUP(AF49,LoanLevelHist!B:D,2,0) -> #N/A | AI49: 1.1574029 | AJ49: =VLOOKUP(AF49,'v1'!AB:AD,3,0) -> 0.53957985
A50: [49,] | B50: 41974 | C50: 0.73175021 | D50: 0.64276365 | E50: =VLOOKUP(B50,'v1'!B:D,3,0) -> 0.95249545 | G50: [49,] | H50: 41974 | I50: 0.69831895 | J50: 0.57493723 | K50: =VLOOKUP(H50,'v1'!H:J,3,0) -> 0.70744131 | M50: [49,] | N50: 41974 | O50: 0.026388849 | P50: 0.15065891 | Q50: =VLOOKUP(N50,'v1'!M:O,3,0) -> 0.1864728 | S50: [49,] | T50: 41974 | U50: 1.346327 | V50: 1.980964 | W50: =VLOOKUP(T50,'v1'!R:T,3,0) -> 2.8510892 | AE50: [49,] | AF50: 35916 | AG50: 0 | AH50: =VLOOKUP(AF50,LoanLevelHist!B:D,2,0) -> #N/A | AI50: 1.1277319 | AJ50: =VLOOKUP(AF50,'v1'!AB:AD,3,0) -> 0.5256341
A51: [50,] | B51: 42005 | C51: 0.687607 | D51: 0.64107251 | E51: =VLOOKUP(B51,'v1'!B:D,3,0) -> 0.95646479 | G51: [50,] | H51: 42005 | I51: 0.64969268 | J51: 0.5692599 | K51: =VLOOKUP(H51,'v1'!H:J,3,0) -> 0.70160083 | M51: [50,] | N51: 42005 | O51: 0.085151275 | P51: 0.15386724 | Q51: =VLOOKUP(N51,'v1'!M:O,3,0) -> 0.19050565 | S51: [50,] | T51: 42005 | U51: 1.3409663 | V51: 2.0467567 | W51: =VLOOKUP(T51,'v1'!R:T,3,0) -> 2.9205375 | AE51: [50,] | AF51: 35947 | AG51: 0 | AH51: =VLOOKUP(AF51,LoanLevelHist!B:D,2,0) -> #N/A | AI51: 1.104452 | AJ51: =VLOOKUP(AF51,'v1'!AB:AD,3,0) -> 0.51556978
A52: [51,] | B52: 42036 | C52: 0.69063 | D52: 0.63960815 | E52: =VLOOKUP(B52,'v1'!B:D,3,0) -> 0.96136132 | G52: [51,] | H52: 42036 | I52: 0.64380936 | J52: 0.56405824 | K52: =VLOOKUP(H52,'v1'!H:J,3,0) -> 0.69745946 | M52: [51,] | N52: 42036 | O52: 0.13158484 | P52: 0.15802962 | Q52: =VLOOKUP(N52,'v1'!M:O,3,0) -> 0.19511252 | S52: [51,] | T52: 42036 | U52: 1.4401413 | V52: 2.1113436 | W52: =VLOOKUP(T52,'v1'!R:T,3,0) -> 2.9859048 | AE52: [51,] | AF52: 35977 | AG52: 0 | AH52: =VLOOKUP(AF52,LoanLevelHist!B:D,2,0) -> #N/A | AI52: 1.0844987 | AJ52: =VLOOKUP(AF52,'v1'!AB:AD,3,0) -> 0.50544418
A53: [52,] | B53: 42064 | C53: 0.62462778 | D53: 0.63780695 | E53: =VLOOKUP(B53,'v1'!B:D,3,0) -> 0.96425929 | G53: [52,] | H53: 42064 | I53: 0.58813601 | J53: 0.55886163 | K53: =VLOOKUP(H53,'v1'!H:J,3,0) -> 0.69201004 | M53: [52,] | N53: 42064 | O53: 0.093392531 | P53: 0.16193536 | Q53: =VLOOKUP(N53,'v1'!M:O,3,0) -> 0.20065168 | S53: [52,] | T53: 42064 | U53: 1.1949048 | V53: 2.1750906 | W53: =VLOOKUP(T53,'v1'!R:T,3,0) -> 3.052645 | AE53: [52,] | AF53: 36008 | AG53: 0 | AH53: =VLOOKUP(AF53,LoanLevelHist!B:D,2,0) -> #N/A | AI53: 1.0647429 | AJ53: =VLOOKUP(AF53,'v1'!AB:AD,3,0) -> 0.49552463
A54: [53,] | B54: 42095 | C54: 0.53754335 | D54: 0.62708854 | E54: =VLOOKUP(B54,'v1'!B:D,3,0) -> 0.94547493 | G54: [53,] | H54: 42095 | I54: 0.50731464 | J54: 0.54410039 | K54: =VLOOKUP(H54,'v1'!H:J,3,0) -> 0.6739559 | M54: [53,] | N54: 42095 | O54: 0.067893245 | P54: 0.16225908 | Q54: =VLOOKUP(N54,'v1'!M:O,3,0) -> 0.19886911 | S54: [53,] | T54: 42095 | U54: 1.1920219 | V54: 2.2280993 | W54: =VLOOKUP(T54,'v1'!R:T,3,0) -> 2.9182594 | AE54: [53,] | AF54: 36039 | AG54: 0 | AH54: =VLOOKUP(AF54,LoanLevelHist!B:D,2,0) -> #N/A | AI54: 1.0553938 | AJ54: =VLOOKUP(AF54,'v1'!AB:AD,3,0) -> 0.48977749
A55: [54,] | B55: 42125 | C55: 0.51417879 | D55: 0.6118633 | E55: =VLOOKUP(B55,'v1'!B:D,3,0) -> 0.92029304 | G55: [54,] | H55: 42125 | I55: 0.48334305 | J55: 0.52555581 | K55: =VLOOKUP(H55,'v1'!H:J,3,0) -> 0.65134723 | M55: [54,] | N55: 42125 | O55: 0.076871349 | P55: 0.16319541 | Q55: =VLOOKUP(N55,'v1'!M:O,3,0) -> 0.19862347 | S55: [54,] | T55: 42125 | U55: 1.0176029 | V55: 2.2730081 | W55: =VLOOKUP(T55,'v1'!R:T,3,0) -> 2.796801 | AE55: [54,] | AF55: 36069 | AG55: 0 | AH55: =VLOOKUP(AF55,LoanLevelHist!B:D,2,0) -> #N/A | AI55: 1.0469577 | AJ55: =VLOOKUP(AF55,'v1'!AB:AD,3,0) -> 0.48582652
A56: [55,] | B56: 42156 | C56: 0.47831995 | D56: 0.59734139 | E56: =VLOOKUP(B56,'v1'!B:D,3,0) -> 0.89587108 | G56: [55,] | H56: 42156 | I56: 0.44822073 | J56: 0.50835014 | K56: =VLOOKUP(H56,'v1'!H:J,3,0) -> 0.63025236 | M56: [55,] | N56: 42156 | O56: 0.020595158 | P56: 0.16186591 | Q56: =VLOOKUP(N56,'v1'!M:O,3,0) -> 0.19580512 | S56: [55,] | T56: 42156 | U56: 1.1365317 | V56: 2.3123045 | W56: =VLOOKUP(T56,'v1'!R:T,3,0) -> 2.6866429 | AE56: [55,] | AF56: 36100 | AG56: 0 | AH56: =VLOOKUP(AF56,LoanLevelHist!B:D,2,0) -> #N/A | AI56: 1.0266388 | AJ56: =VLOOKUP(AF56,'v1'!AB:AD,3,0) -> 0.47617635
A57: [56,] | B57: 42186 | C57: 0.46056295 | D57: 0.59017046 | E57: =VLOOKUP(B57,'v1'!B:D,3,0) -> 0.88740404 | G57: [56,] | H57: 42186 | I57: 0.4219143 | J57: 0.49883025 | K57: =VLOOKUP(H57,'v1'!H:J,3,0) -> 0.61883731 | M57: [56,] | N57: 42186 | O57: 0.081415183 | P57: 0.16202045 | Q57: =VLOOKUP(N57,'v1'!M:O,3,0) -> 0.19643845 | S57: [56,] | T57: 42186 | U57: 1.2301638 | V57: 2.3671945 | W57: =VLOOKUP(T57,'v1'!R:T,3,0) -> 2.7054653 | AE57: [56,] | AF57: 36130 | AG57: 0 | AH57: =VLOOKUP(AF57,LoanLevelHist!B:D,2,0) -> #N/A | AI57: 0.99900362 | AJ57: =VLOOKUP(AF57,'v1'!AB:AD,3,0) -> 0.46307804
... A64: [63,] | B64: 42401 | C64: 0.48709674 | D64: 0.58557454 | E64: =VLOOKUP(B64,'v1'!B:D,3,0) -> 0.89593135 | G64: [63,] | H64: 42401 | I64: 0.45481421 | J64: 0.4802897 | K64: =VLOOKUP(H64,'v1'!H:J,3,0) -> 0.60158013 | M64: [63,] | N64: 42401 | O64: 0.11530497 | P64: 0.19309556 | Q64: =VLOOKUP(N64,'v1'!M:O,3,0) -> 0.23793581 | S64: [63,] | T64: 42401 | U64: 1.1764374 | V64: 2.7500129 | W64: =VLOOKUP(T64,'v1'!R:T,3,0) -> 3.1382257 | AE64: [63,] | AF64: 36342 | AG64: 0 | AH64: =VLOOKUP(AF64,LoanLevelHist!B:D,2,0) -> 0.029062142 | AI64: 0.89813849 | AJ64: =VLOOKUP(AF64,'v1'!AB:AD,3,0) -> 0.41225808
AE65: [64,] | AF65: 36373 | AG65: 0 | AH65: =VLOOKUP(AF65,LoanLevelHist!B:D,2,0) -> 0.060712974 | AI65: 0.9013269 | AJ65: =VLOOKUP(AF65,'v1'!AB:AD,3,0) -> 0.41238628
AE66: [65,] | AF66: 36404 | AG66: 0 | AH66: =VLOOKUP(AF66,LoanLevelHist!B:D,2,0) -> 0.06583242 | AI66: 0.90956135 | AJ66: =VLOOKUP(AF66,'v1'!AB:AD,3,0) -> 0.41493057
AE67: [66,] | AF67: 36434 | AG67: 0 | AH67: =VLOOKUP(AF67,LoanLevelHist!B:D,2,0) -> 0.082015385 | AI67: 0.92006625 | AJ67: =VLOOKUP(AF67,'v1'!AB:AD,3,0) -> 0.41938624
AE68: [67,] | AF68: 36465 | AG68: 0 | AH68: =VLOOKUP(AF68,LoanLevelHist!B:D,2,0) -> 0.082767818 | AI68: 0.93696602 | AJ68: =VLOOKUP(AF68,'v1'!AB:AD,3,0) -> 0.4262688
AE69: [68,] | AF69: 36495 | AG69: 0 | AH69: =VLOOKUP(AF69,LoanLevelHist!B:D,2,0) -> 0.13170375 | AI69: 0.95482609 | AJ69: =VLOOKUP(AF69,'v1'!AB:AD,3,0) -> 0.4341158
AE70: [69,] | AF70: 36526 | AG70: 0 | AH70: =VLOOKUP(AF70,LoanLevelHist!B:D,2,0) -> 0.14161341 | AI70: 0.97539712 | AJ70: =VLOOKUP(AF70,'v1'!AB:AD,3,0) -> 0.44070557
AE71: [70,] | AF71: 36557 | AG71: 0 | AH71: =VLOOKUP(AF71,LoanLevelHist!B:D,2,0) -> 0.21005513 | AI71: 0.98827893 | AJ71: =VLOOKUP(AF71,'v1'!AB:AD,3,0) -> 0.44388874
AE72: [71,] | AF72: 36586 | AG72: 0 | AH72: =VLOOKUP(AF72,LoanLevelHist!B:D,2,0) -> 0.2208505 | AI72: 1.0110615 | AJ72: =VLOOKUP(AF72,'v1'!AB:AD,3,0) -> 0.45139982
AE73: [72,] | AF73: 36617 | AG73: 0 | AH73: =VLOOKUP(AF73,LoanLevelHist!B:D,2,0) -> 0.21403561 | AI73: 1.0319912 | AJ73: =VLOOKUP(AF73,'v1'!AB:AD,3,0) -> 0.4591474
AE74: [73,] | AF74: 36647 | AG74: 0 | AH74: =VLOOKUP(AF74,LoanLevelHist!B:D,2,0) -> 0.19625704 | AI74: 1.0517649 | AJ74: =VLOOKUP(AF74,'v1'!AB:AD,3,0) -> 0.46609717
AE75: [74,] | AF75: 36678 | AG75: 0 | AH75: =VLOOKUP(AF75,LoanLevelHist!B:D,2,0) -> 0.19105319 | AI75: 1.0651493 | AJ75: =VLOOKUP(AF75,'v1'!AB:AD,3,0) -> 0.47089258
AE76: [75,] | AF76: 36708 | AG76: 0 | AH76: =VLOOKUP(AF76,LoanLevelHist!B:D,2,0) -> 0.22355436 | AI76: 1.078284 | AJ76: =VLOOKUP(AF76,'v1'!AB:AD,3,0) -> 0.47510527
... AE263: [262,] | AF263: 42401 | AG263: 0.45481421 | AH263: =VLOOKUP(AF263,LoanLevelHist!B:D,2,0) -> #N/A | AI263: 0.58808763 | AJ263: =VLOOKUP(AF263,'v1'!AB:AD,3,0) -> 0.56720945

Sheet v1
A1: Overall | B1: x_vals | C1: y_vals.act | D1: y_vals.mdl | G1: Conv | H1: x_vals | I1: y_vals.act | J1: y_vals.mdl | M1: x_vals | N1: y_vals.act | O1: y_vals.mdl | R1: x_vals | S1: y_vals.act | T1: y_vals.mdl | W1: x_vals | X1: y_vals.act | Y1: y_vals.mdl | AB1: x_vals | AC1: y_vals.act | AD1: y_vals.mdl
A2: [1,] | B2: 40513 | C2: 2.9403271 | D2: 2.1523348 | G2: [1,] | H2: 40513 | I2: 2.9436942 | J2: 2.1546881 | L2: [1,] | M2: 40513 | N2: 8.7425281 | O2: 0.81217765 | Q2: [1,] | R2: 40513 | S2: 1.0463194 | T2: 1.4039362 | V2: [1,] | W2: 41091 | X2: 0 | Y2: 0.3002854 | AA2: [1,] | AB2: 34335 | AC2: 0 | AD2: 0.004866125
A3: [2,] | B3: 40544 | C3: 2.8515888 | D3: 2.1791283 | G3: [2,] | H3: 40544 | I3: 2.854404 | J3: 2.1831644 | L3: [2,] | M3: 40544 | N3: 2.532783 | O3: 0.3182789 | Q3: [2,] | R3: 40544 | S3: 2.0846884 | T3: 1.4034489 | V3: [2,] | W3: 41122 | X3: 0 | Y3: 0.45887599 | AA3: [2,] | AB3: 34366 | AC3: 0 | AD3: 0.21411522
A4: [3,] | B4: 40575 | C4: 3.0092574 | D4: 2.2621515 | G4: [3,] | H4: 40575 | I4: 3.0184761 | J4: 2.2672433 | L4: [3,] | M4: 40575 | N4: 0 | O4: 0.23491254 | Q4: [3,] | R4: 40575 | S4: 1.4608418 | T4: 1.5226294 | V4: [3,] | W4: 41153 | X4: 0 | Y4: 0.63430868 | AA4: [3,] | AB4: 34394 | AC4: 0 | AD4: 0.21726305
A5: [4,] | B5: 40603 | C5: 2.5804835 | D5: 2.3374511 | G5: [4,] | H5: 40603 | I5: 2.591815 | J5: 2.3459676 | L5: [4,] | M5: 40603 | N5: 0 | O5: 0.13124103 | Q5: [4,] | R5: 40603 | S5: 1.3464863 | T5: 1.5476715 | V5: [4,] | W5: 41183 | X5: 0.65312716 | Y5: 0.82961526 | AA5: [4,] | AB5: 34486 | AC5: 0 | AD5: 0.014112837
A6: [5,] | B6: 40634 | C6: 2.2254604 | D6: 2.2796873 | G6: [5,] | H6: 40634 | I6: 2.2371486 | J6: 2.2890867 | L6: [5,] | M6: 40634 | N6: 0.22696274 | O6: 0.11974373 | Q6: [5,] | R6: 40634 | S6: 0.98139408 | T6: 1.5496788 | V6: [5,] | W6: 41214 | X6: 0.4869495 | Y6: 1.0406365 | AA6: [5,] | AB6: 34516 | AC6: 0 | AD6: 0.24276857
A7: [6,] | B7: 40664 | C7: 2.135774 | D7: 2.2326217 | G7: [6,] | H7: 40664 | I7: 2.1435584 | J7: 2.2427195 | L7: [6,] | M7: 40664 | N7: 0.41511956 | O7: 0.10884532 | Q7: [6,] | R7: 40664 | S7: 1.710417 | T7: 1.622068 | V7: [6,] | W7: 41244 | X7: 0.89675317 | Y7: 1.2221443 | AA7: [6,] | AB7: 34547 | AC7: 0 | AD7: 0.25454949
A8: [7,] | B8: 40695 | C8: 2.1134526 | D8: 2.233831 | G8: [7,] | H8: 40695 | I8: 2.1173279 | J8: 2.2447437 | L8: [7,] | M8: 40695 | N8: 0.14997256 | O8: 0.096631916 | Q8: [7,] | R8: 40695 | S8: 2.6223028 | T8: 1.7372122 | V8: [7,] | W8: 41275 | X8: 0.8899795 | Y8: 1.4605462 | AA8: [7,] | AB8: 34578 | AC8: 0 | AD8: 0.26680185
A9: [8,] | B9: 40725 | C9: 2.076756 | D9: 2.1894364 | G9: [8,] | H9: 40725 | I9: 2.0846664 | J9: 2.2009849 | L9: [8,] | M9: 40725 | N9: 0.29877672 | O9: 0.08972298 | Q9: [8,] | R9: 40725 | S9: 2.0476761 | T9: 1.834349 | V9: [8,] | W9: 41306 | X9: 1.1800204 | Y9: 1.6776543 | AA9: [8,] | AB9: 34608 | AC9: 0 | AD9: 0.28058556
A10: [9,] | B10: 40756 | C10: 2.0678545 | D10: 2.1524204 | G10: [9,] | H10: 40756 | I10: 2.0767136 | J10: 2.1637331 | L10: [9,] | M10: 40756 | N10: 0.13344405 | O10: 0.08973857 | Q10: [9,] | R10: 40756 | S10: 2.1192492 | T10: 1.9552517 | V10: [9,] | W10: 41334 | X10: 1.2525012 | Y10: 1.8897288 | AA10: [9,] | AB10: 34639 | AC10: 0 | AD10: 0.29522473
A11: [10,] | B11: 40787 | C11: 2.1195307 | D11: 2.1118378 | G11: [10,] | H11: 40787 | I11: 2.1306944 | J11: 2.1226307 | L11: [10,] | M11: 40787 | N11: 0.19410047 | O11: 0.090452568 | Q11: [10,] | R11: 40787 | S11: 1.968303 | T11: 2.0691216 | V11: [10,] | W11: 41365 | X11: 1.1485688 | Y11: 2.0516141 | AA11: [10,] | AB11: 34669 | AC11: 0 | AD11: 0.3115286
A12: [11,] | B12: 40817 | C12: 2.1812705 | D12: 2.1322872 | G12: [11,] | H12: 40817 | I12: 2.1940196 | J12: 2.1427486 | L12: [11,] | M12: 40817 | N12: 0.080194662 | O12: 0.095590107 | Q12: [11,] | R12: 40817 | S12: 2.0323255 | T12: 2.2106295 | V12: [11,] | W12: 41395 | X12: 1.1727388 | Y12: 2.2291296 | AA12: [11,] | AB12: 34700 | AC12: 0 | AD12: 0.32733927
A13: [12,] | B13: 40848 | C13: 2.2641557 | D13: 2.1564726 | G13: [12,] | H13: 40848 | I13: 2.2744068 | J13: 2.167375 | L13: [12,] | M13: 40848 | N13: 0 | O13: 0.093902772 | Q13: [12,] | R13: 40848 | S13: 2.7040705 | T13: 2.3867472 | V13: [12,] | W13: 41426 | X13: 1.3703528 | Y13: 2.4255927 | AA13: [12,] | AB13: 34731 | AC13: 0 | AD13: 0.3425625
... A45: [44,] | B45: 41821 | C45: 0.71890987 | D45: 0.93889907 | G45: [44,] | H45: 41821 | I45: 0.69287565 | J45: 0.74684527 | L45: [44,] | M45: 41821 | N45: 0.089049625 | O45: 0.15965077 | Q45: [44,] | R45: 41821 | S45: 1.1971972 | T45: 2.4360087 | V45: [44,] | W45: 42401 | X45: 1.4464891 | Y45: 11.364858 | AA45: [44,] | AB45: 35765 | AC45: 0 | AD45: 0.55451885
A46: [45,] | B46: 41852 | C46: 0.74288919 | D46: 0.94145507 | G46: [45,] | H46: 41852 | I46: 0.71117159 | J46: 0.73820704 | L46: [45,] | M46: 41852 | N46: 0.11911886 | O46: 0.16591988 | Q46: [45,] | R46: 41852 | S46: 1.2960073 | T46: 2.5214116 | AA46: [45,] | AB46: 35796 | AC46: 0 | AD46: 0.55100098
A47: [46,] | B47: 41883 | C47: 0.72468512 | D47: 0.9335229 | G47: [46,] | H47: 41883 | I47: 0.69269283 | J47: 0.72280787 | L47: [46,] | M47: 41883 | N47: 0.082103125 | O47: 0.16965118 | Q47: [46,] | R47: 41883 | S47: 1.3282972 | T47: 2.537318 | AA47: [46,] | AB47: 35827 | AC47: 0 | AD47: 0.55453178
A48: [47,] | B48: 41913 | C48: 0.72620129 | D48: 0.93906527 | G48: [47,] | H48: 41913 | I48: 0.68970529 | J48: 0.71677494 | L48: [47,] | M48: 41913 | N48: 0.048598743 | O48: 0.17523445 | Q48: [47,] | R48: 41913 | S48: 1.3058516 | T48: 2.6423744 | AA48: [47,] | AB48: 35855 | AC48: 0 | AD48: 0.55230636
A49: [48,] | B49: 41944 | C49: 0.68886207 | D49: 0.94433406 | G49: [48,] | H49: 41944 | I49: 0.65397914 | J49: 0.7108191 | L49: [48,] | M49: 41944 | N49: 0.11785444 | O49: 0.18075821 | Q49: [48,] | R49: 41944 | S49: 1.3450918 | T49: 2.7450738 | AA49: [48,] | AB49: 35886 | AC49: 0 | AD49: 0.53957985
A50: [49,] | B50: 41974 | C50: 0.73175021 | D50: 0.95249545 | G50: [49,] | H50: 41974 | I50: 0.69831895 | J50: 0.70744131 | L50: [49,] | M50: 41974 | N50: 0.026388849 | O50: 0.1864728 | Q50: [49,] | R50: 41974 | S50: 1.346327 | T50: 2.8510892 | AA50: [49,] | AB50: 35916 | AC50: 0 | AD50: 0.5256341
A51: [50,] | B51: 42005 | C51: 0.687607 | D51: 0.95646479 | G51: [50,] | H51: 42005 | I51: 0.64969268 | J51: 0.70160083 | L51: [50,] | M51: 42005 | N51: 0.085151275 | O51: 0.19050565 | Q51: [50,] | R51: 42005 | S51: 1.3409663 | T51: 2.9205375 | AA51: [50,] | AB51: 35947 | AC51: 0 | AD51: 0.51556978
A52: [51,] | B52: 42036 | C52: 0.69063 | D52: 0.96136132 | G52: [51,] | H52: 42036 | I52: 0.64380936 | J52: 0.69745946 | L52: [51,] | M52: 42036 | N52: 0.13158484 | O52: 0.19511252 | Q52: [51,] | R52: 42036 | S52: 1.4401413 | T52: 2.9859048 | AA52: [51,] | AB52: 35977 | AC52: 0 | AD52: 0.50544418
A53: [52,] | B53: 42064 | C53: 0.62462778 | D53: 0.96425929 | G53: [52,] | H53: 42064 | I53: 0.58813601 | J53: 0.69201004 | L53: [52,] | M53: 42064 | N53: 0.093392531 | O53: 0.20065168 | Q53: [52,] | R53: 42064 | S53: 1.1949048 | T53: 3.052645 | AA53: [52,] | AB53: 36008 | AC53: 0 | AD53: 0.49552463
A54: [53,] | B54: 42095 | C54: 0.53754335 | D54: 0.94547493 | G54: [53,] | H54: 42095 | I54: 0.50731464 | J54: 0.6739559 | L54: [53,] | M54: 42095 | N54: 0.067893245 | O54: 0.19886911 | Q54: [53,] | R54: 42095 | S54: 1.1920219 | T54: 2.9182594 | AA54: [53,] | AB54: 36039 | AC54: 0 | AD54: 0.48977749
A55: [54,] | B55: 42125 | C55: 0.51417879 | D55: 0.92029304 | G55: [54,] | H55: 42125 | I55: 0.48334305 | J55: 0.65134723 | L55: [54,] | M55: 42125 | N55: 0.076871349 | O55: 0.19862347 | Q55: [54,] | R55: 42125 | S55: 1.0176029 | T55: 2.796801 | AA55: [54,] | AB55: 36069 | AC55: 0 | AD55: 0.48582652
A56: [55,] | B56: 42156 | C56: 0.47831995 | D56: 0.89587108 | G56: [55,] | H56: 42156 | I56: 0.44822073 | J56: 0.63025236 | L56: [55,] | M56: 42156 | N56: 0.020595158 | O56: 0.19580512 | Q56: [55,] | R56: 42156 | S56: 1.1365317 | T56: 2.6866429 | AA56: [55,] | AB56: 36100 | AC56: 0 | AD56: 0.47617635
A57: [56,] | B57: 42186 | C57: 0.46056295 | D57: 0.88740404 | G57: [56,] | H57: 42186 | I57: 0.4219143 | J57: 0.61883731 | L57: [56,] | M57: 42186 | N57: 0.081415183 | O57: 0.19643845 | Q57: [56,] | R57: 42186 | S57: 1.2301638 | T57: 2.7054653 | AA57: [56,] | AB57: 36130 | AC57: 0 | AD57: 0.46307804
... A64: [63,] | B64: 42401 | C64: 0.48709674 | D64: 0.89593135 | G64: [63,] | H64: 42401 | I64: 0.45481421 | J64: 0.60158013 | L64: [63,] | M64: 42401 | N64: 0.11530497 | O64: 0.23793581 | Q64: [63,] | R64: 42401 | S64: 1.1764374 | T64: 3.1382257 | AA64: [63,] | AB64: 36342 | AC64: 0 | AD64: 0.41225808
AA65: [64,] | AB65: 36373 | AC65: 0 | AD65: 0.41238628
AA66: [65,] | AB66: 36404 | AC66: 0 | AD66: 0.41493057
AA67: [66,] | AB67: 36434 | AC67: 0 | AD67: 0.41938624
AA68: [67,] | AB68: 36465 | AC68: 0 | AD68: 0.4262688
AA69: [68,] | AB69: 36495 | AC69: 0 | AD69: 0.4341158
AA70: [69,] | AB70: 36526 | AC70: 0 | AD70: 0.44070557
AA71: [70,] | AB71: 36557 | AC71: 0 | AD71: 0.44388874
AA72: [71,] | AB72: 36586 | AC72: 0 | AD72: 0.45139982
AA73: [72,] | AB73: 36617 | AC73: 0 | AD73: 0.4591474
AA74: [73,] | AB74: 36647 | AC74: 0 | AD74: 0.46609717
AA75: [74,] | AB75: 36678 | AC75: 0 | AD75: 0.47089258
AA76: [75,] | AB76: 36708 | AC76: 0 | AD76: 0.47510527
... AA263: [262,] | AB263: 42401 | AC263: 0.45481421 | AD263: 0.56720945

Sheet LoanLevelHist
B1: x_vals | C1: y_vals.act | D1: y_vals.mdl
A2: [1,] | B2: 36220 | C2: 0 | D2: 0.00053010549
A3: [2,] | B3: 36251 | C3: 0.014883822 | D3: 0.0029025082
A4: [3,] | B4: 36281 | C4: 0.016324422 | D4: 0.0038963064
A5: [4,] | B5: 36312 | C5: 0.025276824 | D5: 0.0050999991
A6: [5,] | B6: 36342 | C6: 0.029062142 | D6: 0.0059149776
A7: [6,] | B7: 36373 | C7: 0.060712974 | D7: 0.011474892
A8: [7,] | B8: 36404 | C8: 0.06583242 | D8: 0.019012124
A9: [8,] | B9: 36434 | C9: 0.082015385 | D9: 0.037969088
A10: [9,] | B10: 36465 | C10: 0.082767818 | D10: 0.066280295
A11: [10,] | B11: 36495 | C11: 0.13170375 | D11: 0.10742569
A12: [11,] | B12: 36526 | C12: 0.14161341 | D12: 0.13743869
A13: [12,] | B13: 36557 | C13: 0.21005513 | D13: 0.17423998
... A197: [196,] | B197: 42156 | C197: 0.32915964 | D197: 1.205516
