Workbook

Sheet incentive-Old
A1: marketTicker | B1: asOf | C1: count(1) | D1: sum(p.schamBalance) | E1: wavg_conv_incentive | H1: marketTicker | I1: FNCQ30 | V1: marketTicker | W1: asOf | X1: count(1) | Y1: sum(p.schamBalance) | Z1: wavg_conv_incentive | AC1: marketTicker | AD1: FGU6
A2: FNCL | B2: 34366 | C2: 126636 | D2: 2.7849025e+11 | E2: 107.0043 | V2: FGLMC | W2: 34366 | X2: 47564 | Y2: 1.7936303e+11 | Z2: 73.945826
A3: FNCL | B3: 34394 | C3: 128266 | D3: 2.8205083e+11 | E3: 89.666174 | H3: Row Labels | I3: Sum of wavg_conv_incentive | J3: FGU6 | M3: CQ | N3: U6 | V3: FGLMC | W3: 34394 | X3: 48770 | Y3: 1.8267643e+11 | Z3: 57.988038 | AC3: Row Labels | AD3: Sum of wavg_conv_incentive
A4: FNCL | B4: 34425 | C4: 129601 | D4: 2.838742e+11 | E4: 26.947319 | H4: 40118 | I4: -4.9894067 | J4: =VLOOKUP(H4,AC:AD,2,0) -> #N/A | L4: 40118 | M4: -4.9894067 | N4: =J4 -> #N/A | V4: FGLMC | W4: 34425 | X4: 50054 | Y4: 1.8717384e+11 | Z4: -4.1527811 | AC4: 40148 | AD4: -105.08739
A5: FNCL | B5: 34455 | C5: 130768 | D5: 2.847529e+11 | E5: -43.681837 | H5: 40148 | I5: -36.613236 | J5: =VLOOKUP(H5,AC:AD,2,0) -> -105.08739 | L5: 40148 | M5: -36.613236 | N5: =J5 -> -105.08739 | V5: FGLMC | W5: 34516 | X5: 53319 | Y5: 1.9825763e+11 | Z5: -80.743533 | AC5: 40179 | AD5: -98.003423
A6: FNCL | B6: 34486 | C6: 131996 | D6: 2.8712206e+11 | E6: -68.44648 | H6: 40179 | I6: -44.605224 | J6: =VLOOKUP(H6,AC:AD,2,0) -> -98.003423 | L6: 40179 | M6: -44.605224 | N6: =J6 -> -98.003423 | V6: FGLMC | W6: 34547 | X6: 54110 | Y6: 2.0067919e+11 | Z6: -100.77592 | AC6: 40210 | AD6: -97.794944
A7: FNCL | B7: 34516 | C7: 133140 | D7: 2.8891975e+11 | E7: -52.809469 | H7: 40210 | I7: -54.844578 | J7: =VLOOKUP(H7,AC:AD,2,0) -> -97.794944 | L7: 40210 | M7: -54.844578 | N7: =J7 -> -97.794944 | V7: FGLMC | W7: 34578 | X7: 54835 | Y7: 2.0294126e+11 | Z7: -88.136929 | AC7: 40238 | AD7: -94.947502
A8: FNCL | B8: 34547 | C8: 134153 | D8: 2.9064065e+11 | E8: -73.407546 | H8: 40238 | I8: -51.04832 | J8: =VLOOKUP(H8,AC:AD,2,0) -> -94.947502 | L8: 40238 | M8: -51.04832 | N8: =J8 -> -94.947502 | V8: FGLMC | W8: 34608 | X8: 55530 | Y8: 2.0522667e+11 | Z8: -100.2613 | AC8: 40269 | AD8: -114.99673
A9: FNCL | B9: 34578 | C9: 135077 | D9: 2.9202625e+11 | E9: -61.490295 | H9: 40269 | I9: -49.683488 | J9: =VLOOKUP(H9,AC:AD,2,0) -> -114.99673 | L9: 40269 | M9: -49.683488 | N9: =J9 -> -114.99673 | V9: FGLMC | W9: 34639 | X9: 56108 | Y9: 2.0697511e+11 | Z9: -128.01045 | AC9: 40299 | AD9: -157.71884
A10: FNCL | B10: 34608 | C10: 135888 | D10: 2.9339599e+11 | E10: -74.241147 | H10: 40299 | I10: -115.53618 | J10: =VLOOKUP(H10,AC:AD,2,0) -> -157.71884 | L10: 40299 | M10: -115.53618 | N10: =J10 -> -157.71884 | V10: FGLMC | W10: 34669 | X10: 56529 | Y10: 2.0775371e+11 | Z10: -152.61497 | AC10: 40330 | AD10: -139.52632
A11: FNCL | B11: 34639 | C11: 136567 | D11: 2.94792e+11 | E11: -103.05369 | H11: 40330 | I11: -85.12122 | J11: =VLOOKUP(H11,AC:AD,2,0) -> -139.52632 | L11: 40330 | M11: -85.12122 | N11: =J11 -> -139.52632 | V11: FGLMC | W11: 34700 | X11: 56894 | Y11: 2.0840618e+11 | Z11: -154.01171 | AC11: 40360 | AD11: -124.47866
A12: FNCL | B12: 34669 | C12: 137384 | D12: 2.9702273e+11 | E12: -127.43149 | H12: 40360 | I12: -60.412157 | J12: =VLOOKUP(H12,AC:AD,2,0) -> -124.47866 | L12: 40360 | M12: -60.412157 | N12: =J12 -> -124.47866 | V12: FGLMC | W12: 34731 | X12: 57294 | Y12: 2.0935918e+11 | Z12: -148.22078 | AC12: 40391 | AD12: -112.51808
A13: FNCL | B13: 34700 | C13: 138175 | D13: 2.9953479e+11 | E13: -128.62333 | H13: 40391 | I13: -40.448867 | J13: =VLOOKUP(H13,AC:AD,2,0) -> -112.51808 | L13: 40391 | M13: -40.448867 | N13: =J13 -> -112.51808 | V13: FGLMC | W13: 34759 | X13: 57702 | Y13: 2.1044467e+11 | Z13: -116.15734 | AC13: 40422 | AD13: -101.41902
A14: FNCL | B14: 34731 | C14: 138749 | D14: 3.0057806e+11 | E14: -123.40996 | H14: 40422 | I14: -24.274786 | J14: =VLOOKUP(H14,AC:AD,2,0) -> -101.41902 | L14: 40422 | M14: -24.274786 | N14: =J14 -> -101.41902 | V14: FGLMC | W14: 34790 | X14: 58144 | Y14: 2.120786e+11 | Z14: -76.166095 | AC14: 40452 | AD14: -99.895145
A15: FNCL | B15: 34759 | C15: 139252 | D15: 3.0151552e+11 | E15: -91.951416 | H15: 40452 | I15: -14.893102 | J15: =VLOOKUP(H15,AC:AD,2,0) -> -99.895145 | L15: 40452 | M15: -14.893102 | N15: =J15 -> -99.895145 | V15: FGLMC | W15: 34820 | X15: 58699 | Y15: 2.1408617e+11 | Z15: -62.319054 | AC15: 40483 | AD15: -92.860667
... A86: FNCL | B86: 36923 | C86: 209121 | D86: 7.1193641e+11 | E86: 51.855543 | H86: 42614 | I86: 95.9103 | J86: =VLOOKUP(H86,AC:AD,2,0) -> 23.468273 | L86: 42614 | M86: 95.9103 | N86: =J86 -> 23.468273 | V86: FGLMC | W86: 37043 | X86: 118503 | Y86: 5.9330542e+11 | Z86: 27.945896 | AC86: 42644 | AD86: 20.674881
A87: FNCL | B87: 36951 | C87: 210670 | D87: 7.2415943e+11 | E87: 48.884561 | H87: 42644 | I87: 92.71246 | J87: =VLOOKUP(H87,AC:AD,2,0) -> 20.674881 | L87: 42644 | M87: 92.71246 | N87: =J87 -> 20.674881 | V87: FGLMC | W87: 37073 | X87: 119870 | Y87: 6.0680606e+11 | Z87: 26.571854 | AC87: Grand Total | AD87: -8535.2186
A88: FNCL | B88: 36982 | C88: 212403 | D88: 7.3713162e+11 | E88: 57.785857 | H88: Grand Total | I88: -938.75158 | J88: =VLOOKUP(H88,AC:AD,2,0) -> -8535.2186 | V88: FGLMC | W88: 37104 | X88: 121166 | Y88: 6.1879176e+11 | Z88: 27.293108
A89: FNCL | B89: 37012 | C89: 214231 | D89: 7.5255621e+11 | E89: 43.00738 | V89: FGLMC | W89: 37135 | X89: 122179 | Y89: 6.2884091e+11 | Z89: 43.784024
A90: FNCL | B90: 37043 | C90: 216060 | D90: 768634381863 | E90: 30.547849 | V90: FGLMC | W90: 37165 | X90: 123141 | Y90: 6.3851928e+11 | Z90: 55.184295
A91: FNCL | B91: 37073 | C91: 217775 | D91: 7.838996e+11 | E91: 29.511147 | V91: FGLMC | W91: 37196 | X91: 124004 | Y91: 6.4630665e+11 | Z91: 74.575512
A92: FNCL | B92: 37104 | C92: 219337 | D92: 800219895172 | E92: 30.593293 | V92: FGLMC | W92: 37226 | X92: 124910 | Y92: 6.525821e+11 | Z92: 69.073783
A93: FNCL | B93: 37135 | C93: 220863 | D93: 8.1627696e+11 | E93: 46.826924 | V93: FGLMC | W93: 37257 | X93: 125965 | Y93: 6.5648633e+11 | Z93: 25.825198
A94: FNCL | B94: 37165 | C94: 222193 | D94: 8.2934041e+11 | E94: 58.092522 | V94: FGLMC | W94: 37288 | X94: 126547 | Y94: 6.562536e+11 | Z94: 28.533205
A95: FNCL | B95: 37196 | C95: 223572 | D95: 8.4108138e+11 | E95: 77.469385 | V95: FGLMC | W95: 37316 | X95: 127084 | Y95: 6.6257802e+11 | Z95: 42.920968
A96: FNCL | B96: 37226 | C96: 225055 | D96: 8.5335439e+11 | E96: 71.369073 | V96: FGLMC | W96: 37347 | X96: 127647 | Y96: 6.6788022e+11 | Z96: 17.715364
A97: FNCL | B97: 37257 | C97: 226605 | D97: 8.6500934e+11 | E97: 27.730251 | V97: FGLMC | W97: 37377 | X97: 128359 | Y97: 6.7490772e+11 | Z97: 23.054175
A98: FNCL | B98: 37288 | C98: 227719 | D98: 8.6800265e+11 | E98: 30.344967 | V98: FGLMC | W98: 37408 | X98: 128856 | Y98: 6.7812981e+11 | Z98: 39.77031
A99: FNCL | B99: 37316 | C99: 228962 | D99: 8.7969648e+11 | E99: 44.91829 | V99: FGLMC | W99: 37438 | X99: 129396 | Y99: 6.8301745e+11 | Z99: 57.194818
A100: FNCL | B100: 37347 | C100: 229290 | D100: 8.9113707e+11 | E100: 19.847829 | V100: FGLMC | W100: 37469 | X100: 129977 | Y100: 6.8806762e+11 | Z100: 73.695127
... A506: FNCL | B506: 42614 | C506: 310733 | D506: 1.7881847e+12 | E506: 100.10124 | V506: FGU6 | W506: 42644 | X506: 4021 | Y506: 2.8689194e+10 | Z506: 20.674881
A507: FNCR | B507: 42614 | C507: 1385 | D507: 3.4088681e+10 | E507: -122.38415
A508: FNCL | B508: 42644 | C508: 311376 | D508: 1.7941305e+12 | E508: 95.225376
A509: FNCQ30 | B509: 42644 | C509: 2155 | D509: 3.8990715e+10 | E509: 92.71246
A510: FNCK | B510: 42644 | C510: 2303 | D510: 5.6641835e+10 | E510: 56.763576
A511: FNCR | B511: 42644 | C511: 1390 | D511: 3.3686514e+10 | E511: -125.33458

Sheet incentive-new
A1: marketTicker | B1: asOf | C1: count(1) | D1: sum(p.schamBalance) | E1: wavg_conv_incentive | H1: marketTicker | I1: FNCQ30
A2: FNCL | B2: 34366 | C2: 126636 | D2: 2.7849025e+11 | E2: 107.00931
A3: FNCL | B3: 34394 | C3: 128266 | D3: 2.8205083e+11 | E3: 89.666182 | H3: Row Labels | I3: Sum of wavg_conv_incentive | M3: CQ | N3: U6
A4: FNCL | B4: 34425 | C4: 129601 | D4: 2.838742e+11 | E4: 26.947327 | H4: 40118 | I4: -27.092277 | L4: 40118 | M4: -27.092277 | N4: ='incentive-Old'!N4 -> #N/A
A5: FNCL | B5: 34455 | C5: 130768 | D5: 2.847529e+11 | E5: -43.676845 | H5: 40148 | I5: -90.836386 | L5: 40148 | M5: -90.836386 | N5: ='incentive-Old'!N5 -> -105.08739
A6: FNCL | B6: 34486 | C6: 131996 | D6: 2.8712206e+11 | E6: -68.436492 | H6: 40179 | I6: -100.92704 | L6: 40179 | M6: -100.92704 | N6: ='incentive-Old'!N6 -> -98.003423
A7: FNCL | B7: 34516 | C7: 133140 | D7: 2.8891975e+11 | E7: -52.809463 | H7: 40210 | I7: -113.02685 | L7: 40210 | M7: -113.02685 | N7: ='incentive-Old'!N7 -> -97.794944
A8: FNCL | B8: 34547 | C8: 134153 | D8: 2.9064065e+11 | E8: -73.402561 | H8: 40238 | I8: -109.29651 | L8: 40238 | M8: -109.29651 | N8: ='incentive-Old'!N8 -> -94.947502
A9: FNCL | B9: 34578 | C9: 135077 | D9: 2.9202625e+11 | E9: -61.490292 | H9: 40269 | I9: -108.64596 | L9: 40269 | M9: -108.64596 | N9: ='incentive-Old'!N9 -> -114.99673
A10: FNCL | B10: 34608 | C10: 135888 | D10: 2.9339599e+11 | E10: -74.241154 | H10: 40299 | I10: -174.60705 | L10: 40299 | M10: -174.60705 | N10: ='incentive-Old'!N10 -> -157.71884
A11: FNCL | B11: 34639 | C11: 136567 | D11: 2.94792e+11 | E11: -103.04371 | H11: 40330 | I11: -153.54855 | L11: 40330 | M11: -153.54855 | N11: ='incentive-Old'!N11 -> -139.52632
A12: FNCL | B12: 34669 | C12: 137384 | D12: 2.9702273e+11 | E12: -127.42651 | H12: 40360 | I12: -134.91198 | L12: 40360 | M12: -134.91198 | N12: ='incentive-Old'!N12 -> -124.47866
A13: FNCL | B13: 34700 | C13: 138175 | D13: 2.9953479e+11 | E13: -128.62334 | H13: 40391 | I13: -120.20285 | L13: 40391 | M13: -120.20285 | N13: ='incentive-Old'!N13 -> -112.51808
A14: FNCL | B14: 34731 | C14: 138749 | D14: 3.0057806e+11 | E14: -123.40497 | H14: 40422 | I14: -107.95134 | L14: 40422 | M14: -107.95134 | N14: ='incentive-Old'!N14 -> -101.41902
A15: FNCL | B15: 34759 | C15: 139252 | D15: 3.0151552e+11 | E15: -91.946436 | H15: 40452 | I15: -103.21243 | L15: 40452 | M15: -103.21243 | N15: ='incentive-Old'!N15 -> -99.895145
... A87: FNCL | B87: 36951 | C87: 210670 | D87: 7.2415943e+11 | E87: 48.884554 | H87: 42644 | I87: 36.767421 | L87: 42644 | M87: 36.767421 | N87: ='incentive-Old'!N87 -> 20.674881
A88: FNCL | B88: 36982 | C88: 212403 | D88: 7.3713162e+11 | E88: 57.785848 | H88: Grand Total | I88: -7400.8268
A89: FNCL | B89: 37012 | C89: 214231 | D89: 7.5255621e+11 | E89: 43.007402
A90: FNCL | B90: 37043 | C90: 216060 | D90: 768634381863 | E90: 30.557826
A91: FNCL | B91: 37073 | C91: 217775 | D91: 7.838996e+11 | E91: 29.516152
A92: FNCL | B92: 37104 | C92: 219337 | D92: 800219895172 | E92: 30.593298
A93: FNCL | B93: 37135 | C93: 220863 | D93: 8.1627696e+11 | E93: 46.826922
A94: FNCL | B94: 37165 | C94: 222193 | D94: 8.2934041e+11 | E94: 58.092513
A95: FNCL | B95: 37196 | C95: 223572 | D95: 8.4108138e+11 | E95: 77.469411
A96: FNCL | B96: 37226 | C96: 225055 | D96: 8.5335439e+11 | E96: 71.369073
A97: FNCL | B97: 37257 | C97: 226605 | D97: 8.6500934e+11 | E97: 27.730228
A98: FNCL | B98: 37288 | C98: 227719 | D98: 8.6800265e+11 | E98: 30.344988
A99: FNCL | B99: 37316 | C99: 228962 | D99: 8.7969648e+11 | E99: 44.918276
A100: FNCL | B100: 37347 | C100: 229290 | D100: 8.9113707e+11 | E100: 19.847855
... A511: FNCR | B511: 42644 | C511: 1390 | D511: 3.3686514e+10 | E511: -179.86157

Sheet incentive-fncl
B1: FNCL | C1: FGLMC | D1: FNCL-new
A2: 34366 | B2: 107.0043 | C2: 73.945826 | D2: 107.00931
A3: 34394 | B3: 89.666174 | C3: 57.988038 | D3: 89.666182
A4: 34425 | B4: 26.947319 | C4: -4.1527811 | D4: 26.947327
A5: 34455 | B5: -43.681837 | C5: #N/A | D5: -43.676845
A6: 34486 | B6: -68.44648 | C6: #N/A | D6: -68.436492
A7: 34516 | B7: -52.809469 | C7: -80.743533 | D7: -52.809463
A8: 34547 | B8: -73.407546 | C8: -100.77592 | D8: -73.402561
A9: 34578 | B9: -61.490295 | C9: -88.136929 | D9: -61.490292
A10: 34608 | B10: -74.241147 | C10: -100.2613 | D10: -74.241154
A11: 34639 | B11: -103.05369 | C11: -128.01045 | D11: -103.04371
A12: 34669 | B12: -127.43149 | C12: -152.61497 | D12: -127.42651
A13: 34700 | B13: -128.62333 | C13: -154.01171 | D13: -128.62334
A14: 34731 | B14: -123.40996 | C14: -148.22078 | D14: -123.40497
A15: 34759 | B15: -91.951416 | C15: -116.15734 | D15: -91.946436
A16: 34790 | B16: -52.891252 | C16: -76.166095 | D16: -52.881268
A17: 34820 | B17: -39.319677 | C17: -62.319054 | D17: -39.309693
A18: 34851 | B18: -6.6569489e-05 | C18: -22.433263 | D18: 0.0049215736
... A36: 35400 | B36: 21.601914 | C36: 7.9121844 | D36: 21.606921
A37: 35431 | B37: 21.251524 | C37: #N/A | D37: 21.256535
A38: 35462 | B38: -2.6483723 | C38: #N/A | D38: -2.6483701
A39: 35490 | B39: 16.165563 | C39: 2.4535559 | D39: 16.165569
A40: 35521 | B40: -10.334937 | C40: -23.607543 | D40: -10.334925
A41: 35551 | B41: -34.392277 | C41: -47.364809 | D41: -34.387273
A42: 35582 | B42: -13.097062 | C42: -25.740117 | D42: -13.097065
A43: 35612 | B43: 11.542781 | C43: -0.71725803 | D43: 11.542767
A44: 35643 | B44: 32.376007 | C44: 20.248377 | D44: 32.385996
A45: 35674 | B45: 29.064817 | C45: 17.274103 | D45: 29.069805
A46: 35704 | B46: 36.958565 | C46: 25.605442 | D46: 36.958583
A47: 35735 | B47: 49.5489 | C47: 38.610209 | D47: 49.548893
A48: 35765 | B48: 57.411579 | C48: 46.107023 | D48: 57.416603
A49: 35796 | B49: 65.269228 | C49: 54.111407 | D49: 65.269257
A50: 35827 | B50: 84.207985 | C50: 73.944942 | D50: 84.208012
... A274: 42644 | B274: 95.225376 | C274: 93.421904 | D274: 95.225376

Sheet burnout-old
A1: marketTicker | B1: asOf | C1: count(1) | D1: sum(p.schamBalance) | E1: burnout | H1: marketTicker | I1: FNCL | V1: marketTicker | W1: asOf | X1: count(1) | Y1: sum(p.schamBalance) | Z1: burnout | AC1: marketTicker | AD1: FGLMC
A2: FNCL | B2: 34366 | C2: 126636 | D2: 2.7849025e+11 | E2: 251.95761 | V2: FGLMC | W2: 34366 | X2: 47564 | Y2: 1.7936303e+11 | Z2: 145.28415
A3: FNCL | B3: 34394 | C3: 128266 | D3: 2.8205083e+11 | E3: 249.5091 | H3: Row Labels | I3: Sum of burnout | L3: CQ | M3: U6 | P3: FNCL | Q3: FGLMC | V3: FGLMC | W3: 34394 | X3: 48770 | Y3: 1.8267643e+11 | Z3: 143.04177 | AC3: Row Labels | AD3: Sum of burnout
A4: FNCL | B4: 34425 | C4: 129601 | D4: 2.838742e+11 | E4: 245.31636 | H4: 34366 | I4: 251.95761 | K4: 40118 | L4: 1.9218944 | O4: 34366 | P4: 251.95761 | Q4: =VLOOKUP(O4,AC:AD,2,0) -> 145.28415 | V4: FGLMC | W4: 34425 | X4: 50054 | Y4: 1.8717384e+11 | Z4: 137.08415 | AC4: 34366 | AD4: 145.28415
A5: FNCL | B5: 34455 | C5: 130768 | D5: 2.847529e+11 | E5: 236.85925 | H5: 34394 | I5: 249.5091 | K5: 40148 | L5: 0.64902249 | M5: 0 | O5: 34394 | P5: 249.5091 | Q5: =VLOOKUP(O5,AC:AD,2,0) -> 143.04177 | V5: FGLMC | W5: 34516 | X5: 53319 | Y5: 1.9825763e+11 | Z5: 118.36124 | AC5: 34394 | AD5: 143.04177
A6: FNCL | B6: 34486 | C6: 131996 | D6: 2.8712206e+11 | E6: 229.56331 | H6: 34425 | I6: 245.31636 | K6: 40179 | L6: 0.49452227 | M6: 4.9170627 | O6: 34425 | P6: 245.31636 | Q6: =VLOOKUP(O6,AC:AD,2,0) -> 137.08415 | V6: FGLMC | W6: 34547 | X6: 54110 | Y6: 2.0067919e+11 | Z6: 115.59347 | AC6: 34425 | AD6: 137.08415
A7: FNCL | B7: 34516 | C7: 133140 | D7: 2.8891975e+11 | E7: 224.50622 | H7: 34455 | I7: 236.85925 | K7: 40210 | L7: 0.35851172 | M7: 9.8069641 | O7: 34455 | P7: 236.85925 | Q7: =VLOOKUP(O7,AC:AD,2,0) -> #N/A | V7: FGLMC | W7: 34578 | X7: 54835 | Y7: 2.0294126e+11 | Z7: 113.6446 | AC7: 34516 | AD7: 118.36124
A8: FNCL | B8: 34547 | C8: 134153 | D8: 2.9064065e+11 | E8: 220.3634 | H8: 34486 | I8: 229.56331 | K8: 40238 | L8: 0.30684047 | M8: 11.961283 | O8: 34486 | P8: 229.56331 | Q8: =VLOOKUP(O8,AC:AD,2,0) -> #N/A | V8: FGLMC | W8: 34608 | X8: 55530 | Y8: 2.0522667e+11 | Z8: 111.80985 | AC8: 34547 | AD8: 115.59347
A9: FNCL | B9: 34578 | C9: 135077 | D9: 2.9202625e+11 | E9: 217.90412 | H9: 34516 | I9: 224.50622 | K9: 40269 | L9: 0.28064005 | M9: 13.703567 | O9: 34516 | P9: 224.50622 | Q9: =VLOOKUP(O9,AC:AD,2,0) -> 118.36124 | V9: FGLMC | W9: 34639 | X9: 56108 | Y9: 2.0697511e+11 | Z9: 110.08239 | AC9: 34578 | AD9: 113.6446
A10: FNCL | B10: 34608 | C10: 135888 | D10: 2.9339599e+11 | E10: 214.88641 | H10: 34547 | I10: 220.3634 | K10: 40299 | L10: 0.22090426 | M10: 13.939863 | O10: 34547 | P10: 220.3634 | Q10: =VLOOKUP(O10,AC:AD,2,0) -> 115.59347 | V10: FGLMC | W10: 34669 | X10: 56529 | Y10: 2.0775371e+11 | Z10: 108.86373 | AC10: 34608 | AD10: 111.80985
A11: FNCL | B11: 34639 | C11: 136567 | D11: 2.94792e+11 | E11: 211.8504 | H11: 34578 | I11: 217.90412 | K11: 40330 | L11: 0.17682655 | M11: 14.063196 | O11: 34578 | P11: 217.90412 | Q11: =VLOOKUP(O11,AC:AD,2,0) -> 113.6446 | V11: FGLMC | W11: 34700 | X11: 56894 | Y11: 2.0840618e+11 | Z11: 107.7822 | AC11: 34639 | AD11: 110.08239
A12: FNCL | B12: 34669 | C12: 137384 | D12: 2.9702273e+11 | E12: 208.49005 | H12: 34608 | I12: 214.88641 | K12: 40360 | L12: 0.29090501 | M12: 14.824078 | O12: 34608 | P12: 214.88641 | Q12: =VLOOKUP(O12,AC:AD,2,0) -> 111.80985 | V12: FGLMC | W12: 34731 | X12: 57294 | Y12: 2.0935918e+11 | Z12: 106.645 | AC12: 34669 | AD12: 108.86373
A13: FNCL | B13: 34700 | C13: 138175 | D13: 2.9953479e+11 | E13: 205.19476 | H13: 34639 | I13: 211.8504 | K13: 40391 | L13: 0.61043681 | M13: 15.693997 | O13: 34639 | P13: 211.8504 | Q13: =VLOOKUP(O13,AC:AD,2,0) -> 110.08239 | V13: FGLMC | W13: 34759 | X13: 57702 | Y13: 2.1044467e+11 | Z13: 105.83272 | AC13: 34700 | AD13: 107.7822
A14: FNCL | B14: 34731 | C14: 138749 | D14: 3.0057806e+11 | E14: 203.2055 | H14: 34669 | I14: 208.49005 | K14: 40422 | L14: 1.3809286 | M14: 14.553939 | O14: 34669 | P14: 208.49005 | Q14: =VLOOKUP(O14,AC:AD,2,0) -> 108.86373 | V14: FGLMC | W14: 34790 | X14: 58144 | Y14: 2.120786e+11 | Z14: 105.42317 | AC14: 34731 | AD14: 106.645
A15: FNCL | B15: 34759 | C15: 139252 | D15: 3.0151552e+11 | E15: 202.29015 | H15: 34700 | I15: 205.19476 | K15: 40452 | L15: 2.4290505 | M15: 13.262777 | O15: 34700 | P15: 205.19476 | Q15: =VLOOKUP(O15,AC:AD,2,0) -> 107.7822 | V15: FGLMC | W15: 34820 | X15: 58699 | Y15: 2.1408617e+11 | Z15: 105.17908 | AC15: 34759 | AD15: 105.83272
A16: FNCL | B16: 34790 | C16: 139640 | D16: 3.021308e+11 | E16: 202.84205 | H16: 34731 | I16: 203.2055 | K16: 40483 | L16: 3.9756242 | M16: 12.744435 | O16: 34731 | P16: 203.2055 | Q16: =VLOOKUP(O16,AC:AD,2,0) -> 106.645 | V16: FGLMC | W16: 34851 | X16: 59299 | Y16: 2.1598512e+11 | Z16: 106.29004 | AC16: 34790 | AD16: 105.42317
... A87: FNCL | B87: 36951 | C87: 210670 | D87: 7.2415943e+11 | E87: 142.83336 | H87: 36892 | I87: 136.03035 | K87: 42644 | L87: 536.29165 | M87: 203.35451 | O87: 36892 | P87: 136.03035 | Q87: =VLOOKUP(O87,AC:AD,2,0) -> 108.2777 | V87: FGLMC | W87: 37073 | X87: 119870 | Y87: 6.0680606e+11 | Z87: 121.89771 | AC87: 37012 | AD87: 123.80266
A88: FNCL | B88: 36982 | C88: 212403 | D88: 7.3713162e+11 | E88: 146.04587 | H88: 36923 | I88: 139.83109 | O88: 36923 | P88: 139.83109 | Q88: =VLOOKUP(O88,AC:AD,2,0) -> 112.88573 | V88: FGLMC | W88: 37104 | X88: 121166 | Y88: 6.1879176e+11 | Z88: 120.03616 | AC88: 37043 | AD88: 123.46542
A89: FNCL | B89: 37012 | C89: 214231 | D89: 7.5255621e+11 | E89: 145.93705 | H89: 36951 | I89: 142.83336 | O89: 36951 | P89: 142.83336 | Q89: =VLOOKUP(O89,AC:AD,2,0) -> 117.17362 | V89: FGLMC | W89: 37135 | X89: 122179 | Y89: 6.2884091e+11 | Z89: 121.14817 | AC89: 37073 | AD89: 121.89771
A90: FNCL | B90: 37043 | C90: 216060 | D90: 768634381863 | E90: 144.26662 | H90: 36982 | I90: 146.04587 | O90: 36982 | P90: 146.04587 | Q90: =VLOOKUP(O90,AC:AD,2,0) -> 121.95311 | V90: FGLMC | W90: 37165 | X90: 123141 | Y90: 6.3851928e+11 | Z90: 123.28032 | AC90: 37104 | AD90: 120.03616
A91: FNCL | B91: 37073 | C91: 217775 | D91: 7.838996e+11 | E91: 142.05361 | H91: 37012 | I91: 145.93705 | O91: 37012 | P91: 145.93705 | Q91: =VLOOKUP(O91,AC:AD,2,0) -> 123.80266 | V91: FGLMC | W91: 37196 | X91: 124004 | Y91: 6.4630665e+11 | Z91: 128.74472 | AC91: 37135 | AD91: 121.14817
A92: FNCL | B92: 37104 | C92: 219337 | D92: 800219895172 | E92: 140.23209 | H92: 37043 | I92: 144.26662 | O92: 37043 | P92: 144.26662 | Q92: =VLOOKUP(O92,AC:AD,2,0) -> 123.46542 | V92: FGLMC | W92: 37226 | X92: 124910 | Y92: 6.525821e+11 | Z92: 132.56423 | AC92: 37165 | AD92: 123.28032
A93: FNCL | B93: 37135 | C93: 220863 | D93: 8.1627696e+11 | E93: 140.24036 | H93: 37073 | I93: 142.05361 | O93: 37073 | P93: 142.05361 | Q93: =VLOOKUP(O93,AC:AD,2,0) -> 121.89771 | V93: FGLMC | W93: 37257 | X93: 125965 | Y93: 6.5648633e+11 | Z93: 130.0656 | AC93: 37196 | AD93: 128.74472
A94: FNCL | B94: 37165 | C94: 222193 | D94: 8.2934041e+11 | E94: 141.8189 | H94: 37104 | I94: 140.23209 | O94: 37104 | P94: 140.23209 | Q94: =VLOOKUP(O94,AC:AD,2,0) -> 120.03616 | V94: FGLMC | W94: 37288 | X94: 126547 | Y94: 6.562536e+11 | Z94: 127.54838 | AC94: 37226 | AD94: 132.56423
A95: FNCL | B95: 37196 | C95: 223572 | D95: 8.4108138e+11 | E95: 146.84808 | H95: 37135 | I95: 140.24036 | O95: 37135 | P95: 140.24036 | Q95: =VLOOKUP(O95,AC:AD,2,0) -> 121.14817 | V95: FGLMC | W95: 37316 | X95: 127084 | Y95: 6.6257802e+11 | Z95: 126.43465 | AC95: 37257 | AD95: 130.0656
A96: FNCL | B96: 37226 | C96: 225055 | D96: 8.5335439e+11 | E96: 149.0178 | H96: 37165 | I96: 141.8189 | O96: 37165 | P96: 141.8189 | Q96: =VLOOKUP(O96,AC:AD,2,0) -> 123.28032 | V96: FGLMC | W96: 37347 | X96: 127647 | Y96: 6.6788022e+11 | Z96: 123.78984 | AC96: 37288 | AD96: 127.54838
A97: FNCL | B97: 37257 | C97: 226605 | D97: 8.6500934e+11 | E97: 145.12474 | H97: 37196 | I97: 146.84808 | O97: 37196 | P97: 146.84808 | Q97: =VLOOKUP(O97,AC:AD,2,0) -> 128.74472 | V97: FGLMC | W97: 37377 | X97: 128359 | Y97: 6.7490772e+11 | Z97: 121.72259 | AC97: 37316 | AD97: 126.43465
A98: FNCL | B98: 37288 | C98: 227719 | D98: 8.6800265e+11 | E98: 141.90889 | H98: 37226 | I98: 149.0178 | O98: 37226 | P98: 149.0178 | Q98: =VLOOKUP(O98,AC:AD,2,0) -> 132.56423 | V98: FGLMC | W98: 37408 | X98: 128856 | Y98: 6.7812981e+11 | Z98: 122.71052 | AC98: 37347 | AD98: 123.78984
A99: FNCL | B99: 37316 | C99: 228962 | D99: 8.7969648e+11 | E99: 140.14657 | H99: 37257 | I99: 145.12474 | O99: 37257 | P99: 145.12474 | Q99: =VLOOKUP(O99,AC:AD,2,0) -> 130.0656 | V99: FGLMC | W99: 37438 | X99: 129396 | Y99: 6.8301745e+11 | Z99: 125.92833 | AC99: 37377 | AD99: 121.72259
... A272: FNCQ30 | B272: 40756 | C272: 417 | D272: 6.8720906e+09 | E272: 3.3781765 | H272: 42522 | I272: 747.51191 | O272: 42522 | P272: 747.51191 | Q272: =VLOOKUP(O272,AC:AD,2,0) -> 656.5497 | V272: FGLMC | W272: 40817 | X272: 165496 | Y272: 1.1395399e+12 | Z272: 468.70827 | AC272: 42644 | AD272: 670.332
A273: FNCK | B273: 40756 | C273: 1268 | D273: 5.8408841e+10 | E273: 101.89298 | H273: 42552 | I273: 751.47374 | O273: 42552 | P273: 751.47374 | Q273: =VLOOKUP(O273,AC:AD,2,0) -> 660.42479 | V273: FGT6 | W273: 40817 | X273: 375 | Y273: 6.5425466e+09 | Z273: 62.986194 | AC273: Grand Total | AD273: 73919.095
A274: FNCL | B274: 40787 | C274: 281942 | D274: 1.7360003e+12 | E274: 460.67966 | H274: 42583 | I274: 758.63197 | O274: 42583 | P274: 758.63197 | Q274: =VLOOKUP(O274,AC:AD,2,0) -> 665.08946 | V274: FGU6 | W274: 40817 | X274: 691 | Y274: 9.5534419e+09 | Z274: 13.360194
A275: FNCQ30 | B275: 40787 | C275: 437 | D275: 7.3938545e+09 | E275: 6.2995813 | H275: 42614 | I275: 763.25649 | O275: 42614 | P275: 763.25649 | Q275: =VLOOKUP(O275,AC:AD,2,0) -> 668.65915 | V275: FGLMC | W275: 40848 | X275: 165673 | Y275: 1.1287583e+12 | Z275: 487.75751
A276: FNCK | B276: 40787 | C276: 1327 | D276: 5.9412547e+10 | E276: 111.80566 | H276: 42644 | I276: 765.70794 | O276: 42644 | P276: 765.70794 | Q276: =VLOOKUP(O276,AC:AD,2,0) -> 670.332 | V276: FGT6 | W276: 40848 | X276: 420 | Y276: 7.2473259e+09 | Z276: 66.112071
A277: FNCL | B277: 40817 | C277: 282590 | D277: 1.7300621e+12 | E277: 479.35715 | H277: Grand Total | I277: 83134.214 | V277: FGU6 | W277: 40848 | X277: 724 | Y277: 1.001488e+10 | Z277: 13.361427
A278: FNCQ30 | B278: 40817 | C278: 461 | D278: 7.9908166e+09 | E278: 10.934382 | V278: FGLMC | W278: 40878 | X278: 165738 | Y278: 1.1127283e+12 | Z278: 508.87236
A279: FNCK | B279: 40817 | C279: 1392 | D279: 6.0879464e+10 | E279: 124.27176 | V279: FGT6 | W279: 40878 | X279: 454 | Y279: 7.9041058e+09 | Z279: 71.839435
A280: FNCL | B280: 40848 | C280: 283012 | D280: 1.7161114e+12 | E280: 499.022 | V280: FGU6 | W280: 40878 | X280: 767 | Y280: 1.0531877e+10 | Z280: 13.522223
A281: FNCQ30 | B281: 40848 | C281: 487 | D281: 8.5171652e+09 | E281: 14.836859 | V281: FGLMC | W281: 40909 | X281: 165766 | Y281: 1.0930802e+12 | Z281: 531.91417
A282: FNCK | B282: 40848 | C282: 1471 | D282: 6.1528555e+10 | E282: 132.97804 | V282: FGT6 | W282: 40909 | X282: 477 | Y282: 8.2800819e+09 | Z282: 80.471067
...

Sheet burnout-new
A1: marketTicker | B1: asOf | C1: count(1) | D1: sum(p.schamBalance) | E1: burnout | H1: marketTicker | I1: FNCL | W1: FNCQ | X1: FGU6 | Y1: FNCQ-new | Z1: adj | AD1: FNCQ | AE1: FGU6 | AF1: FNCQ-new
A2: FNCL | B2: 34366 | C2: 126636 | D2: 2.7849025e+11 | E2: 251.95761 | V2: 40118 | W2: 1.9218944 | Y2: 1.4505423 | Z2: =Y2 -> 1.4505423 | AC2: 34366 | AD2: 251.95761 | AE2: 145.28415 | AF2: 251.95761
A3: FNCL | B3: 34394 | C3: 128266 | D3: 2.8205083e+11 | E3: 249.5091 | H3: Row Labels | I3: Sum of burnout | V3: 40148 | W3: 0.64902249 | X3: 0 | Y3: 0.48012526 | Z3: =Y3 -> 0.48012526 | AC3: 34394 | AD3: 249.5091 | AE3: 143.04177 | AF3: 249.5091
A4: FNCL | B4: 34425 | C4: 129601 | D4: 2.838742e+11 | E4: 245.31636 | H4: 34366 | I4: 251.95761 | V4: 40179 | W4: 0.49452227 | X4: 4.9170627 | Y4: 0.32101831 | Z4: =Y4 -> 0.32101831 | AC4: 34425 | AD4: 245.31636 | AE4: 137.08415 | AF4: 245.31636
A5: FNCL | B5: 34455 | C5: 130768 | D5: 2.847529e+11 | E5: 236.85925 | H5: 34394 | I5: 249.5091 | V5: 40210 | W5: 0.35851172 | X5: 9.8069641 | Y5: 0.22558191 | Z5: =Y5 -> 0.22558191 | AC5: 34455 | AD5: 236.85925 | AE5: #N/A | AF5: 236.85925
A6: FNCL | B6: 34486 | C6: 131996 | D6: 2.8712206e+11 | E6: 229.56331 | H6: 34425 | I6: 245.31636 | V6: 40238 | W6: 0.30684047 | X6: 11.961283 | Y6: 0.18571925 | Z6: =Y6 -> 0.18571925 | AC6: 34486 | AD6: 229.56331 | AE6: #N/A | AF6: 229.56331
A7: FNCL | B7: 34516 | C7: 133140 | D7: 2.8891975e+11 | E7: 224.50622 | H7: 34455 | I7: 236.85925 | V7: 40269 | W7: 0.28064005 | X7: 13.703567 | Y7: 0.16611417 | Z7: =Y7 -> 0.16611417 | AC7: 34516 | AD7: 224.50622 | AE7: 118.36124 | AF7: 224.50622
A8: FNCL | B8: 34547 | C8: 134153 | D8: 2.9064065e+11 | E8: 220.3634 | H8: 34486 | I8: 229.56331 | V8: 40299 | W8: 0.22090426 | X8: 13.939863 | Y8: 0.13075737 | Z8: =Y8 -> 0.13075737 | AC8: 34547 | AD8: 220.3634 | AE8: 115.59347 | AF8: 220.3634
A9: FNCL | B9: 34578 | C9: 135077 | D9: 2.9202625e+11 | E9: 217.90412 | H9: 34516 | I9: 224.50622 | V9: 40330 | W9: 0.17682655 | X9: 14.063196 | Y9: 0.10466791 | Z9: =Y9 -> 0.10466791 | AC9: 34578 | AD9: 217.90412 | AE9: 113.6446 | AF9: 217.90412
A10: FNCL | B10: 34608 | C10: 135888 | D10: 2.9339599e+11 | E10: 214.88641 | H10: 34547 | I10: 220.3634 | V10: 40360 | W10: 0.29090501 | X10: 14.824078 | Y10: 0.087774893 | Z10: =Y10 -> 0.087774893 | AC10: 34608 | AD10: 214.88641 | AE10: 111.80985 | AF10: 214.88641
A11: FNCL | B11: 34639 | C11: 136567 | D11: 2.94792e+11 | E11: 211.8504 | H11: 34578 | I11: 217.90412 | V11: 40391 | W11: 0.61043681 | X11: 15.693997 | Y11: 0.082587727 | Z11: =Y11 -> 0.082587727 | AC11: 34639 | AD11: 211.8504 | AE11: 110.08239 | AF11: 211.8504
A12: FNCL | B12: 34669 | C12: 137384 | D12: 2.9702273e+11 | E12: 208.49005 | H12: 34608 | I12: 214.88641 | V12: 40422 | W12: 1.3809286 | X12: 14.553939 | Y12: 0.083798517 | Z12: =Y12 -> 0.083798517 | AC12: 34669 | AD12: 208.49005 | AE12: 108.86373 | AF12: 208.49005
A13: FNCL | B13: 34700 | C13: 138175 | D13: 2.9953479e+11 | E13: 205.19476 | H13: 34639 | I13: 211.8504 | V13: 40452 | W13: 2.4290505 | X13: 13.262777 | Y13: 0.081063264 | Z13: =Y13 -> 0.081063264 | AC13: 34700 | AD13: 205.19476 | AE13: 107.7822 | AF13: 205.19476
A14: FNCL | B14: 34731 | C14: 138749 | D14: 3.0057806e+11 | E14: 203.2055 | H14: 34669 | I14: 208.49005 | V14: 40483 | W14: 3.9756242 | X14: 12.744435 | Y14: 0.088173912 | Z14: =Y14 -> 0.088173912 | AC14: 34731 | AD14: 203.2055 | AE14: 106.645 | AF14: 203.2055
A15: FNCL | B15: 34759 | C15: 139252 | D15: 3.0151552e+11 | E15: 202.29015 | H15: 34700 | I15: 205.19476 | V15: 40513 | W15: 4.674049 | X15: 28.76601 | Y15: 0.088252045 | Z15: =Y15 -> 0.088252045 | AC15: 34759 | AD15: 202.29015 | AE15: 105.83272 | AF15: 202.29015
A16: FNCL | B16: 34790 | C16: 139640 | D16: 3.021308e+11 | E16: 202.84205 | H16: 34731 | I16: 203.2055 | V16: 40544 | W16: 4.1468342 | X16: 25.532554 | Y16: 0.076971532 | Z16: =Y16 -> 0.076971532 | AC16: 34790 | AD16: 202.84205 | AE16: 105.42317 | AF16: 202.84205
A17: FNCL | B17: 34820 | C17: 140171 | D17: 3.0319317e+11 | E17: 203.25316 | H17: 34759 | I17: 202.29015 | V17: 40575 | W17: 3.6643835 | X17: 22.865091 | Y17: 0.067492857 | Z17: =Y17 -> 0.067492857 | AC17: 34820 | AD17: 203.25316 | AE17: 105.17908 | AF17: 203.25316
A18: FNCL | B18: 34851 | C18: 140845 | D18: 3.052762e+11 | E18: 204.95903 | H18: 34790 | I18: 202.84205 | V18: 40603 | W18: 3.2371946 | X18: 19.619897 | Y18: 0.059694932 | Z18: =Y18 -> 0.059694932 | AC18: 34851 | AD18: 204.95903 | AE18: 106.29004 | AF18: 204.95903
... A36: FNCL | B36: 35400 | C36: 157183 | D36: 3.8057316e+11 | E36: 202.16336 | H36: 35339 | I36: 201.52113 | V36: 41153 | W36: 24.635723 | X36: 14.207314 | Y36: 0.38300337 | Z36: =Y36 -> 0.38300337 | AC36: 35400 | AD36: 202.16336 | AE36: 116.51091 | AF36: 202.16336
A37: FNCL | B37: 35431 | C37: 157961 | D37: 3.8357929e+11 | E37: 203.16046 | H37: 35370 | I37: 200.91033 | V37: 41183 | W37: 25.461006 | X37: 14.553131 | Y37: 0.44391159 | Z37: =Y37 -> 0.44391159 | AC37: 35431 | AD37: 203.16046 | AE37: #N/A | AF37: 203.16046
A38: FNCL | B38: 35462 | C38: 158587 | D38: 3.8562288e+11 | E38: 202.71587 | H38: 35400 | I38: 202.16336 | V38: 41214 | W38: 27.630828 | X38: 15.35103 | Y38: 0.57488644 | Z38: =Y38 -> 0.57488644 | AC38: 35462 | AD38: 202.71587 | AE38: #N/A | AF38: 202.71587
A39: FNCL | B39: 35490 | C39: 159328 | D39: 3.8894459e+11 | E39: 202.99673 | H39: 35431 | I39: 203.16046 | V39: 41244 | W39: 28.742283 | X39: 16.101464 | Y39: 0.68356834 | Z39: =Y39 -> 0.68356834 | AC39: 35490 | AD39: 202.99673 | AE39: 110.34651 | AF39: 202.99673
A40: FNCL | B40: 35521 | C40: 160031 | D40: 3.9199635e+11 | E40: 202.17957 | H40: 35462 | I40: 202.71587 | V40: 41275 | W40: 30.359266 | X40: 17.082345 | Y40: 0.79595639 | Z40: =Y40 -> 0.79595639 | AC40: 35521 | AD40: 202.17957 | AE40: 110.26799 | AF40: 202.17957
A41: FNCL | B41: 35551 | C41: 160667 | D41: 3.9440199e+11 | E41: 200.35044 | H41: 35490 | I41: 202.99673 | V41: 41306 | W41: 30.960673 | X41: 18.053924 | Y41: 0.84420618 | Z41: =Y41 -> 0.84420618 | AC41: 35551 | AD41: 200.35044 | AE41: 109.56182 | AF41: 200.35044
A42: FNCL | B42: 35582 | C42: 161332 | D42: 3.976503e+11 | E42: 198.6867 | H42: 35521 | I42: 202.17957 | V42: 41334 | W42: 30.921277 | X42: 18.711542 | Y42: 0.83879467 | Z42: =Y42 -> 0.83879467 | AC42: 35582 | AD42: 198.6867 | AE42: 109.49678 | AF42: 198.6867
A43: FNCL | B43: 35612 | C43: 161858 | D43: 3.9966136e+11 | E43: 199.10925 | H43: 35551 | I43: 200.35044 | V43: 41365 | W43: 31.023499 | X43: 22.694087 | Y43: 0.88038042 | Z43: =Y43 -> 0.88038042 | AC43: 35612 | AD43: 199.10925 | AE43: 110.16909 | AF43: 199.10925
A44: FNCL | B44: 35643 | C44: 162531 | D44: 4.0247325e+11 | E44: 200.42509 | H44: 35582 | I44: 198.6867 | V44: 41395 | W44: 31.877954 | X44: 24.062315 | Y44: 1.2000134 | Z44: =Y44 -> 1.2000134 | AC44: 35643 | AD44: 200.42509 | AE44: 112.09615 | AF44: 200.42509
A45: FNCL | B45: 35674 | C45: 163328 | D45: 4.07135e+11 | E45: 200.38467 | H45: 35612 | I45: 199.10925 | V45: 41426 | W45: 34.567711 | X45: 25.745124 | Y45: 1.9913455 | Z45: =Y45 -> 1.9913455 | AC45: 35674 | AD45: 200.38467 | AE45: 113.55314 | AF45: 200.38467
A46: FNCL | B46: 35704 | C46: 164171 | D46: 4.109579e+11 | E46: 201.35902 | H46: 35643 | I46: 200.42509 | V46: 41456 | W46: 36.19942 | X46: 25.846636 | Y46: 2.3755332 | Z46: =Y46 -> 2.3755332 | AC46: 35704 | AD46: 201.35902 | AE46: 115.57607 | AF46: 201.35902
A47: FNCL | B47: 35735 | C47: 164998 | D47: 4.1557814e+11 | E47: 202.58725 | H47: 35674 | I47: 200.38467 | V47: 41487 | W47: 37.409506 | X47: 25.620758 | Y47: 2.5159948 | Z47: =Y47 -> 2.5159948 | AC47: 35735 | AD47: 202.58725 | AE47: 117.82552 | AF47: 202.58725
A48: FNCL | B48: 35765 | C48: 165889 | D48: 4.2044218e+11 | E48: 204.24042 | H48: 35704 | I48: 201.35902 | V48: 41518 | W48: 38.802837 | X48: 25.460693 | Y48: 2.620359 | Z48: =Y48 -> 2.620359 | AC48: 35765 | AD48: 204.24042 | AE48: 120.97942 | AF48: 204.24042
A49: FNCL | B49: 35796 | C49: 166964 | D49: 4.2550701e+11 | E49: 206.67739 | H49: 35735 | I49: 202.58725 | V49: 41548 | W49: 40.350233 | X49: 25.388491 | Y49: 2.7321088 | Z49: =Y49 -> 2.7321088 | AC49: 35796 | AD49: 206.67739 | AE49: 124.5222 | AF49: 206.67739
A50: FNCL | B50: 35827 | C50: 167888 | D50: 4.3013336e+11 | E50: 210.98901 | H50: 35765 | I50: 204.24042 | V50: 41579 | W50: 43.29522 | X50: 26.104352 | Y50: 3.286884 | Z50: =Y50 -> 3.286884 | AC50: 35827 | AD50: 210.98901 | AE50: 131.45642 | AF50: 210.98901
... A52: FNCL | B52: 35886 | C52: 170201 | D52: 4.4057218e+11 | E52: 215.69953 | H52: 35827 | I52: 210.98901 | V52: 41640 | W52: 63.331362 | X52: 28.270617 | Y52: 3.7179778 | Z52: =Y52 -> 3.7179778 | AC52: 35886 | AD52: 215.69953 | AE52: 137.90438 | AF52: 215.69953
A53: FNCL | B53: 35916 | C53: 171456 | D53: 4.47378e+11 | E53: 212.55112 | H53: 35855 | I53: 214.89746 | V53: 41671 | W53: 301.14409 | X53: 28.53045 | Y53: 2.6061218 | Z53: =Y53-$AA$53 -> -235.2066 | AA53: =W53-W52 -> 237.81273 | AC53: 35916 | AD53: 212.55112 | AE53: 137.62608 | AF53: 212.55112
A54: FNCL | B54: 35947 | C54: 172582 | D54: 4.5460079e+11 | E54: 210.2175 | H54: 35886 | I54: 215.69953 | V54: 41699 | W54: 301.37205 | X54: 29.126172 | Y54: 5.874234 | Z54: =Y54-$AA$53 -> -231.93849 | AC54: 35947 | AD54: 210.2175 | AE54: 137.19933 | AF54: 210.2175
A55: FNCL | B55: 35977 | C55: 173773 | D55: 4.6333752e+11 | E55: 209.55848 | H55: 35916 | I55: 212.55112 | V55: 41730 | W55: 301.98822 | X55: 29.717152 | Y55: 9.0169566 | Z55: =Y55-$AA$53 -> -228.79577 | AC55: 35977 | AD55: 209.55848 | AE55: 138.6348 | AF55: 209.55848
A56: FNCL | B56: 36008 | C56: 174901 | D56: 4.7396393e+11 | E56: 208.0412 | H56: 35947 | I56: 210.2175 | V56: 41760 | W56: 302.78433 | X56: 30.470586 | Y56: 12.257541 | Z56: =Y56-$AA$53 -> -225.55518 | AC56: 36008 | AD56: 208.0412 | AE56: 140.24654 | AF56: 208.0412
A57: FNCL | B57: 36039 | C57: 175971 | D57: 482637195788 | E57: 207.67492 | H57: 35977 | I57: 209.55848 | V57: 41791 | W57: 305.36428 | X57: 31.918593 | Y57: 16.767147 | Z57: =Y57-$AA$53 -> -221.04558 | AC57: 36039 | AD57: 207.67492 | AE57: 143.133 | AF57: 207.67492
A58: FNCL | B58: 36069 | C58: 177221 | D58: 4.9275968e+11 | E58: 209.86963 | H58: 36008 | I58: 208.0412 | V58: 41821 | W58: 307.67519 | X58: 33.538877 | Y58: 21.453039 | Z58: =Y58-$AA$53 -> -216.35969 | AC58: 36069 | AD58: 209.86963 | AE58: 148.92795 | AF58: 209.86963
...

Sheet Sheet6
A1: marketTicker | B1: asOf | C1: count(1) | D1: sum(p.schamBalance) | E1: burnout | H1: marketTicker | I1: FNCQ30 | T1: marketTicker | U1: asOf | V1: count(1) | W1: sum(slh.schamBalance) | X1: wavg_burnout | Z1: marketTicker | AA1: FNCQ30 | AD1: marketTicker | AE1: asOf | AF1: count(1) | AG1: sum(slh.schamBalance) | AH1: wavg_burnout | AJ1: marketTicker | AK1: asOf | AL1: count(1) | AM1: sum(slh.schamBalance) | AN1: wavg_burnout
A2: FNCL | B2: 34366 | C2: 126636 | D2: 2.7849025e+11 | E2: (NULL) | T2: FNCK | U2: 41640 | V2: 37828 | W2: 1.9926412e+10 | X2: 0.010594034 | AD2: FNCK | AE2: 41640 | AF2: 37816 | AG2: 1.9920516e+10 | AH2: 0.18571326 | AJ2: FNCK | AK2: 41640 | AL2: 37816 | AM2: 1.9920516e+10 | AN2: 0.18571326
A3: FNCL | B3: 34394 | C3: 128266 | D3: 2.8205083e+11 | E3: (NULL) | H3: Row Labels | I3: Sum of burnout | T3: FNCL | U3: 41640 | V3: 2112785 | W3: 4.5076035e+11 | X3: 0.015537335 | Z3: Row Labels | AA3: Sum of wavg_burnout | AD3: FNCL | AE3: 41640 | AF3: 2103627 | AG3: 4.4889765e+11 | AH3: 0.22499285 | AJ3: FNCL | AK3: 41640 | AL3: 2103627 | AM3: 4.4889765e+11 | AN3: 0.22499285
A4: FNCL | B4: 34425 | C4: 129601 | D4: 2.838742e+11 | E4: (NULL) | H4: 40118 | I4: 0 | T4: FNCQ30 | U4: 41640 | V4: 91949 | W4: 1.7744983e+10 | X4: 0.0016875501 | Z4: 41640 | AA4: 0.0016875501 | AD4: FNCQ30 | AE4: 41640 | AF4: 91865 | AG4: 1.7728747e+10 | AH4: 0.43631298 | AJ4: FNCQ30 | AK4: 41640 | AL4: 91865 | AM4: 1.7728747e+10 | AN4: 0.43631298
A5: FNCL | B5: 34455 | C5: 130768 | D5: 2.847529e+11 | E5: (NULL) | H5: 40148 | I5: 0 | T5: FNCR | U5: 41640 | V5: 91858 | W5: 1.7481058e+10 | X5: 4.4024115e-05 | Z5: 41671 | AA5: 0.026066012 | AD5: FNCR | AE5: 41640 | AF5: 91779 | AG5: 1.7466812e+10 | AH5: 0.54303922 | AJ5: FNCR | AK5: 41640 | AL5: 91779 | AM5: 1.7466812e+10 | AN5: 0.54303922
A6: FNCL | B6: 34486 | C6: 131996 | D6: 2.8712206e+11 | E6: (NULL) | H6: 40179 | I6: 0 | T6: FNCK | U6: 41671 | V6: 148776 | W6: 5.9263029e+10 | X6: 0.039293765 | Z6: 41699 | AA6: 0.058762658 | AD6: FNCL | AE6: 41671 | AF6: 9 | AG6: 1520873.2 | AH6: 0.48496053 | AJ6: FNCL | AK6: 41671 | AL6: 9 | AM6: 1520873.2 | AN6: 0.48496053
A7: FNCL | B7: 34516 | C7: 133140 | D7: 2.8891975e+11 | E7: (NULL) | H7: 40210 | I7: 0 | T7: FNCL | U7: 41671 | V7: 11073971 | W7: 1.6428024e+12 | X7: 0.095004051 | Z7: 41730 | AA7: 0.090205503 | AD7: FNCL | AE7: 41699 | AF7: 9 | AG7: 1518652.7 | AH7: 0.54023761 | AJ7: FNCL | AK7: 41699 | AL7: 9 | AM7: 1518652.7 | AN7: 0.54023761
A8: FNCL | B8: 34547 | C8: 134153 | D8: 2.9064065e+11 | E8: (NULL) | H8: 40238 | I8: 0 | T8: FNCQ30 | U8: 41671 | V8: 248074 | W8: 4.8668276e+10 | X8: 0.026066012 | Z8: 41760 | AA8: 0.12262935 | AD8: FNCL | AE8: 41730 | AF8: 9 | AG8: 1515641.6 | AH8: 0.59423959 | AJ8: FNCL | AK8: 41730 | AL8: 9 | AM8: 1515641.6 | AN8: 0.59423959
A9: FNCL | B9: 34578 | C9: 135077 | D9: 2.9202625e+11 | E9: (NULL) | H9: 40269 | I9: 0 | T9: FNCR | U9: 41671 | V9: 203053 | W9: 3.9453982e+10 | X9: 0.00059409691 | Z9: 41791 | AA9: 0.16776423 | AD9: FNCL | AE9: 41760 | AF9: 9 | AG9: 1513395.2 | AH9: 0.64804679 | AJ9: FNCL | AK9: 41760 | AL9: 9 | AM9: 1513395.2 | AN9: 0.64804679
A10: FNCL | B10: 34608 | C10: 135888 | D10: 2.9339599e+11 | E10: (NULL) | H10: 40299 | I10: 0 | T10: FNCK | U10: 41699 | V10: 149368 | W10: 5.9112508e+10 | X10: 0.08715663 | Z10: 41821 | AA10: 0.21466752 | AD10: FNCL | AE10: 41791 | AF10: 9 | AG10: 1511172.3 | AH10: 0.71894735 | AJ10: FNCL | AK10: 41791 | AL10: 9 | AM10: 1511172.3 | AN10: 0.71894735
A11: FNCL | B11: 34639 | C11: 136567 | D11: 2.94792e+11 | E11: (NULL) | H11: 40330 | I11: 0 | T11: FNCL | U11: 41699 | V11: 11155252 | W11: 1.6450737e+12 | X11: 0.19935541 | Z11: 41852 | AA11: 0.26423443 | AD11: FNCL | AE11: 41821 | AF11: 9 | AG11: 1508941.6 | AH11: 0.79230211 | AJ11: FNCL | AK11: 41821 | AL11: 9 | AM11: 1508941.6 | AN11: 0.79230211
A12: FNCL | B12: 34669 | C12: 137384 | D12: 2.9702273e+11 | E12: (NULL) | H12: 40360 | I12: 0 | T12: FNCQ30 | U12: 41699 | V12: 250091 | W12: 4.8824847e+10 | X12: 0.058762658 | Z12: 41883 | AA12: 0.31604248 | AD12: FNCL | AE12: 41852 | AF12: 8 | AG12: 1376290 | AH12: 0.87850373 | AJ12: FNCL | AK12: 41852 | AL12: 8 | AM12: 1376290 | AN12: 0.87850373
A13: FNCL | B13: 34700 | C13: 138175 | D13: 2.9953479e+11 | E13: (NULL) | H13: 40391 | I13: 0 | T13: FNCR | U13: 41699 | V13: 204423 | W13: 3.9545065e+10 | X13: 0.0016027638 | Z13: 41913 | AA13: 0.36634402 | AD13: FNCL | AE13: 41883 | AF13: 6 | AG13: 980274.29 | AH13: 1.3530897 | AJ13: FNCL | AK13: 41883 | AL13: 6 | AM13: 980274.29 | AN13: 1.3530897
A14: FNCL | B14: 34731 | C14: 138749 | D14: 3.0057806e+11 | E14: (NULL) | H14: 40422 | I14: 0 | T14: FNCK | U14: 41730 | V14: 149680 | W14: 5.8882336e+10 | X14: 0.13332404 | Z14: 41944 | AA14: 0.42917005 | AD14: FNCL | AE14: 41913 | AF14: 6 | AG14: 978872.18 | AH14: 1.4683962 | AJ14: FNCL | AK14: 41913 | AL14: 6 | AM14: 978872.18 | AN14: 1.4683962
A15: FNCL | B15: 34759 | C15: 139252 | D15: 3.0151552e+11 | E15: (NULL) | H15: 40452 | I15: 0 | T15: FNCL | U15: 41730 | V15: 11224581 | W15: 1.6458998e+12 | X15: 0.29963735 | Z15: 41974 | AA15: 0.49614808 | AD15: FNCL | AE15: 41944 | AF15: 12 | AG15: 1976818.2 | AH15: 0.67667196 | AJ15: FNCL | AK15: 41944 | AL15: 12 | AM15: 1976818.2 | AN15: 0.67667196
... A19: FNCL | B19: 34881 | C19: 141735 | D19: 3.0857951e+11 | E19: (NULL) | H19: 40575 | I19: 0 | T19: FNCL | U19: 41760 | V19: 11302026 | W19: 1.6472037e+12 | X19: 0.39658817 | Z19: 42095 | AA19: 0.90415384 | AD19: FNCL | AE19: 42064 | AF19: 2 | AG19: 489893.13 | AH19: 1.0024645 | AJ19: FNCL | AK19: 42064 | AL19: 2 | AM19: 489893.13 | AN19: 1.0024645
A20: FNCL | B20: 34912 | C20: 142847 | D20: 3.1330609e+11 | E20: (NULL) | H20: 40603 | I20: 0 | T20: FNCQ30 | U20: 41760 | V20: 252880 | W20: 4.8833988e+10 | X20: 0.12262935 | Z20: 42125 | AA20: 1.0168506 | AD20: FNCL | AE20: 42095 | AF20: 1 | AG20: 132862.57 | AH20: 0.19261922
A21: FNCL | B21: 34943 | C21: 143912 | D21: 3.1785586e+11 | E21: (NULL) | H21: 40634 | I21: 0 | T21: FNCR | U21: 41760 | V21: 206231 | W21: 3.9571745e+10 | X21: 0.0033200706 | Z21: 42156 | AA21: 1.1073703
A22: FNCL | B22: 34973 | C22: 144902 | D22: 3.2193807e+11 | E22: (NULL) | H22: 40664 | I22: 0 | T22: FNCK | U22: 41791 | V22: 150377 | W22: 5.8302886e+10 | X22: 0.24663304 | Z22: 42186 | AA22: 1.179398
A23: FNCL | B23: 35004 | C23: 145867 | D23: 3.2658666e+11 | E23: (NULL) | H23: 40695 | I23: 0 | T23: FNCL | U23: 41791 | V23: 11379639 | W23: 1.6477623e+12 | X23: 0.51642661 | Z23: 42217 | AA23: 1.2460954
A24: FNCL | B24: 35034 | C24: 146882 | D24: 3.3196489e+11 | E24: (NULL) | H24: 40725 | I24: 0 | T24: FNCQ30 | U24: 41791 | V24: 253638 | W24: 4.8703898e+10 | X24: 0.16776423 | Z24: 42248 | AA24: 1.3331945
A25: FNCL | B25: 35065 | C25: 147919 | D25: 3.3730406e+11 | E25: (NULL) | H25: 40756 | I25: 0 | T25: FNCR | U25: 41791 | V25: 206723 | W25: 3.9499963e+10 | X25: 0.0052458411 | Z25: 42278 | AA25: 1.4232993
A26: FNCL | B26: 35096 | C26: 148833 | D26: 3.4167242e+11 | E26: (NULL) | H26: 40787 | I26: 0 | T26: FNCK | U26: 41821 | V26: 150750 | W26: 5.7986266e+10 | X26: 0.31493176 | Z26: 42309 | AA26: 1.5264951
A27: FNCL | B27: 35125 | C27: 149785 | D27: 3.4654545e+11 | E27: (NULL) | H27: 40817 | I27: 0 | T27: FNCL | U27: 41821 | V27: 11469276 | W27: 1.6506931e+12 | X27: 0.63476562 | Z27: 42339 | AA27: 1.6086768
A28: FNCL | B28: 35156 | C28: 150727 | D28: 3.5046556e+11 | E28: (NULL) | H28: 40848 | I28: 0 | T28: FNCQ30 | U28: 41821 | V28: 254650 | W28: 4.8587339e+10 | X28: 0.21466752 | Z28: 42370 | AA28: 1.69109
A29: FNCL | B29: 35186 | C29: 151726 | D29: 3.5468325e+11 | E29: (NULL) | H29: 40878 | I29: 0 | T29: FNCR | U29: 41821 | V29: 207239 | W29: 3.9425086e+10 | X29: 0.0074383333 | Z29: 42401 | AA29: 1.7850472
A30: FNCL | B30: 35217 | C30: 152681 | D30: 3.5915351e+11 | E30: (NULL) | H30: 40909 | I30: 0 | T30: FNCK | U30: 41852 | V30: 151375 | W30: 5.7752775e+10 | X30: 0.38339101 | Z30: 42430 | AA30: 1.9155648
A31: FNCL | B31: 35247 | C31: 153592 | D31: 3.6414591e+11 | E31: (NULL) | H31: 40940 | I31: 0 | T31: FNCL | U31: 41852 | V31: 11570260 | W31: 1.6549038e+12 | X31: 0.75117856 | Z31: 42461 | AA31: 2.0561627
A32: FNCL | B32: 35278 | C32: 154353 | D32: 3.6784358e+11 | E32: (NULL) | H32: 40969 | I32: 0 | T32: FNCQ30 | U32: 41852 | V32: 255445 | W32: 4.8410068e+10 | X32: 0.26423443 | Z32: 42491 | AA32: 2.1973782
... A37: FNCL | B37: 35431 | C37: 157961 | D37: 3.8357929e+11 | E37: (NULL) | H37: 41122 | I37: 0 | T37: FNCR | U37: 41883 | V37: 208054 | W37: 3.922889e+10 | X37: 0.012840728 | Z37: 42644 | AA37: 3.0168821
A38: FNCL | B38: 35462 | C38: 158587 | D38: 3.8562288e+11 | E38: (NULL) | H38: 41153 | I38: 0 | T38: FNCK | U38: 41913 | V38: 152755 | W38: 5.7277588e+10 | X38: 0.51670783 | Z38: Grand Total | AA38: 38.997003
A39: FNCL | B39: 35490 | C39: 159328 | D39: 3.8894459e+11 | E39: (NULL) | H39: 41183 | I39: 0 | T39: FNCL | U39: 41913 | V39: 11773649 | W39: 1.664206e+12 | X39: 0.97319959
A40: FNCL | B40: 35521 | C40: 160031 | D40: 3.9199635e+11 | E40: (NULL) | H40: 41214 | I40: 0 | T40: FNCQ30 | U40: 41913 | V40: 256953 | W40: 4.7991344e+10 | X40: 0.36634402
A41: FNCL | B41: 35551 | C41: 160667 | D41: 3.9440199e+11 | E41: (NULL) | H41: 41244 | I41: 0 | T41: FNCR | U41: 41913 | V41: 208376 | W41: 3.9117482e+10 | X41: 0.015682418
A42: FNCL | B42: 35582 | C42: 161332 | D42: 3.976503e+11 | E42: (NULL) | H42: 41275 | I42: 0 | T42: FNCK | U42: 41944 | V42: 153320 | W42: 5.7006381e+10 | X42: 0.59887014
A43: FNCL | B43: 35612 | C43: 161858 | D43: 3.9966136e+11 | E43: (NULL) | H43: 41306 | I43: 0 | T43: FNCL | U43: 41944 | V43: 11879695 | W43: 1.6700859e+12 | X43: 1.0979696
A44: FNCL | B44: 35643 | C44: 162531 | D44: 4.0247325e+11 | E44: (NULL) | H44: 41334 | I44: 0 | T44: FNCQ30 | U44: 41944 | V44: 257530 | W44: 4.7764623e+10 | X44: 0.42917005
A45: FNCL | B45: 35674 | C45: 163328 | D45: 4.07135e+11 | E45: (NULL) | H45: 41365 | I45: 0 | T45: FNCR | U45: 41944 | V45: 208693 | W45: 3.900735e+10 | X45: 0.020163356
A46: FNCL | B46: 35704 | C46: 164171 | D46: 4.109579e+11 | E46: (NULL) | H46: 41395 | I46: 0 | T46: FNCK | U46: 41974 | V46: 153920 | W46: 5.6722992e+10 | X46: 0.68461737
A47: FNCL | B47: 35735 | C47: 164998 | D47: 4.1557814e+11 | E47: (NULL) | H47: 41426 | I47: 0 | T47: FNCL | U47: 41974 | V47: 11972745 | W47: 1.6732042e+12 | X47: 1.2267024
...

Sheet Sheet1
N42: 100000 | O42: 880
N43: 100 | O43: =O42/N42*100 -> 0.88
