Workbook

Sheet conventional_refi_elig-old
A1: marketTicker | B1: asOf | C1: count(1) | D1: sum(p.schamBalance) | E1: wavg_pct_conventional_eligible | H1: marketTicker | I1: FNCL | U1: marketTicker | V1: asOf | W1: count(1) | X1: sum(p.schamBalance) | Y1: wavg_pct_conventional_eligible | AA1: marketTicker | AB1: FGLMC
A2: FNCL | B2: 34366 | C2: 126636 | D2: 2.7849025e+11 | E2: 100 | U2: FGLMC | V2: 34366 | W2: 47564 | X2: 1.7936303e+11 | Y2: 99.042895
A3: FNCL | B3: 34394 | C3: 128266 | D3: 2.8205083e+11 | E3: 100 | H3: Row Labels | I3: Sum of wavg_pct_conventional_eligible | U3: FGLMC | V3: 34394 | W3: 48770 | X3: 1.8267643e+11 | Y3: 98.72842 | AA3: Row Labels | AB3: Sum of wavg_pct_conventional_eligible
A4: FNCL | B4: 34425 | C4: 129601 | D4: 2.838742e+11 | E4: 100 | H4: 34366 | I4: 100 | U4: FGLMC | V4: 34425 | W4: 50054 | X4: 1.8717384e+11 | Y4: 98.420927 | AA4: 34366 | AB4: 99.042895
A5: FNCL | B5: 34455 | C5: 130768 | D5: 2.847529e+11 | E5: 100 | H5: 34394 | I5: 100 | U5: FGLMC | V5: 34516 | W5: 53319 | X5: 1.9825763e+11 | Y5: 97.681204 | AA5: 34394 | AB5: 98.72842
A6: FNCL | B6: 34486 | C6: 131996 | D6: 2.8712206e+11 | E6: 100 | H6: 34425 | I6: 100 | U6: FGLMC | V6: 34547 | W6: 54110 | X6: 2.0067919e+11 | Y6: 97.503899 | AA6: 34425 | AB6: 98.420927
A7: FNCL | B7: 34516 | C7: 133140 | D7: 2.8891975e+11 | E7: 100 | H7: 34455 | I7: 100 | U7: FGLMC | V7: 34578 | W7: 54835 | X7: 2.0294126e+11 | Y7: 97.356955 | AA7: 34516 | AB7: 97.681204
A8: FNCL | B8: 34547 | C8: 134153 | D8: 2.9064065e+11 | E8: 100 | H8: 34486 | I8: 100 | U8: FGLMC | V8: 34608 | W8: 55530 | X8: 2.0522667e+11 | Y8: 97.202263 | AA8: 34547 | AB8: 97.503899
A9: FNCL | B9: 34578 | C9: 135077 | D9: 2.9202625e+11 | E9: 100 | H9: 34516 | I9: 100 | U9: FGLMC | V9: 34639 | W9: 56108 | X9: 2.0697511e+11 | Y9: 97.077694 | AA9: 34578 | AB9: 97.356955
A10: FNCL | B10: 34608 | C10: 135888 | D10: 2.9339599e+11 | E10: 100 | H10: 34547 | I10: 100 | U10: FGLMC | V10: 34669 | W10: 56529 | X10: 2.0775371e+11 | Y10: 96.978985 | AA10: 34608 | AB10: 97.202263
A11: FNCL | B11: 34639 | C11: 136567 | D11: 2.94792e+11 | E11: 100 | H11: 34578 | I11: 100 | U11: FGLMC | V11: 34700 | W11: 56894 | X11: 2.0840618e+11 | Y11: 96.901214 | AA11: 34639 | AB11: 97.077694
A12: FNCL | B12: 34669 | C12: 137384 | D12: 2.9702273e+11 | E12: 100 | H12: 34608 | I12: 100 | U12: FGLMC | V12: 34731 | W12: 57294 | X12: 2.0935918e+11 | Y12: 96.79793 | AA12: 34669 | AB12: 96.978985
A13: FNCL | B13: 34700 | C13: 138175 | D13: 2.9953479e+11 | E13: 100 | H13: 34639 | I13: 100 | U13: FGLMC | V13: 34759 | W13: 57702 | X13: 2.1044467e+11 | Y13: 96.704604 | AA13: 34700 | AB13: 96.901214
A14: FNCL | B14: 34731 | C14: 138749 | D14: 3.0057806e+11 | E14: 100 | H14: 34669 | I14: 100 | U14: FGLMC | V14: 34790 | W14: 58144 | X14: 2.120786e+11 | Y14: 96.580893 | AA14: 34731 | AB14: 96.79793
A15: FNCL | B15: 34759 | C15: 139252 | D15: 3.0151552e+11 | E15: 100 | H15: 34700 | I15: 100 | U15: FGLMC | V15: 34820 | W15: 58699 | X15: 2.1408617e+11 | Y15: 96.415451 | AA15: 34759 | AB15: 96.704604
... A272: FNCQ30 | B272: 40756 | C272: 417 | D272: 6.8720906e+09 | E272: 0 | H272: 42522 | I272: 80.844712 | U272: FGLMC | V272: 40817 | W272: 165496 | X272: 1.1395399e+12 | Y272: 82.080865 | AA272: 42644 | AB272: 98.507721
A273: FNCK | B273: 40756 | C273: 1268 | D273: 5.8408841e+10 | E273: 94.4086 | H273: 42552 | I273: 81.316631 | U273: FGT6 | V273: 40817 | W273: 375 | X273: 6.5425466e+09 | Y273: 99.115497 | AA273: Grand Total | AB273: 24250.897
A274: FNCL | B274: 40787 | C274: 281942 | D274: 1.7360003e+12 | E274: 32.764034 | H274: 42583 | I274: 81.746914 | U274: FGU6 | V274: 40817 | W274: 691 | X274: 9.5534419e+09 | Y274: 0.026814301
A275: FNCQ30 | B275: 40787 | C275: 437 | D275: 7.3938545e+09 | E275: 0 | H275: 42614 | I275: 82.263257 | U275: FGLMC | V275: 40848 | W275: 165673 | X275: 1.1287583e+12 | Y275: 81.852423
A276: FNCK | B276: 40787 | C276: 1327 | D276: 5.9412547e+10 | E276: 94.733558 | H276: 42644 | I276: 82.742466 | U276: FGT6 | V276: 40848 | W276: 420 | X276: 7.2473259e+09 | Y276: 99.004683
A277: FNCL | B277: 40817 | C277: 282590 | D277: 1.7300621e+12 | E277: 33.314262 | H277: Grand Total | I277: 9985.1449 | U277: FGU6 | V277: 40848 | W277: 724 | X277: 1.001488e+10 | Y277: 0.028386633
A278: FNCQ30 | B278: 40817 | C278: 461 | D278: 7.9908166e+09 | E278: 0 | U278: FGLMC | V278: 40878 | W278: 165738 | X278: 1.1127283e+12 | Y278: 81.548158
A279: FNCK | B279: 40817 | C279: 1392 | D279: 6.0879464e+10 | E279: 94.955293 | U279: FGT6 | V279: 40878 | W279: 454 | X279: 7.9041058e+09 | Y279: 99.007416
A280: FNCL | B280: 40848 | C280: 283012 | D280: 1.7161114e+12 | E280: 33.857405 | U280: FGU6 | V280: 40878 | W280: 767 | X280: 1.0531877e+10 | Y280: 0.035833976
A281: FNCQ30 | B281: 40848 | C281: 487 | D281: 8.5171652e+09 | E281: 0 | U281: FGLMC | V281: 40909 | W281: 165766 | X281: 1.0930802e+12 | Y281: 81.4988
A282: FNCK | B282: 40848 | C282: 1471 | D282: 6.1528555e+10 | E282: 95.068088 | U282: FGT6 | V282: 40909 | W282: 477 | X282: 8.2800819e+09 | Y282: 99.075969
A283: FNCL | B283: 40878 | C283: 283516 | D283: 1.704192e+12 | E283: 34.479221 | U283: FGU6 | V283: 40909 | W283: 787 | X283: 1.0704728e+10 | Y283: 0.041563006
A284: FNCQ30 | B284: 40878 | C284: 514 | D284: 9.0740215e+09 | E284: 0 | U284: FGLMC | V284: 40940 | W284: 165773 | X284: 1.0814107e+12 | Y284: 81.497876
A285: FNCK | B285: 40878 | C285: 1523 | D285: 6.343284e+10 | E285: 93.392118 | U285: FGT6 | V285: 40940 | W285: 506 | X285: 9.1772409e+09 | Y285: 99.282856
A286: FNCL | B286: 40909 | C286: 284179 | D286: 1.7047182e+12 | E286: 35.260333 | U286: FGU6 | V286: 40940 | W286: 834 | X286: 1.1647194e+10 | Y286: 0.041739208
A287: FNCQ30 | B287: 40909 | C287: 537 | D287: 9.4003226e+09 | E287: 0 | U287: FGLMC | V287: 40969 | W287: 165846 | X287: 1.0781765e+12 | Y287: 83.555137
A288: FNCK | B288: 40909 | C288: 1561 | D288: 6.3431287e+10 | E288: 93.607801 | U288: FGT6 | V288: 40969 | W288: 540 | X288: 9.8606952e+09 | Y288: 99.530771
A289: FNCL | B289: 40940 | C289: 284757 | D289: 1.6958104e+12 | E289: 35.859228 | U289: FGU6 | V289: 40969 | W289: 875 | X289: 1.2353959e+10 | Y289: 0.058641666
... A506: FNCL | B506: 42614 | C506: 310733 | D506: 1.7881847e+12 | E506: 82.263257 | U506: FGU6 | V506: 42644 | W506: 4021 | X506: 2.8689194e+10 | Y506: 75.577792
A507: FNCR | B507: 42614 | C507: 1385 | D507: 3.4088681e+10 | E507: 9.7493767
A508: FNCL | B508: 42644 | C508: 311376 | D508: 1.7941305e+12 | E508: 82.742466
A509: FNCQ30 | B509: 42644 | C509: 2155 | D509: 3.8990715e+10 | E509: 34.506461
A510: FNCK | B510: 42644 | C510: 2303 | D510: 5.6641835e+10 | E510: 96.843677
A511: FNCR | B511: 42644 | C511: 1390 | D511: 3.3686514e+10 | E511: 9.9036506

Sheet conventional_refi_elig-new
A1: marketTicker | B1: asOf | C1: count(1) | D1: sum(p.schamBalance) | E1: conventional_eligible | G1: marketTicker | H1: FNCL | V1: FNCL | W1: FGLMC | X1: FNCL-new
A2: FNCL | B2: 34366 | C2: 126636 | D2: 2.7849025e+11 | E2: 87.51949 | U2: 34366 | V2: 100 | W2: =VLOOKUP(U2,'conventional_refi_elig-old'!AA:AB,2,0) -> 99.042895 | X2: 87.51949
A3: FNCL | B3: 34394 | C3: 128266 | D3: 2.8205083e+11 | E3: 87.536095 | G3: Row Labels | H3: Sum of conventional_eligible | U3: 34394 | V3: 100 | W3: =VLOOKUP(U3,'conventional_refi_elig-old'!AA:AB,2,0) -> 98.72842 | X3: 87.536095
A4: FNCL | B4: 34425 | C4: 129601 | D4: 2.838742e+11 | E4: 87.48246 | G4: 34366 | H4: 87.51949 | U4: 34425 | V4: 100 | W4: =VLOOKUP(U4,'conventional_refi_elig-old'!AA:AB,2,0) -> 98.420927 | X4: 87.48246
A5: FNCL | B5: 34455 | C5: 130768 | D5: 2.847529e+11 | E5: 87.493192 | G5: 34394 | H5: 87.536095 | U5: 34455 | V5: 100 | W5: =VLOOKUP(U5,'conventional_refi_elig-old'!AA:AB,2,0) -> #N/A | X5: 87.493192
A6: FNCL | B6: 34486 | C6: 131996 | D6: 2.8712206e+11 | E6: 87.523951 | G6: 34425 | H6: 87.48246 | U6: 34486 | V6: 100 | W6: =VLOOKUP(U6,'conventional_refi_elig-old'!AA:AB,2,0) -> #N/A | X6: 87.523951
A7: FNCL | B7: 34516 | C7: 133140 | D7: 2.8891975e+11 | E7: 87.55596 | G7: 34455 | H7: 87.493192 | U7: 34516 | V7: 100 | W7: =VLOOKUP(U7,'conventional_refi_elig-old'!AA:AB,2,0) -> 97.681204 | X7: 87.55596
A8: FNCL | B8: 34547 | C8: 134153 | D8: 2.9064065e+11 | E8: 87.584157 | G8: 34486 | H8: 87.523951 | U8: 34547 | V8: 100 | W8: =VLOOKUP(U8,'conventional_refi_elig-old'!AA:AB,2,0) -> 97.503899 | X8: 87.584157
A9: FNCL | B9: 34578 | C9: 135077 | D9: 2.9202625e+11 | E9: 87.60921 | G9: 34516 | H9: 87.55596 | U9: 34578 | V9: 100 | W9: =VLOOKUP(U9,'conventional_refi_elig-old'!AA:AB,2,0) -> 97.356955 | X9: 87.60921
A10: FNCL | B10: 34608 | C10: 135888 | D10: 2.9339599e+11 | E10: 87.640087 | G10: 34547 | H10: 87.584157 | U10: 34608 | V10: 100 | W10: =VLOOKUP(U10,'conventional_refi_elig-old'!AA:AB,2,0) -> 97.202263 | X10: 87.640087
A11: FNCL | B11: 34639 | C11: 136567 | D11: 2.94792e+11 | E11: 87.596137 | G11: 34578 | H11: 87.60921 | U11: 34639 | V11: 100 | W11: =VLOOKUP(U11,'conventional_refi_elig-old'!AA:AB,2,0) -> 97.077694 | X11: 87.596137
A12: FNCL | B12: 34669 | C12: 137384 | D12: 2.9702273e+11 | E12: 87.621296 | G12: 34608 | H12: 87.640087 | U12: 34669 | V12: 100 | W12: =VLOOKUP(U12,'conventional_refi_elig-old'!AA:AB,2,0) -> 96.978985 | X12: 87.621296
A13: FNCL | B13: 34700 | C13: 138175 | D13: 2.9953479e+11 | E13: 87.604003 | G13: 34639 | H13: 87.596137 | U13: 34700 | V13: 100 | W13: =VLOOKUP(U13,'conventional_refi_elig-old'!AA:AB,2,0) -> 96.901214 | X13: 87.604003
A14: FNCL | B14: 34731 | C14: 138749 | D14: 3.0057806e+11 | E14: 87.597083 | G14: 34669 | H14: 87.621296 | U14: 34731 | V14: 100 | W14: =VLOOKUP(U14,'conventional_refi_elig-old'!AA:AB,2,0) -> 96.79793 | X14: 87.597083
A15: FNCL | B15: 34759 | C15: 139252 | D15: 3.0151552e+11 | E15: 87.621204 | G15: 34700 | H15: 87.604003 | U15: 34759 | V15: 100 | W15: =VLOOKUP(U15,'conventional_refi_elig-old'!AA:AB,2,0) -> 96.704604 | X15: 87.621204
... A274: FNCL | B274: 40787 | C274: 281942 | D274: 1.7360003e+12 | E274: 79.804318 | G274: 42583 | H274: 97.278876 | U274: 42644 | V274: 82.742466 | W274: =VLOOKUP(U274,'conventional_refi_elig-old'!AA:AB,2,0) -> 98.507721 | X274: 97.369124
A275: FNCQ30 | B275: 40787 | C275: 437 | D275: 7.3938545e+09 | E275: 0 | G275: 42614 | H275: 97.324472
A276: FNCK | B276: 40787 | C276: 1327 | D276: 5.9412547e+10 | E276: 97.85709 | G276: 42644 | H276: 97.369124
A277: FNCL | B277: 40817 | C277: 282590 | D277: 1.7300621e+12 | E277: 79.769992 | G277: Grand Total | H277: 23798.966
A278: FNCQ30 | B278: 40817 | C278: 461 | D278: 7.9908166e+09 | E278: 0
A279: FNCK | B279: 40817 | C279: 1392 | D279: 6.0879464e+10 | E279: 97.915562
A280: FNCL | B280: 40848 | C280: 283012 | D280: 1.7161114e+12 | E280: 79.6395
A281: FNCQ30 | B281: 40848 | C281: 487 | D281: 8.5171652e+09 | E281: 0
A282: FNCK | B282: 40848 | C282: 1471 | D282: 6.1528555e+10 | E282: 97.820125
A283: FNCL | B283: 40878 | C283: 283516 | D283: 1.704192e+12 | E283: 79.507087
A284: FNCQ30 | B284: 40878 | C284: 514 | D284: 9.0740215e+09 | E284: 0
A285: FNCK | B285: 40878 | C285: 1523 | D285: 6.343284e+10 | E285: 97.523756
A286: FNCL | B286: 40909 | C286: 284179 | D286: 1.7047182e+12 | E286: 79.847724
A287: FNCQ30 | B287: 40909 | C287: 537 | D287: 9.4003226e+09 | E287: 0
A288: FNCK | B288: 40909 | C288: 1561 | D288: 6.3431287e+10 | E288: 97.620997
A289: FNCL | B289: 40940 | C289: 284757 | D289: 1.6958104e+12 | E289: 80.077576
... A511: FNCR | B511: 42644 | C511: 1390 | D511: 3.3686514e+10 | E511: 32.519924

Sheet loan
A1: marketTicker | B1: asOf | C1: count(1) | D1: sum(p.schamBalance) | E1: wavg_pct_conventional_eligible | G1: marketTicker | H1: FNCR
A2: FNCL | B2: 34366 | C2: 126636 | D2: 2.7849025e+11 | E2: (NULL)
A3: FNCL | B3: 34394 | C3: 128266 | D3: 2.8205083e+11 | E3: (NULL) | G3: Row Labels | H3: Sum of wavg_pct_conventional_eligible
A4: FNCL | B4: 34425 | C4: 129601 | D4: 2.838742e+11 | E4: (NULL) | G4: 41091 | H4: 0
A5: FNCL | B5: 34455 | C5: 130768 | D5: 2.847529e+11 | E5: (NULL) | G5: 41122 | H5: 0
A6: FNCL | B6: 34486 | C6: 131996 | D6: 2.8712206e+11 | E6: (NULL) | G6: 41153 | H6: 0
A7: FNCL | B7: 34516 | C7: 133140 | D7: 2.8891975e+11 | E7: (NULL) | G7: 41183 | H7: 0
A8: FNCL | B8: 34547 | C8: 134153 | D8: 2.9064065e+11 | E8: (NULL) | G8: 41214 | H8: 0
A9: FNCL | B9: 34578 | C9: 135077 | D9: 2.9202625e+11 | E9: (NULL) | G9: 41244 | H9: 0
A10: FNCL | B10: 34608 | C10: 135888 | D10: 2.9339599e+11 | E10: (NULL) | G10: 41275 | H10: 0
A11: FNCL | B11: 34639 | C11: 136567 | D11: 2.94792e+11 | E11: (NULL) | G11: 41306 | H11: 0
A12: FNCL | B12: 34669 | C12: 137384 | D12: 2.9702273e+11 | E12: (NULL) | G12: 41334 | H12: 0
A13: FNCL | B13: 34700 | C13: 138175 | D13: 2.9953479e+11 | E13: (NULL) | G13: 41365 | H13: 0
A14: FNCL | B14: 34731 | C14: 138749 | D14: 3.0057806e+11 | E14: (NULL) | G14: 41395 | H14: 0
A15: FNCL | B15: 34759 | C15: 139252 | D15: 3.0151552e+11 | E15: (NULL) | G15: 41426 | H15: 0
... A55: FNCL | B55: 35977 | C55: 173773 | D55: 4.6333752e+11 | E55: (NULL) | G55: 42644 | H55: 16.083708
A56: FNCL | B56: 36008 | C56: 174901 | D56: 4.7396393e+11 | E56: (NULL) | G56: Grand Total | H56: 418.18748
A57: FNCL | B57: 36039 | C57: 175971 | D57: 482637195788 | E57: (NULL)
A58: FNCL | B58: 36069 | C58: 177221 | D58: 4.9275968e+11 | E58: (NULL)
A59: FNCL | B59: 36100 | C59: 178640 | D59: 5.0221163e+11 | E59: (NULL)
A60: FNCL | B60: 36130 | C60: 179937 | D60: 5.0886082e+11 | E60: (NULL)
A61: FNCL | B61: 36161 | C61: 181535 | D61: 5.191816e+11 | E61: (NULL)
A62: FNCL | B62: 36192 | C62: 183021 | D62: 5.2926655e+11 | E62: (NULL)
A63: FNCL | B63: 36220 | C63: 184355 | D63: 5.4075554e+11 | E63: (NULL)
A64: FNCL | B64: 36251 | C64: 185605 | D64: 5.4975047e+11 | E64: (NULL)
A65: FNCL | B65: 36281 | C65: 186717 | D65: 5.5650618e+11 | E65: (NULL)
A66: FNCL | B66: 36312 | C66: 187662 | D66: 563458838273 | E66: (NULL)
A67: FNCL | B67: 36342 | C67: 188811 | D67: 5.7220461e+11 | E67: (NULL)
A68: FNCL | B68: 36373 | C68: 189841 | D68: 5.7929147e+11 | E68: (NULL)
... A331: FNCK | B331: 41275 | C331: 1864 | D331: 5.9324751e+10 | E331: (NULL)
A332: FNCL | B332: 41306 | C332: 295747 | D332: 1.6414088e+12 | E332: 0.0094182361
A333: FNCQ30 | B333: 41306 | C333: 1265 | D333: 3.5343557e+10 | E333: 0
A334: FNCR | B334: 41306 | C334: 572 | D334: 2.571078e+10 | E334: 0
A335: FNCK | B335: 41306 | C335: 1890 | D335: 5.9341254e+10 | E335: 0
A336: FNCL | B336: 41334 | C336: 296480 | D336: 1.6390993e+12 | E336: 0.004686178
A337: FNCQ30 | B337: 41334 | C337: 1335 | D337: 3.7312889e+10 | E337: 0
A338: FNCR | B338: 41334 | C338: 639 | D338: 2.7919269e+10 | E338: 0
A339: FNCK | B339: 41334 | C339: 1907 | D339: 5.8273863e+10 | E339: 0
A340: FNCL | B340: 41365 | C340: 296774 | D340: 1.6329286e+12 | E340: 0.0037037715
A341: FNCQ30 | B341: 41365 | C341: 1395 | D341: 3.9156033e+10 | E341: 0
...

Sheet remove q2min
A1: marketTicker | B1: asOf | C1: count(1) | D1: sum(p.schamBalance) | E1: conventional_eligible | G1: marketTicker | H1: FNCL | V1: FNCL | W1: FGLMC | X1: FNCL-new
A2: FNCL | B2: 34366 | C2: 126636 | D2: 2.7849025e+11 | E2: 100 | U2: 34366 | V2: 100 | W2: =VLOOKUP(U2,'conventional_refi_elig-old'!AA:AB,2,0) -> 99.042895 | X2: =VLOOKUP(U2,G:H,2,0) -> 100
A3: FNCL | B3: 34394 | C3: 128266 | D3: 2.8205083e+11 | E3: 100 | G3: Row Labels | H3: Sum of conventional_eligible | U3: 34394 | V3: 100 | W3: =VLOOKUP(U3,'conventional_refi_elig-old'!AA:AB,2,0) -> 98.72842 | X3: =VLOOKUP(U3,G:H,2,0) -> 100
A4: FNCL | B4: 34425 | C4: 129601 | D4: 2.838742e+11 | E4: 100 | G4: 34366 | H4: 100 | U4: 34425 | V4: 100 | W4: =VLOOKUP(U4,'conventional_refi_elig-old'!AA:AB,2,0) -> 98.420927 | X4: =VLOOKUP(U4,G:H,2,0) -> 100
A5: FNCL | B5: 34455 | C5: 130768 | D5: 2.847529e+11 | E5: 100 | G5: 34394 | H5: 100 | U5: 34455 | V5: 100 | W5: =VLOOKUP(U5,'conventional_refi_elig-old'!AA:AB,2,0) -> #N/A | X5: =VLOOKUP(U5,G:H,2,0) -> 100
A6: FNCL | B6: 34486 | C6: 131996 | D6: 2.8712206e+11 | E6: 100 | G6: 34425 | H6: 100 | U6: 34486 | V6: 100 | W6: =VLOOKUP(U6,'conventional_refi_elig-old'!AA:AB,2,0) -> #N/A | X6: =VLOOKUP(U6,G:H,2,0) -> 100
A7: FNCL | B7: 34516 | C7: 133140 | D7: 2.8891975e+11 | E7: 100 | G7: 34455 | H7: 100 | U7: 34516 | V7: 100 | W7: =VLOOKUP(U7,'conventional_refi_elig-old'!AA:AB,2,0) -> 97.681204 | X7: =VLOOKUP(U7,G:H,2,0) -> 100
A8: FNCL | B8: 34547 | C8: 134153 | D8: 2.9064065e+11 | E8: 100 | G8: 34486 | H8: 100 | U8: 34547 | V8: 100 | W8: =VLOOKUP(U8,'conventional_refi_elig-old'!AA:AB,2,0) -> 97.503899 | X8: =VLOOKUP(U8,G:H,2,0) -> 100
A9: FNCL | B9: 34578 | C9: 135077 | D9: 2.9202625e+11 | E9: 100 | G9: 34516 | H9: 100 | U9: 34578 | V9: 100 | W9: =VLOOKUP(U9,'conventional_refi_elig-old'!AA:AB,2,0) -> 97.356955 | X9: =VLOOKUP(U9,G:H,2,0) -> 100
A10: FNCL | B10: 34608 | C10: 135888 | D10: 2.9339599e+11 | E10: 100 | G10: 34547 | H10: 100 | U10: 34608 | V10: 100 | W10: =VLOOKUP(U10,'conventional_refi_elig-old'!AA:AB,2,0) -> 97.202263 | X10: =VLOOKUP(U10,G:H,2,0) -> 100
A11: FNCL | B11: 34639 | C11: 136567 | D11: 2.94792e+11 | E11: 100 | G11: 34578 | H11: 100 | U11: 34639 | V11: 100 | W11: =VLOOKUP(U11,'conventional_refi_elig-old'!AA:AB,2,0) -> 97.077694 | X11: =VLOOKUP(U11,G:H,2,0) -> 100
A12: FNCL | B12: 34669 | C12: 137384 | D12: 2.9702273e+11 | E12: 100 | G12: 34608 | H12: 100 | U12: 34669 | V12: 100 | W12: =VLOOKUP(U12,'conventional_refi_elig-old'!AA:AB,2,0) -> 96.978985 | X12: =VLOOKUP(U12,G:H,2,0) -> 100
A13: FNCL | B13: 34700 | C13: 138175 | D13: 2.9953479e+11 | E13: 100 | G13: 34639 | H13: 100 | U13: 34700 | V13: 100 | W13: =VLOOKUP(U13,'conventional_refi_elig-old'!AA:AB,2,0) -> 96.901214 | X13: =VLOOKUP(U13,G:H,2,0) -> 100
A14: FNCL | B14: 34731 | C14: 138749 | D14: 3.0057806e+11 | E14: 100 | G14: 34669 | H14: 100 | U14: 34731 | V14: 100 | W14: =VLOOKUP(U14,'conventional_refi_elig-old'!AA:AB,2,0) -> 96.79793 | X14: =VLOOKUP(U14,G:H,2,0) -> 100
A15: FNCL | B15: 34759 | C15: 139252 | D15: 3.0151552e+11 | E15: 100 | G15: 34700 | H15: 100 | U15: 34759 | V15: 100 | W15: =VLOOKUP(U15,'conventional_refi_elig-old'!AA:AB,2,0) -> 96.704604 | X15: =VLOOKUP(U15,G:H,2,0) -> 100
... A274: FNCL | B274: 40787 | C274: 281942 | D274: 1.7360003e+12 | E274: 79.805684 | G274: 42583 | H274: 97.27284 | U274: 42644 | V274: 82.742466 | W274: =VLOOKUP(U274,'conventional_refi_elig-old'!AA:AB,2,0) -> 98.507721 | X274: =VLOOKUP(U274,G:H,2,0) -> 97.363427
A275: FNCQ30 | B275: 40787 | C275: 437 | D275: 7.3938545e+09 | E275: 0 | G275: 42614 | H275: 97.318617
A276: FNCK | B276: 40787 | C276: 1327 | D276: 5.9412547e+10 | E276: 97.85709 | G276: 42644 | H276: 97.363427
A277: FNCL | B277: 40817 | C277: 282590 | D277: 1.7300621e+12 | E277: 79.771503 | G277: Grand Total | H277: 23832.838
A278: FNCQ30 | B278: 40817 | C278: 461 | D278: 7.9908166e+09 | E278: 0
A279: FNCK | B279: 40817 | C279: 1392 | D279: 6.0879464e+10 | E279: 97.915562
A280: FNCL | B280: 40848 | C280: 283012 | D280: 1.7161114e+12 | E280: 79.640842
A281: FNCQ30 | B281: 40848 | C281: 487 | D281: 8.5171652e+09 | E281: 0
A282: FNCK | B282: 40848 | C282: 1471 | D282: 6.1528555e+10 | E282: 97.820125
A283: FNCL | B283: 40878 | C283: 283516 | D283: 1.704192e+12 | E283: 79.50859
A284: FNCQ30 | B284: 40878 | C284: 514 | D284: 9.0740215e+09 | E284: 0
A285: FNCK | B285: 40878 | C285: 1523 | D285: 6.343284e+10 | E285: 97.523756
A286: FNCL | B286: 40909 | C286: 284179 | D286: 1.7047182e+12 | E286: 79.848175
A287: FNCQ30 | B287: 40909 | C287: 537 | D287: 9.4003226e+09 | E287: 0
A288: FNCK | B288: 40909 | C288: 1561 | D288: 6.3431287e+10 | E288: 97.620997
A289: FNCL | B289: 40940 | C289: 284757 | D289: 1.6958104e+12 | E289: 80.07812
... A511: FNCR | B511: 42644 | C511: 1390 | D511: 3.3686514e+10 | E511: 32.519924

Sheet use bucket match
A1: marketTicker | B1: asOf | C1: count(1) | D1: sum(p.schamBalance) | E1: conventional_eligible | G1: marketTicker | H1: FNCL | U1: loan
A2: FNCL | B2: 34366 | C2: 126636 | D2: 2.7849025e+11 | E2: 87.51949
A3: FNCL | B3: 34394 | C3: 128266 | D3: 2.8205083e+11 | E3: 87.536095 | G3: Row Labels | H3: Sum of conventional_eligible
A4: FNCL | B4: 34425 | C4: 129601 | D4: 2.838742e+11 | E4: 87.48246 | G4: 34366 | H4: 87.51949
A5: FNCL | B5: 34455 | C5: 130768 | D5: 2.847529e+11 | E5: 87.493192 | G5: 34394 | H5: 87.536095
A6: FNCL | B6: 34486 | C6: 131996 | D6: 2.8712206e+11 | E6: 87.523951 | G6: 34425 | H6: 87.48246
A7: FNCL | B7: 34516 | C7: 133140 | D7: 2.8891975e+11 | E7: 87.55596 | G7: 34455 | H7: 87.493192
A8: FNCL | B8: 34547 | C8: 134153 | D8: 2.9064065e+11 | E8: 87.584157 | G8: 34486 | H8: 87.523951
A9: FNCL | B9: 34578 | C9: 135077 | D9: 2.9202625e+11 | E9: 87.60921 | G9: 34516 | H9: 87.55596
A10: FNCL | B10: 34608 | C10: 135888 | D10: 2.9339599e+11 | E10: 87.640087 | G10: 34547 | H10: 87.584157
A11: FNCL | B11: 34639 | C11: 136567 | D11: 2.94792e+11 | E11: 87.596137 | G11: 34578 | H11: 87.60921
A12: FNCL | B12: 34669 | C12: 137384 | D12: 2.9702273e+11 | E12: 87.621296 | G12: 34608 | H12: 87.640087
A13: FNCL | B13: 34700 | C13: 138175 | D13: 2.9953479e+11 | E13: 87.604003 | G13: 34639 | H13: 87.596137
A14: FNCL | B14: 34731 | C14: 138749 | D14: 3.0057806e+11 | E14: 87.597083 | G14: 34669 | H14: 87.621296
A15: FNCL | B15: 34759 | C15: 139252 | D15: 3.0151552e+11 | E15: 87.621204 | G15: 34700 | H15: 87.604003
A16: FNCL | B16: 34790 | C16: 139640 | D16: 3.021308e+11 | E16: 87.63401 | G16: 34731 | H16: 87.597083
A17: FNCL | B17: 34820 | C17: 140171 | D17: 3.0319317e+11 | E17: 87.640007 | G17: 34759 | H17: 87.621204 | U17: step 1
A18: FNCL | B18: 34851 | C18: 140845 | D18: 3.052762e+11 | E18: 87.677953 | G18: 34790 | H18: 87.63401
A19: FNCL | B19: 34881 | C19: 141735 | D19: 3.0857951e+11 | E19: 87.676236 | G19: 34820 | H19: 87.640007
A20: FNCL | B20: 34912 | C20: 142847 | D20: 3.1330609e+11 | E20: 87.689905 | G20: 34851 | H20: 87.677953
A21: FNCL | B21: 34943 | C21: 143912 | D21: 3.1785586e+11 | E21: 87.687611 | G21: 34881 | H21: 87.676236
A22: FNCL | B22: 34973 | C22: 144902 | D22: 3.2193807e+11 | E22: 87.671479 | G22: 34912 | H22: 87.689905
A23: FNCL | B23: 35004 | C23: 145867 | D23: 3.2658666e+11 | E23: 87.657273 | G23: 34943 | H23: 87.687611
A24: FNCL | B24: 35034 | C24: 146882 | D24: 3.3196489e+11 | E24: 87.650829 | G24: 34973 | H24: 87.671479
A25: FNCL | B25: 35065 | C25: 147919 | D25: 3.3730406e+11 | E25: 87.651441 | G25: 35004 | H25: 87.657273
A26: FNCL | B26: 35096 | C26: 148833 | D26: 3.4167242e+11 | E26: 87.638767 | G26: 35034 | H26: 87.650829
A27: FNCL | B27: 35125 | C27: 149785 | D27: 3.4654545e+11 | E27: 87.594846 | G27: 35065 | H27: 87.651441
A28: FNCL | B28: 35156 | C28: 150727 | D28: 3.5046556e+11 | E28: 87.539968 | G28: 35096 | H28: 87.638767
A29: FNCL | B29: 35186 | C29: 151726 | D29: 3.5468325e+11 | E29: 87.48948 | G29: 35125 | H29: 87.594846
... A34: FNCL | B34: 35339 | C34: 155900 | D34: 3.7515495e+11 | E34: 87.123163 | G34: 35278 | H34: 87.210539
A35: FNCL | B35: 35370 | C35: 156553 | D35: 3.7816455e+11 | E35: 87.087522 | G35: 35309 | H35: 87.167279 | U35: step 3
A36: FNCL | B36: 35400 | C36: 157183 | D36: 3.8057316e+11 | E36: 87.06562 | G36: 35339 | H36: 87.123163
A37: FNCL | B37: 35431 | C37: 157961 | D37: 3.8357929e+11 | E37: 87.062966 | G37: 35370 | H37: 87.087522
A38: FNCL | B38: 35462 | C38: 158587 | D38: 3.8562288e+11 | E38: 87.059408 | G38: 35400 | H38: 87.06562
A39: FNCL | B39: 35490 | C39: 159328 | D39: 3.8894459e+11 | E39: 87.054439 | G39: 35431 | H39: 87.062966
A40: FNCL | B40: 35521 | C40: 160031 | D40: 3.9199635e+11 | E40: 87.025258 | G40: 35462 | H40: 87.059408
A41: FNCL | B41: 35551 | C41: 160667 | D41: 3.9440199e+11 | E41: 87.004007 | G41: 35490 | H41: 87.054439
A42: FNCL | B42: 35582 | C42: 161332 | D42: 3.976503e+11 | E42: 86.986453 | G42: 35521 | H42: 87.025258
A43: FNCL | B43: 35612 | C43: 161858 | D43: 3.9966136e+11 | E43: 86.982192 | G43: 35551 | H43: 87.004007
A44: FNCL | B44: 35643 | C44: 162531 | D44: 4.0247325e+11 | E44: 86.972078 | G44: 35582 | H44: 86.986453
...

Sheet fix2013
A1: marketTicker | B1: asOf | C1: count(1) | D1: sum(p.schamBalance) | E1: conventional_eligible | G1: marketTicker | H1: FNCL | U1: loan
A2: FNCL | B2: 34366 | C2: 126636 | D2: 2.7849025e+11 | E2: 87.51949
A3: FNCL | B3: 34394 | C3: 128266 | D3: 2.8205083e+11 | E3: 87.536095 | G3: Row Labels | H3: Sum of conventional_eligible
A4: FNCL | B4: 34425 | C4: 129601 | D4: 2.838742e+11 | E4: 87.48246 | G4: 34366 | H4: 87.51949
A5: FNCL | B5: 34455 | C5: 130768 | D5: 2.847529e+11 | E5: 87.493192 | G5: 34394 | H5: 87.536095
A6: FNCL | B6: 34486 | C6: 131996 | D6: 2.8712206e+11 | E6: 87.523951 | G6: 34425 | H6: 87.48246
A7: FNCL | B7: 34516 | C7: 133140 | D7: 2.8891975e+11 | E7: 87.55596 | G7: 34455 | H7: 87.493192
A8: FNCL | B8: 34547 | C8: 134153 | D8: 2.9064065e+11 | E8: 87.584157 | G8: 34486 | H8: 87.523951
A9: FNCL | B9: 34578 | C9: 135077 | D9: 2.9202625e+11 | E9: 87.60921 | G9: 34516 | H9: 87.55596
A10: FNCL | B10: 34608 | C10: 135888 | D10: 2.9339599e+11 | E10: 87.640087 | G10: 34547 | H10: 87.584157
A11: FNCL | B11: 34639 | C11: 136567 | D11: 2.94792e+11 | E11: 87.596137 | G11: 34578 | H11: 87.60921
A12: FNCL | B12: 34669 | C12: 137384 | D12: 2.9702273e+11 | E12: 87.621296 | G12: 34608 | H12: 87.640087
A13: FNCL | B13: 34700 | C13: 138175 | D13: 2.9953479e+11 | E13: 87.604003 | G13: 34639 | H13: 87.596137
A14: FNCL | B14: 34731 | C14: 138749 | D14: 3.0057806e+11 | E14: 87.597083 | G14: 34669 | H14: 87.621296
A15: FNCL | B15: 34759 | C15: 139252 | D15: 3.0151552e+11 | E15: 87.621204 | G15: 34700 | H15: 87.604003
A16: FNCL | B16: 34790 | C16: 139640 | D16: 3.021308e+11 | E16: 87.63401 | G16: 34731 | H16: 87.597083
A17: FNCL | B17: 34820 | C17: 140171 | D17: 3.0319317e+11 | E17: 87.640007 | G17: 34759 | H17: 87.621204 | U17: step 1
A18: FNCL | B18: 34851 | C18: 140845 | D18: 3.052762e+11 | E18: 87.677953 | G18: 34790 | H18: 87.63401
A19: FNCL | B19: 34881 | C19: 141735 | D19: 3.0857951e+11 | E19: 87.676236 | G19: 34820 | H19: 87.640007
A20: FNCL | B20: 34912 | C20: 142847 | D20: 3.1330609e+11 | E20: 87.689905 | G20: 34851 | H20: 87.677953
A21: FNCL | B21: 34943 | C21: 143912 | D21: 3.1785586e+11 | E21: 87.687611 | G21: 34881 | H21: 87.676236
A22: FNCL | B22: 34973 | C22: 144902 | D22: 3.2193807e+11 | E22: 87.671479 | G22: 34912 | H22: 87.689905
A23: FNCL | B23: 35004 | C23: 145867 | D23: 3.2658666e+11 | E23: 87.657273 | G23: 34943 | H23: 87.687611
A24: FNCL | B24: 35034 | C24: 146882 | D24: 3.3196489e+11 | E24: 87.650829 | G24: 34973 | H24: 87.671479
A25: FNCL | B25: 35065 | C25: 147919 | D25: 3.3730406e+11 | E25: 87.651441 | G25: 35004 | H25: 87.657273
A26: FNCL | B26: 35096 | C26: 148833 | D26: 3.4167242e+11 | E26: 87.638767 | G26: 35034 | H26: 87.650829
A27: FNCL | B27: 35125 | C27: 149785 | D27: 3.4654545e+11 | E27: 87.594846 | G27: 35065 | H27: 87.651441
A28: FNCL | B28: 35156 | C28: 150727 | D28: 3.5046556e+11 | E28: 87.539968 | G28: 35096 | H28: 87.638767
A29: FNCL | B29: 35186 | C29: 151726 | D29: 3.5468325e+11 | E29: 87.48948 | G29: 35125 | H29: 87.594846
... A34: FNCL | B34: 35339 | C34: 155900 | D34: 3.7515495e+11 | E34: 87.123163 | G34: 35278 | H34: 87.210539
A35: FNCL | B35: 35370 | C35: 156553 | D35: 3.7816455e+11 | E35: 87.087522 | G35: 35309 | H35: 87.167279 | U35: step 3
A36: FNCL | B36: 35400 | C36: 157183 | D36: 3.8057316e+11 | E36: 87.06562 | G36: 35339 | H36: 87.123163
A37: FNCL | B37: 35431 | C37: 157961 | D37: 3.8357929e+11 | E37: 87.062966 | G37: 35370 | H37: 87.087522
A38: FNCL | B38: 35462 | C38: 158587 | D38: 3.8562288e+11 | E38: 87.059408 | G38: 35400 | H38: 87.06562
A39: FNCL | B39: 35490 | C39: 159328 | D39: 3.8894459e+11 | E39: 87.054439 | G39: 35431 | H39: 87.062966
A40: FNCL | B40: 35521 | C40: 160031 | D40: 3.9199635e+11 | E40: 87.025258 | G40: 35462 | H40: 87.059408
A41: FNCL | B41: 35551 | C41: 160667 | D41: 3.9440199e+11 | E41: 87.004007 | G41: 35490 | H41: 87.054439
A42: FNCL | B42: 35582 | C42: 161332 | D42: 3.976503e+11 | E42: 86.986453 | G42: 35521 | H42: 87.025258
A43: FNCL | B43: 35612 | C43: 161858 | D43: 3.9966136e+11 | E43: 86.982192 | G43: 35551 | H43: 87.004007
A44: FNCL | B44: 35643 | C44: 162531 | D44: 4.0247325e+11 | E44: 86.972078 | G44: 35582 | H44: 86.986453
...

Sheet cltv_fico elig
A1: marketTicker | B1: asOf | C1: count(1) | D1: sum(p.schamBalance) | E1: percent_eligible_fico | G1: marketTicker | H1: FNCL
A2: FNCL | B2: 34366 | C2: 126636 | D2: 2.7849025e+11 | E2: (NULL)
A3: FNCL | B3: 34394 | C3: 128266 | D3: 2.8205083e+11 | E3: (NULL) | G3: Row Labels | H3: Sum of percent_eligible_fico
A4: FNCL | B4: 34425 | C4: 129601 | D4: 2.838742e+11 | E4: (NULL) | G4: 34366 | H4: 0
A5: FNCL | B5: 34455 | C5: 130768 | D5: 2.847529e+11 | E5: (NULL) | G5: 34394 | H5: 0
A6: FNCL | B6: 34486 | C6: 131996 | D6: 2.8712206e+11 | E6: (NULL) | G6: 34425 | H6: 0
A7: FNCL | B7: 34516 | C7: 133140 | D7: 2.8891975e+11 | E7: (NULL) | G7: 34455 | H7: 0
A8: FNCL | B8: 34547 | C8: 134153 | D8: 2.9064065e+11 | E8: (NULL) | G8: 34486 | H8: 0
A9: FNCL | B9: 34578 | C9: 135077 | D9: 2.9202625e+11 | E9: (NULL) | G9: 34516 | H9: 0
A10: FNCL | B10: 34608 | C10: 135888 | D10: 2.9339599e+11 | E10: (NULL) | G10: 34547 | H10: 0
A11: FNCL | B11: 34639 | C11: 136567 | D11: 2.94792e+11 | E11: (NULL) | G11: 34578 | H11: 0
A12: FNCL | B12: 34669 | C12: 137384 | D12: 2.9702273e+11 | E12: (NULL) | G12: 34608 | H12: 0
A13: FNCL | B13: 34700 | C13: 138175 | D13: 2.9953479e+11 | E13: (NULL) | G13: 34639 | H13: 0
A14: FNCL | B14: 34731 | C14: 138749 | D14: 3.0057806e+11 | E14: (NULL) | G14: 34669 | H14: 0
A15: FNCL | B15: 34759 | C15: 139252 | D15: 3.0151552e+11 | E15: (NULL) | G15: 34700 | H15: 0
... A29: FNCL | B29: 35186 | C29: 151726 | D29: 3.5468325e+11 | E29: (NULL) | G29: 35125 | H29: 0
A30: FNCL | B30: 35217 | C30: 152681 | D30: 3.5915351e+11 | E30: 80.821943 | G30: 35156 | H30: 0
A31: FNCL | B31: 35247 | C31: 153592 | D31: 3.6414591e+11 | E31: 82.763683 | G31: 35186 | H31: 0
A32: FNCL | B32: 35278 | C32: 154353 | D32: 3.6784358e+11 | E32: 83.040138 | G32: 35217 | H32: 80.821943
A33: FNCL | B33: 35309 | C33: 155081 | D33: 3.7051341e+11 | E33: 83.132137 | G33: 35247 | H33: 82.763683
A34: FNCL | B34: 35339 | C34: 155900 | D34: 3.7515495e+11 | E34: 83.372933 | G34: 35278 | H34: 83.040138
A35: FNCL | B35: 35370 | C35: 156553 | D35: 3.7816455e+11 | E35: 83.498885 | G35: 35309 | H35: 83.132137
A36: FNCL | B36: 35400 | C36: 157183 | D36: 3.8057316e+11 | E36: 83.591682 | G36: 35339 | H36: 83.372933
A37: FNCL | B37: 35431 | C37: 157961 | D37: 3.8357929e+11 | E37: 83.855799 | G37: 35370 | H37: 83.498885
A38: FNCL | B38: 35462 | C38: 158587 | D38: 3.8562288e+11 | E38: 84.035552 | G38: 35400 | H38: 83.591682
A39: FNCL | B39: 35490 | C39: 159328 | D39: 3.8894459e+11 | E39: 84.280331 | G39: 35431 | H39: 83.855799
A40: FNCL | B40: 35521 | C40: 160031 | D40: 3.9199635e+11 | E40: 84.348351 | G40: 35462 | H40: 84.035552
A41: FNCL | B41: 35551 | C41: 160667 | D41: 3.9440199e+11 | E41: 84.457331 | G41: 35490 | H41: 84.280331
... A276: FNCK | B276: 40787 | C276: 1327 | D276: 5.9412547e+10 | E276: 99.818959 | G276: 42644 | H276: 95.280324
A277: FNCL | B277: 40817 | C277: 282590 | D277: 1.7300621e+12 | E277: 92.997309 | G277: Grand Total | H277: 22037.967
A278: FNCQ30 | B278: 40817 | C278: 461 | D278: 7.9908166e+09 | E278: 89.750605
A279: FNCK | B279: 40817 | C279: 1392 | D279: 6.0879464e+10 | E279: 99.827854
A280: FNCL | B280: 40848 | C280: 283012 | D280: 1.7161114e+12 | E280: 93.065803
A281: FNCQ30 | B281: 40848 | C281: 487 | D281: 8.5171652e+09 | E281: 89.673633
A282: FNCK | B282: 40848 | C282: 1471 | D282: 6.1528555e+10 | E282: 99.838875
A283: FNCL | B283: 40878 | C283: 283516 | D283: 1.704192e+12 | E283: 93.141427
A284: FNCQ30 | B284: 40878 | C284: 514 | D284: 9.0740215e+09 | E284: 89.664991
A285: FNCK | B285: 40878 | C285: 1523 | D285: 6.343284e+10 | E285: 99.64864
A286: FNCL | B286: 40909 | C286: 284179 | D286: 1.7047182e+12 | E286: 93.243765
A287: FNCQ30 | B287: 40909 | C287: 537 | D287: 9.4003226e+09 | E287: 89.747898
...
