Workbook

Sheet FHL
A1: HARP_eligible | B1: dimensionCombination | C1: factorDate | D1: modifyDate | E1: sliceId | F1: wacls | G1: ols | H1: burnout | I1: cpr | J1: bal | K1: currLLPA | L1: currMIP | M1: currPMI | N1: pct_dq | O1: pct_fha | P1: pct_HARPed | Q1: pct_inv | R1: issueDate | S1: origMIP | T1: origPMI | U1: pct_owner | V1: poolListName | W1: refi_elig_pct | X1: incentive | Y1: pct_REFI | Z1: replineMode | AA1: origbal | AB1: pct_2nd | AC1: pct_tpo | AD1: cltv | AE1: odti | AF1: fico | AG1: oltv | AH1: sato | AI1: wac | AJ1: wala | AK1: wam
A2: 0 | B2: ALGORITHM:TICKER | C2: 20100301 | D2: 20100301 | E2: TICKER:FGLMC | F2: 225871.87 | G2: 226331.11 | H2: 0 | I2: 0 | J2: 4159148.5 | K2: 38.1 | L2: NA | M2: 21.86 | N2: 0.3 | O2: NA | P2: 0 | Q2: 0 | R2: 20100201 | S2: NA | T2: 0 | U2: 91.27 | V2: FHL30.350.10(GEN) | W2: 100 | X2: -132.75 | Y2: 33.72 | Z2: PL | AA2: 2710471.1 | AB2: 8.72 | AC2: 62.71 | AD2: 71.64 | AE2: 32.99 | AF2: 771.99 | AG2: 69.99 | AH2: -116.1 | AI2: 3.9 | AJ2: 1 | AK2: 359
A3: 0 | B3: ALGORITHM:TICKER | C3: 20100401 | D3: 20100401 | E3: TICKER:FGLMC | F3: 244246.03 | G3: 245117.41 | H3: 0 | I3: 0.24 | J3: 4152182.5 | K3: 38.1 | L3: NA | M3: 14.47 | N3: 0.14 | O3: NA | P3: 0 | Q3: 0 | R3: 20100201 | S3: NA | T3: 0 | U3: 91.27 | V3: FHL30.350.10(GEN) | W3: 100 | X3: -125.03 | Y3: 16.31 | Z3: PL | AA3: 4153021.5 | AB3: 8.72 | AC3: 79.12 | AD3: 71.26 | AE3: 30.21 | AF3: 774.09 | AG3: 71.39 | AH3: -116.1 | AI3: 3.9 | AJ3: 2 | AK3: 357.34
A4: 0 | B4: ALGORITHM:TICKER | C4: 20100501 | D4: 20100501 | E4: TICKER:FGLMC | F4: 243835.03 | G4: 245117.41 | H4: 0 | I4: 0.23 | J4: 4145195.5 | K4: 36.38 | L4: NA | M4: 9.38 | N4: 0.08 | O4: NA | P4: 0 | Q4: 0 | R4: 20100201 | S4: NA | T4: 0 | U4: 91.26 | V4: FHL30.350.10(GEN) | W4: 100 | X4: -130.18 | Y4: 16.32 | Z4: PL | AA4: 4146017.4 | AB4: 8.73 | AC4: 79.13 | AD4: 70.87 | AE4: 30.21 | AF4: 774.09 | AG4: 71.39 | AH4: -116.1 | AI4: 3.9 | AJ4: 3 | AK4: 356.34
A5: 0 | B5: ALGORITHM:TICKER | C5: 20100601 | D5: 20100601 | E5: TICKER:FGLMC | F5: 243422.57 | G5: 245117.41 | H5: 0 | I5: 0.23 | J5: 4138183.8 | K5: 36.38 | L5: NA | M5: 4.49 | N5: 0.04 | O5: NA | P5: 0 | Q5: 0 | R5: 20100201 | S5: NA | T5: 0 | U5: 91.27 | V5: FHL30.350.10(GEN) | W5: 100 | X5: -105.04 | Y5: 16.32 | Z5: PL | AA5: 4139011.5 | AB5: 8.72 | AC5: 79.15 | AD5: 70.5 | AE5: 30.21 | AF5: 774.09 | AG5: 71.39 | AH5: -116.1 | AI5: 3.9 | AJ5: 4 | AK5: 355.34
A6: 0 | B6: ALGORITHM:TICKER | C6: 20100701 | D6: 20100701 | E6: TICKER:FGLMC | F6: 243008.78 | G6: 245117.41 | H6: 0 | I6: 0.24 | J6: 4131149.3 | K6: 36.38 | L6: NA | M6: 9.38 | N6: 0.07 | O6: NA | P6: 0 | Q6: 0 | R6: 20100201 | S6: NA | T6: 0 | U6: 91.26 | V6: FHL30.350.10(GEN) | W6: 100 | X6: -92.27 | Y6: 16.33 | Z6: PL | AA6: 4131980.9 | AB6: 8.73 | AC6: 79.17 | AD6: 70.98 | AE6: 30.21 | AF6: 774.09 | AG6: 71.39 | AH6: -116.11 | AI6: 3.9 | AJ6: 5 | AK6: 354.34
A7: 0 | B7: ALGORITHM:TICKER | C7: 20100801 | D7: 20100801 | E7: TICKER:FGLMC | F7: 234862.64 | G7: 235580.5 | H7: 0 | I7: 0.24 | J7: 14561484 | K7: 41.82 | L7: NA | M7: 14.51 | N7: 0.06 | O7: NA | P7: 37.82 | Q7: 0 | R7: 20100201 | S7: NA | T7: 1.48 | U7: 95.44 | V7: FHL30.350.10(GEN) | W7: 98.79 | X7: -56.61 | Y7: 49.13 | Z7: PL | AA7: 4124927.5 | AB7: 4.55 | AC7: 44.74 | AD7: 70.05 | AE7: 30.69 | AF7: 773.12 | AG7: 70.03 | AH7: -80.66 | AI7: 4.12 | AJ7: 1.69 | AK7: 354.4
A8: 0 | B8: ALGORITHM:TICKER | C8: 20100901 | D8: 20100901 | E8: TICKER:FGLMC | F8: 236078.75 | G8: 236346.94 | H8: 0 | I8: 0.94 | J8: 91126400 | K8: 33.03 | L8: NA | M8: 11.56 | N8: 0.09 | O8: NA | P8: 17.42 | Q8: 0.04 | R8: 20100201 | S8: NA | T8: 6.08 | U8: 94.41 | V8: FHL30.350.10(GEN) | W8: 99.8 | X8: -35.71 | Y8: 37.7 | Z8: PL | AA8: 14547219 | AB8: 5.54 | AC8: 29 | AD8: 69.25 | AE8: 27.95 | AF8: 776.45 | AG8: 69.21 | AH8: -58.93 | AI8: 4.11 | AJ8: 0.36 | AK8: 356.39
A9: 0.75 | B9: ALGORITHM:TICKER | C9: 20101001 | D9: 20101001 | E9: TICKER:FGLMC | F9: 259972.96 | G9: 260331.46 | H9: 0 | I9: 0.11 | J9: 7.2246486e+08 | K9: 39.39 | L9: NA | M9: 13.72 | N9: 0.1 | O9: NA | P9: 19.14 | Q9: 0.03 | R9: 20100201 | S9: NA | T9: 5.26 | U9: 93.27 | V9: FHL30.350.10(GEN) | W9: 99.55 | X9: -24.52 | Y9: 54.32 | Z9: PL | AA9: 91003299 | AB9: 6.69 | AC9: 40.73 | AD9: 70.52 | AE9: 31.08 | AF9: 773.31 | AG9: 70.54 | AH9: -47.03 | AI9: 4.18 | AJ9: 0.59 | AK9: 356.53
A10: 0.25 | B10: ALGORITHM:TICKER | C10: 20101101 | D10: 20101101 | E10: TICKER:FGLMC | F10: 257722.18 | G10: 258100.19 | H10: 0 | I10: 0.74 | J10: 2098631719 | K10: 39.69 | L10: NA | M10: 14.07 | N10: 0.13 | O10: NA | P10: 13.32 | Q10: 0.15 | R10: 20100201 | S10: NA | T10: 5.31 | U10: 94.66 | V10: FHL30.350.10(GEN) | W10: 99.69 | X10: -20.54 | Y10: 60.77 | Z10: PL | AA10: 7.2154088e+08 | AB10: 5.18 | AC10: 59.17 | AD10: 70.56 | AE10: 31.12 | AF10: 772.77 | AG10: 70.39 | AH10: -41.85 | AI10: 4.14 | AJ10: 0.61 | AK10: 357.53
A11: 0.13 | B11: ALGORITHM:TICKER | C11: 20101201 | D11: 20101201 | E11: TICKER:FGLMC | F11: 266897.83 | G11: 267437.8 | H11: 0 | I11: 0.49 | J11: 3887367018 | K11: 39.09 | L11: NA | M11: 15.39 | N11: 0.17 | O11: NA | P11: 24.74 | Q11: 0.16 | R11: 20100201 | S11: NA | T11: 4.45 | U11: 95.39 | V11: FHL30.350.10(GEN) | W11: 99.65 | X11: -34.18 | Y11: 66.59 | Z11: PL | AA11: 2095761141 | AB11: 4.44 | AC11: 51.65 | AD11: 69.12 | AE11: 28.99 | AF11: 771.94 | AG11: 68.83 | AH11: -40 | AI11: 4.1 | AJ11: 0.97 | AK11: 357.59
A12: 0.1 | B12: ALGORITHM:TICKER | C12: 20110101 | D12: 20110101 | E12: TICKER:FGLMC | F12: 266208.8 | G12: 267079.74 | H12: 0 | I12: 0.56 | J12: 5063291523 | K12: 40.58 | L12: NA | M12: 18.64 | N12: 0.07 | O12: NA | P12: 19.7 | Q12: 0.16 | R12: 20100201 | S12: NA | T12: 4.22 | U12: 95.52 | V12: FHL30.350.10(GEN) | W12: 99.48 | X12: -78.15 | Y12: 68.11 | Z12: PL | AA12: 3851290928 | AB12: 4.3 | AC12: 56.88 | AD12: 69.48 | AE12: 29.39 | AF12: 772.56 | AG12: 68.56 | AH12: -39.49 | AI12: 4.09 | AJ12: 1.74 | AK12: 356.71
A13: 0.11 | B13: ALGORITHM:TICKER | C13: 20110201 | D13: 20110201 | E13: TICKER:FGLMC | F13: 264993.21 | G13: 266371.35 | H13: 0 | I13: 1.14 | J13: 5212681546 | K13: 44.14 | L13: NA | M13: 20.88 | N13: 0.14 | O13: NA | P13: 19.21 | Q13: 0.16 | R13: 20100201 | S13: NA | T13: 4.11 | U13: 95.54 | V13: FHL30.350.10(GEN) | W13: 98.59 | X13: -85.03 | Y13: 68.37 | Z13: PL | AA13: 5056000336 | AB13: 4.29 | AC13: 55.72 | AD13: 70.08 | AE13: 29.45 | AF13: 772.46 | AG13: 68.46 | AH13: -39.19 | AI13: 4.09 | AJ13: 2.72 | AK13: 355.34
... A86: 0.19 | B86: ALGORITHM:TICKER | C86: 20170301 | D86: 20170301 | E86: TICKER:FGLMC | F86: 186586.68 | G86: 222013.2 | H86: 1920.31 | I86: 9.07 | J86: 2111228304 | K86: 1.12 | L86: NA | M86: 0 | N86: 0.5 | O86: NA | P86: 17.38 | Q86: 0.44 | R86: 20100201 | S86: NA | T86: 0.75 | U86: 94.95 | V86: FHL30.350.10(GEN) | W86: 99.98 | X86: 3.4 | Y86: 66.68 | Z86: PL | AA86: 2128025704 | AB86: 4.6 | AC86: 52.61 | AD86: 46.1 | AE86: 30.28 | AF86: 770.4 | AG86: 69.22 | AH86: -41.11 | AI86: 4.07 | AJ86: 75.69 | AK86: 271.49

Sheet FNM
A1: HARP_eligible | B1: dimensionCombination | C1: factorDate | D1: modifyDate | E1: sliceId | F1: wacls | G1: ols | H1: burnout | I1: cpr | J1: bal | K1: currLLPA | L1: currMIP | M1: currPMI | N1: pct_dq | O1: pct_fha | P1: pct_HARPed | Q1: pct_inv | R1: issueDate | S1: origMIP | T1: origPMI | U1: pct_owner | V1: poolListName | W1: refi_elig_pct | X1: incentive | Y1: pct_REFI | Z1: replineMode | AA1: origbal | AB1: pct_2nd | AC1: pct_tpo | AD1: cltv | AE1: odti | AF1: fico | AG1: oltv | AH1: sato | AI1: wac | AJ1: wala | AK1: wam
A2: 0 | B2: ALGORITHM:TICKER | C2: 20100201 | D2: 20100201 | E2: TICKER:FNCL | F2: 212780.48 | G2: 213153.06 | H2: 0 | I2: 0.19 | J2: 12412898 | K2: 73.03 | L2: NA | M2: 30.51 | N2: 0.22 | O2: NA | P2: 11.23 | Q2: 0 | R2: 20100101 | S2: NA | T2: 10.39 | U2: 90.63 | V2: FNM30.350.10(GEN) | W2: 90.63 | X2: -55.1 | Y2: 55.84 | Z2: PL | AA2: 3267706 | AB2: 9.36 | AC2: 24.83 | AD2: 72.78 | AE2: 0 | AF2: 775.93 | AG2: 68.32 | AH2: -96.34 | AI2: 4.05 | AJ2: 0.85 | AK2: 354.95
A3: 0 | B3: ALGORITHM:TICKER | C3: 20100301 | D3: 20100301 | E3: TICKER:FNCL | F3: 186054.83 | G3: 186822.52 | H3: 0 | I3: 0.12 | J3: 22872830 | K3: 53.21 | L3: NA | M3: 18.06 | N3: 0.39 | O3: NA | P3: 22.85 | Q3: 0 | R3: 20100101 | S3: NA | T3: 7.71 | U3: 91.9 | V3: FNM30.350.10(GEN) | W3: 91.9 | X3: -48.56 | Y3: 51.61 | Z3: PL | AA3: 12394738 | AB3: 8.09 | AC3: 34.96 | AD3: 69.4 | AE3: 0 | AF3: 771.92 | AG3: 72.63 | AH3: -97.9 | AI3: 4.04 | AJ3: 1.7 | AK3: 349.37
A4: 0 | B4: ALGORITHM:TICKER | C4: 20100401 | D4: 20100401 | E4: TICKER:FNCL | F4: 212452.55 | G4: 213360.52 | H4: 0 | I4: 0.13 | J4: 25788304 | K4: 54.12 | L4: NA | M4: 16.75 | N4: 0.16 | O4: NA | P4: 31.56 | Q4: 0.57 | R4: 20100101 | S4: NA | T4: 6.82 | U4: 89.22 | V4: FNM30.350.10(GEN) | W4: 89.22 | X4: -49.67 | Y4: 51.08 | Z4: PL | AA4: 22838371 | AB4: 10.2 | AC4: 39.3 | AD4: 69.1 | AE4: 0 | AF4: 766.27 | AG4: 69.42 | AH4: -98.99 | AI4: 4.04 | AJ4: 2.57 | AK4: 348.97
A5: 0 | B5: ALGORITHM:TICKER | C5: 20100501 | D5: 20100501 | E5: TICKER:FNCL | F5: 196622.86 | G5: 197915.27 | H5: 0 | I5: 0.26 | J5: 29315300 | K5: 49.71 | L5: NA | M5: 14.71 | N5: 0.09 | O5: NA | P5: 28.51 | Q5: 0.94 | R5: 20100101 | S5: NA | T5: 7.68 | U5: 89.35 | V5: FNM30.350.10(GEN) | W5: 89.35 | X5: -45.41 | Y5: 50.32 | Z5: PL | AA5: 25749367 | AB5: 9.7 | AC5: 35.03 | AD5: 69.32 | AE5: 0 | AF5: 768.75 | AG5: 69.36 | AH5: -98.49 | AI5: 4.05 | AJ5: 3.36 | AK5: 347.66
A6: 0 | B6: ALGORITHM:TICKER | C6: 20100601 | D6: 20100601 | E6: TICKER:FNCL | F6: 197232.94 | G6: 198555.22 | H6: 0 | I6: 0.21 | J6: 36882562 | K6: 42.65 | L6: NA | M6: 11.67 | N6: 0.13 | O6: NA | P6: 26.34 | Q6: 1.55 | R6: 20100101 | S6: NA | T6: 6.09 | U6: 90.74 | V6: FNM30.350.10(GEN) | W6: 90.74 | X6: -46.09 | Y6: 46.24 | Z6: PL | AA6: 29270815 | AB6: 7.69 | AC6: 45.24 | AD6: 69.45 | AE6: 0 | AF6: 768.57 | AG6: 69.1 | AH6: -102.8 | AI6: 4.03 | AJ6: 3.72 | AK6: 349.12
A7: 0 | B7: ALGORITHM:TICKER | C7: 20100701 | D7: 20100701 | E7: TICKER:FNCL | F7: 220920.4 | G7: 222229.69 | H7: 0 | I7: 0.6 | J7: 87263562 | K7: 26.54 | L7: NA | M7: 5.27 | N7: 0.15 | O7: NA | P7: 18.47 | Q7: 1.49 | R7: 20100101 | S7: NA | T7: 5.22 | U7: 93.89 | V7: FNM30.350.10(GEN) | W7: 93.81 | X7: -30.22 | Y7: 39.57 | Z7: PL | AA7: 36826754 | AB7: 4.6 | AC7: 42.82 | AD7: 68.62 | AE7: 0 | AF7: 768.7 | AG7: 68.59 | AH7: -93.34 | AI7: 4.11 | AJ7: 3.01 | AK7: 350.67
A8: 0 | B8: ALGORITHM:TICKER | C8: 20100801 | D8: 20100801 | E8: TICKER:FNCL | F8: 245786.65 | G8: 246299.3 | H8: 0 | I8: 1.75 | J8: 4.9059017e+08 | K8: 10.06 | L8: NA | M8: 0.98 | N8: 0.09 | O8: NA | P8: 20.13 | Q8: 0.76 | R8: 20100101 | S8: NA | T8: 7.31 | U8: 94.8 | V8: FNM30.350.10(GEN) | W8: 93.94 | X8: -1.14 | Y8: 54.43 | Z8: PL | AA8: 87134375 | AB8: 4.43 | AC8: 52.49 | AD8: 69.24 | AE8: 0 | AF8: 772.77 | AG8: 69.22 | AH8: -59.86 | AI8: 4.32 | AJ8: 0.83 | AK8: 355.89
A9: 0 | B9: ALGORITHM:TICKER | C9: 20100901 | D9: 20100901 | E9: TICKER:FNCL | F9: 244833.31 | G9: 245096.94 | H9: 0 | I9: 0.9 | J9: 2967379734 | K9: 6.16 | L9: NA | M9: 0.18 | N9: 0.07 | O9: NA | P9: 26.82 | Q9: 0.46 | R9: 20100101 | S9: NA | T9: 6.3 | U9: 95.76 | V9: FNM30.350.10(GEN) | W9: 94.53 | X9: -0.56 | Y9: 63.29 | Z9: PL | AA9: 4.8991804e+08 | AB9: 3.76 | AC9: 71.23 | AD9: 68.72 | AE9: 0 | AF9: 774.23 | AG9: 68.69 | AH9: -43.41 | AI9: 4.32 | AJ9: 0.48 | AK9: 357.84
A10: 0 | B10: ALGORITHM:TICKER | C10: 20101001 | D10: 20101001 | E10: TICKER:FNCL | F10: 250318.14 | G10: 250629.7 | H10: 0 | I10: 1.3 | J10: 8684787874 | K10: 5.57 | L10: NA | M10: 0.09 | N10: 0.09 | O10: NA | P10: 27.37 | Q10: 0.4 | R10: 20100101 | S10: NA | T10: 5.79 | U10: 95.64 | V10: FNM30.350.10(GEN) | W10: 94.67 | X10: -5.8 | Y10: 68.02 | Z10: PL | AA10: 2957328910 | AB10: 3.94 | AC10: 74.73 | AD10: 68.32 | AE10: 0 | AF10: 773.97 | AG10: 68.11 | AH10: -37.66 | AI10: 4.27 | AJ10: 0.63 | AK10: 357.1
A11: 0 | B11: ALGORITHM:TICKER | C11: 20101101 | D11: 20101101 | E11: TICKER:FNCL | F11: 249043.03 | G11: 249572.18 | H11: 0 | I11: 0.97 | J11: 13373362167 | K11: 5.95 | L11: NA | M11: 0.12 | N11: 0.16 | O11: NA | P11: 26.48 | Q11: 0.41 | R11: 20100101 | S11: NA | T11: 5.79 | U11: 95.47 | V11: FNM30.350.10(GEN) | W11: 94.5 | X11: -10.69 | Y11: 67.93 | Z11: PL | AA11: 8672849751 | AB11: 4.11 | AC11: 71.19 | AD11: 68.53 | AE11: 0 | AF11: 774.01 | AG11: 68.09 | AH11: -38.15 | AI11: 4.22 | AJ11: 1.14 | AK11: 356.96
A12: 0 | B12: ALGORITHM:TICKER | C12: 20101201 | D12: 20101201 | E12: TICKER:FNCL | F12: 251308.12 | G12: 252030.02 | H12: 0 | I12: 2.33 | J12: 20936982252 | K12: 6.15 | L12: NA | M12: 0.11 | N12: 0.15 | O12: NA | P12: 26.74 | Q12: 0.43 | R12: 20100101 | S12: NA | T12: 5.92 | U12: 95.12 | V12: FNM30.350.10(GEN) | W12: 93.24 | X12: -17.49 | Y12: 66.67 | Z12: PL | AA12: 13354702347 | AB12: 4.43 | AC12: 68.16 | AD12: 68.89 | AE12: 0 | AF12: 773.8 | AG12: 68.37 | AH12: -38.66 | AI12: 4.15 | AJ12: 1.42 | AK12: 356.88
A13: 0 | B13: ALGORITHM:TICKER | C13: 20110101 | D13: 20110101 | E13: TICKER:FNCL | F13: 250921.11 | G13: 252065.76 | H13: 0 | I13: 2.12 | J13: 22982367010 | K13: 6.21 | L13: NA | M13: 0.12 | N13: 0.13 | O13: NA | P13: 26.92 | Q13: 0.42 | R13: 20100101 | S13: NA | T13: 5.97 | U13: 95.14 | V13: FNM30.350.10(GEN) | W13: 92.69 | X13: -19.16 | Y13: 66.36 | Z13: PL | AA13: 20907379928 | AB13: 4.43 | AC13: 68.19 | AD13: 69.62 | AE13: 0 | AF13: 773.74 | AG13: 68.49 | AH13: -38.81 | AI13: 4.14 | AJ13: 2.29 | AK13: 356.01
... A86: 0.03 | B86: ALGORITHM:TICKER | C86: 20170201 | D86: 20170201 | E86: TICKER:FNCL | F86: 191181.04 | G86: 227178.47 | H86: 1401.36 | I86: 12.82 | J86: 7830966937 | K86: 2.08 | L86: NA | M86: 0.01 | N86: 0.61 | O86: NA | P86: 12.4 | Q86: 0.69 | R86: 20100101 | S86: NA | T86: 6 | U86: 94.33 | V86: FNM30.350.10(GEN) | W86: 99.27 | X86: 14.48 | Y86: 65.99 | Z86: PL | AA86: 7921058357 | AB86: 4.96 | AC86: 61.8 | AD86: 45.63 | AE86: 0 | AF86: 772.71 | AG86: 69.35 | AH86: -41.23 | AI86: 4.1 | AJ86: 75.11 | AK86: 272.46

Sheet Diff
A1: HARP_eligible | B1: dimensionCombination | C1: factorDate | D1: modifyDate | E1: sliceId | F1: wacls | G1: ols | H1: burnout | I1: cpr | J1: bal | K1: currLLPA | L1: currMIP | M1: currPMI | N1: pct_dq | O1: pct_fha | P1: pct_HARPed | Q1: pct_inv | R1: issueDate | S1: origMIP | T1: origPMI | U1: pct_owner | V1: poolListName | W1: refi_elig_pct | X1: incentive | Y1: pct_REFI | Z1: replineMode | AA1: origbal | AB1: pct_2nd | AC1: pct_tpo | AD1: cltv | AE1: odti | AF1: fico | AG1: oltv | AH1: sato | AI1: wac | AJ1: wala | AK1: wam
A2: =FHL!A2-FNM!A3 -> 0 | B2: =FHL!B2-FNM!B3 -> #VALUE! | C2: =FHL!C2-FNM!C3 -> 0 | D2: =FHL!D2-FNM!D3 -> 0 | E2: =FHL!E2-FNM!E3 -> #VALUE! | F2: =FHL!F2-FNM!F3 -> 39817.04 | G2: =FHL!G2-FNM!G3 -> 39508.59 | H2: =FHL!H2-FNM!H3 -> 0 | ... AK2: =FHL!AK2-FNM!AK3 -> 9.63
A3: =FHL!A3-FNM!A4 -> 0 | B3: =FHL!B3-FNM!B4 -> #VALUE! | C3: =FHL!C3-FNM!C4 -> 0 | D3: =FHL!D3-FNM!D4 -> 0 | E3: =FHL!E3-FNM!E4 -> #VALUE! | F3: =FHL!F3-FNM!F4 -> 31793.48 | G3: =FHL!G3-FNM!G4 -> 31756.89 | H3: =FHL!H3-FNM!H4 -> 0 | ... AK3: =FHL!AK3-FNM!AK4 -> 8.37
A4: =FHL!A4-FNM!A5 -> 0 | B4: =FHL!B4-FNM!B5 -> #VALUE! | C4: =FHL!C4-FNM!C5 -> 0 | D4: =FHL!D4-FNM!D5 -> 0 | E4: =FHL!E4-FNM!E5 -> #VALUE! | F4: =FHL!F4-FNM!F5 -> 47212.17 | G4: =FHL!G4-FNM!G5 -> 47202.14 | H4: =FHL!H4-FNM!H5 -> 0 | ... AK4: =FHL!AK4-FNM!AK5 -> 8.68
A5: =FHL!A5-FNM!A6 -> 0 | B5: =FHL!B5-FNM!B6 -> #VALUE! | C5: =FHL!C5-FNM!C6 -> 0 | D5: =FHL!D5-FNM!D6 -> 0 | E5: =FHL!E5-FNM!E6 -> #VALUE! | F5: =FHL!F5-FNM!F6 -> 46189.63 | G5: =FHL!G5-FNM!G6 -> 46562.19 | H5: =FHL!H5-FNM!H6 -> 0 | ... AK5: =FHL!AK5-FNM!AK6 -> 6.22
A6: =FHL!A6-FNM!A7 -> 0 | B6: =FHL!B6-FNM!B7 -> #VALUE! | C6: =FHL!C6-FNM!C7 -> 0 | D6: =FHL!D6-FNM!D7 -> 0 | E6: =FHL!E6-FNM!E7 -> #VALUE! | F6: =FHL!F6-FNM!F7 -> 22088.38 | G6: =FHL!G6-FNM!G7 -> 22887.72 | H6: =FHL!H6-FNM!H7 -> 0 | ... AK6: =FHL!AK6-FNM!AK7 -> 3.67
A7: =FHL!A7-FNM!A8 -> 0 | B7: =FHL!B7-FNM!B8 -> #VALUE! | C7: =FHL!C7-FNM!C8 -> 0 | D7: =FHL!D7-FNM!D8 -> 0 | E7: =FHL!E7-FNM!E8 -> #VALUE! | F7: =FHL!F7-FNM!F8 -> -10924.01 | G7: =FHL!G7-FNM!G8 -> -10718.8 | H7: =FHL!H7-FNM!H8 -> 0 | ... AK7: =FHL!AK7-FNM!AK8 -> -1.49
A8: =FHL!A8-FNM!A9 -> 0 | B8: =FHL!B8-FNM!B9 -> #VALUE! | C8: =FHL!C8-FNM!C9 -> 0 | D8: =FHL!D8-FNM!D9 -> 0 | E8: =FHL!E8-FNM!E9 -> #VALUE! | F8: =FHL!F8-FNM!F9 -> -8754.56 | G8: =FHL!G8-FNM!G9 -> -8750 | H8: =FHL!H8-FNM!H9 -> 0 | ... AK8: =FHL!AK8-FNM!AK9 -> -1.45
A9: =FHL!A9-FNM!A10 -> 0.75 | B9: =FHL!B9-FNM!B10 -> #VALUE! | C9: =FHL!C9-FNM!C10 -> 0 | D9: =FHL!D9-FNM!D10 -> 0 | E9: =FHL!E9-FNM!E10 -> #VALUE! | F9: =FHL!F9-FNM!F10 -> 9654.82 | G9: =FHL!G9-FNM!G10 -> 9701.76 | H9: =FHL!H9-FNM!H10 -> 0 | ... AK9: =FHL!AK9-FNM!AK10 -> -0.57
A10: =FHL!A10-FNM!A11 -> 0.25 | B10: =FHL!B10-FNM!B11 -> #VALUE! | C10: =FHL!C10-FNM!C11 -> 0 | D10: =FHL!D10-FNM!D11 -> 0 | E10: =FHL!E10-FNM!E11 -> #VALUE! | F10: =FHL!F10-FNM!F11 -> 8679.15 | G10: =FHL!G10-FNM!G11 -> 8528.01 | H10: =FHL!H10-FNM!H11 -> 0 | ... AK10: =FHL!AK10-FNM!AK11 -> 0.57
A11: =FHL!A11-FNM!A12 -> 0.13 | B11: =FHL!B11-FNM!B12 -> #VALUE! | C11: =FHL!C11-FNM!C12 -> 0 | D11: =FHL!D11-FNM!D12 -> 0 | E11: =FHL!E11-FNM!E12 -> #VALUE! | F11: =FHL!F11-FNM!F12 -> 15589.71 | G11: =FHL!G11-FNM!G12 -> 15407.78 | H11: =FHL!H11-FNM!H12 -> 0 | ... AK11: =FHL!AK11-FNM!AK12 -> 0.71
A12: =FHL!A12-FNM!A13 -> 0.1 | B12: =FHL!B12-FNM!B13 -> #VALUE! | C12: =FHL!C12-FNM!C13 -> 0 | D12: =FHL!D12-FNM!D13 -> 0 | E12: =FHL!E12-FNM!E13 -> #VALUE! | F12: =FHL!F12-FNM!F13 -> 15287.69 | G12: =FHL!G12-FNM!G13 -> 15013.98 | H12: =FHL!H12-FNM!H13 -> 0 | ... AK12: =FHL!AK12-FNM!AK13 -> 0.7
A13: =FHL!A13-FNM!A14 -> 0.11 | B13: =FHL!B13-FNM!B14 -> #VALUE! | C13: =FHL!C13-FNM!C14 -> 0 | D13: =FHL!D13-FNM!D14 -> 0 | E13: =FHL!E13-FNM!E14 -> #VALUE! | F13: =FHL!F13-FNM!F14 -> 15169.32 | G13: =FHL!G13-FNM!G14 -> 14949.27 | H13: =FHL!H13-FNM!H14 -> 0 | ... AK13: =FHL!AK13-FNM!AK14 -> 0.45
... A67: =FHL!A67-FNM!A68 -> 0.11 | B67: =FHL!B67-FNM!B68 -> #VALUE! | C67: =FHL!C67-FNM!C68 -> 0 | D67: =FHL!D67-FNM!D68 -> 0 | E67: =FHL!E67-FNM!E68 -> #VALUE! | F67: =FHL!F67-FNM!F68 -> -4302.62 | G67: =FHL!G67-FNM!G68 -> -5264.96 | H67: =FHL!H67-FNM!H68 -> 629.91 | ... AK67: =FHL!AK67-FNM!AK68 -> -0.13

Sheet Incentive
B1: FHL incentive | C1: FNM incentive | S1: PoolListName | T1: asof | U1: TotalBalance | V1: AvgIncentive | W1: PoolCount | Z1: PoolListName | AA1: asof | AB1: TotalBalance | AC1: AvgIncentive | AD1: PoolCount | AG1: FHL | AH1: FNM
A2: 20100301 | B2: -132.75 | C2: -55.1 | S2: FHL30.350.10(GEN) | T2: 40210 | U2: 2714429 | V2: -132.4832 | W2: 1 | Z2: FNM30.350.10(GEN) | AA2: 40179 | AB2: 6583675 | AC2: -73.093344 | AD2: 2 | AF2: 40210 | AG2: -132.4832 | AH2: -50.084436
A3: 20100401 | B3: -125.03 | C3: -48.56 | S3: FHL30.350.10(GEN) | T3: 40238 | U3: 4159148.5 | V3: -132.75128 | W3: 2 | Z3: FNM30.350.10(GEN) | AA3: 40210 | AB3: 12469876 | AC3: -50.084436 | AD3: 4 | AF3: 40238 | AG3: -132.75128 | AH3: -45.858026
A4: 20100501 | B4: -130.18 | C4: -49.67 | S4: FHL30.350.10(GEN) | T4: 40269 | U4: 4152182.5 | V4: -125.03622 | W4: 2 | Z4: FNM30.350.10(GEN) | AA4: 40238 | AB4: 22930199 | AC4: -45.858026 | AD4: 8 | AF4: 40269 | AG4: -125.03622 | AH4: -47.270376
A5: 20100601 | B5: -105.04 | C5: -45.41 | N5: PoolListName | O5: TotalBalance | P5: PoolCount | S5: FHL30.350.10(GEN) | T5: 40299 | U5: 4145195.5 | V5: -130.18738 | W5: 2 | Z5: FNM30.350.10(GEN) | AA5: 40269 | AB5: 25846157 | AC5: -47.270376 | AD5: 10 | AF5: 40299 | AG5: -130.18738 | AH5: -43.313598
A6: 20100701 | B6: -92.27 | C6: -46.09 | N6: FHL30.350.10(T6) | O6: 510949.58 | P6: 1 | S6: FHL30.350.10(GEN) | T6: 40330 | U6: 4138183.8 | V6: -105.04334 | W6: 2 | Z6: FNM30.350.10(GEN) | AA6: 40299 | AB6: 29374689 | AC6: -43.313598 | AD6: 13 | AF6: 40330 | AG6: -105.04334 | AH6: -43.786118
A7: 20100801 | B7: -56.61 | C7: -30.22 | N7: FHL30.350.10(MHA90) | O7: 1043882.6 | P7: 1 | S7: FHL30.350.10(GEN) | T7: 40360 | U7: 4131149.3 | V7: -92.276296 | W7: 2 | Z7: FNM30.350.10(GEN) | AA7: 40330 | AB7: 38949484 | AC7: -43.786118 | AD7: 17 | AF7: 40360 | AG7: -92.276296 | AH7: -29.58407
A8: 20100901 | B8: -35.71 | C8: -1.14 | N8: FHL30.350.10(MHA95) | O8: 8374815.8 | P8: 1 | S8: FHL30.350.10(GEN) | T8: 40391 | U8: 14561484 | V8: -56.619979 | W8: 5 | Z8: FNM30.350.10(GEN) | AA8: 40360 | AB8: 89328927 | AC8: -29.58407 | AD8: 23 | AF8: 40391 | AG8: -56.619979 | AH8: -1.1476246
A9: 20101001 | B9: -24.52 | C9: -0.56 | N9: FHL30.350.10(U6) | O9: 3063171.5 | P9: 2 | S9: FHL30.350.10(GEN) | T9: 40422 | U9: 91126400 | V9: -35.717578 | W9: 12 | Z9: FNM30.350.10(GEN) | AA9: 40391 | AB9: 4.9265278e+08 | AC9: -1.1476246 | AD9: 41 | AF9: 40422 | AG9: -35.717578 | AH9: -0.46559102
A10: 20101101 | B10: -20.54 | C10: -5.8 | N10: FHL30.350.10(MHA85) | O10: 4269309.9 | P10: 2 | S10: FHL30.350.10(GEN) | T10: 40452 | U10: 7.2246486e+08 | V10: -24.523062 | W10: 34 | Z10: FNM30.350.10(GEN) | AA10: 40422 | AB10: 2.9595826e+09 | AC10: -0.46559102 | AD10: 106 | AF10: 40452 | AG10: -24.523062 | AH10: -5.7982079
A11: 20101201 | B11: -34.18 | C11: -10.69 | N11: FHL30.350.10(HHLB) | O11: 1.011277e+08 | P11: 8 | S11: FHL30.350.10(GEN) | T11: 40483 | U11: 2.0986317e+09 | V11: -20.54926 | W11: 72 | Z11: FNM30.350.10(GEN) | AA11: 40452 | AB11: 8.6800726e+09 | AC11: -5.7982079 | AD11: 231 | AF11: 40483 | AG11: -20.54926 | AH11: -10.695447
A12: 20110101 | B12: -78.15 | C12: -17.49 | N12: FHL30.350.10(LLB) | O12: 36205869 | P12: 8 | S12: FHL30.350.10(GEN) | T12: 40513 | U12: 3.856688e+09 | V12: -34.223745 | W12: 125 | Z12: FNM30.350.10(GEN) | AA12: 40483 | AB12: 1.3364581e+10 | AC12: -10.695447 | AD12: 372 | AF12: 40513 | AG12: -34.223745 | AH12: -17.468601
A13: 20110201 | B13: -85.03 | C13: -19.16 | N13: FHL30.350.10(MLB) | O13: 95720648 | P13: 16 | S13: FHL30.350.10(GEN) | T13: 40544 | U13: 5.0630709e+09 | V13: -78.121478 | W13: 154 | Z13: FNM30.350.10(GEN) | AA13: 40513 | AB13: 2.0899069e+10 | AC13: -17.468601 | AD13: 562 | AF13: 40544 | AG13: -78.121478 | AH13: -19.133786
A14: 20110301 | B14: -104.53 | C14: -19.28 | N14: FHL30.350.10(HLB) | O14: 2.0841368e+08 | P14: 23 | S14: FHL30.350.10(GEN) | T14: 40575 | U14: 5.2123938e+09 | V14: -84.992275 | W14: 158 | Z14: FNM30.350.10(GEN) | AA14: 40544 | AB14: 2.2942683e+10 | AC14: -19.133786 | AD14: 622 | AF14: 40575 | AG14: -84.992275 | AH14: -19.251755
A15: 20110401 | B15: -91.43 | C15: -19.46 | N15: FHL30.350.10(ABOVE175K) | O15: 3.6152435e+09 | P15: 123 | S15: FHL30.350.10(GEN) | T15: 40603 | U15: 5.2082867e+09 | V15: -104.50907 | W15: 161 | Z15: FNM30.350.10(GEN) | AA15: 40575 | AB15: 2.2983144e+10 | AC15: -19.251755 | AD15: 636 | AF15: 40603 | AG15: -104.50907 | AH15: -19.437011
A16: 20110501 | B16: -90.26 | C16: -19.35 | N16: FHL30.350.10(GEN) | O16: 4.110084e+09 | P16: 179 | S16: FHL30.350.10(GEN) | T16: 40634 | U16: 5.2085965e+09 | V16: -91.405959 | W16: 163 | Z16: FNM30.350.10(GEN) | AA16: 40603 | AB16: 2.293753e+10 | AC16: -19.437011 | AD16: 639 | AF16: 40634 | AG16: -91.405959 | AH16: -19.324756
A17: 20110601 | B17: -68.71 | C17: -19.35 | S17: FHL30.350.10(GEN) | T17: 40664 | U17: 5.1953948e+09 | V17: -90.234933 | W17: 164 | Z17: FNM30.350.10(GEN) | AA17: 40634 | AB17: 2.2875559e+10 | AC17: -19.324756 | AD17: 640 | AF17: 40664 | AG17: -90.234933 | AH17: -19.323915
A18: 20110701 | B18: -54.69 | C18: -19.16 | S18: FHL30.350.10(GEN) | T18: 40695 | U18: 5.1901913e+09 | V18: -68.683689 | W18: 167 | Z18: FNM30.350.10(GEN) | AA18: 40664 | AB18: 2.281562e+10 | AC18: -19.323915 | AD18: 642 | AF18: 40695 | AG18: -68.683689 | AH18: -19.132893
A19: 20110801 | B19: -57.94 | C19: -19.04 | N19: PoolListName | O19: TotalBalance | P19: PoolCount | S19: FHL30.350.10(GEN) | T19: 40725 | U19: 5.1684653e+09 | V19: -54.671937 | W19: 167 | Z19: FNM30.350.10(GEN) | AA19: 40695 | AB19: 2.2743402e+10 | AC19: -19.132893 | AD19: 643 | AF19: 40725 | AG19: -54.671937 | AH19: -19.014275
A20: 20110901 | B20: -28.18 | C20: -19.09 | N20: FNM30.350.10(MHA90) | O20: 5194214.4 | P20: 1 | S20: FHL30.350.10(GEN) | T20: 40756 | U20: 5.1482301e+09 | V20: -57.912209 | W20: 167 | Z20: FNM30.350.10(GEN) | AA20: 40725 | AB20: 2.2653603e+10 | AC20: -19.014275 | AD20: 643 | AF20: 40756 | AG20: -57.912209 | AH20: -19.062104
A21: 20111001 | B21: -10.6 | C21: -18.82 | N21: FNM30.350.10(LOWFICO) | O21: 982032 | P21: 1 | S21: FHL30.350.10(GEN) | T21: 40787 | U21: 5.1246426e+09 | V21: -28.166462 | W21: 167 | Z21: FNM30.350.10(GEN) | AA21: 40756 | AB21: 2.2567608e+10 | AC21: -19.062104 | AD21: 643 | AF21: 40787 | AG21: -28.166462 | AH21: -18.786152
A22: 20111101 | B22: -13.08 | C22: -18.7 | N22: FNM30.350.10(MHA85) | O22: 10559769 | P22: 2 | S22: FHL30.350.10(GEN) | T22: 40817 | U22: 5.0889145e+09 | V22: -10.586959 | W22: 167 | Z22: FNM30.350.10(GEN) | AA22: 40787 | AB22: 2.2454913e+10 | AC22: -18.786152 | AD22: 644 | AF22: 40817 | AG22: -10.586959 | AH22: -18.673349
A23: 20111201 | B23: -4.44 | C23: -18.8 | N23: FNM30.350.10(INV100) | O23: 5954904 | P23: 3 | S23: FHL30.350.10(GEN) | T23: 40848 | U23: 5.0525582e+09 | V23: -13.05885 | W23: 167 | Z23: FNM30.350.10(GEN) | AA23: 40817 | AB23: 2.2267994e+10 | AC23: -18.673349 | AD23: 644 | AF23: 40848 | AG23: -13.05885 | AH23: -18.768622
A24: 20120101 | B24: -0.53 | C24: -18.81 | N24: FNM30.350.10(MHA100) | O24: 5817288.9 | P24: 3 | S24: FHL30.350.10(GEN) | T24: 40878 | U24: 5.004994e+09 | V24: -4.41013 | W24: 167 | Z24: FNM30.350.10(GEN) | AA24: 40848 | AB24: 22033509405 | AC24: -18.768622 | AD24: 645 | AF24: 40878 | AG24: -4.41013 | AH24: -18.789503
A25: 20120201 | B25: 2.19 | C25: -18.84 | N25: FNM30.350.10(MHA80) | O25: 96940304 | P25: 4 | S25: FHL30.350.10(GEN) | T25: 40909 | U25: 4.9683152e+09 | V25: -0.51684894 | W25: 167 | Z25: FNM30.350.10(GEN) | AA25: 40878 | AB25: 2.1736339e+10 | AC25: -18.789503 | AD25: 645 | AF25: 40909 | AG25: -0.51684894 | AH25: -18.813894
A26: 20120301 | B26: 5.45 | C26: -18.87 | N26: FNM30.350.10(MHA95) | O26: 5813646.5 | P26: 4 | S26: FHL30.350.10(GEN) | T26: 40940 | U26: 4.9275283e+09 | V26: 2.212249 | W26: 167 | Z26: FNM30.350.10(GEN) | AA26: 40909 | AB26: 2.1517626e+10 | AC26: -18.813894 | AD26: 645 | AF26: 40940 | AG26: 2.212249 | AH26: -18.848748
A27: 20120401 | B27: 1.94 | C27: -18.91 | N27: FNM30.350.10(CQ) | O27: 9661025.8 | P27: 5 | S27: FHL30.350.10(GEN) | T27: 40969 | U27: 4.9490383e+09 | V27: 5.4680633 | W27: 168 | Z27: FNM30.350.10(GEN) | AA27: 40940 | AB27: 2.1279225e+10 | AC27: -18.848748 | AD27: 645 | AF27: 40969 | AG27: 5.4680633 | AH27: -18.891267
A28: 20120501 | B28: 11.52 | C28: -19.06 | N28: FNM30.350.10(CK) | O28: 1.6510864e+08 | P28: 12 | S28: FHL30.350.10(GEN) | T28: 41000 | U28: 5.2024238e+09 | V28: 1.9920419 | W28: 175 | Z28: FNM30.350.10(GEN) | AA28: 40969 | AB28: 2.0986947e+10 | AC28: -18.891267 | AD28: 646 | AF28: 41000 | AG28: 1.9920419 | AH28: -19.0351
A29: 20120601 | B29: 23.29 | C29: -19.05 | N29: FNM30.350.10(LLB) | O29: 61792518 | P29: 13 | S29: FHL30.350.10(GEN) | T29: 41030 | U29: 5.1498021e+09 | V29: 11.615211 | W29: 175 | Z29: FNM30.350.10(GEN) | AA29: 41000 | AB29: 2.0659795e+10 | AC29: -19.0351 | AD29: 646 | AF29: 41030 | AG29: 11.615211 | AH29: -19.024032
A30: 20120701 | B30: 39.04 | C30: -19 | N30: FNM30.350.10(MLB) | O30: 1.3237298e+08 | P30: 15 | S30: FHL30.350.10(GEN) | T30: 41061 | U30: 5.1084821e+09 | V30: 24.335996 | W30: 177 | Z30: FNM30.350.10(GEN) | AA30: 41030 | AB30: 2.0426265e+10 | AC30: -19.024032 | AD30: 646 | AF30: 41061 | AG30: 24.335996 | AH30: -18.975152
A31: 20120801 | B31: 51.47 | C31: -18.93 | N31: FNM30.350.10(HHLB) | O31: 2.1228249e+08 | P31: 20 | S31: FHL30.350.10(GEN) | T31: 41091 | U31: 5.0482915e+09 | V31: 39.051833 | W31: 178 | Z31: FNM30.350.10(GEN) | AA31: 41061 | AB31: 2.0185493e+10 | AC31: -18.975152 | AD31: 650 | AF31: 41091 | AG31: 39.051833 | AH31: -18.911951
... A34: 20121101 | B34: 69.43 | C34: -19.01 | N34: FNM30.350.10(GEN) | O34: 1.5776741e+10 | P34: 651 | S34: FHL30.350.10(GEN) | T34: 41183 | U34: 4.6802914e+09 | V34: 59.661727 | W34: 178 | Z34: FNM30.350.10(GEN) | AA34: 41153 | AB34: 1.8674628e+10 | AC34: -19.029571 | AD34: 650 | AF34: 41183 | AG34: 59.661727 | AH34: -19.006413
A35: 20121201 | B35: 72.24 | C35: -18.98 | S35: FHL30.350.10(GEN) | T35: 41214 | U35: 4.5446044e+09 | V35: 69.488558 | W35: 178 | Z35: FNM30.350.10(GEN) | AA35: 41183 | AB35: 1.8104742e+10 | AC35: -19.006413 | AD35: 650 | AF35: 41214 | AG35: 69.488558 | AH35: -18.985349
A36: 20130101 | B36: 72.86 | C36: -19.05 | S36: FHL30.350.10(GEN) | T36: 41244 | U36: 4.3828309e+09 | V36: 72.219019 | W36: 178 | Z36: FNM30.350.10(GEN) | AA36: 41214 | AB36: 1.7529285e+10 | AC36: -18.985349 | AD36: 651 | AF36: 41244 | AG36: 72.219019 | AH36: -19.044215
A37: 20130201 | B37: 66.18 | C37: -19.12 | S37: FHL30.350.10(GEN) | T37: 41275 | U37: 4.2373884e+09 | V37: 72.843223 | W37: 178 | Z37: FNM30.350.10(GEN) | AA37: 41244 | AB37: 1.6917534e+10 | AC37: -19.044215 | AD37: 651 | AF37: 41275 | AG37: 72.843223 | AH37: -19.133043
A38: 20130301 | B38: 52.14 | C38: -19.28 | S38: FHL30.350.10(GEN) | T38: 41306 | U38: 4.110084e+09 | V38: 66.16996 | W38: 179 | Z38: FNM30.350.10(GEN) | AA38: 41275 | AB38: 1.6292697e+10 | AC38: -19.133043 | AD38: 651 | AF38: 41306 | AG38: 66.16996 | AH38: -19.271415
A39: 20130401 | B39: 51.04 | C39: -19.51 | S39: FHL30.350.10(GEN) | T39: 41334 | U39: 4.0110984e+09 | V39: 52.125052 | W39: 179 | Z39: FNM30.350.10(GEN) | AA39: 41306 | AB39: 1.5776741e+10 | AC39: -19.271415 | AD39: 651 | AF39: 41334 | AG39: 52.125052 | AH39: -19.498861
A40: 20130501 | B40: 64.21 | C40: -19.62 | S40: FHL30.350.10(GEN) | T40: 41365 | U40: 3.9156008e+09 | V40: 51.033561 | W40: 179 | Z40: FNM30.350.10(GEN) | AA40: 41334 | AB40: 1.5355382e+10 | AC40: -19.498861 | AD40: 651 | AF40: 41365 | AG40: 51.033561 | AH40: -19.607861
A41: 20130601 | B41: 57.36 | C41: -19.54 | S41: FHL30.350.10(GEN) | T41: 41395 | U41: 3.8316251e+09 | V41: 64.156321 | W41: 179 | Z41: FNM30.350.10(GEN) | AA41: 41365 | AB41: 1.4985041e+10 | AC41: -19.607861 | AD41: 651 | AF41: 41395 | AG41: 64.156321 | AH41: -19.562791
A42: 20130701 | B42: 3.52 | C42: -19.71 | S42: FHL30.350.10(GEN) | T42: 41426 | U42: 3.7472023e+09 | V42: 57.300507 | W42: 180 | Z42: FNM30.350.10(GEN) | AA42: 41395 | AB42: 1.4653498e+10 | AC42: -19.562791 | AD42: 651 | AF42: 41426 | AG42: 57.300507 | AH42: -19.725833
...

Sheet Sheet5
C1: FNM | L1: FHL | U1: 2747333 | AK1: 2747333
A2: PoolListName | C2: TotalBalance | D2: AvgOrigPMI | E2: AvgLLPA | F2: AvgPMI | G2: AvgIncentive | H2: PoolCount | J2: PoolListName | K2: asof | L2: TotalBalance | M2: AvgOrigPMI | N2: AvgLLPA | O2: AvgPMI | P2: AvgIncentive | Q2: PoolCount | S2: PoolListName | T2: asof | U2: TotalBalance | V2: AvgOrigPMI | W2: AvgLLPA | X2: AvgPMI | Y2: AvgIncentive | Z2: PoolCount | AA2: refi_incentive | AI2: PoolListName | AJ2: asof | AK2: TotalBalance | AL2: AvgOrigPMI | AM2: AvgLLPA | AN2: AvgPMI | AO2: AvgIncentive | AP2: PoolCount | AQ2: refi_incentive
A3: FNM30.350.10(GEN) | B3: 40210 | C3: 12469876 | D3: 10.335373 | E3: 66.250763 | F3: 140.6842 | G3: -50.084436 | H3: 4 | J3: FHL30.350.10(GEN) | K3: 40210 | L3: 2714429 | M3: 0 | N3: 39.1923 | O3: 62.5 | P3: -132.4832 | Q3: 1
A4: FNM30.350.10(GEN) | B4: 40238 | C4: 22930199 | D4: 7.6868087 | E4: 49.578768 | F4: 138.65952 | G4: -45.858026 | H4: 8 | J4: FHL30.350.10(GEN) | K4: 40238 | L4: 4159148.5 | M4: 0 | N4: 38.10727 | O4: 62.5 | P4: -132.75128 | Q4: 2
A5: FNM30.350.10(GEN) | B5: 40269 | C5: 25846157 | D5: 6.8091637 | E5: 50.897297 | F5: 139.3359 | G5: -47.270376 | H5: 10 | J5: FHL30.350.10(GEN) | K5: 40269 | L5: 4152182.5 | M5: 0 | N5: 38.106937 | O5: 62.5 | P5: -125.03622 | Q5: 2 | S5: FNM30.350.10(GEN) | T5: 40269 | U5: 1730551 | V5: 0 | W5: 94.7962 | X5: 144.58 | Y5: -61.3593 | Z5: 1 | AA5: -84.7187 | AI5: FNM30.350.10(GEN) | AJ5: 40269 | AK5: 1730551 | AL5: 0 | AM5: 94.7962 | AN5: 144.58 | AO5: -61.3593 | AP5: 1 | AQ5: -114.8193
A6: FNM30.350.10(GEN) | B6: 40299 | C6: 29374689 | D6: 7.6630913 | E6: 46.890629 | F6: 139.97336 | G6: -43.313598 | H6: 13 | J6: FHL30.350.10(GEN) | K6: 40299 | L6: 4145195.5 | M6: 0 | N6: 36.380534 | O6: 68.75 | P6: -130.18738 | Q6: 2 | S6: FNM30.350.10(GEN) | T6: 40299 | U6: 1727955.3 | V6: 0 | W6: 94.7962 | X6: 144.58 | Y6: -61.4643 | Z6: 1 | AA6: -95.2187 | AI6: FNM30.350.10(GEN) | AJ6: 40299 | AK6: 1727955.3 | AL6: 0 | AM6: 94.7962 | AN6: 144.58 | AO6: -61.4643 | AP6: 1 | AQ6: -125.3193
A7: FNM30.350.10(GEN) | B7: 40330 | C7: 38949484 | D7: 5.7695277 | E7: 38.722985 | F7: 141.11193 | G7: -43.786118 | H7: 17 | J7: FHL30.350.10(GEN) | K7: 40330 | L7: 4138183.8 | M7: 0 | N7: 36.382428 | O7: 68.75 | P7: -105.04334 | Q7: 2 | S7: FNM30.350.10(GEN) | T7: 40330 | U7: 1725370.6 | V7: 0 | W7: 94.7962 | X7: 144.58 | Y7: -61.2618 | Z7: 1 | AA7: -74.9687 | AI7: FNM30.350.10(GEN) | AJ7: 40330 | AK7: 1725370.6 | AL7: 0 | AM7: 94.7962 | AN7: 144.58 | AO7: -61.2618 | AP7: 1 | AQ7: -105.0692
A8: FNM30.350.10(GEN) | B8: 40360 | C8: 89328927 | D8: 5.0997264 | E8: 25.209744 | F8: 142.33138 | G8: -29.58407 | H8: 23 | J8: FHL30.350.10(GEN) | K8: 40360 | L8: 4131149.3 | M8: 0 | N8: 36.384321 | O8: 68.75 | P8: -92.276296 | Q8: 2 | S8: FNM30.350.10(GEN) | T8: 40360 | U8: 1722756.1 | V8: 0 | W8: 94.7962 | X8: 144.58 | Y8: -61.0853 | Z8: 1 | AA8: -57.3187 | AI8: FNM30.350.10(GEN) | AJ8: 40360 | AK8: 1722756.1 | AL8: 0 | AM8: 94.7962 | AN8: 144.58 | AO8: -61.0853 | AP8: 1 | AQ8: -87.4192
A9: FNM30.350.10(GEN) | B9: 40391 | C9: 4.9265278e+08 | D9: 7.28616 | E9: 9.8945676 | F9: 143.94168 | G9: -1.1476246 | H9: 41 | J9: FHL30.350.10(GEN) | K9: 40391 | L9: 14561484 | M9: 1.4883197 | N9: 41.822985 | O9: 68.809944 | P9: -56.619979 | Q9: 5 | S9: FNM30.350.10(GEN) | T9: 40391 | U9: 1720132.7 | V9: 0 | W9: 94.7962 | X9: 144.58 | Y9: -60.9343 | Z9: 1 | AA9: -42.2187 | AI9: FNM30.350.10(GEN) | AJ9: 40391 | AK9: 1720132.7 | AL9: 0 | AM9: 94.7962 | AN9: 144.58 | AO9: -60.9343 | AP9: 1 | AQ9: -72.3192
A10: FNM30.350.10(GEN) | B10: 40422 | C10: 2.9595826e+09 | D10: 6.3233027 | E10: 6.0746637 | F10: 144.42416 | G10: -0.46559102 | H10: 106 | J10: FHL30.350.10(GEN) | K10: 40422 | L10: 91126400 | M10: 6.0830644 | N10: 33.031971 | O10: 68.795476 | P10: -35.717578 | Q10: 12 | S10: FNM30.350.10(GEN) | T10: 40422 | U10: 1717479.6 | V10: 0 | W10: 94.7962 | X10: 144.58 | Y10: -60.8018 | Z10: 1 | AA10: -28.9687 | AI10: FNM30.350.10(GEN) | AJ10: 40422 | AK10: 1717479.6 | AL10: 0 | AM10: 94.7962 | AN10: 144.58 | AO10: -60.8018 | AP10: 1 | AQ10: -59.0692
A11: FNM30.350.10(GEN) | B11: 40452 | C11: 8.6800726e+09 | D11: 5.7986132 | E11: 5.5597236 | F11: 144.51864 | G11: -5.7982079 | H11: 231 | J11: FHL30.350.10(GEN) | K11: 40452 | L11: 7.2246486e+08 | M11: 5.2646522 | N11: 39.392656 | O11: 68.823298 | P11: -24.523062 | Q11: 34 | S11: FNM30.350.10(GEN) | T11: 40452 | U11: 1713038.2 | V11: 0 | W11: 94.7962 | X11: 144.58 | Y11: -60.7253 | Z11: 1 | AA11: -21.3231 | AI11: FNM30.350.10(GEN) | AJ11: 40452 | AK11: 1713038.2 | AL11: 0 | AM11: 94.7962 | AN11: 144.58 | AO11: -60.7253 | AP11: 1 | AQ11: -51.4192
A12: FNM30.350.10(GEN) | B12: 40483 | C12: 1.3364581e+10 | D12: 5.8006223 | E12: 5.9385787 | F12: 144.53588 | G12: -10.695447 | H12: 372 | J12: FHL30.350.10(GEN) | K12: 40483 | L12: 2.0986317e+09 | M12: 5.3116713 | N12: 39.699012 | O12: 93.408224 | P12: -20.54926 | Q12: 72 | S12: FNM30.350.10(GEN) | T12: 40483 | U12: 1710402.6 | V12: 0 | W12: 94.7962 | X12: 144.58 | Y12: -60.6243 | Z12: 1 | AA12: -11.2231 | AI12: FNM30.350.10(GEN) | AJ12: 40483 | AK12: 1710402.6 | AL12: 0 | AM12: 94.7962 | AN12: 144.58 | AO12: -60.6243 | AP12: 1 | AQ12: -41.3192
A13: FNM30.350.10(GEN) | B13: 40513 | C13: 2.0899069e+10 | D13: 5.9321826 | E13: 6.1410223 | F13: 144.55241 | G13: -17.468601 | H13: 562 | J13: FHL30.350.10(GEN) | K13: 40513 | L13: 3.856688e+09 | M13: 4.4110059 | N13: 39.089147 | O13: 93.431509 | P13: -34.223745 | Q13: 125 | S13: FNM30.350.10(GEN) | T13: 40513 | U13: 1707757.9 | V13: 0 | W13: 94.7962 | X13: 144.58 | Y13: -60.7055 | Z13: 1 | AA13: -19.3481 | AI13: FNM30.350.10(GEN) | AJ13: 40513 | AK13: 1707757.9 | AL13: 0 | AM13: 94.7962 | AN13: 144.58 | AO13: -60.7055 | AP13: 1 | AQ13: -49.4443
A14: FNM30.350.10(GEN) | B14: 40544 | C14: 2.2942683e+10 | D14: 5.9837907 | E14: 6.2044915 | F14: 144.55679 | G14: -19.133786 | H14: 622 | J14: FHL30.350.10(GEN) | K14: 40544 | L14: 5.0630709e+09 | M14: 4.2536126 | N14: 40.624793 | O14: 93.465969 | P14: -78.121478 | Q14: 154 | S14: FNM30.350.10(GEN) | T14: 40544 | U14: 1703294.9 | V14: 0 | W14: 94.7962 | X14: 144.58 | Y14: -61.0983 | Z14: 1 | AA14: -58.6274 | AI14: FNM30.350.10(GEN) | AJ14: 40544 | AK14: 1703294.9 | AL14: 0 | AM14: 94.7962 | AN14: 144.58 | AO14: -61.0983 | AP14: 1 | AQ14: -88.7192
A15: FNM30.350.10(GEN) | B15: 40575 | C15: 2.2983144e+10 | D15: 5.9903756 | E15: 6.2540923 | F15: 144.55319 | G15: -19.251755 | H15: 636 | J15: FHL30.350.10(GEN) | K15: 40575 | L15: 5.2123938e+09 | M15: 4.1420861 | N15: 44.22281 | O15: 93.483361 | P15: -84.992275 | Q15: 158 | S15: FNM30.350.10(GEN) | T15: 40575 | U15: 1700584.6 | V15: 0 | W15: 94.7962 | X15: 144.58 | Y15: -61.148 | Z15: 1 | AA15: -63.6025 | AI15: FNM30.350.10(GEN) | AJ15: 40575 | AK15: 1700584.6 | AL15: 0 | AM15: 94.7962 | AN15: 144.58 | AO15: -61.148 | AP15: 1 | AQ15: -93.6943
A16: FNM30.350.10(GEN) | B16: 40603 | C16: 2.293753e+10 | D16: 5.9902636 | E16: 6.2540767 | F16: 144.5532 | G16: -19.437011 | H16: 639 | J16: FHL30.350.10(GEN) | K16: 40603 | L16: 5.2082867e+09 | M16: 4.140861 | N16: 47.373649 | O16: 93.509553 | P16: -104.50907 | Q16: 161 | S16: FNM30.350.10(GEN) | T16: 40603 | U16: 1697885.7 | V16: 0 | W16: 94.7962 | X16: 144.58 | Y16: -61.3268 | Z16: 1 | AA16: -81.4775 | AI16: FNM30.350.10(GEN) | AJ16: 40603 | AK16: 1697885.7 | AL16: 0 | AM16: 94.7962 | AN16: 144.58 | AO16: -61.3268 | AP16: 1 | AQ16: -111.5693
... A87: FNM30.350.10(GEN) | B87: 42767 | C87: 7.8341474e+09 | D87: 6.0251651 | E87: 2.0827828 | F87: 94.568403 | G87: 14.497276 | H87: 654 | J87: FHL30.350.10(GEN) | K87: 42767 | L87: 2.1328037e+09 | M87: 4.7048123 | N87: 6.9118795 | O87: 94.622036 | P87: 8.561514 | Q87: 194 | S87: FNM30.350.10(GEN) | T87: 42767 | U87: 896624.41 | V87: 0 | W87: 20.3986 | X87: 94.58 | Y87: 3.371 | Z87: 1 | AA87: 3.371 | AI87: FNM30.350.10(GEN) | AJ87: 42767 | AK87: 896624.41 | AL87: 0 | AM87: 20.3986 | AN87: 94.58 | AO87: 3.371 | AP87: 1 | AQ87: 3.371

Sheet Sheet6
C1: FNM | L1: FHL
A2: PoolListName | C2: TotalBalance | D2: AvgOrigPMI | E2: AvgLLPA | F2: AvgPMI | G2: AvgIncentive | H2: PoolCount | J2: PoolListName | K2: asof | L2: TotalBalance | M2: AvgOrigPMI | N2: AvgLLPA | O2: AvgPMI | P2: AvgIncentive | Q2: PoolCount
A3: FNM30.350.10(GEN) | B3: 40210 | C3: 12469876 | D3: 12.538172 | E3: 33.248797 | F3: 62.5 | G3: -98.326693 | H3: 4 | J3: FHL30.350.10(GEN) | K3: 40210 | L3: 2714429 | M3: 0 | N3: 39.1923 | O3: 62.5 | P3: -132.4832 | Q3: 1
A4: FNM30.350.10(GEN) | B4: 40238 | C4: 22930199 | D4: 6.8067642 | E4: 36.634999 | F4: 62.5 | G4: -96.592947 | H4: 8 | J4: FHL30.350.10(GEN) | K4: 40238 | L4: 4159148.5 | M4: 0 | N4: 38.10727 | O4: 62.5 | P4: -132.75128 | Q4: 2
A5: FNM30.350.10(GEN) | B5: 40269 | C5: 25846157 | D5: 6.0290786 | E5: 35.809772 | F5: 62.5 | G5: -96.107251 | H5: 10 | J5: FHL30.350.10(GEN) | K5: 40269 | L5: 4152182.5 | M5: 0 | N5: 38.106937 | O5: 62.5 | P5: -125.03622 | Q5: 2
A6: FNM30.350.10(GEN) | B6: 40299 | C6: 29374689 | D6: 5.2962499 | E6: 33.72152 | F6: 68.75 | G6: -105.5544 | H6: 13 | J6: FHL30.350.10(GEN) | K6: 40299 | L6: 4145195.5 | M6: 0 | N6: 36.380534 | O6: 68.75 | P6: -130.18738 | Q6: 2
A7: FNM30.350.10(GEN) | B7: 40330 | C7: 38949484 | D7: 3.9878714 | E7: 34.786911 | F7: 68.75 | G7: -87.788699 | H7: 17 | J7: FHL30.350.10(GEN) | K7: 40330 | L7: 4138183.8 | M7: 0 | N7: 36.382428 | O7: 68.75 | P7: -105.04334 | Q7: 2
A8: FNM30.350.10(GEN) | B8: 40360 | C8: 89328927 | D8: 1.7359062 | E8: 30.166083 | F8: 68.75 | G8: -60.158843 | H8: 23 | J8: FHL30.350.10(GEN) | K8: 40360 | L8: 4131149.3 | M8: 0 | N8: 36.384321 | O8: 68.75 | P8: -92.276296 | Q8: 2
A9: FNM30.350.10(GEN) | B9: 40391 | C9: 4.9265278e+08 | D9: 0.31423925 | E9: 27.599331 | F9: 68.75 | G9: -23.616461 | H9: 41 | J9: FHL30.350.10(GEN) | K9: 40391 | L9: 14561484 | M9: 1.4883197 | N9: 41.822985 | O9: 68.809944 | P9: -56.619979 | Q9: 5
A10: FNM30.350.10(GEN) | B10: 40422 | C10: 2.9595826e+09 | D10: 0.40286196 | E10: 26.41269 | F10: 68.75 | G10: -9.9778144 | H10: 106 | J10: FHL30.350.10(GEN) | K10: 40422 | L10: 91126400 | M10: 6.0830644 | N10: 33.031971 | O10: 68.795476 | P10: -35.717578 | Q10: 12
A11: FNM30.350.10(GEN) | B11: 40452 | C11: 8.6800726e+09 | D11: 0.52365278 | E11: 26.280119 | F11: 68.757162 | G11: -7.1859427 | H11: 231 | J11: FHL30.350.10(GEN) | K11: 40452 | L11: 7.2246486e+08 | M11: 5.2646522 | N11: 39.392656 | O11: 68.823298 | P11: -24.523062 | Q11: 34
A12: FNM30.350.10(GEN) | B12: 40483 | C12: 1.3364581e+10 | D12: 0.48043739 | E12: 26.730149 | F12: 93.349857 | G12: -2.1022224 | H12: 372 | J12: FHL30.350.10(GEN) | K12: 40483 | L12: 2.0986317e+09 | M12: 5.3116713 | N12: 39.699012 | O12: 93.408224 | P12: -20.54926 | Q12: 72
A13: FNM30.350.10(GEN) | B13: 40513 | C13: 2.0899069e+10 | D13: 0.45255561 | E13: 26.778567 | F13: 93.345705 | G13: -16.859543 | H13: 562 | J13: FHL30.350.10(GEN) | K13: 40513 | L13: 3.856688e+09 | M13: 4.4110059 | N13: 39.089147 | O13: 93.431509 | P13: -34.223745 | Q13: 125
A14: FNM30.350.10(GEN) | B14: 40544 | C14: 2.2942683e+10 | D14: 0.62064729 | E14: 27.316918 | F14: 93.347027 | G14: -57.542097 | H14: 622 | J14: FHL30.350.10(GEN) | K14: 40544 | L14: 5.0630709e+09 | M14: 4.2536126 | N14: 40.624793 | O14: 93.465969 | P14: -78.121478 | Q14: 154
... A87: FNM30.350.10(GEN) | B87: 42767 | C87: 7.8341474e+09 | D87: 6.0239225 | E87: 2.0828917 | F87: 94.568403 | G87: 14.495946 | H87: 654 | J87: FHL30.350.10(GEN) | K87: 42767 | L87: 2.1328037e+09 | M87: 4.7048123 | N87: 6.9118795 | O87: 94.622036 | P87: 8.561514 | Q87: 194
