Workbook

Sheet Sheet1
H1: VA/FHA | I1: calcOrigMonth_LL | J1: sum(cello_loan.OriginalLoanAmount) | N1: FHL | O1: calcOrigMonth_LL | P1: sum(cello_loan.OriginalLoanAmount) | S1: FNM | T1: calcOrigMonth_LL | U1: sum(cello_loan.OriginalLoanAmount)
I2: (NULL) | J2: 11033991000 | O2: 198306 | P2: 75865 | T2: 198702 | U2: 85000
I3: 198401 | J3: 435000 | O3: 198311 | P3: 48876 | T3: 199107 | U3: 216000
I4: 198402 | J4: 306000 | O4: 198510 | P4: 65041 | T4: 199109 | U4: 30600
I5: 198403 | J5: 814000 | O5: 198704 | P5: 18900 | T5: 199111 | U5: 29250
I6: 198404 | J6: 813000 | O6: 198803 | P6: 55000 | T6: 199201 | U6: 62720
I7: 198405 | J7: 1199000 | O7: 198805 | P7: 40413 | T7: 199205 | U7: 108000
I8: 198406 | J8: 683000 | O8: 198806 | P8: 65000 | T8: 199206 | U8: 34850
I9: 198407 | J9: 650000 | O9: 198807 | P9: 269145 | T9: 199207 | U9: 100800
I10: 198408 | J10: 785000 | O10: 198811 | P10: 68022 | T10: 199209 | U10: 52200
I11: 198409 | J11: 601000 | O11: 198812 | P11: 103321 | T11: 199210 | U11: 150900
I12: 198410 | J12: 636000 | O12: 198901 | P12: 215173 | T12: 199211 | U12: 171000
I13: 198411 | J13: 804000 | O13: 198906 | P13: 89847 | T13: 199302 | U13: 129910
I14: 198412 | J14: 1042000 | O14: 199003 | P14: 130173 | T14: 199303 | U14: 518300
... I291: 200801 | J291: 1503753000 | O291: 201403 | P291: 3253682806 | T291: 201604 | U291: 87507981
I292: 200802 | J292: 1688771000 | O292: 201404 | P292: 4426120682
I293: 200803 | J293: 2586600299 | O293: 201405 | P293: 4819212943
I294: 200804 | J294: 2937983000 | O294: 201406 | P294: 5545824995
I295: 200805 | J295: 3636383000 | O295: 201407 | P295: 6700322892
I296: 200806 | J296: 3902355000 | O296: 201408 | P296: 6654772084
I297: 200807 | J297: 3602249000 | O297: 201409 | P297: 6367278364
I298: 200808 | J298: 3180729707 | O298: 201410 | P298: 5779492201
I299: 200809 | J299: 2906779000 | O299: 201411 | P299: 5445838376
I300: 200810 | J300: 3639319000 | O300: 201412 | P300: 4972651877
I301: 200811 | J301: 3770749300 | O301: 201501 | P301: 5284729535
I302: 200812 | J302: 2992550000 | O302: 201502 | P302: 4573212409
I303: 200901 | J303: 5294082000 | O303: 201503 | P303: 5490203962
... I315: 201001 | J315: 13266855000 | O315: 201603 | P315: 1544597796
I316: 201002 | J316: 8793130000
I317: 201003 | J317: 8661501000
I318: 201004 | J318: 12493490000
I319: 201005 | J319: 13645857108
I320: 201006 | J320: 14382005442
I321: 201007 | J321: 17091212000
I322: 201008 | J322: 12511641205
I323: 201009 | J323: 16122616000
I324: 201010 | J324: 17566326067
I325: 201011 | J325: 17284727407
I326: 201012 | J326: 15216488000
I327: 201101 | J327: 12743226000
...

Sheet Sheet2
B1: FHA/VA | C1: FHL/FNM | F1: FHA/VA | G1: FHL/FNM
A2: 199302 | B2: =VLOOKUP(A2,Sheet1!I:J,2,0) -> 32256000 | C2: =VLOOKUP(A2,Sheet1!O:P,2,0)+VLOOKUP(A2,Sheet1!T:U,2,0) -> 1620460 | E2: 199302 | F2: =B2/(B2+C2) -> 0.9521656 | G2: =1-F2 -> 0.047834396
A3: 199303 | B3: =VLOOKUP(A3,Sheet1!I:J,2,0) -> 37019000 | C3: =VLOOKUP(A3,Sheet1!O:P,2,0)+VLOOKUP(A3,Sheet1!T:U,2,0) -> 2321592 | E3: 199303 | F3: =B3/(B3+C3) -> 0.94098736 | G3: =1-F3 -> 0.059012635
A4: 199304 | B4: =VLOOKUP(A4,Sheet1!I:J,2,0) -> 65312000 | C4: =VLOOKUP(A4,Sheet1!O:P,2,0)+VLOOKUP(A4,Sheet1!T:U,2,0) -> 1632401.9 | E4: 199304 | F4: =B4/(B4+C4) -> 0.97561556 | G4: =1-F4 -> 0.024384442
A5: 199305 | B5: =VLOOKUP(A5,Sheet1!I:J,2,0) -> 89247000 | C5: =VLOOKUP(A5,Sheet1!O:P,2,0)+VLOOKUP(A5,Sheet1!T:U,2,0) -> 3932009.2 | E5: 199305 | F5: =B5/(B5+C5) -> 0.95780156 | G5: =1-F5 -> 0.042198444
A6: 199306 | B6: =VLOOKUP(A6,Sheet1!I:J,2,0) -> 105806000 | C6: =VLOOKUP(A6,Sheet1!O:P,2,0)+VLOOKUP(A6,Sheet1!T:U,2,0) -> 4469330 | E6: 199306 | F6: =B6/(B6+C6) -> 0.95947117 | G6: =1-F6 -> 0.040528829
A7: 199307 | B7: =VLOOKUP(A7,Sheet1!I:J,2,0) -> 107982000 | C7: =VLOOKUP(A7,Sheet1!O:P,2,0)+VLOOKUP(A7,Sheet1!T:U,2,0) -> 4246325 | E7: 199307 | F7: =B7/(B7+C7) -> 0.96216352 | G7: =1-F7 -> 0.037836482
A8: 199308 | B8: =VLOOKUP(A8,Sheet1!I:J,2,0) -> 116532000 | C8: =VLOOKUP(A8,Sheet1!O:P,2,0)+VLOOKUP(A8,Sheet1!T:U,2,0) -> 2611405 | E8: 199308 | F8: =B8/(B8+C8) -> 0.97808183 | G8: =1-F8 -> 0.021918167
A9: 199309 | B9: =VLOOKUP(A9,Sheet1!I:J,2,0) -> 140915000 | C9: =VLOOKUP(A9,Sheet1!O:P,2,0)+VLOOKUP(A9,Sheet1!T:U,2,0) -> 3146775 | E9: 199309 | F9: =B9/(B9+C9) -> 0.97815677 | G9: =1-F9 -> 0.021843234
A10: 199310 | B10: =VLOOKUP(A10,Sheet1!I:J,2,0) -> 165910000 | C10: =VLOOKUP(A10,Sheet1!O:P,2,0)+VLOOKUP(A10,Sheet1!T:U,2,0) -> 5771933 | E10: 199310 | F10: =B10/(B10+C10) -> 0.96638008 | G10: =1-F10 -> 0.033619921
A11: 199311 | B11: =VLOOKUP(A11,Sheet1!I:J,2,0) -> 204764000 | C11: =VLOOKUP(A11,Sheet1!O:P,2,0)+VLOOKUP(A11,Sheet1!T:U,2,0) -> 5882752 | E11: 199311 | F11: =B11/(B11+C11) -> 0.9720729 | G11: =1-F11 -> 0.027927096
A12: 199312 | B12: =VLOOKUP(A12,Sheet1!I:J,2,0) -> 213735000 | C12: =VLOOKUP(A12,Sheet1!O:P,2,0)+VLOOKUP(A12,Sheet1!T:U,2,0) -> 8305937 | E12: 199312 | F12: =B12/(B12+C12) -> 0.96259277 | G12: =1-F12 -> 0.037407233
A13: 199401 | B13: =VLOOKUP(A13,Sheet1!I:J,2,0) -> 183947000 | C13: =VLOOKUP(A13,Sheet1!O:P,2,0)+VLOOKUP(A13,Sheet1!T:U,2,0) -> 10725266 | E13: 199401 | F13: =B13/(B13+C13) -> 0.94490604 | G13: =1-F13 -> 0.05509396
... A279: 201603 | B279: =VLOOKUP(A279,Sheet1!I:J,2,0) -> 8500069000 | C279: =VLOOKUP(A279,Sheet1!O:P,2,0)+VLOOKUP(A279,Sheet1!T:U,2,0) -> 4.8213506e+09 | E279: 201603 | F279: =B279/(B279+C279) -> 0.63807531 | G279: =1-F279 -> 0.36192469

Sheet Sheet3
