Workbook

Sheet Raw Data
A1: id | B1: marketTicker | C1: OrigYear | D1: coupon | E1: ficoBucket | F1: cltvBucket | G1: total_balance | H1: fha_refi_incentive_old | I1: fha_refi_incentive_new | J1: fha_refi_incentive_delta | K1: refi_incentive_old | L1: refi_incentive_new | M1: refi_incentive_delta
A2: =B2&C2&D2&E2&F2 -> FGU620123.576085 | B2: FGU6 | C2: 2012 | D2: 3.5 | E2: 760 | F2: 85 | G2: 1397121 | H2: -90.6674 | I2: -65.6674 | J2: 25 | K2: -37.8908 | L2: -35.6175 | M2: 2.2733
A3: =B3&C3&D3&E3&F3 -> FGU62012472080 | B3: FGU6 | C3: 2012 | D3: 4 | E3: 720 | F3: 80 | G3: 18262792 | H3: -43.237833 | I3: -18.238253 | J3: 24.99958 | K3: 1.870247 | L3: 8.1382573 | M3: 6.2680103
A4: =B4&C4&D4&E4&F4 -> FGU62012472085 | B4: FGU6 | C4: 2012 | D4: 4 | E4: 720 | F4: 85 | G4: 2256668.9 | H4: -34.5928 | I4: -9.5928 | J4: 25 | K4: 6.628 | L4: 15.0043 | M4: 8.3763
A5: =B5&C5&D5&E5&F5 -> FGU62012474080 | B5: FGU6 | C5: 2012 | D5: 4 | E5: 740 | F5: 80 | G5: 1.7962993e+08 | H5: -49.636223 | I5: -24.63646 | J5: 24.999763 | K5: 0.37924918 | L5: 6.5202592 | M5: 6.14101
A6: =B6&C6&D6&E6&F6 -> FGU62012474085 | B6: FGU6 | C6: 2012 | D6: 4 | E6: 740 | F6: 85 | G6: 39989905 | H6: -43.531757 | I6: -18.531893 | J6: 24.999864 | K6: 3.6174777 | L6: 10.117683 | M6: 6.5002054
A7: =B7&C7&D7&E7&F7 -> FGU62012474090 | B7: FGU6 | C7: 2012 | D7: 4 | E7: 740 | F7: 90 | G7: 2476179.2 | H7: -43.6008 | I7: -18.602 | J7: 24.9988 | K7: -1.5552 | L7: 7.4879 | M7: 9.0431
A8: =B8&C8&D8&E8&F8 -> FGU62012476080 | B8: FGU6 | C8: 2012 | D8: 4 | E8: 760 | F8: 80 | G8: 2415954.2 | H8: -59.454147 | I8: -34.454147 | J8: 25 | K8: 3.9007161 | L8: 9.0984186 | M8: 5.1977025
A9: =B9&C9&D9&E9&F9 -> FGU62012476085 | B9: FGU6 | C9: 2012 | D9: 4 | E9: 760 | F9: 85 | G9: 1.038268e+08 | H9: -45.837701 | I9: -20.838259 | J9: 24.999442 | K9: 6.4728171 | L9: 12.312809 | M9: 5.8399917
A10: =B10&C10&D10&E10&F10 -> FGU62012476090 | B10: FGU6 | C10: 2012 | D10: 4 | E10: 760 | F10: 90 | G10: 607829.24 | H10: 10.3953 | I10: 35.3925 | J10: 24.9972 | K10: 60.6431 | L10: 60.6431 | M10: 0
A11: =B11&C11&D11&E11&F11 -> FGU62012478080 | B11: FGU6 | C11: 2012 | D11: 4 | E11: 780 | F11: 80 | G11: 35036123 | H11: -60.120022 | I11: -35.120024 | J11: 24.999999 | K11: 11.875315 | L11: 13.894599 | M11: 2.0192836
A12: =B12&C12&D12&E12&F12 -> FGU62012478085 | B12: FGU6 | C12: 2012 | D12: 4 | E12: 780 | F12: 85 | G12: 2323496.8 | H12: -53.2839 | I12: -28.2839 | J12: 25 | K12: 4.512 | L12: 8.1224 | M12: 3.6104
A13: =B13&C13&D13&E13&F13 -> FGU620124.568095 | B13: FGU6 | C13: 2012 | D13: 4.5 | E13: 680 | F13: 95 | G13: 483242.4 | H13: -15.27 | I13: 9.72 | J13: 24.99 | K13: -2.9386 | L13: 12.4423 | M13: 15.3809
... A45: =B45&C45&D45&E45&F45 -> FGU92012474095 | B45: FGU9 | C45: 2012 | D45: 4 | E45: 740 | F45: 95 | G45: 859258.68 | H45: -12.8453 | I45: 12.1495 | J45: 24.9948 | K45: 13.2018 | L45: 26.0012 | M45: 12.7994
A46: =B46&C46&D46&E46&F46 -> FGU920124760100+ | B46: FGU9 | C46: 2012 | D46: 4 | E46: 760 | F46: 100+ | G46: 6155194.6 | H46: -44.72 | I46: -19.7218 | J46: 24.9982 | K46: -18.0487 | L46: -3.1945 | M46: 14.8542
A47: =B47&C47&D47&E47&F47 -> FGU92012476095 | B47: FGU9 | C47: 2012 | D47: 4 | E47: 760 | F47: 95 | G47: 7712001.2 | H47: -50.820372 | I47: -25.820711 | J47: 24.999661 | K47: -13.04282 | L47: -5.2434125 | M47: 7.7994078
A48: =B48&C48&D48&E48&F48 -> FGU920124780100+ | B48: FGU9 | C48: 2012 | D48: 4 | E48: 780 | F48: 100+ | G48: 2408820.9 | H48: -52.448864 | I48: -27.448864 | J48: 25 | K48: -28.789341 | L48: -12.986359 | M48: 15.802982
A49: =B49&C49&D49&E49&F49 -> FGU92012478095 | B49: FGU9 | C49: 2012 | D49: 4 | E49: 780 | F49: 95 | G49: 49332423 | H49: -63.776729 | I49: -38.776768 | J49: 24.999961 | K49: -27.050356 | L49: -17.492736 | M49: 9.5576201
A50: =B50&C50&D50&E50&F50 -> FGU920124.570095 | B50: FGU9 | C50: 2012 | D50: 4.5 | E50: 700 | F50: 95 | G50: 2286334.8 | H50: 21.0186 | I50: 46.0181 | J50: 24.9995 | K50: 37.4653 | L50: 55.5556 | M50: 18.0903
A51: =B51&C51&D51&E51&F51 -> FGU920124.5720100 | B51: FGU9 | C51: 2012 | D51: 4.5 | E51: 720 | F51: 100 | G51: 15595419 | H51: 9.4287266 | I51: 34.423707 | J51: 24.994981 | K51: 22.897873 | L51: 41.58506 | M51: 18.687186
A52: =B52&C52&D52&E52&F52 -> FGU920124.5720100+ | B52: FGU9 | C52: 2012 | D52: 4.5 | E52: 720 | F52: 100+ | G52: 8145104.9 | H52: -3.8733 | I52: 21.1241 | J52: 24.9974 | K52: 12.1027 | L52: 30.2417 | M52: 18.139
A53: =B53&C53&D53&E53&F53 -> FGU920124.5740100 | B53: FGU9 | C53: 2012 | D53: 4.5 | E53: 740 | F53: 100 | G53: 2807505.5 | H53: 20.382 | I53: 45.3789 | J53: 24.9969 | K53: 27.9019 | L53: 49.2505 | M53: 21.3486
A54: =B54&C54&D54&E54&F54 -> FGU920124.5740100+ | B54: FGU9 | C54: 2012 | D54: 4.5 | E54: 740 | F54: 100+ | G54: 88943742 | H54: -2.080405 | I54: 22.915629 | J54: 24.996034 | K54: 10.451983 | L54: 29.022976 | M54: 18.570993
A55: =B55&C55&D55&E55&F55 -> FGU920124.574095 | B55: FGU9 | C55: 2012 | D55: 4.5 | E55: 740 | F55: 95 | G55: 9690401.5 | H55: -1.8287 | I55: 23.1645 | J55: 24.9932 | K55: 24.6983 | L55: 38.0833 | M55: 13.385
A56: =B56&C56&D56&E56&F56 -> FGU920124.5760100+ | B56: FGU9 | C56: 2012 | D56: 4.5 | E56: 760 | F56: 100+ | G56: 47050528 | H56: 15.819866 | I56: 40.815215 | J56: 24.995349 | K56: 31.276532 | L56: 48.658414 | M56: 17.381882
A57: =B57&C57&D57&E57&F57 -> FGU920124.576097 | B57: FGU9 | C57: 2012 | D57: 4.5 | E57: 760 | F57: 97 | G57: 1.339748e+08 | H57: -4.064 | I57: 20.9277 | J57: 24.9917 | K57: 24.7962 | L57: 37.6154 | M57: 12.8192
A58: =B58&C58&D58&E58&F58 -> FGU920124.5780100+ | B58: FGU9 | C58: 2012 | D58: 4.5 | E58: 780 | F58: 100+ | G58: 5537165.9 | H58: 23.874875 | I58: 48.871697 | J58: 24.996822 | K58: 40.063767 | L58: 58.024694 | M58: 17.960927
A59: =B59&C59&D59&E59&F59 -> FGU920133.5700100+ | B59: FGU9 | C59: 2013 | D59: 3.5 | E59: 700 | F59: 100+ | G59: 1063274.6 | H59: -53.6141 | I59: -28.6158 | J59: 24.9983 | K59: -53.6141 | L59: -28.6158 | M59: 24.9983
A60: =B60&C60&D60&E60&F60 -> FGU920133.576097 | B60: FGU9 | C60: 2013 | D60: 3.5 | E60: 760 | F60: 97 | G60: 3603174.9 | H60: -104.8085 | I60: -79.8089 | J60: 24.9996 | K60: -87.9547 | L60: -70.617 | M60: 17.3377
A61: =B61&C61&D61&E61&F61 -> FGU920133.5780100+ | B61: FGU9 | C61: 2013 | D61: 3.5 | E61: 780 | F61: 100+ | G61: 946242.49 | H61: -112.8281 | I61: -87.8281 | J61: 25 | K61: -99.8108 | L61: -81.6866 | M61: 18.1242
A62: =B62&C62&D62&E62&F62 -> FGU920134680100+ | B62: FGU9 | C62: 2013 | D62: 4 | E62: 680 | F62: 100+ | G62: 2069224.2 | H62: -30.06736 | I62: -5.0677176 | J62: 24.999642 | K62: -29.098492 | L62: -5.03661 | M62: 24.061882
A63: =B63&C63&D63&E63&F63 -> FGU920134720100 | B63: FGU9 | C63: 2013 | D63: 4 | E63: 720 | F63: 100 | G63: 9861007.8 | H63: -55.9709 | I63: -30.9717 | J63: 24.9992 | K63: -39.4976 | L63: -23.2985 | M63: 16.1991
A64: =B64&C64&D64&E64&F64 -> FGU920134740100 | B64: FGU9 | C64: 2013 | D64: 4 | E64: 740 | F64: 100 | G64: 8997663.9 | H64: -43.4035 | I64: -18.4042 | J64: 24.9993 | K64: -25.3368 | L64: -8.9674 | M64: 16.3694
A65: =B65&C65&D65&E65&F65 -> FGU920134740100+ | B65: FGU9 | C65: 2013 | D65: 4 | E65: 740 | F65: 100+ | G65: 2.3476241e+08 | H65: -46.894666 | I65: -21.895215 | J65: 24.999451 | K65: -38.790573 | L65: -18.152673 | M65: 20.6379
A66: =B66&C66&D66&E66&F66 -> FGU920134760100 | B66: FGU9 | C66: 2013 | D66: 4 | E66: 760 | F66: 100 | G66: 4622251 | H66: -40.3218 | I66: -15.3228 | J66: 24.999 | K66: -24.8148 | L66: -7.9322 | M66: 16.8826
A67: =B67&C67&D67&E67&F67 -> FGU920134760100+ | B67: FGU9 | C67: 2013 | D67: 4 | E67: 760 | F67: 100+ | G67: 8943822.4 | H67: -48.1907 | I67: -23.1918 | J67: 24.9989 | K67: -43.1336 | L67: -21.0274 | M67: 22.1062
A68: =B68&C68&D68&E68&F68 -> FGU920134780100+ | B68: FGU9 | C68: 2013 | D68: 4 | E68: 780 | F68: 100+ | G68: 459973.58 | H68: -12.4141 | I68: 12.5858 | J68: 24.9999 | K68: 2.9226 | L68: 21.3493 | M68: 18.4267
A69: =B69&C69&D69&E69&F69 -> FGU920134.5700100+ | B69: FGU9 | C69: 2013 | D69: 4.5 | E69: 700 | F69: 100+ | G69: 16154593 | H69: -5.5854015 | I69: 19.408297 | J69: 24.993698 | K69: -5.4860353 | L69: 19.408297 | M69: 24.894332
A70: =B70&C70&D70&E70&F70 -> FGU920134.5720100+ | B70: FGU9 | C70: 2013 | D70: 4.5 | E70: 720 | F70: 100+ | G70: 4053124.6 | H70: 5.1044998 | I70: 30.098991 | J70: 24.994492 | K70: 6.3890202 | L70: 30.288732 | M70: 23.899712
A71: =B71&C71&D71&E71&F71 -> FGU920134.5740100+ | B71: FGU9 | C71: 2013 | D71: 4.5 | E71: 740 | F71: 100+ | G71: 38290048 | H71: 11.095493 | I71: 36.092019 | J71: 24.996526 | K71: 14.902225 | L71: 37.71853 | M71: 22.816305
...

Sheet Complete Data
A1: marketTicker | B1: OrigYear | C1: coupon | D1: ficoBucket | E1: cltvBucket | F1: id | G1: total_balance | H1: fha_refi_incentive_old | I1: fha_refi_incentive_new | J1: fha_refi_incentive_delta | K1: refi_incentive_old | L1: refi_incentive_new | M1: refi_incentive_delta
A2: FGU6 | B2: 2012 | C2: 3.5 | D2: 620 | E2: 80 | F2: =A2&B2&C2&D2&E2 -> FGU620123.562080 | G2: =IF(ISNA(VLOOKUP($F2,'Raw Data'!$A:$M,7,0)),"",VLOOKUP($F2,'Raw Data'!$A:$M,7,0)) | H2: =IF(ISNA(VLOOKUP($F2,'Raw Data'!$A:$M,8,0)),"",VLOOKUP($F2,'Raw Data'!$A:$M,8,0)) | I2: =IF(ISNA(VLOOKUP($F2,'Raw Data'!$A:$M,9,0)),"",VLOOKUP($F2,'Raw Data'!$A:$M,9,0)) | J2: =IF(ISNA(VLOOKUP($F2,'Raw Data'!$A:$M,10,0)),"",VLOOKUP($F2,'Raw Data'!$A:$M,10,0)) | K2: =IF(ISNA(VLOOKUP($F2,'Raw Data'!$A:$M,11,0)),"",VLOOKUP($F2,'Raw Data'!$A:$M,11,0)) | L2: =IF(ISNA(VLOOKUP($F2,'Raw Data'!$A:$M,12,0)),"",VLOOKUP($F2,'Raw Data'!$A:$M,12,0)) | M2: =IF(ISNA(VLOOKUP($F2,'Raw Data'!$A:$M,13,0)),"",VLOOKUP($F2,'Raw Data'!$A:$M,13,0))
A3: FGU6 | B3: 2012 | C3: 3.5 | D3: 640 | E3: 80 | F3: =A3&B3&C3&D3&E3 -> FGU620123.564080 | G3: =IF(ISNA(VLOOKUP($F3,'Raw Data'!$A:$M,7,0)),"",VLOOKUP($F3,'Raw Data'!$A:$M,7,0)) | H3: =IF(ISNA(VLOOKUP($F3,'Raw Data'!$A:$M,8,0)),"",VLOOKUP($F3,'Raw Data'!$A:$M,8,0)) | I3: =IF(ISNA(VLOOKUP($F3,'Raw Data'!$A:$M,9,0)),"",VLOOKUP($F3,'Raw Data'!$A:$M,9,0)) | J3: =IF(ISNA(VLOOKUP($F3,'Raw Data'!$A:$M,10,0)),"",VLOOKUP($F3,'Raw Data'!$A:$M,10,0)) | K3: =IF(ISNA(VLOOKUP($F3,'Raw Data'!$A:$M,11,0)),"",VLOOKUP($F3,'Raw Data'!$A:$M,11,0)) | L3: =IF(ISNA(VLOOKUP($F3,'Raw Data'!$A:$M,12,0)),"",VLOOKUP($F3,'Raw Data'!$A:$M,12,0)) | M3: =IF(ISNA(VLOOKUP($F3,'Raw Data'!$A:$M,13,0)),"",VLOOKUP($F3,'Raw Data'!$A:$M,13,0))
A4: FGU6 | B4: 2012 | C4: 3.5 | D4: 660 | E4: 80 | F4: =A4&B4&C4&D4&E4 -> FGU620123.566080 | G4: =IF(ISNA(VLOOKUP($F4,'Raw Data'!$A:$M,7,0)),"",VLOOKUP($F4,'Raw Data'!$A:$M,7,0)) | H4: =IF(ISNA(VLOOKUP($F4,'Raw Data'!$A:$M,8,0)),"",VLOOKUP($F4,'Raw Data'!$A:$M,8,0)) | I4: =IF(ISNA(VLOOKUP($F4,'Raw Data'!$A:$M,9,0)),"",VLOOKUP($F4,'Raw Data'!$A:$M,9,0)) | J4: =IF(ISNA(VLOOKUP($F4,'Raw Data'!$A:$M,10,0)),"",VLOOKUP($F4,'Raw Data'!$A:$M,10,0)) | K4: =IF(ISNA(VLOOKUP($F4,'Raw Data'!$A:$M,11,0)),"",VLOOKUP($F4,'Raw Data'!$A:$M,11,0)) | L4: =IF(ISNA(VLOOKUP($F4,'Raw Data'!$A:$M,12,0)),"",VLOOKUP($F4,'Raw Data'!$A:$M,12,0)) | M4: =IF(ISNA(VLOOKUP($F4,'Raw Data'!$A:$M,13,0)),"",VLOOKUP($F4,'Raw Data'!$A:$M,13,0))
A5: FGU6 | B5: 2012 | C5: 3.5 | D5: 680 | E5: 80 | F5: =A5&B5&C5&D5&E5 -> FGU620123.568080 | G5: =IF(ISNA(VLOOKUP($F5,'Raw Data'!$A:$M,7,0)),"",VLOOKUP($F5,'Raw Data'!$A:$M,7,0)) | H5: =IF(ISNA(VLOOKUP($F5,'Raw Data'!$A:$M,8,0)),"",VLOOKUP($F5,'Raw Data'!$A:$M,8,0)) | I5: =IF(ISNA(VLOOKUP($F5,'Raw Data'!$A:$M,9,0)),"",VLOOKUP($F5,'Raw Data'!$A:$M,9,0)) | J5: =IF(ISNA(VLOOKUP($F5,'Raw Data'!$A:$M,10,0)),"",VLOOKUP($F5,'Raw Data'!$A:$M,10,0)) | K5: =IF(ISNA(VLOOKUP($F5,'Raw Data'!$A:$M,11,0)),"",VLOOKUP($F5,'Raw Data'!$A:$M,11,0)) | L5: =IF(ISNA(VLOOKUP($F5,'Raw Data'!$A:$M,12,0)),"",VLOOKUP($F5,'Raw Data'!$A:$M,12,0)) | M5: =IF(ISNA(VLOOKUP($F5,'Raw Data'!$A:$M,13,0)),"",VLOOKUP($F5,'Raw Data'!$A:$M,13,0))
A6: FGU6 | B6: 2012 | C6: 3.5 | D6: 700 | E6: 80 | F6: =A6&B6&C6&D6&E6 -> FGU620123.570080 | G6: =IF(ISNA(VLOOKUP($F6,'Raw Data'!$A:$M,7,0)),"",VLOOKUP($F6,'Raw Data'!$A:$M,7,0)) | H6: =IF(ISNA(VLOOKUP($F6,'Raw Data'!$A:$M,8,0)),"",VLOOKUP($F6,'Raw Data'!$A:$M,8,0)) | I6: =IF(ISNA(VLOOKUP($F6,'Raw Data'!$A:$M,9,0)),"",VLOOKUP($F6,'Raw Data'!$A:$M,9,0)) | J6: =IF(ISNA(VLOOKUP($F6,'Raw Data'!$A:$M,10,0)),"",VLOOKUP($F6,'Raw Data'!$A:$M,10,0)) | K6: =IF(ISNA(VLOOKUP($F6,'Raw Data'!$A:$M,11,0)),"",VLOOKUP($F6,'Raw Data'!$A:$M,11,0)) | L6: =IF(ISNA(VLOOKUP($F6,'Raw Data'!$A:$M,12,0)),"",VLOOKUP($F6,'Raw Data'!$A:$M,12,0)) | M6: =IF(ISNA(VLOOKUP($F6,'Raw Data'!$A:$M,13,0)),"",VLOOKUP($F6,'Raw Data'!$A:$M,13,0))
A7: FGU6 | B7: 2012 | C7: 3.5 | D7: 720 | E7: 80 | F7: =A7&B7&C7&D7&E7 -> FGU620123.572080 | G7: =IF(ISNA(VLOOKUP($F7,'Raw Data'!$A:$M,7,0)),"",VLOOKUP($F7,'Raw Data'!$A:$M,7,0)) | H7: =IF(ISNA(VLOOKUP($F7,'Raw Data'!$A:$M,8,0)),"",VLOOKUP($F7,'Raw Data'!$A:$M,8,0)) | I7: =IF(ISNA(VLOOKUP($F7,'Raw Data'!$A:$M,9,0)),"",VLOOKUP($F7,'Raw Data'!$A:$M,9,0)) | J7: =IF(ISNA(VLOOKUP($F7,'Raw Data'!$A:$M,10,0)),"",VLOOKUP($F7,'Raw Data'!$A:$M,10,0)) | K7: =IF(ISNA(VLOOKUP($F7,'Raw Data'!$A:$M,11,0)),"",VLOOKUP($F7,'Raw Data'!$A:$M,11,0)) | L7: =IF(ISNA(VLOOKUP($F7,'Raw Data'!$A:$M,12,0)),"",VLOOKUP($F7,'Raw Data'!$A:$M,12,0)) | M7: =IF(ISNA(VLOOKUP($F7,'Raw Data'!$A:$M,13,0)),"",VLOOKUP($F7,'Raw Data'!$A:$M,13,0))
A8: FGU6 | B8: 2012 | C8: 3.5 | D8: 740 | E8: 80 | F8: =A8&B8&C8&D8&E8 -> FGU620123.574080 | G8: =IF(ISNA(VLOOKUP($F8,'Raw Data'!$A:$M,7,0)),"",VLOOKUP($F8,'Raw Data'!$A:$M,7,0)) | H8: =IF(ISNA(VLOOKUP($F8,'Raw Data'!$A:$M,8,0)),"",VLOOKUP($F8,'Raw Data'!$A:$M,8,0)) | I8: =IF(ISNA(VLOOKUP($F8,'Raw Data'!$A:$M,9,0)),"",VLOOKUP($F8,'Raw Data'!$A:$M,9,0)) | J8: =IF(ISNA(VLOOKUP($F8,'Raw Data'!$A:$M,10,0)),"",VLOOKUP($F8,'Raw Data'!$A:$M,10,0)) | K8: =IF(ISNA(VLOOKUP($F8,'Raw Data'!$A:$M,11,0)),"",VLOOKUP($F8,'Raw Data'!$A:$M,11,0)) | L8: =IF(ISNA(VLOOKUP($F8,'Raw Data'!$A:$M,12,0)),"",VLOOKUP($F8,'Raw Data'!$A:$M,12,0)) | M8: =IF(ISNA(VLOOKUP($F8,'Raw Data'!$A:$M,13,0)),"",VLOOKUP($F8,'Raw Data'!$A:$M,13,0))
A9: FGU6 | B9: 2012 | C9: 3.5 | D9: 760 | E9: 80 | F9: =A9&B9&C9&D9&E9 -> FGU620123.576080 | G9: =IF(ISNA(VLOOKUP($F9,'Raw Data'!$A:$M,7,0)),"",VLOOKUP($F9,'Raw Data'!$A:$M,7,0)) | H9: =IF(ISNA(VLOOKUP($F9,'Raw Data'!$A:$M,8,0)),"",VLOOKUP($F9,'Raw Data'!$A:$M,8,0)) | I9: =IF(ISNA(VLOOKUP($F9,'Raw Data'!$A:$M,9,0)),"",VLOOKUP($F9,'Raw Data'!$A:$M,9,0)) | J9: =IF(ISNA(VLOOKUP($F9,'Raw Data'!$A:$M,10,0)),"",VLOOKUP($F9,'Raw Data'!$A:$M,10,0)) | K9: =IF(ISNA(VLOOKUP($F9,'Raw Data'!$A:$M,11,0)),"",VLOOKUP($F9,'Raw Data'!$A:$M,11,0)) | L9: =IF(ISNA(VLOOKUP($F9,'Raw Data'!$A:$M,12,0)),"",VLOOKUP($F9,'Raw Data'!$A:$M,12,0)) | M9: =IF(ISNA(VLOOKUP($F9,'Raw Data'!$A:$M,13,0)),"",VLOOKUP($F9,'Raw Data'!$A:$M,13,0))
A10: FGU6 | B10: 2012 | C10: 3.5 | D10: 780 | E10: 80 | F10: =A10&B10&C10&D10&E10 -> FGU620123.578080 | G10: =IF(ISNA(VLOOKUP($F10,'Raw Data'!$A:$M,7,0)),"",VLOOKUP($F10,'Raw Data'!$A:$M,7,0)) | H10: =IF(ISNA(VLOOKUP($F10,'Raw Data'!$A:$M,8,0)),"",VLOOKUP($F10,'Raw Data'!$A:$M,8,0)) | I10: =IF(ISNA(VLOOKUP($F10,'Raw Data'!$A:$M,9,0)),"",VLOOKUP($F10,'Raw Data'!$A:$M,9,0)) | J10: =IF(ISNA(VLOOKUP($F10,'Raw Data'!$A:$M,10,0)),"",VLOOKUP($F10,'Raw Data'!$A:$M,10,0)) | K10: =IF(ISNA(VLOOKUP($F10,'Raw Data'!$A:$M,11,0)),"",VLOOKUP($F10,'Raw Data'!$A:$M,11,0)) | L10: =IF(ISNA(VLOOKUP($F10,'Raw Data'!$A:$M,12,0)),"",VLOOKUP($F10,'Raw Data'!$A:$M,12,0)) | M10: =IF(ISNA(VLOOKUP($F10,'Raw Data'!$A:$M,13,0)),"",VLOOKUP($F10,'Raw Data'!$A:$M,13,0))
A11: FGU6 | B11: 2012 | C11: 3.5 | D11: 620 | E11: 85 | F11: =A11&B11&C11&D11&E11 -> FGU620123.562085 | G11: =IF(ISNA(VLOOKUP($F11,'Raw Data'!$A:$M,7,0)),"",VLOOKUP($F11,'Raw Data'!$A:$M,7,0)) | H11: =IF(ISNA(VLOOKUP($F11,'Raw Data'!$A:$M,8,0)),"",VLOOKUP($F11,'Raw Data'!$A:$M,8,0)) | I11: =IF(ISNA(VLOOKUP($F11,'Raw Data'!$A:$M,9,0)),"",VLOOKUP($F11,'Raw Data'!$A:$M,9,0)) | J11: =IF(ISNA(VLOOKUP($F11,'Raw Data'!$A:$M,10,0)),"",VLOOKUP($F11,'Raw Data'!$A:$M,10,0)) | K11: =IF(ISNA(VLOOKUP($F11,'Raw Data'!$A:$M,11,0)),"",VLOOKUP($F11,'Raw Data'!$A:$M,11,0)) | L11: =IF(ISNA(VLOOKUP($F11,'Raw Data'!$A:$M,12,0)),"",VLOOKUP($F11,'Raw Data'!$A:$M,12,0)) | M11: =IF(ISNA(VLOOKUP($F11,'Raw Data'!$A:$M,13,0)),"",VLOOKUP($F11,'Raw Data'!$A:$M,13,0))
A12: FGU6 | B12: 2012 | C12: 3.5 | D12: 640 | E12: 85 | F12: =A12&B12&C12&D12&E12 -> FGU620123.564085 | G12: =IF(ISNA(VLOOKUP($F12,'Raw Data'!$A:$M,7,0)),"",VLOOKUP($F12,'Raw Data'!$A:$M,7,0)) | H12: =IF(ISNA(VLOOKUP($F12,'Raw Data'!$A:$M,8,0)),"",VLOOKUP($F12,'Raw Data'!$A:$M,8,0)) | I12: =IF(ISNA(VLOOKUP($F12,'Raw Data'!$A:$M,9,0)),"",VLOOKUP($F12,'Raw Data'!$A:$M,9,0)) | J12: =IF(ISNA(VLOOKUP($F12,'Raw Data'!$A:$M,10,0)),"",VLOOKUP($F12,'Raw Data'!$A:$M,10,0)) | K12: =IF(ISNA(VLOOKUP($F12,'Raw Data'!$A:$M,11,0)),"",VLOOKUP($F12,'Raw Data'!$A:$M,11,0)) | L12: =IF(ISNA(VLOOKUP($F12,'Raw Data'!$A:$M,12,0)),"",VLOOKUP($F12,'Raw Data'!$A:$M,12,0)) | M12: =IF(ISNA(VLOOKUP($F12,'Raw Data'!$A:$M,13,0)),"",VLOOKUP($F12,'Raw Data'!$A:$M,13,0))
A13: FGU6 | B13: 2012 | C13: 3.5 | D13: 660 | E13: 85 | F13: =A13&B13&C13&D13&E13 -> FGU620123.566085 | G13: =IF(ISNA(VLOOKUP($F13,'Raw Data'!$A:$M,7,0)),"",VLOOKUP($F13,'Raw Data'!$A:$M,7,0)) | H13: =IF(ISNA(VLOOKUP($F13,'Raw Data'!$A:$M,8,0)),"",VLOOKUP($F13,'Raw Data'!$A:$M,8,0)) | I13: =IF(ISNA(VLOOKUP($F13,'Raw Data'!$A:$M,9,0)),"",VLOOKUP($F13,'Raw Data'!$A:$M,9,0)) | J13: =IF(ISNA(VLOOKUP($F13,'Raw Data'!$A:$M,10,0)),"",VLOOKUP($F13,'Raw Data'!$A:$M,10,0)) | K13: =IF(ISNA(VLOOKUP($F13,'Raw Data'!$A:$M,11,0)),"",VLOOKUP($F13,'Raw Data'!$A:$M,11,0)) | L13: =IF(ISNA(VLOOKUP($F13,'Raw Data'!$A:$M,12,0)),"",VLOOKUP($F13,'Raw Data'!$A:$M,12,0)) | M13: =IF(ISNA(VLOOKUP($F13,'Raw Data'!$A:$M,13,0)),"",VLOOKUP($F13,'Raw Data'!$A:$M,13,0))
... A55: FGU6 | B55: 2012 | C55: 3.5 | D55: 780 | E55: 100 | F55: =A55&B55&C55&D55&E55 -> FGU620123.5780100 | G55: =IF(ISNA(VLOOKUP($F55,'Raw Data'!$A:$M,7,0)),"",VLOOKUP($F55,'Raw Data'!$A:$M,7,0)) | H55: =IF(ISNA(VLOOKUP($F55,'Raw Data'!$A:$M,8,0)),"",VLOOKUP($F55,'Raw Data'!$A:$M,8,0)) | I55: =IF(ISNA(VLOOKUP($F55,'Raw Data'!$A:$M,9,0)),"",VLOOKUP($F55,'Raw Data'!$A:$M,9,0)) | J55: =IF(ISNA(VLOOKUP($F55,'Raw Data'!$A:$M,10,0)),"",VLOOKUP($F55,'Raw Data'!$A:$M,10,0)) | K55: =IF(ISNA(VLOOKUP($F55,'Raw Data'!$A:$M,11,0)),"",VLOOKUP($F55,'Raw Data'!$A:$M,11,0)) | L55: =IF(ISNA(VLOOKUP($F55,'Raw Data'!$A:$M,12,0)),"",VLOOKUP($F55,'Raw Data'!$A:$M,12,0)) | M55: =IF(ISNA(VLOOKUP($F55,'Raw Data'!$A:$M,13,0)),"",VLOOKUP($F55,'Raw Data'!$A:$M,13,0))
A56: FGU6 | B56: 2012 | C56: 3.5 | D56: 620 | E56: 100+ | F56: =A56&B56&C56&D56&E56 -> FGU620123.5620100+ | G56: =IF(ISNA(VLOOKUP($F56,'Raw Data'!$A:$M,7,0)),"",VLOOKUP($F56,'Raw Data'!$A:$M,7,0)) | H56: =IF(ISNA(VLOOKUP($F56,'Raw Data'!$A:$M,8,0)),"",VLOOKUP($F56,'Raw Data'!$A:$M,8,0)) | I56: =IF(ISNA(VLOOKUP($F56,'Raw Data'!$A:$M,9,0)),"",VLOOKUP($F56,'Raw Data'!$A:$M,9,0)) | J56: =IF(ISNA(VLOOKUP($F56,'Raw Data'!$A:$M,10,0)),"",VLOOKUP($F56,'Raw Data'!$A:$M,10,0)) | K56: =IF(ISNA(VLOOKUP($F56,'Raw Data'!$A:$M,11,0)),"",VLOOKUP($F56,'Raw Data'!$A:$M,11,0)) | L56: =IF(ISNA(VLOOKUP($F56,'Raw Data'!$A:$M,12,0)),"",VLOOKUP($F56,'Raw Data'!$A:$M,12,0)) | M56: =IF(ISNA(VLOOKUP($F56,'Raw Data'!$A:$M,13,0)),"",VLOOKUP($F56,'Raw Data'!$A:$M,13,0))
A57: FGU6 | B57: 2012 | C57: 3.5 | D57: 640 | E57: 100+ | F57: =A57&B57&C57&D57&E57 -> FGU620123.5640100+ | G57: =IF(ISNA(VLOOKUP($F57,'Raw Data'!$A:$M,7,0)),"",VLOOKUP($F57,'Raw Data'!$A:$M,7,0)) | H57: =IF(ISNA(VLOOKUP($F57,'Raw Data'!$A:$M,8,0)),"",VLOOKUP($F57,'Raw Data'!$A:$M,8,0)) | I57: =IF(ISNA(VLOOKUP($F57,'Raw Data'!$A:$M,9,0)),"",VLOOKUP($F57,'Raw Data'!$A:$M,9,0)) | J57: =IF(ISNA(VLOOKUP($F57,'Raw Data'!$A:$M,10,0)),"",VLOOKUP($F57,'Raw Data'!$A:$M,10,0)) | K57: =IF(ISNA(VLOOKUP($F57,'Raw Data'!$A:$M,11,0)),"",VLOOKUP($F57,'Raw Data'!$A:$M,11,0)) | L57: =IF(ISNA(VLOOKUP($F57,'Raw Data'!$A:$M,12,0)),"",VLOOKUP($F57,'Raw Data'!$A:$M,12,0)) | M57: =IF(ISNA(VLOOKUP($F57,'Raw Data'!$A:$M,13,0)),"",VLOOKUP($F57,'Raw Data'!$A:$M,13,0))
A58: FGU6 | B58: 2012 | C58: 3.5 | D58: 660 | E58: 100+ | F58: =A58&B58&C58&D58&E58 -> FGU620123.5660100+ | G58: =IF(ISNA(VLOOKUP($F58,'Raw Data'!$A:$M,7,0)),"",VLOOKUP($F58,'Raw Data'!$A:$M,7,0)) | H58: =IF(ISNA(VLOOKUP($F58,'Raw Data'!$A:$M,8,0)),"",VLOOKUP($F58,'Raw Data'!$A:$M,8,0)) | I58: =IF(ISNA(VLOOKUP($F58,'Raw Data'!$A:$M,9,0)),"",VLOOKUP($F58,'Raw Data'!$A:$M,9,0)) | J58: =IF(ISNA(VLOOKUP($F58,'Raw Data'!$A:$M,10,0)),"",VLOOKUP($F58,'Raw Data'!$A:$M,10,0)) | K58: =IF(ISNA(VLOOKUP($F58,'Raw Data'!$A:$M,11,0)),"",VLOOKUP($F58,'Raw Data'!$A:$M,11,0)) | L58: =IF(ISNA(VLOOKUP($F58,'Raw Data'!$A:$M,12,0)),"",VLOOKUP($F58,'Raw Data'!$A:$M,12,0)) | M58: =IF(ISNA(VLOOKUP($F58,'Raw Data'!$A:$M,13,0)),"",VLOOKUP($F58,'Raw Data'!$A:$M,13,0))
A59: FGU6 | B59: 2012 | C59: 3.5 | D59: 680 | E59: 100+ | F59: =A59&B59&C59&D59&E59 -> FGU620123.5680100+ | G59: =IF(ISNA(VLOOKUP($F59,'Raw Data'!$A:$M,7,0)),"",VLOOKUP($F59,'Raw Data'!$A:$M,7,0)) | H59: =IF(ISNA(VLOOKUP($F59,'Raw Data'!$A:$M,8,0)),"",VLOOKUP($F59,'Raw Data'!$A:$M,8,0)) | I59: =IF(ISNA(VLOOKUP($F59,'Raw Data'!$A:$M,9,0)),"",VLOOKUP($F59,'Raw Data'!$A:$M,9,0)) | J59: =IF(ISNA(VLOOKUP($F59,'Raw Data'!$A:$M,10,0)),"",VLOOKUP($F59,'Raw Data'!$A:$M,10,0)) | K59: =IF(ISNA(VLOOKUP($F59,'Raw Data'!$A:$M,11,0)),"",VLOOKUP($F59,'Raw Data'!$A:$M,11,0)) | L59: =IF(ISNA(VLOOKUP($F59,'Raw Data'!$A:$M,12,0)),"",VLOOKUP($F59,'Raw Data'!$A:$M,12,0)) | M59: =IF(ISNA(VLOOKUP($F59,'Raw Data'!$A:$M,13,0)),"",VLOOKUP($F59,'Raw Data'!$A:$M,13,0))
A60: FGU6 | B60: 2012 | C60: 3.5 | D60: 700 | E60: 100+ | F60: =A60&B60&C60&D60&E60 -> FGU620123.5700100+ | G60: =IF(ISNA(VLOOKUP($F60,'Raw Data'!$A:$M,7,0)),"",VLOOKUP($F60,'Raw Data'!$A:$M,7,0)) | H60: =IF(ISNA(VLOOKUP($F60,'Raw Data'!$A:$M,8,0)),"",VLOOKUP($F60,'Raw Data'!$A:$M,8,0)) | I60: =IF(ISNA(VLOOKUP($F60,'Raw Data'!$A:$M,9,0)),"",VLOOKUP($F60,'Raw Data'!$A:$M,9,0)) | J60: =IF(ISNA(VLOOKUP($F60,'Raw Data'!$A:$M,10,0)),"",VLOOKUP($F60,'Raw Data'!$A:$M,10,0)) | K60: =IF(ISNA(VLOOKUP($F60,'Raw Data'!$A:$M,11,0)),"",VLOOKUP($F60,'Raw Data'!$A:$M,11,0)) | L60: =IF(ISNA(VLOOKUP($F60,'Raw Data'!$A:$M,12,0)),"",VLOOKUP($F60,'Raw Data'!$A:$M,12,0)) | M60: =IF(ISNA(VLOOKUP($F60,'Raw Data'!$A:$M,13,0)),"",VLOOKUP($F60,'Raw Data'!$A:$M,13,0))
A61: FGU6 | B61: 2012 | C61: 3.5 | D61: 720 | E61: 100+ | F61: =A61&B61&C61&D61&E61 -> FGU620123.5720100+ | G61: =IF(ISNA(VLOOKUP($F61,'Raw Data'!$A:$M,7,0)),"",VLOOKUP($F61,'Raw Data'!$A:$M,7,0)) | H61: =IF(ISNA(VLOOKUP($F61,'Raw Data'!$A:$M,8,0)),"",VLOOKUP($F61,'Raw Data'!$A:$M,8,0)) | I61: =IF(ISNA(VLOOKUP($F61,'Raw Data'!$A:$M,9,0)),"",VLOOKUP($F61,'Raw Data'!$A:$M,9,0)) | J61: =IF(ISNA(VLOOKUP($F61,'Raw Data'!$A:$M,10,0)),"",VLOOKUP($F61,'Raw Data'!$A:$M,10,0)) | K61: =IF(ISNA(VLOOKUP($F61,'Raw Data'!$A:$M,11,0)),"",VLOOKUP($F61,'Raw Data'!$A:$M,11,0)) | L61: =IF(ISNA(VLOOKUP($F61,'Raw Data'!$A:$M,12,0)),"",VLOOKUP($F61,'Raw Data'!$A:$M,12,0)) | M61: =IF(ISNA(VLOOKUP($F61,'Raw Data'!$A:$M,13,0)),"",VLOOKUP($F61,'Raw Data'!$A:$M,13,0))
A62: FGU6 | B62: 2012 | C62: 3.5 | D62: 740 | E62: 100+ | F62: =A62&B62&C62&D62&E62 -> FGU620123.5740100+ | G62: =IF(ISNA(VLOOKUP($F62,'Raw Data'!$A:$M,7,0)),"",VLOOKUP($F62,'Raw Data'!$A:$M,7,0)) | H62: =IF(ISNA(VLOOKUP($F62,'Raw Data'!$A:$M,8,0)),"",VLOOKUP($F62,'Raw Data'!$A:$M,8,0)) | I62: =IF(ISNA(VLOOKUP($F62,'Raw Data'!$A:$M,9,0)),"",VLOOKUP($F62,'Raw Data'!$A:$M,9,0)) | J62: =IF(ISNA(VLOOKUP($F62,'Raw Data'!$A:$M,10,0)),"",VLOOKUP($F62,'Raw Data'!$A:$M,10,0)) | K62: =IF(ISNA(VLOOKUP($F62,'Raw Data'!$A:$M,11,0)),"",VLOOKUP($F62,'Raw Data'!$A:$M,11,0)) | L62: =IF(ISNA(VLOOKUP($F62,'Raw Data'!$A:$M,12,0)),"",VLOOKUP($F62,'Raw Data'!$A:$M,12,0)) | M62: =IF(ISNA(VLOOKUP($F62,'Raw Data'!$A:$M,13,0)),"",VLOOKUP($F62,'Raw Data'!$A:$M,13,0))
A63: FGU6 | B63: 2012 | C63: 3.5 | D63: 760 | E63: 100+ | F63: =A63&B63&C63&D63&E63 -> FGU620123.5760100+ | G63: =IF(ISNA(VLOOKUP($F63,'Raw Data'!$A:$M,7,0)),"",VLOOKUP($F63,'Raw Data'!$A:$M,7,0)) | H63: =IF(ISNA(VLOOKUP($F63,'Raw Data'!$A:$M,8,0)),"",VLOOKUP($F63,'Raw Data'!$A:$M,8,0)) | I63: =IF(ISNA(VLOOKUP($F63,'Raw Data'!$A:$M,9,0)),"",VLOOKUP($F63,'Raw Data'!$A:$M,9,0)) | J63: =IF(ISNA(VLOOKUP($F63,'Raw Data'!$A:$M,10,0)),"",VLOOKUP($F63,'Raw Data'!$A:$M,10,0)) | K63: =IF(ISNA(VLOOKUP($F63,'Raw Data'!$A:$M,11,0)),"",VLOOKUP($F63,'Raw Data'!$A:$M,11,0)) | L63: =IF(ISNA(VLOOKUP($F63,'Raw Data'!$A:$M,12,0)),"",VLOOKUP($F63,'Raw Data'!$A:$M,12,0)) | M63: =IF(ISNA(VLOOKUP($F63,'Raw Data'!$A:$M,13,0)),"",VLOOKUP($F63,'Raw Data'!$A:$M,13,0))
A64: FGU6 | B64: 2012 | C64: 3.5 | D64: 780 | E64: 100+ | F64: =A64&B64&C64&D64&E64 -> FGU620123.5780100+ | G64: =IF(ISNA(VLOOKUP($F64,'Raw Data'!$A:$M,7,0)),"",VLOOKUP($F64,'Raw Data'!$A:$M,7,0)) | H64: =IF(ISNA(VLOOKUP($F64,'Raw Data'!$A:$M,8,0)),"",VLOOKUP($F64,'Raw Data'!$A:$M,8,0)) | I64: =IF(ISNA(VLOOKUP($F64,'Raw Data'!$A:$M,9,0)),"",VLOOKUP($F64,'Raw Data'!$A:$M,9,0)) | J64: =IF(ISNA(VLOOKUP($F64,'Raw Data'!$A:$M,10,0)),"",VLOOKUP($F64,'Raw Data'!$A:$M,10,0)) | K64: =IF(ISNA(VLOOKUP($F64,'Raw Data'!$A:$M,11,0)),"",VLOOKUP($F64,'Raw Data'!$A:$M,11,0)) | L64: =IF(ISNA(VLOOKUP($F64,'Raw Data'!$A:$M,12,0)),"",VLOOKUP($F64,'Raw Data'!$A:$M,12,0)) | M64: =IF(ISNA(VLOOKUP($F64,'Raw Data'!$A:$M,13,0)),"",VLOOKUP($F64,'Raw Data'!$A:$M,13,0))
A65: FGU6 | B65: 2013 | C65: 3.5 | D65: 620 | E65: 80 | F65: =A65&B65&C65&D65&E65 -> FGU620133.562080 | G65: =IF(ISNA(VLOOKUP($F65,'Raw Data'!$A:$M,7,0)),"",VLOOKUP($F65,'Raw Data'!$A:$M,7,0)) | H65: =IF(ISNA(VLOOKUP($F65,'Raw Data'!$A:$M,8,0)),"",VLOOKUP($F65,'Raw Data'!$A:$M,8,0)) | I65: =IF(ISNA(VLOOKUP($F65,'Raw Data'!$A:$M,9,0)),"",VLOOKUP($F65,'Raw Data'!$A:$M,9,0)) | J65: =IF(ISNA(VLOOKUP($F65,'Raw Data'!$A:$M,10,0)),"",VLOOKUP($F65,'Raw Data'!$A:$M,10,0)) | K65: =IF(ISNA(VLOOKUP($F65,'Raw Data'!$A:$M,11,0)),"",VLOOKUP($F65,'Raw Data'!$A:$M,11,0)) | L65: =IF(ISNA(VLOOKUP($F65,'Raw Data'!$A:$M,12,0)),"",VLOOKUP($F65,'Raw Data'!$A:$M,12,0)) | M65: =IF(ISNA(VLOOKUP($F65,'Raw Data'!$A:$M,13,0)),"",VLOOKUP($F65,'Raw Data'!$A:$M,13,0))
A66: FGU6 | B66: 2013 | C66: 3.5 | D66: 640 | E66: 80 | F66: =A66&B66&C66&D66&E66 -> FGU620133.564080 | G66: =IF(ISNA(VLOOKUP($F66,'Raw Data'!$A:$M,7,0)),"",VLOOKUP($F66,'Raw Data'!$A:$M,7,0)) | H66: =IF(ISNA(VLOOKUP($F66,'Raw Data'!$A:$M,8,0)),"",VLOOKUP($F66,'Raw Data'!$A:$M,8,0)) | I66: =IF(ISNA(VLOOKUP($F66,'Raw Data'!$A:$M,9,0)),"",VLOOKUP($F66,'Raw Data'!$A:$M,9,0)) | J66: =IF(ISNA(VLOOKUP($F66,'Raw Data'!$A:$M,10,0)),"",VLOOKUP($F66,'Raw Data'!$A:$M,10,0)) | K66: =IF(ISNA(VLOOKUP($F66,'Raw Data'!$A:$M,11,0)),"",VLOOKUP($F66,'Raw Data'!$A:$M,11,0)) | L66: =IF(ISNA(VLOOKUP($F66,'Raw Data'!$A:$M,12,0)),"",VLOOKUP($F66,'Raw Data'!$A:$M,12,0)) | M66: =IF(ISNA(VLOOKUP($F66,'Raw Data'!$A:$M,13,0)),"",VLOOKUP($F66,'Raw Data'!$A:$M,13,0))
A67: FGU6 | B67: 2013 | C67: 3.5 | D67: 660 | E67: 80 | F67: =A67&B67&C67&D67&E67 -> FGU620133.566080 | G67: =IF(ISNA(VLOOKUP($F67,'Raw Data'!$A:$M,7,0)),"",VLOOKUP($F67,'Raw Data'!$A:$M,7,0)) | H67: =IF(ISNA(VLOOKUP($F67,'Raw Data'!$A:$M,8,0)),"",VLOOKUP($F67,'Raw Data'!$A:$M,8,0)) | I67: =IF(ISNA(VLOOKUP($F67,'Raw Data'!$A:$M,9,0)),"",VLOOKUP($F67,'Raw Data'!$A:$M,9,0)) | J67: =IF(ISNA(VLOOKUP($F67,'Raw Data'!$A:$M,10,0)),"",VLOOKUP($F67,'Raw Data'!$A:$M,10,0)) | K67: =IF(ISNA(VLOOKUP($F67,'Raw Data'!$A:$M,11,0)),"",VLOOKUP($F67,'Raw Data'!$A:$M,11,0)) | L67: =IF(ISNA(VLOOKUP($F67,'Raw Data'!$A:$M,12,0)),"",VLOOKUP($F67,'Raw Data'!$A:$M,12,0)) | M67: =IF(ISNA(VLOOKUP($F67,'Raw Data'!$A:$M,13,0)),"",VLOOKUP($F67,'Raw Data'!$A:$M,13,0))
A68: FGU6 | B68: 2013 | C68: 3.5 | D68: 680 | E68: 80 | F68: =A68&B68&C68&D68&E68 -> FGU620133.568080 | G68: =IF(ISNA(VLOOKUP($F68,'Raw Data'!$A:$M,7,0)),"",VLOOKUP($F68,'Raw Data'!$A:$M,7,0)) | H68: =IF(ISNA(VLOOKUP($F68,'Raw Data'!$A:$M,8,0)),"",VLOOKUP($F68,'Raw Data'!$A:$M,8,0)) | I68: =IF(ISNA(VLOOKUP($F68,'Raw Data'!$A:$M,9,0)),"",VLOOKUP($F68,'Raw Data'!$A:$M,9,0)) | J68: =IF(ISNA(VLOOKUP($F68,'Raw Data'!$A:$M,10,0)),"",VLOOKUP($F68,'Raw Data'!$A:$M,10,0)) | K68: =IF(ISNA(VLOOKUP($F68,'Raw Data'!$A:$M,11,0)),"",VLOOKUP($F68,'Raw Data'!$A:$M,11,0)) | L68: =IF(ISNA(VLOOKUP($F68,'Raw Data'!$A:$M,12,0)),"",VLOOKUP($F68,'Raw Data'!$A:$M,12,0)) | M68: =IF(ISNA(VLOOKUP($F68,'Raw Data'!$A:$M,13,0)),"",VLOOKUP($F68,'Raw Data'!$A:$M,13,0))
A69: FGU6 | B69: 2013 | C69: 3.5 | D69: 700 | E69: 80 | F69: =A69&B69&C69&D69&E69 -> FGU620133.570080 | G69: =IF(ISNA(VLOOKUP($F69,'Raw Data'!$A:$M,7,0)),"",VLOOKUP($F69,'Raw Data'!$A:$M,7,0)) | H69: =IF(ISNA(VLOOKUP($F69,'Raw Data'!$A:$M,8,0)),"",VLOOKUP($F69,'Raw Data'!$A:$M,8,0)) | I69: =IF(ISNA(VLOOKUP($F69,'Raw Data'!$A:$M,9,0)),"",VLOOKUP($F69,'Raw Data'!$A:$M,9,0)) | J69: =IF(ISNA(VLOOKUP($F69,'Raw Data'!$A:$M,10,0)),"",VLOOKUP($F69,'Raw Data'!$A:$M,10,0)) | K69: =IF(ISNA(VLOOKUP($F69,'Raw Data'!$A:$M,11,0)),"",VLOOKUP($F69,'Raw Data'!$A:$M,11,0)) | L69: =IF(ISNA(VLOOKUP($F69,'Raw Data'!$A:$M,12,0)),"",VLOOKUP($F69,'Raw Data'!$A:$M,12,0)) | M69: =IF(ISNA(VLOOKUP($F69,'Raw Data'!$A:$M,13,0)),"",VLOOKUP($F69,'Raw Data'!$A:$M,13,0))
A70: FGU6 | B70: 2013 | C70: 3.5 | D70: 720 | E70: 80 | F70: =A70&B70&C70&D70&E70 -> FGU620133.572080 | G70: =IF(ISNA(VLOOKUP($F70,'Raw Data'!$A:$M,7,0)),"",VLOOKUP($F70,'Raw Data'!$A:$M,7,0)) | H70: =IF(ISNA(VLOOKUP($F70,'Raw Data'!$A:$M,8,0)),"",VLOOKUP($F70,'Raw Data'!$A:$M,8,0)) | I70: =IF(ISNA(VLOOKUP($F70,'Raw Data'!$A:$M,9,0)),"",VLOOKUP($F70,'Raw Data'!$A:$M,9,0)) | J70: =IF(ISNA(VLOOKUP($F70,'Raw Data'!$A:$M,10,0)),"",VLOOKUP($F70,'Raw Data'!$A:$M,10,0)) | K70: =IF(ISNA(VLOOKUP($F70,'Raw Data'!$A:$M,11,0)),"",VLOOKUP($F70,'Raw Data'!$A:$M,11,0)) | L70: =IF(ISNA(VLOOKUP($F70,'Raw Data'!$A:$M,12,0)),"",VLOOKUP($F70,'Raw Data'!$A:$M,12,0)) | M70: =IF(ISNA(VLOOKUP($F70,'Raw Data'!$A:$M,13,0)),"",VLOOKUP($F70,'Raw Data'!$A:$M,13,0))
A71: FGU6 | B71: 2013 | C71: 3.5 | D71: 740 | E71: 80 | F71: =A71&B71&C71&D71&E71 -> FGU620133.574080 | G71: =IF(ISNA(VLOOKUP($F71,'Raw Data'!$A:$M,7,0)),"",VLOOKUP($F71,'Raw Data'!$A:$M,7,0)) | H71: =IF(ISNA(VLOOKUP($F71,'Raw Data'!$A:$M,8,0)),"",VLOOKUP($F71,'Raw Data'!$A:$M,8,0)) | I71: =IF(ISNA(VLOOKUP($F71,'Raw Data'!$A:$M,9,0)),"",VLOOKUP($F71,'Raw Data'!$A:$M,9,0)) | J71: =IF(ISNA(VLOOKUP($F71,'Raw Data'!$A:$M,10,0)),"",VLOOKUP($F71,'Raw Data'!$A:$M,10,0)) | K71: =IF(ISNA(VLOOKUP($F71,'Raw Data'!$A:$M,11,0)),"",VLOOKUP($F71,'Raw Data'!$A:$M,11,0)) | L71: =IF(ISNA(VLOOKUP($F71,'Raw Data'!$A:$M,12,0)),"",VLOOKUP($F71,'Raw Data'!$A:$M,12,0)) | M71: =IF(ISNA(VLOOKUP($F71,'Raw Data'!$A:$M,13,0)),"",VLOOKUP($F71,'Raw Data'!$A:$M,13,0))
A72: FGU6 | B72: 2013 | C72: 3.5 | D72: 760 | E72: 80 | F72: =A72&B72&C72&D72&E72 -> FGU620133.576080 | G72: =IF(ISNA(VLOOKUP($F72,'Raw Data'!$A:$M,7,0)),"",VLOOKUP($F72,'Raw Data'!$A:$M,7,0)) | H72: =IF(ISNA(VLOOKUP($F72,'Raw Data'!$A:$M,8,0)),"",VLOOKUP($F72,'Raw Data'!$A:$M,8,0)) | I72: =IF(ISNA(VLOOKUP($F72,'Raw Data'!$A:$M,9,0)),"",VLOOKUP($F72,'Raw Data'!$A:$M,9,0)) | J72: =IF(ISNA(VLOOKUP($F72,'Raw Data'!$A:$M,10,0)),"",VLOOKUP($F72,'Raw Data'!$A:$M,10,0)) | K72: =IF(ISNA(VLOOKUP($F72,'Raw Data'!$A:$M,11,0)),"",VLOOKUP($F72,'Raw Data'!$A:$M,11,0)) | L72: =IF(ISNA(VLOOKUP($F72,'Raw Data'!$A:$M,12,0)),"",VLOOKUP($F72,'Raw Data'!$A:$M,12,0)) | M72: =IF(ISNA(VLOOKUP($F72,'Raw Data'!$A:$M,13,0)),"",VLOOKUP($F72,'Raw Data'!$A:$M,13,0))
A73: FGU6 | B73: 2013 | C73: 3.5 | D73: 780 | E73: 80 | F73: =A73&B73&C73&D73&E73 -> FGU620133.578080 | G73: =IF(ISNA(VLOOKUP($F73,'Raw Data'!$A:$M,7,0)),"",VLOOKUP($F73,'Raw Data'!$A:$M,7,0)) | H73: =IF(ISNA(VLOOKUP($F73,'Raw Data'!$A:$M,8,0)),"",VLOOKUP($F73,'Raw Data'!$A:$M,8,0)) | I73: =IF(ISNA(VLOOKUP($F73,'Raw Data'!$A:$M,9,0)),"",VLOOKUP($F73,'Raw Data'!$A:$M,9,0)) | J73: =IF(ISNA(VLOOKUP($F73,'Raw Data'!$A:$M,10,0)),"",VLOOKUP($F73,'Raw Data'!$A:$M,10,0)) | K73: =IF(ISNA(VLOOKUP($F73,'Raw Data'!$A:$M,11,0)),"",VLOOKUP($F73,'Raw Data'!$A:$M,11,0)) | L73: =IF(ISNA(VLOOKUP($F73,'Raw Data'!$A:$M,12,0)),"",VLOOKUP($F73,'Raw Data'!$A:$M,12,0)) | M73: =IF(ISNA(VLOOKUP($F73,'Raw Data'!$A:$M,13,0)),"",VLOOKUP($F73,'Raw Data'!$A:$M,13,0))
A74: FGU6 | B74: 2013 | C74: 3.5 | D74: 620 | E74: 85 | F74: =A74&B74&C74&D74&E74 -> FGU620133.562085 | G74: =IF(ISNA(VLOOKUP($F74,'Raw Data'!$A:$M,7,0)),"",VLOOKUP($F74,'Raw Data'!$A:$M,7,0)) | H74: =IF(ISNA(VLOOKUP($F74,'Raw Data'!$A:$M,8,0)),"",VLOOKUP($F74,'Raw Data'!$A:$M,8,0)) | I74: =IF(ISNA(VLOOKUP($F74,'Raw Data'!$A:$M,9,0)),"",VLOOKUP($F74,'Raw Data'!$A:$M,9,0)) | J74: =IF(ISNA(VLOOKUP($F74,'Raw Data'!$A:$M,10,0)),"",VLOOKUP($F74,'Raw Data'!$A:$M,10,0)) | K74: =IF(ISNA(VLOOKUP($F74,'Raw Data'!$A:$M,11,0)),"",VLOOKUP($F74,'Raw Data'!$A:$M,11,0)) | L74: =IF(ISNA(VLOOKUP($F74,'Raw Data'!$A:$M,12,0)),"",VLOOKUP($F74,'Raw Data'!$A:$M,12,0)) | M74: =IF(ISNA(VLOOKUP($F74,'Raw Data'!$A:$M,13,0)),"",VLOOKUP($F74,'Raw Data'!$A:$M,13,0))
A75: FGU6 | B75: 2013 | C75: 3.5 | D75: 640 | E75: 85 | F75: =A75&B75&C75&D75&E75 -> FGU620133.564085 | G75: =IF(ISNA(VLOOKUP($F75,'Raw Data'!$A:$M,7,0)),"",VLOOKUP($F75,'Raw Data'!$A:$M,7,0)) | H75: =IF(ISNA(VLOOKUP($F75,'Raw Data'!$A:$M,8,0)),"",VLOOKUP($F75,'Raw Data'!$A:$M,8,0)) | I75: =IF(ISNA(VLOOKUP($F75,'Raw Data'!$A:$M,9,0)),"",VLOOKUP($F75,'Raw Data'!$A:$M,9,0)) | J75: =IF(ISNA(VLOOKUP($F75,'Raw Data'!$A:$M,10,0)),"",VLOOKUP($F75,'Raw Data'!$A:$M,10,0)) | K75: =IF(ISNA(VLOOKUP($F75,'Raw Data'!$A:$M,11,0)),"",VLOOKUP($F75,'Raw Data'!$A:$M,11,0)) | L75: =IF(ISNA(VLOOKUP($F75,'Raw Data'!$A:$M,12,0)),"",VLOOKUP($F75,'Raw Data'!$A:$M,12,0)) | M75: =IF(ISNA(VLOOKUP($F75,'Raw Data'!$A:$M,13,0)),"",VLOOKUP($F75,'Raw Data'!$A:$M,13,0))
A76: FGU6 | B76: 2013 | C76: 3.5 | D76: 660 | E76: 85 | F76: =A76&B76&C76&D76&E76 -> FGU620133.566085 | G76: =IF(ISNA(VLOOKUP($F76,'Raw Data'!$A:$M,7,0)),"",VLOOKUP($F76,'Raw Data'!$A:$M,7,0)) | H76: =IF(ISNA(VLOOKUP($F76,'Raw Data'!$A:$M,8,0)),"",VLOOKUP($F76,'Raw Data'!$A:$M,8,0)) | I76: =IF(ISNA(VLOOKUP($F76,'Raw Data'!$A:$M,9,0)),"",VLOOKUP($F76,'Raw Data'!$A:$M,9,0)) | J76: =IF(ISNA(VLOOKUP($F76,'Raw Data'!$A:$M,10,0)),"",VLOOKUP($F76,'Raw Data'!$A:$M,10,0)) | K76: =IF(ISNA(VLOOKUP($F76,'Raw Data'!$A:$M,11,0)),"",VLOOKUP($F76,'Raw Data'!$A:$M,11,0)) | L76: =IF(ISNA(VLOOKUP($F76,'Raw Data'!$A:$M,12,0)),"",VLOOKUP($F76,'Raw Data'!$A:$M,12,0)) | M76: =IF(ISNA(VLOOKUP($F76,'Raw Data'!$A:$M,13,0)),"",VLOOKUP($F76,'Raw Data'!$A:$M,13,0))
... A118: FGU6 | B118: 2013 | C118: 3.5 | D118: 780 | E118: 100 | F118: =A118&B118&C118&D118&E118 -> FGU620133.5780100 | G118: =IF(ISNA(VLOOKUP($F118,'Raw Data'!$A:$M,7,0)),"",VLOOKUP($F118,'Raw Data'!$A:$M,7,0)) | H118: =IF(ISNA(VLOOKUP($F118,'Raw Data'!$A:$M,8,0)),"",VLOOKUP($F118,'Raw Data'!$A:$M,8,0)) | I118: =IF(ISNA(VLOOKUP($F118,'Raw Data'!$A:$M,9,0)),"",VLOOKUP($F118,'Raw Data'!$A:$M,9,0)) | J118: =IF(ISNA(VLOOKUP($F118,'Raw Data'!$A:$M,10,0)),"",VLOOKUP($F118,'Raw Data'!$A:$M,10,0)) | K118: =IF(ISNA(VLOOKUP($F118,'Raw Data'!$A:$M,11,0)),"",VLOOKUP($F118,'Raw Data'!$A:$M,11,0)) | L118: =IF(ISNA(VLOOKUP($F118,'Raw Data'!$A:$M,12,0)),"",VLOOKUP($F118,'Raw Data'!$A:$M,12,0)) | M118: =IF(ISNA(VLOOKUP($F118,'Raw Data'!$A:$M,13,0)),"",VLOOKUP($F118,'Raw Data'!$A:$M,13,0))
A119: FGU6 | B119: 2013 | C119: 3.5 | D119: 620 | E119: 100+ | F119: =A119&B119&C119&D119&E119 -> FGU620133.5620100+ | G119: =IF(ISNA(VLOOKUP($F119,'Raw Data'!$A:$M,7,0)),"",VLOOKUP($F119,'Raw Data'!$A:$M,7,0)) | H119: =IF(ISNA(VLOOKUP($F119,'Raw Data'!$A:$M,8,0)),"",VLOOKUP($F119,'Raw Data'!$A:$M,8,0)) | I119: =IF(ISNA(VLOOKUP($F119,'Raw Data'!$A:$M,9,0)),"",VLOOKUP($F119,'Raw Data'!$A:$M,9,0)) | J119: =IF(ISNA(VLOOKUP($F119,'Raw Data'!$A:$M,10,0)),"",VLOOKUP($F119,'Raw Data'!$A:$M,10,0)) | K119: =IF(ISNA(VLOOKUP($F119,'Raw Data'!$A:$M,11,0)),"",VLOOKUP($F119,'Raw Data'!$A:$M,11,0)) | L119: =IF(ISNA(VLOOKUP($F119,'Raw Data'!$A:$M,12,0)),"",VLOOKUP($F119,'Raw Data'!$A:$M,12,0)) | M119: =IF(ISNA(VLOOKUP($F119,'Raw Data'!$A:$M,13,0)),"",VLOOKUP($F119,'Raw Data'!$A:$M,13,0))
A120: FGU6 | B120: 2013 | C120: 3.5 | D120: 640 | E120: 100+ | F120: =A120&B120&C120&D120&E120 -> FGU620133.5640100+ | G120: =IF(ISNA(VLOOKUP($F120,'Raw Data'!$A:$M,7,0)),"",VLOOKUP($F120,'Raw Data'!$A:$M,7,0)) | H120: =IF(ISNA(VLOOKUP($F120,'Raw Data'!$A:$M,8,0)),"",VLOOKUP($F120,'Raw Data'!$A:$M,8,0)) | I120: =IF(ISNA(VLOOKUP($F120,'Raw Data'!$A:$M,9,0)),"",VLOOKUP($F120,'Raw Data'!$A:$M,9,0)) | J120: =IF(ISNA(VLOOKUP($F120,'Raw Data'!$A:$M,10,0)),"",VLOOKUP($F120,'Raw Data'!$A:$M,10,0)) | K120: =IF(ISNA(VLOOKUP($F120,'Raw Data'!$A:$M,11,0)),"",VLOOKUP($F120,'Raw Data'!$A:$M,11,0)) | L120: =IF(ISNA(VLOOKUP($F120,'Raw Data'!$A:$M,12,0)),"",VLOOKUP($F120,'Raw Data'!$A:$M,12,0)) | M120: =IF(ISNA(VLOOKUP($F120,'Raw Data'!$A:$M,13,0)),"",VLOOKUP($F120,'Raw Data'!$A:$M,13,0))
A121: FGU6 | B121: 2013 | C121: 3.5 | D121: 660 | E121: 100+ | F121: =A121&B121&C121&D121&E121 -> FGU620133.5660100+ | G121: =IF(ISNA(VLOOKUP($F121,'Raw Data'!$A:$M,7,0)),"",VLOOKUP($F121,'Raw Data'!$A:$M,7,0)) | H121: =IF(ISNA(VLOOKUP($F121,'Raw Data'!$A:$M,8,0)),"",VLOOKUP($F121,'Raw Data'!$A:$M,8,0)) | I121: =IF(ISNA(VLOOKUP($F121,'Raw Data'!$A:$M,9,0)),"",VLOOKUP($F121,'Raw Data'!$A:$M,9,0)) | J121: =IF(ISNA(VLOOKUP($F121,'Raw Data'!$A:$M,10,0)),"",VLOOKUP($F121,'Raw Data'!$A:$M,10,0)) | K121: =IF(ISNA(VLOOKUP($F121,'Raw Data'!$A:$M,11,0)),"",VLOOKUP($F121,'Raw Data'!$A:$M,11,0)) | L121: =IF(ISNA(VLOOKUP($F121,'Raw Data'!$A:$M,12,0)),"",VLOOKUP($F121,'Raw Data'!$A:$M,12,0)) | M121: =IF(ISNA(VLOOKUP($F121,'Raw Data'!$A:$M,13,0)),"",VLOOKUP($F121,'Raw Data'!$A:$M,13,0))
A122: FGU6 | B122: 2013 | C122: 3.5 | D122: 680 | E122: 100+ | F122: =A122&B122&C122&D122&E122 -> FGU620133.5680100+ | G122: =IF(ISNA(VLOOKUP($F122,'Raw Data'!$A:$M,7,0)),"",VLOOKUP($F122,'Raw Data'!$A:$M,7,0)) | H122: =IF(ISNA(VLOOKUP($F122,'Raw Data'!$A:$M,8,0)),"",VLOOKUP($F122,'Raw Data'!$A:$M,8,0)) | I122: =IF(ISNA(VLOOKUP($F122,'Raw Data'!$A:$M,9,0)),"",VLOOKUP($F122,'Raw Data'!$A:$M,9,0)) | J122: =IF(ISNA(VLOOKUP($F122,'Raw Data'!$A:$M,10,0)),"",VLOOKUP($F122,'Raw Data'!$A:$M,10,0)) | K122: =IF(ISNA(VLOOKUP($F122,'Raw Data'!$A:$M,11,0)),"",VLOOKUP($F122,'Raw Data'!$A:$M,11,0)) | L122: =IF(ISNA(VLOOKUP($F122,'Raw Data'!$A:$M,12,0)),"",VLOOKUP($F122,'Raw Data'!$A:$M,12,0)) | M122: =IF(ISNA(VLOOKUP($F122,'Raw Data'!$A:$M,13,0)),"",VLOOKUP($F122,'Raw Data'!$A:$M,13,0))
...

Sheet Pivot
A1: OrigYear | B1: 2012
A2: coupon | B2: 4.5
A3: marketTicker | B3: FGU9
A4: FICO | B4: CLTV
B5: 80 | C5: 85 | D5: 90 | E5: 95 | F5: 97 | G5: 100 | H5: 100+
A6: Sum of fha_refi_incentive_new
A7: 680 | B7: 0 | C7: 0 | D7: 0 | E7: 0 | F7: 0 | G7: 0 | H7: 0
A8: 700 | B8: 0 | C8: 0 | D8: 0 | E8: 46.0181 | F8: 0 | G8: 0 | H8: 0
A9: 720 | B9: 0 | C9: 0 | D9: 0 | E9: 0 | F9: 0 | G9: 34.423707 | H9: 21.1241
A10: 740 | B10: 0 | C10: 0 | D10: 0 | E10: 23.1645 | F10: 0 | G10: 45.3789 | H10: 22.915629
A11: 780 | B11: 0 | C11: 0 | D11: 0 | E11: 0 | F11: 0 | G11: 0 | H11: 48.871697
A12: 760 | B12: 0 | C12: 0 | D12: 0 | E12: 0 | F12: 20.9277 | G12: 0 | H12: 40.815215
A13: 620 | B13: 0 | C13: 0 | D13: 0 | E13: 0 | F13: 0 | G13: 0 | H13: 0
A14: 640 | B14: 0 | C14: 0 | D14: 0 | E14: 0 | F14: 0 | G14: 0 | H14: 0
A15: 660 | B15: 0 | C15: 0 | D15: 0 | E15: 0 | F15: 0 | G15: 0 | H15: 0
A16: Sum of fha_refi_incentive_old
A17: 680 | B17: 0 | C17: 0 | D17: 0 | E17: 0 | F17: 0 | G17: 0 | H17: 0
A18: 700 | B18: 0 | C18: 0 | D18: 0 | E18: 21.0186 | F18: 0 | G18: 0 | H18: 0
A19: 720 | B19: 0 | C19: 0 | D19: 0 | E19: 0 | F19: 0 | G19: 9.4287266 | H19: -3.8733
A20: 740 | B20: 0 | C20: 0 | D20: 0 | E20: -1.8287 | F20: 0 | G20: 20.382 | H20: -2.080405
A21: 780 | B21: 0 | C21: 0 | D21: 0 | E21: 0 | F21: 0 | G21: 0 | H21: 23.874875
A22: 760 | B22: 0 | C22: 0 | D22: 0 | E22: 0 | F22: -4.064 | G22: 0 | H22: 15.819866
A23: 620 | B23: 0 | C23: 0 | D23: 0 | E23: 0 | F23: 0 | G23: 0 | H23: 0
A24: 640 | B24: 0 | C24: 0 | D24: 0 | E24: 0 | F24: 0 | G24: 0 | H24: 0
A25: 660 | B25: 0 | C25: 0 | D25: 0 | E25: 0 | F25: 0 | G25: 0 | H25: 0
A26: Sum of fha_refi_incentive_delta
A27: 680 | B27: 0 | C27: 0 | D27: 0 | E27: 0 | F27: 0 | G27: 0 | H27: 0
A28: 700 | B28: 0 | C28: 0 | D28: 0 | E28: 24.9995 | F28: 0 | G28: 0 | H28: 0
A29: 720 | B29: 0 | C29: 0 | D29: 0 | E29: 0 | F29: 0 | G29: 24.994981 | H29: 24.9974
A30: 740 | B30: 0 | C30: 0 | D30: 0 | E30: 24.9932 | F30: 0 | G30: 24.9969 | H30: 24.996034
A31: 780 | B31: 0 | C31: 0 | D31: 0 | E31: 0 | F31: 0 | G31: 0 | H31: 24.996822
A32: 760 | B32: 0 | C32: 0 | D32: 0 | E32: 0 | F32: 24.9917 | G32: 0 | H32: 24.995349
A33: 620 | B33: 0 | C33: 0 | D33: 0 | E33: 0 | F33: 0 | G33: 0 | H33: 0
A34: 640 | B34: 0 | C34: 0 | D34: 0 | E34: 0 | F34: 0 | G34: 0 | H34: 0
A35: 660 | B35: 0 | C35: 0 | D35: 0 | E35: 0 | F35: 0 | G35: 0 | H35: 0
A36: Sum of refi_incentive_new
A37: 680 | B37: 0 | C37: 0 | D37: 0 | E37: 0 | F37: 0 | G37: 0 | H37: 0
A38: 700 | B38: 0 | C38: 0 | D38: 0 | E38: 55.5556 | F38: 0 | G38: 0 | H38: 0
A39: 720 | B39: 0 | C39: 0 | D39: 0 | E39: 0 | F39: 0 | G39: 41.58506 | H39: 30.2417
A40: 740 | B40: 0 | C40: 0 | D40: 0 | E40: 38.0833 | F40: 0 | G40: 49.2505 | H40: 29.022976
...

Sheet U9-2010-4.5
D1: FGU9 2010 4.5
A3: Incentive to FHA - Old
B4: CLTV
A5: FICO | B5: 0 and < 80 | C5: >= 80 and < 85 | D5: >= 85 and < 90 | E5: >= 90 and < 95 | F5: >= 95 and < 97 | G5: >= 97 and < 100 | H5: >= 100
A6: <620
A7: 660
A8: 680
A9: 700 | E9: 21.0186
A10: 720 | G10: 9.4287266 | H10: -3.8733
A11: 740 | E11: -1.8287 | G11: 20.382 | H11: -2.080405
A12: 760 | F12: -4.064 | H12: 16.66801
A13: >= 780
A15: Incentive to FHA - New
B16: CLTV
A17: FICO | B17: 0 and < 80 | C17: >= 80 and < 85 | D17: >= 85 and < 90 | E17: >= 90 and < 95 | F17: >= 95 and < 97 | G17: >= 97 and < 100 | H17: >= 100
A18: <620
A19: 660
A20: 680
A21: 700 | E21: 46.0181
A22: 720 | G22: 34.423707 | H22: 21.1241
A23: 740 | E23: 23.1645 | G23: 45.3789 | H23: 22.915629
A24: 760 | F24: 20.9277 | H24: 41.663514
A25: >= 780
A27: Incentive to FHA - Delta | D27: (New - Old)
B28: CLTV
A29: FICO | B29: 0 and < 80 | C29: >= 80 and < 85 | D29: >= 85 and < 90 | E29: >= 90 and < 95 | F29: >= 95 and < 97 | G29: >= 97 and < 100 | H29: >= 100
A30: <620 | B30: =B18-B6 -> 0 | C30: =C18-C6 -> 0 | D30: =D18-D6 -> 0 | E30: =E18-E6 -> 0 | F30: =F18-F6 -> 0 | G30: =G18-G6 -> 0 | H30: =H18-H6 -> 0
A31: 660 | B31: =B19-B7 -> 0 | C31: =C19-C7 -> 0 | D31: =D19-D7 -> 0 | E31: =E19-E7 -> 0 | F31: =F19-F7 -> 0 | G31: =G19-G7 -> 0 | H31: =H19-H7 -> 0
A32: 680 | B32: =B20-B8 -> 0 | C32: =C20-C8 -> 0 | D32: =D20-D8 -> 0 | E32: =E20-E8 -> 0 | F32: =F20-F8 -> 0 | G32: =G20-G8 -> 0 | H32: =H20-H8 -> 0
A33: 700 | B33: =B21-B9 -> 0 | C33: =C21-C9 -> 0 | D33: =D21-D9 -> 0 | E33: =E21-E9 -> 24.9995 | F33: =F21-F9 -> 0 | G33: =G21-G9 -> 0 | H33: =H21-H9 -> 0
A34: 720 | B34: =B22-B10 -> 0 | C34: =C22-C10 -> 0 | D34: =D22-D10 -> 0 | E34: =E22-E10 -> 0 | F34: =F22-F10 -> 0 | G34: =G22-G10 -> 24.994981 | H34: =H22-H10 -> 24.9974
A35: 740 | B35: =B23-B11 -> 0 | C35: =C23-C11 -> 0 | D35: =D23-D11 -> 0 | E35: =E23-E11 -> 24.9932 | F35: =F23-F11 -> 0 | G35: =G23-G11 -> 24.9969 | H35: =H23-H11 -> 24.996034
A36: 760 | B36: =B24-B12 -> 0 | C36: =C24-C12 -> 0 | D36: =D24-D12 -> 0 | E36: =E24-E12 -> 0 | F36: =F24-F12 -> 24.9917 | G36: =G24-G12 -> 0 | H36: =H24-H12 -> 24.995504
A37: >= 780 | B37: =B25-B13 -> 0 | C37: =C25-C13 -> 0 | D37: =D25-D13 -> 0 | E37: =E25-E13 -> 0 | F37: =F25-F13 -> 0 | G37: =G25-G13 -> 0 | H37: =H25-H13 -> 0
A39: Balance Distribution
B40: CLTV
A41: FICO | B41: 0 and < 80 | C41: >= 80 and < 85 | D41: >= 85 and < 90 | E41: >= 90 and < 95 | F41: >= 95 and < 97 | G41: >= 97 and < 100 | H41: >= 100
A42: <620
A43: 660
A44: 680
...

Sheet U6-2012-3.5
D1: FGU6 2012 3.5
A3: Incentive to FHA - Old
B4: CLTV
A5: FICO | B5: 0 and < 80 | C5: >= 80 and < 85 | D5: >= 85 and < 90 | E5: >= 90 and < 95 | F5: >= 95 and < 97 | G5: >= 97 and < 100 | H5: >= 100
A6: <620
A7: 660
A8: 680
A9: 700
A10: 720
A11: 740
A12: 760
A13: >= 780 | D13: -90.6674
A15: Incentive to FHA - New
B16: CLTV
A17: FICO | B17: 0 and < 80 | C17: >= 80 and < 85 | D17: >= 85 and < 90 | E17: >= 90 and < 95 | F17: >= 95 and < 97 | G17: >= 97 and < 100 | H17: >= 100
A18: <620
A19: 660
A20: 680
A21: 700
A22: 720
A23: 740
A24: 760
A25: >= 780 | D25: -65.6674
A27: Incentive to FHA - Delta | D27: (New - Old)
B28: CLTV
A29: FICO | B29: 0 and < 80 | C29: >= 80 and < 85 | D29: >= 85 and < 90 | E29: >= 90 and < 95 | F29: >= 95 and < 97 | G29: >= 97 and < 100 | H29: >= 100
A30: <620 | B30: =B18-B6 -> 0 | C30: =C18-C6 -> 0 | D30: =D18-D6 -> 0 | E30: =E18-E6 -> 0 | F30: =F18-F6 -> 0 | G30: =G18-G6 -> 0 | H30: =H18-H6 -> 0
A31: 660 | B31: =B19-B7 -> 0 | C31: =C19-C7 -> 0 | D31: =D19-D7 -> 0 | E31: =E19-E7 -> 0 | F31: =F19-F7 -> 0 | G31: =G19-G7 -> 0 | H31: =H19-H7 -> 0
A32: 680 | B32: =B20-B8 -> 0 | C32: =C20-C8 -> 0 | D32: =D20-D8 -> 0 | E32: =E20-E8 -> 0 | F32: =F20-F8 -> 0 | G32: =G20-G8 -> 0 | H32: =H20-H8 -> 0
A33: 700 | B33: =B21-B9 -> 0 | C33: =C21-C9 -> 0 | D33: =D21-D9 -> 0 | E33: =E21-E9 -> 0 | F33: =F21-F9 -> 0 | G33: =G21-G9 -> 0 | H33: =H21-H9 -> 0
A34: 720 | B34: =B22-B10 -> 0 | C34: =C22-C10 -> 0 | D34: =D22-D10 -> 0 | E34: =E22-E10 -> 0 | F34: =F22-F10 -> 0 | G34: =G22-G10 -> 0 | H34: =H22-H10 -> 0
A35: 740 | B35: =B23-B11 -> 0 | C35: =C23-C11 -> 0 | D35: =D23-D11 -> 0 | E35: =E23-E11 -> 0 | F35: =F23-F11 -> 0 | G35: =G23-G11 -> 0 | H35: =H23-H11 -> 0
A36: 760 | B36: =B24-B12 -> 0 | C36: =C24-C12 -> 0 | D36: =D24-D12 -> 0 | E36: =E24-E12 -> 0 | F36: =F24-F12 -> 0 | G36: =G24-G12 -> 0 | H36: =H24-H12 -> 0
A37: >= 780 | B37: =B25-B13 -> 0 | C37: =C25-C13 -> 0 | D37: =D25-D13 -> 25 | E37: =E25-E13 -> 0 | F37: =F25-F13 -> 0 | G37: =G25-G13 -> 0 | H37: =H25-H13 -> 0
A39: Balance Distribution
B40: CLTV
A41: FICO | B41: 0 and < 80 | C41: >= 80 and < 85 | D41: >= 85 and < 90 | E41: >= 90 and < 95 | F41: >= 95 and < 97 | G41: >= 97 and < 100 | H41: >= 100
A42: <620
A43: 660
A44: 680
...
