Workbook

Sheet Sheet1
A1: Date | B1: v20 | C1: v21 | D1: model | F1: Date | G1: OAS | H1: model | K1: Date | L1: v20 | M1: v21 | N1: Backfilled V21 | O1: v20+diff
A2: 42006 | B2: -138.1459 | C2: =VLOOKUP(A2,F:G,2,0) -> #N/A | D2: v20 | F2: 42104 | G2: 127.0942 | H2: v21 | K2: 42006 | L2: -138.1459 | M2: #N/A | N2: 55.322102 | O2: =L2+$P$70 -> 122.8548
A3: 42009 | B3: -152.3426 | C3: =VLOOKUP(A3,F:G,2,0) -> #N/A | D3: v20 | F3: 42107 | G3: 130.7266 | H3: v21 | K3: 42009 | L3: -152.3426 | M3: #N/A | N3: 59.036499 | O3: =L3+$P$70 -> 108.6581
A4: 42010 | B4: -152.0367 | C4: =VLOOKUP(A4,F:G,2,0) -> #N/A | D4: v20 | F4: 42108 | G4: 138.2887 | H4: v21 | K4: 42010 | L4: -152.0367 | M4: #N/A | N4: 72.9394 | O4: =L4+$P$70 -> 108.964
A5: 42011 | B5: -139.4918 | C5: =VLOOKUP(A5,F:G,2,0) -> #N/A | D5: v20 | F5: 42109 | G5: 136.0755 | H5: v21 | K5: 42011 | L5: -139.4918 | M5: #N/A | N5: 83.752296 | O5: =L5+$P$70 -> 121.5089
A6: 42012 | B6: -109.7992 | C6: =VLOOKUP(A6,F:G,2,0) -> #N/A | D6: v20 | F6: 42110 | G6: 139.1769 | H6: v21 | K6: 42012 | L6: -109.7992 | M6: #N/A | N6: 96.112 | O6: =L6+$P$70 -> 151.2015
A7: 42013 | B7: -99.9245 | C7: =VLOOKUP(A7,F:G,2,0) -> #N/A | D7: v20 | F7: 42111 | G7: 125.3102 | H7: v21 | K7: 42013 | L7: -99.9245 | M7: #N/A | N7: 113.2768 | O7: =L7+$P$70 -> 161.0762
A8: 42016 | B8: -72.5883 | C8: =VLOOKUP(A8,F:G,2,0) -> #N/A | D8: v20 | F8: 42114 | G8: 115.6804 | H8: v21 | K8: 42016 | L8: -72.5883 | M8: #N/A | N8: 146.3428 | O8: =L8+$P$70 -> 188.4124
A9: 42017 | B9: -48.9905 | C9: =VLOOKUP(A9,F:G,2,0) -> #N/A | D9: v20 | F9: 42115 | G9: 107.4848 | H9: v21 | K9: 42017 | L9: -48.9905 | M9: #N/A | N9: 174.1528 | O9: =L9+$P$70 -> 212.0102
A10: 42018 | B10: -53.479 | C10: =VLOOKUP(A10,F:G,2,0) -> #N/A | D10: v20 | F10: 42116 | G10: 99.4964 | H10: v21 | K10: 42018 | L10: -53.479 | M10: #N/A | N10: 184.2774 | O10: =L10+$P$70 -> 207.5217
A11: 42019 | B11: -34.5176 | C11: =VLOOKUP(A11,F:G,2,0) -> #N/A | D11: v20 | F11: 42117 | G11: 99.1439 | H11: v21 | K11: 42019 | L11: -34.5176 | M11: #N/A | N11: 215.29179 | O11: =L11+$P$70 -> 226.4831
A12: 42020 | B12: -48.934 | C12: =VLOOKUP(A12,F:G,2,0) -> #N/A | D12: v20 | F12: 42118 | G12: 100.3833 | H12: v21 | K12: 42020 | L12: -48.934 | M12: #N/A | N12: 187.4767 | O12: =L12+$P$70 -> 212.0667
A13: 42024 | B13: -38.6205 | C13: =VLOOKUP(A13,F:G,2,0) -> #N/A | D13: v20 | F13: 42121 | G13: 97.056 | H13: v21 | K13: 42024 | L13: -38.6205 | M13: #N/A | N13: 200.5645 | O13: =L13+$P$70 -> 222.3802
... A69: 42103 | B69: -153.2722 | C69: =VLOOKUP(A69,F:G,2,0) -> #N/A | D69: v20 | F69: 42201 | G69: 48.3326 | H69: v21 | K69: 42103 | L69: -153.2722 | M69: #N/A | N69: 109.698 | O69: =L69+$P$70 -> 107.7285
A70: 42104 | B70: -133.9065 | C70: =VLOOKUP(A70,F:G,2,0) -> 127.0942 | D70: v20 | F70: 42202 | G70: 47.8202 | H70: v21 | K70: 42104 | L70: -133.9065 | M70: 127.0942 | N70: 127.0935 | O70: =L70+$P$70 -> 127.0942 | P70: 261.0007
A71: 42107 | B71: -133.1836 | C71: =VLOOKUP(A71,F:G,2,0) -> 130.7266 | D71: v20 | F71: 42205 | G71: 45.5665 | H71: v21 | K71: 42107 | L71: -133.1836 | M71: 130.7266 | N71: 130.7556 | O71: =L71+$P$70 -> 127.8171
A72: 42108 | B72: -134.8033 | C72: =VLOOKUP(A72,F:G,2,0) -> 138.2887 | D72: v20 | F72: 42206 | G72: 44.9564 | H72: v21 | K72: 42108 | L72: -134.8033 | M72: 138.2887 | N72: 138.2887 | O72: =L72+$P$70 -> 126.1974
A73: 42109 | B73: -140.3716 | C73: =VLOOKUP(A73,F:G,2,0) -> 136.0755 | D73: v20 | F73: 42207 | G73: 39.3369 | H73: v21 | K73: 42109 | L73: -140.3716 | M73: 136.0755 | N73: 136.07491 | O73: =L73+$P$70 -> 120.6291
A74: 42110 | B74: -141.224 | C74: =VLOOKUP(A74,F:G,2,0) -> 139.1769 | D74: v20 | F74: 42208 | G74: 35.8512 | H74: v21 | K74: 42110 | L74: -141.224 | M74: 139.1769 | N74: 139.1769 | O74: =L74+$P$70 -> 119.7767
A75: 42111 | B75: -156.3411 | C75: =VLOOKUP(A75,F:G,2,0) -> 125.3102 | D75: v20 | F75: 42209 | G75: 35.2906 | H75: v21 | K75: 42111 | L75: -156.3411 | M75: 125.3102 | N75: 125.3101 | O75: =L75+$P$70 -> 104.6596
A76: 42114 | B76: -165.034 | C76: =VLOOKUP(A76,F:G,2,0) -> 115.6804 | D76: v20 | F76: 42212 | G76: 45.6662 | H76: v21 | K76: 42114 | L76: -165.034 | M76: 115.6804 | N76: 115.6797 | O76: =L76+$P$70 -> 95.9667
A77: 42115 | B77: -169.8048 | C77: =VLOOKUP(A77,F:G,2,0) -> 107.4848 | D77: v20 | F77: 42213 | G77: 44.048 | H77: v21 | K77: 42115 | L77: -169.8048 | M77: 107.4848 | N77: 107.4842 | O77: =L77+$P$70 -> 91.1959
A78: 42116 | B78: -168.9825 | C78: =VLOOKUP(A78,F:G,2,0) -> 99.4964 | D78: v20 | F78: 42214 | G78: 52.5424 | H78: v21 | K78: 42116 | L78: -168.9825 | M78: 99.4964 | N78: 99.495796 | O78: =L78+$P$70 -> 92.0182
A79: 42117 | B79: -174.489 | C79: =VLOOKUP(A79,F:G,2,0) -> 99.1439 | D79: v20 | F79: 42215 | G79: 56.8137 | H79: v21 | K79: 42117 | L79: -174.489 | M79: 99.1439 | N79: 99.143402 | O79: =L79+$P$70 -> 86.5117
A80: 42118 | B80: -179.8706 | C80: =VLOOKUP(A80,F:G,2,0) -> 100.3833 | D80: v20 | F80: 42216 | G80: 55.1827 | H80: v21 | K80: 42118 | L80: -179.8706 | M80: 100.3833 | N80: 100.3833 | O80: =L80+$P$70 -> 81.1301
A81: 42121 | B81: -181.8879 | C81: =VLOOKUP(A81,F:G,2,0) -> 97.056 | D81: v20 | F81: 42219 | G81: 53.4879 | H81: v21 | K81: 42121 | L81: -181.8879 | M81: 97.056 | N81: 97.072701 | O81: =L81+$P$70 -> 79.1128
A82: 42122 | B82: -188.4646 | C82: =VLOOKUP(A82,F:G,2,0) -> 81.5968 | D82: v20 | F82: 42220 | G82: 54.3218 | H82: v21 | K82: 42122 | L82: -188.4646 | M82: 81.5968 | N82: 81.623901 | O82: =L82+$P$70 -> 72.5361
... A156: 42228 | B156: -168.8875 | C156: =VLOOKUP(A156,F:G,2,0) -> 49.7119 | D156: v20 | F156: 42327 | G156: 80.3921 | H156: v21 | K156: 42228 | L156: -168.8875 | M156: 49.7119 | N156: 49.711399 | O156: =L156+$P$70 -> 92.1132
A157: 42229 | C157: =VLOOKUP(A157,F:G,2,0) -> 49.487 | F157: 42328 | G157: 69.5885 | H157: v21 | K157: 42229 | M157: 49.487 | N157: 49.487
A158: 42230 | C158: =VLOOKUP(A158,F:G,2,0) -> 46.8979 | F158: 42331 | G158: 62.042 | H158: v21 | K158: 42230 | M158: 46.8979 | N158: 46.8979
A159: 42233 | C159: =VLOOKUP(A159,F:G,2,0) -> 51.7185 | F159: 42332 | G159: 67.2167 | H159: v21 | K159: 42233 | M159: 51.7185 | N159: 51.718498
A160: 42234 | C160: =VLOOKUP(A160,F:G,2,0) -> 55.3883 | F160: 42333 | G160: 61.8171 | H160: v21 | K160: 42234 | M160: 55.3883 | N160: 55.388302
A161: 42235 | C161: =VLOOKUP(A161,F:G,2,0) -> 65.3884 | F161: 42335 | G161: 58.9507 | H161: v21 | K161: 42235 | M161: 65.3884 | N161: 65.387802
A162: 42236 | C162: =VLOOKUP(A162,F:G,2,0) -> 63.931 | F162: 42338 | G162: 54.8951 | H162: v21 | K162: 42236 | M162: 63.931 | N162: 63.930401
A163: 42237 | C163: =VLOOKUP(A163,F:G,2,0) -> 66.9188 | F163: 42339 | G163: 55.4935 | H163: v21 | K163: 42237 | M163: 66.9188 | N163: 66.918297
A164: 42240 | C164: =VLOOKUP(A164,F:G,2,0) -> 73.8726 | F164: 42340 | G164: 47.9858 | H164: v21 | K164: 42240 | M164: 73.8726 | N164: 73.872002
A165: 42241 | C165: =VLOOKUP(A165,F:G,2,0) -> 73.7057 | F165: 42341 | G165: 43.2034 | H165: v21 | K165: 42241 | M165: 73.7057 | N165: 73.7052
A166: 42242 | C166: =VLOOKUP(A166,F:G,2,0) -> 75.4673 | F166: 42342 | G166: 40.6102 | H166: v21 | K166: 42242 | M166: 75.4673 | N166: 75.466797
A167: 42243 | C167: =VLOOKUP(A167,F:G,2,0) -> 75.6844 | F167: 42345 | G167: 33.5858 | H167: v21 | K167: 42243 | M167: 75.6844 | N167: 75.684402
A168: 42244 | C168: =VLOOKUP(A168,F:G,2,0) -> 64.8481 | F168: 42346 | G168: 33.1171 | H168: v21 | K168: 42244 | M168: 64.8481 | N168: 64.847504
...

Sheet Sheet2
A1: AsOfDate | B1: TickerName | C1: SeriesNumValue | D1: ModelType | H1: Average of SeriesNumValue | I1: Column Labels
A2: 41593 | B2: FN30.400.10(IOX) | C2: 175.0663 | D2: v20 | H2: Row Labels | I2: v20 | J2: v21 | K2: Grand Total | N2: Row Labels | O2: v20 | P2: v21 | Q2: Backfilled V21 | R2: v20+diff | S2: Barcap
A3: 41596 | B3: FN30.400.10(IOX) | C3: 179.3541 | D3: v20 | H3: 41593 | I3: 175.0663 | K3: 175.0663 | N3: 41593 | O3: 175.0663 | Q3: 174.9868 | R3: =O3+Sheet1!$P$70 -> 436.067 | S3: 991
A4: 41597 | B4: FN30.400.10(IOX) | C4: 161.8585 | D4: v20 | H4: 41596 | I4: 179.3541 | K4: 179.3541 | N4: 41596 | O4: 179.3541 | Q4: 179.3907 | R4: =O4+Sheet1!$P$70 -> 440.3548 | S4: 939
A5: 41598 | B5: FN30.400.10(IOX) | C5: 140.7564 | D5: v20 | H5: 41597 | I5: 161.8585 | K5: 161.8585 | N5: 41597 | O5: 161.8585 | Q5: 161.8232 | R5: =O5+Sheet1!$P$70 -> 422.8592 | S5: 930
A6: 41599 | B6: FN30.400.10(IOX) | C6: 164.0781 | D6: v20 | H6: 41598 | I6: 140.7564 | K6: 140.7564 | N6: 41598 | O6: 140.7564 | Q6: 140.72749 | R6: =O6+Sheet1!$P$70 -> 401.7571 | S6: 919
A7: 41600 | B7: FN30.400.10(IOX) | C7: 176.1895 | D7: v20 | H7: 41599 | I7: 164.0781 | K7: 164.0781 | N7: 41599 | O7: 164.0781 | Q7: 164.22971 | R7: =O7+Sheet1!$P$70 -> 425.0788 | S7: 895
A8: 41603 | B8: FN30.400.10(IOX) | C8: 173.2382 | D8: v20 | H8: 41600 | I8: 176.1895 | K8: 176.1895 | N8: 41600 | O8: 176.1895 | Q8: 176.2106 | R8: =O8+Sheet1!$P$70 -> 437.1902 | S8: 846
A9: 41604 | B9: FN30.400.10(IOX) | C9: 174.5157 | D9: v20 | H9: 41603 | I9: 173.2382 | K9: 173.2382 | N9: 41603 | O9: 173.2382 | Q9: 173.25909 | R9: =O9+Sheet1!$P$70 -> 434.2389 | S9: 855
A10: 41605 | B10: FN30.400.10(IOX) | C10: 167.0001 | D10: v20 | H10: 41604 | I10: 174.5157 | K10: 174.5157 | N10: 41604 | O10: 174.5157 | Q10: 174.4735 | R10: =O10+Sheet1!$P$70 -> 435.5164 | S10: 869
A11: 41607 | B11: FN30.400.10(IOX) | C11: 164.6639 | D11: v20 | H11: 41605 | I11: 167.0001 | K11: 167.0001 | N11: 41605 | O11: 167.0001 | Q11: 166.94 | R11: =O11+Sheet1!$P$70 -> 428.0008 | S11: 872
A12: 41610 | B12: FN30.400.10(IOX) | C12: 146.7724 | D12: v20 | H12: 41607 | I12: 164.6639 | K12: 164.6639 | N12: 41607 | O12: 164.6639 | Q12: 164.66389 | R12: =O12+Sheet1!$P$70 -> 425.6646 | S12: 882
A13: 41611 | B13: FN30.400.10(IOX) | C13: 148.8281 | D13: v20 | H13: 41610 | I13: 146.7724 | K13: 146.7724 | N13: 41610 | O13: 146.7724 | Q13: 146.7724 | R13: =O13+Sheet1!$P$70 -> 407.7731 | S13: 872
A14: 41612 | B14: FN30.400.10(IOX) | C14: 129.9705 | D14: v20 | H14: 41611 | I14: 148.8281 | K14: 148.8281 | N14: 41611 | O14: 148.8281 | Q14: 148.85809 | R14: =O14+Sheet1!$P$70 -> 409.8288 | S14: 834
... A351: 42104 | B351: FN30.400.10(IOX) | C351: -133.9065 | D351: v20 | H351: 42103 | I351: -153.2722 | K351: -153.2722 | N351: 42103 | O351: -153.2722 | Q351: 109.698 | R351: =O351+Sheet1!$P$70 -> 107.7285 | S351: 688
A352: 42107 | B352: FN30.400.10(IOX) | C352: -133.1836 | D352: v20 | H352: 42104 | I352: -133.9065 | J352: 127.0942 | K352: -3.40615 | N352: 42104 | O352: -133.9065 | P352: 127.0942 | Q352: 127.0935 | R352: =O352+Sheet1!$P$70 -> 127.0942 | S352: 687
A353: 42108 | B353: FN30.400.10(IOX) | C353: -134.8033 | D353: v20 | H353: 42107 | I353: -133.1836 | J353: 130.7266 | K353: -1.2285 | N353: 42107 | O353: -133.1836 | P353: 130.7266 | Q353: 130.7556 | R353: =O353+Sheet1!$P$70 -> 127.8171 | S353: 688
A354: 42109 | B354: FN30.400.10(IOX) | C354: -140.3716 | D354: v20 | H354: 42108 | I354: -134.8033 | J354: 138.2887 | K354: 1.7427 | N354: 42108 | O354: -134.8033 | P354: 138.2887 | Q354: 138.2887 | R354: =O354+Sheet1!$P$70 -> 126.1974 | S354: 694
A355: 42110 | B355: FN30.400.10(IOX) | C355: -141.224 | D355: v20 | H355: 42109 | I355: -140.3716 | J355: 136.0755 | K355: -2.14805 | N355: 42109 | O355: -140.3716 | P355: 136.0755 | Q355: 136.07491 | R355: =O355+Sheet1!$P$70 -> 120.6291 | S355: 704
A356: 42111 | B356: FN30.400.10(IOX) | C356: -156.3411 | D356: v20 | H356: 42110 | I356: -141.224 | J356: 139.1769 | K356: -1.02355 | N356: 42110 | O356: -141.224 | P356: 139.1769 | Q356: 139.1769 | R356: =O356+Sheet1!$P$70 -> 119.7767 | S356: 686
A357: 42114 | B357: FN30.400.10(IOX) | C357: -165.034 | D357: v20 | H357: 42111 | I357: -156.3411 | J357: 125.3102 | K357: -15.51545 | N357: 42111 | O357: -156.3411 | P357: 125.3102 | Q357: 125.3101 | R357: =O357+Sheet1!$P$70 -> 104.6596 | S357: 705
A358: 42115 | B358: FN30.400.10(IOX) | C358: -169.8048 | D358: v20 | H358: 42114 | I358: -165.034 | J358: 115.6804 | K358: -24.6768 | N358: 42114 | O358: -165.034 | P358: 115.6804 | Q358: 115.6797 | R358: =O358+Sheet1!$P$70 -> 95.9667 | S358: 713
A359: 42116 | B359: FN30.400.10(IOX) | C359: -168.9825 | D359: v20 | H359: 42115 | I359: -169.8048 | J359: 107.4848 | K359: -31.16 | N359: 42115 | O359: -169.8048 | P359: 107.4848 | Q359: 107.4842 | R359: =O359+Sheet1!$P$70 -> 91.1959 | S359: 749
A360: 42117 | B360: FN30.400.10(IOX) | C360: -174.489 | D360: v20 | H360: 42116 | I360: -168.9825 | J360: 99.4964 | K360: -34.74305 | N360: 42116 | O360: -168.9825 | P360: 99.4964 | Q360: 99.495796 | R360: =O360+Sheet1!$P$70 -> 92.0182 | S360: 784
A361: 42118 | B361: FN30.400.10(IOX) | C361: -179.8706 | D361: v20 | H361: 42117 | I361: -174.489 | J361: 99.1439 | K361: -37.67255 | N361: 42117 | O361: -174.489 | P361: 99.1439 | Q361: 99.143402 | R361: =O361+Sheet1!$P$70 -> 86.5117 | S361: 817
A362: 42121 | B362: FN30.400.10(IOX) | C362: -181.8879 | D362: v20 | H362: 42118 | I362: -179.8706 | J362: 100.3833 | K362: -39.74365 | N362: 42118 | O362: -179.8706 | P362: 100.3833 | Q362: 100.3833 | R362: =O362+Sheet1!$P$70 -> 81.1301 | S362: 748
A363: 42122 | B363: FN30.400.10(IOX) | C363: -188.4646 | D363: v20 | H363: 42121 | I363: -181.8879 | J363: 97.056 | K363: -42.41595 | N363: 42121 | O363: -181.8879 | P363: 97.056 | Q363: 97.072701 | R363: =O363+Sheet1!$P$70 -> 79.1128 | S363: 704
... A438: 42104 | B438: FN30.400.10(IOX) | C438: 127.0942 | D438: v21 | H438: 42228 | I438: -168.8875 | J438: 49.7119 | K438: -59.5878 | N438: 42228 | O438: -168.8875 | P438: 49.7119 | Q438: 49.711399 | R438: =O438+Sheet1!$P$70 -> 92.1132 | S438: 436
A439: 42107 | B439: FN30.400.10(IOX) | C439: 130.7266 | D439: v21 | H439: 42229 | J439: 49.487 | K439: 49.487 | N439: 42229 | P439: 49.487 | Q439: 49.487 | S439: 433
A440: 42108 | B440: FN30.400.10(IOX) | C440: 138.2887 | D440: v21 | H440: 42230 | J440: 46.8979 | K440: 46.8979 | N440: 42230 | P440: 46.8979 | Q440: 46.8979 | S440: 432
A441: 42109 | B441: FN30.400.10(IOX) | C441: 136.0755 | D441: v21 | H441: 42233 | J441: 51.7185 | K441: 51.7185 | N441: 42233 | P441: 51.7185 | Q441: 51.718498 | S441: 434
A442: 42110 | B442: FN30.400.10(IOX) | C442: 139.1769 | D442: v21 | H442: 42234 | J442: 55.3883 | K442: 55.3883 | N442: 42234 | P442: 55.3883 | Q442: 55.388302 | S442: 421
A443: 42111 | B443: FN30.400.10(IOX) | C443: 125.3102 | D443: v21 | H443: 42235 | J443: 65.3884 | K443: 65.3884 | N443: 42235 | P443: 65.3884 | Q443: 65.387802 | S443: 427
A444: 42114 | B444: FN30.400.10(IOX) | C444: 115.6804 | D444: v21 | H444: 42236 | J444: 63.931 | K444: 63.931 | N444: 42236 | P444: 63.931 | Q444: 63.930401 | S444: 425
A445: 42115 | B445: FN30.400.10(IOX) | C445: 107.4848 | D445: v21 | H445: 42237 | J445: 66.9188 | K445: 66.9188 | N445: 42237 | P445: 66.9188 | Q445: 66.918297 | S445: 418
A446: 42116 | B446: FN30.400.10(IOX) | C446: 99.4964 | D446: v21 | H446: 42240 | J446: 73.8726 | K446: 73.8726 | N446: 42240 | P446: 73.8726 | Q446: 73.872002 | S446: 409
A447: 42117 | B447: FN30.400.10(IOX) | C447: 99.1439 | D447: v21 | H447: 42241 | J447: 73.7057 | K447: 73.7057 | N447: 42241 | P447: 73.7057 | Q447: 73.7052 | S447: 393
A448: 42118 | B448: FN30.400.10(IOX) | C448: 100.3833 | D448: v21 | H448: 42242 | J448: 75.4673 | K448: 75.4673 | N448: 42242 | P448: 75.4673 | Q448: 75.466797 | S448: 379
A449: 42121 | B449: FN30.400.10(IOX) | C449: 97.056 | D449: v21 | H449: 42243 | J449: 75.6844 | K449: 75.6844 | N449: 42243 | P449: 75.6844 | Q449: 75.684402 | S449: 355
A450: 42122 | B450: FN30.400.10(IOX) | C450: 81.5968 | D450: v21 | H450: 42244 | J450: 64.8481 | K450: 64.8481 | N450: 42244 | P450: 64.8481 | Q450: 64.847504 | S450: 358
...

Sheet Sheet3
B1: Barcap | C1: YB v20 | D1: YB OAS v21 | E1: v20+diff
A2: 40588 | B2: 302 | D2: -46.355499
A3: 40589 | B3: 286 | D3: -59.443802
A4: 40590 | B4: 279 | D4: -65.651901
A5: 40591 | B5: 288 | D5: -47.389
A6: 40592 | B6: 289 | D6: -51.927299
A7: 40596 | B7: 308 | D7: -36.043598
A8: 40597 | B8: 306 | D8: -40.838699
A9: 40598 | B9: 308 | D9: -36.337601
A10: 40599 | B10: 315 | D10: -30.010599
A11: 40602 | B11: 319 | D11: -27.406799
A12: 40603 | B12: 322 | D12: -22.981199
A13: 40604 | B13: 320 | D13: -28.4123
... A690: 41592 | B690: 338 | D690: 175.7213
A691: 41593 | B691: 334 | C691: 175.0663 | D691: 174.9868 | E691: =C691+Sheet1!$P$70 -> 436.067
A692: 41596 | B692: 336 | C692: 179.3541 | D692: 179.3907 | E692: =C692+Sheet1!$P$70 -> 440.3548
A693: 41597 | B693: 317 | C693: 161.8585 | D693: 161.8232 | E693: =C693+Sheet1!$P$70 -> 422.8592
A694: 41598 | B694: 295 | C694: 140.7564 | D694: 140.72749 | E694: =C694+Sheet1!$P$70 -> 401.7571
A695: 41599 | B695: 322 | C695: 164.0781 | D695: 164.22971 | E695: =C695+Sheet1!$P$70 -> 425.0788
A696: 41600 | B696: 335 | C696: 176.1895 | D696: 176.2106 | E696: =C696+Sheet1!$P$70 -> 437.1902
A697: 41603 | B697: 327 | C697: 173.2382 | D697: 173.25909 | E697: =C697+Sheet1!$P$70 -> 434.2389
A698: 41604 | B698: 334 | C698: 174.5157 | D698: 174.4735 | E698: =C698+Sheet1!$P$70 -> 435.5164
A699: 41605 | B699: 320 | C699: 167.0001 | D699: 166.94 | E699: =C699+Sheet1!$P$70 -> 428.0008
A700: 41607 | B700: 324 | C700: 164.6639 | D700: 164.66389 | E700: =C700+Sheet1!$P$70 -> 425.6646
A701: 41610 | B701: 297 | C701: 146.7724 | D701: 146.7724 | E701: =C701+Sheet1!$P$70 -> 407.7731
A702: 41611 | B702: 300 | C702: 148.8281 | D702: 148.85809 | E702: =C702+Sheet1!$P$70 -> 409.8288
... A1126: 42228 | B1126: 12 | C1126: -168.8875 | D1126: 49.711399 | E1126: =C1126+Sheet1!$P$70 -> 92.1132
A1127: 42229 | B1127: 3 | D1127: 49.487
A1128: 42230 | B1128: 3 | D1128: 46.8979
A1129: 42233 | B1129: 6 | D1129: 51.718498
A1130: 42234 | B1130: 6 | D1130: 55.388302
A1131: 42235 | B1131: 9 | D1131: 65.387802
A1132: 42236 | B1132: 12 | D1132: 63.930401
A1133: 42237 | B1133: 15 | D1133: 66.918297
A1134: 42240 | B1134: 24 | D1134: 73.872002
A1135: 42241 | B1135: 16 | D1135: 73.7052
A1136: 42242 | B1136: 22 | D1136: 75.466797
A1137: 42243 | B1137: 21 | D1137: 75.684402
A1138: 42244 | B1138: 14 | D1138: 64.847504
... A1250: 42411 | B1250: -34 | D1250: 76.545998
...
