Workbook

Sheet Sheet1
C1: y_vals.act | D1: y_vals.mdl | E1: y_vals.curt | F1: y_vals.defualt | G1: y_vals.turn | H1: y_vals.refi | M1: y_vals.act | N1: y_vals.mdl | O1: y_vals.curt | P1: y_vals.defualt | Q1: y_vals.turn | R1: y_vals.refi | S1: y_vals.act | T1: y_vals.mdl | U1: y_vals.curt | V1: y_vals.defualt | W1: CR | X1: y_vals.refi
K2: [1,] | L2: 41122 | M2: 0.18464355 | N2: 1.1675254 | O2: 0.15737249 | P2: 0.00039199562 | Q2: 0.76277582 | R2: 0.25019898
K3: [2,] | L3: 41153 | M3: 0.14023606 | N3: 1.4731414 | O3: 0.24016375 | P3: 0.0029382208 | Q3: 0.9321142 | R3: 0.30327314
K4: [3,] | L4: 41183 | M4: 0.26491105 | N4: 1.6068261 | O4: 0.26649253 | P4: 0.00040583904 | Q4: 0.99104883 | R4: 0.35539883
K5: [4,] | L5: 41214 | M5: 0.14529536 | N5: 1.9815908 | O5: 0.3335316 | P5: 0.015818076 | Q5: 1.1362337 | R5: 0.50658337
K6: [5,] | L6: 41244 | M6: 5.3730903 | N6: 2.3725866 | O6: 0.37554737 | P6: 0.0005720979 | Q6: 1.3730838 | R6: 0.63834069
K7: [6,] | L7: 41275 | M7: 0.14959325 | N7: 1.7144583 | O7: 0.29086878 | P7: 0.00079349195 | Q7: 0.86834856 | R7: 0.56274853
A8: [1,] | B8: 41306 | C8: 0.12016988 | D8: 0.60454115 | E8: 0.13318112 | F8: 0.00099159038 | G8: 0.34716476 | H8: 0.12417952 | K8: [7,] | L8: 41306 | M8: 0.21374687 | N8: 1.3054821 | O8: 0.22054631 | P8: 0.00087602822 | Q8: 0.73122667 | R8: 0.35743785 | S8: 0.12016988 | T8: 0.60454115 | U8: 0.13318112 | V8: 0.00099159038 | W8: 0.34716476 | X8: 0.12417952
A9: [2,] | B9: 41334 | C9: 0.21554381 | D9: 0.97223188 | E9: 0.19696897 | F9: 0.0059259008 | G9: 0.64428031 | H9: 0.12725326 | K9: [8,] | L9: 41334 | M9: 1.38657 | N9: 1.7579526 | O9: 0.27521102 | P9: 0.0098360985 | Q9: 1.1610501 | R9: 0.31914014 | S9: 0.21554381 | T9: 0.97223188 | U9: 0.19696897 | V9: 0.0059259008 | W9: 0.64428031 | X9: 0.12725326
A10: [3,] | B10: 41365 | C10: 1.4744307 | D10: 1.2635727 | E10: 0.24124089 | F10: 0.016281829 | G10: 0.86575993 | H10: 0.14384965 | K10: [9,] | L10: 41365 | M10: 0.45746197 | N10: 2.4427687 | O10: 0.31488608 | P10: 0.095121319 | Q10: 1.6323936 | R10: 0.41452294 | S10: 1.4744307 | T10: 1.2635727 | U10: 0.24124089 | V10: 0.016281829 | W10: 0.86575993 | X10: 0.14384965
A11: [4,] | B11: 41395 | C11: 0.57396963 | D11: 1.4777031 | E11: 0.25584944 | F11: 0.050503922 | G11: 1.0064592 | H11: 0.16987685 | K11: [10,] | L11: 41395 | M11: 2.1376792 | N11: 2.7305718 | O11: 0.31635488 | P11: 0.071013633 | Q11: 1.8869046 | R11: 0.47305093 | S11: 0.57396963 | T11: 1.4777031 | U11: 0.25584944 | V11: 0.050503922 | W11: 1.0064592 | X11: 0.16987685
A12: [5,] | B12: 41426 | C12: 0.6331116 | D12: 1.8406544 | E12: 0.28870432 | F12: 0.094136027 | G12: 1.2859839 | H12: 0.1793301 | K12: [11,] | L12: 41426 | M12: 2.0824156 | N12: 2.9922673 | O12: 0.32615509 | P12: 0.073330508 | Q12: 2.1961273 | R12: 0.41476976 | S12: 0.6331116 | T12: 1.8406544 | U12: 0.28870432 | V12: 0.094136027 | W12: 1.2859839 | X12: 0.1793301
A13: [6,] | B13: 41456 | C13: 0.365465 | D13: 2.636799 | E13: 0.30791883 | F13: 0.81170322 | G13: 1.383912 | H13: 0.15324374 | K13: [12,] | L13: 41456 | M13: 2.8796844 | N13: 3.0820546 | O13: 0.33530999 | P13: 0.27996723 | Q13: 2.2348674 | R13: 0.25193232 | S13: 0.365465 | T13: 2.636799 | U13: 0.30791883 | V13: 0.81170322 | W13: 1.383912 | X13: 0.15324374
A14: [7,] | B14: 41487 | C14: 2.477724 | D14: 3.0029013 | E14: 0.30521109 | F14: 1.0771572 | G14: 1.4964864 | H14: 0.14993807 | K14: [13,] | L14: 41487 | M14: 3.6355821 | N14: 3.0660081 | O14: 0.3338986 | P14: 0.36646787 | Q14: 2.186726 | R14: 0.19932507 | S14: 2.477724 | T14: 3.0029013 | U14: 0.30521109 | V14: 1.0771572 | W14: 1.4964864 | X14: 0.14993807
A15: [8,] | B15: 41518 | C15: 1.2169574 | D15: 3.5469534 | E15: 0.31136466 | F15: 1.629096 | G15: 1.4664652 | H15: 0.17620177 | K15: [14,] | L15: 41518 | M15: 3.3367917 | N15: 2.7365736 | O15: 0.33800047 | P15: 0.31873894 | Q15: 1.9100785 | R15: 0.18661194 | S15: 1.2169574 | T15: 3.5469534 | U15: 0.31136466 | V15: 1.629096 | W15: 1.4664652 | X15: 0.17620177
A16: [9,] | B16: 41548 | C16: 2.0703398 | D16: 3.6385645 | E16: 0.2909971 | F16: 1.7747065 | G16: 1.4446256 | H16: 0.16559342 | K16: [15,] | L16: 41548 | M16: 2.1098778 | N16: 2.7706575 | O16: 0.33444348 | P16: 0.34335687 | Q16: 1.9291772 | R16: 0.18102305 | S16: 2.0703398 | T16: 3.6385645 | U16: 0.2909971 | V16: 1.7747065 | W16: 1.4446256 | X16: 0.16559342
A17: [10,] | B17: 41579 | C17: 2.8533816 | D17: 4.3185807 | E17: 0.30427014 | F17: 2.5335758 | G17: 1.3593458 | H17: 0.17029674 | K17: [16,] | L17: 41579 | M17: 3.5623617 | N17: 3.0269909 | O17: 0.3398343 | P17: 0.49843669 | Q17: 1.9732629 | R17: 0.23827509 | S17: 2.8533816 | T17: 4.3185807 | U17: 0.30427014 | V17: 2.5335758 | W17: 1.3593458 | X17: 0.17029674
A18: [11,] | B18: 41609 | C18: 1.2624675 | D18: 4.8865063 | E18: 0.31593368 | F18: 2.916292 | G18: 1.5381771 | H18: 0.17780981 | K18: [17,] | L18: 41609 | M18: 4.3238942 | N18: 3.1114828 | O18: 0.34266371 | P18: 0.47763141 | Q18: 2.0838465 | R18: 0.23061244 | S18: 1.2624675 | T18: 4.8865063 | U18: 0.31593368 | V18: 2.916292 | W18: 1.5381771 | X18: 0.17780981
A19: [12,] | B19: 41640 | C19: 1.8374941 | D19: 5.3229109 | E19: 0.32665541 | F19: 3.6023423 | G19: 1.2790522 | H19: 0.18023503 | K19: [18,] | L19: 41640 | M19: 1.4459923 | N19: 2.5541627 | O19: 0.34550874 | P19: 0.50859897 | Q19: 1.5289197 | R19: 0.18881172 | S19: 1.8374941 | T19: 5.3229109 | U19: 0.32665541 | V19: 3.6023423 | W19: 1.2790522 | X19: 0.18023503
... A50: [43,] | B50: 42583 | C50: 0.47658692 | D50: 18.80389 | E50: 0.44157358 | F50: 12.826985 | G50: 5.4240585 | H50: 0.99045542 | K50: [49,] | L50: 42583 | M50: 0.16442525 | N50: 10.017652 | O50: 0.5751798 | P50: 0.62340111 | Q50: 6.6894944 | R50: 2.3773681 | S50: 0.47658692 | T50: 18.80389 | U50: 0.44157358 | V50: 12.826985 | W50: 5.4240585 | X50: 0.99045542
A51: [44,] | B51: 42614 | C51: 0.17254365 | D51: 18.266034 | E51: 0.44566994 | F51: 13.033985 | G51: 4.5927406 | H51: 0.97384556 | L51: 42614 | S51: 0.17254365 | T51: 18.266034 | U51: 0.44566994 | V51: 13.033985 | W51: 4.5927406 | X51: 0.97384556

Sheet Sheet2
A1: marketTicker | B1: asOf | C1: count(1) | D1: sum(p.schamBalance) | E1: wavg_est_pct_DELQ30p | J1: marketTicker | K1: FNCQ30
A2: FNCL | B2: 34366 | C2: 126636 | D2: 2.7849025e+11 | E2: 1.9894751
A3: FNCL | B3: 34394 | C3: 128266 | D3: 2.8205083e+11 | E3: 1.9585163 | J3: Row Labels | K3: Sum of wavg_est_pct_DELQ30p
A4: FNCL | B4: 34425 | C4: 129601 | D4: 2.838742e+11 | E4: 1.9586566 | J4: 40148 | K4: 0.80449901
A5: FNCL | B5: 34455 | C5: 130768 | D5: 2.847529e+11 | E5: 1.9477244 | J5: 40179 | K5: 1.458639
A6: FNCL | B6: 34486 | C6: 131996 | D6: 2.8712206e+11 | E6: 1.9469508 | J6: 40210 | K6: 1.416573
A7: FNCL | B7: 34516 | C7: 133140 | D7: 2.8891975e+11 | E7: 1.9728531 | J7: 40238 | K7: 1.7293501
A8: FNCL | B8: 34547 | C8: 134153 | D8: 2.9064065e+11 | E8: 1.977559 | J8: 40269 | K8: 1.7478326
A9: FNCL | B9: 34578 | C9: 135077 | D9: 2.9202625e+11 | E9: 1.9951845 | J9: 40299 | K9: 2.0462584
A10: FNCL | B10: 34608 | C10: 135888 | D10: 2.9339599e+11 | E10: 2.0223353 | J10: 40330 | K10: 2.3795044
A11: FNCL | B11: 34639 | C11: 136567 | D11: 2.94792e+11 | E11: 2.077268 | J11: 40360 | K11: 2.5705938
A12: FNCL | B12: 34669 | C12: 137384 | D12: 2.9702273e+11 | E12: 2.0879008 | J12: 40391 | K12: 3.7815514
A13: FNCL | B13: 34700 | C13: 138175 | D13: 2.9953479e+11 | E13: 2.1044252 | J13: 40422 | K13: 3.9507045
A14: FNCL | B14: 34731 | C14: 138749 | D14: 3.0057806e+11 | E14: 2.1420291 | J14: 40452 | K14: 3.6977498
A15: FNCL | B15: 34759 | C15: 139252 | D15: 3.0151552e+11 | E15: 2.1691959 | J15: 40483 | K15: 3.6733533
... A86: FNCL | B86: 36923 | C86: 209121 | D86: 7.1193641e+11 | E86: 2.4205377 | J86: 42644 | K86: 7.7501876
A87: FNCL | B87: 36951 | C87: 210670 | D87: 7.2415943e+11 | E87: 2.0725191 | J87: Grand Total | K87: 261.96069
A88: FNCL | B88: 36982 | C88: 212403 | D88: 7.3713162e+11 | E88: 2.1572388
A89: FNCL | B89: 37012 | C89: 214231 | D89: 7.5255621e+11 | E89: 2.2614647
A90: FNCL | B90: 37043 | C90: 216060 | D90: 768634381863 | E90: 2.258799
A91: FNCL | B91: 37073 | C91: 217775 | D91: 7.838996e+11 | E91: 2.2417884
A92: FNCL | B92: 37104 | C92: 219337 | D92: 800219895172 | E92: 1.8679243
A93: FNCL | B93: 37135 | C93: 220863 | D93: 8.1627696e+11 | E93: 2.1216329
A94: FNCL | B94: 37165 | C94: 222193 | D94: 8.2934041e+11 | E94: 2.0952071
A95: FNCL | B95: 37196 | C95: 223572 | D95: 8.4108138e+11 | E95: 2.2261681
A96: FNCL | B96: 37226 | C96: 225055 | D96: 8.5335439e+11 | E96: 2.5035107
A97: FNCL | B97: 37257 | C97: 226605 | D97: 8.6500934e+11 | E97: 2.1245954
A98: FNCL | B98: 37288 | C98: 227719 | D98: 8.6800265e+11 | E98: 2.2889004
A99: FNCL | B99: 37316 | C99: 228962 | D99: 8.7969648e+11 | E99: 2.1245154
... A509: FNCQ30 | B509: 42644 | C509: 2155 | D509: 3.8990715e+10 | E509: 7.7501876

Sheet Sheet3
A1: marketTicker | B1: asOf | C1: count(1) | D1: sum(p.schamBalance) | E1: wavg_est_pct_DELQ30p | J1: marketTicker | K1: FGU9
A2: FGLMC | B2: 34366 | C2: 47564 | D2: 1.7936303e+11 | E2: 0.90609093
A3: FGLMC | B3: 34394 | C3: 48770 | D3: 1.8267643e+11 | E3: 0.88388459 | J3: Row Labels | K3: Sum of wavg_est_pct_DELQ30p
A4: FGLMC | B4: 34425 | C4: 50054 | D4: 1.8717384e+11 | E4: 0.87783008 | J4: 41091 | K4: 0.54942937
A5: FGLMC | B5: 34516 | C5: 53319 | D5: 1.9825763e+11 | E5: 0.92220229 | J5: 41122 | K5: 0.57992543
A6: FGLMC | B6: 34547 | C6: 54110 | D6: 2.0067919e+11 | E6: 0.94981984 | J6: 41153 | K6: 0.85425081
A7: FGLMC | B7: 34578 | C7: 54835 | D7: 2.0294126e+11 | E7: 0.98095667 | J7: 41183 | K7: 2.5717149
A8: FGLMC | B8: 34608 | C8: 55530 | D8: 2.0522667e+11 | E8: 1.0212469 | J8: 41214 | K8: 5.017555
A9: FGLMC | B9: 34639 | C9: 56108 | D9: 2.0697511e+11 | E9: 1.0535932 | J9: 41244 | K9: 6.4709299
A10: FGLMC | B10: 34669 | C10: 56529 | D10: 2.0775371e+11 | E10: 1.0880094 | J10: 41275 | K10: 8.2520511
A11: FGLMC | B11: 34700 | C11: 56894 | D11: 2.0840618e+11 | E11: 1.1308304 | J11: 41306 | K11: 9.9797961
A12: FGLMC | B12: 34731 | C12: 57294 | D12: 2.0935918e+11 | E12: 1.1674185 | J12: 41334 | K12: 11.376138
A13: FGLMC | B13: 34759 | C13: 57702 | D13: 2.1044467e+11 | E13: 1.205176 | J13: 41365 | K13: 11.525803
A14: FGLMC | B14: 34790 | C14: 58144 | D14: 2.120786e+11 | E14: 1.2331038 | J14: 41395 | K14: 11.437916
A15: FGLMC | B15: 34820 | C15: 58699 | D15: 2.1408617e+11 | E15: 1.2635669 | J15: 41426 | K15: 11.616415
... A55: FGLMC | B55: 36100 | C55: 91404 | D55: 4.0547723e+11 | E55: 1.7650725 | J55: 42644 | K55: 14.882005
A56: FGLMC | B56: 36130 | C56: 92421 | D56: 4.1598787e+11 | E56: 1.7271859 | J56: Grand Total | K56: 690.81996
A57: FGLMC | B57: 36161 | C57: 93582 | D57: 4.2302971e+11 | E57: 1.7035505
A58: FGLMC | B58: 36192 | C58: 94621 | D58: 4.2878933e+11 | E58: 1.6814236
A59: FGLMC | B59: 36220 | C59: 95673 | D59: 4.35071e+11 | E59: 1.6622171
A60: FGLMC | B60: 36251 | C60: 96985 | D60: 4.4584451e+11 | E60: 1.638805
A61: FGLMC | B61: 36281 | C61: 98319 | D61: 4.5486137e+11 | E61: 1.6204742
A62: FGLMC | B62: 36312 | C62: 99372 | D62: 4.6259681e+11 | E62: 1.6113701
A63: FGLMC | B63: 36342 | C63: 100290 | D63: 469015767726 | E63: 1.5956072
A64: FGLMC | B64: 36373 | C64: 101048 | D64: 4.744466e+11 | E64: 1.5820696
A65: FGLMC | B65: 36404 | C65: 101791 | D65: 4.7895318e+11 | E65: 1.564237
A66: FGLMC | B66: 36434 | C66: 102667 | D66: 4.8368493e+11 | E66: 1.6096727
A67: FGLMC | B67: 36465 | C67: 103263 | D67: 4.8611327e+11 | E67: 1.630289
A68: FGLMC | B68: 36495 | C68: 103797 | D68: 4.889775e+11 | E68: 1.6746326
... A505: FGU6 | B505: 42644 | C505: 4021 | D505: 2.8689194e+10 | E505: 7.1507452

Sheet Sheet4
B1: FGu9 | E1: FNCR | F1: FGU9
A2: 41091 | B2: 0.54942937 | D2: 41091 | E2: 0.64001894 | F2: 0.54942937
A3: 41122 | B3: 0.57992543 | D3: 41122 | E3: 0.6380606 | F3: 0.57992543
A4: 41153 | B4: 0.85425081 | D4: 41153 | E4: 0.77067869 | F4: 0.85425081
A5: 41183 | B5: 2.5717149 | D5: 41183 | E5: 1.121 | F5: 2.5717149
A6: 41214 | B6: 5.017555 | D6: 41214 | E6: 2.1766444 | F6: 5.017555
A7: 41244 | B7: 6.4709299 | D7: 41244 | E7: 2.8534115 | F7: 6.4709299
A8: 41275 | B8: 8.2520511 | D8: 41275 | E8: 3.9268988 | F8: 8.2520511
A9: 41306 | B9: 9.9797961 | D9: 41306 | E9: 4.8780756 | F9: 9.9797961
A10: 41334 | B10: 11.376138 | D10: 41334 | E10: 6.4258643 | F10: 11.376138
A11: 41365 | B11: 11.525803 | D11: 41365 | E11: 7.1453053 | F11: 11.525803
A12: 41395 | B12: 11.437916 | D12: 41395 | E12: 8.2532155 | F12: 11.437916
A13: 41426 | B13: 11.616415 | D13: 41426 | E13: 9.1766103 | F13: 11.616415
... A53: 42644 | B53: 14.882005 | D53: 42644 | E53: 16.64344 | F53: 14.882005

Sheet Sheet5
A1: marketTicker | B1: asOf | C1: count(1) | D1: sum(p.schamBalance) | E1: wavg_fico | H1: marketTicker | I1: asOf | J1: count(1) | K1: sum(p.schamBalance) | L1: wavg_fico | P1: CR | Q1: U9
A2: FGU9 | B2: 41091 | C2: 127 | D2: 6.5991265e+09 | E2: 737.68154 | H2: FNCR | I2: 41091 | J2: 91 | K2: 5.5556952e+09 | L2: 738.64511 | O2: 41091 | P2: 738.64511 | Q2: 737.68154
A3: FGU9 | B3: 41122 | C3: 218 | D3: 8.7994582e+09 | E3: 737.87358 | H3: FNCR | I3: 41122 | J3: 156 | K3: 8.7543983e+09 | L3: 737.50319 | O3: 41122 | P3: 737.50319 | Q3: 737.87358
A4: FGU9 | B4: 41153 | C4: 315 | D4: 1.0777885e+10 | E4: 737.37025 | H4: FNCR | I4: 41153 | J4: 210 | K4: 1.2053254e+10 | L4: 736.59922 | O4: 41153 | P4: 736.59922 | Q4: 737.37025
A5: FGU9 | B5: 41183 | C5: 415 | D5: 12488997687 | E5: 736.99561 | H5: FNCR | I5: 41183 | J5: 281 | K5: 1.5145163e+10 | L5: 735.76492 | O5: 41183 | P5: 735.76492 | Q5: 736.99561
A6: FGU9 | B6: 41214 | C6: 509 | D6: 1.3991619e+10 | E6: 737.02963 | H6: FNCR | I6: 41214 | J6: 339 | K6: 1.7141507e+10 | L6: 734.9039 | O6: 41214 | P6: 734.9039 | Q6: 737.02963
A7: FGU9 | B7: 41244 | C7: 623 | D7: 1.5791782e+10 | E7: 736.54953 | H7: FNCR | I7: 41244 | J7: 427 | K7: 2.0228877e+10 | L7: 734.13776 | O7: 41244 | P7: 734.13776 | Q7: 736.54953
A8: FGU9 | B8: 41275 | C8: 707 | D8: 1.6754712e+10 | E8: 736.33573 | H8: FNCR | I8: 41275 | J8: 493 | K8: 2.2634124e+10 | L8: 732.99664 | O8: 41275 | P8: 732.99664 | Q8: 736.33573
A9: FGU9 | B9: 41306 | C9: 803 | D9: 1.7947136e+10 | E9: 735.94693 | H9: FNCR | I9: 41306 | J9: 572 | K9: 2.571078e+10 | L9: 731.48458 | O9: 41306 | P9: 731.48458 | Q9: 735.94693
A10: FGU9 | B10: 41334 | C10: 924 | D10: 1.9179633e+10 | E10: 735.4103 | H10: FNCR | I10: 41334 | J10: 639 | K10: 2.7919269e+10 | L10: 730.75064 | O10: 41334 | P10: 730.75064 | Q10: 735.4103
A11: FGU9 | B11: 41365 | C11: 1042 | D11: 2.0590651e+10 | E11: 734.81823 | H11: FNCR | I11: 41365 | J11: 704 | K11: 3.0041763e+10 | L11: 729.86945 | O11: 41365 | P11: 729.86945 | Q11: 734.81823
A12: FGU9 | B12: 41395 | C12: 1149 | D12: 2.1763932e+10 | E12: 734.36647 | H12: FNCR | I12: 41395 | J12: 760 | K12: 3.2087573e+10 | L12: 729.23726 | O12: 41395 | P12: 729.23726 | Q12: 734.36647
A13: FGU9 | B13: 41426 | C13: 1253 | D13: 2.2743333e+10 | E13: 733.84557 | H13: FNCR | I13: 41426 | J13: 806 | K13: 3.3554082e+10 | L13: 728.73357 | O13: 41426 | P13: 728.73357 | Q13: 733.84557
... A53: FGU9 | B53: 42644 | C53: 2450 | D53: 2.1624654e+10 | E53: 728.71901 | H53: FNCR | I53: 42644 | J53: 1390 | K53: 3.3686514e+10 | L53: 722.82862 | O53: 42644 | P53: 722.82862 | Q53: 728.71901

Sheet Sheet6
A1: marketTicker | B1: asOf | C1: count(1) | D1: sum(p.schamBalance) | E1: cltv | H1: marketTicker | I1: asOf | J1: count(1) | K1: sum(p.schamBalance) | L1: cltv | P1: CR | Q1: U9
A2: FGU9 | B2: 41091 | C2: 127 | D2: 6.5991265e+09 | E2: 153.55531 | H2: FNCR | I2: 41091 | J2: 91 | K2: 5.5556952e+09 | L2: 153.18207 | O2: 41091 | P2: =L2 -> 153.18207 | Q2: =E2 -> 153.55531
A3: FGU9 | B3: 41122 | C3: 218 | D3: 8.7994582e+09 | E3: 152.51267 | H3: FNCR | I3: 41122 | J3: 156 | K3: 8.7543983e+09 | L3: 153.01738 | O3: 41122 | P3: =L3 -> 153.01738 | Q3: =E3 -> 152.51267
A4: FGU9 | B4: 41153 | C4: 315 | D4: 1.0777885e+10 | E4: 151.49346 | H4: FNCR | I4: 41153 | J4: 210 | K4: 1.2053254e+10 | L4: 152.97002 | O4: 41153 | P4: =L4 -> 152.97002 | Q4: =E4 -> 151.49346
A5: FGU9 | B5: 41183 | C5: 415 | D5: 12488997687 | E5: 150.93178 | H5: FNCR | I5: 41183 | J5: 281 | K5: 1.5145163e+10 | L5: 152.8948 | O5: 41183 | P5: =L5 -> 152.8948 | Q5: =E5 -> 150.93178
A6: FGU9 | B6: 41214 | C6: 509 | D6: 1.3991619e+10 | E6: 150.24051 | H6: FNCR | I6: 41214 | J6: 339 | K6: 1.7141507e+10 | L6: 152.49358 | O6: 41214 | P6: =L6 -> 152.49358 | Q6: =E6 -> 150.24051
A7: FGU9 | B7: 41244 | C7: 623 | D7: 1.5791782e+10 | E7: 149.65815 | H7: FNCR | I7: 41244 | J7: 427 | K7: 2.0228877e+10 | L7: 152.17059 | O7: 41244 | P7: =L7 -> 152.17059 | Q7: =E7 -> 149.65815
A8: FGU9 | B8: 41275 | C8: 707 | D8: 1.6754712e+10 | E8: 148.25249 | H8: FNCR | I8: 41275 | J8: 493 | K8: 2.2634124e+10 | L8: 151.25458 | O8: 41275 | P8: =L8 -> 151.25458 | Q8: =E8 -> 148.25249
A9: FGU9 | B9: 41306 | C9: 803 | D9: 1.7947136e+10 | E9: 146.95443 | H9: FNCR | I9: 41306 | J9: 572 | K9: 2.571078e+10 | L9: 150.42993 | O9: 41306 | P9: =L9 -> 150.42993 | Q9: =E9 -> 146.95443
A10: FGU9 | B10: 41334 | C10: 924 | D10: 1.9179633e+10 | E10: 145.82837 | H10: FNCR | I10: 41334 | J10: 639 | K10: 2.7919269e+10 | L10: 149.36004 | O10: 41334 | P10: =L10 -> 149.36004 | Q10: =E10 -> 145.82837
A11: FGU9 | B11: 41365 | C11: 1042 | D11: 2.0590651e+10 | E11: 143.14549 | H11: FNCR | I11: 41365 | J11: 704 | K11: 3.0041763e+10 | L11: 146.64197 | O11: 41365 | P11: =L11 -> 146.64197 | Q11: =E11 -> 143.14549
A12: FGU9 | B12: 41395 | C12: 1149 | D12: 2.1763932e+10 | E12: 140.66188 | H12: FNCR | I12: 41395 | J12: 760 | K12: 3.2087573e+10 | L12: 144.12414 | O12: 41395 | P12: =L12 -> 144.12414 | Q12: =E12 -> 140.66188
A13: FGU9 | B13: 41426 | C13: 1253 | D13: 2.2743333e+10 | E13: 138.29251 | H13: FNCR | I13: 41426 | J13: 806 | K13: 3.3554082e+10 | L13: 141.64054 | O13: 41426 | P13: =L13 -> 141.64054 | Q13: =E13 -> 138.29251
... A53: FGU9 | B53: 42644 | C53: 2450 | D53: 2.1624654e+10 | E53: 107.96582 | H53: FNCR | I53: 42644 | J53: 1390 | K53: 3.3686514e+10 | L53: 109.91183 | O53: 42644 | P53: =L53 -> 109.91183 | Q53: =E53 -> 107.96582

Sheet Sheet7
A1: marketTicker | C1: count(1) | D1: sum(p.schamBalance) | E1: pct_DELQ | F1: =M1 -> est_pct_DELQ | I1: marketTicker | J1: asOf | K1: count(1) | L1: sum(p.schamBalance) | M1: est_pct_DELQ
A2: FGU9 | B2: 41091 | C2: 43 | D2: 2.4477519e+09 | E2: 0 | F2: =M2 -> 0.5665142 | I2: FGU9 | J2: 41091 | K2: 43 | L2: 2.4477519e+09 | M2: 0.5665142
A3: FGU9 | B3: 41122 | C3: 51 | D3: 1.4546401e+09 | E3: 0.075549308 | F3: =M3 -> 0.80462923 | I3: FGU9 | J3: 41122 | K3: 51 | L3: 1.4546401e+09 | M3: 0.80462923
A4: FGU9 | B4: 41153 | C4: 92 | D4: 3.2304137e+09 | E4: 0.43301591 | F4: =M4 -> 0.66656192 | I4: FGU9 | J4: 41153 | K4: 92 | L4: 3.2304137e+09 | M4: 0.66656192
A5: FGU9 | B5: 41183 | C5: 104 | D5: 1.9374275e+09 | E5: 0.40970105 | F5: =M5 -> 0.67829768 | I5: FGU9 | J5: 41183 | K5: 104 | L5: 1.9374275e+09 | M5: 0.67829768
A6: FGU9 | B6: 41214 | C6: 117 | D6: 2.2394548e+09 | E6: 0.42960628 | F6: =M6 -> 1.6300853 | I6: FGU9 | J6: 41214 | K6: 117 | L6: 2.2394548e+09 | M6: 1.6300853
A7: FGU9 | B7: 41244 | C7: 156 | D7: 2.8947731e+09 | E7: 0.37819341 | F7: =M7 -> 2.1476901 | I7: FGU9 | J7: 41244 | K7: 156 | L7: 2.8947731e+09 | M7: 2.1476901
A8: FGU9 | B8: 41275 | C8: 190 | D8: 3.3944596e+09 | E8: 0.46471961 | F8: =M8 -> 3.0345349 | I8: FGU9 | J8: 41275 | K8: 190 | L8: 3.3944596e+09 | M8: 3.0345349
A9: FGU9 | B9: 41306 | C9: 281 | D9: 4.6345708e+09 | E9: 0.64457549 | F9: =M9 -> 3.9344482 | I9: FGU9 | J9: 41306 | K9: 281 | L9: 4.6345708e+09 | M9: 3.9344482
A10: FGU9 | B10: 41334 | C10: 463 | D10: 7.3904975e+09 | E10: 0.59617198 | F10: =M10 -> 6.0049269 | I10: FGU9 | J10: 41334 | K10: 463 | L10: 7.3904975e+09 | M10: 6.0049269
A11: FGU9 | B11: 41365 | C11: 582 | D11: 9.8771479e+09 | E11: 0.77901802 | F11: =M11 -> 7.3264827 | I11: FGU9 | J11: 41365 | K11: 582 | L11: 9.8771479e+09 | M11: 7.3264827
A12: FGU9 | B12: 41395 | C12: 637 | D12: 9.623377e+09 | E12: 0.54961221 | F12: =M12 -> 6.5447538 | I12: FGU9 | J12: 41395 | K12: 637 | L12: 9.623377e+09 | M12: 6.5447538
A13: FGU9 | B13: 41426 | C13: 799 | D13: 1.359955e+10 | E13: 0.71241461 | F13: =M13 -> 9.0907853 | I13: FGU9 | J13: 41426 | K13: 799 | L13: 1.359955e+10 | M13: 9.0907853
... A53: FGU9 | B53: 42644 | C53: 102 | D53: 4.7699832e+08 | E53: 0.48762813 | F53: =M53 -> 11.159582 | I53: FGU9 | J53: 42644 | K53: 102 | L53: 4.7699832e+08 | M53: 11.159582

Sheet Sheet8
A1: asOf | B1: loan_count | C1: Pct_CURRENT | D1: Credit Loan Pct_DQ | E1: Pct_DQ30 | F1: Pct_DQ60 | G1: Pct_DELQ90p | H1: FHL Pool Dist. Pct_DQ | I1: 90Plus | L1: asOf | M1: count(1) | N1: sum(p.schamBalance) | O1: pct_DELQ30p
A2: 36220 | B2: 49622 | C2: 99.730081 | D2: =100-C2 -> 0.2699186 | E2: 0.054522918 | F2: 0 | G2: 0 | H2: =O59 -> 0 | I2: =D2-E2-F2-G2 -> 0.21539568 | L2: 34366 | M2: 47564 | N2: 1.7936303e+11
A3: 36251 | B3: 156989 | C3: 99.422192 | D3: =100-C3 -> 0.57780832 | E3: 0.33074534 | F3: 0.0019214528 | G3: 0 | H3: =O60 -> 0 | I3: =D3-E3-F3-G3 -> 0.24514153 | L3: 34394 | M3: 48770 | N3: 1.8267643e+11
A4: 36281 | B4: 298188 | C4: 99.287483 | D4: =100-C4 -> 0.71251659 | E4: 0.40651162 | F4: 0.017657331 | G4: 0 | H4: =O61 -> 0 | I4: =D4-E4-F4-G4 -> 0.28834764 | L4: 34425 | M4: 50054 | N4: 1.8717384e+11
A5: 36312 | B5: 430571 | C5: 99.152591 | D5: =100-C5 -> 0.84740946 | E5: 0.52094367 | F5: 0.020026874 | G5: 0.0037167533 | H5: =O62 -> 0 | I5: =D5-E5-F5-G5 -> 0.30272216 | L5: 34516 | M5: 53319 | N5: 1.9825763e+11
A6: 36342 | B6: 554185 | C6: 99.171645 | D6: =100-C6 -> 0.82835452 | E6: 0.50163999 | F6: 0.026990694 | G6: 0.0065241002 | H6: =O63 -> 0 | I6: =D6-E6-F6-G6 -> 0.29319973 | L6: 34547 | M6: 54110 | N6: 2.0067919e+11
A7: 36373 | B7: 619932 | C7: 99.102903 | D7: =100-C7 -> 0.897097 | E7: 0.5593499 | F7: 0.03374177 | G7: 0.010117682 | H7: =O64 -> 0 | I7: =D7-E7-F7-G7 -> 0.29388764 | L7: 34578 | M7: 54835 | N7: 2.0294126e+11
A8: 36404 | B8: 718229 | C8: 99.108809 | D8: =100-C8 -> 0.89119134 | E8: 0.5815867 | F8: 0.039082579 | G8: 0.014809572 | H8: =O65 -> 0 | I8: =D8-E8-F8-G8 -> 0.25571249 | L8: 34608 | M8: 55530 | N8: 2.0522667e+11
A9: 36434 | B9: 787242 | C9: 98.958198 | D9: =100-C9 -> 1.0418021 | E9: 0.720794 | F9: 0.048711252 | G9: 0.019356958 | H9: =O66 -> 0 | I9: =D9-E9-F9-G9 -> 0.25293984 | L9: 34639 | M9: 56108 | N9: 2.0697511e+11
A10: 36465 | B10: 843723 | C10: 98.806086 | D10: =100-C10 -> 1.1939137 | E10: 0.81932885 | F10: 0.071692344 | G10: 0.027622713 | H10: =O67 -> 0 | I10: =D10-E10-F10-G10 -> 0.27526981 | L10: 34669 | M10: 56529 | N10: 2.0775371e+11
A11: 36495 | B11: 891171 | C11: 98.610063 | D11: =100-C11 -> 1.3899368 | E11: 0.92327036 | F11: 0.087563878 | G11: 0.040321399 | H11: =O68 -> 0 | I11: =D11-E11-F11-G11 -> 0.33878114 | L11: 34700 | M11: 56894 | N11: 2.0840618e+11
A12: 36526 | B12: 922877 | C12: 98.818389 | D12: =100-C12 -> 1.1816106 | E12: 0.82778727 | F12: 0.087504939 | G12: 0.051492797 | H12: =O69 -> 0 | I12: =D12-E12-F12-G12 -> 0.21482559 | L12: 34731 | M12: 57294 | N12: 2.0935918e+11
A13: 36557 | B13: 996498 | C13: 98.692861 | D13: =100-C13 -> 1.3071394 | E13: 0.86383876 | F13: 0.098848942 | G13: 0.066521511 | H13: =O70 -> 0 | I13: =D13-E13-F13-G13 -> 0.27793021 | L13: 34759 | M13: 57702 | N13: 2.1044467e+11
... A200: 42248 | B200: 6755405 | C200: 96.607976 | D200: =100-C200 -> 3.3920239 | E200: 0.97861637 | F200: 0.29708455 | G200: 0.98998549 | H200: =O257 -> 1.0121178 | I200: =D200-E200-F200-G200 -> 1.1263375 | L200: 40513 | M200: 164406 | N200: 1.2120815e+12
A201: 42278 | B201: 6686986 | C201: 96.559594 | D201: =100-C201 -> 3.4404064 | E201: 1.0303396 | F201: 0.30724606 | G201: 0.98424741 | H201: =O258 -> 1.0622828 | I201: =D201-E201-F201-G201 -> 1.1185733 | L201: 40544 | M201: 164673 | N201: 1.1992573e+12 | O201: 3.0128214
A202: 42309 | B202: 6617869 | C202: 96.743116 | D202: =100-C202 -> 3.2568843 | E202: 1.0080307 | F202: 0.30206804 | G202: 0.9725461 | H202: =O259 -> 1.1008957 | I202: =D202-E202-F202-G202 -> 0.9742394 | L202: 40575 | M202: 164748 | N202: 1.1885596e+12 | O202: 2.8732592
A203: 42339 | B203: 6560388 | C203: 96.519176 | D203: =100-C203 -> 3.4808239 | E203: 1.0747304 | F203: 0.31026826 | G203: 0.96907134 | H203: =O260 -> 1.0584249 | I203: =D203-E203-F203-G203 -> 1.1267539 | L203: 40603 | M203: 165054 | N203: 1.1877261e+12 | O203: 2.8713921
L204: 40634 | M204: 165207 | N204: 1.1802217e+12 | O204: 2.8952651
L205: 40664 | M205: 165400 | N205: 1.1758834e+12 | O205: 2.3541367
L206: 40695 | M206: 165598 | N206: 1.172148e+12 | O206: 2.4356705
L207: 40725 | M207: 165825 | N207: 1.1704422e+12 | O207: 2.392553
L208: 40756 | M208: 166050 | N208: 1.1641807e+12 | O208: 2.4089953
L209: 40787 | M209: 166303 | N209: 1.1607203e+12 | O209: 2.590059
L210: 40817 | M210: 166562 | N210: 1.1556359e+12 | O210: 2.449594
L211: 40848 | M211: 166817 | N211: 1.1460205e+12 | O211: 2.456328
L212: 40878 | M212: 166959 | N212: 1.1311643e+12 | O212: 2.4778767
L213: 40909 | M213: 167030 | N213: 1.112065e+12 | O213: 2.5749063
L214: 40940 | M214: 167113 | N214: 1.1022352e+12 | O214: 2.516676
L215: 40969 | M215: 167261 | N215: 1.1003911e+12 | O215: 2.3705864
... L270: 42644 | M270: 176274 | N270: 1.1915457e+12 | O270: 0.92102612

Sheet Sheet9
A1: endStatus | B1: count(1)
A2: 1 | B2: 15667807
A3: 2 | B3: 4563581
A4: 3 | B4: 2172134
A5: 4 | B5: 1551780
A6: 5 | B6: 1270971
A7: 6 | B7: 1061099
A8: 7 | B8: 904422
A9: 8 | B9: 780453
A10: 9 | B10: 678168
A11: 10 | B11: 592768
A12: 11 | B12: 519337
A13: 12 | B13: 457346
... A139: 239 | B139: 1
A140: C | B140: 946762134
A141: REO | B141: 2377137
A142: X | B142: 15676910
A143: XX | B143: 33

Sheet Sheet10
A1: asOf | B1: loan_count | C1: Pct_CURRENT | D1: Pct_DQ30 | E1: Pct_DQ60 | F1: Pct_DELQ90p | G1: FHL Pool Dist. Pct_DQ | H1: Credit Loan Pct_DQ | I1: Final Est
A2: 36220 | B2: 49532 | C2: 99.945359 | D2: 0.054640612 | E2: 0 | F2: 0 | G2: =Sheet8!H2 -> 0 | H2: =100-C2-F2 -> 0.054640612 | I2: 1.9123135
A3: 36251 | B3: 156624 | C3: 99.666516 | D3: 0.33155813 | E3: 0.0019261746 | F3: 0 | G3: =Sheet8!H3 -> 0 | H3: =100-C3-F3 -> 0.3334843 | I3: 1.8930168
A4: 36281 | B4: 297390 | C4: 99.574604 | D4: 0.40768718 | E4: 0.017708393 | F4: 0 | G4: =Sheet8!H4 -> 0 | H4: =100-C4-F4 -> 0.42539557 | I4: 1.8866777
A5: 36312 | B5: 429289 | C5: 99.454078 | D5: 0.52252768 | E5: 0.020087769 | F5: 0.0033064196 | G5: =Sheet8!H5 -> 0 | H5: =100-C5-F5 -> 0.54261544 | I5: 1.8765765
A6: 36342 | B6: 552591 | C6: 99.463627 | D6: 0.50311692 | E6: 0.02707016 | F6: 0.0061862497 | G6: =Sheet8!H6 -> 0 | H6: =100-C6-F6 -> 0.53018708 | I6: 1.8739051
A7: 36373 | B7: 618067 | C7: 99.395912 | D7: 0.56100368 | E7: 0.033841531 | F7: 0.0092430099 | G7: =Sheet8!H7 -> 0 | H7: =100-C7-F7 -> 0.59484521 | I7: 1.8694955
A8: 36404 | B8: 716282 | C8: 99.365125 | D8: 0.58309081 | E8: 0.039183654 | F8: 0.01260066 | G8: =Sheet8!H8 -> 0 | H8: =100-C8-F8 -> 0.62227446 | I8: 1.868191
A9: 36434 | B9: 785158 | C9: 99.213714 | D9: 0.72265514 | E9: 0.048837028 | F9: 0.014793626 | G9: =Sheet8!H9 -> 0 | H9: =100-C9-F9 -> 0.77149216 | I9: 1.8708576
A10: 36465 | B10: 841299 | C10: 99.08498 | D10: 0.82164153 | E10: 0.071894706 | F10: 0.021483324 | G10: =Sheet8!H10 -> 0 | H10: =100-C10-F10 -> 0.89353623 | I10: 1.8859878
A11: 36495 | B11: 888100 | C11: 98.95473 | D11: 0.92649742 | E11: 0.087869935 | F11: 0.030903008 | G11: =Sheet8!H11 -> 0 | H11: =100-C11-F11 -> 1.0143674 | I11: 1.9029153
A12: 36526 | B12: 920684 | C12: 99.043966 | D12: 0.82967689 | E12: 0.087704689 | F12: 0.03865277 | G12: =Sheet8!H12 -> 0 | H12: =100-C12-F12 -> 0.91738158 | I12: 1.9070484
A13: 36557 | B13: 993485 | C13: 98.986744 | D13: 0.86641107 | E13: 0.099143291 | F13: 0.047701291 | G13: =Sheet8!H13 -> 0 | H13: =100-C13-F13 -> 0.96555436 | I13: 1.9205306
... A203: 42339 | B203: 6432505 | C203: 98.370788 | D203: 1.0953479 | E203: 0.31622041 | F203: 0.21764372 | G203: =Sheet8!H203 -> 1.0584249 | H203: =100-C203-F203 -> 1.4115683 | I203: 1.3805288
I204: 1.5422289
I205: 1.4065676
I206: 1.2183144
I207: 1.5262257
I208: 1.4977465
I209: 1.4712136
I210: 1.4719451
I211: 1.4750533
I212: 1.4740019
I213: 1.4712161

Sheet Sheet11
A1: marketTicker | B1: asOf | C1: count(1) | D1: sum(p.schamBalance) | E1: wavg_est_pct_DELQ | I1: marketTicker | J1: FNCL
A2: FNCL | B2: 34366 | C2: 126636 | D2: 2.7849025e+11 | E2: 1.286306
A3: FNCL | B3: 34394 | C3: 128266 | D3: 2.8205083e+11 | E3: 1.2716448 | I3: Row Labels | J3: Average of wavg_est_pct_DELQ
A4: FNCL | B4: 34425 | C4: 129601 | D4: 2.838742e+11 | E4: 1.2733665 | I4: 34366 | J4: 1.286306
A5: FNCL | B5: 34455 | C5: 130768 | D5: 2.847529e+11 | E5: 1.2679915 | I5: 34394 | J5: 1.2716448
A6: FNCL | B6: 34486 | C6: 131996 | D6: 2.8712206e+11 | E6: 1.2682805 | I6: 34425 | J6: 1.2733665
A7: FNCL | B7: 34516 | C7: 133140 | D7: 2.8891975e+11 | E7: 1.2794984 | I7: 34455 | J7: 1.2679915
A8: FNCL | B8: 34547 | C8: 134153 | D8: 2.9064065e+11 | E8: 1.282509 | I8: 34486 | J8: 1.2682805
A9: FNCL | B9: 34578 | C9: 135077 | D9: 2.9202625e+11 | E9: 1.2902224 | I9: 34516 | J9: 1.2794984
A10: FNCL | B10: 34608 | C10: 135888 | D10: 2.9339599e+11 | E10: 1.3026677 | I10: 34547 | J10: 1.282509
A11: FNCL | B11: 34639 | C11: 136567 | D11: 2.94792e+11 | E11: 1.3242652 | I11: 34578 | J11: 1.2902224
A12: FNCL | B12: 34669 | C12: 137384 | D12: 2.9702273e+11 | E12: 1.3281879 | I12: 34608 | J12: 1.3026677
A13: FNCL | B13: 34700 | C13: 138175 | D13: 2.9953479e+11 | E13: 1.3342847 | I13: 34639 | J13: 1.3242652
A14: FNCL | B14: 34731 | C14: 138749 | D14: 3.0057806e+11 | E14: 1.3487485 | I14: 34669 | J14: 1.3281879
A15: FNCL | B15: 34759 | C15: 139252 | D15: 3.0151552e+11 | E15: 1.3600014 | I15: 34700 | J15: 1.3342847
... A276: FNCL | B276: 40817 | C276: 282590 | D276: 1.7300621e+12 | E276: 1.7601501 | I276: 42644 | J276: 0.97050398
A277: FNCQ30 | B277: 40817 | C277: 461 | D277: 7.9908166e+09 | E277: 0.75882348 | I277: Grand Total | J277: 1.409234
A278: FNCK | B278: 40848 | C278: 1471 | D278: 6.1528555e+10 | E278: 0.35186889
A279: FNCL | B279: 40848 | C279: 283012 | D279: 1.7161114e+12 | E279: 1.7905626
A280: FNCQ30 | B280: 40848 | C280: 487 | D280: 8.5171652e+09 | E280: 0.88230223
A281: FNCK | B281: 40878 | C281: 1523 | D281: 6.343284e+10 | E281: 0.33375708
A282: FNCL | B282: 40878 | C282: 283516 | D282: 1.704192e+12 | E282: 1.7659988
A283: FNCQ30 | B283: 40878 | C283: 514 | D283: 9.0740215e+09 | E283: 0.94963849
A284: FNCK | B284: 40909 | C284: 1561 | D284: 6.3431287e+10 | E284: 0.35943791
A285: FNCL | B285: 40909 | C285: 284179 | D285: 1.7047182e+12 | E285: 1.7377773
A286: FNCQ30 | B286: 40909 | C286: 537 | D286: 9.4003226e+09 | E286: 0.76887676
A287: FNCK | B287: 40940 | C287: 1581 | D287: 6.3028905e+10 | E287: 0.31740517
A288: FNCL | B288: 40940 | C288: 284757 | D288: 1.6958104e+12 | E288: 1.7549117
A289: FNCQ30 | B289: 40940 | C289: 563 | D289: 1.0323436e+10 | E289: 0.67759528
... A509: FNCQ30 | B509: 42644 | C509: 2155 | D509: 3.8990715e+10 | E509: 2.4605833

Sheet Sheet12
A1: asof | B1: marketTicker | C1: wavg_pct_dq | D1: wavg_pct_dq | E1: wavg_pct_dq
A2: 34366 | B2: FNCL | C2: 0 | D2: 1.223931 | E2: 1.223931
A3: 34394 | B3: FNCL | C3: 0 | D3: 1.2085666 | E3: 1.2085666
A4: 34425 | B4: FNCL | C4: 0 | D4: 1.2094406 | E4: 1.2094406
A5: 34455 | B5: FNCL | C5: 0 | D5: 1.2035318 | E5: 1.2035318
A6: 34486 | B6: FNCL | C6: 0 | D6: 1.2030177 | E6: 1.2030177
A7: 34516 | B7: FNCL | C7: 0 | D7: 1.2131021 | E7: 1.2131021
A8: 34547 | B8: FNCL | C8: 0 | D8: 1.2144602 | E8: 1.2144602
A9: 34578 | B9: FNCL | C9: 0 | D9: 1.2212414 | E9: 1.2212414
A10: 34608 | B10: FNCL | C10: 0 | D10: 1.2324575 | E10: 1.2324575
A11: 34639 | B11: FNCL | C11: 0 | D11: 1.2535275 | E11: 1.2535275
A12: 34669 | B12: FNCL | C12: 0 | D12: 1.2562336 | E12: 1.2562336
A13: 34700 | B13: FNCL | C13: 0 | D13: 1.2613355 | E13: 1.2613355
... A274: 42644 | B274: FNCL | C274: 0 | D274: 0.91991258 | E274: 0.91991543

Sheet Sheet13
A1: marketTicker | B1: asOf | C1: count(1) | D1: sum(p.schamBalance) | E1: wavg_est_pct_DELQ | I1: marketTicker | J1: FGLMC
A2: FNCL | B2: 34366 | C2: 126636 | D2: 2.7849025e+11 | E2: 1.4470822
A3: FNCL | B3: 34394 | C3: 128266 | D3: 2.8205083e+11 | E3: 1.4298345 | I3: Row Labels | J3: Sum of wavg_est_pct_DELQ
A4: FNCL | B4: 34425 | C4: 129601 | D4: 2.838742e+11 | E4: 1.4324728 | I4: 34366 | J4: 0.80361498
A5: FNCL | B5: 34455 | C5: 130768 | D5: 2.847529e+11 | E5: 1.426759 | I5: 34394 | J5: 0.78380996
A6: FNCL | B6: 34486 | C6: 131996 | D6: 2.8712206e+11 | E6: 1.4277735 | I6: 34425 | J6: 0.7774142
A7: FNCL | B7: 34516 | C7: 133140 | D7: 2.8891975e+11 | E7: 1.4432029 | I7: 34516 | J7: 0.81117871
A8: FNCL | B8: 34547 | C8: 134153 | D8: 2.9064065e+11 | E8: 1.4475193 | I8: 34547 | J8: 0.83311088
A9: FNCL | B9: 34578 | C9: 135077 | D9: 2.9202625e+11 | E9: 1.4580492 | I9: 34578 | J9: 0.8587133
A10: FNCL | B10: 34608 | C10: 135888 | D10: 2.9339599e+11 | E10: 1.4744727 | I10: 34608 | J10: 0.89129761
A11: FNCL | B11: 34639 | C11: 136567 | D11: 2.94792e+11 | E11: 1.5053132 | I11: 34639 | J11: 0.91780418
A12: FNCL | B12: 34669 | C12: 137384 | D12: 2.9702273e+11 | E12: 1.5114035 | I12: 34669 | J12: 0.944843
A13: FNCL | B13: 34700 | C13: 138175 | D13: 2.9953479e+11 | E13: 1.5209769 | I13: 34700 | J13: 0.97786363
A14: FNCL | B14: 34731 | C14: 138749 | D14: 3.0057806e+11 | E14: 1.541844 | I14: 34731 | J14: 1.0060865
A15: FNCL | B15: 34759 | C15: 139252 | D15: 3.0151552e+11 | E15: 1.5573519 | I15: 34759 | J15: 1.0346256
... A272: FNCK | B272: 40787 | C272: 1327 | D272: 5.9412547e+10 | E272: 0.35443358 | I272: 42644 | J272: 0.91217402
A273: FNCL | B273: 40787 | C273: 281942 | D273: 1.7360003e+12 | E273: 2.3664834 | I273: Grand Total | J273: 425.55399
A274: FNCQ30 | B274: 40787 | C274: 437 | D274: 7.3938545e+09 | E274: 1.4866077
A275: FNCK | B275: 40817 | C275: 1392 | D275: 6.0879464e+10 | E275: 0.37927002
A276: FNCL | B276: 40817 | C276: 282590 | D276: 1.7300621e+12 | E276: 2.3720246
A277: FNCQ30 | B277: 40817 | C277: 461 | D277: 7.9908166e+09 | E277: 1.5209736
A278: FNCK | B278: 40848 | C278: 1471 | D278: 6.1528555e+10 | E278: 0.41576847
A279: FNCL | B279: 40848 | C279: 283012 | D279: 1.7161114e+12 | E279: 2.4312028
A280: FNCQ30 | B280: 40848 | C280: 487 | D280: 8.5171652e+09 | E280: 1.5914264
A281: FNCK | B281: 40878 | C281: 1523 | D281: 6.343284e+10 | E281: 0.3882497
A282: FNCL | B282: 40878 | C282: 283516 | D282: 1.704192e+12 | E282: 2.3949356
A283: FNCQ30 | B283: 40878 | C283: 514 | D283: 9.0740215e+09 | E283: 1.8030247
A284: FNCK | B284: 40909 | C284: 1561 | D284: 6.3431287e+10 | E284: 0.40859414
A285: FNCL | B285: 40909 | C285: 284179 | D285: 1.7047182e+12 | E285: 2.3517845
... A509: FNCQ30 | B509: 42644 | C509: 2155 | D509: 3.8990715e+10 | E509: 3.5322278

Sheet Sheet14
A1: marketTicker | B1: asOf | C1: count(1) | D1: sum(p.schamBalance) | E1: wavg_est_pct_DELQ | I1: marketTicker | J1: FNCL
A2: FNCL | B2: 34366 | C2: 126636 | D2: 2.7849025e+11 | E2: 1.6024989
A3: FNCL | B3: 34394 | C3: 128266 | D3: 2.8205083e+11 | E3: 1.5826146 | I3: Row Labels | J3: Sum of wavg_est_pct_DELQ
A4: FNCL | B4: 34425 | C4: 129601 | D4: 2.838742e+11 | E4: 1.5861307 | I4: 34366 | J4: 1.6024989
A5: FNCL | B5: 34455 | C5: 130768 | D5: 2.847529e+11 | E5: 1.579996 | I5: 34394 | J5: 1.5826146
A6: FNCL | B6: 34486 | C6: 131996 | D6: 2.8712206e+11 | E6: 1.5817748 | I6: 34425 | J6: 1.5861307
A7: FNCL | B7: 34516 | C7: 133140 | D7: 2.8891975e+11 | E7: 1.601473 | I7: 34455 | J7: 1.579996
A8: FNCL | B8: 34547 | C8: 134153 | D8: 2.9064065e+11 | E8: 1.6071468 | I8: 34486 | J8: 1.5817748
A9: FNCL | B9: 34578 | C9: 135077 | D9: 2.9202625e+11 | E9: 1.620605 | I9: 34516 | J9: 1.601473
A10: FNCL | B10: 34608 | C10: 135888 | D10: 2.9339599e+11 | E10: 1.6411552 | I10: 34547 | J10: 1.6071468
A11: FNCL | B11: 34639 | C11: 136567 | D11: 2.94792e+11 | E11: 1.6813183 | I11: 34578 | J11: 1.620605
A12: FNCL | B12: 34669 | C12: 137384 | D12: 2.9702273e+11 | E12: 1.6895392 | I12: 34608 | J12: 1.6411552
A13: FNCL | B13: 34700 | C13: 138175 | D13: 2.9953479e+11 | E13: 1.7024021 | I13: 34639 | J13: 1.6813183
A14: FNCL | B14: 34731 | C14: 138749 | D14: 3.0057806e+11 | E14: 1.7294729 | I14: 34669 | J14: 1.6895392
A15: FNCL | B15: 34759 | C15: 139252 | D15: 3.0151552e+11 | E15: 1.7490008 | I15: 34700 | J15: 1.7024021
... A276: FNCL | B276: 40817 | C276: 282590 | D276: 1.7300621e+12 | E276: 2.9793792 | I276: 42644 | J276: 1.3108734
A277: FNCQ30 | B277: 40817 | C277: 461 | D277: 7.9908166e+09 | E277: 2.2813194 | I277: Grand Total | J277: 545.62151
A278: FNCK | B278: 40848 | C278: 1471 | D278: 6.1528555e+10 | E278: 0.47618529
A279: FNCL | B279: 40848 | C279: 283012 | D279: 1.7161114e+12 | E279: 3.0668713
A280: FNCQ30 | B280: 40848 | C280: 487 | D280: 8.5171652e+09 | E280: 2.2994773
A281: FNCK | B281: 40878 | C281: 1523 | D281: 6.343284e+10 | E281: 0.44153872
A282: FNCL | B282: 40878 | C282: 283516 | D282: 1.704192e+12 | E282: 3.020493
A283: FNCQ30 | B283: 40878 | C283: 514 | D283: 9.0740215e+09 | E283: 2.6548469
A284: FNCK | B284: 40909 | C284: 1561 | D284: 6.3431287e+10 | E284: 0.45430277
A285: FNCL | B285: 40909 | C285: 284179 | D285: 1.7047182e+12 | E285: 2.9610605
A286: FNCQ30 | B286: 40909 | C286: 537 | D286: 9.4003226e+09 | E286: 2.3343366
A287: FNCK | B287: 40940 | C287: 1581 | D287: 6.3028905e+10 | E287: 0.41741412
A288: FNCL | B288: 40940 | C288: 284757 | D288: 1.6958104e+12 | E288: 2.8756494
A289: FNCQ30 | B289: 40940 | C289: 563 | D289: 1.0323436e+10 | E289: 2.083277
... A509: FNCQ30 | B509: 42644 | C509: 2155 | D509: 3.8990715e+10 | E509: 4.5994

Sheet Sheet15
A1: marketTicker | B1: asOf | C1: count(1) | D1: sum(p.schamBalance) | E1: wavg_est_pct_DELQ | I1: marketTicker | J1: FNCR | V1: marketTicker | W1: asOf | X1: count(1) | Y1: sum(p.schamBalance) | Z1: wavg_pct_DELQ | AC1: marketTicker | AD1: FGU6 | AG1: marketTicker | AH1: asOf | AI1: count(1) | AJ1: sum(p.schamBalance) | AK1: wavg_pct_DELQ | AN1: marketTicker | AO1: FGLMC
A2: FNCL | B2: 34366 | C2: 126636 | D2: 2.7849025e+11 | E2: 1.6024989 | V2: FGLMC | W2: 34366 | X2: 47564 | Y2: 1.7936303e+11 | Z2: (NULL) | AG2: FGLMC | AH2: 34366 | AI2: 47564 | AJ2: 1.7936303e+11 | AK2: 0.80361498
A3: FNCL | B3: 34394 | C3: 128266 | D3: 2.8205083e+11 | E3: 1.5826146 | I3: Row Labels | J3: Sum of wavg_est_pct_DELQ | V3: FGLMC | W3: 34394 | X3: 48770 | Y3: 1.8267643e+11 | Z3: (NULL) | AC3: Row Labels | AD3: Sum of wavg_pct_DELQ | AG3: FGLMC | AH3: 34394 | AI3: 48770 | AJ3: 1.8267643e+11 | AK3: 0.78380996 | AN3: Row Labels | AO3: Sum of wavg_pct_DELQ
A4: FNCL | B4: 34425 | C4: 129601 | D4: 2.838742e+11 | E4: 1.5861307 | I4: 41091 | J4: 0.63988217 | V4: FGLMC | W4: 34425 | X4: 50054 | Y4: 1.8717384e+11 | Z4: (NULL) | AC4: 40179 | AD4: 0 | AG4: FGLMC | AH4: 34425 | AI4: 50054 | AJ4: 1.8717384e+11 | AK4: 0.7774142 | AN4: 34366 | AO4: 0.80361498
A5: FNCL | B5: 34455 | C5: 130768 | D5: 2.847529e+11 | E5: 1.579996 | I5: 41122 | J5: 0.63758887 | V5: FGLMC | W5: 34516 | X5: 53319 | Y5: 1.9825763e+11 | Z5: (NULL) | AC5: 40210 | AD5: 0 | AG5: FGLMC | AH5: 34516 | AI5: 53319 | AJ5: 1.9825763e+11 | AK5: 0.81117871 | AN5: 34394 | AO5: 0.78380996
A6: FNCL | B6: 34486 | C6: 131996 | D6: 2.8712206e+11 | E6: 1.5817748 | I6: 41153 | J6: 0.7309202 | V6: FGLMC | W6: 34547 | X6: 54110 | Y6: 2.0067919e+11 | Z6: (NULL) | AC6: 40238 | AD6: 0 | AG6: FGLMC | AH6: 34547 | AI6: 54110 | AJ6: 2.0067919e+11 | AK6: 0.83311088 | AN6: 34425 | AO6: 0.7774142
A7: FNCL | B7: 34516 | C7: 133140 | D7: 2.8891975e+11 | E7: 1.601473 | I7: 41183 | J7: 0.99545238 | V7: FGLMC | W7: 34578 | X7: 54835 | Y7: 2.0294126e+11 | Z7: (NULL) | AC7: 40269 | AD7: 0 | AG7: FGLMC | AH7: 34578 | AI7: 54835 | AJ7: 2.0294126e+11 | AK7: 0.8587133 | AN7: 34516 | AO7: 0.81117871
A8: FNCL | B8: 34547 | C8: 134153 | D8: 2.9064065e+11 | E8: 1.6071468 | I8: 41214 | J8: 1.7676815 | V8: FGLMC | W8: 34608 | X8: 55530 | Y8: 2.0522667e+11 | Z8: (NULL) | AC8: 40299 | AD8: 0 | AG8: FGLMC | AH8: 34608 | AI8: 55530 | AJ8: 2.0522667e+11 | AK8: 0.89129761 | AN8: 34547 | AO8: 0.83311088
A9: FNCL | B9: 34578 | C9: 135077 | D9: 2.9202625e+11 | E9: 1.620605 | I9: 41244 | J9: 2.3296503 | V9: FGLMC | W9: 34639 | X9: 56108 | Y9: 2.0697511e+11 | Z9: (NULL) | AC9: 40330 | AD9: 0 | AG9: FGLMC | AH9: 34639 | AI9: 56108 | AJ9: 2.0697511e+11 | AK9: 0.91780418 | AN9: 34578 | AO9: 0.8587133
A10: FNCL | B10: 34608 | C10: 135888 | D10: 2.9339599e+11 | E10: 1.6411552 | I10: 41275 | J10: 3.1118165 | V10: FGLMC | W10: 34669 | X10: 56529 | Y10: 2.0775371e+11 | Z10: (NULL) | AC10: 40360 | AD10: 0 | AG10: FGLMC | AH10: 34669 | AI10: 56529 | AJ10: 2.0775371e+11 | AK10: 0.944843 | AN10: 34608 | AO10: 0.89129761
A11: FNCL | B11: 34639 | C11: 136567 | D11: 2.94792e+11 | E11: 1.6813183 | I11: 41306 | J11: 3.817642 | V11: FGLMC | W11: 34700 | X11: 56894 | Y11: 2.0840618e+11 | Z11: (NULL) | AC11: 40391 | AD11: 0 | AG11: FGLMC | AH11: 34700 | AI11: 56894 | AJ11: 2.0840618e+11 | AK11: 0.97786363 | AN11: 34639 | AO11: 0.91780418
A12: FNCL | B12: 34669 | C12: 137384 | D12: 2.9702273e+11 | E12: 1.6895392 | I12: 41334 | J12: 4.739229 | V12: FGLMC | W12: 34731 | X12: 57294 | Y12: 2.0935918e+11 | Z12: (NULL) | AC12: 40422 | AD12: 0 | AG12: FGLMC | AH12: 34731 | AI12: 57294 | AJ12: 2.0935918e+11 | AK12: 1.0060865 | AN12: 34669 | AO12: 0.944843
A13: FNCL | B13: 34700 | C13: 138175 | D13: 2.9953479e+11 | E13: 1.7024021 | I13: 41365 | J13: 5.0093207 | V13: FGLMC | W13: 34759 | X13: 57702 | Y13: 2.1044467e+11 | Z13: (NULL) | AC13: 40452 | AD13: 0 | AG13: FGLMC | AH13: 34759 | AI13: 57702 | AJ13: 2.1044467e+11 | AK13: 1.0346256 | AN13: 34700 | AO13: 0.97786363
A14: FNCL | B14: 34731 | C14: 138749 | D14: 3.0057806e+11 | E14: 1.7294729 | I14: 41395 | J14: 5.6087351 | V14: FGLMC | W14: 34790 | X14: 58144 | Y14: 2.120786e+11 | Z14: (NULL) | AC14: 40483 | AD14: 0 | AG14: FGLMC | AH14: 34790 | AI14: 58144 | AJ14: 2.120786e+11 | AK14: 1.0563913 | AN14: 34731 | AO14: 1.0060865
A15: FNCL | B15: 34759 | C15: 139252 | D15: 3.0151552e+11 | E15: 1.7490008 | I15: 41426 | J15: 6.009455 | V15: FGLMC | W15: 34820 | X15: 58699 | Y15: 2.1408617e+11 | Z15: (NULL) | AC15: 40513 | AD15: 0 | AG15: FGLMC | AH15: 34820 | AI15: 58699 | AJ15: 2.1408617e+11 | AK15: 1.0806903 | AN15: 34759 | AO15: 1.0346256
... A55: FNCL | B55: 35977 | C55: 173773 | D55: 4.6333752e+11 | E55: 2.1649251 | I55: 42644 | J55: 8.0720116 | V55: FGLMC | W55: 36100 | X55: 91404 | Y55: 4.0547723e+11 | Z55: (NULL) | AC55: 41730 | AD55: 1.3749409 | AG55: FGLMC | AH55: 36100 | AI55: 91404 | AJ55: 4.0547723e+11 | AK55: 1.4495447 | AN55: 36039 | AO55: 1.4743324
A56: FNCL | B56: 36008 | C56: 174901 | D56: 4.7396393e+11 | E56: 2.1339763 | I56: Grand Total | J56: 386.15881 | V56: FGLMC | W56: 36130 | X56: 92421 | Y56: 4.1598787e+11 | Z56: (NULL) | AC56: 41760 | AD56: 1.1629516 | AG56: FGLMC | AH56: 36130 | AI56: 92421 | AJ56: 4.1598787e+11 | AK56: 1.420419 | AN56: 36069 | AO56: 1.4678452
A57: FNCL | B57: 36039 | C57: 175971 | D57: 482637195788 | E57: 2.1101698 | V57: FGLMC | W57: 36161 | X57: 93582 | Y57: 4.2302971e+11 | Z57: (NULL) | AC57: 41791 | AD57: 1.2056711 | AG57: FGLMC | AH57: 36161 | AI57: 93582 | AJ57: 4.2302971e+11 | AK57: 1.402162 | AN57: 36100 | AO57: 1.4495447
A58: FNCL | B58: 36069 | C58: 177221 | D58: 4.9275968e+11 | E58: 2.081031 | V58: FGLMC | W58: 36192 | X58: 94621 | Y58: 4.2878933e+11 | Z58: (NULL) | AC58: 41821 | AD58: 1.2512759 | AG58: FGLMC | AH58: 36192 | AI58: 94621 | AJ58: 4.2878933e+11 | AK58: 1.3855032 | AN58: 36130 | AO58: 1.420419
A59: FNCL | B59: 36100 | C59: 178640 | D59: 5.0221163e+11 | E59: 2.0577436 | V59: FGLMC | W59: 36220 | X59: 95673 | Y59: 4.35071e+11 | Z59: (NULL) | AC59: 41852 | AD59: 1.3748903 | AG59: FGLMC | AH59: 36220 | AI59: 95673 | AJ59: 4.35071e+11 | AK59: 1.3702198 | AN59: 36161 | AO59: 1.402162
A60: FNCL | B60: 36130 | C60: 179937 | D60: 5.0886082e+11 | E60: 2.0229252 | V60: FGLMC | W60: 36251 | X60: 96985 | Y60: 4.4584451e+11 | Z60: (NULL) | AC60: 41883 | AD60: 1.3725435 | AG60: FGLMC | AH60: 36251 | AI60: 96985 | AJ60: 4.4584451e+11 | AK60: 1.351192 | AN60: 36192 | AO60: 1.3855032
A61: FNCL | B61: 36161 | C61: 181535 | D61: 5.191816e+11 | E61: 1.9721468 | V61: FGLMC | W61: 36281 | X61: 98319 | Y61: 4.5486137e+11 | Z61: (NULL) | AC61: 41913 | AD61: 1.5156709 | AG61: FGLMC | AH61: 36281 | AI61: 98319 | AJ61: 4.5486137e+11 | AK61: 1.3367837 | AN61: 36220 | AO61: 1.3702198
A62: FNCL | B62: 36192 | C62: 183021 | D62: 5.2926655e+11 | E62: 1.9330398 | V62: FGLMC | W62: 36312 | X62: 99372 | Y62: 4.6259681e+11 | Z62: (NULL) | AC62: 41944 | AD62: 1.4726434 | AG62: FGLMC | AH62: 36312 | AI62: 99372 | AJ62: 4.6259681e+11 | AK62: 1.3323314 | AN62: 36251 | AO62: 1.351192
A63: FNCL | B63: 36220 | C63: 184355 | D63: 5.4075554e+11 | E63: 1.9123135 | V63: FGLMC | W63: 36342 | X63: 100290 | Y63: 469015767726 | Z63: (NULL) | AC63: 41974 | AD63: 1.387377 | AG63: FGLMC | AH63: 36342 | AI63: 100290 | AJ63: 469015767726 | AK63: 1.3183938 | AN63: 36281 | AO63: 1.3367837
A64: FNCL | B64: 36251 | C64: 185605 | D64: 5.4975047e+11 | E64: 1.8930168 | V64: FGLMC | W64: 36373 | X64: 101048 | Y64: 4.744466e+11 | Z64: (NULL) | AC64: 42005 | AD64: 1.7261371 | AG64: FGLMC | AH64: 36373 | AI64: 101048 | AJ64: 4.744466e+11 | AK64: 1.306993 | AN64: 36312 | AO64: 1.3323314
A65: FNCL | B65: 36281 | C65: 186717 | D65: 5.5650618e+11 | E65: 1.8866777 | V65: FGLMC | W65: 36404 | X65: 101791 | Y65: 4.7895318e+11 | Z65: (NULL) | AC65: 42036 | AD65: 1.4925348 | AG65: FGLMC | AH65: 36404 | AI65: 101791 | AJ65: 4.7895318e+11 | AK65: 1.2896148 | AN65: 36342 | AO65: 1.3183938
A66: FNCL | B66: 36312 | C66: 187662 | D66: 563458838273 | E66: 1.8765765 | V66: FGLMC | W66: 36434 | X66: 102667 | Y66: 4.8368493e+11 | Z66: (NULL) | AC66: 42064 | AD66: 1.736817 | AG66: FGLMC | AH66: 36434 | AI66: 102667 | AJ66: 4.8368493e+11 | AK66: 1.3319561 | AN66: 36373 | AO66: 1.306993
A67: FNCL | B67: 36342 | C67: 188811 | D67: 5.7220461e+11 | E67: 1.8739051 | V67: FGLMC | W67: 36465 | X67: 103263 | Y67: 4.8611327e+11 | Z67: (NULL) | AC67: 42095 | AD67: 1.5938871 | AG67: FGLMC | AH67: 36465 | AI67: 103263 | AJ67: 4.8611327e+11 | AK67: 1.3493823 | AN67: 36404 | AO67: 1.2896148
A68: FNCL | B68: 36373 | C68: 189841 | D68: 5.7929147e+11 | E68: 1.8694955 | V68: FGLMC | W68: 36495 | X68: 103797 | Y68: 4.889775e+11 | Z68: (NULL) | AC68: 42125 | AD68: 1.2770979 | AG68: FGLMC | AH68: 36495 | AI68: 103797 | AJ68: 4.889775e+11 | AK68: 1.3878861 | AN68: 36434 | AO68: 1.3319561
... A85: FNCL | B85: 36892 | C85: 207893 | D85: 7.0010634e+11 | E85: 1.8179976 | V85: FGLMC | W85: 37012 | X85: 117279 | Y85: 5.8314536e+11 | Z85: (NULL) | AC85: 42644 | AD85: 1.4940006 | AG85: FGLMC | AH85: 37012 | AI85: 117279 | AJ85: 5.8314536e+11 | AK85: 1.5222715 | AN85: 36951 | AO85: 1.6204407
A86: FNCL | B86: 36923 | C86: 209121 | D86: 7.1193641e+11 | E86: 2.0408824 | V86: FGLMC | W86: 37043 | X86: 118507 | Y86: 5.9331218e+11 | Z86: (NULL) | AC86: Grand Total | AD86: 99.433037 | AG86: FGLMC | AH86: 37043 | AI86: 118507 | AJ86: 5.9331218e+11 | AK86: 1.5040233 | AN86: 36982 | AO86: 1.5052378
A87: FNCL | B87: 36951 | C87: 210670 | D87: 7.2415943e+11 | E87: 1.6950482 | V87: FGLMC | W87: 37073 | X87: 119874 | Y87: 6.0681246e+11 | Z87: (NULL) | AG87: FGLMC | AH87: 37073 | AI87: 119874 | AJ87: 6.0681246e+11 | AK87: 1.5602148 | AN87: 37012 | AO87: 1.5222715
A88: FNCL | B88: 36982 | C88: 212403 | D88: 7.3713162e+11 | E88: 1.78351 | V88: FGLMC | W88: 37104 | X88: 121171 | Y88: 6.1879923e+11 | Z88: (NULL) | AG88: FGLMC | AH88: 37104 | AI88: 121171 | AJ88: 6.1879923e+11 | AK88: 1.5327841 | AN88: 37043 | AO88: 1.5040233
A89: FNCL | B89: 37012 | C89: 214231 | D89: 7.5255621e+11 | E89: 1.8885179 | V89: FGLMC | W89: 37135 | X89: 122185 | Y89: 6.2884901e+11 | Z89: (NULL) | AG89: FGLMC | AH89: 37135 | AI89: 122185 | AJ89: 6.2884901e+11 | AK89: 1.3528547 | AN89: 37073 | AO89: 1.5602148
A90: FNCL | B90: 37043 | C90: 216060 | D90: 768634381863 | E90: 1.8881292 | V90: FGLMC | W90: 37165 | X90: 123147 | Y90: 6.3852697e+11 | Z90: (NULL) | AG90: FGLMC | AH90: 37165 | AI90: 123147 | AJ90: 6.3852697e+11 | AK90: 1.6303611 | AN90: 37104 | AO90: 1.5327841
A91: FNCL | B91: 37073 | C91: 217775 | D91: 7.838996e+11 | E91: 1.881026 | V91: FGLMC | W91: 37196 | X91: 124010 | Y91: 6.4631404e+11 | Z91: (NULL) | AG91: FGLMC | AH91: 37196 | AI91: 124010 | AJ91: 6.4631404e+11 | AK91: 1.5184501 | AN91: 37135 | AO91: 1.3528547
A92: FNCL | B92: 37104 | C92: 219337 | D92: 800219895172 | E92: 1.5634442 | V92: FGLMC | W92: 37226 | X92: 124916 | Y92: 6.5258917e+11 | Z92: (NULL) | AG92: FGLMC | AH92: 37226 | AI92: 124916 | AJ92: 6.5258917e+11 | AK92: 1.6220576 | AN92: 37165 | AO92: 1.6303611
A93: FNCL | B93: 37135 | C93: 220863 | D93: 8.1627696e+11 | E93: 1.8359976 | V93: FGLMC | W93: 37257 | X93: 125971 | Y93: 6.5649284e+11 | Z93: (NULL) | AG93: FGLMC | AH93: 37257 | AI93: 125971 | AJ93: 6.5649284e+11 | AK93: 1.7067191 | AN93: 37196 | AO93: 1.5184501
A94: FNCL | B94: 37165 | C94: 222193 | D94: 8.2934041e+11 | E94: 1.7924382 | V94: FGLMC | W94: 37288 | X94: 126553 | Y94: 6.5625962e+11 | Z94: (NULL) | AG94: FGLMC | AH94: 37288 | AI94: 126553 | AJ94: 6.5625962e+11 | AK94: 1.5241945 | AN94: 37226 | AO94: 1.6220576
A95: FNCL | B95: 37196 | C95: 223572 | D95: 8.4108138e+11 | E95: 1.9156774 | V95: FGLMC | W95: 37316 | X95: 127090 | Y95: 6.6258357e+11 | Z95: (NULL) | AG95: FGLMC | AH95: 37316 | AI95: 127090 | AJ95: 6.6258357e+11 | AK95: 1.5930691 | AN95: 37257 | AO95: 1.7067191
...

Sheet Sheet16
A1: marketTicker | B1: asOf | C1: count(1) | D1: sum(p.schamBalance) | E1: wavg_est_pct_DELQ | I1: marketTicker | J1: FNCL | V1: marketTicker | W1: asOf | X1: count(1) | Y1: sum(p.schamBalance) | Z1: wavg_est_pct_DELQ | AC1: marketTicker | AD1: FNCQ30
A2: FNCL | B2: 34366 | C2: 126636 | D2: 2.7849025e+11 | E2: 1.3394729 | V2: FNCL | W2: 34366 | X2: 126636 | Y2: 2.7849025e+11 | Z2: 1.7020031
A3: FNCL | B3: 34394 | C3: 128266 | D3: 2.8205083e+11 | E3: 1.3332664 | I3: Row Labels | J3: Sum of wavg_est_pct_DELQ | V3: FNCL | W3: 34394 | X3: 128266 | Y3: 2.8205083e+11 | Z3: 1.6776446 | AC3: Row Labels | AD3: Sum of wavg_est_pct_DELQ
A4: FNCL | B4: 34425 | C4: 129601 | D4: 2.838742e+11 | E4: 1.3521719 | I4: 34366 | J4: 1.3394729 | V4: FNCL | W4: 34425 | X4: 129601 | Y4: 2.838742e+11 | Z4: 1.6805913 | AC4: 40148 | AD4: 0.75367855
A5: FNCL | B5: 34455 | C5: 130768 | D5: 2.847529e+11 | E5: (NULL) | I5: 34394 | J5: 1.3332664 | V5: FNCL | W5: 34455 | X5: 130768 | Y5: 2.847529e+11 | Z5: 1.7124684 | AC5: 40179 | AD5: 1.1570779
A6: FNCL | B6: 34486 | C6: 131996 | D6: 2.8712206e+11 | E6: (NULL) | I6: 34425 | J6: 1.3521719 | V6: FNCL | W6: 34486 | X6: 131996 | Y6: 2.8712206e+11 | Z6: 1.7107855 | AC6: 40210 | AD6: 2.7443325
A7: FNCL | B7: 34516 | C7: 133140 | D7: 2.8891975e+11 | E7: 1.4269713 | I7: 34455 | J7: 0 | V7: FNCL | W7: 34516 | X7: 133140 | Y7: 2.8891975e+11 | Z7: 1.6926805 | AC7: 40238 | AD7: 3.5717938
A8: FNCL | B8: 34547 | C8: 134153 | D8: 2.9064065e+11 | E8: 1.4595596 | I8: 34486 | J8: 0 | V8: FNCL | W8: 34547 | X8: 134153 | Y8: 2.9064065e+11 | Z8: 1.6985935 | AC8: 40269 | AD8: 4.6748905
A9: FNCL | B9: 34578 | C9: 135077 | D9: 2.9202625e+11 | E9: 1.5854416 | I9: 34516 | J9: 1.4269713 | V9: FNCL | W9: 34578 | X9: 135077 | Y9: 2.9202625e+11 | Z9: 1.7056174 | AC9: 40299 | AD9: 5.5534793
A10: FNCL | B10: 34608 | C10: 135888 | D10: 2.9339599e+11 | E10: 1.5084729 | I10: 34547 | J10: 1.4595596 | V10: FNCL | W10: 34608 | X10: 135888 | Y10: 2.9339599e+11 | Z10: 1.7444788 | AC10: 40330 | AD10: 5.6050328
A11: FNCL | B11: 34639 | C11: 136567 | D11: 2.94792e+11 | E11: 1.5594128 | I11: 34578 | J11: 1.5854416 | V11: FNCL | W11: 34639 | X11: 136567 | Y11: 2.94792e+11 | Z11: 1.8030514 | AC11: 40360 | AD11: 6.8953637
A12: FNCL | B12: 34669 | C12: 137384 | D12: 2.9702273e+11 | E12: 1.5615706 | I12: 34608 | J12: 1.5084729 | V12: FNCL | W12: 34669 | X12: 137384 | Y12: 2.9702273e+11 | Z12: 1.8178422 | AC12: 40391 | AD12: 7.091091
A13: FNCL | B13: 34700 | C13: 138175 | D13: 2.9953479e+11 | E13: 1.7142885 | I13: 34639 | J13: 1.5594128 | V13: FNCL | W13: 34700 | X13: 138175 | Y13: 2.9953479e+11 | Z13: 1.8238207 | AC13: 40422 | AD13: 7.2768792
A14: FNCL | B14: 34731 | C14: 138749 | D14: 3.0057806e+11 | E14: 1.8170431 | I14: 34669 | J14: 1.5615706 | V14: FNCL | W14: 34731 | X14: 138749 | Y14: 3.0057806e+11 | Z14: 1.86139 | AC14: 40452 | AD14: 6.4659271
A15: FNCL | B15: 34759 | C15: 139252 | D15: 3.0151552e+11 | E15: 1.8449893 | I15: 34700 | J15: 1.7142885 | V15: FNCL | W15: 34759 | X15: 139252 | Y15: 3.0151552e+11 | Z15: 1.8885212 | AC15: 40483 | AD15: 5.844497
A16: FNCL | B16: 34790 | C16: 139640 | D16: 3.021308e+11 | E16: 1.7825149 | I16: 34731 | J16: 1.8170431 | V16: FNCL | W16: 34790 | X16: 139640 | Y16: 3.021308e+11 | Z16: 1.9097922 | AC16: 40513 | AD16: 7.3669787
A17: FNCL | B17: 34820 | C17: 140171 | D17: 3.0319317e+11 | E17: 1.8095622 | I17: 34759 | J17: 1.8449893 | V17: FNCL | W17: 34820 | X17: 140171 | Y17: 3.0319317e+11 | Z17: 1.9227469 | AC17: 40544 | AD17: 1.9044024
A18: FNCL | B18: 34851 | C18: 140845 | D18: 3.052762e+11 | E18: 1.8223262 | I18: 34790 | J18: 1.7825149 | V18: FNCL | W18: 34851 | X18: 140845 | Y18: 3.052762e+11 | Z18: 1.9306331 | AC18: 40575 | AD18: 1.7712367
... A36: FNCL | B36: 35400 | C36: 157183 | D36: 3.8057316e+11 | E36: 2.1619329 | I36: 35339 | J36: 2.08633 | V36: FNCL | W36: 35400 | X36: 157183 | Y36: 3.8057316e+11 | Z36: 2.2417086 | AC36: 41122 | AD36: 1.6001347
A37: FNCL | B37: 35431 | C37: 157961 | D37: 3.8357929e+11 | E37: (NULL) | I37: 35370 | J37: 2.1201728 | V37: FNCL | W37: 35431 | X37: 157961 | Y37: 3.8357929e+11 | Z37: 2.2947167 | AC37: 41153 | AD37: 1.589152
A38: FNCL | B38: 35462 | C38: 158587 | D38: 3.8562288e+11 | E38: (NULL) | I38: 35400 | J38: 2.1619329 | V38: FNCL | W38: 35462 | X38: 158587 | Y38: 3.8562288e+11 | Z38: 2.3186864 | AC38: 41183 | AD38: 1.4680845
A39: FNCL | B39: 35490 | C39: 159328 | D39: 3.8894459e+11 | E39: 2.3435396 | I39: 35431 | J39: 0 | V39: FNCL | W39: 35490 | X39: 159328 | Y39: 3.8894459e+11 | Z39: 2.3568095 | AC39: 41214 | AD39: 1.6781519
A40: FNCL | B40: 35521 | C40: 160031 | D40: 3.9199635e+11 | E40: 2.334694 | I40: 35462 | J40: 0 | V40: FNCL | W40: 35521 | X40: 160031 | Y40: 3.9199635e+11 | Z40: 2.4167611 | AC40: 41244 | AD40: 1.4378311
A41: FNCL | B41: 35551 | C41: 160667 | D41: 3.9440199e+11 | E41: 2.3621533 | I41: 35490 | J41: 2.3435396 | V41: FNCL | W41: 35551 | X41: 160667 | Y41: 3.9440199e+11 | Z41: 2.4492645 | AC41: 41275 | AD41: 1.4974738
A42: FNCL | B42: 35582 | C42: 161332 | D42: 3.976503e+11 | E42: 2.3833537 | I42: 35521 | J42: 2.334694 | V42: FNCL | W42: 35582 | X42: 161332 | Y42: 3.976503e+11 | Z42: 2.4795058 | AC42: 41306 | AD42: 1.5432276
A43: FNCL | B43: 35612 | C43: 161858 | D43: 3.9966136e+11 | E43: 2.4698767 | I43: 35551 | J43: 2.3621533 | V43: FNCL | W43: 35612 | X43: 161858 | Y43: 3.9966136e+11 | Z43: 2.4896049 | AC43: 41334 | AD43: 1.5445274
A44: FNCL | B44: 35643 | C44: 162531 | D44: 4.0247325e+11 | E44: 2.4801191 | I44: 35582 | J44: 2.3833537 | V44: FNCL | W44: 35643 | X44: 162531 | Y44: 4.0247325e+11 | Z44: 2.4985984 | AC44: 41365 | AD44: 1.5321599
A45: FNCL | B45: 35674 | C45: 163328 | D45: 4.07135e+11 | E45: 2.4981032 | I45: 35612 | J45: 2.4698767 | V45: FNCL | W45: 35674 | X45: 163328 | Y45: 4.07135e+11 | Z45: 2.5175351 | AC45: 41395 | AD45: 1.359586
A46: FNCL | B46: 35704 | C46: 164171 | D46: 4.109579e+11 | E46: 2.4930597 | I46: 35643 | J46: 2.4801191 | V46: FNCL | W46: 35704 | X46: 164171 | Y46: 4.109579e+11 | Z46: 2.5479923 | AC46: 41426 | AD46: 1.275903
A47: FNCL | B47: 35735 | C47: 164998 | D47: 4.1557814e+11 | E47: 2.5364798 | I47: 35674 | J47: 2.4981032 | V47: FNCL | W47: 35735 | X47: 164998 | Y47: 4.1557814e+11 | Z47: 2.5540115 | AC47: 41456 | AD47: 1.3386877
A48: FNCL | B48: 35765 | C48: 165889 | D48: 4.2044218e+11 | E48: 2.5392196 | I48: 35704 | J48: 2.4930597 | V48: FNCL | W48: 35765 | X48: 165889 | Y48: 4.2044218e+11 | Z48: 2.5550326 | AC48: 41487 | AD48: 1.532915
A49: FNCL | B49: 35796 | C49: 166964 | D49: 4.2550701e+11 | E49: 2.5528912 | I49: 35735 | J49: 2.5364798 | V49: FNCL | W49: 35796 | X49: 166964 | Y49: 4.2550701e+11 | Z49: 2.5689652 | AC49: 41518 | AD49: 1.3623292
A50: FNCL | B50: 35827 | C50: 167888 | D50: 4.3013336e+11 | E50: 2.4847921 | I50: 35765 | J50: 2.5392196 | V50: FNCL | W50: 35827 | X50: 167888 | Y50: 4.3013336e+11 | Z50: 2.555121 | AC50: 41548 | AD50: 1.4786037
... A86: FNCL | B86: 36923 | C86: 209121 | D86: 7.1193641e+11 | E86: 2.1839563 | I86: 36861 | J86: 2.1060134 | V86: FNCL | W86: 36923 | X86: 209121 | Y86: 7.1193641e+11 | Z86: 2.1899263 | AC86: 42644 | AD86: 2.0516269
A87: FNCL | B87: 36951 | C87: 210670 | D87: 7.2415943e+11 | E87: 2.2891687 | I87: 36892 | J87: 2.2817559 | V87: FNCL | W87: 36951 | X87: 210670 | Y87: 7.2415943e+11 | Z87: 2.2959411 | AC87: Grand Total | AD87: 192.2984
A88: FNCL | B88: 36982 | C88: 212403 | D88: 7.3713162e+11 | E88: 2.1667011 | I88: 36923 | J88: 2.1839563 | V88: FNCL | W88: 36982 | X88: 212403 | Y88: 7.3713162e+11 | Z88: 2.1728905
A89: FNCL | B89: 37012 | C89: 214231 | D89: 7.5255621e+11 | E89: 2.1718727 | I89: 36951 | J89: 2.2891687 | V89: FNCL | W89: 37012 | X89: 214231 | Y89: 7.5255621e+11 | Z89: 2.1776197
A90: FNCL | B90: 37043 | C90: 216060 | D90: 768634381863 | E90: 2.144774 | I90: 36982 | J90: 2.1667011 | V90: FNCL | W90: 37043 | X90: 216060 | Y90: 768634381863 | Z90: 2.1510662
A91: FNCL | B91: 37073 | C91: 217775 | D91: 7.838996e+11 | E91: 2.1835669 | I91: 37012 | J91: 2.1718727 | V91: FNCL | W91: 37073 | X91: 217775 | Y91: 7.838996e+11 | Z91: 2.1898011
A92: FNCL | B92: 37104 | C92: 219337 | D92: 800219895172 | E92: 2.1324049 | I92: 37043 | J92: 2.144774 | V92: FNCL | W92: 37104 | X92: 219337 | Y92: 800219895172 | Z92: 2.1388077
...

Sheet Sheet17
A1: marketTicker | B1: asOf | C1: count(1) | D1: sum(p.schamBalance) | E1: wavg_est_pct_DELQ | I1: marketTicker | J1: FNCL
A2: FNCL | B2: 34366 | C2: 126636 | D2: 2.7849025e+11 | E2: 1.273842
A3: FNCL | B3: 34394 | C3: 128266 | D3: 2.8205083e+11 | E3: 1.2570568 | I3: Row Labels | J3: Sum of wavg_est_pct_DELQ
A4: FNCL | B4: 34425 | C4: 129601 | D4: 2.838742e+11 | E4: 1.2581451 | I4: 34366 | J4: 1.273842
A5: FNCL | B5: 34455 | C5: 130768 | D5: 2.847529e+11 | E5: 1.305171 | I5: 34394 | J5: 1.2570568
A6: FNCL | B6: 34486 | C6: 131996 | D6: 2.8712206e+11 | E6: 1.3040233 | I6: 34425 | J6: 1.2581451
A7: FNCL | B7: 34516 | C7: 133140 | D7: 2.8891975e+11 | E7: 1.2633223 | I7: 34455 | J7: 1.305171
A8: FNCL | B8: 34547 | C8: 134153 | D8: 2.9064065e+11 | E8: 1.2665115 | I8: 34486 | J8: 1.3040233
A9: FNCL | B9: 34578 | C9: 135077 | D9: 2.9202625e+11 | E9: 1.2686391 | I9: 34516 | J9: 1.2633223
A10: FNCL | B10: 34608 | C10: 135888 | D10: 2.9339599e+11 | E10: 1.2954163 | I10: 34547 | J10: 1.2665115
A11: FNCL | B11: 34639 | C11: 136567 | D11: 2.94792e+11 | E11: 1.3325704 | I11: 34578 | J11: 1.2686391
A12: FNCL | B12: 34669 | C12: 137384 | D12: 2.9702273e+11 | E12: 1.3419997 | I12: 34608 | J12: 1.2954163
A13: FNCL | B13: 34700 | C13: 138175 | D13: 2.9953479e+11 | E13: 1.3425664 | I13: 34639 | J13: 1.3325704
A14: FNCL | B14: 34731 | C14: 138749 | D14: 3.0057806e+11 | E14: 1.3657551 | I14: 34669 | J14: 1.3419997
A15: FNCL | B15: 34759 | C15: 139252 | D15: 3.0151552e+11 | E15: 1.3827562 | I15: 34700 | J15: 1.3425664
... A276: FNCL | B276: 40817 | C276: 282590 | D276: 1.7300621e+12 | E276: 2.5966651 | I276: 42644 | J276: 0.94728345
A277: FNCQ30 | B277: 40817 | C277: 461 | D277: 7.9908166e+09 | E277: 1.2235435 | I277: Grand Total | J277: 462.98917
A278: FNCK | B278: 40848 | C278: 1471 | D278: 6.1528555e+10 | E278: 0.35476043
A279: FNCL | B279: 40848 | C279: 283012 | D279: 1.7161114e+12 | E279: 2.5862469
A280: FNCQ30 | B280: 40848 | C280: 487 | D280: 8.5171652e+09 | E280: 1.4425548
A281: FNCK | B281: 40878 | C281: 1523 | D281: 6.343284e+10 | E281: 0.34851175
A282: FNCL | B282: 40878 | C282: 283516 | D282: 1.704192e+12 | E282: 2.5913291
A283: FNCQ30 | B283: 40878 | C283: 514 | D283: 9.0740215e+09 | E283: 1.4337457
A284: FNCK | B284: 40909 | C284: 1561 | D284: 6.3431287e+10 | E284: 0.34007539
A285: FNCL | B285: 40909 | C285: 284179 | D285: 1.7047182e+12 | E285: 2.6562975
A286: FNCQ30 | B286: 40909 | C286: 537 | D286: 9.4003226e+09 | E286: 1.5478917
A287: FNCK | B287: 40940 | C287: 1581 | D287: 6.3028905e+10 | E287: 0.41533967
A288: FNCL | B288: 40940 | C288: 284757 | D288: 1.6958104e+12 | E288: 2.5880479
