Workbook

Sheet 0510v1

Sheet 0510v2
AM3: Fix burnout corve

Sheet 0510v3
BA1: x_vals | BB1: actual | BC1: model v2 | BD1: model v1 | BE1: Square Error | BG1: RMSE | BJ1: actual | BK1: model v2 | BL1: model v1 | BP1: actual | BQ1: model v2 | BR1: model v1 | BV1: actual | BW1: model v2 | BX1: model v1
AL2: Fix loan size corve | BA2: 36526 | BB2: 1.2535394 | BC2: 1.0729859 | BD2: =VLOOKUP(BA2,Symphony!A:J,8,0) -> 1.1 | BE2: =(BC2-BB2)^2 -> 0.032599552 | BF2: =(BD2-BB2)^2 -> 0.023574342 | BG2: =SUM(BC2:BC190)/COUNT(BC2:BC190) -> 14.213824 | BH2: =SUM(BD2:BD190)/COUNT(BD2:BD190) -> 11.056614 | BI2: 39600 | BJ2: 15.996829 | BK2: 2.8692321 | BL2: =VLOOKUP(BI2,Symphony!L:U,8,0) -> 0 | BO2: 40238 | BP2: 0 | BQ2: 1.5412316 | BR2: =VLOOKUP(BO2,Symphony!W:AF,8,0) -> 0.1 | BU2: 41518 | BV2: 0 | BW2: 0.36900499 | BX2: =VLOOKUP(BU2,Symphony!AH:AQ,8,0) -> 0
BA3: 36557 | BB3: 1.1353791 | BC3: 0.86519501 | BD3: =VLOOKUP(BA3,Symphony!A:J,8,0) -> 0.5 | BE3: =(BC3-BB3)^2 -> 0.072999438 | BF3: =(BD3-BB3)^2 -> 0.40370658 | BG3: =SUM(BC2:BC190) -> 2686.4127 | BH3: =SUM(BD2:BD190) -> 2089.7 | BI3: 39630 | BJ3: 14.47073 | BK3: 0.89335337 | BL3: =VLOOKUP(BI3,Symphony!L:U,8,0) -> 0 | BO3: 40299 | BP3: 2.3546342 | BQ3: 1.8461067 | BR3: =VLOOKUP(BO3,Symphony!W:AF,8,0) -> 0.1 | BU3: 41548 | BV3: 0 | BW3: 0.69948155 | BX3: =VLOOKUP(BU3,Symphony!AH:AQ,8,0) -> 0
BA4: 36586 | BB4: 1.1811762 | BC4: 0.8680051 | BD4: =VLOOKUP(BA4,Symphony!A:J,8,0) -> 0.4 | BE4: =(BC4-BB4)^2 -> 0.098076111 | BF4: =(BD4-BB4)^2 -> 0.61023618 | BG4: =COUNT(BC2:BC190) -> 189 | BH4: =COUNT(BD2:BD190) -> 189 | BI4: 39661 | BJ4: 3.5877677 | BK4: 0.63532943 | BL4: =VLOOKUP(BI4,Symphony!L:U,8,0) -> 0 | BO4: 40330 | BP4: 0 | BQ4: 2.5494255 | BR4: =VLOOKUP(BO4,Symphony!W:AF,8,0) -> 0.1 | BU4: 41579 | BV4: 0 | BW4: 0.74770525 | BX4: =VLOOKUP(BU4,Symphony!AH:AQ,8,0) -> 0
BA5: 36617 | BB5: 1.4526721 | BC5: 1.0882602 | BD5: =VLOOKUP(BA5,Symphony!A:J,8,0) -> 0.3 | BE5: =(BC5-BB5)^2 -> 0.13279604 | BF5: =(BD5-BB5)^2 -> 1.328653 | BI5: 39692 | BJ5: 6.2488483 | BK5: 1.4753515 | BL5: =VLOOKUP(BI5,Symphony!L:U,8,0) -> 0 | BO5: 40360 | BP5: 0 | BQ5: 2.4258926 | BR5: =VLOOKUP(BO5,Symphony!W:AF,8,0) -> 0.2 | BU5: 41609 | BV5: 28.50765 | BW5: 0.41685401 | BX5: =VLOOKUP(BU5,Symphony!AH:AQ,8,0) -> 0
BA6: 36647 | BB6: 1.2976516 | BC6: 1.3819538 | BD6: =VLOOKUP(BA6,Symphony!A:J,8,0) -> 0.4 | BE6: =(BC6-BB6)^2 -> 0.0071068719 | BF6: =(BD6-BB6)^2 -> 0.80577834 | BI6: 39722 | BJ6: 25.124779 | BK6: 2.6798276 | BL6: =VLOOKUP(BI6,Symphony!L:U,8,0) -> 0 | BO6: 40391 | BP6: 0 | BQ6: 3.9371497 | BR6: =VLOOKUP(BO6,Symphony!W:AF,8,0) -> 0.2 | BU6: 41640 | BV6: 0.011096823 | BW6: 0.98331072 | BX6: =VLOOKUP(BU6,Symphony!AH:AQ,8,0) -> 0
BA7: 36678 | BB7: 2.0225927 | BC7: 1.0305623 | BD7: =VLOOKUP(BA7,Symphony!A:J,8,0) -> 0.4 | BE7: =(BC7-BB7)^2 -> 0.9841242 | BF7: =(BD7-BB7)^2 -> 2.632807 | BI7: 39753 | BJ7: 13.325528 | BK7: 2.6662738 | BL7: =VLOOKUP(BI7,Symphony!L:U,8,0) -> 4.5 | BO7: 40422 | BP7: 0 | BQ7: 4.8307402 | BR7: =VLOOKUP(BO7,Symphony!W:AF,8,0) -> 0.2 | BU7: 41671 | BV7: 0 | BW7: 2.4013903 | BX7: =VLOOKUP(BU7,Symphony!AH:AQ,8,0) -> 0
BA8: 36708 | BB8: 1.5807117 | BC8: 1.6282349 | BD8: =VLOOKUP(BA8,Symphony!A:J,8,0) -> 0.3 | BE8: =(BC8-BB8)^2 -> 0.0022584517 | BF8: =(BD8-BB8)^2 -> 1.6402224 | BI8: 39783 | BJ8: 11.720807 | BK8: 5.8503446 | BL8: =VLOOKUP(BI8,Symphony!L:U,8,0) -> 3.2 | BO8: 40452 | BP8: 1.7488395 | BQ8: 5.297038 | BR8: =VLOOKUP(BO8,Symphony!W:AF,8,0) -> 0.3 | BU8: 41699 | BV8: 24.647675 | BW8: 3.4863476 | BX8: =VLOOKUP(BU8,Symphony!AH:AQ,8,0) -> 0
BA9: 36739 | BB9: 1.5421276 | BC9: 2.3249456 | BD9: =VLOOKUP(BA9,Symphony!A:J,8,0) -> 0.4 | BE9: =(BC9-BB9)^2 -> 0.61280411 | BF9: =(BD9-BB9)^2 -> 1.3044554 | BI9: 39814 | BJ9: 25.676602 | BK9: 33.765847 | BL9: =VLOOKUP(BI9,Symphony!L:U,8,0) -> 3.5 | BO9: 40483 | BP9: 3.9109832 | BQ9: 4.7351392 | BR9: =VLOOKUP(BO9,Symphony!W:AF,8,0) -> 0.3 | BU9: 41730 | BV9: 3.5371075 | BW9: 3.3320511 | BX9: =VLOOKUP(BU9,Symphony!AH:AQ,8,0) -> 0
BA10: 36770 | BB10: 2.5043866 | BC10: 3.2576578 | BD10: =VLOOKUP(BA10,Symphony!A:J,8,0) -> 0.5 | BE10: =(BC10-BB10)^2 -> 0.56741757 | BF10: =(BD10-BB10)^2 -> 4.0175656 | BI10: 39845 | BJ10: 25.060766 | BK10: 42.984359 | BL10: =VLOOKUP(BI10,Symphony!L:U,8,0) -> 32.2 | BO10: 40513 | BP10: 3.6766564 | BQ10: 3.9004244 | BR10: =VLOOKUP(BO10,Symphony!W:AF,8,0) -> 0.3 | BU10: 41760 | BV10: 2.5529922 | BW10: 3.2039984 | BX10: =VLOOKUP(BU10,Symphony!AH:AQ,8,0) -> 0
BA11: 36800 | BB11: 2.4512741 | BC11: 4.4467392 | BD11: =VLOOKUP(BA11,Symphony!A:J,8,0) -> 0.9 | BE11: =(BC11-BB11)^2 -> 3.9818808 | BF11: =(BD11-BB11)^2 -> 2.4064513 | BI11: 39873 | BJ11: 33.953462 | BK11: 40.530241 | BL11: =VLOOKUP(BI11,Symphony!L:U,8,0) -> 51.5 | BO11: 40544 | BP11: 5.7761375 | BQ11: 2.9596164 | BR11: =VLOOKUP(BO11,Symphony!W:AF,8,0) -> 0.3 | BU11: 41791 | BV11: 6.3775145 | BW11: 4.3863251 | BX11: =VLOOKUP(BU11,Symphony!AH:AQ,8,0) -> 0
BA12: 36831 | BB12: 3.0477081 | BC12: 4.344863 | BD12: =VLOOKUP(BA12,Symphony!A:J,8,0) -> 1.4 | BE12: =(BC12-BB12)^2 -> 1.6826107 | BF12: =(BD12-BB12)^2 -> 2.7149421 | BI12: 39904 | BJ12: 38.035695 | BK12: 43.102779 | BL12: =VLOOKUP(BI12,Symphony!L:U,8,0) -> 39.4 | BO12: 40575 | BP12: 3.6317529 | BQ12: 2.3371116 | BR12: =VLOOKUP(BO12,Symphony!W:AF,8,0) -> 0.1 | BU12: 41821 | BV12: 8.4648546 | BW12: 3.5785867 | BX12: =VLOOKUP(BU12,Symphony!AH:AQ,8,0) -> 0.1
BA13: 36861 | BB13: 3.1145932 | BC13: 5.8622284 | BD13: =VLOOKUP(BA13,Symphony!A:J,8,0) -> 2.2 | BE13: =(BC13-BB13)^2 -> 7.5494994 | BF13: =(BD13-BB13)^2 -> 0.83648074 | BI13: 39934 | BJ13: 34.34713 | BK13: 46.684262 | BL13: =VLOOKUP(BI13,Symphony!L:U,8,0) -> 51.1 | BO13: 40603 | BP13: 4.4212626 | BQ13: 2.1224182 | BR13: =VLOOKUP(BO13,Symphony!W:AF,8,0) -> 0.1 | BU13: 41852 | BV13: 7.8898601 | BW13: 3.4860708 | BX13: =VLOOKUP(BU13,Symphony!AH:AQ,8,0) -> 0.1
BA14: 36892 | BB14: 5.0764757 | BC14: 14.532159 | BD14: =VLOOKUP(BA14,Symphony!A:J,8,0) -> 3 | BE14: =(BC14-BB14)^2 -> 89.409945 | BF14: =(BD14-BB14)^2 -> 4.3117515 | BI14: 39965 | BJ14: 41.274734 | BK14: 45.30583 | BL14: =VLOOKUP(BI14,Symphony!L:U,8,0) -> 60.7 | BO14: 40634 | BP14: 2.207404 | BQ14: 2.5757817 | BR14: =VLOOKUP(BO14,Symphony!W:AF,8,0) -> 0.1 | BU14: 41883 | BV14: 4.3261102 | BW14: 3.8628412 | BX14: =VLOOKUP(BU14,Symphony!AH:AQ,8,0) -> 0.1
BA15: 36923 | BB15: 20.00396 | BC15: 27.815628 | BD15: =VLOOKUP(BA15,Symphony!A:J,8,0) -> 7.8 | BE15: =(BC15-BB15)^2 -> 61.022157 | BF15: =(BD15-BB15)^2 -> 148.93664 | BI15: 39995 | BJ15: 51.664181 | BK15: 18.751641 | BL15: =VLOOKUP(BI15,Symphony!L:U,8,0) -> 57.3 | BO15: 40664 | BP15: 5.69139 | BQ15: 2.6082146 | BR15: =VLOOKUP(BO15,Symphony!W:AF,8,0) -> 0.1 | BU15: 41913 | BV15: 6.3552727 | BW15: 4.0473741 | BX15: =VLOOKUP(BU15,Symphony!AH:AQ,8,0) -> 0.1
BA16: 36951 | BB16: 26.83627 | BC16: 27.655269 | BD16: =VLOOKUP(BA16,Symphony!A:J,8,0) -> 13.4 | BE16: =(BC16-BB16)^2 -> 0.67075912 | BF16: =(BD16-BB16)^2 -> 180.53335 | BI16: 40026 | BJ16: 33.070951 | BK16: 28.670772 | BL16: =VLOOKUP(BI16,Symphony!L:U,8,0) -> 16.3 | BO16: 40695 | BP16: 4.5115981 | BQ16: 3.1254222 | BR16: =VLOOKUP(BO16,Symphony!W:AF,8,0) -> 0.1 | BU16: 41944 | BV16: 3.9338496 | BW16: 4.4542296 | BX16: =VLOOKUP(BU16,Symphony!AH:AQ,8,0) -> 0.1
... BA26: 37257 | BB26: 24.542736 | BC26: 12.202545 | BD26: =VLOOKUP(BA26,Symphony!A:J,8,0) -> 19.4 | BE26: =(BC26-BB26)^2 -> 152.28031 | BF26: =(BD26-BB26)^2 -> 26.447731 | BI26: 40330 | BJ26: 41.995495 | BK26: 37.824111 | BL26: =VLOOKUP(BI26,Symphony!L:U,8,0) -> 32.5 | BO26: 41000 | BP26: 3.2881293 | BQ26: 6.1034787 | BR26: =VLOOKUP(BO26,Symphony!W:AF,8,0) -> 0.4 | BU26: 42248 | BV26: 5.79433 | BW26: 6.0652144 | BX26: =VLOOKUP(BU26,Symphony!AH:AQ,8,0) -> 0.3
BA27: 37288 | BB27: 17.144156 | BC27: 12.348718 | BD27: =VLOOKUP(BA27,Symphony!A:J,8,0) -> 8.9 | BE27: =(BC27-BB27)^2 -> 22.996221 | BF27: =(BD27-BB27)^2 -> 67.966106 | BI27: 40360 | BJ27: 62.382325 | BK27: 43.449976 | BL27: =VLOOKUP(BI27,Symphony!L:U,8,0) -> 42.8 | BO27: 41030 | BP27: 6.2361495 | BQ27: 6.0960113 | BR27: =VLOOKUP(BO27,Symphony!W:AF,8,0) -> 0.4
BA28: 37316 | BB28: 17.229207 | BC28: 16.596833 | BD28: =VLOOKUP(BA28,Symphony!A:J,8,0) -> 9.3 | BE28: =(BC28-BB28)^2 -> 0.39989581 | BF28: =(BD28-BB28)^2 -> 62.872317 | BI28: 40391 | BJ28: 54.217748 | BK28: 46.963352 | BL28: =VLOOKUP(BI28,Symphony!L:U,8,0) -> 51.1 | BO28: 41061 | BP28: 4.6862508 | BQ28: 5.6912365 | BR28: =VLOOKUP(BO28,Symphony!W:AF,8,0) -> 0.5
BA29: 37347 | BB29: 11.999618 | BC29: 9.2059086 | BD29: =VLOOKUP(BA29,Symphony!A:J,8,0) -> 11.6 | BE29: =(BC29-BB29)^2 -> 7.8048131 | BF29: =(BD29-BB29)^2 -> 0.15969464 | BI29: 40422 | BJ29: 58.550964 | BK29: 50.752726 | BL29: =VLOOKUP(BI29,Symphony!L:U,8,0) -> 56 | BO29: 41091 | BP29: 3.5066665 | BQ29: 5.3835072 | BR29: =VLOOKUP(BO29,Symphony!W:AF,8,0) -> 0.6
BA30: 37377 | BB30: 11.14014 | BC30: 10.812034 | BD30: =VLOOKUP(BA30,Symphony!A:J,8,0) -> 7.3 | BE30: =(BC30-BB30)^2 -> 0.10765385 | BF30: =(BD30-BB30)^2 -> 14.746677 | BI30: 40452 | BJ30: 53.083728 | BK30: 51.120233 | BL30: =VLOOKUP(BI30,Symphony!L:U,8,0) -> 69.5 | BO30: 41122 | BP30: 4.3441979 | BQ30: 5.1374031 | BR30: =VLOOKUP(BO30,Symphony!W:AF,8,0) -> 0.6
BA31: 37408 | BB31: 10.601735 | BC31: 15.744875 | BD31: =VLOOKUP(BA31,Symphony!A:J,8,0) -> 8.1 | BE31: =(BC31-BB31)^2 -> 26.451887 | BF31: =(BD31-BB31)^2 -> 6.2586775 | BI31: 40483 | BJ31: 64.495353 | BK31: 51.440022 | BL31: =VLOOKUP(BI31,Symphony!L:U,8,0) -> 75.1 | BO31: 41153 | BP31: 3.7691802 | BQ31: 5.2234263 | BR31: =VLOOKUP(BO31,Symphony!W:AF,8,0) -> 0.7
BA32: 37438 | BB32: 15.80622 | BC32: 28.326336 | BD32: =VLOOKUP(BA32,Symphony!A:J,8,0) -> 11 | BE32: =(BC32-BB32)^2 -> 156.7533 | BF32: =(BD32-BB32)^2 -> 23.099751 | BI32: 40513 | BJ32: 54.952043 | BK32: 49.756447 | BL32: =VLOOKUP(BI32,Symphony!L:U,8,0) -> 76.7 | BO32: 41183 | BP32: 4.1025358 | BQ32: 5.5732985 | BR32: =VLOOKUP(BO32,Symphony!W:AF,8,0) -> 0.6
BA33: 37469 | BB33: 28.023003 | BC33: 39.12222 | BD33: =VLOOKUP(BA33,Symphony!A:J,8,0) -> 15.8 | BE33: =(BC33-BB33)^2 -> 123.19262 | BF33: =(BD33-BB33)^2 -> 149.40181 | BI33: 40544 | BJ33: 23.760501 | BK33: 15.193048 | BL33: =VLOOKUP(BI33,Symphony!L:U,8,0) -> 70.9 | BO33: 41214 | BP33: 5.284974 | BQ33: 6.1183736 | BR33: =VLOOKUP(BO33,Symphony!W:AF,8,0) -> 0.7
BA34: 37500 | BB34: 32.991438 | BC34: 43.870621 | BD34: =VLOOKUP(BA34,Symphony!A:J,8,0) -> 22.7 | BE34: =(BC34-BB34)^2 -> 118.35663 | BF34: =(BD34-BB34)^2 -> 105.91369 | BI34: 40575 | BJ34: 15.303476 | BK34: 9.2072614 | BL34: =VLOOKUP(BI34,Symphony!L:U,8,0) -> 17.3 | BO34: 41244 | BP34: 5.1292449 | BQ34: 7.2162199 | BR34: =VLOOKUP(BO34,Symphony!W:AF,8,0) -> 0.8
BA35: 37530 | BB35: 46.555598 | BC35: 47.89982 | BD35: =VLOOKUP(BA35,Symphony!A:J,8,0) -> 34.8 | BE35: =(BC35-BB35)^2 -> 1.8069323 | BF35: =(BD35-BB35)^2 -> 138.19408 | BI35: 40603 | BJ35: 7.7544968 | BK35: 3.6315816 | BL35: =VLOOKUP(BI35,Symphony!L:U,8,0) -> 11.7 | BO35: 41275 | BP35: 4.4049161 | BQ35: 5.9954479 | BR35: =VLOOKUP(BO35,Symphony!W:AF,8,0) -> 0.8
BA36: 37561 | BB36: 44.391856 | BC36: 46.244397 | BD36: =VLOOKUP(BA36,Symphony!A:J,8,0) -> 46.8 | BE36: =(BC36-BB36)^2 -> 3.4319097 | BF36: =(BD36-BB36)^2 -> 5.799159 | BI36: 40634 | BJ36: 5.8152588 | BK36: 4.8205952 | BL36: =VLOOKUP(BI36,Symphony!L:U,8,0) -> 5.5 | BO36: 41306 | BP36: 3.8427588 | BQ36: 5.7579429 | BR36: =VLOOKUP(BO36,Symphony!W:AF,8,0) -> 0.8
BA37: 37591 | BB37: 43.743179 | BC37: 45.99616 | BD37: =VLOOKUP(BA37,Symphony!A:J,8,0) -> 42.1 | BE37: =(BC37-BB37)^2 -> 5.0759225 | BF37: =(BD37-BB37)^2 -> 2.7000377 | BI37: 40664 | BJ37: 8.0867463 | BK37: 5.3998976 | BL37: =VLOOKUP(BI37,Symphony!L:U,8,0) -> 6.7 | BO37: 41334 | BP37: 4.4682231 | BQ37: 5.7934517 | BR37: =VLOOKUP(BO37,Symphony!W:AF,8,0) -> 0.8
BA38: 37622 | BB38: 40.428082 | BC38: 44.05701 | BD38: =VLOOKUP(BA38,Symphony!A:J,8,0) -> 40.2 | BE38: =(BC38-BB38)^2 -> 13.169118 | BF38: =(BD38-BB38)^2 -> 0.052021508 | BI38: 40695 | BJ38: 12.600923 | BK38: 9.4555706 | BL38: =VLOOKUP(BI38,Symphony!L:U,8,0) -> 7 | BO38: 41365 | BP38: 5.0909126 | BQ38: 6.2663772 | BR38: =VLOOKUP(BO38,Symphony!W:AF,8,0) -> 0.6
... BA47: 37895 | BB47: 24.586138 | BC47: 11.233364 | BD47: =VLOOKUP(BA47,Symphony!A:J,8,0) -> 6.7 | BE47: =(BC47-BB47)^2 -> 178.29657 | BF47: =(BD47-BB47)^2 -> 319.91393 | BI47: 40969 | BJ47: 30.029058 | BK47: 29.305594 | BL47: =VLOOKUP(BI47,Symphony!L:U,8,0) -> 38.9 | BO47: 41640 | BP47: 2.6446191 | BQ47: 1.4968611 | BR47: =VLOOKUP(BO47,Symphony!W:AF,8,0) -> 3.7
AS48: =2/7 -> 0.28571429 | BA48: 37926 | BB48: 17.287137 | BC48: 14.344513 | BD48: =VLOOKUP(BA48,Symphony!A:J,8,0) -> 8.5 | BE48: =(BC48-BB48)^2 -> 8.6590355 | BF48: =(BD48-BB48)^2 -> 77.213775 | BI48: 41000 | BJ48: 19.779476 | BK48: 26.728044 | BL48: =VLOOKUP(BI48,Symphony!L:U,8,0) -> 35.9 | BO48: 41671 | BP48: 3.0469981 | BQ48: 1.7265849 | BR48: =VLOOKUP(BO48,Symphony!W:AF,8,0) -> 3
AR49: 1 | AS49: =46/AR49 -> 46 | BA49: 37956 | BB49: 16.294472 | BC49: 13.784175 | BD49: =VLOOKUP(BA49,Symphony!A:J,8,0) -> 10.8 | BE49: =(BC49-BB49)^2 -> 6.3015921 | BF49: =(BD49-BB49)^2 -> 30.189224 | BI49: 41030 | BJ49: 23.651007 | BK49: 28.379789 | BL49: =VLOOKUP(BI49,Symphony!L:U,8,0) -> 27.3 | BO49: 41699 | BP49: 3.4715777 | BQ49: 2.4233097 | BR49: =VLOOKUP(BO49,Symphony!W:AF,8,0) -> 3.3
AR50: 2 | AS50: =46/AR50 -> 23 | BA50: 37987 | BB50: 12.154475 | BC50: 13.906402 | BD50: =VLOOKUP(BA50,Symphony!A:J,8,0) -> 11.1 | BE50: =(BC50-BB50)^2 -> 3.0692483 | BF50: =(BD50-BB50)^2 -> 1.1119175 | BI50: 41061 | BJ50: 31.172286 | BK50: 31.064502 | BL50: =VLOOKUP(BI50,Symphony!L:U,8,0) -> 31.4 | BO50: 41730 | BP50: 3.1302724 | BQ50: 2.6030643 | BR50: =VLOOKUP(BO50,Symphony!W:AF,8,0) -> 4.3
AR51: 3 | AS51: =46/AR51 -> 15.333333 | BA51: 38018 | BB51: 17.779597 | BC51: 18.262365 | BD51: =VLOOKUP(BA51,Symphony!A:J,8,0) -> 11.3 | BE51: =(BC51-BB51)^2 -> 0.23306496 | BF51: =(BD51-BB51)^2 -> 41.985174 | BI51: 41091 | BJ51: 37.993907 | BK51: 34.832657 | BL51: =VLOOKUP(BI51,Symphony!L:U,8,0) -> 37.5 | BO51: 41760 | BP51: 3.3140616 | BQ51: 3.0821754 | BR51: =VLOOKUP(BO51,Symphony!W:AF,8,0) -> 4.8
AR52: 4 | AS52: =46/AR52 -> 11.5 | BA52: 38047 | BB52: 25.619347 | BC52: 21.234025 | BD52: =VLOOKUP(BA52,Symphony!A:J,8,0) -> 13.9 | BE52: =(BC52-BB52)^2 -> 19.231054 | BF52: =(BD52-BB52)^2 -> 137.3431 | BI52: 41122 | BJ52: 47.795395 | BK52: 38.040831 | BL52: =VLOOKUP(BI52,Symphony!L:U,8,0) -> 42.7 | BO52: 41791 | BP52: 3.4633798 | BQ52: 4.4882945 | BR52: =VLOOKUP(BO52,Symphony!W:AF,8,0) -> 5.9
AR53: 5 | AS53: =46/AR53 -> 9.2 | BA53: 38078 | BB53: 31.887201 | BC53: 29.601354 | BD53: =VLOOKUP(BA53,Symphony!A:J,8,0) -> 15.1 | BE53: =(BC53-BB53)^2 -> 5.2250971 | BF53: =(BD53-BB53)^2 -> 281.81011 | BI53: 41153 | BJ53: 39.761897 | BK53: 36.638207 | BL53: =VLOOKUP(BI53,Symphony!L:U,8,0) -> 47.6 | BO53: 41821 | BP53: 4.0920546 | BQ53: 4.9165422 | BR53: =VLOOKUP(BO53,Symphony!W:AF,8,0) -> 8.7
AR54: 6 | AS54: =46/AR54 -> 7.6666667 | BA54: 38108 | BB54: 20.563351 | BC54: 10.57512 | BD54: =VLOOKUP(BA54,Symphony!A:J,8,0) -> 19.9 | BE54: =(BC54-BB54)^2 -> 99.764753 | BF54: =(BD54-BB54)^2 -> 0.44003415 | BI54: 41183 | BJ54: 45.502454 | BK54: 38.342819 | BL54: =VLOOKUP(BI54,Symphony!L:U,8,0) -> 42.5 | BO54: 41852 | BP54: 3.6296264 | BQ54: 4.5076516 | BR54: =VLOOKUP(BO54,Symphony!W:AF,8,0) -> 9.3
AR55: 7 | AS55: =46/AR55 -> 6.5714286 | BA55: 38139 | BB55: 14.43089 | BC55: 4.7523065 | BD55: =VLOOKUP(BA55,Symphony!A:J,8,0) -> 9.5 | BE55: =(BC55-BB55)^2 -> 93.674983 | BF55: =(BD55-BB55)^2 -> 24.313679 | BI55: 41214 | BJ55: 40.140056 | BK55: 39.093695 | BL55: =VLOOKUP(BI55,Symphony!L:U,8,0) -> 47.6 | BO55: 41883 | BP55: 3.9555965 | BQ55: 5.3791426 | BR55: =VLOOKUP(BO55,Symphony!W:AF,8,0) -> 9.7
AR56: 8 | AS56: =46/AR56 -> 5.75 | BA56: 38169 | BB56: 9.634259 | BC56: 4.7247936 | BD56: =VLOOKUP(BA56,Symphony!A:J,8,0) -> 4.7 | BE56: =(BC56-BB56)^2 -> 24.10285 | BF56: =(BD56-BB56)^2 -> 24.346911 | BI56: 41244 | BJ56: 37.646957 | BK56: 38.149546 | BL56: =VLOOKUP(BI56,Symphony!L:U,8,0) -> 49 | BO56: 41913 | BP56: 4.2275735 | BQ56: 5.386127 | BR56: =VLOOKUP(BO56,Symphony!W:AF,8,0) -> 10.5
AR57: 9 | AS57: =46/AR57 -> 5.1111111 | BA57: 38200 | BB57: 9.4855108 | BC57: 7.846016 | BD57: =VLOOKUP(BA57,Symphony!A:J,8,0) -> 4.8 | BE57: =(BC57-BB57)^2 -> 2.6879432 | BF57: =(BD57-BB57)^2 -> 21.954012 | BI57: 41275 | BJ57: 39.133241 | BK57: 39.51708 | BL57: =VLOOKUP(BI57,Symphony!L:U,8,0) -> 45.6 | BO57: 41944 | BP57: 3.4268202 | BQ57: 6.1053442 | BR57: =VLOOKUP(BO57,Symphony!W:AF,8,0) -> 9.9
...

Sheet 0515v4
BB1: actual | BC1: model v2 | BD1: model v1 | BE1: Square Error | BG1: RMSE | BJ1: actual | BK1: model v2 | BL1: model v1 | BP1: actual | BQ1: model v2 | BR1: model v1 | BV1: actual | BW1: model v2 | BX1: model v1
AL2: Fix loan size corve | BA2: 36526 | BB2: 1.2535394 | BC2: 1.102312 | BD2: =VLOOKUP(BA2,Symphony!A:J,8,0) -> 1.1 | BE2: =(BC2-BB2)^2 -> 0.022869725 | BF2: =(BD2-BB2)^2 -> 0.023574342 | BG2: =SUM(BC2:BC190)/COUNT(BC2:BC190) -> 14.47563 | BH2: =SUM(BD2:BD190)/COUNT(BD2:BD190) -> 11.056614 | BI2: 39600 | BJ2: 15.996829 | BK2: 2.8692321 | BL2: =VLOOKUP(BI2,Symphony!L:U,8,0) -> 0 | BO2: 40238 | BP2: 0 | BQ2: 1.5412316 | BR2: =VLOOKUP(BO2,Symphony!W:AF,8,0) -> 0.1 | BU2: 41518 | BV2: 0 | BW2: 0.36900499 | BX2: =VLOOKUP(BU2,Symphony!AH:AQ,8,0) -> 0
BA3: 36557 | BB3: 1.1353791 | BC3: 0.88898749 | BD3: =VLOOKUP(BA3,Symphony!A:J,8,0) -> 0.5 | BE3: =(BC3-BB3)^2 -> 0.060708819 | BF3: =(BD3-BB3)^2 -> 0.40370658 | BG3: =SUM(BC2:BC190) -> 2735.894 | BH3: =SUM(BD2:BD190) -> 2089.7 | BI3: 39630 | BJ3: 14.47073 | BK3: 0.89335337 | BL3: =VLOOKUP(BI3,Symphony!L:U,8,0) -> 0 | BO3: 40299 | BP3: 2.3546342 | BQ3: 1.8461067 | BR3: =VLOOKUP(BO3,Symphony!W:AF,8,0) -> 0.1 | BU3: 41548 | BV3: 0 | BW3: 0.69948155 | BX3: =VLOOKUP(BU3,Symphony!AH:AQ,8,0) -> 0
BA4: 36586 | BB4: 1.1811762 | BC4: 0.891973 | BD4: =VLOOKUP(BA4,Symphony!A:J,8,0) -> 0.4 | BE4: =(BC4-BB4)^2 -> 0.083638464 | BF4: =(BD4-BB4)^2 -> 0.61023618 | BG4: =COUNT(BC2:BC190) -> 189 | BH4: =COUNT(BD2:BD190) -> 189 | BI4: 39661 | BJ4: 3.5877677 | BK4: 0.63532943 | BL4: =VLOOKUP(BI4,Symphony!L:U,8,0) -> 0 | BO4: 40330 | BP4: 0 | BQ4: 2.5494255 | BR4: =VLOOKUP(BO4,Symphony!W:AF,8,0) -> 0.1 | BU4: 41579 | BV4: 0 | BW4: 0.74770525 | BX4: =VLOOKUP(BU4,Symphony!AH:AQ,8,0) -> 0
BA5: 36617 | BB5: 1.4526721 | BC5: 1.1181887 | BD5: =VLOOKUP(BA5,Symphony!A:J,8,0) -> 0.3 | BE5: =(BC5-BB5)^2 -> 0.11187916 | BF5: =(BD5-BB5)^2 -> 1.328653 | BI5: 39692 | BJ5: 6.2488483 | BK5: 1.4753515 | BL5: =VLOOKUP(BI5,Symphony!L:U,8,0) -> 0 | BO5: 40360 | BP5: 0 | BQ5: 2.4258926 | BR5: =VLOOKUP(BO5,Symphony!W:AF,8,0) -> 0.2 | BU5: 41609 | BV5: 28.50765 | BW5: 0.41685401 | BX5: =VLOOKUP(BU5,Symphony!AH:AQ,8,0) -> 0
BA6: 36647 | BB6: 1.2976516 | BC6: 1.4198725 | BD6: =VLOOKUP(BA6,Symphony!A:J,8,0) -> 0.4 | BE6: =(BC6-BB6)^2 -> 0.014937965 | BF6: =(BD6-BB6)^2 -> 0.80577834 | BI6: 39722 | BJ6: 25.124779 | BK6: 2.6798276 | BL6: =VLOOKUP(BI6,Symphony!L:U,8,0) -> 0 | BO6: 40391 | BP6: 0 | BQ6: 3.9371497 | BR6: =VLOOKUP(BO6,Symphony!W:AF,8,0) -> 0.2 | BU6: 41640 | BV6: 0.011096823 | BW6: 0.98331072 | BX6: =VLOOKUP(BU6,Symphony!AH:AQ,8,0) -> 0
BA7: 36678 | BB7: 2.0225927 | BC7: 1.0590759 | BD7: =VLOOKUP(BA7,Symphony!A:J,8,0) -> 0.4 | BE7: =(BC7-BB7)^2 -> 0.92836452 | BF7: =(BD7-BB7)^2 -> 2.632807 | BI7: 39753 | BJ7: 13.325528 | BK7: 2.6662738 | BL7: =VLOOKUP(BI7,Symphony!L:U,8,0) -> 4.5 | BO7: 40422 | BP7: 0 | BQ7: 4.8307402 | BR7: =VLOOKUP(BO7,Symphony!W:AF,8,0) -> 0.2 | BU7: 41671 | BV7: 0 | BW7: 2.4013903 | BX7: =VLOOKUP(BU7,Symphony!AH:AQ,8,0) -> 0
BA8: 36708 | BB8: 1.5807117 | BC8: 1.672826 | BD8: =VLOOKUP(BA8,Symphony!A:J,8,0) -> 0.3 | BE8: =(BC8-BB8)^2 -> 0.0084850556 | BF8: =(BD8-BB8)^2 -> 1.6402224 | BI8: 39783 | BJ8: 11.720807 | BK8: 5.8503446 | BL8: =VLOOKUP(BI8,Symphony!L:U,8,0) -> 3.2 | BO8: 40452 | BP8: 1.7488395 | BQ8: 5.297038 | BR8: =VLOOKUP(BO8,Symphony!W:AF,8,0) -> 0.3 | BU8: 41699 | BV8: 24.647675 | BW8: 3.4863476 | BX8: =VLOOKUP(BU8,Symphony!AH:AQ,8,0) -> 0
BA9: 36739 | BB9: 1.5421276 | BC9: 2.388384 | BD9: =VLOOKUP(BA9,Symphony!A:J,8,0) -> 0.4 | BE9: =(BC9-BB9)^2 -> 0.71614992 | BF9: =(BD9-BB9)^2 -> 1.3044554 | BI9: 39814 | BJ9: 25.676602 | BK9: 33.765847 | BL9: =VLOOKUP(BI9,Symphony!L:U,8,0) -> 3.5 | BO9: 40483 | BP9: 3.9109832 | BQ9: 4.7351392 | BR9: =VLOOKUP(BO9,Symphony!W:AF,8,0) -> 0.3 | BU9: 41730 | BV9: 3.5371075 | BW9: 3.3320511 | BX9: =VLOOKUP(BU9,Symphony!AH:AQ,8,0) -> 0
BA10: 36770 | BB10: 2.5043866 | BC10: 3.3462125 | BD10: =VLOOKUP(BA10,Symphony!A:J,8,0) -> 0.5 | BE10: =(BC10-BB10)^2 -> 0.70867093 | BF10: =(BD10-BB10)^2 -> 4.0175656 | BI10: 39845 | BJ10: 25.060766 | BK10: 42.984359 | BL10: =VLOOKUP(BI10,Symphony!L:U,8,0) -> 32.2 | BO10: 40513 | BP10: 3.6766564 | BQ10: 3.9004244 | BR10: =VLOOKUP(BO10,Symphony!W:AF,8,0) -> 0.3 | BU10: 41760 | BV10: 2.5529922 | BW10: 3.2039984 | BX10: =VLOOKUP(BU10,Symphony!AH:AQ,8,0) -> 0
BA11: 36800 | BB11: 2.4512741 | BC11: 4.5672072 | BD11: =VLOOKUP(BA11,Symphony!A:J,8,0) -> 0.9 | BE11: =(BC11-BB11)^2 -> 4.4771727 | BF11: =(BD11-BB11)^2 -> 2.4064513 | BI11: 39873 | BJ11: 33.953462 | BK11: 40.530241 | BL11: =VLOOKUP(BI11,Symphony!L:U,8,0) -> 51.5 | BO11: 40544 | BP11: 5.7761375 | BQ11: 2.9596164 | BR11: =VLOOKUP(BO11,Symphony!W:AF,8,0) -> 0.3 | BU11: 41791 | BV11: 6.3775145 | BW11: 4.3863251 | BX11: =VLOOKUP(BU11,Symphony!AH:AQ,8,0) -> 0
BA12: 36831 | BB12: 3.0477081 | BC12: 4.463726 | BD12: =VLOOKUP(BA12,Symphony!A:J,8,0) -> 1.4 | BE12: =(BC12-BB12)^2 -> 2.0051065 | BF12: =(BD12-BB12)^2 -> 2.7149421 | BI12: 39904 | BJ12: 38.035695 | BK12: 43.102779 | BL12: =VLOOKUP(BI12,Symphony!L:U,8,0) -> 39.4 | BO12: 40575 | BP12: 3.6317529 | BQ12: 2.3371116 | BR12: =VLOOKUP(BO12,Symphony!W:AF,8,0) -> 0.1 | BU12: 41821 | BV12: 8.4648546 | BW12: 3.5785867 | BX12: =VLOOKUP(BU12,Symphony!AH:AQ,8,0) -> 0.1
BA13: 36861 | BB13: 3.1145932 | BC13: 6.0217257 | BD13: =VLOOKUP(BA13,Symphony!A:J,8,0) -> 2.2 | BE13: =(BC13-BB13)^2 -> 8.4514194 | BF13: =(BD13-BB13)^2 -> 0.83648074 | BI13: 39934 | BJ13: 34.34713 | BK13: 46.684262 | BL13: =VLOOKUP(BI13,Symphony!L:U,8,0) -> 51.1 | BO13: 40603 | BP13: 4.4212626 | BQ13: 2.1224182 | BR13: =VLOOKUP(BO13,Symphony!W:AF,8,0) -> 0.1 | BU13: 41852 | BV13: 7.8898601 | BW13: 3.4860708 | BX13: =VLOOKUP(BU13,Symphony!AH:AQ,8,0) -> 0.1
BA14: 36892 | BB14: 5.0764757 | BC14: 14.913297 | BD14: =VLOOKUP(BA14,Symphony!A:J,8,0) -> 3 | BE14: =(BC14-BB14)^2 -> 96.763055 | BF14: =(BD14-BB14)^2 -> 4.3117515 | BI14: 39965 | BJ14: 41.274734 | BK14: 45.30583 | BL14: =VLOOKUP(BI14,Symphony!L:U,8,0) -> 60.7 | BO14: 40634 | BP14: 2.207404 | BQ14: 2.5757817 | BR14: =VLOOKUP(BO14,Symphony!W:AF,8,0) -> 0.1 | BU14: 41883 | BV14: 4.3261102 | BW14: 3.8628412 | BX14: =VLOOKUP(BU14,Symphony!AH:AQ,8,0) -> 0.1
BA15: 36923 | BB15: 20.00396 | BC15: 28.493058 | BD15: =VLOOKUP(BA15,Symphony!A:J,8,0) -> 7.8 | BE15: =(BC15-BB15)^2 -> 72.064778 | BF15: =(BD15-BB15)^2 -> 148.93664 | BI15: 39995 | BJ15: 51.664181 | BK15: 18.751641 | BL15: =VLOOKUP(BI15,Symphony!L:U,8,0) -> 57.3 | BO15: 40664 | BP15: 5.69139 | BQ15: 2.6082146 | BR15: =VLOOKUP(BO15,Symphony!W:AF,8,0) -> 0.1 | BU15: 41913 | BV15: 6.3552727 | BW15: 4.0473741 | BX15: =VLOOKUP(BU15,Symphony!AH:AQ,8,0) -> 0.1
BA16: 36951 | BB16: 26.83627 | BC16: 28.331825 | BD16: =VLOOKUP(BA16,Symphony!A:J,8,0) -> 13.4 | BE16: =(BC16-BB16)^2 -> 2.2366853 | BF16: =(BD16-BB16)^2 -> 180.53335 | BI16: 40026 | BJ16: 33.070951 | BK16: 28.670772 | BL16: =VLOOKUP(BI16,Symphony!L:U,8,0) -> 16.3 | BO16: 40695 | BP16: 4.5115981 | BQ16: 3.1254222 | BR16: =VLOOKUP(BO16,Symphony!W:AF,8,0) -> 0.1 | BU16: 41944 | BV16: 3.9338496 | BW16: 4.4542296 | BX16: =VLOOKUP(BU16,Symphony!AH:AQ,8,0) -> 0.1
... BA26: 37257 | BB26: 24.542736 | BC26: 12.539681 | BD26: =VLOOKUP(BA26,Symphony!A:J,8,0) -> 19.4 | BE26: =(BC26-BB26)^2 -> 144.07332 | BF26: =(BD26-BB26)^2 -> 26.447731 | BI26: 40330 | BJ26: 41.995495 | BK26: 37.824111 | BL26: =VLOOKUP(BI26,Symphony!L:U,8,0) -> 32.5 | BO26: 41000 | BP26: 3.2881293 | BQ26: 6.1034787 | BR26: =VLOOKUP(BO26,Symphony!W:AF,8,0) -> 0.4 | BU26: 42248 | BV26: 5.79433 | BW26: 6.0652144 | BX26: =VLOOKUP(BU26,Symphony!AH:AQ,8,0) -> 0.3
BA27: 37288 | BB27: 17.144156 | BC27: 12.692967 | BD27: =VLOOKUP(BA27,Symphony!A:J,8,0) -> 8.9 | BE27: =(BC27-BB27)^2 -> 19.813086 | BF27: =(BD27-BB27)^2 -> 67.966106 | BI27: 40360 | BJ27: 62.382325 | BK27: 43.449976 | BL27: =VLOOKUP(BI27,Symphony!L:U,8,0) -> 42.8 | BO27: 41030 | BP27: 6.2361495 | BQ27: 6.0960113 | BR27: =VLOOKUP(BO27,Symphony!W:AF,8,0) -> 0.4
BA28: 37316 | BB28: 17.229207 | BC28: 17.049727 | BD28: =VLOOKUP(BA28,Symphony!A:J,8,0) -> 9.3 | BE28: =(BC28-BB28)^2 -> 0.032212969 | BF28: =(BD28-BB28)^2 -> 62.872317 | BI28: 40391 | BJ28: 54.217748 | BK28: 46.963352 | BL28: =VLOOKUP(BI28,Symphony!L:U,8,0) -> 51.1 | BO28: 41061 | BP28: 4.6862508 | BQ28: 5.6912365 | BR28: =VLOOKUP(BO28,Symphony!W:AF,8,0) -> 0.5
BA29: 37347 | BB29: 11.999618 | BC29: 9.4673925 | BD29: =VLOOKUP(BA29,Symphony!A:J,8,0) -> 11.6 | BE29: =(BC29-BB29)^2 -> 6.4121664 | BF29: =(BD29-BB29)^2 -> 0.15969464 | BI29: 40422 | BJ29: 58.550964 | BK29: 50.752726 | BL29: =VLOOKUP(BI29,Symphony!L:U,8,0) -> 56 | BO29: 41091 | BP29: 3.5066665 | BQ29: 5.3835072 | BR29: =VLOOKUP(BO29,Symphony!W:AF,8,0) -> 0.6
BA30: 37377 | BB30: 11.14014 | BC30: 11.117107 | BD30: =VLOOKUP(BA30,Symphony!A:J,8,0) -> 7.3 | BE30: =(BC30-BB30)^2 -> 0.0005305527 | BF30: =(BD30-BB30)^2 -> 14.746677 | BI30: 40452 | BJ30: 53.083728 | BK30: 51.120233 | BL30: =VLOOKUP(BI30,Symphony!L:U,8,0) -> 69.5 | BO30: 41122 | BP30: 4.3441979 | BQ30: 5.1374031 | BR30: =VLOOKUP(BO30,Symphony!W:AF,8,0) -> 0.6
BA31: 37408 | BB31: 10.601735 | BC31: 16.178059 | BD31: =VLOOKUP(BA31,Symphony!A:J,8,0) -> 8.1 | BE31: =(BC31-BB31)^2 -> 31.095394 | BF31: =(BD31-BB31)^2 -> 6.2586775 | BI31: 40483 | BJ31: 64.495353 | BK31: 51.440022 | BL31: =VLOOKUP(BI31,Symphony!L:U,8,0) -> 75.1 | BO31: 41153 | BP31: 3.7691802 | BQ31: 5.2234263 | BR31: =VLOOKUP(BO31,Symphony!W:AF,8,0) -> 0.7
BA32: 37438 | BB32: 15.80622 | BC32: 29.054288 | BD32: =VLOOKUP(BA32,Symphony!A:J,8,0) -> 11 | BE32: =(BC32-BB32)^2 -> 175.51131 | BF32: =(BD32-BB32)^2 -> 23.099751 | BI32: 40513 | BJ32: 54.952043 | BK32: 49.756447 | BL32: =VLOOKUP(BI32,Symphony!L:U,8,0) -> 76.7 | BO32: 41183 | BP32: 4.1025358 | BQ32: 5.5732985 | BR32: =VLOOKUP(BO32,Symphony!W:AF,8,0) -> 0.6
BA33: 37469 | BB33: 28.023003 | BC33: 40.049083 | BD33: =VLOOKUP(BA33,Symphony!A:J,8,0) -> 15.8 | BE33: =(BC33-BB33)^2 -> 144.62658 | BF33: =(BD33-BB33)^2 -> 149.40181 | BI33: 40544 | BJ33: 23.760501 | BK33: 15.193048 | BL33: =VLOOKUP(BI33,Symphony!L:U,8,0) -> 70.9 | BO33: 41214 | BP33: 5.284974 | BQ33: 6.1183736 | BR33: =VLOOKUP(BO33,Symphony!W:AF,8,0) -> 0.7
BA34: 37500 | BB34: 32.991438 | BC34: 44.8685 | BD34: =VLOOKUP(BA34,Symphony!A:J,8,0) -> 22.7 | BE34: =(BC34-BB34)^2 -> 141.06462 | BF34: =(BD34-BB34)^2 -> 105.91369 | BI34: 40575 | BJ34: 15.303476 | BK34: 9.2072614 | BL34: =VLOOKUP(BI34,Symphony!L:U,8,0) -> 17.3 | BO34: 41244 | BP34: 5.1292449 | BQ34: 7.2162199 | BR34: =VLOOKUP(BO34,Symphony!W:AF,8,0) -> 0.8
BA35: 37530 | BB35: 46.555598 | BC35: 48.947564 | BD35: =VLOOKUP(BA35,Symphony!A:J,8,0) -> 34.8 | BE35: =(BC35-BB35)^2 -> 5.7215034 | BF35: =(BD35-BB35)^2 -> 138.19408 | BI35: 40603 | BJ35: 7.7544968 | BK35: 3.6315816 | BL35: =VLOOKUP(BI35,Symphony!L:U,8,0) -> 11.7 | BO35: 41275 | BP35: 4.4049161 | BQ35: 5.9954479 | BR35: =VLOOKUP(BO35,Symphony!W:AF,8,0) -> 0.8
BA36: 37561 | BB36: 44.391856 | BC36: 47.272332 | BD36: =VLOOKUP(BA36,Symphony!A:J,8,0) -> 46.8 | BE36: =(BC36-BB36)^2 -> 8.2971435 | BF36: =(BD36-BB36)^2 -> 5.799159 | BI36: 40634 | BJ36: 5.8152588 | BK36: 4.8205952 | BL36: =VLOOKUP(BI36,Symphony!L:U,8,0) -> 5.5 | BO36: 41306 | BP36: 3.8427588 | BQ36: 5.7579429 | BR36: =VLOOKUP(BO36,Symphony!W:AF,8,0) -> 0.8
BA37: 37591 | BB37: 43.743179 | BC37: 47.031769 | BD37: =VLOOKUP(BA37,Symphony!A:J,8,0) -> 42.1 | BE37: =(BC37-BB37)^2 -> 10.814821 | BF37: =(BD37-BB37)^2 -> 2.7000377 | BI37: 40664 | BJ37: 8.0867463 | BK37: 5.3998976 | BL37: =VLOOKUP(BI37,Symphony!L:U,8,0) -> 6.7 | BO37: 41334 | BP37: 4.4682231 | BQ37: 5.7934517 | BR37: =VLOOKUP(BO37,Symphony!W:AF,8,0) -> 0.8
BA38: 37622 | BB38: 40.428082 | BC38: 45.066666 | BD38: =VLOOKUP(BA38,Symphony!A:J,8,0) -> 40.2 | BE38: =(BC38-BB38)^2 -> 21.516458 | BF38: =(BD38-BB38)^2 -> 0.052021508 | BI38: 40695 | BJ38: 12.600923 | BK38: 9.4555706 | BL38: =VLOOKUP(BI38,Symphony!L:U,8,0) -> 7 | BO38: 41365 | BP38: 5.0909126 | BQ38: 6.2663772 | BR38: =VLOOKUP(BO38,Symphony!W:AF,8,0) -> 0.6
... BA67: 38504 | BB67: 11.774235 | BC67: 12.23549 | BD67: =VLOOKUP(BA67,Symphony!A:J,8,0) -> 10.9 | BE67: =(BC67-BB67)^2 -> 0.21275659 | BF67: =(BD67-BB67)^2 -> 0.76428675 | BI67: 41579 | BJ67: 3.2750731 | BK67: 9.2882411 | BL67: =VLOOKUP(BI67,Symphony!L:U,8,0) -> 3.2 | BO67: 42248 | BP67: 5.8122177 | BQ67: 12.75883 | BR67: =VLOOKUP(BO67,Symphony!W:AF,8,0) -> 17.5
BA68: 38534 | BB68: 12.945005 | BC68: 18.105587 | BD68: =VLOOKUP(BA68,Symphony!A:J,8,0) -> 14.4 | BE68: =(BC68-BB68)^2 -> 26.631607 | BF68: =(BD68-BB68)^2 -> 2.1170115 | BI68: 41609 | BJ68: 3.3417272 | BK68: 7.6998228 | BL68: =VLOOKUP(BI68,Symphony!L:U,8,0) -> 5.8
BA69: 38565 | BB69: 14.128098 | BC69: 12.650897 | BD69: =VLOOKUP(BA69,Symphony!A:J,8,0) -> 19.6 | BE69: =(BC69-BB69)^2 -> 2.1821225 | BF69: =(BD69-BB69)^2 -> 29.941715 | BI69: 41640 | BJ69: 2.64253 | BK69: 4.4859151 | BL69: =VLOOKUP(BI69,Symphony!L:U,8,0) -> 5.1
BA70: 38596 | BB70: 9.4783024 | BC70: 9.2727316 | BD70: =VLOOKUP(BA70,Symphony!A:J,8,0) -> 15.5 | BE70: =(BC70-BB70)^2 -> 0.042259385 | BF70: =(BD70-BB70)^2 -> 36.260841 | BI70: 41671 | BJ70: 2.2120201 | BK70: 4.808789 | BL70: =VLOOKUP(BI70,Symphony!L:U,8,0) -> 3.6
BA71: 38626 | BB71: 8.220598 | BC71: 8.7861806 | BD71: =VLOOKUP(BA71,Symphony!A:J,8,0) -> 12.4 | BE71: =(BC71-BB71)^2 -> 0.31988365 | BF71: =(BD71-BB71)^2 -> 17.467401 | BI71: 41699 | BJ71: 2.8273155 | BK71: 7.7186837 | BL71: =VLOOKUP(BI71,Symphony!L:U,8,0) -> 3.6
BA72: 38657 | BB72: 6.2572786 | BC72: 4.8827541 | BD72: =VLOOKUP(BA72,Symphony!A:J,8,0) -> 11.7 | BE72: =(BC72-BB72)^2 -> 1.8893174 | BF72: =(BD72-BB72)^2 -> 29.623217 | BI72: 41730 | BJ72: 3.5360723 | BK72: 8.0557135 | BL72: =VLOOKUP(BI72,Symphony!L:U,8,0) -> 4.8
BA73: 38687 | BB73: 4.3821714 | BC73: 2.8803688 | BD73: =VLOOKUP(BA73,Symphony!A:J,8,0) -> 5.9 | BE73: =(BC73-BB73)^2 -> 2.2554111 | BF73: =(BD73-BB73)^2 -> 2.3038035 | BI73: 41760 | BJ73: 3.4113012 | BK73: 8.5973817 | BL73: =VLOOKUP(BI73,Symphony!L:U,8,0) -> 4.7
BA74: 38718 | BB74: 2.7522874 | BC74: 3.9348935 | BD74: =VLOOKUP(BA74,Symphony!A:J,8,0) -> 2.8 | BE74: =(BC74-BB74)^2 -> 1.3985572 | BF74: =(BD74-BB74)^2 -> 0.0022764914 | BI74: 41791 | BJ74: 6.1601927 | BK74: 13.898102 | BL74: =VLOOKUP(BI74,Symphony!L:U,8,0) -> 4.8
BA75: 38749 | BB75: 3.0806618 | BC75: 5.1268944 | BD75: =VLOOKUP(BA75,Symphony!A:J,8,0) -> 3 | BE75: =(BC75-BB75)^2 -> 4.1870677 | BF75: =(BD75-BB75)^2 -> 0.0065063338 | BI75: 41821 | BJ75: 6.5807217 | BK75: 14.568939 | BL75: =VLOOKUP(BI75,Symphony!L:U,8,0) -> 6.7
BA76: 38777 | BB76: 3.8368855 | BC76: 4.0972019 | BD76: =VLOOKUP(BA76,Symphony!A:J,8,0) -> 4.4 | BE76: =(BC76-BB76)^2 -> 0.067764635 | BF76: =(BD76-BB76)^2 -> 0.31709795 | BI76: 41852 | BJ76: 5.6859122 | BK76: 15.142814 | BL76: =VLOOKUP(BI76,Symphony!L:U,8,0) -> 6.9
BA77: 38808 | BB77: 2.1681415 | BC77: 3.5144091 | BD77: =VLOOKUP(BA77,Symphony!A:J,8,0) -> 3.1 | BE77: =(BC77-BB77)^2 -> 1.8124365 | BF77: =(BD77-BB77)^2 -> 0.86836028 | BI77: 41883 | BJ77: 5.7710525 | BK77: 16.247815 | BL77: =VLOOKUP(BI77,Symphony!L:U,8,0) -> 7.3
...

Sheet 0601v5
AO58: -->

Sheet 0620v6
AO58: -->

Sheet Symphony
A1: Factor Date(yyyymmdd) | B1: Scham Balance(mm) | C1: Loan Count | D1: Model [301] CPR | E1: Model CPR Curtail Model CPR | F1: Default Model | G1: Turnover Model | H1: Refinance Model | I1: Scham Balance(mm) | J1: CPR | L1: Factor Date(yyyymmdd) | M1: Scham Balance(mm) | N1: Loan Count | O1: Model [301] CPR | P1: Model CPR Curtail Model CPR | Q1: Default Model | R1: Turnover Model | S1: Refinance Model | T1: Scham Balance(mm) | U1: CPR | W1: Factor Date(yyyymmdd) | X1: Scham Balance(mm) | Y1: Loan Count | Z1: Model [301] CPR | AA1: Model CPR Curtail Model CPR | AB1: Default Model | AC1: Turnover Model | AD1: Refinance Model | AE1: Scham Balance(mm) | AF1: CPR | AH1: Factor Date(yyyymmdd) | AI1: Scham Balance(mm) | AJ1: Loan Count | AK1: Model [301] CPR | AL1: Model CPR Curtail Model CPR | AM1: Default Model | AN1: Turnover Model | AO1: Refinance Model | AP1: Scham Balance(mm) | AQ1: CPR
A2: 34335 | B2: 14830 | C2: 136312 | J2: 0.4 | L2: 39600 | M2: 160 | N2: 260 | U2: 0 | W2: 40179 | X2: 140 | Y2: 583 | Z2: 0.2 | AA2: 0.1 | AB2: 0 | AC2: 0 | AD2: 0.1 | AE2: 45 | AF2: 0.1 | AH2: 41091 | AI2: 6760 | AJ2: 31489 | AQ2: 0.3
A3: 34366 | B3: 179363 | C3: -77922 | D3: 1.8 | E3: 0.1 | F3: 0 | G3: 1.2 | H3: 0.5 | I3: 14808 | J3: 28.1 | L3: 39630 | M3: 377 | N3: 614 | U3: 7.3 | W3: 40210 | X3: 281 | Y3: 1151 | Z3: 0.3 | AA3: 0.1 | AB3: 0.1 | AC3: 0 | AD3: 0.1 | AE3: 140 | AF3: 0.1 | AH3: 41122 | AI3: 8813 | AJ3: 41204 | AK3: 0.3 | AL3: 0.1 | AM3: 0.1 | AN3: 0 | AO3: 0 | AP3: 6589 | AQ3: 0.4
A4: 34394 | B4: 182676 | C4: 2543287 | J4: 22.1 | L4: 39661 | M4: 622 | N4: 1027 | U4: 9.2 | W4: 40238 | X4: 455 | Y4: 1859 | Z4: 0.3 | AA4: 0.1 | AB4: 0.1 | AC4: 0 | AD4: 0.1 | AE4: 281 | AF4: 0.8 | AH4: 41153 | AI4: 10828 | AJ4: 50680 | AK4: 0.4 | AL4: 0.2 | AM4: 0.2 | AN4: 0 | AO4: 0 | AP4: 8785 | AQ4: 0.5
A5: 34425 | B5: 187174 | C5: 2546834 | D5: 10.7 | E5: 0.4 | F5: 0.2 | G5: 4 | H5: 6.4 | I5: 159945 | J5: 17.8 | L5: 39692 | M5: 764 | N5: 1277 | U5: 4.2 | W5: 40269 | X5: 646 | Y5: 2617 | Z5: 0.4 | AA5: 0.2 | AB5: 0.1 | AC5: 0 | AD5: 0.1 | AE5: 451 | AF5: 0.7 | AH5: 41183 | AI5: 12550 | AJ5: 59049 | AK5: 0.5 | AL5: 0.2 | AM5: 0.2 | AN5: 0 | AO5: 0 | AP5: 10759 | AQ5: 0.6
A6: 34486 | B6: 5736 | C6: 58168 | J6: 0.2 | L6: 39722 | M6: 816 | N6: 1371 | U6: 6.4 | W6: 40299 | X6: 873 | Y6: 3565 | Z6: 0.5 | AA6: 0.2 | AB6: 0.2 | AC6: 0.1 | AD6: 0.1 | AE6: 640 | AF6: 0.4 | AH6: 41214 | AI6: 14031 | AJ6: 66109 | AK6: 0.6 | AL6: 0.2 | AM6: 0.3 | AN6: 0 | AO6: 0 | AP6: 12466 | AQ6: 1.3
A7: 34516 | B7: 198258 | C7: 2820612 | D7: 1.4 | E7: 0.2 | F7: 0 | G7: 1.1 | H7: 0.1 | I7: 5730 | J7: 8.1 | L7: 39753 | M7: 962 | N7: 1595 | O7: 6.9 | P7: 0.4 | Q7: 0 | R7: 2.1 | S7: 4.5 | T7: 810 | U7: 23.3 | W7: 40330 | X7: 1088 | Y7: 4435 | Z7: 0.6 | AA7: 0.2 | AB7: 0.2 | AC7: 0.1 | AD7: 0.1 | AE7: 872 | AF7: 0.8 | AH7: 41244 | AI7: 15886 | AJ7: 75493 | AK7: 0.7 | AL7: 0.3 | AM7: 0.4 | AN7: 0 | AO7: 0 | AP7: 13957 | AQ7: 1.3
A8: 34547 | B8: 200679 | C8: 2870901 | D8: 6.2 | E8: 0.4 | F8: 0.2 | G8: 5.2 | H8: 0.4 | I8: 180741 | J8: 6.7 | L8: 39783 | M8: 1017 | N8: 1706 | O8: 5.8 | P8: 0.4 | Q8: 0 | R8: 2.2 | S8: 3.2 | T8: 940 | U8: 13.5 | W8: 40360 | X8: 1323 | Y8: 5411 | Z8: 0.8 | AA8: 0.2 | AB8: 0.3 | AC8: 0.1 | AD8: 0.2 | AE8: 1086 | AF8: 0.4 | AH8: 41275 | AI8: 16827 | AJ8: 80164 | AK8: 0.7 | AL8: 0.3 | AM8: 0.4 | AN8: 0 | AO8: 0 | AP8: 15752 | AQ8: 1.7
A9: 34578 | B9: 202941 | C9: 2908429 | D9: 5.7 | E9: 0.4 | F9: 0.2 | G9: 4.8 | H9: 0.3 | I9: 183703 | J9: 5.8 | L9: 39814 | M9: 1109 | N9: 1865 | O9: 6.1 | P9: 0.4 | Q9: 0.1 | R9: 2.2 | S9: 3.5 | T9: 1004 | U9: 12.9 | W9: 40391 | X9: 1563 | Y9: 6388 | Z9: 0.9 | AA9: 0.2 | AB9: 0.3 | AC9: 0.1 | AD9: 0.2 | AE9: 1321 | AF9: 1.2 | AH9: 41306 | AI9: 18038 | AJ9: 86285 | AK9: 0.8 | AL9: 0.3 | AM9: 0.5 | AN9: 0 | AO9: 0 | AP9: 16707 | AQ9: 1.7
A10: 34608 | B10: 205227 | C10: 2946070 | D10: 6.1 | E10: 0.4 | F10: 0.2 | G10: 5.2 | H10: 0.3 | I10: 186367 | J10: 5.7 | L10: 39845 | M10: 1145 | N10: 1888 | O10: 34.5 | P10: 0.5 | Q10: 0.1 | R10: 2.7 | S10: 32.2 | T10: 1095 | U10: 26.3 | W10: 40422 | X10: 1800 | Y10: 7401 | Z10: 1 | AA10: 0.2 | AB10: 0.4 | AC10: 0.1 | AD10: 0.2 | AE10: 1559 | AF10: 1.4 | AH10: 41334 | AI10: 19271 | AJ10: 92651 | AK10: 0.9 | AL10: 0.3 | AM10: 0.6 | AN10: 0 | AO10: 0 | AP10: 17897 | AQ10: 1.7
A11: 34639 | B11: 206975 | C11: 2983794 | D11: 5.2 | E11: 0.4 | F11: 0.3 | G11: 4.3 | H11: 0.3 | I11: 188883 | J11: 5 | L11: 39873 | M11: 1143 | N11: 1884 | O11: 53 | P11: 0.5 | Q11: 0.1 | R11: 2.2 | S11: 51.5 | T11: 1115 | U11: 25.8 | W11: 40452 | X11: 2304 | Y11: 9395 | Z11: 1.1 | AA11: 0.3 | AB11: 0.5 | AC11: 0.2 | AD11: 0.3 | AE11: 1796 | AF11: 0.9 | AH11: 41365 | AI11: 20640 | AJ11: 99757 | AK11: 1 | AL11: 0.3 | AM11: 0.7 | AN11: 0 | AO11: 0 | AP11: 19125 | AQ11: 2.3
A12: 34669 | B12: 207754 | C12: 2996810 | D12: 4.7 | E12: 0.4 | F12: 0.3 | G12: 3.8 | H12: 0.2 | I12: 190959 | J12: 4.7 | L12: 39904 | M12: 1120 | N12: 1821 | O12: 41.4 | P12: 0.5 | Q12: 0.1 | R12: 2.6 | S12: 39.4 | T12: 1114 | U12: 35.4 | W12: 40483 | X12: 2545 | Y12: 10435 | Z12: 1.1 | AA12: 0.2 | AB12: 0.5 | AC12: 0.1 | AD12: 0.3 | AE12: 2285 | AF12: 2 | AH12: 41395 | AI12: 21885 | AJ12: 106455 | AK12: 1.1 | AL12: 0.3 | AM12: 0.7 | AN12: 0 | AO12: 0 | AP12: 20521 | AQ12: 2.2
A13: 34700 | B13: 208406 | C13: 3021274 | D13: 4 | E13: 0.4 | F13: 0.3 | G13: 3.1 | H13: 0.1 | I13: 191957 | J13: 4.6 | L13: 39934 | M13: 1079 | N13: 1743 | O13: 53.3 | P13: 0.5 | Q13: 0.1 | R13: 3.6 | S13: 51.1 | T13: 1079 | U13: 40 | W13: 40513 | X13: 3128 | Y13: 13787 | Z13: 1.2 | AA13: 0.3 | AB13: 0.6 | AC13: 0.1 | AD13: 0.3 | AE13: 2538 | AF13: 1.9 | AH13: 41426 | AI13: 22822 | AJ13: 111487 | AK13: 1.2 | AL13: 0.3 | AM13: 0.8 | AN13: 0 | AO13: 0 | AP13: 21692 | AQ13: 2.7
A14: 34731 | B14: 209359 | C14: 3049573 | D14: 4.1 | E14: 0.4 | F14: 0.3 | G14: 3.3 | H14: 0.1 | I14: 192788 | J14: 3.8 | L14: 39965 | M14: 1033 | N14: 1675 | O14: 62.8 | P14: 0.5 | Q14: 0.1 | R14: 4.3 | S14: 60.7 | T14: 1033 | U14: 36.7 | W14: 40544 | X14: 3904 | Y14: 16944 | Z14: 1.4 | AA14: 0.3 | AB14: 0.7 | AC14: 0.1 | AD14: 0.3 | AE14: 3118 | AF14: 1.9 | AH14: 41456 | AI14: 23570 | AJ14: 115653 | AK14: 1.3 | AL14: 0.3 | AM14: 0.9 | AN14: 0 | AO14: 0 | AP14: 22658 | AQ14: 3.2
A15: 34759 | B15: 210445 | C15: 3069674 | D15: 3.4 | E15: 0.4 | F15: 0.3 | G15: 2.5 | H15: 0.1 | I15: 194024 | J15: 3.4 | L15: 39995 | M15: 993 | N15: 1597 | O15: 59.7 | P15: 0.5 | Q15: 0.2 | R15: 4.8 | S15: 57.3 | T15: 993 | U15: 43.6 | W15: 40575 | X15: 4397 | Y15: 19006 | Z15: 1.2 | AA15: 0.3 | AB15: 0.7 | AC15: 0.1 | AD15: 0.1 | AE15: 3893 | AF15: 2.4 | AH15: 41487 | AI15: 24181 | AJ15: 119179 | AK15: 1.4 | AL15: 0.3 | AM15: 1 | AN15: 0 | AO15: 0 | AP15: 23452 | AQ15: 3.5
A16: 34790 | B16: 212079 | C16: 3094809 | D16: 4.1 | E16: 0.4 | F16: 0.3 | G16: 3.2 | H16: 0.2 | I16: 195308 | J16: 3.7 | L16: 40026 | M16: 946 | N16: 1500 | O16: 21.4 | P16: 0.5 | Q16: 0.2 | R16: 5.3 | S16: 16.3 | T16: 946 | U16: 53.7 | W16: 40603 | X16: 5261 | Y16: 22621 | Z16: 1.2 | AA16: 0.3 | AB16: 0.8 | AC16: 0 | AD16: 0.1 | AE16: 4379 | AF16: 2.1 | AH16: 41518 | AI16: 24584 | AJ16: 121646 | AK16: 1.5 | AL16: 0.3 | AM16: 1.2 | AN16: 0 | AO16: 0 | AP16: 24069 | AQ16: 3.8
A17: 34820 | B17: 214086 | C17: 3125886 | D17: 6.2 | E17: 0.4 | F17: 0.4 | G17: 5 | H17: 0.5 | I17: 197012 | J17: 4.5 | L17: 40057 | M17: 886 | N17: 1446 | O17: 30.9 | P17: 0.5 | Q17: 0.2 | R17: 5.3 | S17: 26.4 | T17: 886 | U17: 35.9 | W17: 40634 | X17: 6141 | Y17: 26305 | Z17: 1.1 | AA17: 0.3 | AB17: 0.8 | AC17: 0 | AD17: 0.1 | AE17: 5221 | AF17: 2.2 | AH17: 41548 | AI17: 24975 | AJ17: 124136 | AK17: 1.6 | AL17: 0.3 | AM17: 1.3 | AN17: 0 | AO17: 0 | AP17: 24463 | AQ17: 3.6
A18: 34851 | B18: 215985 | C18: 3147405 | D18: 7.3 | E18: 0.4 | F18: 0.4 | G18: 5.9 | H18: 0.7 | I18: 198999 | J18: 4.7 | L18: 40087 | M18: 853 | N18: 1392 | O18: 32.9 | P18: 0.5 | Q18: 0.2 | R18: 5.5 | S18: 28.3 | T18: 853 | U18: 37.4 | W18: 40664 | X18: 6849 | Y18: 29403 | Z18: 1.1 | AA18: 0.3 | AB18: 0.8 | AC18: 0 | AD18: 0.1 | AE18: 6118 | AF18: 1.8 | AH18: 41579 | AI18: 25218 | AJ18: 125790 | AK18: 1.8 | AL18: 0.3 | AM18: 1.4 | AN18: 0 | AO18: 0 | AP18: 24864 | AQ18: 3.2
... A36: 35400 | B36: 289245 | C36: 2859341 | D36: 9.3 | E36: 0.5 | F36: 0.5 | G36: 6.6 | H36: 1.9 | I36: 274394 | J36: 6.6 | L36: 40634 | M36: 3017 | N36: 5310 | O36: 7 | P36: 0.3 | Q36: 0.1 | R36: 1.2 | S36: 5.5 | T36: 2640 | U36: 7.7 | W36: 41214 | X36: 24388 | Y36: 112369 | Z36: 3.4 | AA36: 0.3 | AB36: 1.5 | AC36: 0.9 | AD36: 0.7 | AE36: 22958 | AF36: 4.2 | AH36: 42125 | AI36: 24665 | AJ36: 128320 | AK36: 5.6 | AL36: 0.4 | AM36: 4.7 | AN36: 0.4 | AO36: 0.2 | AP36: 24621 | AQ36: 6.3
A37: 35462 | B37: 6910 | C37: 61672 | J37: 0.7 | L37: 40664 | M37: 3577 | N37: 6312 | O37: 8.8 | P37: 0.3 | Q37: 0.1 | R37: 1.8 | S37: 6.7 | T37: 2993 | U37: 5.9 | W37: 41244 | X37: 26151 | Y37: 121233 | Z37: 3.6 | AA37: 0.3 | AB37: 1.6 | AC37: 1 | AD37: 0.8 | AE37: 24216 | AF37: 4.5 | AH37: 42156 | AI37: 24529 | AJ37: 127870 | AK37: 6.1 | AL37: 0.4 | AM37: 4.9 | AN37: 0.5 | AO37: 0.4 | AP37: 24491 | AQ37: 6.9
A38: 35490 | B38: 305559 | C38: 3035039 | D38: 1.6 | E38: 0.2 | F38: 0 | G38: 1.1 | H38: 0.4 | I38: 6899 | J38: 6.3 | L38: 40695 | M38: 4261 | N38: 7494 | O38: 9.5 | P38: 0.4 | Q38: 0.1 | R38: 2.2 | S38: 7 | T38: 3554 | U38: 8.1 | W38: 41275 | X38: 26924 | Y38: 125180 | Z38: 3.6 | AA38: 0.3 | AB38: 1.6 | AC38: 0.9 | AD38: 0.8 | AE38: 25906 | AF38: 4.4 | AH38: 42186 | AI38: 24378 | AJ38: 127357 | AK38: 6.4 | AL38: 0.4 | AM38: 5.1 | AN38: 0.7 | AO38: 0.4 | AP38: 24344 | AQ38: 7.5
A39: 35521 | B39: 308204 | C39: 3056252 | D39: 9.5 | E39: 0.5 | F39: 0.5 | G39: 5.3 | H39: 3.5 | I39: 293808 | J39: 6.4 | L39: 40725 | M39: 5049 | N39: 8850 | O39: 13.3 | P39: 0.4 | Q39: 0.1 | R39: 2.6 | S39: 10.4 | T39: 4201 | U39: 12.2 | W39: 41306 | X39: 28114 | Y39: 131256 | Z39: 3.8 | AA39: 0.3 | AB39: 1.6 | AC39: 1 | AD39: 0.8 | AE39: 26744 | AF39: 4.4 | AH39: 42217 | AI39: 24215 | AJ39: 126805 | AK39: 6.6 | AL39: 0.4 | AM39: 5.3 | AN39: 0.7 | AO39: 0.3 | AP39: 24182 | AQ39: 7.5
A40: 35551 | B40: 310467 | C40: 3064711 | D40: 9.1 | E40: 0.5 | F40: 0.5 | G40: 6.5 | H40: 1.8 | I40: 296551 | J40: 7.8 | L40: 40756 | M40: 5564 | N40: 9707 | O40: 16.9 | P40: 0.4 | Q40: 0.1 | R40: 3.2 | S40: 13.7 | T40: 4989 | U40: 16.8 | W40: 41334 | X40: 29329 | Y40: 137562 | Z40: 3.5 | AA40: 0.3 | AB40: 1.7 | AC40: 0.8 | AD40: 0.8 | AE40: 27934 | AF40: 3.9 | AH40: 42248 | AI40: 24054 | AJ40: 126286 | AK40: 6.9 | AL40: 0.4 | AM40: 5.5 | AN40: 0.7 | AO40: 0.3 | AP40: 24019 | AQ40: 7.4
A41: 35582 | B41: 312257 | C41: 3069222 | D41: 8.3 | E41: 0.5 | F41: 0.5 | G41: 6.6 | H41: 0.8 | I41: 298560 | J41: 7.6 | L41: 40787 | M41: 6014 | N41: 10407 | O41: 17 | P41: 0.4 | Q41: 0.1 | R41: 3.4 | S41: 13.6 | T41: 5464 | U41: 22.2 | W41: 41365 | X41: 30831 | Y41: 145248 | Z41: 3.4 | AA41: 0.3 | AB41: 1.7 | AC41: 0.8 | AD41: 0.6 | AE41: 29117 | AF41: 4.8 | AH41: 42278 | AI41: 23899 | AJ41: 125765 | AK41: 7.5 | AL41: 0.4 | AM41: 5.7 | AN41: 1 | AO41: 0.6 | AP41: 23860 | AQ41: 7.5
A42: 35612 | B42: 315318 | C42: 3105544 | D42: 10 | E42: 0.5 | F42: 0.5 | G42: 7.6 | H42: 1.6 | I42: 300543 | J42: 7.7 | L42: 40817 | M42: 6630 | N42: 11097 | O42: 36.4 | P42: 0.5 | Q42: 0.1 | R42: 3.9 | S42: 33.4 | T42: 5882 | U42: 51.1 | W42: 41395 | X42: 32247 | Y42: 152608 | Z42: 3.9 | AA42: 0.3 | AB42: 1.7 | AC42: 1.2 | AD42: 0.6 | AE42: 30595 | AF42: 5.7 | AH42: 42309 | AI42: 23732 | AJ42: 125228 | AK42: 7.6 | AL42: 0.4 | AM42: 5.9 | AN42: 0.8 | AO42: 0.6 | AP42: 23706 | AQ42: 7.3
A43: 35643 | B43: 318969 | C43: 3137130 | D43: 12.2 | E43: 0.5 | F43: 0.5 | G43: 8.5 | H43: 3 | I43: 303665 | J43: 8.3 | L43: 40848 | M43: 7276 | N43: 12452 | O43: 45.7 | P43: 0.5 | Q43: 0.1 | R43: 3.5 | S43: 43.3 | T43: 6151 | U43: 33.7 | W43: 41426 | X43: 33327 | Y43: 158344 | Z43: 5 | AA43: 0.3 | AB43: 1.6 | AC43: 1.7 | AD43: 1.4 | AE43: 31847 | AF43: 6.5 | AH43: 42339 | AI43: 23575 | AJ43: 124779 | AK43: 7.9 | AL43: 0.4 | AM43: 6.1 | AN43: 0.9 | AO43: 0.7 | AP43: 23544 | AQ43: 6.6
A44: 35674 | B44: 322890 | C44: 3157045 | D44: 13.6 | E44: 0.5 | F44: 0.6 | G44: 8.7 | H44: 4.4 | I44: 307252 | J44: 9.7 | L44: 40878 | M44: 7936 | N44: 13754 | O44: 40 | P44: 0.4 | Q44: 0.1 | R44: 3.5 | S44: 37.4 | T44: 6993 | U44: 26 | W44: 41456 | X44: 34269 | Y44: 163501 | Z44: 7.6 | AA44: 0.3 | AB44: 1.6 | AC44: 2.3 | AD44: 3.4 | AE44: 33000 | AF44: 7.1 | AH44: 42370 | AI44: 23423 | AJ44: 124224 | AK44: 7.8 | AL44: 0.4 | AM44: 6.3 | AN44: 0.7 | AO44: 0.5 | AP44: 23403 | AQ44: 7.2
A45: 35704 | B45: 326223 | C45: 3174759 | D45: 13.4 | E45: 0.5 | F45: 0.6 | G45: 8.7 | H45: 4.2 | I45: 310898 | J45: 10.9 | L45: 40909 | M45: 8282 | N45: 14445 | O45: 43.6 | P45: 0.5 | Q45: 0.1 | R45: 3.3 | S45: 41.2 | T45: 7697 | U45: 23.8 | W45: 41487 | X45: 34933 | Y45: 167337 | Z45: 7.1 | AA45: 0.4 | AB45: 1.6 | AC45: 2.5 | AD45: 2.7 | AE45: 33976 | AF45: 7.4 | AH45: 42401 | AI45: 23264 | AJ45: 123812 | AQ45: 6
A46: 35735 | B46: 331462 | C46: 3201257 | D46: 13.2 | E46: 0.5 | F46: 0.6 | G46: 7.8 | H46: 4.9 | I46: 313971 | J46: 10.3 | L46: 40940 | M46: 9267 | N46: 16282 | O46: 44.4 | P46: 0.5 | Q46: 0.1 | R46: 3.6 | S46: 41.9 | T46: 8084 | U46: 24.6 | W46: 41518 | X46: 35369 | Y46: 170093 | Z46: 7.4 | AA46: 0.4 | AB46: 1.7 | AC46: 2.7 | AD46: 2.9 | AE46: 34627 | AF46: 6.4 | AH46: 42430 | AI46: 23130 | AJ46: 123356 | AQ46: 6.5
A47: 35765 | B47: 335920 | C47: 3265152 | D47: 14.7 | E47: 0.5 | F47: 0.6 | G47: 8 | H47: 6.3 | I47: 319494 | J47: 12 | L47: 40969 | M47: 9986 | N47: 17485 | O47: 41 | P47: 0.5 | Q47: 0.1 | R47: 2.7 | S47: 38.9 | T47: 8950 | U47: 31.8 | W47: 41548 | X47: 35805 | Y47: 172926 | Z47: 8 | AA47: 0.4 | AB47: 1.7 | AC47: 3.1 | AD47: 3 | AE47: 35120 | AF47: 5.3 | AH47: 42461 | AI47: 22981 | AJ47: 122626 | AQ47: 8.9
A48: 35796 | B48: 341078 | C48: 3325510 | D48: 14.9 | E48: 0.5 | F48: 0.6 | G48: 7.2 | H48: 7.2 | I48: 323587 | J48: 12.6 | L48: 41000 | M48: 10994 | N48: 19424 | O48: 38.2 | P48: 0.5 | Q48: 0.1 | R48: 2.9 | S48: 35.9 | T48: 9534 | U48: 28.4 | W48: 41579 | X48: 36130 | Y48: 175002 | Z48: 7.5 | AA48: 0.4 | AB48: 1.8 | AC48: 2.6 | AD48: 2.9 | AE48: 35591 | AF48: 5.3 | AH48: 42491 | AI48: 22785 | AJ48: 121936 | AQ48: 8.6
A49: 35827 | B49: 342378 | C49: 3331629 | D49: 16.2 | E49: 0.5 | F49: 0.6 | G49: 7.5 | H49: 8.3 | I49: 328666 | J49: 11.7 | L49: 41030 | M49: 11137 | N49: 19883 | O49: 30.5 | P49: 0.5 | Q49: 0.1 | R49: 3.8 | S49: 27.3 | T49: 10475 | U49: 21 | W49: 41609 | X49: 36393 | Y49: 177074 | Z49: 9.1 | AA49: 0.4 | AB49: 1.9 | AC49: 2.7 | AD49: 4.3 | AE49: 35911 | AF49: 5.7
A50: 35855 | B50: 347236 | C50: 3316694 | D50: 17.6 | E50: 0.5 | F50: 0.6 | G50: 5.7 | H50: 11.6 | I50: 330385 | J50: 20.6 | L50: 41061 | M50: 11637 | N50: 20760 | O50: 34.9 | P50: 0.5 | Q50: 0.1 | R50: 4.5 | S50: 31.4 | T50: 10865 | U50: 24.7 | W50: 41640 | X50: 36440 | Y50: 177682 | Z50: 8.4 | AA50: 0.4 | AB50: 2 | AC50: 2.5 | AD50: 3.7 | AE50: 36157 | AF50: 6.3
A51: 35886 | B51: 356845 | C51: 3310937 | D51: 17.1 | E51: 0.5 | F51: 0.6 | G51: 6 | H51: 10.9 | I51: 332358 | J51: 26.5 | L51: 41091 | M51: 12347 | N51: 21919 | O51: 41.1 | P51: 0.5 | Q51: 0.1 | R51: 5 | S51: 37.5 | T51: 11330 | U51: 31.6 | W51: 41671 | X51: 36537 | Y51: 178877 | Z51: 7.9 | AA51: 0.4 | AB51: 2.1 | AC51: 2.6 | AD51: 3 | AE51: 36180 | AF51: 4.7
A52: 35916 | B52: 363989 | C52: 3349987 | D52: 17 | E52: 0.5 | F52: 0.5 | G52: 7.6 | H52: 9.2 | I52: 339830 | J52: 26 | L52: 41122 | M52: 12632 | N52: 22301 | O52: 46.4 | P52: 0.5 | Q52: 0.1 | R52: 5.6 | S52: 42.7 | T52: 11918 | U52: 38.5 | W52: 41699 | X52: 36655 | Y52: 179874 | Z52: 7.7 | AA52: 0.4 | AB52: 2.2 | AC52: 2 | AD52: 3.3 | AE52: 36333 | AF52: 5.2
A53: 35947 | B53: 369968 | C53: 3407847 | D53: 17.2 | E53: 0.5 | F53: 0.5 | G53: 8.3 | H53: 8.7 | I53: 347341 | J53: 21.4 | L53: 41153 | M53: 12933 | N53: 22598 | O53: 51 | P53: 0.5 | Q53: 0.1 | R53: 5.5 | S53: 47.6 | T53: 12074 | U53: 47.6 | W53: 41730 | X53: 36681 | Y53: 180259 | Z53: 9 | AA53: 0.4 | AB53: 2.3 | AC53: 2.2 | AD53: 4.3 | AE53: 36438 | AF53: 6.1
A54: 35977 | B54: 377340 | C54: 3485737 | D54: 17.4 | E54: 0.5 | F54: 0.5 | G54: 8.5 | H54: 8.8 | I54: 355266 | J54: 18.3 | L54: 41183 | M54: 13643 | N54: 24218 | O54: 46.3 | P54: 0.5 | Q54: 0.1 | R54: 5.7 | S54: 42.5 | T54: 12218 | U54: 38.4 | W54: 41760 | X54: 36636 | Y54: 180425 | Z54: 10.7 | AA54: 0.4 | AB54: 2.4 | AC54: 3.5 | AD54: 4.8 | AE54: 36434 | AF54: 6.5
A55: 36008 | B55: 386367 | C55: 3499598 | D55: 19.6 | E55: 0.5 | F55: 0.5 | G55: 8.6 | H55: 11 | I55: 363935 | J55: 18.6 | L55: 41214 | M55: 14818 | N55: 26198 | O55: 50.6 | P55: 0.5 | Q55: 0.1 | R55: 4.8 | S55: 47.6 | T55: 13062 | U55: 43.2 | W55: 41791 | X55: 36550 | Y55: 180384 | Z55: 12.8 | AA55: 0.4 | AB55: 2.4 | AC55: 4.6 | AD55: 5.9 | AE55: 36376 | AF55: 7.1
A56: 36039 | B56: 391656 | C56: 3482462 | D56: 20.1 | E56: 0.5 | F56: 0.5 | G56: 8.7 | H56: 11.5 | I56: 357265 | J56: 19.9 | L56: 41244 | M56: 16088 | N56: 28696 | O56: 51.8 | P56: 0.5 | Q56: 0.1 | R56: 4.7 | S56: 49 | T56: 14110 | U56: 38.1 | W56: 41821 | X56: 36430 | Y56: 180157 | Z56: 16.6 | AA56: 0.4 | AB56: 2.4 | AC56: 5.9 | AD56: 8.7 | AE56: 36271 | AF56: 7.8
A57: 36069 | B57: 395905 | C57: 3467292 | D57: 20.7 | E57: 0.5 | F57: 0.5 | G57: 8.9 | H57: 11.9 | I57: 350040 | J57: 19.5 | L57: 41275 | M57: 15943 | N57: 28485 | O57: 48.3 | P57: 0.5 | Q57: 0.1 | R57: 4.2 | S57: 45.6 | T57: 15383 | U57: 38.5 | W57: 41852 | X57: 36253 | Y57: 179613 | Z57: 17.9 | AA57: 0.4 | AB57: 2.5 | AC57: 6.6 | AD57: 9.3 | AE57: 36128 | AF57: 8.6
...

Sheet Spline
A1: $baselineConstant | M1: $baselineConstant
A2: [1] | B2: 0.00156602 | E2: =1-(1-B2)^12 -> 0.018631222 | M2: [1] | N2: 0.00156602
G3: min | H3: max
A4: $adjustmentFactor | F4: incentive | G4: 0.1881784 | H4: 8.0787627 | M4: $adjustmentFactor
A5: [1] | B5: 1 | F5: media | G5: 1.750085 | H5: 8.019768 | M5: [1] | N5: 1
F6: creditAvailability | G6: 0.2997271 | H6: 1.0222064
A7: $incentiveSpline | F7: burnout | G7: 0.0265197 | H7: 1.0908822 | M7: $incentiveSpline
B8: incentiveKnots | C8: incentiveKnotValues | F8: wacls | G8: 0.9928522 | H8: 2.3261874 | O8: incentiveKnotValues | P8: incentiveKnotValues
A9: 1 | B9: -82.41878 | C9: 0.1881784 | F9: cltv | G9: 1.021494 | H9: 1.935855 | M9: 1 | N9: -82.41878 | O9: 0.1881784 | P9: 0.1881784
A10: 2 | B10: -91.57643 | C10: 0.1885555 | F10: refiElig | G10: 0.2140407 | H10: 0.9438382 | M10: 2 | N10: -91.57643 | O10: 0.1885555 | P10: 0.1885555
A11: 3 | B11: -25.26403 | C11: 0.6278052 | F11: pct_HARP | G11: 0.4509201 | H11: 0.8744477 | M11: 3 | N11: -25.26403 | O11: 0.6278052 | P11: 0.6278052
A12: 4 | B12: 45.95287 | C12: 2.7178946 | F12: pct_tpo | G12: 1.124353 | H12: 1.335878 | M12: 4 | N12: 45.95287 | O12: 2.7178946 | P12: 2.7178946
A13: 5 | B13: 180.74843 | C13: 7.1311858 | F13: Multiplier | G13: =PRODUCT(G4:G12) -> 0.00028809956 | H13: =PRODUCT(H4:H12) -> 358.70615 | M13: 5 | N13: 180.74843 | O13: 7.1311858 | P13: 7.1311858
A14: 6 | B14: 265.79655 | C14: 8.0626374 | M14: 6 | N14: 265.79655 | O14: 8.0626374 | P14: 8.0626374
A15: 7 | B15: 292.37621 | C15: 8.0787627 | M15: 7 | N15: 292.37621 | O15: 8.0787627 | P15: 8.0787627
A17: $mediaSpline | M17: $mediaSpline
B18: mediaKnots | C18: mediaKnotValues | O18: mediaKnotValues | P18: mediaKnotValues
A19: 1 | B19: 8.771141 | C19: 1.750085 | M19: 1 | N19: 8.771141 | O19: 1.750085 | P19: 1.750085
A20: 2 | B20: 9.745712 | C20: 1.753592 | M20: 2 | N20: 9.745712 | O20: 1.753592 | P20: 1.753592
A21: 3 | B21: 35.169708 | C21: 3.344232 | M21: 3 | N21: 35.169708 | O21: 3.344232 | P21: 3.344232
A22: 4 | B22: 68.790867 | C22: 7.509477 | M22: 4 | N22: 68.790867 | O22: 7.509477 | P22: 7.509477
A23: 5 | B23: 86.652726 | C23: 8.003761 | M23: 5 | N23: 86.652726 | O23: 8.003761 | P23: 8.003761
A24: 6 | B24: 95.317998 | C24: 8.019768 | M24: 6 | N24: 95.317998 | O24: 8.019768 | P24: 8.019768
A26: $creditAvailabilitySpline | M26: $creditAvailabilitySpline
B27: creditAvailabilityKnots | C27: creditAvailabilityKnotValues | O27: creditAvailabilityKnotValues | P27: creditAvailabilityKnotValues
A28: 1 | B28: 79.75881 | C28: 0.2997271 | M28: 1 | N28: 79.75881 | O28: 0.2997271 | P28: 0.2997271
A29: 2 | B29: 88.6209 | C29: 0.3003278 | M29: 2 | N29: 88.6209 | O29: 0.3003278 | P29: 0.3003278
A30: 3 | B30: 104.96013 | C30: 0.5871067 | M30: 3 | N30: 104.96013 | O30: 0.5871067 | P30: 0.5871067
A31: 4 | B31: 122.14821 | C31: 1.020166 | M31: 4 | N31: 122.14821 | O31: 1.020166 | P31: 1.020166
A32: 5 | B32: 134.36303 | C32: 1.0222064 | M32: 5 | N32: 134.36303 | O32: 1.0222064 | P32: 1.0222064
A34: $walaSpline | M34: $walaSpline
B35: walaKnots | C35: walaKnotValues | O35: walaKnotValues | P35: walaKnotValues
A36: 1 | B36: 1.494576 | C36: 0.5340185 | M36: 1 | N36: 1.494576 | O36: 0.5340185 | P36: 0.5340185
A37: 2 | B37: 1.660641 | C37: 0.5350887 | M37: 2 | N37: 1.660641 | O37: 0.5350887 | P37: 0.5350887
A38: 3 | B38: 3.997196 | C38: 0.7759459 | M38: 3 | N38: 3.997196 | O38: 0.7759459 | P38: 0.7759459
A39: 4 | B39: 7.520243 | C39: 0.937447 | M39: 4 | N39: 7.520243 | O39: 0.937447 | P39: 0.937447
A40: 5 | B40: 18.753596 | C40: 1.1408688 | M40: 5 | N40: 18.753596 | O40: 1.1408688 | P40: 1.1408688
A41: 6 | B41: 41.257911 | C41: 1.1522775 | M41: 6 | N41: 41.257911 | O41: 1.1522775 | P41: 1.1522775
A43: $burnoutSpline | M43: $burnoutSpline
B44: burnoutKnots | C44: burnoutKnotValues | O44: burnoutKnotValues | P44: burnoutKnotValues
...
