Workbook
Name temp: Sheet4!$A$1:$D$1305

Sheet 0415
E110: 0.001094 | F110: =1-(1-E110)^12 -> 0.013049296
E111: 0.01682 | F111: =1-(1-E111)^12 -> 0.1841761
F115: Min. | G115: 1st Qu. | H115: Median | I115: Mean | J115: 3rd Qu. | K115: Max.
E116: smm | F116: 0.001094 | G116: 0.006086 | H116: 0.007443 | I116: 0.007492 | J116: 0.008765 | K116: 0.01682
E117: cpr | F117: =1-(1-F116)^12 -> 0.013049296 | G117: =1-(1-G116)^12 -> 0.07063632 | H117: =1-(1-H116)^12 -> 0.085748927 | I117: =1-(1-I116)^12 -> 0.086290391 | J117: =1-(1-J116)^12 -> 0.1002548 | K117: =1-(1-K116)^12 -> 0.1841761
D312: rmse
C313: v2 | D313: 0.01972951 | E313: 177923.8 | F313: 1.21837
C314: v1 | D314: 0.01973536 | E314: 185634.4 | F314: 1.303067

Sheet 0603

Sheet Sheet2
B2: wala
B36: wala+hpa
B70: wala+hpa+lockin
B104: wala+hpa+lockIn+cltv
B172: seasonality

Sheet Sheet3
A1: $baselineConstant
A2: [1] | B2: 0.004987769
A4: $adjustmentFactor | U4: 95000
A5: [1] | B5: 1 | H5: baseline | I5: =1-(1-B2)^12 -> 0.058238285 | U5: =225*8 -> 1800 | V5: =52*5 -> 260
U6: =U4/U5 -> 52.777778
A7: $walaSpline | U7: =U6*6.125 -> 323.26389
B8: walaKnots | C8: walaKnotValues | I8: min | J8: max
A9: 1 | B9: 0 | C9: 0 | H9: wala | I9: =MIN(C9:C15) -> 0 | J9: =MAX(C9:C15) -> 1.5709575
A10: 2 | B10: 2.828915 | C10: 0.3576073 | H10: hpa | I10: =C19 -> 0.6947943 | J10: =C25 -> 1.5309615
A11: 3 | B11: 6.974569 | C11: 0.6140533 | H11: lockin | I11: =C29 -> 0.4745794 | J11: =C33 -> 1.1483328
A12: 4 | B12: 14.446979 | C12: 0.9605929 | H12: cltv | I12: =C41 -> 0.0799046 | J12: =C37 -> 0.98716564
A13: 5 | B13: 34.647005 | C13: 1.2251989 | H13: seasonality | I13: =MIN(C54:C65) -> 0.6834917 | J13: =MAX(C54:C65) -> 1.241067
A14: 6 | B14: 125.69886 | C14: 1.5678218 | H14: Multiplier | I14: =PRODUCT(I9:I13) -> 0 | J14: =PRODUCT(J9:J13) -> 3.3836212
A15: 7 | B15: 138.26875 | C15: 1.5709575 | J15: =I5*J14 -> 0.1970563
A17: $hpa2yrSpline
B18: hpa2yrKnots | C18: hpa2yrKnotValues
A19: 1 | B19: 84.00417 | C19: 0.6947943
A20: 2 | B20: 93.33797 | C20: 0.6961866
A21: 3 | B21: 105.97197 | C21: 0.7947514
A22: 4 | B22: 111.60619 | C22: 1.0720002
A23: 5 | B23: 117.4251 | C23: 1.4195463
A24: 6 | B24: 122.05362 | C24: 1.5279056
A25: 7 | B25: 134.25898 | C25: 1.5309615
A27: $incentiveSpline
B28: incentiveKnots | C28: incentiveKnotValues
A29: 1 | B29: -397.85229 | C29: 0.4745794
A30: 2 | B30: -265.23486 | C30: 0.4755304
A31: 3 | B31: -77.824624 | C31: 0.960728
A32: 4 | B32: -37.776615 | C32: 1.1460407
A33: 5 | B33: -3.777661 | C33: 1.1483328
A35: $cltvSpline
B36: cltvKnots | C36: cltvKnotValues
A37: 1 | B37: 49.17447 | C37: 0.98716564
A38: 2 | B38: 54.6383 | C38: 0.98519525
A39: 3 | B39: 94.54368 | C39: 0.67408208
A40: 4 | B40: 115.13824 | C40: 0.08006473
A41: 5 | B41: 126.65206 | C41: 0.0799046
A43: $pct_PURCHSpline
B44: pct_PURCHKnots | C44: pct_PURCHKnotValues
A45: 1 | B45: 13.85285 | C45: 0.8513775
...

Sheet Sheet4
A1: asof | B1: distributionType | C1: subType | D1: sum(purp.rpb) | I1: Sum of sum(purp.rpb) | J1: Column Labels
A2: 37773 | B2: N/A | C2: 3 | D2: 4.9922128e+08 | J2: BRW | L2: HBUY | N2: MOD | O2: MTGINS | Q2: N/A | R2: NAPURP | S2: PURCH | U2: RE-FI | Z2: (blank) | AA2: Grand Total | AH2: BRW | AJ2: HBUY | AL2: MOD | AM2: MTGINS | AO2: N/A | AP2: NAPURP | AQ2: PURCH | AS2: RE-FI | AX2: Grand Total
A3: 37773 | B3: PURCH | C3: 1 | D3: 9.7922399e+10 | I3: Row Labels | J3: 1 | K3: >1 | L3: 1st | M3: N/A | N3: LM | O3: N/A | P3: Y | Q3: 3 | R3: ALL | S3: 1 | T3: ALL | U3: 2 | V3: ALL | W3: CO | X3: N/S | Y3: NCO | Z3: (blank) | AG3: Row Labels | AH3: 1 | AI3: >1 | AJ3: 1st | AK3: N/A | AL3: LM | AM3: N/A | AN3: Y | AO3: 3 | AP3: ALL | AQ3: 1 | AR3: ALL | AS3: 2 | AT3: ALL | AU3: CO | AV3: N/S | AW3: NCO
A4: 37773 | B4: RE-FI | C4: 2 | D4: 2.8199006e+11 | I4: 37773 | J4: 0 | K4: 0 | L4: 0 | M4: 0 | N4: 0 | O4: 0 | P4: 0 | Q4: 0.0013123185 | R4: 0 | S4: 0.25741165 | T4: 0 | U4: 0.74127603 | V4: 0 | W4: 0 | X4: 0 | Y4: 0 | Z4: 0 | AA4: 1 | AG4: 37773 | AH4: 0 | AI4: 0 | AJ4: 0 | AK4: 0 | AL4: 0 | AM4: 0 | AN4: 0 | AO4: 0.0013123185 | AP4: 0 | AQ4: 0.25741165 | AR4: 0 | AS4: 0.74127603 | AT4: 0 | AU4: 0 | AV4: 0 | AW4: 0 | AX4: 1
A5: 37803 | B5: N/A | C5: 3 | D5: 5.2106394e+08 | I5: 37803 | J5: 0 | K5: 0 | L5: 0 | M5: 0 | N5: 0 | O5: 0 | P5: 0 | Q5: 0.0012541173 | R5: 0 | S5: 0.24899753 | T5: 0 | U5: 0.74974835 | V5: 0 | W5: 0 | X5: 0 | Y5: 0 | Z5: 0 | AA5: 1 | AG5: 37803 | AH5: 0 | AI5: 0 | AJ5: 0 | AK5: 0 | AL5: 0 | AM5: 0 | AN5: 0 | AO5: 0.0012541173 | AP5: 0 | AQ5: 0.24899753 | AR5: 0 | AS5: 0.74974835 | AT5: 0 | AU5: 0 | AV5: 0 | AW5: 0 | AX5: 1
A6: 37803 | B6: PURCH | C6: 1 | D6: 1.0345414e+11 | I6: 37834 | J6: 0 | K6: 0 | L6: 0 | M6: 0 | N6: 0 | O6: 0 | P6: 0 | Q6: 0.0011725725 | R6: 0 | S6: 0.24207859 | T6: 0 | U6: 0.75674884 | V6: 0 | W6: 0 | X6: 0 | Y6: 0 | Z6: 0 | AA6: 1 | AG6: 37834 | AH6: 0 | AI6: 0 | AJ6: 0 | AK6: 0 | AL6: 0 | AM6: 0 | AN6: 0 | AO6: 0.0011725725 | AP6: 0 | AQ6: 0.24207859 | AR6: 0 | AS6: 0.75674884 | AT6: 0 | AU6: 0 | AV6: 0 | AW6: 0 | AX6: 1
A7: 37803 | B7: RE-FI | C7: 2 | D7: 3.115074e+11 | I7: 37865 | J7: 0 | K7: 0 | L7: 0 | M7: 0 | N7: 0 | O7: 0 | P7: 0 | Q7: 0.0010723894 | R7: 0 | S7: 0.23094222 | T7: 0 | U7: 0.76798539 | V7: 0 | W7: 0 | X7: 0 | Y7: 0 | Z7: 0 | AA7: 1 | AG7: 37865 | AH7: 0 | AI7: 0 | AJ7: 0 | AK7: 0 | AL7: 0 | AM7: 0 | AN7: 0 | AO7: 0.0010723894 | AP7: 0 | AQ7: 0.23094222 | AR7: 0 | AS7: 0.76798539 | AT7: 0 | AU7: 0 | AV7: 0 | AW7: 0 | AX7: 1
A8: 37834 | B8: N/A | C8: 3 | D8: 5.4256902e+08 | I8: 37895 | J8: 0 | K8: 0 | L8: 0 | M8: 0 | N8: 0 | O8: 0 | P8: 0 | Q8: 0.0010320325 | R8: 0 | S8: 0.22580108 | T8: 0 | U8: 0.77316689 | V8: 0 | W8: 0 | X8: 0 | Y8: 0 | Z8: 0 | AA8: 1 | AG8: 37895 | AH8: 0 | AI8: 0 | AJ8: 0 | AK8: 0 | AL8: 0 | AM8: 0 | AN8: 0 | AO8: 0.0010320325 | AP8: 0 | AQ8: 0.22580108 | AR8: 0 | AS8: 0.77316689 | AT8: 0 | AU8: 0 | AV8: 0 | AW8: 0 | AX8: 1
A9: 37834 | B9: PURCH | C9: 1 | D9: 1.1201383e+11 | I9: 37926 | J9: 0 | K9: 0 | L9: 0 | M9: 0 | N9: 0 | O9: 0 | P9: 0 | Q9: 0.0010091196 | R9: 0 | S9: 0.22569114 | T9: 0 | U9: 0.77329974 | V9: 0 | W9: 0 | X9: 0 | Y9: 0 | Z9: 0 | AA9: 1 | AG9: 37926 | AH9: 0 | AI9: 0 | AJ9: 0 | AK9: 0 | AL9: 0 | AM9: 0 | AN9: 0 | AO9: 0.0010091196 | AP9: 0 | AQ9: 0.22569114 | AR9: 0 | AS9: 0.77329974 | AT9: 0 | AU9: 0 | AV9: 0 | AW9: 0 | AX9: 1
A10: 37834 | B10: RE-FI | C10: 2 | D10: 3.5016042e+11 | I10: 37956 | J10: 0 | K10: 0 | L10: 0 | M10: 0 | N10: 0 | O10: 0 | P10: 0 | Q10: 0.001018541 | R10: 0 | S10: 0.22843396 | T10: 0 | U10: 0.7705475 | V10: 0 | W10: 0 | X10: 0 | Y10: 0 | Z10: 0 | AA10: 1 | AG10: 37956 | AH10: 0 | AI10: 0 | AJ10: 0 | AK10: 0 | AL10: 0 | AM10: 0 | AN10: 0 | AO10: 0.001018541 | AP10: 0 | AQ10: 0.22843396 | AR10: 0 | AS10: 0.7705475 | AT10: 0 | AU10: 0 | AV10: 0 | AW10: 0 | AX10: 1
A11: 37865 | B11: N/A | C11: 3 | D11: 5.6646959e+08 | I11: 37987 | J11: 0 | K11: 0 | L11: 0 | M11: 0 | N11: 0 | O11: 0 | P11: 0 | Q11: 0.0010179887 | R11: 0 | S11: 0.23227881 | T11: 0 | U11: 0.7667032 | V11: 0 | W11: 0 | X11: 0 | Y11: 0 | Z11: 0 | AA11: 1 | AG11: 37987 | AH11: 0 | AI11: 0 | AJ11: 0 | AK11: 0 | AL11: 0 | AM11: 0 | AN11: 0 | AO11: 0.0010179887 | AP11: 0 | AQ11: 0.23227881 | AR11: 0 | AS11: 0.7667032 | AT11: 0 | AU11: 0 | AV11: 0 | AW11: 0 | AX11: 1
A12: 37865 | B12: PURCH | C12: 1 | D12: 1.219909e+11 | I12: 38018 | J12: 0 | K12: 0 | L12: 0 | M12: 0 | N12: 0 | O12: 0 | P12: 0 | Q12: 0.0010145987 | R12: 0 | S12: 0.23626733 | T12: 0 | U12: 0.76271807 | V12: 0 | W12: 0 | X12: 0 | Y12: 0 | Z12: 0 | AA12: 1 | AG12: 38018 | AH12: 0 | AI12: 0 | AJ12: 0 | AK12: 0 | AL12: 0 | AM12: 0 | AN12: 0 | AO12: 0.0010145987 | AP12: 0 | AQ12: 0.23626733 | AR12: 0 | AS12: 0.76271807 | AT12: 0 | AU12: 0 | AV12: 0 | AW12: 0 | AX12: 1
A13: 37865 | B13: RE-FI | C13: 2 | D13: 4.0567389e+11 | I13: 38047 | J13: 0 | K13: 0 | L13: 0 | M13: 0 | N13: 0 | O13: 0 | P13: 0 | Q13: 0.0010219212 | R13: 0 | S13: 0.23996882 | T13: 0 | U13: 0.75900926 | V13: 0 | W13: 0 | X13: 0 | Y13: 0 | Z13: 0 | AA13: 1 | AG13: 38047 | AH13: 0 | AI13: 0 | AJ13: 0 | AK13: 0 | AL13: 0 | AM13: 0 | AN13: 0 | AO13: 0.0010219212 | AP13: 0 | AQ13: 0.23996882 | AR13: 0 | AS13: 0.75900926 | AT13: 0 | AU13: 0 | AV13: 0 | AW13: 0 | AX13: 1
A14: 37895 | B14: N/A | C14: 3 | D14: 6.0009964e+08 | I14: 38078 | J14: 0 | K14: 0 | L14: 0 | M14: 0 | N14: 0 | O14: 0 | P14: 0 | Q14: 0.001033901 | R14: 0 | S14: 0.24109034 | T14: 0 | U14: 0.75787576 | V14: 0 | W14: 0 | X14: 0 | Y14: 0 | Z14: 0 | AA14: 1 | AG14: 38078 | AH14: 0 | AI14: 0 | AJ14: 0 | AK14: 0 | AL14: 0 | AM14: 0 | AN14: 0 | AO14: 0.001033901 | AP14: 0 | AQ14: 0.24109034 | AR14: 0 | AS14: 0.75787576 | AT14: 0 | AU14: 0 | AV14: 0 | AW14: 0 | AX14: 1
A15: 37895 | B15: PURCH | C15: 1 | D15: 1.3129737e+11 | I15: 38108 | J15: 0 | K15: 0 | L15: 0 | M15: 0 | N15: 0 | O15: 0 | P15: 0 | Q15: 0.00087222252 | R15: 0 | S15: 0.24023966 | T15: 0 | U15: 0.75888812 | V15: 0 | W15: 0 | X15: 0 | Y15: 0 | Z15: 0 | AA15: 1 | AG15: 38108 | AH15: 0 | AI15: 0 | AJ15: 0 | AK15: 0 | AL15: 0 | AM15: 0 | AN15: 0 | AO15: 0.00087222252 | AP15: 0 | AQ15: 0.24023966 | AR15: 0 | AS15: 0.75888812 | AT15: 0 | AU15: 0 | AV15: 0 | AW15: 0 | AX15: 1
... A158: 39356 | B158: N/A | C158: 3 | D158: 5.2311355e+08 | I158: 42461 | J158: 0.14259644 | K158: 0.18885541 | L158: 0.036793535 | M158: 0.0001386514 | N158: 0.002305466 | O158: 1.1157659e-06 | P158: 0.059280313 | Q158: 0 | R158: 1.2197961e-05 | S158: 0 | T158: 0.1177634 | U158: 0 | V158: 0.22612674 | W158: 0.063962711 | X158: 0.010835992 | Y158: 0.15132804 | Z158: 0 | AA158: 1 | AG158: 42461 | AH158: 0.14259644 | AI158: 0.18885541 | AJ158: 0.036793535 | AK158: 0.0001386514 | AL158: 0.002305466 | AM158: 1.1157659e-06 | AN158: 0.059280313 | AO158: 0 | AP158: 1.2197961e-05 | AQ158: 0 | AR158: 0.1177634 | AS158: 0 | AT158: 0.22612674 | AU158: 0.063962711 | AV158: 0.010835992 | AW158: 0.15132804 | AX158: 1
A159: 39356 | B159: PURCH | C159: 1 | D159: 9.155368e+11 | I159: (blank) | J159: #DIV/0! | K159: #DIV/0! | L159: #DIV/0! | M159: #DIV/0! | N159: #DIV/0! | O159: #DIV/0! | P159: #DIV/0! | Q159: #DIV/0! | R159: #DIV/0! | S159: #DIV/0! | T159: #DIV/0! | U159: #DIV/0! | V159: #DIV/0! | W159: #DIV/0! | X159: #DIV/0! | Y159: #DIV/0! | Z159: #DIV/0! | AA159: #DIV/0!
A160: 39356 | B160: RE-FI | C160: 2 | D160: 1.3430731e+12 | I160: Grand Total | J160: 0.12830883 | K160: 0.17338954 | L160: 0.029386216 | M160: 0.0056169222 | N160: 0.00045067573 | O160: 0.0054513944 | P160: 0.044084454 | Q160: 5.6819749e-05 | R160: 3.8629806e-05 | S160: 0.046423776 | T160: 0.12310552 | U160: 0.084539837 | V160: 0.10530395 | W160: 0.076377622 | X160: 0.050849944 | Y160: 0.12661587 | Z160: 0 | AA160: 1
A161: 39387 | B161: N/A | C161: 3 | D161: 503502255
A162: 39387 | B162: PURCH | C162: 1 | D162: 9.6191803e+11
A163: 39387 | B163: RE-FI | C163: 2 | D163: 1.3749695e+12
A164: 39417 | B164: N/A | C164: 3 | D164: 4.9269486e+08
A165: 39417 | B165: PURCH | C165: 1 | D165: 9.9297061e+11
A166: 39417 | B166: RE-FI | C166: 2 | D166: 1.4009072e+12
A167: 39448 | B167: N/A | C167: 3 | D167: 4.8390549e+08
A168: 39448 | B168: PURCH | C168: 1 | D168: 1.0079021e+12
A169: 39448 | B169: RE-FI | C169: 2 | D169: 1.4137532e+12
A170: 39479 | B170: N/A | C170: 3 | D170: 4.7453828e+08
A171: 39479 | B171: PURCH | C171: 1 | D171: 1.034383e+12
A172: 39479 | B172: RE-FI | C172: 2 | D172: 1.44511e+12
... A182: 39600 | B182: BRW | C182: 1 | D182: 6.826793e+11
A183: 39600 | B183: BRW | C183: >1 | D183: 7.8228397e+11
A184: 39600 | B184: HBUY | C184: 1st | D184: 1.862525e+11
A185: 39600 | B185: HBUY | C185: N/A | D185: 6.5891714e+10
A186: 39600 | B186: MTGINS | C186: N/A | D186: 6.4345971e+10
A187: 39600 | B187: MTGINS | C187: Y | D187: 2.5439239e+11
A188: 39600 | B188: NAPURP | C188: ALL | D188: 4.3927177e+08
A189: 39600 | B189: PURCH | C189: ALL | D189: 1.0711663e+12
A190: 39600 | B190: RE-FI | C190: CO | D190: 4.8350873e+11
A191: 39600 | B191: RE-FI | C191: N/S | D191: 7.6167967e+11
...

Sheet V2
A1: Total | C1: Actual | D1: Model V2 | E1: Model V1 | G1: Coventional | I1: Actual | J1: Model V2 | K1: Model V1 | M1: Jumbo | O1: Actual | P1: Model V2 | Q1: Model V1 | S1: CQ | U1: Actual | V1: Model V2 | W1: Model V1 | Y1: CR | AA1: Actual | AB1: Model V2 | AC1: Model V1
A2: [1,] | B2: 34366 | C2: 0.52955312 | D2: 1.2224822 | E2: ='v1'!D2 -> 1.0126187 | G2: [1,] | H2: 34366 | I2: 0.52955312 | J2: 1.2224822 | K2: ='v1'!J2 -> 1.0126187 | M2: [1,] | N2: 39600 | O2: 0.3312982 | P2: 0.70777887 | Q2: ='v1'!P2 -> 0.86242858 | S2: [1,] | T2: 40118 | U2: 0 | V2: 0.075126622 | W2: ='v1'!V2 -> 0.074460925 | Y2: [1,] | Z2: 41091 | AA2: 2.0789498 | AB2: 0.075717739 | AC2: ='v1'!AB2 -> 0.00011999219
A3: [2,] | B3: 34394 | C3: 0.84363937 | D3: 1.9459622 | E3: ='v1'!D3 -> 1.6178198 | G3: [2,] | H3: 34394 | I3: 0.84363937 | J3: 1.9459622 | K3: ='v1'!J3 -> 1.6178198 | M3: [2,] | N3: 39630 | O3: 4.6405563 | P3: 1.1942045 | Q3: ='v1'!P3 -> 1.0439701 | S3: [2,] | T3: 40148 | U3: 0.067238957 | V3: 0.053905519 | W3: ='v1'!V3 -> 0.056165954 | Y3: [2,] | Z3: 41122 | AA3: 0.12978227 | AB3: 0.081192588 | AC3: ='v1'!AB3 -> 0.00017698087
A4: [3,] | B4: 34486 | C4: 0.95767199 | D4: 1.1850755 | E4: ='v1'!D4 -> 1.0724392 | G4: [3,] | H4: 34486 | I4: 0.95767199 | J4: 1.1850755 | K4: ='v1'!J4 -> 1.0724392 | M4: [3,] | N4: 39661 | O4: 3.0416077 | P4: 1.3240017 | Q4: ='v1'!P4 -> 1.0507818 | S4: [3,] | T4: 40179 | U4: 0.091488552 | V4: 0.056770796 | W4: ='v1'!V4 -> 0.043467686 | Y4: [3,] | Z4: 41153 | AA4: 0.31147135 | AB4: 0.081231488 | AC4: ='v1'!AB4 -> 0.00012931917
A5: [4,] | B5: 34516 | C5: 3.8795125 | D5: 3.581311 | E5: ='v1'!D5 -> 3.5718071 | G5: [4,] | H5: 34516 | I5: 3.8795125 | J5: 3.581311 | K5: ='v1'!J5 -> 3.5718071 | M5: [4,] | N5: 39692 | O5: 6.8969439 | P5: 1.3989986 | Q5: ='v1'!P5 -> 0.98714105 | S5: [4,] | T5: 40210 | U5: 2.072118 | V5: 0.059623679 | W5: ='v1'!V5 -> 0.040691811 | Y5: [4,] | Z5: 41183 | AA5: 0.067222465 | AB5: 0.082119416 | AC5: ='v1'!AB5 -> 0.00015765229
A6: [5,] | B6: 34547 | C6: 3.7547288 | D6: 3.6722371 | E6: ='v1'!D6 -> 3.6949527 | G6: [5,] | H6: 34547 | I6: 3.7547288 | J6: 3.6722371 | K6: ='v1'!J6 -> 3.6949527 | M6: [5,] | N6: 39722 | O6: 4.1813427 | P6: 1.8391878 | Q6: ='v1'!P6 -> 1.3015952 | S6: [5,] | T6: 40238 | U6: 0.05427457 | V6: 0.097164186 | W6: ='v1'!V6 -> 0.06068541 | Y6: [5,] | Z6: 41214 | AA6: 0.7910543 | AB6: 0.079927536 | AC6: ='v1'!AB6 -> 0.00014912829
A7: [6,] | B7: 34578 | C7: 3.8812581 | D7: 3.2997085 | E7: ='v1'!D7 -> 3.356852 | G7: [6,] | H7: 34578 | I7: 3.8812581 | J7: 3.2997085 | K7: ='v1'!J7 -> 3.356852 | M7: [6,] | N7: 39753 | O7: 7.1340651 | P7: 1.8645218 | Q7: ='v1'!P7 -> 1.3230234 | S7: [6,] | T7: 40269 | U7: 1.1691675 | V7: 0.12876323 | W7: ='v1'!V7 -> 0.094608432 | Y7: [6,] | Z7: 41244 | AA7: 0.4938142 | AB7: 0.075278686 | AC7: ='v1'!AB7 -> 9.9373279e-05
A8: [7,] | B8: 34608 | C8: 3.346453 | D8: 3.2360134 | E8: ='v1'!D8 -> 3.3104104 | G8: [7,] | H8: 34608 | I8: 3.346453 | J8: 3.2360134 | K8: ='v1'!J8 -> 3.3104104 | M8: [7,] | N8: 39783 | O8: 7.3962832 | P8: 2.0891619 | Q8: ='v1'!P8 -> 1.5676798 | S8: [7,] | T8: 40299 | U8: 0.89390651 | V8: 0.10262696 | W8: ='v1'!V8 -> 0.085916464 | Y8: [7,] | Z8: 41275 | AA8: 0.058123537 | AB8: 0.067680888 | AC8: ='v1'!AB8 -> 9.5475469e-05
A9: [8,] | B9: 34639 | C9: 3.5972626 | D9: 2.9055065 | E9: ='v1'!D9 -> 3.0271815 | G9: [8,] | H9: 34639 | I9: 3.5972626 | J9: 2.9055065 | K9: ='v1'!J9 -> 3.0271815 | M9: [8,] | N9: 40544 | O9: 2.9953408 | P9: 0.4693613 | Q9: ='v1'!P9 -> 0.4602215 | S9: [8,] | T9: 40330 | U9: 0.41990071 | V9: 0.15536538 | W9: ='v1'!V9 -> 0.14852685 | Y9: [8,] | Z9: 41306 | AA9: 0.17183822 | AB9: 0.089093844 | AC9: ='v1'!AB9 -> 0.00021015086
A10: [9,] | B10: 34669 | C10: 3.6325202 | D10: 2.8138153 | E10: ='v1'!D10 -> 2.8886113 | G10: [9,] | H10: 34669 | I10: 3.6325202 | J10: 2.8138153 | K10: ='v1'!J10 -> 2.8886113 | M10: [9,] | N10: 40575 | O10: 0.23849025 | P10: 0.62526127 | Q10: ='v1'!P10 -> 0.48294854 | S10: [9,] | T10: 40360 | U10: 1.3504491 | V10: 0.17902357 | W10: ='v1'!V10 -> 0.18174416 | Y10: [9,] | Z10: 41334 | AA10: 0.44405119 | AB10: 0.13263628 | AC10: ='v1'!AB10 -> 0.00030801743
A11: [10,] | B11: 34700 | C11: 2.9523485 | D11: 2.1197167 | E11: ='v1'!D11 -> 2.1731403 | G11: [10,] | H11: 34700 | I11: 2.9523485 | J11: 2.1197167 | K11: ='v1'!J11 -> 2.1731403 | M11: [10,] | N11: 40603 | O11: 0.42683799 | P11: 0.91382648 | Q11: ='v1'!P11 -> 0.57162511 | S11: [10,] | T11: 40391 | U11: 1.5691643 | V11: 0.21465875 | W11: ='v1'!V11 -> 0.23831887 | Y11: [10,] | Z11: 41365 | AA11: 0.45304209 | AB11: 0.16023436 | AC11: ='v1'!AB11 -> 0.00055838293
A12: [11,] | B12: 34731 | C12: 2.5759915 | D12: 2.3265959 | E12: ='v1'!D12 -> 2.391463 | G12: [11,] | H12: 34731 | I12: 2.5759915 | J12: 2.3265959 | K12: ='v1'!J12 -> 2.391463 | M12: [11,] | N12: 40634 | O12: 2.2400458 | P12: 1.4434602 | Q12: ='v1'!P12 -> 0.8915748 | S12: [11,] | T12: 40422 | U12: 1.8872929 | V12: 0.20959422 | W12: ='v1'!V12 -> 0.25912715 | Y12: [11,] | Z12: 41395 | AA12: 0.68102338 | AB12: 0.17931373 | AC12: ='v1'!AB12 -> 0.00099404122
A13: [12,] | B13: 34759 | C13: 2.7604149 | D13: 3.411908 | E13: ='v1'!D13 -> 3.5628466 | G13: [12,] | H13: 34759 | I13: 2.7604149 | J13: 3.411908 | K13: ='v1'!J13 -> 3.5628466 | M13: [12,] | N13: 40664 | O13: 2.8233936 | P13: 1.917037 | Q13: ='v1'!P13 -> 1.2072516 | S13: [12,] | T13: 40452 | U13: 4.34878 | V13: 0.22482208 | W13: ='v1'!V13 -> 0.25262812 | Y13: [12,] | Z13: 41426 | AA13: 0.79776108 | AB13: 0.22090368 | AC13: ='v1'!AB13 -> 0.0022536117
... A46: [45,] | B46: 35827 | C46: 4.4194416 | D46: 4.9914946 | E46: ='v1'!D46 -> 4.7872993 | G46: [45,] | H46: 35827 | I46: 4.4194416 | J46: 4.9914946 | K46: ='v1'!J46 -> 4.7872993 | M46: [45,] | N46: 42005 | O46: 0.37910156 | P46: 4.6093046 | Q46: ='v1'!P46 -> 5.7089408 | S46: [45,] | T46: 41456 | U46: 2.0025424 | V46: 1.1827596 | W46: ='v1'!V46 -> 1.6352723 | Y46: [45,] | Z46: 42430 | AA46: 1.5891994 | AB46: 1.0547095 | AC46: ='v1'!AB46 -> 1.5181084
A47: [46,] | B47: 35855 | C47: 5.3148224 | D47: 6.4259796 | E47: ='v1'!D47 -> 6.1160713 | G47: [46,] | H47: 35855 | I47: 5.3148224 | J47: 6.4259796 | K47: ='v1'!J47 -> 6.1160713 | M47: [46,] | N47: 42036 | O47: 0 | P47: 5.3472206 | Q47: ='v1'!P47 -> 5.6238875 | S47: [46,] | T47: 41487 | U47: 1.5084997 | V47: 1.1205213 | W47: ='v1'!V47 -> 1.5829175
A48: [47,] | B48: 35886 | C48: 5.2053662 | D48: 5.9881213 | E48: ='v1'!D48 -> 5.6752041 | G48: [47,] | H48: 35886 | I48: 5.2053662 | J48: 5.9881213 | K48: ='v1'!J48 -> 5.6752041 | M48: [47,] | N48: 42064 | O48: 0 | P48: 5.6979853 | Q48: ='v1'!P48 -> 5.7787969 | S48: [47,] | T48: 41518 | U48: 1.4313876 | V48: 0.95579718 | W48: ='v1'!V48 -> 1.3513754
A49: [48,] | B49: 35916 | C49: 5.139206 | D49: 5.7908249 | E49: ='v1'!D49 -> 5.4054346 | G49: [48,] | H49: 35916 | I49: 5.139206 | J49: 5.7908249 | K49: ='v1'!J49 -> 5.4054346 | M49: [48,] | N49: 42095 | O49: 0 | P49: 6.5233889 | Q49: ='v1'!P49 -> 6.3345774 | S49: [48,] | T49: 41548 | U49: 1.1616095 | V49: 0.97451582 | W49: ='v1'!V49 -> 1.3851252
A50: [49,] | B50: 35947 | C50: 4.9888157 | D50: 6.0730667 | E50: ='v1'!D50 -> 5.5795007 | G50: [49,] | H50: 35947 | I50: 4.9888157 | J50: 6.0730667 | K50: ='v1'!J50 -> 5.5795007 | M50: [49,] | N50: 42125 | O50: 0 | P50: 7.365728 | Q50: ='v1'!P50 -> 7.5152846 | S50: [49,] | T50: 41579 | U50: 0.99903957 | V50: 0.96790778 | W50: ='v1'!V50 -> 1.3633623
A51: [50,] | B51: 35977 | C51: 8.5725676 | D51: 7.3359307 | E51: ='v1'!D51 -> 6.7227323 | G51: [50,] | H51: 35977 | I51: 8.5725676 | J51: 7.3359307 | K51: ='v1'!J51 -> 6.7227323 | M51: [50,] | N51: 42156 | O51: 5.4940626 | P51: 8.7725603 | Q51: ='v1'!P51 -> 10.972833 | S51: [50,] | T51: 41609 | U51: 1.3293593 | V51: 1.0054907 | W51: ='v1'!V51 -> 1.4298542
A52: [51,] | B52: 36008 | C52: 5.9333979 | D52: 7.1613864 | E52: ='v1'!D52 -> 6.5105165 | G52: [51,] | H52: 36008 | I52: 5.9333979 | J52: 7.1613864 | K52: ='v1'!J52 -> 6.5105165 | M52: [51,] | N52: 42186 | O52: 5.484271 | P52: 8.7105639 | Q52: ='v1'!P52 -> 9.7492641 | S52: [51,] | T52: 41640 | U52: 0.80815131 | V52: 0.73886072 | W52: ='v1'!V52 -> 1.0552068
A53: [52,] | B53: 36039 | C53: 6.8849873 | D53: 5.8249636 | E53: ='v1'!D53 -> 5.2829975 | G53: [52,] | H53: 36039 | I53: 6.8849873 | J53: 5.8249636 | K53: ='v1'!J53 -> 5.2829975 | M53: [52,] | N53: 42217 | O53: 5.1035087 | P53: 9.0195755 | Q53: ='v1'!P53 -> 9.832692 | S53: [52,] | T53: 41671 | U53: 0.83253222 | V53: 0.83563857 | W53: ='v1'!V53 -> 1.1807405
A54: [53,] | B54: 36069 | C54: 3.7178603 | D54: 5.7148531 | E54: ='v1'!D54 -> 5.1712973 | G54: [53,] | H54: 36069 | I54: 3.7178603 | J54: 5.7148531 | K54: ='v1'!J54 -> 5.1712973 | M54: [53,] | N54: 42248 | O54: 3.5524325 | P54: 7.6301861 | Q54: ='v1'!P54 -> 8.6350338 | S54: [53,] | T54: 41699 | U54: 1.1545647 | V54: 1.2178866 | W54: ='v1'!V54 -> 1.7015187
A55: [54,] | B55: 36100 | C55: 3.934328 | D55: 4.262506 | E55: ='v1'!D55 -> 3.9076614 | G55: [54,] | H55: 36100 | I55: 3.934328 | J55: 4.262506 | K55: ='v1'!J55 -> 3.9076614 | M55: [54,] | N55: 42278 | O55: 4.6278352 | P55: 7.3936641 | Q55: ='v1'!P55 -> 8.5476676 | S55: [54,] | T55: 41730 | U55: 1.3183224 | V55: 1.4927062 | W55: ='v1'!V55 -> 2.0463971
A56: [55,] | B56: 36130 | C56: 3.9755617 | D56: 3.3004371 | E56: ='v1'!D56 -> 3.0087598 | G56: [55,] | H56: 36130 | I56: 3.9755617 | J56: 3.3004371 | K56: ='v1'!J56 -> 3.0087598 | M56: [55,] | N56: 42309 | O56: 2.3534554 | P56: 6.6553332 | Q56: ='v1'!P56 -> 8.2949739 | S56: [55,] | T56: 41760 | U56: 1.6430336 | V56: 1.7588329 | W56: ='v1'!V56 -> 2.3586393
A57: [56,] | B57: 36161 | C57: 1.6642834 | D57: 1.700749 | E57: ='v1'!D57 -> 1.489161 | G57: [56,] | H57: 36161 | I57: 1.6642834 | J57: 1.700749 | K57: ='v1'!J57 -> 1.489161 | M57: [56,] | N57: 42339 | O57: 4.4837839 | P57: 7.1521228 | Q57: ='v1'!P57 -> 7.8825696 | S57: [56,] | T57: 41791 | U57: 1.8650125 | V57: 2.1903159 | W57: ='v1'!V57 -> 2.8885976
A58: [57,] | B58: 36192 | C58: 1.8480881 | D58: 2.0784949 | E58: ='v1'!D58 -> 1.7220757 | G58: [57,] | H58: 36192 | I58: 1.8480881 | J58: 2.0784949 | K58: ='v1'!J58 -> 1.7220757 | M58: [57,] | N58: 42370 | O58: 3.3750992 | P58: 5.3192907 | Q58: ='v1'!P58 -> 5.8453703 | S58: [57,] | T58: 41821 | U58: 1.7663513 | V58: 2.1505829 | W58: ='v1'!V58 -> 2.8387388
... A60: [59,] | B60: 36251 | C60: 3.1416549 | D60: 3.7616229 | E60: ='v1'!D60 -> 3.1922254 | G60: [59,] | H60: 36251 | I60: 3.1416549 | J60: 3.7616229 | K60: ='v1'!J60 -> 3.1922254 | M60: [59,] | N60: 42430 | O60: 0 | P60: 7.0819854 | Q60: ='v1'!P60 -> 7.0097849 | S60: [59,] | T60: 41883 | U60: 1.3226091 | V60: 1.9923641 | W60: ='v1'!V60 -> 2.6185058
A61: [60,] | B61: 36281 | C61: 2.5622875 | D61: 4.3044882 | E61: ='v1'!D61 -> 3.7518331 | G61: [60,] | H61: 36281 | I61: 2.5622875 | J61: 4.3044882 | K61: ='v1'!J61 -> 3.7518331 | S61: [60,] | T61: 41913 | U61: 1.4833231 | V61: 2.010199 | W61: ='v1'!V61 -> 2.6502453
A62: [61,] | B62: 36312 | C62: 4.06934 | D62: 5.0557882 | E62: ='v1'!D62 -> 4.4848825 | G62: [61,] | H62: 36312 | I62: 4.06934 | J62: 5.0557882 | K62: ='v1'!J62 -> 4.4848825 | S62: [61,] | T62: 41944 | U62: 1.2232484 | V62: 1.8783047 | W62: ='v1'!V62 -> 2.4499986
A63: [62,] | B63: 36342 | C63: 6.6327677 | D63: 5.6792945 | E63: ='v1'!D63 -> 5.064539 | G63: [62,] | H63: 36342 | I63: 6.6327677 | J63: 5.6792945 | K63: ='v1'!J63 -> 5.064539 | S63: [62,] | T63: 41974 | U63: 1.4133377 | V63: 1.9852387 | W63: ='v1'!V63 -> 2.5767055
A64: [63,] | B64: 36373 | C64: 6.2399507 | D64: 5.9817306 | E64: ='v1'!D64 -> 5.3239603 | G64: [63,] | H64: 36373 | I64: 6.2399507 | J64: 5.9817306 | K64: ='v1'!J64 -> 5.3239603 | S64: [63,] | T64: 42005 | U64: 1.1853211 | V64: 1.5758897 | W64: ='v1'!V64 -> 2.0138979
A65: [64,] | B65: 36404 | C65: 6.7773571 | D65: 5.1744985 | E65: ='v1'!D65 -> 4.5940637 | G65: [64,] | H65: 36404 | I65: 6.7773571 | J65: 5.1744985 | K65: ='v1'!J65 -> 4.5940637 | S65: [64,] | T65: 42036 | U65: 1.2869747 | V65: 1.8546558 | W65: ='v1'!V65 -> 2.3083657
A66: [65,] | B66: 36434 | C66: 5.5032788 | D66: 5.2490879 | E66: ='v1'!D66 -> 4.6820499 | G66: [65,] | H66: 36434 | I66: 5.5032788 | J66: 5.2490879 | K66: ='v1'!J66 -> 4.6820499 | S66: [65,] | T66: 42064 | U66: 1.7225365 | V66: 2.4391107 | W66: ='v1'!V66 -> 3.0402891
A67: [66,] | B67: 36465 | C67: 5.3728795 | D67: 4.9059196 | E67: ='v1'!D67 -> 4.4037217 | G67: [66,] | H67: 36465 | I67: 5.3728795 | J67: 4.9059196 | K67: ='v1'!J67 -> 4.4037217 | S67: [66,] | T67: 42095 | U67: 1.7252982 | V67: 2.7756321 | W67: ='v1'!V67 -> 3.4343876
A68: [67,] | B68: 36495 | C68: 5.4206973 | D68: 5.2028844 | E68: ='v1'!D68 -> 4.6959146 | G68: [67,] | H68: 36495 | I68: 5.4206973 | J68: 5.2028844 | K68: ='v1'!J68 -> 4.6959146 | S68: [67,] | T68: 42125 | U68: 1.3993223 | V68: 3.2942102 | W68: ='v1'!V68 -> 4.0097868
A69: [68,] | B69: 36526 | C69: 4.4843473 | D69: 3.9536901 | E69: ='v1'!D69 -> 3.5785964 | G69: [68,] | H69: 36526 | I69: 4.4843473 | J69: 3.9536901 | K69: ='v1'!J69 -> 3.5785964 | S69: [68,] | T69: 42156 | U69: 3.0437809 | V69: 3.4976194 | W69: ='v1'!V69 -> 4.3219316
A70: [69,] | B70: 36557 | C70: 4.4982097 | D70: 3.9748723 | E70: ='v1'!D70 -> 3.5983981 | G70: [69,] | H70: 36557 | I70: 4.4982097 | J70: 3.9748723 | K70: ='v1'!J70 -> 3.5983981 | S70: [69,] | T70: 42186 | U70: 2.039729 | V70: 3.2204166 | W70: ='v1'!V70 -> 4.0138723
A71: [70,] | B71: 36586 | C71: 5.6013373 | D71: 5.2169414 | E71: ='v1'!D71 -> 4.7528451 | G71: [70,] | H71: 36586 | I71: 5.6013373 | J71: 5.2169414 | K71: ='v1'!J71 -> 4.7528451 | S71: [70,] | T71: 42217 | U71: 2.1461508 | V71: 3.3017385 | W71: ='v1'!V71 -> 4.1451579
A72: [71,] | B72: 36617 | C72: 6.6249054 | D72: 6.1289798 | E72: ='v1'!D72 -> 5.5735063 | G72: [71,] | H72: 36617 | I72: 6.6249054 | J72: 6.1289798 | K72: ='v1'!J72 -> 5.5735063 | S72: [71,] | T72: 42248 | U72: 2.4810739 | V72: 2.8574589 | W72: ='v1'!V72 -> 3.5536769
... A78: [77,] | B78: 36800 | C78: 6.66848 | D78: 7.18003 | E78: ='v1'!D78 -> 6.5805458 | G78: [77,] | H78: 36800 | I78: 6.66848 | J78: 7.18003 | K78: ='v1'!J78 -> 6.5805458 | S78: [77,] | T78: 42430 | U78: 2.6082729 | V78: 2.4094315 | W78: ='v1'!V78 -> 3.0926238
...

Sheet v1
A1: Total | C1: Actual | D1: Model | G1: Coventional | I1: Actual | J1: Model | M1: Jumbo | O1: Actual | P1: Model | S1: CQ | U1: Actual | V1: Model | Y1: CR | AA1: Actual | AB1: Model
A2: [1,] | B2: 34366 | C2: 0.52955312 | D2: 1.0126187 | G2: [1,] | H2: 34366 | I2: 0.52955312 | J2: 1.0126187 | M2: [1,] | N2: 39600 | O2: 0.3312982 | P2: 0.86242858 | S2: [1,] | T2: 40118 | U2: 0 | V2: 0.074460925 | Y2: [1,] | Z2: 41091 | AA2: 2.0789498 | AB2: 0.00011999219
A3: [2,] | B3: 34394 | C3: 0.84363937 | D3: 1.6178198 | G3: [2,] | H3: 34394 | I3: 0.84363937 | J3: 1.6178198 | M3: [2,] | N3: 39630 | O3: 4.6405563 | P3: 1.0439701 | S3: [2,] | T3: 40148 | U3: 0.067238957 | V3: 0.056165954 | Y3: [2,] | Z3: 41122 | AA3: 0.12978227 | AB3: 0.00017698087
A4: [3,] | B4: 34486 | C4: 0.95767199 | D4: 1.0724392 | G4: [3,] | H4: 34486 | I4: 0.95767199 | J4: 1.0724392 | M4: [3,] | N4: 39661 | O4: 3.0416077 | P4: 1.0507818 | S4: [3,] | T4: 40179 | U4: 0.091488552 | V4: 0.043467686 | Y4: [3,] | Z4: 41153 | AA4: 0.31147135 | AB4: 0.00012931917
A5: [4,] | B5: 34516 | C5: 3.8795125 | D5: 3.5718071 | G5: [4,] | H5: 34516 | I5: 3.8795125 | J5: 3.5718071 | M5: [4,] | N5: 39692 | O5: 6.8969439 | P5: 0.98714105 | S5: [4,] | T5: 40210 | U5: 2.072118 | V5: 0.040691811 | Y5: [4,] | Z5: 41183 | AA5: 0.067222465 | AB5: 0.00015765229
A6: [5,] | B6: 34547 | C6: 3.7547288 | D6: 3.6949527 | G6: [5,] | H6: 34547 | I6: 3.7547288 | J6: 3.6949527 | M6: [5,] | N6: 39722 | O6: 4.1813427 | P6: 1.3015952 | S6: [5,] | T6: 40238 | U6: 0.05427457 | V6: 0.06068541 | Y6: [5,] | Z6: 41214 | AA6: 0.7910543 | AB6: 0.00014912829
A7: [6,] | B7: 34578 | C7: 3.8812581 | D7: 3.356852 | G7: [6,] | H7: 34578 | I7: 3.8812581 | J7: 3.356852 | M7: [6,] | N7: 39753 | O7: 7.1340651 | P7: 1.3230234 | S7: [6,] | T7: 40269 | U7: 1.1691675 | V7: 0.094608432 | Y7: [6,] | Z7: 41244 | AA7: 0.4938142 | AB7: 9.9373279e-05
A8: [7,] | B8: 34608 | C8: 3.346453 | D8: 3.3104104 | G8: [7,] | H8: 34608 | I8: 3.346453 | J8: 3.3104104 | M8: [7,] | N8: 39783 | O8: 7.3962832 | P8: 1.5676798 | S8: [7,] | T8: 40299 | U8: 0.89390651 | V8: 0.085916464 | Y8: [7,] | Z8: 41275 | AA8: 0.058123537 | AB8: 9.5475469e-05
A9: [8,] | B9: 34639 | C9: 3.5972626 | D9: 3.0271815 | G9: [8,] | H9: 34639 | I9: 3.5972626 | J9: 3.0271815 | M9: [8,] | N9: 40544 | O9: 2.9953408 | P9: 0.4602215 | S9: [8,] | T9: 40330 | U9: 0.41990071 | V9: 0.14852685 | Y9: [8,] | Z9: 41306 | AA9: 0.17183822 | AB9: 0.00021015086
A10: [9,] | B10: 34669 | C10: 3.6325202 | D10: 2.8886113 | G10: [9,] | H10: 34669 | I10: 3.6325202 | J10: 2.8886113 | M10: [9,] | N10: 40575 | O10: 0.23849025 | P10: 0.48294854 | S10: [9,] | T10: 40360 | U10: 1.3504491 | V10: 0.18174416 | Y10: [9,] | Z10: 41334 | AA10: 0.44405119 | AB10: 0.00030801743
A11: [10,] | B11: 34700 | C11: 2.9523485 | D11: 2.1731403 | G11: [10,] | H11: 34700 | I11: 2.9523485 | J11: 2.1731403 | M11: [10,] | N11: 40603 | O11: 0.42683799 | P11: 0.57162511 | S11: [10,] | T11: 40391 | U11: 1.5691643 | V11: 0.23831887 | Y11: [10,] | Z11: 41365 | AA11: 0.45304209 | AB11: 0.00055838293
A12: [11,] | B12: 34731 | C12: 2.5759915 | D12: 2.391463 | G12: [11,] | H12: 34731 | I12: 2.5759915 | J12: 2.391463 | M12: [11,] | N12: 40634 | O12: 2.2400458 | P12: 0.8915748 | S12: [11,] | T12: 40422 | U12: 1.8872929 | V12: 0.25912715 | Y12: [11,] | Z12: 41395 | AA12: 0.68102338 | AB12: 0.00099404122
A13: [12,] | B13: 34759 | C13: 2.7604149 | D13: 3.5628466 | G13: [12,] | H13: 34759 | I13: 2.7604149 | J13: 3.5628466 | M13: [12,] | N13: 40664 | O13: 2.8233936 | P13: 1.2072516 | S13: [12,] | T13: 40452 | U13: 4.34878 | V13: 0.25262812 | Y13: [12,] | Z13: 41426 | AA13: 0.79776108 | AB13: 0.0022536117
... A46: [45,] | B46: 35827 | C46: 4.4194416 | D46: 4.7872993 | G46: [45,] | H46: 35827 | I46: 4.4194416 | J46: 4.7872993 | M46: [45,] | N46: 42005 | O46: 0.37910156 | P46: 5.7089408 | S46: [45,] | T46: 41456 | U46: 2.0025424 | V46: 1.6352723 | Y46: [45,] | Z46: 42430 | AA46: 1.5891994 | AB46: 1.5181084
A47: [46,] | B47: 35855 | C47: 5.3148224 | D47: 6.1160713 | G47: [46,] | H47: 35855 | I47: 5.3148224 | J47: 6.1160713 | M47: [46,] | N47: 42036 | O47: 0 | P47: 5.6238875 | S47: [46,] | T47: 41487 | U47: 1.5084997 | V47: 1.5829175
A48: [47,] | B48: 35886 | C48: 5.2053662 | D48: 5.6752041 | G48: [47,] | H48: 35886 | I48: 5.2053662 | J48: 5.6752041 | M48: [47,] | N48: 42064 | O48: 0 | P48: 5.7787969 | S48: [47,] | T48: 41518 | U48: 1.4313876 | V48: 1.3513754
A49: [48,] | B49: 35916 | C49: 5.139206 | D49: 5.4054346 | G49: [48,] | H49: 35916 | I49: 5.139206 | J49: 5.4054346 | M49: [48,] | N49: 42095 | O49: 0 | P49: 6.3345774 | S49: [48,] | T49: 41548 | U49: 1.1616095 | V49: 1.3851252
A50: [49,] | B50: 35947 | C50: 4.9888157 | D50: 5.5795007 | G50: [49,] | H50: 35947 | I50: 4.9888157 | J50: 5.5795007 | M50: [49,] | N50: 42125 | O50: 0 | P50: 7.5152846 | S50: [49,] | T50: 41579 | U50: 0.99903957 | V50: 1.3633623
A51: [50,] | B51: 35977 | C51: 8.5725676 | D51: 6.7227323 | G51: [50,] | H51: 35977 | I51: 8.5725676 | J51: 6.7227323 | M51: [50,] | N51: 42156 | O51: 5.4940626 | P51: 10.972833 | S51: [50,] | T51: 41609 | U51: 1.3293593 | V51: 1.4298542
A52: [51,] | B52: 36008 | C52: 5.9333979 | D52: 6.5105165 | G52: [51,] | H52: 36008 | I52: 5.9333979 | J52: 6.5105165 | M52: [51,] | N52: 42186 | O52: 5.484271 | P52: 9.7492641 | S52: [51,] | T52: 41640 | U52: 0.80815131 | V52: 1.0552068
A53: [52,] | B53: 36039 | C53: 6.8849873 | D53: 5.2829975 | G53: [52,] | H53: 36039 | I53: 6.8849873 | J53: 5.2829975 | M53: [52,] | N53: 42217 | O53: 5.1035087 | P53: 9.832692 | S53: [52,] | T53: 41671 | U53: 0.83253222 | V53: 1.1807405
A54: [53,] | B54: 36069 | C54: 3.7178603 | D54: 5.1712973 | G54: [53,] | H54: 36069 | I54: 3.7178603 | J54: 5.1712973 | M54: [53,] | N54: 42248 | O54: 3.5524325 | P54: 8.6350338 | S54: [53,] | T54: 41699 | U54: 1.1545647 | V54: 1.7015187
A55: [54,] | B55: 36100 | C55: 3.934328 | D55: 3.9076614 | G55: [54,] | H55: 36100 | I55: 3.934328 | J55: 3.9076614 | M55: [54,] | N55: 42278 | O55: 4.6278352 | P55: 8.5476676 | S55: [54,] | T55: 41730 | U55: 1.3183224 | V55: 2.0463971
A56: [55,] | B56: 36130 | C56: 3.9755617 | D56: 3.0087598 | G56: [55,] | H56: 36130 | I56: 3.9755617 | J56: 3.0087598 | M56: [55,] | N56: 42309 | O56: 2.3534554 | P56: 8.2949739 | S56: [55,] | T56: 41760 | U56: 1.6430336 | V56: 2.3586393
A57: [56,] | B57: 36161 | C57: 1.6642834 | D57: 1.489161 | G57: [56,] | H57: 36161 | I57: 1.6642834 | J57: 1.489161 | M57: [56,] | N57: 42339 | O57: 4.4837839 | P57: 7.8825696 | S57: [56,] | T57: 41791 | U57: 1.8650125 | V57: 2.8885976
A58: [57,] | B58: 36192 | C58: 1.8480881 | D58: 1.7220757 | G58: [57,] | H58: 36192 | I58: 1.8480881 | J58: 1.7220757 | M58: [57,] | N58: 42370 | O58: 3.3750992 | P58: 5.8453703 | S58: [57,] | T58: 41821 | U58: 1.7663513 | V58: 2.8387388
... A60: [59,] | B60: 36251 | C60: 3.1416549 | D60: 3.1922254 | G60: [59,] | H60: 36251 | I60: 3.1416549 | J60: 3.1922254 | M60: [59,] | N60: 42430 | O60: 0 | P60: 7.0097849 | S60: [59,] | T60: 41883 | U60: 1.3226091 | V60: 2.6185058
A61: [60,] | B61: 36281 | C61: 2.5622875 | D61: 3.7518331 | G61: [60,] | H61: 36281 | I61: 2.5622875 | J61: 3.7518331 | S61: [60,] | T61: 41913 | U61: 1.4833231 | V61: 2.6502453
A62: [61,] | B62: 36312 | C62: 4.06934 | D62: 4.4848825 | G62: [61,] | H62: 36312 | I62: 4.06934 | J62: 4.4848825 | S62: [61,] | T62: 41944 | U62: 1.2232484 | V62: 2.4499986
A63: [62,] | B63: 36342 | C63: 6.6327677 | D63: 5.064539 | G63: [62,] | H63: 36342 | I63: 6.6327677 | J63: 5.064539 | S63: [62,] | T63: 41974 | U63: 1.4133377 | V63: 2.5767055
A64: [63,] | B64: 36373 | C64: 6.2399507 | D64: 5.3239603 | G64: [63,] | H64: 36373 | I64: 6.2399507 | J64: 5.3239603 | S64: [63,] | T64: 42005 | U64: 1.1853211 | V64: 2.0138979
A65: [64,] | B65: 36404 | C65: 6.7773571 | D65: 4.5940637 | G65: [64,] | H65: 36404 | I65: 6.7773571 | J65: 4.5940637 | S65: [64,] | T65: 42036 | U65: 1.2869747 | V65: 2.3083657
A66: [65,] | B66: 36434 | C66: 5.5032788 | D66: 4.6820499 | G66: [65,] | H66: 36434 | I66: 5.5032788 | J66: 4.6820499 | S66: [65,] | T66: 42064 | U66: 1.7225365 | V66: 3.0402891
A67: [66,] | B67: 36465 | C67: 5.3728795 | D67: 4.4037217 | G67: [66,] | H67: 36465 | I67: 5.3728795 | J67: 4.4037217 | S67: [66,] | T67: 42095 | U67: 1.7252982 | V67: 3.4343876
A68: [67,] | B68: 36495 | C68: 5.4206973 | D68: 4.6959146 | G68: [67,] | H68: 36495 | I68: 5.4206973 | J68: 4.6959146 | S68: [67,] | T68: 42125 | U68: 1.3993223 | V68: 4.0097868
A69: [68,] | B69: 36526 | C69: 4.4843473 | D69: 3.5785964 | G69: [68,] | H69: 36526 | I69: 4.4843473 | J69: 3.5785964 | S69: [68,] | T69: 42156 | U69: 3.0437809 | V69: 4.3219316
A70: [69,] | B70: 36557 | C70: 4.4982097 | D70: 3.5983981 | G70: [69,] | H70: 36557 | I70: 4.4982097 | J70: 3.5983981 | S70: [69,] | T70: 42186 | U70: 2.039729 | V70: 4.0138723
A71: [70,] | B71: 36586 | C71: 5.6013373 | D71: 4.7528451 | G71: [70,] | H71: 36586 | I71: 5.6013373 | J71: 4.7528451 | S71: [70,] | T71: 42217 | U71: 2.1461508 | V71: 4.1451579
A72: [71,] | B72: 36617 | C72: 6.6249054 | D72: 5.5735063 | G72: [71,] | H72: 36617 | I72: 6.6249054 | J72: 5.5735063 | S72: [71,] | T72: 42248 | U72: 2.4810739 | V72: 3.5536769
... A78: [77,] | B78: 36800 | C78: 6.66848 | D78: 6.5805458 | G78: [77,] | H78: 36800 | I78: 6.66848 | J78: 6.5805458 | S78: [77,] | T78: 42430 | U78: 2.6082729 | V78: 3.0926238
...
