Workbook

Sheet Sheet1
D1: shock | E1: shift | M1: fn30.400.14(IOX)
D2: -25 | E2: -29 | M2: fnm30.300.13(GEN)
D3: -50 | E3: -62
B4: n13.80(AS) | D4: 25 | E4: 23
B5: n13.80(AS) | D5: 50 | E5: 47
B6: f4267(CS) | D6: 100 | E6: 97
B7: N14.14(SA) | D7: 150 | E7: 147
B8: N13.98(SA)
B9: FHL.PC.339(S5) | E9: 1yr CPR | G9: 1m CPR | M9: 42083
B10: fn30.300.12(IOX) | D10: 42185 | M10: 42094
D11: fn30.400.10(IOX) | E11: 0
D14: Month Index | E14: ProjectedCPR
C15: 42156 | D15: 1 | E15: =[1]!YBSCEN($D$11,"0y","Market","ProjectedCPR","Swap",$D$10,"LMMSkew","","Model",100,0,0,"Immediate","ParShift|Y",$E$11,"Spread Change",0,100,"CPRPROJ",,,,"Default",D15,,,"Default",,) -> 14.638 | F15: =((1-E15/100)^(1/12)) -> 0.9868975 | H15: Cello Model | I15: Base | J15: Cello | K15: Down 50 | L15: Cello | M15: Up 50
C16: 42186 | D16: =D15+1 -> 2 | E16: =[1]!YBSCEN($D$11,"0y","Market","ProjectedCPR","Swap",$D$10,"LMMSkew","","Model",100,0,0,"Immediate","ParShift|Y",$E$11,"Spread Change",0,100,"CPRPROJ",,,Sheet2!B$5,"Default",D16,,,"Default",,) -> 14.662 | F16: =((1-E16/100)^(1/12)) -> 0.98687437
C17: 42217 | D17: =D16+1 -> 3 | E17: =[1]!YBSCEN($D$11,"0y","Market","ProjectedCPR","Swap",$D$10,"LMMSkew","","Model",100,0,0,"Immediate","ParShift|Y",$E$11,"Spread Change",0,100,"CPRPROJ",,,Sheet2!B$5,"Default",D17,,,"Default",,) -> 13.017 | F17: =((1-E17/100)^(1/12)) -> 0.98844581
C18: 42248 | D18: =D17+1 -> 4 | E18: =[1]!YBSCEN($D$11,"0y","Market","ProjectedCPR","Swap",$D$10,"LMMSkew","","Model",100,0,0,"Immediate","ParShift|Y",$E$11,"Spread Change",0,100,"CPRPROJ",,,Sheet2!B$5,"Default",D18,,,"Default",,) -> 14.166 | F18: =((1-E18/100)^(1/12)) -> 0.9873511
C19: 42278 | D19: =D18+1 -> 5 | E19: =[1]!YBSCEN($D$11,"0y","Market","ProjectedCPR","Swap",$D$10,"LMMSkew","","Model",100,0,0,"Immediate","ParShift|Y",$E$11,"Spread Change",0,100,"CPRPROJ",,,Sheet2!B$5,"Default",D19,,,"Default",,) -> 11.952 | F19: =((1-E19/100)^(1/12)) -> 0.98944872
C20: 42309 | D20: =D19+1 -> 6 | E20: =[1]!YBSCEN($D$11,"0y","Market","ProjectedCPR","Swap",$D$10,"LMMSkew","","Model",100,0,0,"Immediate","ParShift|Y",$E$11,"Spread Change",0,100,"CPRPROJ",,,Sheet2!B$5,"Default",D20,,,"Default",,) -> 12.892 | F20: =((1-E20/100)^(1/12)) -> 0.9885641
C21: 42339 | D21: =D20+1 -> 7 | E21: =[1]!YBSCEN($D$11,"0y","Market","ProjectedCPR","Swap",$D$10,"LMMSkew","","Model",100,0,0,"Immediate","ParShift|Y",$E$11,"Spread Change",0,100,"CPRPROJ",,,Sheet2!B$5,"Default",D21,,,"Default",,) -> 15.249 | F21: =((1-E21/100)^(1/12)) -> 0.9863069
C22: 42370 | D22: =D21+1 -> 8 | E22: =[1]!YBSCEN($D$11,"0y","Market","ProjectedCPR","Swap",$D$10,"LMMSkew","","Model",100,0,0,"Immediate","ParShift|Y",$E$11,"Spread Change",0,100,"CPRPROJ",,,Sheet2!B$5,"Default",D22,,,"Default",,) -> 14.802 | F22: =((1-E22/100)^(1/12)) -> 0.98673936
C23: 42401 | D23: =D22+1 -> 9 | E23: =[1]!YBSCEN($D$11,"0y","Market","ProjectedCPR","Swap",$D$10,"LMMSkew","","Model",100,0,0,"Immediate","ParShift|Y",$E$11,"Spread Change",0,100,"CPRPROJ",,,Sheet2!B$5,"Default",D23,,,"Default",,) -> 15.205 | F23: =((1-E23/100)^(1/12)) -> 0.98634956
C24: 42430 | D24: =D23+1 -> 10 | E24: =[1]!YBSCEN($D$11,"0y","Market","ProjectedCPR","Swap",$D$10,"LMMSkew","","Model",100,0,0,"Immediate","ParShift|Y",$E$11,"Spread Change",0,100,"CPRPROJ",,,Sheet2!B$5,"Default",D24,,,"Default",,) -> 16.423 | F24: =((1-E24/100)^(1/12)) -> 0.98516105
C25: 42461 | D25: =D24+1 -> 11 | E25: =[1]!YBSCEN($D$11,"0y","Market","ProjectedCPR","Swap",$D$10,"LMMSkew","","Model",100,0,0,"Immediate","ParShift|Y",$E$11,"Spread Change",0,100,"CPRPROJ",,,Sheet2!B$5,"Default",D25,,,"Default",,) -> 14.71 | F25: =((1-E25/100)^(1/12)) -> 0.9868281
C26: 42491 | D26: =D25+1 -> 12 | E26: =[1]!YBSCEN($D$11,"0y","Market","ProjectedCPR","Swap",$D$10,"LMMSkew","","Model",100,0,0,"Immediate","ParShift|Y",$E$11,"Spread Change",0,100,"CPRPROJ",,,Sheet2!B$5,"Default",D26,,,"Default",,) -> 16.295 | F26: =((1-E26/100)^(1/12)) -> 0.98528669 | P26: New YB | S26: New YB | U26: New YB
C27: 42522 | D27: =D26+1 -> 13 | E27: =[1]!YBSCEN($D$11,"0y","Market","ProjectedCPR","Swap",$D$10,"LMMSkew","","Model",100,0,0,"Immediate","ParShift|Y",$E$11,"Spread Change",0,100,"CPRPROJ",,,Sheet2!B$5,"Default",D27,,,"Default",,) -> 14.309 | F27: =((1-E27/100)^(1/12)) -> 0.98721391 | H27: 0 | I27: -47 | J27: 40
C28: 42552 | D28: =D27+1 -> 14 | E28: =[1]!YBSCEN($D$11,"0y","Market","ProjectedCPR","Swap",$D$10,"LMMSkew","","Model",100,0,0,"Immediate","ParShift|Y",$E$11,"Spread Change",0,100,"CPRPROJ",,,Sheet2!B$5,"Default",D28,,,"Default",,) -> 13.623 | F28: =((1-E28/100)^(1/12)) -> 0.98787011 | H28: 5.5 | N28: 0.1483769 | O28: -0.13300558 | P28: 8.2 | Q28: 7.9701053 | R28: 0.77010529 | S28: 6.57 | T28: -0.035422665 | U28: 9.44 | V28: =U28-E28+G34-L28 -> 9.7378643
C29: 42583 | D29: =D28+1 -> 15 | E29: =[1]!YBSCEN($D$11,"0y","Market","ProjectedCPR","Swap",$D$10,"LMMSkew","","Model",100,0,0,"Immediate","ParShift|Y",$E$11,"Spread Change",0,100,"CPRPROJ",,,Sheet2!B$5,"Default",D29,,,"Default",,) -> 13.152 | F29: =((1-E29/100)^(1/12)) -> 0.98831788 | G29: =100*(1-PRODUCT(F18:F29)) -> 14.407791 | H29: 6.2292122 | I29: 8.5177793 | J29: 4.3789879
C30: 42614 | D30: =D29+1 -> 16 | E30: =[1]!YBSCEN($D$11,"0y","Market","ProjectedCPR","Swap",$D$10,"LMMSkew","","Model",100,0,0,"Immediate","ParShift|Y",$E$11,"Spread Change",0,100,"CPRPROJ",,,Sheet2!B$5,"Default",D30,,,"Default",,) -> 13.003 | F30: =((1-E30/100)^(1/12)) -> 0.98845907
C31: 42644 | D31: =D30+1 -> 17 | E31: =[1]!YBSCEN($D$11,"0y","Market","ProjectedCPR","Swap",$D$10,"LMMSkew","","Model",100,0,0,"Immediate","ParShift|Y",$E$11,"Spread Change",0,100,"CPRPROJ",,,Sheet2!B$5,"Default",D31,,,"Default",,) -> 11.686 | F31: =((1-E31/100)^(1/12)) -> 0.98969748
C32: 42675 | D32: =D31+1 -> 18 | E32: =[1]!YBSCEN($D$11,"0y","Market","ProjectedCPR","Swap",$D$10,"LMMSkew","","Model",100,0,0,"Immediate","ParShift|Y",$E$11,"Spread Change",0,100,"CPRPROJ",,,Sheet2!B$5,"Default",D32,,,"Default",,) -> 11.403 | F32: =((1-E32/100)^(1/12)) -> 0.98996138
C33: 42705 | D33: =D32+1 -> 19 | E33: =[1]!YBSCEN($D$11,"0y","Market","ProjectedCPR","Swap",$D$10,"LMMSkew","","Model",100,0,0,"Immediate","ParShift|Y",$E$11,"Spread Change",0,100,"CPRPROJ",,,Sheet2!B$5,"Default",D33,,,"Default",,) -> 14.017 | F33: =((1-E33/100)^(1/12)) -> 0.98749381
C34: 42736 | D34: =D33+1 -> 20 | E34: =[1]!YBSCEN($D$11,"0y","Market","ProjectedCPR","Swap",$D$10,"LMMSkew","","Model",100,0,0,"Immediate","ParShift|Y",$E$11,"Spread Change",0,100,"CPRPROJ",,,Sheet2!B$5,"Default",D34,,,"Default",,) -> 13.062 | F34: =((1-E34/100)^(1/12)) -> 0.98840319 | G34: =100*(1-PRODUCT(F23:F34)) -> 13.920864
C35: 42767 | D35: =D34+1 -> 21 | E35: =[1]!YBSCEN($D$11,"0y","Market","ProjectedCPR","Swap",$D$10,"LMMSkew","","Model",100,0,0,"Immediate","ParShift|Y",$E$11,"Spread Change",0,100,"CPRPROJ",,,Sheet2!B$5,"Default",D35,,,"Default",,) -> 14.64 | F35: =((1-E35/100)^(1/12)) -> 0.98689557
C36: 42795 | D36: =D35+1 -> 22 | E36: =[1]!YBSCEN($D$11,"0y","Market","ProjectedCPR","Swap",$D$10,"LMMSkew","","Model",100,0,0,"Immediate","ParShift|Y",$E$11,"Spread Change",0,100,"CPRPROJ",,,Sheet2!B$5,"Default",D36,,,"Default",,) -> 15.201 | F36: =((1-E36/100)^(1/12)) -> 0.98635343
C37: 42826 | D37: =D36+1 -> 23 | E37: =[1]!YBSCEN($D$11,"0y","Market","ProjectedCPR","Swap",$D$10,"LMMSkew","","Model",100,0,0,"Immediate","ParShift|Y",$E$11,"Spread Change",0,100,"CPRPROJ",,,Sheet2!B$5,"Default",D37,,,"Default",,) -> 13.603 | F37: =((1-E37/100)^(1/12)) -> 0.98788916
C38: 42856 | D38: =D37+1 -> 24 | E38: =[1]!YBSCEN($D$11,"0y","Market","ProjectedCPR","Swap",$D$10,"LMMSkew","","Model",100,0,0,"Immediate","ParShift|Y",$E$11,"Spread Change",0,100,"CPRPROJ",,,Sheet2!B$5,"Default",D38,,,"Default",,) -> 15.051 | F38: =((1-E38/100)^(1/12)) -> 0.98649871
C39: 42887 | D39: =D38+1 -> 25 | E39: =[1]!YBSCEN($D$11,"0y","Market","ProjectedCPR","Swap",$D$10,"LMMSkew","","Model",100,0,0,"Immediate","ParShift|Y",$E$11,"Spread Change",0,100,"CPRPROJ",,,Sheet2!B$5,"Default",D39,,,"Default",,) -> 12.631 | F39: =((1-E39/100)^(1/12)) -> 0.9888106
C40: 42917 | D40: =D39+1 -> 26 | E40: =[1]!YBSCEN($D$11,"0y","Market","ProjectedCPR","Swap",$D$10,"LMMSkew","","Model",100,0,0,"Immediate","ParShift|Y",$E$11,"Spread Change",0,100,"CPRPROJ",,,Sheet2!B$5,"Default",D40,,,"Default",,) -> 13.046 | F40: =((1-E40/100)^(1/12)) -> 0.98841834 | O40: -0.02131901 | P40: 9.4 | Q40: 8.9739722 | R40: 0.9739722 | S40: 7.73 | T40: 0.31635861 | U40: 10.68 | V40: =U40-E40+G46-L40 -> #VALUE!
C41: 42948 | D41: =D40+1 -> 27 | E41: =[1]!YBSCEN($D$11,"0y","Market","ProjectedCPR","Swap",$D$10,"LMMSkew","","Model",100,0,0,"Immediate","ParShift|Y",$E$11,"Spread Change",0,100,"CPRPROJ",,,Sheet2!B$5,"Default",D41,,,"Default",,) -> 12.621 | F41: =((1-E41/100)^(1/12)) -> 0.98882003
C42: 42979 | D42: =D41+1 -> 28 | E42: =[1]!YBSCEN($D$11,"0y","Market","ProjectedCPR","Swap",$D$10,"LMMSkew","","Model",100,0,0,"Immediate","ParShift|Y",$E$11,"Spread Change",0,100,"CPRPROJ",,,Sheet2!B$5,"Default",D42,,,"Default",,) -> 11.491 | F42: =((1-E42/100)^(1/12)) -> 0.9898794
...

Sheet Sheet2
B5: =[1]!YBMBSDIALS("CC+25","N","","Y",0,"N","Y","N","N","N",$C$6:$C$30,$D$6:$D$30,$E$6:$E$30,$F$6:$F$30,$G$6:$G$30,$H$6:$H$30,$I$6:$I$30,$J$6:$J$30,"","","","","","","",1,"","N","pssLookback(0)") -> YBDIALS_CC+25 | C5: Conventional | D5: GNMA | E5: Whole Loans | F5: ARMs | G5: HELS | H5: Man Housing | I5: Alt-A | J5: GHLC
B6: Turnover Multiplier | C6: 1 | D6: 1 | E6: 1 | F6: 1 | G6: 1 | H6: 1 | I6: 1 | J6: 1
B7: Turnover Seasoning | C7: 1 | D7: 1 | E7: 1 | F7: 1 | G7: 1 | H7: 1 | I7: 1 | J7: 1
B8: Turnover Lockin | C8: 1 | D8: 1 | E8: 1 | F8: 1 | G8: 1 | H8: 1 | I8: 1 | J8: 1
B9: Refinancing Multiplier | C9: 1 | D9: 1 | E9: 1 | F9: 1 | G9: 1 | H9: 1 | I9: 1 | J9: 1
B10: Refinancing Elbow Shift | C10: 0 | D10: 0 | E10: 0 | F10: 0 | G10: 0 | H10: 0 | I10: 0 | J10: 0
B11: Refinancing Curve Steepness | C11: 1 | D11: 1 | E11: 1 | F11: 1 | G11: 1 | H11: 1 | I11: 1 | J11: 1
B12: Refinancing Burnout | C12: 1 | D12: 1 | E12: 1 | F12: 1 | G12: 1 | H12: 1 | I12: 1 | J12: 1
B13: Refinancing Seasoning Adjustment | C13: 1 | D13: 1 | E13: 1 | F13: 1 | G13: 1 | H13: 1 | I13: 1 | J13: 1
B14: Refinancing Media Effect | C14: 1 | D14: 1 | E14: 1 | F14: 1 | G14: 1 | H14: 1 | I14: 1 | J14: 1
B15: Prepayment Decay | C15: 1 | D15: 1 | E15: 1 | F15: 1 | G15: 1 | H15: 1 | I15: 1 | J15: 1
B16: Cashouts | C16: 1 | D16: 1 | E16: 1 | F16: 1 | G16: 1 | H16: 1 | I16: 1 | J16: 1
B17: Credit Score Base | C17: 700 | D17: 700 | E17: 700 | F17: 700 | G17: 700 | H17: 700 | I17: 700 | J17: 700
... B21: Loan Size Base | C21: 200 | D21: 200 | E21: 200 | F21: 200 | G21: 200 | H21: 200 | I21: 200 | J21: 200
B22: Loan Size Slope | C22: 1 | F22: 1 | G22: 1 | H22: 1 | I22: 1 | J22: 1
B23: Arm Spike Height | C23: 0 | D23: 0 | E23: 0 | F23: 0 | G23: 0 | H23: 0 | I23: 0 | J23: 0
B24: Arm Spike Length | C24: 0 | D24: 0 | E24: 0 | F24: 0 | G24: 0 | H24: 0 | I24: 0 | J24: 0
B25: IO Spike Height | C25: 0 | D25: 0 | E25: 0 | F25: 0 | G25: 0 | H25: 0 | I25: 0 | J25: 0
B26: IO Spike Length | C26: 0 | D26: 0 | E26: 0 | F26: 0 | G26: 0 | H26: 0 | I26: 0 | J26: 0
B27: IO Spike Elbow | C27: 0 | D27: 0 | E27: 0 | F27: 0 | G27: 0 | H27: 0 | I27: 0 | J27: 0
B28: Agency Eligibility | C28: 1 | D28: 1 | E28: 1 | F28: 1 | G28: 1 | H28: 1 | I28: 1 | J28: 1
B29: Default Multiplier | C29: 1 | D29: 1 | E29: 1 | F29: 1 | G29: 1 | H29: 1 | I29: 1 | J29: 1
B30: Curtailment Multiplier | C30: 1 | D30: 1 | E30: 1 | F30: 1 | G30: 1 | H30: 1 | I30: 1 | J30: 1
C31: 0 | D31: 0 | E31: 0 | F31: 0 | G31: 0 | H31: 0 | I31: 0 | J31: 0
C32: 1 | D32: 1 | E32: 1 | F32: 1 | G32: 1 | H32: 1 | I32: 1 | J32: 1
C33: 1 | D33: 1 | E33: 1 | F33: 1 | G33: 1 | H33: 1 | I33: 1 | J33: 1
C34: 1 | D34: 1 | E34: 1 | F34: 1 | G34: 1 | H34: 1 | I34: 1 | J34: 1
C35: 1 | D35: 1 | E35: 1 | F35: 1 | G35: 1 | H35: 1 | I35: 1 | J35: 1
C36: 1 | D36: 1 | E36: 1 | F36: 1 | G36: 1 | H36: 1 | I36: 1 | J36: 1
C37: 1 | D37: 1 | E37: 1 | F37: 1 | G37: 1 | H37: 1 | I37: 1 | J37: 1
C38: 1 | D38: 1 | E38: 1 | F38: 1 | G38: 1 | H38: 1 | I38: 1 | J38: 1
C39: 1 | D39: 1 | E39: 1 | F39: 1 | G39: 1 | H39: 1 | I39: 1 | J39: 1
C40: 1 | D40: 1 | E40: 1 | F40: 1 | G40: 1 | H40: 1 | I40: 1 | J40: 1
C41: 1 | D41: 1 | E41: 1 | F41: 1 | G41: 1 | H41: 1 | I41: 1 | J41: 1
C42: 1 | D42: 1 | E42: 1 | F42: 1 | G42: 1 | H42: 1 | I42: 1 | J42: 1
... C47: 0 | D47: 0 | E47: 0 | F47: 0 | G47: 0 | H47: 0 | I47: 0 | J47: 0

Sheet Sheet3
A1: f4267(CS) | B1: Cello Model | C1: Base | D1: Cello | E1: Down 50 | F1: Cello | G1: Up 50
J12: New YB | M12: New YB | O12: New YB
A14: 6.0714335 | B14: 7.5 | C14: 8.8274825 | D14: 8.2 | E14: 13.545198 | F14: 5.4 | G14: 6.0714335 | H14: 0.1483769 | I14: -0.13300558 | J14: 8.03 | K14: 7.4024825 | L14: -0.097517536 | M14: 9.67 | N14: 0.96819797 | O14: 6.85 | P14: =O14-#REF!+A20-F14 -> #REF!
A20: 6.6289664
A26: 7.028934 | B26: 7.5 | C26: 9.4063071 | D26: 9.3 | E26: 14.392801 | F26: 5.8 | G26: 7.028934 | H26: 0.36097504 | I26: -0.02131901 | J26: 8.64 | K26: 8.0323071 | L26: 0.53230712 | M26: 10.22 | N26: 0.53780146 | O26: 7.57 | P26: =O26-#REF!+A32-F26 -> #REF!
A32: 7.2738544
A38: 7.4309409 | B38: 8.4 | C38: 10.096493 | D38: 10.8 | E38: 15.155855 | F38: 6.3 | G38: 7.4309409 | H38: 0.47436818 | I38: 0.1390505 | J38: 9.53 | K38: 8.4544933 | L38: 0.054493267 | M38: 11.73 | N38: -0.19314542 | O38: 8.21 | P38: =O38-#REF!+A44-F38 -> #REF!
A44: 7.6792721
A50: 8.1009732 | B50: 9.6 | C50: 11.226957 | D50: 12.7 | E50: 15.765611 | F50: 6.9 | G50: 8.1009732 | H50: 0.68302188 | I50: 0.32455496 | J50: 11.15 | K50: 9.5509573 | L50: -0.049042674 | M50: 14.14 | N50: -0.40838864 | O50: 9.27 | P50: =O50-#REF!+A56-F50 -> #REF!
A56: 8.5798109
A62: 9.1280595 | B62: 11.2 | C62: 12.386593 | D62: 14.9 | E62: 15.905839 | F62: 7.7 | G62: 9.1280595 | H62: 1.0513616 | I62: 0.71418901 | J62: 13.08 | K62: 11.393593 | L62: 0.19359317 | M62: 16.4 | N62: -0.38416083 | O62: 10.42 | P62: =O62-#REF!+A68-F62 -> #REF!
A68: 9.5198729
A74: 9.8155805 | B74: 12.8 | C74: 13.109623 | D74: 17.1 | E74: 15.703425 | F74: 8.6 | G74: 9.8155805 | H74: 1.657798 | I74: 1.5384278 | J74: 13.92 | K74: 12.710623 | L74: -0.089377412 | M74: 16.37 | N74: -6.4891628 | O74: 10.85 | P74: =O74-#REF!+A80-F74 -> #REF!
A80: 10.086215
A86: 10.304763 | B86: 14.3 | C86: 13.553279 | D86: 18.9 | F86: 9.3 | G86: 10.304763 | H86: -0.33940126 | J86: 15.81 | K86: 14.609279 | L86: 0.30927921 | O86: 11.95

Sheet Sheet4
A2: 42178 | B2: 3.979
A3: peak | B3: 3.55
B4: =B2-B3 -> 0.429
